 ,ts_recv,ts_event,rtype,publisher_id,instrument_id,action,side,depth,price,size,flags,ts_in_delta,sequence,bid_px_00,bid_sz_00,bid_ct_00,ask_px_00,ask_sz_00,ask_ct_00,bid_px_01,bid_sz_01,bid_ct_01,ask_px_01,ask_sz_01,ask_ct_01,bid_px_02,bid_sz_02,bid_ct_02,ask_px_02,ask_sz_02,ask_ct_02,bid_px_03,bid_sz_03,bid_ct_03,ask_px_03,ask_sz_03,ask_ct_03,bid_px_04,bid_sz_04,bid_ct_04,ask_px_04,ask_sz_04,ask_ct_04,bid_px_05,bid_sz_05,bid_ct_05,ask_px_05,ask_sz_05,ask_ct_05,bid_px_06,bid_sz_06,bid_ct_06,ask_px_06,ask_sz_06,ask_ct_06,bid_px_07,bid_sz_07,bid_ct_07,ask_px_07,ask_sz_07,ask_ct_07,bid_px_08,bid_sz_08,bid_ct_08,ask_px_08,ask_sz_08,ask_ct_08,bid_px_09,bid_sz_09,bid_ct_09,ask_px_09,ask_sz_09,ask_ct_09,symbol,order_id
1129,2025-07-17T15:44:21.855471158Z,2025-07-17T15:44:21.855305995Z,160,2,1108,A,A,4,14.03,100,130,165163,253590838,13.26,100,1,13.74,15,1,13.04,2,1,13.75,100,1,13.03,100,1,13.76,15,1,12.73,100,1,13.79,100,1,12.71,100,1,14.03,100,1,12.50,700,1,14.07,2,1,12.46,200,2,14.40,100,1,12.43,700,1,14.56,900,3,12.42,700,1,14.60,700,1,12.37,700,1,14.64,100,1,ARL,302466157
1130,2025-07-17T15:44:24.447075532Z,2025-07-17T15:44:24.446910206Z,160,2,1108,A,A,3,13.77,100,130,165326,253614407,13.26,100,1,13.74,15,1,13.04,2,1,13.75,100,1,13.03,100,1,13.76,15,1,12.73,100,1,13.77,100,1,12.71,100,1,13.79,100,1,12.50,700,1,14.03,100,1,12.46,200,2,14.07,2,1,12.43,700,1,14.40,100,1,12.42,700,1,14.56,900,3,12.37,700,1,14.60,700,1,ARL,302500469
1131,2025-07-17T15:44:24.465555818Z,2025-07-17T15:44:24.465390625Z,160,2,1108,C,A,4,13.79,100,130,165193,253614591,13.26,100,1,13.74,15,1,13.04,2,1,13.75,100,1,13.03,100,1,13.76,15,1,12.73,100,1,13.77,100,1,12.71,100,1,14.03,100,1,12.50,700,1,14.07,2,1,12.46,200,2,14.40,100,1,12.43,700,1,14.56,900,3,12.42,700,1,14.60,700,1,12.37,700,1,14.64,100,1,ARL,302205561
1132,2025-07-17T15:44:30.846822983Z,2025-07-17T15:44:30.846657613Z,160,2,1108,C,A,2,13.76,15,130,165370,253704439,13.26,100,1,13.74,15,1,13.04,2,1,13.75,100,1,13.03,100,1,13.77,100,1,12.73,100,1,14.03,100,1,12.71,100,1,14.07,2,1,12.50,700,1,14.40,100,1,12.46,200,2,14.56,900,3,12.43,700,1,14.60,700,1,12.42,700,1,14.64,100,1,12.37,700,1,14.66,200,2,ARL,302205249
1133,2025-07-17T15:44:31.849784693Z,2025-07-17T15:44:31.849618640Z,160,2,1108,A,A,0,13.72,15,130,166053,253721156,13.26,100,1,13.72,15,1,13.04,2,1,13.74,15,1,13.03,100,1,13.75,100,1,12.73,100,1,13.77,100,1,12.71,100,1,14.03,100,1,12.50,700,1,14.07,2,1,12.46,200,2,14.40,100,1,12.43,700,1,14.56,900,3,12.42,700,1,14.60,700,1,12.37,700,1,14.64,100,1,ARL,302649021
1134,2025-07-17T15:44:31.849921857Z,2025-07-17T15:44:31.849756452Z,160,2,1108,A,A,2,13.75,100,130,165405,253721157,13.26,100,1,13.72,15,1,13.04,2,1,13.74,15,1,13.03,100,1,13.75,200,2,12.73,100,1,13.77,100,1,12.71,100,1,14.03,100,1,12.50,700,1,14.07,2,1,12.46,200,2,14.40,100,1,12.43,700,1,14.56,900,3,12.42,700,1,14.60,700,1,12.37,700,1,14.64,100,1,ARL,302649029
1135,2025-07-17T15:44:31.910124978Z,2025-07-17T15:44:31.909959614Z,160,2,1108,C,A,3,13.77,100,130,165364,253722140,13.26,100,1,13.72,15,1,13.04,2,1,13.74,15,1,13.03,100,1,13.75,200,2,12.73,100,1,14.03,100,1,12.71,100,1,14.07,2,1,12.50,700,1,14.40,100,1,12.46,200,2,14.56,900,3,12.43,700,1,14.60,700,1,12.42,700,1,14.64,100,1,12.37,700,1,14.66,200,2,ARL,302500469
1136,2025-07-17T15:44:32.484497230Z,2025-07-17T15:44:32.484331764Z,160,2,1108,C,A,2,13.75,100,0,165466,253730877,13.26,100,1,13.72,15,1,13.04,2,1,13.74,15,1,13.03,100,1,13.75,100,1,12.73,100,1,14.03,100,1,12.71,100,1,14.07,2,1,12.50,700,1,14.40,100,1,12.46,200,2,14.56,900,3,12.43,700,1,14.60,700,1,12.42,700,1,14.64,100,1,12.37,700,1,14.66,200,2,ARL,302466045
1137,2025-07-17T15:44:32.484497230Z,2025-07-17T15:44:32.484331764Z,160,2,1108,A,A,1,13.73,100,130,165466,253730877,13.26,100,1,13.72,15,1,13.04,2,1,13.73,100,1,13.03,100,1,13.74,15,1,12.73,100,1,13.75,100,1,12.71,100,1,14.03,100,1,12.50,700,1,14.07,2,1,12.46,200,2,14.40,100,1,12.43,700,1,14.56,900,3,12.42,700,1,14.60,700,1,12.37,700,1,14.64,100,1,ARL,302662769
1138,2025-07-17T15:44:32.485238209Z,2025-07-17T15:44:32.485072552Z,160,2,1108,C,A,13,14.84,100,0,165657,253730907,13.26,100,1,13.72,15,1,13.04,2,1,13.73,100,1,13.03,100,1,13.74,15,1,12.73,100,1,13.75,100,1,12.71,100,1,14.03,100,1,12.50,700,1,14.07,2,1,12.46,200,2,14.40,100,1,12.43,700,1,14.56,900,3,12.42,700,1,14.60,700,1,12.37,700,1,14.64,100,1,ARL,302205537
1139,2025-07-17T15:44:32.485238209Z,2025-07-17T15:44:32.485072552Z,160,2,1108,A,A,12,14.79,100,130,165657,253730907,13.26,100,1,13.72,15,1,13.04,2,1,13.73,100,1,13.03,100,1,13.74,15,1,12.73,100,1,13.75,100,1,12.71,100,1,14.03,100,1,12.50,700,1,14.07,2,1,12.46,200,2,14.40,100,1,12.43,700,1,14.56,900,3,12.42,700,1,14.60,700,1,12.37,700,1,14.64,100,1,ARL,302662821
1140,2025-07-17T15:44:33.389387814Z,2025-07-17T15:44:33.389222513Z,160,2,1108,A,A,6,14.28,100,130,165301,253745665,13.26,100,1,13.72,15,1,13.04,2,1,13.73,100,1,13.03,100,1,13.74,15,1,12.73,100,1,13.75,100,1,12.71,100,1,14.03,100,1,12.50,700,1,14.07,2,1,12.46,200,2,14.28,100,1,12.43,700,1,14.40,100,1,12.42,700,1,14.56,900,3,12.37,700,1,14.60,700,1,ARL,302681357
1141,2025-07-17T15:44:33.389389030Z,2025-07-17T15:44:33.389223581Z,160,2,1108,C,A,8,14.56,100,130,165449,253745666,13.26,100,1,13.72,15,1,13.04,2,1,13.73,100,1,13.03,100,1,13.74,15,1,12.73,100,1,13.75,100,1,12.71,100,1,14.03,100,1,12.50,700,1,14.07,2,1,12.46,200,2,14.28,100,1,12.43,700,1,14.40,100,1,12.42,700,1,14.56,800,2,12.37,700,1,14.60,700,1,ARL,146960005
1142,2025-07-17T15:44:36.362187673Z,2025-07-17T15:44:36.362022168Z,160,2,1108,C,A,2,13.74,15,130,165505,253783635,13.26,100,1,13.72,15,1,13.04,2,1,13.73,100,1,13.03,100,1,13.75,100,1,12.73,100,1,14.03,100,1,12.71,100,1,14.07,2,1,12.50,700,1,14.28,100,1,12.46,200,2,14.40,100,1,12.43,700,1,14.56,800,2,12.42,700,1,14.60,700,1,12.37,700,1,14.64,100,1,ARL,302458113
1143,2025-07-17T15:44:37.364377419Z,2025-07-17T15:44:37.364212109Z,160,2,1108,A,A,0,13.70,15,130,165310,253797506,13.26,100,1,13.70,15,1,13.04,2,1,13.72,15,1,13.03,100,1,13.73,100,1,12.73,100,1,13.75,100,1,12.71,100,1,14.03,100,1,12.50,700,1,14.07,2,1,12.46,200,2,14.28,100,1,12.43,700,1,14.40,100,1,12.42,700,1,14.56,800,2,12.37,700,1,14.60,700,1,ARL,302750929
1144,2025-07-17T15:44:37.364519067Z,2025-07-17T15:44:37.364353897Z,160,2,1108,A,A,2,13.73,100,130,165170,253797510,13.26,100,1,13.70,15,1,13.04,2,1,13.72,15,1,13.03,100,1,13.73,200,2,12.73,100,1,13.75,100,1,12.71,100,1,14.03,100,1,12.50,700,1,14.07,2,1,12.46,200,2,14.28,100,1,12.43,700,1,14.40,100,1,12.42,700,1,14.56,800,2,12.37,700,1,14.60,700,1,ARL,302750937
1145,2025-07-17T15:44:37.458119494Z,2025-07-17T15:44:37.457954350Z,160,2,1108,C,A,3,13.75,100,130,165144,253798432,13.26,100,1,13.70,15,1,13.04,2,1,13.72,15,1,13.03,100,1,13.73,200,2,12.73,100,1,14.03,100,1,12.71,100,1,14.07,2,1,12.50,700,1,14.28,100,1,12.46,200,2,14.40,100,1,12.43,700,1,14.56,800,2,12.42,700,1,14.60,700,1,12.37,700,1,14.64,100,1,ARL,302649029
1146,2025-07-17T15:44:38.432460509Z,2025-07-17T15:44:38.432294362Z,160,2,1108,C,A,2,13.73,100,0,166147,253807786,13.26,100,1,13.70,15,1,13.04,2,1,13.72,15,1,13.03,100,1,13.73,100,1,12.73,100,1,14.03,100,1,12.71,100,1,14.07,2,1,12.50,700,1,14.28,100,1,12.46,200,2,14.40,100,1,12.43,700,1,14.56,800,2,12.42,700,1,14.60,700,1,12.37,700,1,14.64,100,1,ARL,302662769
1147,2025-07-17T15:44:38.432460509Z,2025-07-17T15:44:38.432294362Z,160,2,1108,A,A,1,13.71,100,130,166147,253807786,13.26,100,1,13.70,15,1,13.04,2,1,13.71,100,1,13.03,100,1,13.72,15,1,12.73,100,1,13.73,100,1,12.71,100,1,14.03,100,1,12.50,700,1,14.07,2,1,12.46,200,2,14.28,100,1,12.43,700,1,14.40,100,1,12.42,700,1,14.56,800,2,12.37,700,1,14.60,700,1,ARL,302763889
1148,2025-07-17T15:44:38.439253975Z,2025-07-17T15:44:38.439088042Z,160,2,1108,C,A,19,15.92,100,0,165933,253808105,13.26,100,1,13.70,15,1,13.04,2,1,13.71,100,1,13.03,100,1,13.72,15,1,12.73,100,1,13.73,100,1,12.71,100,1,14.03,100,1,12.50,700,1,14.07,2,1,12.46,200,2,14.28,100,1,12.43,700,1,14.40,100,1,12.42,700,1,14.56,800,2,12.37,700,1,14.60,700,1,ARL,301747301
1149,2025-07-17T15:44:38.439253975Z,2025-07-17T15:44:38.439088042Z,160,2,1108,A,A,18,15.77,100,130,165933,253808105,13.26,100,1,13.70,15,1,13.04,2,1,13.71,100,1,13.03,100,1,13.72,15,1,12.73,100,1,13.73,100,1,12.71,100,1,14.03,100,1,12.50,700,1,14.07,2,1,12.46,200,2,14.28,100,1,12.43,700,1,14.40,100,1,12.42,700,1,14.56,800,2,12.37,700,1,14.60,700,1,ARL,302764121
1150,2025-07-17T15:44:38.440321697Z,2025-07-17T15:44:38.440156077Z,160,2,1108,C,A,22,17.58,100,0,165620,253808122,13.26,100,1,13.70,15,1,13.04,2,1,13.71,100,1,13.03,100,1,13.72,15,1,12.73,100,1,13.73,100,1,12.71,100,1,14.03,100,1,12.50,700,1,14.07,2,1,12.46,200,2,14.28,100,1,12.43,700,1,14.40,100,1,12.42,700,1,14.56,800,2,12.37,700,1,14.60,700,1,ARL,301747261
1151,2025-07-17T15:44:38.440321697Z,2025-07-17T15:44:38.440156077Z,160,2,1108,A,A,22,17.42,100,130,165620,253808122,13.26,100,1,13.70,15,1,13.04,2,1,13.71,100,1,13.03,100,1,13.72,15,1,12.73,100,1,13.73,100,1,12.71,100,1,14.03,100,1,12.50,700,1,14.07,2,1,12.46,200,2,14.28,100,1,12.43,700,1,14.40,100,1,12.42,700,1,14.56,800,2,12.37,700,1,14.60,700,1,ARL,302764137
1152,2025-07-17T15:44:43.019262217Z,2025-07-17T15:44:43.019083502Z,160,2,1108,C,A,0,13.70,15,128,178715,253875920,13.26,100,1,13.71,100,1,13.04,2,1,13.72,15,1,13.03,100,1,13.73,100,1,12.73,100,1,14.03,100,1,12.71,100,1,14.07,2,1,12.50,700,1,14.28,100,1,12.46,200,2,14.40,100,1,12.43,700,1,14.56,800,2,12.42,700,1,14.60,700,1,12.37,700,1,14.64,100,1,ARL,302750929
1153,2025-07-17T15:44:43.019352658Z,2025-07-17T15:44:43.019184132Z,160,2,1108,C,A,1,13.72,15,128,168526,253876010,13.26,100,1,13.71,100,1,13.04,2,1,13.73,100,1,13.03,100,1,14.03,100,1,12.73,100,1,14.07,2,1,12.71,100,1,14.28,100,1,12.50,700,1,14.40,100,1,12.46,200,2,14.56,800,2,12.43,700,1,14.60,700,1,12.42,700,1,14.64,100,1,12.37,700,1,14.66,200,2,ARL,302649021
1154,2025-07-17T15:44:44.076009999Z,2025-07-17T15:44:44.075843113Z,160,2,1108,A,A,0,13.70,15,128,166886,253892869,13.26,100,1,13.70,15,1,13.04,2,1,13.71,100,1,13.03,100,1,13.73,100,1,12.73,100,1,14.03,100,1,12.71,100,1,14.07,2,1,12.50,700,1,14.28,100,1,12.46,200,2,14.40,100,1,12.43,700,1,14.56,800,2,12.42,700,1,14.60,700,1,12.37,700,1,14.64,100,1,ARL,302867209
1155,2025-07-17T15:44:44.781630732Z,2025-07-17T15:44:44.781464821Z,160,2,1108,C,A,0,13.70,15,130,165911,253901222,13.26,100,1,13.71,100,1,13.04,2,1,13.73,100,1,13.03,100,1,14.03,100,1,12.73,100,1,14.07,2,1,12.71,100,1,14.28,100,1,12.50,700,1,14.40,100,1,12.46,200,2,14.56,800,2,12.43,700,1,14.60,700,1,12.42,700,1,14.64,100,1,12.37,700,1,14.66,200,2,ARL,302867209
1156,2025-07-17T15:44:53.143249270Z,2025-07-17T15:44:53.143083969Z,160,2,1108,C,A,1,13.73,100,130,165301,254011871,13.26,100,1,13.71,100,1,13.04,2,1,14.03,100,1,13.03,100,1,14.07,2,1,12.73,100,1,14.28,100,1,12.71,100,1,14.40,100,1,12.50,700,1,14.56,800,2,12.46,200,2,14.60,700,1,12.43,700,1,14.64,100,1,12.42,700,1,14.66,200,2,12.37,700,1,14.68,1400,2,ARL,302750937
1157,2025-07-17T15:44:57.191188470Z,2025-07-17T15:44:57.191023026Z,160,2,1108,A,A,1,13.75,100,130,165444,254079162,13.26,100,1,13.71,100,1,13.04,2,1,13.75,100,1,13.03,100,1,14.03,100,1,12.73,100,1,14.07,2,1,12.71,100,1,14.28,100,1,12.50,700,1,14.40,100,1,12.46,200,2,14.56,800,2,12.43,700,1,14.60,700,1,12.42,700,1,14.64,100,1,12.37,700,1,14.66,200,2,ARL,303118785
1158,2025-07-17T15:45:07.065756574Z,2025-07-17T15:45:07.065587919Z,160,2,1108,C,A,0,13.71,100,128,168655,254244597,13.26,100,1,13.75,100,1,13.04,2,1,14.03,100,1,13.03,100,1,14.07,2,1,12.73,100,1,14.28,100,1,12.71,100,1,14.40,100,1,12.50,700,1,14.56,800,2,12.46,200,2,14.60,700,1,12.43,700,1,14.64,100,1,12.42,700,1,14.66,200,2,12.37,700,1,14.68,1400,2,ARL,302763889
1159,2025-07-17T15:45:07.080131505Z,2025-07-17T15:45:07.079966224Z,160,2,1108,C,A,0,13.75,100,130,165281,254245492,13.26,100,1,14.03,100,1,13.04,2,1,14.07,2,1,13.03,100,1,14.28,100,1,12.73,100,1,14.40,100,1,12.71,100,1,14.56,800,2,12.50,700,1,14.60,700,1,12.46,200,2,14.64,100,1,12.43,700,1,14.66,200,2,12.42,700,1,14.68,1400,2,12.37,700,1,14.79,100,1,ARL,303118785
1160,2025-07-17T15:45:07.080687215Z,2025-07-17T15:45:07.080521807Z,160,2,1108,C,A,7,14.66,100,0,165408,254245505,13.26,100,1,14.03,100,1,13.04,2,1,14.07,2,1,13.03,100,1,14.28,100,1,12.73,100,1,14.40,100,1,12.71,100,1,14.56,800,2,12.50,700,1,14.60,700,1,12.46,200,2,14.64,100,1,12.43,700,1,14.66,100,1,12.42,700,1,14.68,1400,2,12.37,700,1,14.79,100,1,ARL,302205289
1161,2025-07-17T15:45:07.080687215Z,2025-07-17T15:45:07.080521807Z,160,2,1108,A,A,11,14.89,100,130,165408,254245505,13.26,100,1,14.03,100,1,13.04,2,1,14.07,2,1,13.03,100,1,14.28,100,1,12.73,100,1,14.40,100,1,12.71,100,1,14.56,800,2,12.50,700,1,14.60,700,1,12.46,200,2,14.64,100,1,12.43,700,1,14.66,100,1,12.42,700,1,14.68,1400,2,12.37,700,1,14.79,100,1,ARL,303330477
1162,2025-07-17T15:45:07.080872245Z,2025-07-17T15:45:07.080706110Z,160,2,1108,C,A,9,14.79,100,0,166135,254245511,13.26,100,1,14.03,100,1,13.04,2,1,14.07,2,1,13.03,100,1,14.28,100,1,12.73,100,1,14.40,100,1,12.71,100,1,14.56,800,2,12.50,700,1,14.60,700,1,12.46,200,2,14.64,100,1,12.43,700,1,14.66,100,1,12.42,700,1,14.68,1400,2,12.37,700,1,14.81,200,2,ARL,302662821
1163,2025-07-17T15:45:07.080872245Z,2025-07-17T15:45:07.080706110Z,160,2,1108,A,A,11,15.06,100,130,166135,254245511,13.26,100,1,14.03,100,1,13.04,2,1,14.07,2,1,13.03,100,1,14.28,100,1,12.73,100,1,14.40,100,1,12.71,100,1,14.56,800,2,12.50,700,1,14.60,700,1,12.46,200,2,14.64,100,1,12.43,700,1,14.66,100,1,12.42,700,1,14.68,1400,2,12.37,700,1,14.81,200,2,ARL,303330485
1164,2025-07-17T15:45:07.081578064Z,2025-07-17T15:45:07.081407507Z,160,2,1108,C,A,9,14.81,100,0,170557,254245568,13.26,100,1,14.03,100,1,13.04,2,1,14.07,2,1,13.03,100,1,14.28,100,1,12.73,100,1,14.40,100,1,12.71,100,1,14.56,800,2,12.50,700,1,14.60,700,1,12.46,200,2,14.64,100,1,12.43,700,1,14.66,100,1,12.42,700,1,14.68,1400,2,12.37,700,1,14.81,100,1,ARL,301747001
1165,2025-07-17T15:45:07.081578064Z,2025-07-17T15:45:07.081407507Z,160,2,1108,A,A,11,14.96,100,128,170557,254245568,13.26,100,1,14.03,100,1,13.04,2,1,14.07,2,1,13.03,100,1,14.28,100,1,12.73,100,1,14.40,100,1,12.71,100,1,14.56,800,2,12.50,700,1,14.60,700,1,12.46,200,2,14.64,100,1,12.43,700,1,14.66,100,1,12.42,700,1,14.68,1400,2,12.37,700,1,14.81,100,1,ARL,303330509
1166,2025-07-17T15:45:07.081607970Z,2025-07-17T15:45:07.081441134Z,160,2,1108,C,A,7,14.66,100,0,166836,254245576,13.26,100,1,14.03,100,1,13.04,2,1,14.07,2,1,13.03,100,1,14.28,100,1,12.73,100,1,14.40,100,1,12.71,100,1,14.56,800,2,12.50,700,1,14.60,700,1,12.46,200,2,14.64,100,1,12.43,700,1,14.68,1400,2,12.42,700,1,14.81,100,1,12.37,700,1,14.89,100,1,ARL,302205309
1167,2025-07-17T15:45:07.081607970Z,2025-07-17T15:45:07.081441134Z,160,2,1108,A,A,9,14.89,100,130,166836,254245576,13.26,100,1,14.03,100,1,13.04,2,1,14.07,2,1,13.03,100,1,14.28,100,1,12.73,100,1,14.40,100,1,12.71,100,1,14.56,800,2,12.50,700,1,14.60,700,1,12.46,200,2,14.64,100,1,12.43,700,1,14.68,1400,2,12.42,700,1,14.81,100,1,12.37,700,1,14.89,200,2,ARL,303330521
1168,2025-07-17T15:45:07.083898999Z,2025-07-17T15:45:07.083732443Z,160,2,1108,C,A,19,17.42,100,0,166556,254246327,13.26,100,1,14.03,100,1,13.04,2,1,14.07,2,1,13.03,100,1,14.28,100,1,12.73,100,1,14.40,100,1,12.71,100,1,14.56,800,2,12.50,700,1,14.60,700,1,12.46,200,2,14.64,100,1,12.43,700,1,14.68,1400,2,12.42,700,1,14.81,100,1,12.37,700,1,14.89,200,2,ARL,302764137
1169,2025-07-17T15:45:07.083898999Z,2025-07-17T15:45:07.083732443Z,160,2,1108,A,A,19,17.76,100,130,166556,254246327,13.26,100,1,14.03,100,1,13.04,2,1,14.07,2,1,13.03,100,1,14.28,100,1,12.73,100,1,14.40,100,1,12.71,100,1,14.56,800,2,12.50,700,1,14.60,700,1,12.46,200,2,14.64,100,1,12.43,700,1,14.68,1400,2,12.42,700,1,14.81,100,1,12.37,700,1,14.89,200,2,ARL,303331309
1170,2025-07-17T15:45:07.085222525Z,2025-07-17T15:45:07.085057258Z,160,2,1108,C,A,0,14.03,100,130,165267,254246434,13.26,100,1,14.07,2,1,13.04,2,1,14.28,100,1,13.03,100,1,14.40,100,1,12.73,100,1,14.56,800,2,12.71,100,1,14.60,700,1,12.50,700,1,14.64,100,1,12.46,200,2,14.68,1400,2,12.43,700,1,14.81,100,1,12.42,700,1,14.89,200,2,12.37,700,1,14.96,100,1,ARL,302466157
1171,2025-07-17T15:45:07.085274852Z,2025-07-17T15:45:07.085109545Z,160,2,1108,A,A,1,14.26,100,130,165307,254246437,13.26,100,1,14.07,2,1,13.04,2,1,14.26,100,1,13.03,100,1,14.28,100,1,12.73,100,1,14.40,100,1,12.71,100,1,14.56,800,2,12.50,700,1,14.60,700,1,12.46,200,2,14.64,100,1,12.43,700,1,14.68,1400,2,12.42,700,1,14.81,100,1,12.37,700,1,14.89,200,2,ARL,303331401
1172,2025-07-17T15:45:07.086534700Z,2025-07-17T15:45:07.086368957Z,160,2,1108,C,A,6,14.64,100,130,165743,254246501,13.26,100,1,14.07,2,1,13.04,2,1,14.26,100,1,13.03,100,1,14.28,100,1,12.73,100,1,14.40,100,1,12.71,100,1,14.56,800,2,12.50,700,1,14.60,700,1,12.46,200,2,14.68,1400,2,12.43,700,1,14.81,100,1,12.42,700,1,14.89,200,2,12.37,700,1,14.96,100,1,ARL,301747005
1173,2025-07-17T15:45:07.086660325Z,2025-07-17T15:45:07.086494745Z,160,2,1108,A,A,7,14.78,100,130,165580,254246502,13.26,100,1,14.07,2,1,13.04,2,1,14.26,100,1,13.03,100,1,14.28,100,1,12.73,100,1,14.40,100,1,12.71,100,1,14.56,800,2,12.50,700,1,14.60,700,1,12.46,200,2,14.68,1400,2,12.43,700,1,14.78,100,1,12.42,700,1,14.81,100,1,12.37,700,1,14.89,200,2,ARL,303331425
1174,2025-07-17T15:45:07.087389466Z,2025-07-17T15:45:07.087223859Z,160,2,1108,C,A,15,15.77,100,0,165607,254246529,13.26,100,1,14.07,2,1,13.04,2,1,14.26,100,1,13.03,100,1,14.28,100,1,12.73,100,1,14.40,100,1,12.71,100,1,14.56,800,2,12.50,700,1,14.60,700,1,12.46,200,2,14.68,1400,2,12.43,700,1,14.78,100,1,12.42,700,1,14.81,100,1,12.37,700,1,14.89,200,2,ARL,302764121
1175,2025-07-17T15:45:07.087389466Z,2025-07-17T15:45:07.087223859Z,160,2,1108,A,A,16,16.08,100,130,165607,254246529,13.26,100,1,14.07,2,1,13.04,2,1,14.26,100,1,13.03,100,1,14.28,100,1,12.73,100,1,14.40,100,1,12.71,100,1,14.56,800,2,12.50,700,1,14.60,700,1,12.46,200,2,14.68,1400,2,12.43,700,1,14.78,100,1,12.42,700,1,14.81,100,1,12.37,700,1,14.89,200,2,ARL,303331429
1176,2025-07-17T15:45:07.133978488Z,2025-07-17T15:45:07.133812895Z,160,2,1108,C,A,8,14.81,100,0,165593,254250625,13.26,100,1,14.07,2,1,13.04,2,1,14.26,100,1,13.03,100,1,14.28,100,1,12.73,100,1,14.40,100,1,12.71,100,1,14.56,800,2,12.50,700,1,14.60,700,1,12.46,200,2,14.68,1400,2,12.43,700,1,14.78,100,1,12.42,700,1,14.89,200,2,12.37,700,1,14.96,100,1,ARL,301747957
1177,2025-07-17T15:45:07.133978488Z,2025-07-17T15:45:07.133812895Z,160,2,1108,A,A,9,14.96,100,130,165593,254250625,13.26,100,1,14.07,2,1,13.04,2,1,14.26,100,1,13.03,100,1,14.28,100,1,12.73,100,1,14.40,100,1,12.71,100,1,14.56,800,2,12.50,700,1,14.60,700,1,12.46,200,2,14.68,1400,2,12.43,700,1,14.78,100,1,12.42,700,1,14.89,200,2,12.37,700,1,14.96,200,2,ARL,303334253
1178,2025-07-17T15:45:07.469961302Z,2025-07-17T15:45:07.469796155Z,160,2,1108,A,A,1,14.08,100,130,165147,254258029,13.26,100,1,14.07,2,1,13.04,2,1,14.08,100,1,13.03,100,1,14.26,100,1,12.73,100,1,14.28,100,1,12.71,100,1,14.40,100,1,12.50,700,1,14.56,800,2,12.46,200,2,14.60,700,1,12.43,700,1,14.68,1400,2,12.42,700,1,14.78,100,1,12.37,700,1,14.89,200,2,ARL,303340405
1179,2025-07-17T15:45:08.094768552Z,2025-07-17T15:45:08.094603115Z,160,2,1108,C,A,9,14.89,100,0,165437,254266885,13.26,100,1,14.07,2,1,13.04,2,1,14.08,100,1,13.03,100,1,14.26,100,1,12.73,100,1,14.28,100,1,12.71,100,1,14.40,100,1,12.50,700,1,14.56,800,2,12.46,200,2,14.60,700,1,12.43,700,1,14.68,1400,2,12.42,700,1,14.78,100,1,12.37,700,1,14.89,100,1,ARL,303330521
1180,2025-07-17T15:45:08.094768552Z,2025-07-17T15:45:08.094603115Z,160,2,1108,A,A,12,15.10,100,130,165437,254266885,13.26,100,1,14.07,2,1,13.04,2,1,14.08,100,1,13.03,100,1,14.26,100,1,12.73,100,1,14.28,100,1,12.71,100,1,14.40,100,1,12.50,700,1,14.56,800,2,12.46,200,2,14.60,700,1,12.43,700,1,14.68,1400,2,12.42,700,1,14.78,100,1,12.37,700,1,14.89,100,1,ARL,303349309
1181,2025-07-17T15:45:08.103306644Z,2025-07-17T15:45:08.103141155Z,160,2,1108,C,A,9,14.89,100,0,165489,254266971,13.26,100,1,14.07,2,1,13.04,2,1,14.08,100,1,13.03,100,1,14.26,100,1,12.73,100,1,14.28,100,1,12.71,100,1,14.40,100,1,12.50,700,1,14.56,800,2,12.46,200,2,14.60,700,1,12.43,700,1,14.68,1400,2,12.42,700,1,14.78,100,1,12.37,700,1,14.96,200,2,ARL,303330477
1182,2025-07-17T15:45:08.103306644Z,2025-07-17T15:45:08.103141155Z,160,2,1108,A,A,11,15.10,100,130,165489,254266971,13.26,100,1,14.07,2,1,13.04,2,1,14.08,100,1,13.03,100,1,14.26,100,1,12.73,100,1,14.28,100,1,12.71,100,1,14.40,100,1,12.50,700,1,14.56,800,2,12.46,200,2,14.60,700,1,12.43,700,1,14.68,1400,2,12.42,700,1,14.78,100,1,12.37,700,1,14.96,200,2,ARL,303349377
1183,2025-07-17T15:45:24.187008278Z,2025-07-17T15:45:24.186842413Z,160,2,1108,C,A,11,15.10,100,0,165865,254547413,13.26,100,1,14.07,2,1,13.04,2,1,14.08,100,1,13.03,100,1,14.26,100,1,12.73,100,1,14.28,100,1,12.71,100,1,14.40,100,1,12.50,700,1,14.56,800,2,12.46,200,2,14.60,700,1,12.43,700,1,14.68,1400,2,12.42,700,1,14.78,100,1,12.37,700,1,14.96,200,2,ARL,303349309
1184,2025-07-17T15:45:24.187008278Z,2025-07-17T15:45:24.186842413Z,160,2,1108,A,A,9,14.88,100,130,165865,254547413,13.26,100,1,14.07,2,1,13.04,2,1,14.08,100,1,13.03,100,1,14.26,100,1,12.73,100,1,14.28,100,1,12.71,100,1,14.40,100,1,12.50,700,1,14.56,800,2,12.46,200,2,14.60,700,1,12.43,700,1,14.68,1400,2,12.42,700,1,14.78,100,1,12.37,700,1,14.88,100,1,ARL,303682385
1185,2025-07-17T15:45:24.187441892Z,2025-07-17T15:45:24.187276389Z,160,2,1108,C,A,12,15.10,100,0,165503,254547415,13.26,100,1,14.07,2,1,13.04,2,1,14.08,100,1,13.03,100,1,14.26,100,1,12.73,100,1,14.28,100,1,12.71,100,1,14.40,100,1,12.50,700,1,14.56,800,2,12.46,200,2,14.60,700,1,12.43,700,1,14.68,1400,2,12.42,700,1,14.78,100,1,12.37,700,1,14.88,100,1,ARL,303349377
1186,2025-07-17T15:45:24.187441892Z,2025-07-17T15:45:24.187276389Z,160,2,1108,A,A,9,14.88,100,130,165503,254547415,13.26,100,1,14.07,2,1,13.04,2,1,14.08,100,1,13.03,100,1,14.26,100,1,12.73,100,1,14.28,100,1,12.71,100,1,14.40,100,1,12.50,700,1,14.56,800,2,12.46,200,2,14.60,700,1,12.43,700,1,14.68,1400,2,12.42,700,1,14.78,100,1,12.37,700,1,14.88,200,2,ARL,303682389
1187,2025-07-17T15:45:37.509454888Z,2025-07-17T15:45:37.509289536Z,160,2,1108,A,A,0,13.94,15,130,165352,254851462,13.26,100,1,13.94,15,1,13.04,2,1,14.07,2,1,13.03,100,1,14.08,100,1,12.73,100,1,14.26,100,1,12.71,100,1,14.28,100,1,12.50,700,1,14.40,100,1,12.46,200,2,14.56,800,2,12.43,700,1,14.60,700,1,12.42,700,1,14.68,1400,2,12.37,700,1,14.78,100,1,ARL,304056997
1188,2025-07-17T15:45:37.998133497Z,2025-07-17T15:45:37.997967775Z,160,2,1108,C,A,2,14.08,100,0,165722,254864588,13.26,100,1,13.94,15,1,13.04,2,1,14.07,2,1,13.03,100,1,14.26,100,1,12.73,100,1,14.28,100,1,12.71,100,1,14.40,100,1,12.50,700,1,14.56,800,2,12.46,200,2,14.60,700,1,12.43,700,1,14.68,1400,2,12.42,700,1,14.78,100,1,12.37,700,1,14.88,200,2,ARL,303340405
1189,2025-07-17T15:45:37.998133497Z,2025-07-17T15:45:37.997967775Z,160,2,1108,A,A,1,13.95,100,130,165722,254864588,13.26,100,1,13.94,15,1,13.04,2,1,13.95,100,1,13.03,100,1,14.07,2,1,12.73,100,1,14.26,100,1,12.71,100,1,14.28,100,1,12.50,700,1,14.40,100,1,12.46,200,2,14.56,800,2,12.43,700,1,14.60,700,1,12.42,700,1,14.68,1400,2,12.37,700,1,14.78,100,1,ARL,304072245
1190,2025-07-17T15:45:44.700593408Z,2025-07-17T15:45:44.700428155Z,160,2,1108,A,A,0,13.89,15,130,165253,254999429,13.26,100,1,13.89,15,1,13.04,2,1,13.94,15,1,13.03,100,1,13.95,100,1,12.73,100,1,14.07,2,1,12.71,100,1,14.26,100,1,12.50,700,1,14.28,100,1,12.46,200,2,14.40,100,1,12.43,700,1,14.56,800,2,12.42,700,1,14.60,700,1,12.37,700,1,14.68,1400,2,ARL,304238913
1191,2025-07-17T15:45:45.262537122Z,2025-07-17T15:45:45.262371701Z,160,2,1108,C,A,2,13.95,100,0,165421,255010979,13.26,100,1,13.89,15,1,13.04,2,1,13.94,15,1,13.03,100,1,14.07,2,1,12.73,100,1,14.26,100,1,12.71,100,1,14.28,100,1,12.50,700,1,14.40,100,1,12.46,200,2,14.56,800,2,12.43,700,1,14.60,700,1,12.42,700,1,14.68,1400,2,12.37,700,1,14.78,100,1,ARL,304072245
1192,2025-07-17T15:45:45.262537122Z,2025-07-17T15:45:45.262371701Z,160,2,1108,A,A,1,13.90,100,130,165421,255010979,13.26,100,1,13.89,15,1,13.04,2,1,13.90,100,1,13.03,100,1,13.94,15,1,12.73,100,1,14.07,2,1,12.71,100,1,14.26,100,1,12.50,700,1,14.28,100,1,12.46,200,2,14.40,100,1,12.43,700,1,14.56,800,2,12.42,700,1,14.60,700,1,12.37,700,1,14.68,1400,2,ARL,304252313
1193,2025-07-17T15:45:45.263289023Z,2025-07-17T15:45:45.263123432Z,160,2,1108,C,A,13,15.06,100,0,165591,255010987,13.26,100,1,13.89,15,1,13.04,2,1,13.90,100,1,13.03,100,1,13.94,15,1,12.73,100,1,14.07,2,1,12.71,100,1,14.26,100,1,12.50,700,1,14.28,100,1,12.46,200,2,14.40,100,1,12.43,700,1,14.56,800,2,12.42,700,1,14.60,700,1,12.37,700,1,14.68,1400,2,ARL,303330485
1194,2025-07-17T15:45:45.263289023Z,2025-07-17T15:45:45.263123432Z,160,2,1108,A,A,13,14.98,100,130,165591,255010987,13.26,100,1,13.89,15,1,13.04,2,1,13.90,100,1,13.03,100,1,13.94,15,1,12.73,100,1,14.07,2,1,12.71,100,1,14.26,100,1,12.50,700,1,14.28,100,1,12.46,200,2,14.40,100,1,12.43,700,1,14.56,800,2,12.42,700,1,14.60,700,1,12.37,700,1,14.68,1400,2,ARL,304252333
1195,2025-07-17T15:45:45.274360382Z,2025-07-17T15:45:45.274194870Z,160,2,1108,C,A,4,14.26,100,130,165512,255011158,13.26,100,1,13.89,15,1,13.04,2,1,13.90,100,1,13.03,100,1,13.94,15,1,12.73,100,1,14.07,2,1,12.71,100,1,14.28,100,1,12.50,700,1,14.40,100,1,12.46,200,2,14.56,800,2,12.43,700,1,14.60,700,1,12.42,700,1,14.68,1400,2,12.37,700,1,14.78,100,1,ARL,303331401
1196,2025-07-17T15:45:45.274410721Z,2025-07-17T15:45:45.274245387Z,160,2,1108,A,A,4,14.18,100,130,165334,255011161,13.26,100,1,13.89,15,1,13.04,2,1,13.90,100,1,13.03,100,1,13.94,15,1,12.73,100,1,14.07,2,1,12.71,100,1,14.18,100,1,12.50,700,1,14.28,100,1,12.46,200,2,14.40,100,1,12.43,700,1,14.56,800,2,12.42,700,1,14.60,700,1,12.37,700,1,14.68,1400,2,ARL,304252469
1197,2025-07-17T15:45:58.419783333Z,2025-07-17T15:45:58.419617935Z,160,2,1108,C,A,2,13.94,15,130,165398,255183198,13.26,100,1,13.89,15,1,13.04,2,1,13.90,100,1,13.03,100,1,14.07,2,1,12.73,100,1,14.18,100,1,12.71,100,1,14.28,100,1,12.50,700,1,14.40,100,1,12.46,200,2,14.56,800,2,12.43,700,1,14.60,700,1,12.42,700,1,14.68,1400,2,12.37,700,1,14.78,100,1,ARL,304056997
1198,2025-07-17T15:45:58.420278691Z,2025-07-17T15:45:58.420113307Z,160,2,1108,C,A,10,14.88,100,0,165384,255183203,13.26,100,1,13.89,15,1,13.04,2,1,13.90,100,1,13.03,100,1,14.07,2,1,12.73,100,1,14.18,100,1,12.71,100,1,14.28,100,1,12.50,700,1,14.40,100,1,12.46,200,2,14.56,800,2,12.43,700,1,14.60,700,1,12.42,700,1,14.68,1400,2,12.37,700,1,14.78,100,1,ARL,303682389
1199,2025-07-17T15:45:58.420278691Z,2025-07-17T15:45:58.420113307Z,160,2,1108,A,A,9,14.77,100,130,165384,255183203,13.26,100,1,13.89,15,1,13.04,2,1,13.90,100,1,13.03,100,1,14.07,2,1,12.73,100,1,14.18,100,1,12.71,100,1,14.28,100,1,12.50,700,1,14.40,100,1,12.46,200,2,14.56,800,2,12.43,700,1,14.60,700,1,12.42,700,1,14.68,1400,2,12.37,700,1,14.77,100,1,ARL,304503585
1200,2025-07-17T15:45:58.420755889Z,2025-07-17T15:45:58.420590199Z,160,2,1108,C,A,11,14.88,100,0,165690,255183204,13.26,100,1,13.89,15,1,13.04,2,1,13.90,100,1,13.03,100,1,14.07,2,1,12.73,100,1,14.18,100,1,12.71,100,1,14.28,100,1,12.50,700,1,14.40,100,1,12.46,200,2,14.56,800,2,12.43,700,1,14.60,700,1,12.42,700,1,14.68,1400,2,12.37,700,1,14.77,100,1,ARL,303682385
1201,2025-07-17T15:45:58.420755889Z,2025-07-17T15:45:58.420590199Z,160,2,1108,A,A,9,14.77,100,130,165690,255183204,13.26,100,1,13.89,15,1,13.04,2,1,13.90,100,1,13.03,100,1,14.07,2,1,12.73,100,1,14.18,100,1,12.71,100,1,14.28,100,1,12.50,700,1,14.40,100,1,12.46,200,2,14.56,800,2,12.43,700,1,14.60,700,1,12.42,700,1,14.68,1400,2,12.37,700,1,14.77,200,2,ARL,304503593
1202,2025-07-17T15:45:58.782892109Z,2025-07-17T15:45:58.782726994Z,160,2,1108,C,A,0,13.89,15,130,165115,255189425,13.26,100,1,13.90,100,1,13.04,2,1,14.07,2,1,13.03,100,1,14.18,100,1,12.73,100,1,14.28,100,1,12.71,100,1,14.40,100,1,12.50,700,1,14.56,800,2,12.46,200,2,14.60,700,1,12.43,700,1,14.68,1400,2,12.42,700,1,14.77,200,2,12.37,700,1,14.78,100,1,ARL,304238913
1203,2025-07-17T15:46:16.783057616Z,2025-07-17T15:46:16.782892334Z,160,2,1108,A,A,0,13.88,15,130,165282,255552962,13.26,100,1,13.88,15,1,13.04,2,1,13.90,100,1,13.03,100,1,14.07,2,1,12.73,100,1,14.18,100,1,12.71,100,1,14.28,100,1,12.50,700,1,14.40,100,1,12.46,200,2,14.56,800,2,12.43,700,1,14.60,700,1,12.42,700,1,14.68,1400,2,12.37,700,1,14.77,200,2,ARL,304949689
1204,2025-07-17T15:46:16.783326241Z,2025-07-17T15:46:16.783160795Z,160,2,1108,C,A,1,13.90,100,0,165446,255552970,13.26,100,1,13.88,15,1,13.04,2,1,14.07,2,1,13.03,100,1,14.18,100,1,12.73,100,1,14.28,100,1,12.71,100,1,14.40,100,1,12.50,700,1,14.56,800,2,12.46,200,2,14.60,700,1,12.43,700,1,14.68,1400,2,12.42,700,1,14.77,200,2,12.37,700,1,14.78,100,1,ARL,304252313
1205,2025-07-17T15:46:16.783326241Z,2025-07-17T15:46:16.783160795Z,160,2,1108,A,A,1,13.89,100,130,165446,255552970,13.26,100,1,13.88,15,1,13.04,2,1,13.89,100,1,13.03,100,1,14.07,2,1,12.73,100,1,14.18,100,1,12.71,100,1,14.28,100,1,12.50,700,1,14.40,100,1,12.46,200,2,14.56,800,2,12.43,700,1,14.60,700,1,12.42,700,1,14.68,1400,2,12.37,700,1,14.77,200,2,ARL,304949697
1206,2025-07-17T15:46:18.782897570Z,2025-07-17T15:46:18.782732218Z,160,2,1108,C,A,0,13.88,15,130,165352,255587336,13.26,100,1,13.89,100,1,13.04,2,1,14.07,2,1,13.03,100,1,14.18,100,1,12.73,100,1,14.28,100,1,12.71,100,1,14.40,100,1,12.50,700,1,14.56,800,2,12.46,200,2,14.60,700,1,12.43,700,1,14.68,1400,2,12.42,700,1,14.77,200,2,12.37,700,1,14.78,100,1,ARL,304949689
1207,2025-07-17T15:46:28.474166897Z,2025-07-17T15:46:28.474001551Z,160,2,1108,C,A,0,13.89,100,130,165346,255746167,13.26,100,1,14.07,2,1,13.04,2,1,14.18,100,1,13.03,100,1,14.28,100,1,12.73,100,1,14.40,100,1,12.71,100,1,14.56,800,2,12.50,700,1,14.60,700,1,12.46,200,2,14.68,1400,2,12.43,700,1,14.77,200,2,12.42,700,1,14.78,100,1,12.37,700,1,14.96,200,2,ARL,304949697
1208,2025-07-17T15:46:28.474726594Z,2025-07-17T15:46:28.474561156Z,160,2,1108,C,A,7,14.77,100,0,165438,255746173,13.26,100,1,14.07,2,1,13.04,2,1,14.18,100,1,13.03,100,1,14.28,100,1,12.73,100,1,14.40,100,1,12.71,100,1,14.56,800,2,12.50,700,1,14.60,700,1,12.46,200,2,14.68,1400,2,12.43,700,1,14.77,100,1,12.42,700,1,14.78,100,1,12.37,700,1,14.96,200,2,ARL,304503593
1209,2025-07-17T15:46:28.474726594Z,2025-07-17T15:46:28.474561156Z,160,2,1108,A,A,9,14.88,100,130,165438,255746173,13.26,100,1,14.07,2,1,13.04,2,1,14.18,100,1,13.03,100,1,14.28,100,1,12.73,100,1,14.40,100,1,12.71,100,1,14.56,800,2,12.50,700,1,14.60,700,1,12.46,200,2,14.68,1400,2,12.43,700,1,14.77,100,1,12.42,700,1,14.78,100,1,12.37,700,1,14.88,100,1,ARL,305184937
1210,2025-07-17T15:46:28.474896460Z,2025-07-17T15:46:28.474730225Z,160,2,1108,C,A,7,14.77,100,0,166235,255746176,13.26,100,1,14.07,2,1,13.04,2,1,14.18,100,1,13.03,100,1,14.28,100,1,12.73,100,1,14.40,100,1,12.71,100,1,14.56,800,2,12.50,700,1,14.60,700,1,12.46,200,2,14.68,1400,2,12.43,700,1,14.78,100,1,12.42,700,1,14.88,100,1,12.37,700,1,14.96,200,2,ARL,304503585
1211,2025-07-17T15:46:28.474896460Z,2025-07-17T15:46:28.474730225Z,160,2,1108,A,A,8,14.88,100,130,166235,255746176,13.26,100,1,14.07,2,1,13.04,2,1,14.18,100,1,13.03,100,1,14.28,100,1,12.73,100,1,14.40,100,1,12.71,100,1,14.56,800,2,12.50,700,1,14.60,700,1,12.46,200,2,14.68,1400,2,12.43,700,1,14.78,100,1,12.42,700,1,14.88,200,2,12.37,700,1,14.96,200,2,ARL,305184953
1212,2025-07-17T15:46:28.474902154Z,2025-07-17T15:46:28.474736101Z,160,2,1108,C,A,10,14.98,100,0,166053,255746178,13.26,100,1,14.07,2,1,13.04,2,1,14.18,100,1,13.03,100,1,14.28,100,1,12.73,100,1,14.40,100,1,12.71,100,1,14.56,800,2,12.50,700,1,14.60,700,1,12.46,200,2,14.68,1400,2,12.43,700,1,14.78,100,1,12.42,700,1,14.88,200,2,12.37,700,1,14.96,200,2,ARL,304252333
1213,2025-07-17T15:46:28.474902154Z,2025-07-17T15:46:28.474736101Z,160,2,1108,A,A,10,15.03,100,128,166053,255746178,13.26,100,1,14.07,2,1,13.04,2,1,14.18,100,1,13.03,100,1,14.28,100,1,12.73,100,1,14.40,100,1,12.71,100,1,14.56,800,2,12.50,700,1,14.60,700,1,12.46,200,2,14.68,1400,2,12.43,700,1,14.78,100,1,12.42,700,1,14.88,200,2,12.37,700,1,14.96,200,2,ARL,305184957
1214,2025-07-17T15:46:28.492881980Z,2025-07-17T15:46:28.492716775Z,160,2,1108,C,A,1,14.18,100,130,165205,255746619,13.26,100,1,14.07,2,1,13.04,2,1,14.28,100,1,13.03,100,1,14.40,100,1,12.73,100,1,14.56,800,2,12.71,100,1,14.60,700,1,12.50,700,1,14.68,1400,2,12.46,200,2,14.78,100,1,12.43,700,1,14.88,200,2,12.42,700,1,14.96,200,2,12.37,700,1,15.03,100,1,ARL,304252469
1215,2025-07-17T15:46:28.492931279Z,2025-07-17T15:46:28.492765859Z,160,2,1108,A,A,1,14.26,100,130,165420,255746621,13.26,100,1,14.07,2,1,13.04,2,1,14.26,100,1,13.03,100,1,14.28,100,1,12.73,100,1,14.40,100,1,12.71,100,1,14.56,800,2,12.50,700,1,14.60,700,1,12.46,200,2,14.68,1400,2,12.43,700,1,14.78,100,1,12.42,700,1,14.88,200,2,12.37,700,1,14.96,200,2,ARL,305185529
1216,2025-07-17T15:46:28.646273467Z,2025-07-17T15:46:28.646108242Z,160,2,1108,A,A,1,14.08,100,130,165225,255748568,13.26,100,1,14.07,2,1,13.04,2,1,14.08,100,1,13.03,100,1,14.26,100,1,12.73,100,1,14.28,100,1,12.71,100,1,14.40,100,1,12.50,700,1,14.56,800,2,12.46,200,2,14.60,700,1,12.43,700,1,14.68,1400,2,12.42,700,1,14.78,100,1,12.37,700,1,14.88,200,2,ARL,305187077
1217,2025-07-17T15:46:57.524024658Z,2025-07-17T15:46:57.523859388Z,160,2,1108,A,A,0,13.92,15,130,165270,256268482,13.26,100,1,13.92,15,1,13.04,2,1,14.07,2,1,13.03,100,1,14.08,100,1,12.73,100,1,14.26,100,1,12.71,100,1,14.28,100,1,12.50,700,1,14.40,100,1,12.46,200,2,14.56,800,2,12.43,700,1,14.60,700,1,12.42,700,1,14.68,1400,2,12.37,700,1,14.78,100,1,ARL,305862145
1218,2025-07-17T15:46:57.932842994Z,2025-07-17T15:46:57.932677299Z,160,2,1108,C,A,2,14.08,100,0,165695,256280751,13.26,100,1,13.92,15,1,13.04,2,1,14.07,2,1,13.03,100,1,14.26,100,1,12.73,100,1,14.28,100,1,12.71,100,1,14.40,100,1,12.50,700,1,14.56,800,2,12.46,200,2,14.60,700,1,12.43,700,1,14.68,1400,2,12.42,700,1,14.78,100,1,12.37,700,1,14.88,200,2,ARL,305187077
1219,2025-07-17T15:46:57.932842994Z,2025-07-17T15:46:57.932677299Z,160,2,1108,A,A,1,13.93,100,130,165695,256280751,13.26,100,1,13.92,15,1,13.04,2,1,13.93,100,1,13.03,100,1,14.07,2,1,12.73,100,1,14.26,100,1,12.71,100,1,14.28,100,1,12.50,700,1,14.40,100,1,12.46,200,2,14.56,800,2,12.43,700,1,14.60,700,1,12.42,700,1,14.68,1400,2,12.37,700,1,14.78,100,1,ARL,305878881
1220,2025-07-17T15:47:06.609456251Z,2025-07-17T15:47:06.609290857Z,160,2,1108,A,A,0,13.88,15,130,165394,256488374,13.26,100,1,13.88,15,1,13.04,2,1,13.92,15,1,13.03,100,1,13.93,100,1,12.73,100,1,14.07,2,1,12.71,100,1,14.26,100,1,12.50,700,1,14.28,100,1,12.46,200,2,14.40,100,1,12.43,700,1,14.56,800,2,12.42,700,1,14.60,700,1,12.37,700,1,14.68,1400,2,ARL,306121113
1221,2025-07-17T15:47:08.787695144Z,2025-07-17T15:47:08.787529505Z,160,2,1108,C,A,2,13.93,100,0,165639,256532991,13.26,100,1,13.88,15,1,13.04,2,1,13.92,15,1,13.03,100,1,14.07,2,1,12.73,100,1,14.26,100,1,12.71,100,1,14.28,100,1,12.50,700,1,14.40,100,1,12.46,200,2,14.56,800,2,12.43,700,1,14.60,700,1,12.42,700,1,14.68,1400,2,12.37,700,1,14.78,100,1,ARL,305878881
1222,2025-07-17T15:47:08.787695144Z,2025-07-17T15:47:08.787529505Z,160,2,1108,A,A,1,13.89,100,130,165639,256532991,13.26,100,1,13.88,15,1,13.04,2,1,13.89,100,1,13.03,100,1,13.92,15,1,12.73,100,1,14.07,2,1,12.71,100,1,14.26,100,1,12.50,700,1,14.28,100,1,12.46,200,2,14.40,100,1,12.43,700,1,14.56,800,2,12.42,700,1,14.60,700,1,12.37,700,1,14.68,1400,2,ARL,306170837
1223,2025-07-17T15:47:08.788440762Z,2025-07-17T15:47:08.788275184Z,160,2,1108,C,A,13,15.03,100,0,165578,256533005,13.26,100,1,13.88,15,1,13.04,2,1,13.89,100,1,13.03,100,1,13.92,15,1,12.73,100,1,14.07,2,1,12.71,100,1,14.26,100,1,12.50,700,1,14.28,100,1,12.46,200,2,14.40,100,1,12.43,700,1,14.56,800,2,12.42,700,1,14.60,700,1,12.37,700,1,14.68,1400,2,ARL,305184957
1224,2025-07-17T15:47:08.788440762Z,2025-07-17T15:47:08.788275184Z,160,2,1108,A,A,13,14.97,100,130,165578,256533005,13.26,100,1,13.88,15,1,13.04,2,1,13.89,100,1,13.03,100,1,13.92,15,1,12.73,100,1,14.07,2,1,12.71,100,1,14.26,100,1,12.50,700,1,14.28,100,1,12.46,200,2,14.40,100,1,12.43,700,1,14.56,800,2,12.42,700,1,14.60,700,1,12.37,700,1,14.68,1400,2,ARL,306170869
1225,2025-07-17T15:47:08.805983406Z,2025-07-17T15:47:08.805818249Z,160,2,1108,C,A,4,14.26,100,130,165157,256533442,13.26,100,1,13.88,15,1,13.04,2,1,13.89,100,1,13.03,100,1,13.92,15,1,12.73,100,1,14.07,2,1,12.71,100,1,14.28,100,1,12.50,700,1,14.40,100,1,12.46,200,2,14.56,800,2,12.43,700,1,14.60,700,1,12.42,700,1,14.68,1400,2,12.37,700,1,14.78,100,1,ARL,305185529
1226,2025-07-17T15:47:08.806033773Z,2025-07-17T15:47:08.805868059Z,160,2,1108,A,A,4,14.17,100,130,165714,256533443,13.26,100,1,13.88,15,1,13.04,2,1,13.89,100,1,13.03,100,1,13.92,15,1,12.73,100,1,14.07,2,1,12.71,100,1,14.17,100,1,12.50,700,1,14.28,100,1,12.46,200,2,14.40,100,1,12.43,700,1,14.56,800,2,12.42,700,1,14.60,700,1,12.37,700,1,14.68,1400,2,ARL,306171457
1227,2025-07-17T15:47:13.121454355Z,2025-07-17T15:47:13.121288953Z,160,2,1108,C,A,0,13.88,15,130,165402,256612694,13.26,100,1,13.89,100,1,13.04,2,1,13.92,15,1,13.03,100,1,14.07,2,1,12.73,100,1,14.17,100,1,12.71,100,1,14.28,100,1,12.50,700,1,14.40,100,1,12.46,200,2,14.56,800,2,12.43,700,1,14.60,700,1,12.42,700,1,14.68,1400,2,12.37,700,1,14.78,100,1,ARL,306121113
1228,2025-07-17T15:47:13.122562533Z,2025-07-17T15:47:13.122396816Z,160,2,1108,C,A,1,13.92,15,130,165717,256612757,13.26,100,1,13.89,100,1,13.04,2,1,14.07,2,1,13.03,100,1,14.17,100,1,12.73,100,1,14.28,100,1,12.71,100,1,14.40,100,1,12.50,700,1,14.56,800,2,12.46,200,2,14.60,700,1,12.43,700,1,14.68,1400,2,12.42,700,1,14.78,100,1,12.37,700,1,14.88,200,2,ARL,305862145
1229,2025-07-17T15:47:24.786476266Z,2025-07-17T15:47:24.786310694Z,160,2,1108,A,A,0,13.87,15,130,165572,256812416,13.26,100,1,13.87,15,1,13.04,2,1,13.89,100,1,13.03,100,1,14.07,2,1,12.73,100,1,14.17,100,1,12.71,100,1,14.28,100,1,12.50,700,1,14.40,100,1,12.46,200,2,14.56,800,2,12.43,700,1,14.60,700,1,12.42,700,1,14.68,1400,2,12.37,700,1,14.78,100,1,ARL,306519385
1230,2025-07-17T15:47:24.786745657Z,2025-07-17T15:47:24.786580061Z,160,2,1108,C,A,1,13.89,100,0,165596,256812420,13.26,100,1,13.87,15,1,13.04,2,1,14.07,2,1,13.03,100,1,14.17,100,1,12.73,100,1,14.28,100,1,12.71,100,1,14.40,100,1,12.50,700,1,14.56,800,2,12.46,200,2,14.60,700,1,12.43,700,1,14.68,1400,2,12.42,700,1,14.78,100,1,12.37,700,1,14.88,200,2,ARL,306170837
1231,2025-07-17T15:47:24.786745657Z,2025-07-17T15:47:24.786580061Z,160,2,1108,A,A,1,13.88,100,130,165596,256812420,13.26,100,1,13.87,15,1,13.04,2,1,13.88,100,1,13.03,100,1,14.07,2,1,12.73,100,1,14.17,100,1,12.71,100,1,14.28,100,1,12.50,700,1,14.40,100,1,12.46,200,2,14.56,800,2,12.43,700,1,14.60,700,1,12.42,700,1,14.68,1400,2,12.37,700,1,14.78,100,1,ARL,306519397
1232,2025-07-17T15:47:24.786925729Z,2025-07-17T15:47:24.786759805Z,160,2,1108,C,A,10,14.88,100,0,165924,256812422,13.26,100,1,13.87,15,1,13.04,2,1,13.88,100,1,13.03,100,1,14.07,2,1,12.73,100,1,14.17,100,1,12.71,100,1,14.28,100,1,12.50,700,1,14.40,100,1,12.46,200,2,14.56,800,2,12.43,700,1,14.60,700,1,12.42,700,1,14.68,1400,2,12.37,700,1,14.78,100,1,ARL,305184937
1233,2025-07-17T15:47:24.786925729Z,2025-07-17T15:47:24.786759805Z,160,2,1108,A,A,9,14.77,100,130,165924,256812422,13.26,100,1,13.87,15,1,13.04,2,1,13.88,100,1,13.03,100,1,14.07,2,1,12.73,100,1,14.17,100,1,12.71,100,1,14.28,100,1,12.50,700,1,14.40,100,1,12.46,200,2,14.56,800,2,12.43,700,1,14.60,700,1,12.42,700,1,14.68,1400,2,12.37,700,1,14.77,100,1,ARL,306519409
1234,2025-07-17T15:47:24.800616004Z,2025-07-17T15:47:24.800449950Z,160,2,1108,C,A,11,14.88,100,0,166054,256812578,13.26,100,1,13.87,15,1,13.04,2,1,13.88,100,1,13.03,100,1,14.07,2,1,12.73,100,1,14.17,100,1,12.71,100,1,14.28,100,1,12.50,700,1,14.40,100,1,12.46,200,2,14.56,800,2,12.43,700,1,14.60,700,1,12.42,700,1,14.68,1400,2,12.37,700,1,14.77,100,1,ARL,305184953
1235,2025-07-17T15:47:24.800616004Z,2025-07-17T15:47:24.800449950Z,160,2,1108,A,A,9,14.75,100,130,166054,256812578,13.26,100,1,13.87,15,1,13.04,2,1,13.88,100,1,13.03,100,1,14.07,2,1,12.73,100,1,14.17,100,1,12.71,100,1,14.28,100,1,12.50,700,1,14.40,100,1,12.46,200,2,14.56,800,2,12.43,700,1,14.60,700,1,12.42,700,1,14.68,1400,2,12.37,700,1,14.75,100,1,ARL,306519741
1236,2025-07-17T15:47:27.860272892Z,2025-07-17T15:47:27.860107552Z,160,2,1108,A,A,0,13.83,15,130,165340,256866835,13.26,100,1,13.83,15,1,13.04,2,1,13.87,15,1,13.03,100,1,13.88,100,1,12.73,100,1,14.07,2,1,12.71,100,1,14.17,100,1,12.50,700,1,14.28,100,1,12.46,200,2,14.40,100,1,12.43,700,1,14.56,800,2,12.42,700,1,14.60,700,1,12.37,700,1,14.68,1400,2,ARL,306587393
1237,2025-07-17T15:47:31.407029312Z,2025-07-17T15:47:31.406863918Z,160,2,1108,C,A,2,13.88,100,0,165394,256910124,13.26,100,1,13.83,15,1,13.04,2,1,13.87,15,1,13.03,100,1,14.07,2,1,12.73,100,1,14.17,100,1,12.71,100,1,14.28,100,1,12.50,700,1,14.40,100,1,12.46,200,2,14.56,800,2,12.43,700,1,14.60,700,1,12.42,700,1,14.68,1400,2,12.37,700,1,14.75,100,1,ARL,306519397
1238,2025-07-17T15:47:31.407029312Z,2025-07-17T15:47:31.406863918Z,160,2,1108,A,A,1,13.84,100,130,165394,256910124,13.26,100,1,13.83,15,1,13.04,2,1,13.84,100,1,13.03,100,1,13.87,15,1,12.73,100,1,14.07,2,1,12.71,100,1,14.17,100,1,12.50,700,1,14.28,100,1,12.46,200,2,14.40,100,1,12.43,700,1,14.56,800,2,12.42,700,1,14.60,700,1,12.37,700,1,14.68,1400,2,ARL,306647425
1239,2025-07-17T15:47:31.407771110Z,2025-07-17T15:47:31.407605685Z,160,2,1108,C,A,14,14.97,100,0,165425,256910129,13.26,100,1,13.83,15,1,13.04,2,1,13.84,100,1,13.03,100,1,13.87,15,1,12.73,100,1,14.07,2,1,12.71,100,1,14.17,100,1,12.50,700,1,14.28,100,1,12.46,200,2,14.40,100,1,12.43,700,1,14.56,800,2,12.42,700,1,14.60,700,1,12.37,700,1,14.68,1400,2,ARL,306170869
1240,2025-07-17T15:47:31.407771110Z,2025-07-17T15:47:31.407605685Z,160,2,1108,A,A,13,14.91,100,130,165425,256910129,13.26,100,1,13.83,15,1,13.04,2,1,13.84,100,1,13.03,100,1,13.87,15,1,12.73,100,1,14.07,2,1,12.71,100,1,14.17,100,1,12.50,700,1,14.28,100,1,12.46,200,2,14.40,100,1,12.43,700,1,14.56,800,2,12.42,700,1,14.60,700,1,12.37,700,1,14.68,1400,2,ARL,306647445
1241,2025-07-17T15:47:31.413491477Z,2025-07-17T15:47:31.413325908Z,160,2,1108,C,A,12,14.78,100,0,165569,256910184,13.26,100,1,13.83,15,1,13.04,2,1,13.84,100,1,13.03,100,1,13.87,15,1,12.73,100,1,14.07,2,1,12.71,100,1,14.17,100,1,12.50,700,1,14.28,100,1,12.46,200,2,14.40,100,1,12.43,700,1,14.56,800,2,12.42,700,1,14.60,700,1,12.37,700,1,14.68,1400,2,ARL,303331425
1242,2025-07-17T15:47:31.413491477Z,2025-07-17T15:47:31.413325908Z,160,2,1108,A,A,9,14.64,100,130,165569,256910184,13.26,100,1,13.83,15,1,13.04,2,1,13.84,100,1,13.03,100,1,13.87,15,1,12.73,100,1,14.07,2,1,12.71,100,1,14.17,100,1,12.50,700,1,14.28,100,1,12.46,200,2,14.40,100,1,12.43,700,1,14.56,800,2,12.42,700,1,14.60,700,1,12.37,700,1,14.64,100,1,ARL,306647521
1243,2025-07-17T15:47:31.433486283Z,2025-07-17T15:47:31.433320466Z,160,2,1108,C,A,14,14.96,100,0,165817,256910721,13.26,100,1,13.83,15,1,13.04,2,1,13.84,100,1,13.03,100,1,13.87,15,1,12.73,100,1,14.07,2,1,12.71,100,1,14.17,100,1,12.50,700,1,14.28,100,1,12.46,200,2,14.40,100,1,12.43,700,1,14.56,800,2,12.42,700,1,14.60,700,1,12.37,700,1,14.64,100,1,ARL,303330509
1244,2025-07-17T15:47:31.433486283Z,2025-07-17T15:47:31.433320466Z,160,2,1108,A,A,13,14.81,100,130,165817,256910721,13.26,100,1,13.83,15,1,13.04,2,1,13.84,100,1,13.03,100,1,13.87,15,1,12.73,100,1,14.07,2,1,12.71,100,1,14.17,100,1,12.50,700,1,14.28,100,1,12.46,200,2,14.40,100,1,12.43,700,1,14.56,800,2,12.42,700,1,14.60,700,1,12.37,700,1,14.64,100,1,ARL,306649913
1245,2025-07-17T15:47:31.574128504Z,2025-07-17T15:47:31.573963059Z,160,2,1108,C,A,20,16.08,100,0,165445,256912087,13.26,100,1,13.83,15,1,13.04,2,1,13.84,100,1,13.03,100,1,13.87,15,1,12.73,100,1,14.07,2,1,12.71,100,1,14.17,100,1,12.50,700,1,14.28,100,1,12.46,200,2,14.40,100,1,12.43,700,1,14.56,800,2,12.42,700,1,14.60,700,1,12.37,700,1,14.64,100,1,ARL,303331429
1246,2025-07-17T15:47:31.574128504Z,2025-07-17T15:47:31.573963059Z,160,2,1108,A,A,20,15.92,100,130,165445,256912087,13.26,100,1,13.83,15,1,13.04,2,1,13.84,100,1,13.03,100,1,13.87,15,1,12.73,100,1,14.07,2,1,12.71,100,1,14.17,100,1,12.50,700,1,14.28,100,1,12.46,200,2,14.40,100,1,12.43,700,1,14.56,800,2,12.42,700,1,14.60,700,1,12.37,700,1,14.64,100,1,ARL,306652001
1247,2025-07-17T15:47:31.575374481Z,2025-07-17T15:47:31.575209032Z,160,2,1108,C,A,23,17.76,100,0,165449,256912094,13.26,100,1,13.83,15,1,13.04,2,1,13.84,100,1,13.03,100,1,13.87,15,1,12.73,100,1,14.07,2,1,12.71,100,1,14.17,100,1,12.50,700,1,14.28,100,1,12.46,200,2,14.40,100,1,12.43,700,1,14.56,800,2,12.42,700,1,14.60,700,1,12.37,700,1,14.64,100,1,ARL,303331309
1248,2025-07-17T15:47:31.575374481Z,2025-07-17T15:47:31.575209032Z,160,2,1108,A,A,23,17.58,100,130,165449,256912094,13.26,100,1,13.83,15,1,13.04,2,1,13.84,100,1,13.03,100,1,13.87,15,1,12.73,100,1,14.07,2,1,12.71,100,1,14.17,100,1,12.50,700,1,14.28,100,1,12.46,200,2,14.40,100,1,12.43,700,1,14.56,800,2,12.42,700,1,14.60,700,1,12.37,700,1,14.64,100,1,ARL,306652017
1249,2025-07-17T15:47:31.740095714Z,2025-07-17T15:47:31.739930142Z,160,2,1108,C,A,15,14.96,100,0,165572,256914067,13.26,100,1,13.83,15,1,13.04,2,1,13.84,100,1,13.03,100,1,13.87,15,1,12.73,100,1,14.07,2,1,12.71,100,1,14.17,100,1,12.50,700,1,14.28,100,1,12.46,200,2,14.40,100,1,12.43,700,1,14.56,800,2,12.42,700,1,14.60,700,1,12.37,700,1,14.64,100,1,ARL,303334253
1250,2025-07-17T15:47:31.740095714Z,2025-07-17T15:47:31.739930142Z,160,2,1108,A,A,13,14.81,100,130,165572,256914067,13.26,100,1,13.83,15,1,13.04,2,1,13.84,100,1,13.03,100,1,13.87,15,1,12.73,100,1,14.07,2,1,12.71,100,1,14.17,100,1,12.50,700,1,14.28,100,1,12.46,200,2,14.40,100,1,12.43,700,1,14.56,800,2,12.42,700,1,14.60,700,1,12.37,700,1,14.64,100,1,ARL,306653713
1251,2025-07-17T15:47:37.159589804Z,2025-07-17T15:47:37.159424166Z,160,2,1108,C,A,2,13.87,15,130,165638,256983942,13.26,100,1,13.83,15,1,13.04,2,1,13.84,100,1,13.03,100,1,14.07,2,1,12.73,100,1,14.17,100,1,12.71,100,1,14.28,100,1,12.50,700,1,14.40,100,1,12.46,200,2,14.56,800,2,12.43,700,1,14.60,700,1,12.42,700,1,14.64,100,1,12.37,700,1,14.68,1400,2,ARL,306519385
1252,2025-07-17T15:47:37.172000440Z,2025-07-17T15:47:37.171834941Z,160,2,1108,A,A,2,13.85,100,130,165499,256984053,13.26,100,1,13.83,15,1,13.04,2,1,13.84,100,1,13.03,100,1,13.85,100,1,12.73,100,1,14.07,2,1,12.71,100,1,14.17,100,1,12.50,700,1,14.28,100,1,12.46,200,2,14.40,100,1,12.43,700,1,14.56,800,2,12.42,700,1,14.60,700,1,12.37,700,1,14.64,100,1,ARL,306749753
1253,2025-07-17T15:47:38.161181283Z,2025-07-17T15:47:38.161015969Z,160,2,1108,A,A,0,13.79,15,130,165314,256998606,13.26,100,1,13.79,15,1,13.04,2,1,13.83,15,1,13.03,100,1,13.84,100,1,12.73,100,1,13.85,100,1,12.71,100,1,14.07,2,1,12.50,700,1,14.17,100,1,12.46,200,2,14.28,100,1,12.43,700,1,14.40,100,1,12.42,700,1,14.56,800,2,12.37,700,1,14.60,700,1,ARL,306770041
1254,2025-07-17T15:47:38.794962245Z,2025-07-17T15:47:38.794795887Z,160,2,1108,C,A,2,13.84,100,0,166358,257010989,13.26,100,1,13.79,15,1,13.04,2,1,13.83,15,1,13.03,100,1,13.85,100,1,12.73,100,1,14.07,2,1,12.71,100,1,14.17,100,1,12.50,700,1,14.28,100,1,12.46,200,2,14.40,100,1,12.43,700,1,14.56,800,2,12.42,700,1,14.60,700,1,12.37,700,1,14.64,100,1,ARL,306647425
1255,2025-07-17T15:47:38.794962245Z,2025-07-17T15:47:38.794795887Z,160,2,1108,A,A,1,13.80,100,128,166358,257010989,13.26,100,1,13.79,15,1,13.04,2,1,13.80,100,1,13.03,100,1,13.83,15,1,12.73,100,1,13.85,100,1,12.71,100,1,14.07,2,1,12.50,700,1,14.17,100,1,12.46,200,2,14.28,100,1,12.43,700,1,14.40,100,1,12.42,700,1,14.56,800,2,12.37,700,1,14.60,700,1,ARL,306784133
1256,2025-07-17T15:47:38.795723570Z,2025-07-17T15:47:38.795557785Z,160,2,1108,C,A,15,14.91,100,0,165785,257011058,13.26,100,1,13.79,15,1,13.04,2,1,13.80,100,1,13.03,100,1,13.83,15,1,12.73,100,1,13.85,100,1,12.71,100,1,14.07,2,1,12.50,700,1,14.17,100,1,12.46,200,2,14.28,100,1,12.43,700,1,14.40,100,1,12.42,700,1,14.56,800,2,12.37,700,1,14.60,700,1,ARL,306647445
1257,2025-07-17T15:47:38.795723570Z,2025-07-17T15:47:38.795557785Z,160,2,1108,A,A,15,14.87,100,130,165785,257011058,13.26,100,1,13.79,15,1,13.04,2,1,13.80,100,1,13.03,100,1,13.83,15,1,12.73,100,1,13.85,100,1,12.71,100,1,14.07,2,1,12.50,700,1,14.17,100,1,12.46,200,2,14.28,100,1,12.43,700,1,14.40,100,1,12.42,700,1,14.56,800,2,12.37,700,1,14.60,700,1,ARL,306784201
1258,2025-07-17T15:47:38.804624258Z,2025-07-17T15:47:38.804458744Z,160,2,1108,C,A,5,14.17,100,130,165514,257011716,13.26,100,1,13.79,15,1,13.04,2,1,13.80,100,1,13.03,100,1,13.83,15,1,12.73,100,1,13.85,100,1,12.71,100,1,14.07,2,1,12.50,700,1,14.28,100,1,12.46,200,2,14.40,100,1,12.43,700,1,14.56,800,2,12.42,700,1,14.60,700,1,12.37,700,1,14.64,100,1,ARL,306171457
1259,2025-07-17T15:47:38.804679592Z,2025-07-17T15:47:38.804513793Z,160,2,1108,A,A,5,14.08,100,130,165799,257011717,13.26,100,1,13.79,15,1,13.04,2,1,13.80,100,1,13.03,100,1,13.83,15,1,12.73,100,1,13.85,100,1,12.71,100,1,14.07,2,1,12.50,700,1,14.08,100,1,12.46,200,2,14.28,100,1,12.43,700,1,14.40,100,1,12.42,700,1,14.56,800,2,12.37,700,1,14.60,700,1,ARL,306784853
1260,2025-07-17T15:47:39.092472059Z,2025-07-17T15:47:39.092305947Z,160,2,1108,C,A,0,13.79,15,130,166112,257018687,13.26,100,1,13.80,100,1,13.04,2,1,13.83,15,1,13.03,100,1,13.85,100,1,12.73,100,1,14.07,2,1,12.71,100,1,14.08,100,1,12.50,700,1,14.28,100,1,12.46,200,2,14.40,100,1,12.43,700,1,14.56,800,2,12.42,700,1,14.60,700,1,12.37,700,1,14.64,100,1,ARL,306770041
1261,2025-07-17T15:47:39.095920859Z,2025-07-17T15:47:39.095755335Z,160,2,1108,C,A,1,13.83,15,130,165524,257018796,13.26,100,1,13.80,100,1,13.04,2,1,13.85,100,1,13.03,100,1,14.07,2,1,12.73,100,1,14.08,100,1,12.71,100,1,14.28,100,1,12.50,700,1,14.40,100,1,12.46,200,2,14.56,800,2,12.43,700,1,14.60,700,1,12.42,700,1,14.64,100,1,12.37,700,1,14.68,1400,2,ARL,306587393
1262,2025-07-17T15:48:08.909366905Z,2025-07-17T15:48:08.909201576Z,160,2,1108,A,A,1,13.83,100,130,165329,257603755,13.26,100,1,13.80,100,1,13.04,2,1,13.83,100,1,13.03,100,1,13.85,100,1,12.73,100,1,14.07,2,1,12.71,100,1,14.08,100,1,12.50,700,1,14.28,100,1,12.46,200,2,14.40,100,1,12.43,700,1,14.56,800,2,12.42,700,1,14.60,700,1,12.37,700,1,14.64,100,1,ARL,307567929
1263,2025-07-17T15:48:08.916721098Z,2025-07-17T15:48:08.916555821Z,160,2,1108,C,A,2,13.85,100,130,165277,257604057,13.26,100,1,13.80,100,1,13.04,2,1,13.83,100,1,13.03,100,1,14.07,2,1,12.73,100,1,14.08,100,1,12.71,100,1,14.28,100,1,12.50,700,1,14.40,100,1,12.46,200,2,14.56,800,2,12.43,700,1,14.60,700,1,12.42,700,1,14.64,100,1,12.37,700,1,14.68,1400,2,ARL,306749753
1264,2025-07-17T15:48:09.653473465Z,2025-07-17T15:48:09.653308042Z,160,2,1108,A,A,0,13.78,15,130,165423,257621095,13.26,100,1,13.78,15,1,13.04,2,1,13.80,100,1,13.03,100,1,13.83,100,1,12.73,100,1,14.07,2,1,12.71,100,1,14.08,100,1,12.50,700,1,14.28,100,1,12.46,200,2,14.40,100,1,12.43,700,1,14.56,800,2,12.42,700,1,14.60,700,1,12.37,700,1,14.64,100,1,ARL,307587873
1265,2025-07-17T15:48:11.166689254Z,2025-07-17T15:48:11.166517494Z,160,2,1108,C,A,0,13.78,15,128,171760,257644020,13.26,100,1,13.80,100,1,13.04,2,1,13.83,100,1,13.03,100,1,14.07,2,1,12.73,100,1,14.08,100,1,12.71,100,1,14.28,100,1,12.50,700,1,14.40,100,1,12.46,200,2,14.56,800,2,12.43,700,1,14.60,700,1,12.42,700,1,14.64,100,1,12.37,700,1,14.68,1400,2,ARL,307587873
1266,2025-07-17T15:48:13.509078553Z,2025-07-17T15:48:13.508913083Z,160,2,1108,A,A,0,13.78,15,130,165470,257727039,13.26,100,1,13.78,15,1,13.04,2,1,13.80,100,1,13.03,100,1,13.83,100,1,12.73,100,1,14.07,2,1,12.71,100,1,14.08,100,1,12.50,700,1,14.28,100,1,12.46,200,2,14.40,100,1,12.43,700,1,14.56,800,2,12.42,700,1,14.60,700,1,12.37,700,1,14.64,100,1,ARL,307714769
1267,2025-07-17T15:48:13.525953545Z,2025-07-17T15:48:13.525788139Z,160,2,1108,A,A,2,13.81,100,130,165406,257727301,13.26,100,1,13.78,15,1,13.04,2,1,13.80,100,1,13.03,100,1,13.81,100,1,12.73,100,1,13.83,100,1,12.71,100,1,14.07,2,1,12.50,700,1,14.08,100,1,12.46,200,2,14.28,100,1,12.43,700,1,14.40,100,1,12.42,700,1,14.56,800,2,12.37,700,1,14.60,700,1,ARL,307715101
1268,2025-07-17T15:48:13.532608874Z,2025-07-17T15:48:13.532443045Z,160,2,1108,C,A,3,13.83,100,130,165829,257727457,13.26,100,1,13.78,15,1,13.04,2,1,13.80,100,1,13.03,100,1,13.81,100,1,12.73,100,1,14.07,2,1,12.71,100,1,14.08,100,1,12.50,700,1,14.28,100,1,12.46,200,2,14.40,100,1,12.43,700,1,14.56,800,2,12.42,700,1,14.60,700,1,12.37,700,1,14.64,100,1,ARL,307567929
1269,2025-07-17T15:48:15.568544154Z,2025-07-17T15:48:15.568378275Z,160,2,1108,C,A,1,13.80,100,0,165879,257757458,13.26,100,1,13.78,15,1,13.04,2,1,13.81,100,1,13.03,100,1,14.07,2,1,12.73,100,1,14.08,100,1,12.71,100,1,14.28,100,1,12.50,700,1,14.40,100,1,12.46,200,2,14.56,800,2,12.43,700,1,14.60,700,1,12.42,700,1,14.64,100,1,12.37,700,1,14.68,1400,2,ARL,306784133
1270,2025-07-17T15:48:15.568544154Z,2025-07-17T15:48:15.568378275Z,160,2,1108,A,A,1,13.79,100,130,165879,257757458,13.26,100,1,13.78,15,1,13.04,2,1,13.79,100,1,13.03,100,1,13.81,100,1,12.73,100,1,14.07,2,1,12.71,100,1,14.08,100,1,12.50,700,1,14.28,100,1,12.46,200,2,14.40,100,1,12.43,700,1,14.56,800,2,12.42,700,1,14.60,700,1,12.37,700,1,14.64,100,1,ARL,307753241
1271,2025-07-17T15:48:24.009355346Z,2025-07-17T15:48:24.009190157Z,160,2,1108,A,A,0,13.75,15,130,165189,257928318,13.26,100,1,13.75,15,1,13.04,2,1,13.78,15,1,13.03,100,1,13.79,100,1,12.73,100,1,13.81,100,1,12.71,100,1,14.07,2,1,12.50,700,1,14.08,100,1,12.46,200,2,14.28,100,1,12.43,700,1,14.40,100,1,12.42,700,1,14.56,800,2,12.37,700,1,14.60,700,1,ARL,307964605
1272,2025-07-17T15:48:24.009522633Z,2025-07-17T15:48:24.009357442Z,160,2,1108,A,A,2,13.79,100,130,165191,257928319,13.26,100,1,13.75,15,1,13.04,2,1,13.78,15,1,13.03,100,1,13.79,200,2,12.73,100,1,13.81,100,1,12.71,100,1,14.07,2,1,12.50,700,1,14.08,100,1,12.46,200,2,14.28,100,1,12.43,700,1,14.40,100,1,12.42,700,1,14.56,800,2,12.37,700,1,14.60,700,1,ARL,307964609
1273,2025-07-17T15:48:24.009944381Z,2025-07-17T15:48:24.009778967Z,160,2,1108,C,A,2,13.79,100,0,165414,257928325,13.26,100,1,13.75,15,1,13.04,2,1,13.78,15,1,13.03,100,1,13.79,100,1,12.73,100,1,13.81,100,1,12.71,100,1,14.07,2,1,12.50,700,1,14.08,100,1,12.46,200,2,14.28,100,1,12.43,700,1,14.40,100,1,12.42,700,1,14.56,800,2,12.37,700,1,14.60,700,1,ARL,307753241
1274,2025-07-17T15:48:24.009944381Z,2025-07-17T15:48:24.009778967Z,160,2,1108,A,A,1,13.76,100,130,165414,257928325,13.26,100,1,13.75,15,1,13.04,2,1,13.76,100,1,13.03,100,1,13.78,15,1,12.73,100,1,13.79,100,1,12.71,100,1,13.81,100,1,12.50,700,1,14.07,2,1,12.46,200,2,14.08,100,1,12.43,700,1,14.28,100,1,12.42,700,1,14.40,100,1,12.37,700,1,14.56,800,2,ARL,307964621
1275,2025-07-17T15:48:24.009974166Z,2025-07-17T15:48:24.009808793Z,160,2,1108,C,A,4,13.81,100,130,165373,257928326,13.26,100,1,13.75,15,1,13.04,2,1,13.76,100,1,13.03,100,1,13.78,15,1,12.73,100,1,13.79,100,1,12.71,100,1,14.07,2,1,12.50,700,1,14.08,100,1,12.46,200,2,14.28,100,1,12.43,700,1,14.40,100,1,12.42,700,1,14.56,800,2,12.37,700,1,14.60,700,1,ARL,307715101
1276,2025-07-17T15:48:24.010555416Z,2025-07-17T15:48:24.010390029Z,160,2,1108,C,A,13,14.77,100,0,165387,257928333,13.26,100,1,13.75,15,1,13.04,2,1,13.76,100,1,13.03,100,1,13.78,15,1,12.73,100,1,13.79,100,1,12.71,100,1,14.07,2,1,12.50,700,1,14.08,100,1,12.46,200,2,14.28,100,1,12.43,700,1,14.40,100,1,12.42,700,1,14.56,800,2,12.37,700,1,14.60,700,1,ARL,306519409
1277,2025-07-17T15:48:24.010555416Z,2025-07-17T15:48:24.010390029Z,160,2,1108,A,A,11,14.65,100,130,165387,257928333,13.26,100,1,13.75,15,1,13.04,2,1,13.76,100,1,13.03,100,1,13.78,15,1,12.73,100,1,13.79,100,1,12.71,100,1,14.07,2,1,12.50,700,1,14.08,100,1,12.46,200,2,14.28,100,1,12.43,700,1,14.40,100,1,12.42,700,1,14.56,800,2,12.37,700,1,14.60,700,1,ARL,307964661
1278,2025-07-17T15:48:24.010677522Z,2025-07-17T15:48:24.010512050Z,160,2,1108,C,A,15,14.87,100,0,165472,257928340,13.26,100,1,13.75,15,1,13.04,2,1,13.76,100,1,13.03,100,1,13.78,15,1,12.73,100,1,13.79,100,1,12.71,100,1,14.07,2,1,12.50,700,1,14.08,100,1,12.46,200,2,14.28,100,1,12.43,700,1,14.40,100,1,12.42,700,1,14.56,800,2,12.37,700,1,14.60,700,1,ARL,306784201
1279,2025-07-17T15:48:24.010677522Z,2025-07-17T15:48:24.010512050Z,160,2,1108,A,A,15,14.83,100,130,165472,257928340,13.26,100,1,13.75,15,1,13.04,2,1,13.76,100,1,13.03,100,1,13.78,15,1,12.73,100,1,13.79,100,1,12.71,100,1,14.07,2,1,12.50,700,1,14.08,100,1,12.46,200,2,14.28,100,1,12.43,700,1,14.40,100,1,12.42,700,1,14.56,800,2,12.37,700,1,14.60,700,1,ARL,307964665
1280,2025-07-17T15:48:42.009954046Z,2025-07-17T15:48:42.009788565Z,160,2,1108,C,A,2,13.78,15,130,165481,258199397,13.26,100,1,13.75,15,1,13.04,2,1,13.76,100,1,13.03,100,1,13.79,100,1,12.73,100,1,14.07,2,1,12.71,100,1,14.08,100,1,12.50,700,1,14.28,100,1,12.46,200,2,14.40,100,1,12.43,700,1,14.56,800,2,12.42,700,1,14.60,700,1,12.37,700,1,14.64,100,1,ARL,307714769
1281,2025-07-17T15:48:42.011846392Z,2025-07-17T15:48:42.011680742Z,160,2,1108,C,A,12,14.75,100,0,165650,258199535,13.26,100,1,13.75,15,1,13.04,2,1,13.76,100,1,13.03,100,1,13.79,100,1,12.73,100,1,14.07,2,1,12.71,100,1,14.08,100,1,12.50,700,1,14.28,100,1,12.46,200,2,14.40,100,1,12.43,700,1,14.56,800,2,12.42,700,1,14.60,700,1,12.37,700,1,14.64,100,1,ARL,306519741
1282,2025-07-17T15:48:42.011846392Z,2025-07-17T15:48:42.011680742Z,160,2,1108,A,A,9,14.64,100,130,165650,258199535,13.26,100,1,13.75,15,1,13.04,2,1,13.76,100,1,13.03,100,1,13.79,100,1,12.73,100,1,14.07,2,1,12.71,100,1,14.08,100,1,12.50,700,1,14.28,100,1,12.46,200,2,14.40,100,1,12.43,700,1,14.56,800,2,12.42,700,1,14.60,700,1,12.37,700,1,14.64,200,2,ARL,308296381
1283,2025-07-17T15:48:42.016761374Z,2025-07-17T15:48:42.016595806Z,160,2,1108,A,A,2,13.77,100,130,165568,258199787,13.26,100,1,13.75,15,1,13.04,2,1,13.76,100,1,13.03,100,1,13.77,100,1,12.73,100,1,13.79,100,1,12.71,100,1,14.07,2,1,12.50,700,1,14.08,100,1,12.46,200,2,14.28,100,1,12.43,700,1,14.40,100,1,12.42,700,1,14.56,800,2,12.37,700,1,14.60,700,1,ARL,308296741
1284,2025-07-17T15:48:42.023432407Z,2025-07-17T15:48:42.023266760Z,160,2,1108,C,A,3,13.79,100,130,165647,258199990,13.26,100,1,13.75,15,1,13.04,2,1,13.76,100,1,13.03,100,1,13.77,100,1,12.73,100,1,14.07,2,1,12.71,100,1,14.08,100,1,12.50,700,1,14.28,100,1,12.46,200,2,14.40,100,1,12.43,700,1,14.56,800,2,12.42,700,1,14.60,700,1,12.37,700,1,14.64,200,2,ARL,307964609
1285,2025-07-17T15:48:46.750088490Z,2025-07-17T15:48:46.749922127Z,160,2,1108,A,A,0,13.73,15,128,166363,258260871,13.26,100,1,13.73,15,1,13.04,2,1,13.75,15,1,13.03,100,1,13.76,100,1,12.73,100,1,13.77,100,1,12.71,100,1,14.07,2,1,12.50,700,1,14.08,100,1,12.46,200,2,14.28,100,1,12.43,700,1,14.40,100,1,12.42,700,1,14.56,800,2,12.37,700,1,14.60,700,1,ARL,308374537
1286,2025-07-17T15:48:46.758551033Z,2025-07-17T15:48:46.758385367Z,160,2,1108,C,A,2,13.76,100,0,165666,258261154,13.26,100,1,13.73,15,1,13.04,2,1,13.75,15,1,13.03,100,1,13.77,100,1,12.73,100,1,14.07,2,1,12.71,100,1,14.08,100,1,12.50,700,1,14.28,100,1,12.46,200,2,14.40,100,1,12.43,700,1,14.56,800,2,12.42,700,1,14.60,700,1,12.37,700,1,14.64,200,2,ARL,307964621
1287,2025-07-17T15:48:46.758551033Z,2025-07-17T15:48:46.758385367Z,160,2,1108,A,A,1,13.74,100,130,165666,258261154,13.26,100,1,13.73,15,1,13.04,2,1,13.74,100,1,13.03,100,1,13.75,15,1,12.73,100,1,13.77,100,1,12.71,100,1,14.07,2,1,12.50,700,1,14.08,100,1,12.46,200,2,14.28,100,1,12.43,700,1,14.40,100,1,12.42,700,1,14.56,800,2,12.37,700,1,14.60,700,1,ARL,308374881
1288,2025-07-17T15:48:46.773668988Z,2025-07-17T15:48:46.773503306Z,160,2,1108,C,A,5,14.08,100,130,165682,258261538,13.26,100,1,13.73,15,1,13.04,2,1,13.74,100,1,13.03,100,1,13.75,15,1,12.73,100,1,13.77,100,1,12.71,100,1,14.07,2,1,12.50,700,1,14.28,100,1,12.46,200,2,14.40,100,1,12.43,700,1,14.56,800,2,12.42,700,1,14.60,700,1,12.37,700,1,14.64,200,2,ARL,306784853
1289,2025-07-17T15:48:46.773720726Z,2025-07-17T15:48:46.773555566Z,160,2,1108,A,A,4,14.01,100,130,165160,258261539,13.26,100,1,13.73,15,1,13.04,2,1,13.74,100,1,13.03,100,1,13.75,15,1,12.73,100,1,13.77,100,1,12.71,100,1,14.01,100,1,12.50,700,1,14.07,2,1,12.46,200,2,14.28,100,1,12.43,700,1,14.40,100,1,12.42,700,1,14.56,800,2,12.37,700,1,14.60,700,1,ARL,308375185
1290,2025-07-17T15:49:02.010494480Z,2025-07-17T15:49:02.010329052Z,160,2,1108,A,A,2,13.75,100,130,165428,258502869,13.26,100,1,13.73,15,1,13.04,2,1,13.74,100,1,13.03,100,1,13.75,115,2,12.73,100,1,13.77,100,1,12.71,100,1,14.01,100,1,12.50,700,1,14.07,2,1,12.46,200,2,14.28,100,1,12.43,700,1,14.40,100,1,12.42,700,1,14.56,800,2,12.37,700,1,14.60,700,1,ARL,308705489
1291,2025-07-17T15:49:02.019989567Z,2025-07-17T15:49:02.019824230Z,160,2,1108,C,A,3,13.77,100,130,165337,258502929,13.26,100,1,13.73,15,1,13.04,2,1,13.74,100,1,13.03,100,1,13.75,115,2,12.73,100,1,14.01,100,1,12.71,100,1,14.07,2,1,12.50,700,1,14.28,100,1,12.46,200,2,14.40,100,1,12.43,700,1,14.56,800,2,12.42,700,1,14.60,700,1,12.37,700,1,14.64,200,2,ARL,308296741
1292,2025-07-17T15:49:03.406005590Z,2025-07-17T15:49:03.405840358Z,160,2,1108,C,A,2,13.75,15,130,165232,258527308,13.26,100,1,13.73,15,1,13.04,2,1,13.74,100,1,13.03,100,1,13.75,100,1,12.73,100,1,14.01,100,1,12.71,100,1,14.07,2,1,12.50,700,1,14.28,100,1,12.46,200,2,14.40,100,1,12.43,700,1,14.56,800,2,12.42,700,1,14.60,700,1,12.37,700,1,14.64,200,2,ARL,307964605
1293,2025-07-17T15:49:04.713997925Z,2025-07-17T15:49:04.713831675Z,160,2,1108,A,A,0,13.71,15,128,166250,258547335,13.26,100,1,13.71,15,1,13.04,2,1,13.73,15,1,13.03,100,1,13.74,100,1,12.73,100,1,13.75,100,1,12.71,100,1,14.01,100,1,12.50,700,1,14.07,2,1,12.46,200,2,14.28,100,1,12.43,700,1,14.40,100,1,12.42,700,1,14.56,800,2,12.37,700,1,14.60,700,1,ARL,308763065
1294,2025-07-17T15:49:06.013111941Z,2025-07-17T15:49:06.012946379Z,160,2,1108,A,A,1,13.73,100,130,165562,258567259,13.26,100,1,13.71,15,1,13.04,2,1,13.73,115,2,13.03,100,1,13.74,100,1,12.73,100,1,13.75,100,1,12.71,100,1,14.01,100,1,12.50,700,1,14.07,2,1,12.46,200,2,14.28,100,1,12.43,700,1,14.40,100,1,12.42,700,1,14.56,800,2,12.37,700,1,14.60,700,1,ARL,308786185
1295,2025-07-17T15:49:06.023292147Z,2025-07-17T15:49:06.023126600Z,160,2,1108,C,A,3,13.75,100,130,165547,258567405,13.26,100,1,13.71,15,1,13.04,2,1,13.73,115,2,13.03,100,1,13.74,100,1,12.73,100,1,14.01,100,1,12.71,100,1,14.07,2,1,12.50,700,1,14.28,100,1,12.46,200,2,14.40,100,1,12.43,700,1,14.56,800,2,12.42,700,1,14.60,700,1,12.37,700,1,14.64,200,2,ARL,308705489
1296,2025-07-17T15:49:06.344356890Z,2025-07-17T15:49:06.344191321Z,160,2,1108,C,A,2,13.74,100,0,165569,258574949,13.26,100,1,13.71,15,1,13.04,2,1,13.73,115,2,13.03,100,1,14.01,100,1,12.73,100,1,14.07,2,1,12.71,100,1,14.28,100,1,12.50,700,1,14.40,100,1,12.46,200,2,14.56,800,2,12.43,700,1,14.60,700,1,12.42,700,1,14.64,200,2,12.37,700,1,14.65,100,1,ARL,308374881
1297,2025-07-17T15:49:06.344356890Z,2025-07-17T15:49:06.344191321Z,160,2,1108,A,A,1,13.72,100,130,165569,258574949,13.26,100,1,13.71,15,1,13.04,2,1,13.72,100,1,13.03,100,1,13.73,115,2,12.73,100,1,14.01,100,1,12.71,100,1,14.07,2,1,12.50,700,1,14.28,100,1,12.46,200,2,14.40,100,1,12.43,700,1,14.56,800,2,12.42,700,1,14.60,700,1,12.37,700,1,14.64,200,2,ARL,308797069
1298,2025-07-17T15:49:06.345104491Z,2025-07-17T15:49:06.344938975Z,160,2,1108,C,A,13,14.83,100,0,165516,258575013,13.26,100,1,13.71,15,1,13.04,2,1,13.72,100,1,13.03,100,1,13.73,115,2,12.73,100,1,14.01,100,1,12.71,100,1,14.07,2,1,12.50,700,1,14.28,100,1,12.46,200,2,14.40,100,1,12.43,700,1,14.56,800,2,12.42,700,1,14.60,700,1,12.37,700,1,14.64,200,2,ARL,307964665
1299,2025-07-17T15:49:06.345104491Z,2025-07-17T15:49:06.344938975Z,160,2,1108,A,A,12,14.78,100,130,165516,258575013,13.26,100,1,13.71,15,1,13.04,2,1,13.72,100,1,13.03,100,1,13.73,115,2,12.73,100,1,14.01,100,1,12.71,100,1,14.07,2,1,12.50,700,1,14.28,100,1,12.46,200,2,14.40,100,1,12.43,700,1,14.56,800,2,12.42,700,1,14.60,700,1,12.37,700,1,14.64,200,2,ARL,308797245
1300,2025-07-17T15:49:06.362945410Z,2025-07-17T15:49:06.362779870Z,160,2,1108,C,A,21,17.58,100,0,165540,258575963,13.26,100,1,13.71,15,1,13.04,2,1,13.72,100,1,13.03,100,1,13.73,115,2,12.73,100,1,14.01,100,1,12.71,100,1,14.07,2,1,12.50,700,1,14.28,100,1,12.46,200,2,14.40,100,1,12.43,700,1,14.56,800,2,12.42,700,1,14.60,700,1,12.37,700,1,14.64,200,2,ARL,306652017
1301,2025-07-17T15:49:06.362945410Z,2025-07-17T15:49:06.362779870Z,160,2,1108,A,A,21,17.43,100,130,165540,258575963,13.26,100,1,13.71,15,1,13.04,2,1,13.72,100,1,13.03,100,1,13.73,115,2,12.73,100,1,14.01,100,1,12.71,100,1,14.07,2,1,12.50,700,1,14.28,100,1,12.46,200,2,14.40,100,1,12.43,700,1,14.56,800,2,12.42,700,1,14.60,700,1,12.37,700,1,14.64,200,2,ARL,308799373
1302,2025-07-17T15:49:10.459317885Z,2025-07-17T15:49:10.459152457Z,160,2,1108,C,A,2,13.73,15,130,165428,258636400,13.26,100,1,13.71,15,1,13.04,2,1,13.72,100,1,13.03,100,1,13.73,100,1,12.73,100,1,14.01,100,1,12.71,100,1,14.07,2,1,12.50,700,1,14.28,100,1,12.46,200,2,14.40,100,1,12.43,700,1,14.56,800,2,12.42,700,1,14.60,700,1,12.37,700,1,14.64,200,2,ARL,308374537
1303,2025-07-17T15:49:11.460597600Z,2025-07-17T15:49:11.460432218Z,160,2,1108,A,A,0,13.69,15,130,165382,258650544,13.26,100,1,13.69,15,1,13.04,2,1,13.71,15,1,13.03,100,1,13.72,100,1,12.73,100,1,13.73,100,1,12.71,100,1,14.01,100,1,12.50,700,1,14.07,2,1,12.46,200,2,14.28,100,1,12.43,700,1,14.40,100,1,12.42,700,1,14.56,800,2,12.37,700,1,14.60,700,1,ARL,308893737
1304,2025-07-17T15:49:11.891643099Z,2025-07-17T15:49:11.891477604Z,160,2,1108,C,A,2,13.72,100,0,165495,258658721,13.26,100,1,13.69,15,1,13.04,2,1,13.71,15,1,13.03,100,1,13.73,100,1,12.73,100,1,14.01,100,1,12.71,100,1,14.07,2,1,12.50,700,1,14.28,100,1,12.46,200,2,14.40,100,1,12.43,700,1,14.56,800,2,12.42,700,1,14.60,700,1,12.37,700,1,14.64,200,2,ARL,308797069
1305,2025-07-17T15:49:11.891643099Z,2025-07-17T15:49:11.891477604Z,160,2,1108,A,A,1,13.70,100,130,165495,258658721,13.26,100,1,13.69,15,1,13.04,2,1,13.70,100,1,13.03,100,1,13.71,15,1,12.73,100,1,13.73,100,1,12.71,100,1,14.01,100,1,12.50,700,1,14.07,2,1,12.46,200,2,14.28,100,1,12.43,700,1,14.40,100,1,12.42,700,1,14.56,800,2,12.37,700,1,14.60,700,1,ARL,308901793
1306,2025-07-17T15:49:11.893989071Z,2025-07-17T15:49:11.893823458Z,160,2,1108,C,A,14,14.81,100,0,165613,258658835,13.26,100,1,13.69,15,1,13.04,2,1,13.70,100,1,13.03,100,1,13.71,15,1,12.73,100,1,13.73,100,1,12.71,100,1,14.01,100,1,12.50,700,1,14.07,2,1,12.46,200,2,14.28,100,1,12.43,700,1,14.40,100,1,12.42,700,1,14.56,800,2,12.37,700,1,14.60,700,1,ARL,306649913
1307,2025-07-17T15:49:11.893989071Z,2025-07-17T15:49:11.893823458Z,160,2,1108,A,A,12,14.66,100,130,165613,258658835,13.26,100,1,13.69,15,1,13.04,2,1,13.70,100,1,13.03,100,1,13.71,15,1,12.73,100,1,13.73,100,1,12.71,100,1,14.01,100,1,12.50,700,1,14.07,2,1,12.46,200,2,14.28,100,1,12.43,700,1,14.40,100,1,12.42,700,1,14.56,800,2,12.37,700,1,14.60,700,1,ARL,308901981
1308,2025-07-17T15:49:11.904231149Z,2025-07-17T15:49:11.904065674Z,160,2,1108,C,A,20,15.92,100,0,165475,258659039,13.26,100,1,13.69,15,1,13.04,2,1,13.70,100,1,13.03,100,1,13.71,15,1,12.73,100,1,13.73,100,1,12.71,100,1,14.01,100,1,12.50,700,1,14.07,2,1,12.46,200,2,14.28,100,1,12.43,700,1,14.40,100,1,12.42,700,1,14.56,800,2,12.37,700,1,14.60,700,1,ARL,306652001
1309,2025-07-17T15:49:11.904231149Z,2025-07-17T15:49:11.904065674Z,160,2,1108,A,A,19,15.76,100,130,165475,258659039,13.26,100,1,13.69,15,1,13.04,2,1,13.70,100,1,13.03,100,1,13.71,15,1,12.73,100,1,13.73,100,1,12.71,100,1,14.01,100,1,12.50,700,1,14.07,2,1,12.46,200,2,14.28,100,1,12.43,700,1,14.40,100,1,12.42,700,1,14.56,800,2,12.37,700,1,14.60,700,1,ARL,308902229
1310,2025-07-17T15:49:11.935521687Z,2025-07-17T15:49:11.935356090Z,160,2,1108,C,A,15,14.81,100,0,165597,258659320,13.26,100,1,13.69,15,1,13.04,2,1,13.70,100,1,13.03,100,1,13.71,15,1,12.73,100,1,13.73,100,1,12.71,100,1,14.01,100,1,12.50,700,1,14.07,2,1,12.46,200,2,14.28,100,1,12.43,700,1,14.40,100,1,12.42,700,1,14.56,800,2,12.37,700,1,14.60,700,1,ARL,306653713
1311,2025-07-17T15:49:11.935521687Z,2025-07-17T15:49:11.935356090Z,160,2,1108,A,A,12,14.66,100,130,165597,258659320,13.26,100,1,13.69,15,1,13.04,2,1,13.70,100,1,13.03,100,1,13.71,15,1,12.73,100,1,13.73,100,1,12.71,100,1,14.01,100,1,12.50,700,1,14.07,2,1,12.46,200,2,14.28,100,1,12.43,700,1,14.40,100,1,12.42,700,1,14.56,800,2,12.37,700,1,14.60,700,1,ARL,308903001
1312,2025-07-17T15:49:11.948701049Z,2025-07-17T15:49:11.948535655Z,160,2,1108,C,A,10,14.64,100,130,165394,258659496,13.26,100,1,13.69,15,1,13.04,2,1,13.70,100,1,13.03,100,1,13.71,15,1,12.73,100,1,13.73,100,1,12.71,100,1,14.01,100,1,12.50,700,1,14.07,2,1,12.46,200,2,14.28,100,1,12.43,700,1,14.40,100,1,12.42,700,1,14.56,800,2,12.37,700,1,14.60,700,1,ARL,306647521
1313,2025-07-17T15:49:11.948829112Z,2025-07-17T15:49:11.948663655Z,160,2,1108,A,A,8,14.50,100,130,165457,258659499,13.26,100,1,13.69,15,1,13.04,2,1,13.70,100,1,13.03,100,1,13.71,15,1,12.73,100,1,13.73,100,1,12.71,100,1,14.01,100,1,12.50,700,1,14.07,2,1,12.46,200,2,14.28,100,1,12.43,700,1,14.40,100,1,12.42,700,1,14.50,100,1,12.37,700,1,14.56,800,2,ARL,308903349
1314,2025-07-17T15:49:12.221221367Z,2025-07-17T15:49:12.221056085Z,160,2,1108,A,A,2,13.71,100,130,165282,258663292,13.26,100,1,13.69,15,1,13.04,2,1,13.70,100,1,13.03,100,1,13.71,115,2,12.73,100,1,13.73,100,1,12.71,100,1,14.01,100,1,12.50,700,1,14.07,2,1,12.46,200,2,14.28,100,1,12.43,700,1,14.40,100,1,12.42,700,1,14.50,100,1,12.37,700,1,14.56,800,2,ARL,308909249
1315,2025-07-17T15:49:12.227986905Z,2025-07-17T15:49:12.227821500Z,160,2,1108,C,A,3,13.73,100,130,165405,258663378,13.26,100,1,13.69,15,1,13.04,2,1,13.70,100,1,13.03,100,1,13.71,115,2,12.73,100,1,14.01,100,1,12.71,100,1,14.07,2,1,12.50,700,1,14.28,100,1,12.46,200,2,14.40,100,1,12.43,700,1,14.50,100,1,12.42,700,1,14.56,800,2,12.37,700,1,14.60,700,1,ARL,308786185
1316,2025-07-17T15:49:14.463229121Z,2025-07-17T15:49:14.463063539Z,160,2,1108,C,A,2,13.71,15,130,165582,258702625,13.26,100,1,13.69,15,1,13.04,2,1,13.70,100,1,13.03,100,1,13.71,100,1,12.73,100,1,14.01,100,1,12.71,100,1,14.07,2,1,12.50,700,1,14.28,100,1,12.46,200,2,14.40,100,1,12.43,700,1,14.50,100,1,12.42,700,1,14.56,800,2,12.37,700,1,14.60,700,1,ARL,308763065
1317,2025-07-17T15:49:15.466365122Z,2025-07-17T15:49:15.466199239Z,160,2,1108,A,A,0,13.67,15,130,165883,258716863,13.26,100,1,13.67,15,1,13.04,2,1,13.69,15,1,13.03,100,1,13.70,100,1,12.73,100,1,13.71,100,1,12.71,100,1,14.01,100,1,12.50,700,1,14.07,2,1,12.46,200,2,14.28,100,1,12.43,700,1,14.40,100,1,12.42,700,1,14.50,100,1,12.37,700,1,14.56,800,2,ARL,308980305
1318,2025-07-17T15:49:16.351024588Z,2025-07-17T15:49:16.350859152Z,160,2,1108,C,A,2,13.70,100,0,165436,258727929,13.26,100,1,13.67,15,1,13.04,2,1,13.69,15,1,13.03,100,1,13.71,100,1,12.73,100,1,14.01,100,1,12.71,100,1,14.07,2,1,12.50,700,1,14.28,100,1,12.46,200,2,14.40,100,1,12.43,700,1,14.50,100,1,12.42,700,1,14.56,800,2,12.37,700,1,14.60,700,1,ARL,308901793
1319,2025-07-17T15:49:16.351024588Z,2025-07-17T15:49:16.350859152Z,160,2,1108,A,A,1,13.68,100,130,165436,258727929,13.26,100,1,13.67,15,1,13.04,2,1,13.68,100,1,13.03,100,1,13.69,15,1,12.73,100,1,13.71,100,1,12.71,100,1,14.01,100,1,12.50,700,1,14.07,2,1,12.46,200,2,14.28,100,1,12.43,700,1,14.40,100,1,12.42,700,1,14.50,100,1,12.37,700,1,14.56,800,2,ARL,308998225
1320,2025-07-17T15:49:16.351759618Z,2025-07-17T15:49:16.351594042Z,160,2,1108,C,A,15,14.78,100,0,165576,258727956,13.26,100,1,13.67,15,1,13.04,2,1,13.68,100,1,13.03,100,1,13.69,15,1,12.73,100,1,13.71,100,1,12.71,100,1,14.01,100,1,12.50,700,1,14.07,2,1,12.46,200,2,14.28,100,1,12.43,700,1,14.40,100,1,12.42,700,1,14.50,100,1,12.37,700,1,14.56,800,2,ARL,308797245
1321,2025-07-17T15:49:16.351759618Z,2025-07-17T15:49:16.351594042Z,160,2,1108,A,A,15,14.74,100,130,165576,258727956,13.26,100,1,13.67,15,1,13.04,2,1,13.68,100,1,13.03,100,1,13.69,15,1,12.73,100,1,13.71,100,1,12.71,100,1,14.01,100,1,12.50,700,1,14.07,2,1,12.46,200,2,14.28,100,1,12.43,700,1,14.40,100,1,12.42,700,1,14.50,100,1,12.37,700,1,14.56,800,2,ARL,308998341
1322,2025-07-17T15:49:16.494111490Z,2025-07-17T15:49:16.493946243Z,160,2,1108,A,A,2,13.69,100,130,165247,258729266,13.26,100,1,13.67,15,1,13.04,2,1,13.68,100,1,13.03,100,1,13.69,115,2,12.73,100,1,13.71,100,1,12.71,100,1,14.01,100,1,12.50,700,1,14.07,2,1,12.46,200,2,14.28,100,1,12.43,700,1,14.40,100,1,12.42,700,1,14.50,100,1,12.37,700,1,14.56,800,2,ARL,309001525
1323,2025-07-17T15:49:16.557924863Z,2025-07-17T15:49:16.557759633Z,160,2,1108,C,A,3,13.71,100,130,165230,258730034,13.26,100,1,13.67,15,1,13.04,2,1,13.68,100,1,13.03,100,1,13.69,115,2,12.73,100,1,14.01,100,1,12.71,100,1,14.07,2,1,12.50,700,1,14.28,100,1,12.46,200,2,14.40,100,1,12.43,700,1,14.50,100,1,12.42,700,1,14.56,800,2,12.37,700,1,14.60,700,1,ARL,308909249
1324,2025-07-17T15:49:21.186150487Z,2025-07-17T15:49:21.185984774Z,160,2,1108,C,A,4,14.07,2,0,165713,258786552,13.26,100,1,13.67,15,1,13.04,2,1,13.68,100,1,13.03,100,1,13.69,115,2,12.73,100,1,14.01,100,1,12.71,100,1,14.28,100,1,12.50,700,1,14.40,100,1,12.46,200,2,14.50,100,1,12.43,700,1,14.56,800,2,12.42,700,1,14.60,700,1,12.37,700,1,14.64,100,1,ARL,296478973
1325,2025-07-17T15:49:21.186150487Z,2025-07-17T15:49:21.185984774Z,160,2,1108,A,A,3,13.98,2,130,165713,258786552,13.26,100,1,13.67,15,1,13.04,2,1,13.68,100,1,13.03,100,1,13.69,115,2,12.73,100,1,13.98,2,1,12.71,100,1,14.01,100,1,12.50,700,1,14.28,100,1,12.46,200,2,14.40,100,1,12.43,700,1,14.50,100,1,12.42,700,1,14.56,800,2,12.37,700,1,14.60,700,1,ARL,309091513
1326,2025-07-17T15:49:24.283152112Z,2025-07-17T15:49:24.282985894Z,160,2,1108,C,A,2,13.69,15,130,166218,258838460,13.26,100,1,13.67,15,1,13.04,2,1,13.68,100,1,13.03,100,1,13.69,100,1,12.73,100,1,13.98,2,1,12.71,100,1,14.01,100,1,12.50,700,1,14.28,100,1,12.46,200,2,14.40,100,1,12.43,700,1,14.50,100,1,12.42,700,1,14.56,800,2,12.37,700,1,14.60,700,1,ARL,308893737
1327,2025-07-17T15:49:34.570197134Z,2025-07-17T15:49:34.570031718Z,160,2,1108,C,A,0,13.67,15,130,165416,258980876,13.26,100,1,13.68,100,1,13.04,2,1,13.69,100,1,13.03,100,1,13.98,2,1,12.73,100,1,14.01,100,1,12.71,100,1,14.28,100,1,12.50,700,1,14.40,100,1,12.46,200,2,14.50,100,1,12.43,700,1,14.56,800,2,12.42,700,1,14.60,700,1,12.37,700,1,14.64,100,1,ARL,308980305
1328,2025-07-17T15:49:34.591512915Z,2025-07-17T15:49:34.591347169Z,160,2,1108,C,A,1,13.69,100,130,165746,258983321,13.26,100,1,13.68,100,1,13.04,2,1,13.98,2,1,13.03,100,1,14.01,100,1,12.73,100,1,14.28,100,1,12.71,100,1,14.40,100,1,12.50,700,1,14.50,100,1,12.46,200,2,14.56,800,2,12.43,700,1,14.60,700,1,12.42,700,1,14.64,100,1,12.37,700,1,14.65,100,1,ARL,309001525
1329,2025-07-17T15:49:38.610017394Z,2025-07-17T15:49:38.609851985Z,160,2,1108,A,A,1,13.72,100,130,165409,259031220,13.26,100,1,13.68,100,1,13.04,2,1,13.72,100,1,13.03,100,1,13.98,2,1,12.73,100,1,14.01,100,1,12.71,100,1,14.28,100,1,12.50,700,1,14.40,100,1,12.46,200,2,14.50,100,1,12.43,700,1,14.56,800,2,12.42,700,1,14.60,700,1,12.37,700,1,14.64,100,1,ARL,309410565
1330,2025-07-17T15:49:38.610073334Z,2025-07-17T15:49:38.609907720Z,160,2,1108,C,B,0,13.26,100,130,165614,259031221,13.04,2,1,13.68,100,1,13.03,100,1,13.72,100,1,12.73,100,1,13.98,2,1,12.71,100,1,14.01,100,1,12.50,700,1,14.28,100,1,12.46,200,2,14.40,100,1,12.43,700,1,14.50,100,1,12.42,700,1,14.56,800,2,12.37,700,1,14.60,700,1,12.36,200,2,14.64,100,1,ARL,291975017
1331,2025-07-17T15:49:39.068515005Z,2025-07-17T15:49:39.068349660Z,160,2,1108,A,B,2,13.02,100,130,165345,259035032,13.04,2,1,13.68,100,1,13.03,100,1,13.72,100,1,13.02,100,1,13.98,2,1,12.73,100,1,14.01,100,1,12.71,100,1,14.28,100,1,12.50,700,1,14.40,100,1,12.46,200,2,14.50,100,1,12.43,700,1,14.56,800,2,12.42,700,1,14.60,700,1,12.37,700,1,14.64,100,1,ARL,309415429
1332,2025-07-17T15:49:44.788414401Z,2025-07-17T15:49:44.788249210Z,160,2,1108,A,A,0,13.67,15,130,165191,259105347,13.04,2,1,13.67,15,1,13.03,100,1,13.68,100,1,13.02,100,1,13.72,100,1,12.73,100,1,13.98,2,1,12.71,100,1,14.01,100,1,12.50,700,1,14.28,100,1,12.46,200,2,14.40,100,1,12.43,700,1,14.50,100,1,12.42,700,1,14.56,800,2,12.37,700,1,14.60,700,1,ARL,309524921
1333,2025-07-17T15:49:44.789020757Z,2025-07-17T15:49:44.788855587Z,160,2,1108,A,A,2,13.70,100,130,165170,259105361,13.04,2,1,13.67,15,1,13.03,100,1,13.68,100,1,13.02,100,1,13.70,100,1,12.73,100,1,13.72,100,1,12.71,100,1,13.98,2,1,12.50,700,1,14.01,100,1,12.46,200,2,14.28,100,1,12.43,700,1,14.40,100,1,12.42,700,1,14.50,100,1,12.37,700,1,14.56,800,2,ARL,309524933
1334,2025-07-17T15:49:44.789702916Z,2025-07-17T15:49:44.789537536Z,160,2,1108,C,A,3,13.72,100,130,165380,259105380,13.04,2,1,13.67,15,1,13.03,100,1,13.68,100,1,13.02,100,1,13.70,100,1,12.73,100,1,13.98,2,1,12.71,100,1,14.01,100,1,12.50,700,1,14.28,100,1,12.46,200,2,14.40,100,1,12.43,700,1,14.50,100,1,12.42,700,1,14.56,800,2,12.37,700,1,14.60,700,1,ARL,309410565
1335,2025-07-17T15:49:54.788658841Z,2025-07-17T15:49:54.788493605Z,160,2,1108,A,A,0,13.65,15,130,165236,259253294,13.04,2,1,13.65,15,1,13.03,100,1,13.67,15,1,13.02,100,1,13.68,100,1,12.73,100,1,13.70,100,1,12.71,100,1,13.98,2,1,12.50,700,1,14.01,100,1,12.46,200,2,14.28,100,1,12.43,700,1,14.40,100,1,12.42,700,1,14.50,100,1,12.37,700,1,14.56,800,2,ARL,309707269
1336,2025-07-17T15:49:54.799535744Z,2025-07-17T15:49:54.799370442Z,160,2,1108,A,A,2,13.68,100,130,165302,259253527,13.04,2,1,13.65,15,1,13.03,100,1,13.67,15,1,13.02,100,1,13.68,200,2,12.73,100,1,13.70,100,1,12.71,100,1,13.98,2,1,12.50,700,1,14.01,100,1,12.46,200,2,14.28,100,1,12.43,700,1,14.40,100,1,12.42,700,1,14.50,100,1,12.37,700,1,14.56,800,2,ARL,309707413
1337,2025-07-17T15:49:54.820634917Z,2025-07-17T15:49:54.820469390Z,160,2,1108,C,A,3,13.70,100,130,165527,259253732,13.04,2,1,13.65,15,1,13.03,100,1,13.67,15,1,13.02,100,1,13.68,200,2,12.73,100,1,13.98,2,1,12.71,100,1,14.01,100,1,12.50,700,1,14.28,100,1,12.46,200,2,14.40,100,1,12.43,700,1,14.50,100,1,12.42,700,1,14.56,800,2,12.37,700,1,14.60,700,1,ARL,309524933
1338,2025-07-17T15:49:59.512104064Z,2025-07-17T15:49:59.511938438Z,160,2,1108,C,A,2,13.68,100,0,165626,259313537,13.04,2,1,13.65,15,1,13.03,100,1,13.67,15,1,13.02,100,1,13.68,100,1,12.73,100,1,13.98,2,1,12.71,100,1,14.01,100,1,12.50,700,1,14.28,100,1,12.46,200,2,14.40,100,1,12.43,700,1,14.50,100,1,12.42,700,1,14.56,800,2,12.37,700,1,14.60,700,1,ARL,308998225
1339,2025-07-17T15:49:59.512104064Z,2025-07-17T15:49:59.511938438Z,160,2,1108,A,A,1,13.66,100,130,165626,259313537,13.04,2,1,13.65,15,1,13.03,100,1,13.66,100,1,13.02,100,1,13.67,15,1,12.73,100,1,13.68,100,1,12.71,100,1,13.98,2,1,12.50,700,1,14.01,100,1,12.46,200,2,14.28,100,1,12.43,700,1,14.40,100,1,12.42,700,1,14.50,100,1,12.37,700,1,14.56,800,2,ARL,309782481
1340,2025-07-17T15:49:59.534062634Z,2025-07-17T15:49:59.533897369Z,160,2,1108,C,A,5,14.01,100,130,165265,259314032,13.04,2,1,13.65,15,1,13.03,100,1,13.66,100,1,13.02,100,1,13.67,15,1,12.73,100,1,13.68,100,1,12.71,100,1,13.98,2,1,12.50,700,1,14.28,100,1,12.46,200,2,14.40,100,1,12.43,700,1,14.50,100,1,12.42,700,1,14.56,800,2,12.37,700,1,14.60,700,1,ARL,308375185
1341,2025-07-17T15:49:59.534115275Z,2025-07-17T15:49:59.533948952Z,160,2,1108,A,A,4,13.93,100,130,166323,259314033,13.04,2,1,13.65,15,1,13.03,100,1,13.66,100,1,13.02,100,1,13.67,15,1,12.73,100,1,13.68,100,1,12.71,100,1,13.93,100,1,12.50,700,1,13.98,2,1,12.46,200,2,14.28,100,1,12.43,700,1,14.40,100,1,12.42,700,1,14.50,100,1,12.37,700,1,14.56,800,2,ARL,309782973
1342,2025-07-17T15:50:00.547404972Z,2025-07-17T15:50:00.547239401Z,160,2,1108,C,A,2,13.67,15,130,165571,259349868,13.04,2,1,13.65,15,1,13.03,100,1,13.66,100,1,13.02,100,1,13.68,100,1,12.73,100,1,13.93,100,1,12.71,100,1,13.98,2,1,12.50,700,1,14.28,100,1,12.46,200,2,14.40,100,1,12.43,700,1,14.50,100,1,12.42,700,1,14.56,800,2,12.37,700,1,14.60,700,1,ARL,309524921
1343,2025-07-17T15:50:00.555536688Z,2025-07-17T15:50:00.555363249Z,160,2,1108,C,A,11,14.65,100,0,173439,259353226,13.04,2,1,13.65,15,1,13.03,100,1,13.66,100,1,13.02,100,1,13.68,100,1,12.73,100,1,13.93,100,1,12.71,100,1,13.98,2,1,12.50,700,1,14.28,100,1,12.46,200,2,14.40,100,1,12.43,700,1,14.50,100,1,12.42,700,1,14.56,800,2,12.37,700,1,14.60,700,1,ARL,307964661
1344,2025-07-17T15:50:00.555536688Z,2025-07-17T15:50:00.555363249Z,160,2,1108,A,A,8,14.54,100,128,173439,259353226,13.04,2,1,13.65,15,1,13.03,100,1,13.66,100,1,13.02,100,1,13.68,100,1,12.73,100,1,13.93,100,1,12.71,100,1,13.98,2,1,12.50,700,1,14.28,100,1,12.46,200,2,14.40,100,1,12.43,700,1,14.50,100,1,12.42,700,1,14.54,100,1,12.37,700,1,14.56,800,2,ARL,309823025
1345,2025-07-17T15:50:03.412422880Z,2025-07-17T15:50:03.412257475Z,160,2,1108,A,A,0,13.63,15,130,165405,259413272,13.04,2,1,13.63,15,1,13.03,100,1,13.65,15,1,13.02,100,1,13.66,100,1,12.73,100,1,13.68,100,1,12.71,100,1,13.93,100,1,12.50,700,1,13.98,2,1,12.46,200,2,14.28,100,1,12.43,700,1,14.40,100,1,12.42,700,1,14.50,100,1,12.37,700,1,14.54,100,1,ARL,309899025
1346,2025-07-17T15:50:03.415527372Z,2025-07-17T15:50:03.415361851Z,160,2,1108,C,A,12,14.64,100,0,165521,259413427,13.04,2,1,13.63,15,1,13.03,100,1,13.65,15,1,13.02,100,1,13.66,100,1,12.73,100,1,13.68,100,1,12.71,100,1,13.93,100,1,12.50,700,1,13.98,2,1,12.46,200,2,14.28,100,1,12.43,700,1,14.40,100,1,12.42,700,1,14.50,100,1,12.37,700,1,14.54,100,1,ARL,308296381
1347,2025-07-17T15:50:03.415527372Z,2025-07-17T15:50:03.415361851Z,160,2,1108,A,A,9,14.53,100,130,165521,259413427,13.04,2,1,13.63,15,1,13.03,100,1,13.65,15,1,13.02,100,1,13.66,100,1,12.73,100,1,13.68,100,1,12.71,100,1,13.93,100,1,12.50,700,1,13.98,2,1,12.46,200,2,14.28,100,1,12.43,700,1,14.40,100,1,12.42,700,1,14.50,100,1,12.37,700,1,14.53,100,1,ARL,309899141
1348,2025-07-17T15:50:03.824292152Z,2025-07-17T15:50:03.824126753Z,160,2,1108,C,A,2,13.66,100,0,165399,259418661,13.04,2,1,13.63,15,1,13.03,100,1,13.65,15,1,13.02,100,1,13.68,100,1,12.73,100,1,13.93,100,1,12.71,100,1,13.98,2,1,12.50,700,1,14.28,100,1,12.46,200,2,14.40,100,1,12.43,700,1,14.50,100,1,12.42,700,1,14.53,100,1,12.37,700,1,14.54,100,1,ARL,309782481
1349,2025-07-17T15:50:03.824292152Z,2025-07-17T15:50:03.824126753Z,160,2,1108,A,A,1,13.64,100,130,165399,259418661,13.04,2,1,13.63,15,1,13.03,100,1,13.64,100,1,13.02,100,1,13.65,15,1,12.73,100,1,13.68,100,1,12.71,100,1,13.93,100,1,12.50,700,1,13.98,2,1,12.46,200,2,14.28,100,1,12.43,700,1,14.40,100,1,12.42,700,1,14.50,100,1,12.37,700,1,14.53,100,1,ARL,309903973
1350,2025-07-17T15:50:03.825028460Z,2025-07-17T15:50:03.824863026Z,160,2,1108,C,A,15,14.74,100,0,165434,259418664,13.04,2,1,13.63,15,1,13.03,100,1,13.64,100,1,13.02,100,1,13.65,15,1,12.73,100,1,13.68,100,1,12.71,100,1,13.93,100,1,12.50,700,1,13.98,2,1,12.46,200,2,14.28,100,1,12.43,700,1,14.40,100,1,12.42,700,1,14.50,100,1,12.37,700,1,14.53,100,1,ARL,308998341
1351,2025-07-17T15:50:03.825028460Z,2025-07-17T15:50:03.824863026Z,160,2,1108,A,A,15,14.70,100,130,165434,259418664,13.04,2,1,13.63,15,1,13.03,100,1,13.64,100,1,13.02,100,1,13.65,15,1,12.73,100,1,13.68,100,1,12.71,100,1,13.93,100,1,12.50,700,1,13.98,2,1,12.46,200,2,14.28,100,1,12.43,700,1,14.40,100,1,12.42,700,1,14.50,100,1,12.37,700,1,14.53,100,1,ARL,309903993
1352,2025-07-17T15:50:04.484898759Z,2025-07-17T15:50:04.484733438Z,160,2,1108,A,A,3,13.66,100,130,165321,259433904,13.04,2,1,13.63,15,1,13.03,100,1,13.64,100,1,13.02,100,1,13.65,15,1,12.73,100,1,13.66,100,1,12.71,100,1,13.68,100,1,12.50,700,1,13.93,100,1,12.46,200,2,13.98,2,1,12.43,700,1,14.28,100,1,12.42,700,1,14.40,100,1,12.37,700,1,14.50,100,1,ARL,309922345
1353,2025-07-17T15:50:04.524729039Z,2025-07-17T15:50:04.524563568Z,160,2,1108,C,A,4,13.68,100,130,165471,259434652,13.04,2,1,13.63,15,1,13.03,100,1,13.64,100,1,13.02,100,1,13.65,15,1,12.73,100,1,13.66,100,1,12.71,100,1,13.93,100,1,12.50,700,1,13.98,2,1,12.46,200,2,14.28,100,1,12.43,700,1,14.40,100,1,12.42,700,1,14.50,100,1,12.37,700,1,14.53,100,1,ARL,309707413
1354,2025-07-17T15:50:06.787826975Z,2025-07-17T15:50:06.787661846Z,160,2,1108,C,A,0,13.63,15,130,165129,259472951,13.04,2,1,13.64,100,1,13.03,100,1,13.65,15,1,13.02,100,1,13.66,100,1,12.73,100,1,13.93,100,1,12.71,100,1,13.98,2,1,12.50,700,1,14.28,100,1,12.46,200,2,14.40,100,1,12.43,700,1,14.50,100,1,12.42,700,1,14.53,100,1,12.37,700,1,14.54,100,1,ARL,309899025
1355,2025-07-17T15:50:09.185499367Z,2025-07-17T15:50:09.185334126Z,160,2,1108,A,A,0,13.61,15,130,165241,259516855,13.04,2,1,13.61,15,1,13.03,100,1,13.64,100,1,13.02,100,1,13.65,15,1,12.73,100,1,13.66,100,1,12.71,100,1,13.93,100,1,12.50,700,1,13.98,2,1,12.46,200,2,14.28,100,1,12.43,700,1,14.40,100,1,12.42,700,1,14.50,100,1,12.37,700,1,14.53,100,1,ARL,310030465
1356,2025-07-17T15:50:09.198476437Z,2025-07-17T15:50:09.198311198Z,160,2,1108,A,A,1,13.64,100,130,165239,259517754,13.04,2,1,13.61,15,1,13.03,100,1,13.64,200,2,13.02,100,1,13.65,15,1,12.73,100,1,13.66,100,1,12.71,100,1,13.93,100,1,12.50,700,1,13.98,2,1,12.46,200,2,14.28,100,1,12.43,700,1,14.40,100,1,12.42,700,1,14.50,100,1,12.37,700,1,14.53,100,1,ARL,310031625
1357,2025-07-17T15:50:09.205487416Z,2025-07-17T15:50:09.205322092Z,160,2,1108,C,A,3,13.66,100,130,165324,259517973,13.04,2,1,13.61,15,1,13.03,100,1,13.64,200,2,13.02,100,1,13.65,15,1,12.73,100,1,13.93,100,1,12.71,100,1,13.98,2,1,12.50,700,1,14.28,100,1,12.46,200,2,14.40,100,1,12.43,700,1,14.50,100,1,12.42,700,1,14.53,100,1,12.37,700,1,14.54,100,1,ARL,309922345
1358,2025-07-17T15:50:09.330738153Z,2025-07-17T15:50:09.330572653Z,160,2,1108,C,A,1,13.64,100,0,165500,259522708,13.04,2,1,13.61,15,1,13.03,100,1,13.64,100,1,13.02,100,1,13.65,15,1,12.73,100,1,13.93,100,1,12.71,100,1,13.98,2,1,12.50,700,1,14.28,100,1,12.46,200,2,14.40,100,1,12.43,700,1,14.50,100,1,12.42,700,1,14.53,100,1,12.37,700,1,14.54,100,1,ARL,309903973
1359,2025-07-17T15:50:09.330738153Z,2025-07-17T15:50:09.330572653Z,160,2,1108,A,A,1,13.62,100,130,165500,259522708,13.04,2,1,13.61,15,1,13.03,100,1,13.62,100,1,13.02,100,1,13.64,100,1,12.73,100,1,13.65,15,1,12.71,100,1,13.93,100,1,12.50,700,1,13.98,2,1,12.46,200,2,14.28,100,1,12.43,700,1,14.40,100,1,12.42,700,1,14.50,100,1,12.37,700,1,14.53,100,1,ARL,310037965
1360,2025-07-17T15:50:20.204539185Z,2025-07-17T15:50:20.204373858Z,160,2,1108,C,A,3,13.65,15,130,165327,259737768,13.04,2,1,13.61,15,1,13.03,100,1,13.62,100,1,13.02,100,1,13.64,100,1,12.73,100,1,13.93,100,1,12.71,100,1,13.98,2,1,12.50,700,1,14.28,100,1,12.46,200,2,14.40,100,1,12.43,700,1,14.50,100,1,12.42,700,1,14.53,100,1,12.37,700,1,14.54,100,1,ARL,309707269
1361,2025-07-17T15:50:25.935579034Z,2025-07-17T15:50:25.935412900Z,160,2,1108,A,A,0,13.59,15,128,166134,259828644,13.04,2,1,13.59,15,1,13.03,100,1,13.61,15,1,13.02,100,1,13.62,100,1,12.73,100,1,13.64,100,1,12.71,100,1,13.93,100,1,12.50,700,1,13.98,2,1,12.46,200,2,14.28,100,1,12.43,700,1,14.40,100,1,12.42,700,1,14.50,100,1,12.37,700,1,14.53,100,1,ARL,310424077
1362,2025-07-17T15:50:26.954828150Z,2025-07-17T15:50:26.954662143Z,160,2,1108,C,A,2,13.62,100,0,166007,259847181,13.04,2,1,13.59,15,1,13.03,100,1,13.61,15,1,13.02,100,1,13.64,100,1,12.73,100,1,13.93,100,1,12.71,100,1,13.98,2,1,12.50,700,1,14.28,100,1,12.46,200,2,14.40,100,1,12.43,700,1,14.50,100,1,12.42,700,1,14.53,100,1,12.37,700,1,14.54,100,1,ARL,310037965
1363,2025-07-17T15:50:26.954828150Z,2025-07-17T15:50:26.954662143Z,160,2,1108,A,A,1,13.60,100,130,166007,259847181,13.04,2,1,13.59,15,1,13.03,100,1,13.60,100,1,13.02,100,1,13.61,15,1,12.73,100,1,13.64,100,1,12.71,100,1,13.93,100,1,12.50,700,1,13.98,2,1,12.46,200,2,14.28,100,1,12.43,700,1,14.40,100,1,12.42,700,1,14.50,100,1,12.37,700,1,14.53,100,1,ARL,310446249
1364,2025-07-17T15:50:26.955565904Z,2025-07-17T15:50:26.955400327Z,160,2,1108,C,A,15,14.70,100,0,165577,259847190,13.04,2,1,13.59,15,1,13.03,100,1,13.60,100,1,13.02,100,1,13.61,15,1,12.73,100,1,13.64,100,1,12.71,100,1,13.93,100,1,12.50,700,1,13.98,2,1,12.46,200,2,14.28,100,1,12.43,700,1,14.40,100,1,12.42,700,1,14.50,100,1,12.37,700,1,14.53,100,1,ARL,309903993
1365,2025-07-17T15:50:26.955565904Z,2025-07-17T15:50:26.955400327Z,160,2,1108,A,A,13,14.65,100,130,165577,259847190,13.04,2,1,13.59,15,1,13.03,100,1,13.60,100,1,13.02,100,1,13.61,15,1,12.73,100,1,13.64,100,1,12.71,100,1,13.93,100,1,12.50,700,1,13.98,2,1,12.46,200,2,14.28,100,1,12.43,700,1,14.40,100,1,12.42,700,1,14.50,100,1,12.37,700,1,14.53,100,1,ARL,310446269
1366,2025-07-17T15:50:26.956259508Z,2025-07-17T15:50:26.956094101Z,160,2,1108,C,A,23,17.43,100,0,165407,259847199,13.04,2,1,13.59,15,1,13.03,100,1,13.60,100,1,13.02,100,1,13.61,15,1,12.73,100,1,13.64,100,1,12.71,100,1,13.93,100,1,12.50,700,1,13.98,2,1,12.46,200,2,14.28,100,1,12.43,700,1,14.40,100,1,12.42,700,1,14.50,100,1,12.37,700,1,14.53,100,1,ARL,308799373
1367,2025-07-17T15:50:26.956259508Z,2025-07-17T15:50:26.956094101Z,160,2,1108,A,A,23,17.28,100,130,165407,259847199,13.04,2,1,13.59,15,1,13.03,100,1,13.60,100,1,13.02,100,1,13.61,15,1,12.73,100,1,13.64,100,1,12.71,100,1,13.93,100,1,12.50,700,1,13.98,2,1,12.46,200,2,14.28,100,1,12.43,700,1,14.40,100,1,12.42,700,1,14.50,100,1,12.37,700,1,14.53,100,1,ARL,310446293
1368,2025-07-17T15:50:26.983044736Z,2025-07-17T15:50:26.982879448Z,160,2,1108,A,A,19,15.51,100,130,165288,259847556,13.04,2,1,13.59,15,1,13.03,100,1,13.60,100,1,13.02,100,1,13.61,15,1,12.73,100,1,13.64,100,1,12.71,100,1,13.93,100,1,12.50,700,1,13.98,2,1,12.46,200,2,14.28,100,1,12.43,700,1,14.40,100,1,12.42,700,1,14.50,100,1,12.37,700,1,14.53,100,1,ARL,310447441
1369,2025-07-17T15:50:26.983057675Z,2025-07-17T15:50:26.982892468Z,160,2,1108,C,A,21,15.78,100,130,165207,259847557,13.04,2,1,13.59,15,1,13.03,100,1,13.60,100,1,13.02,100,1,13.61,15,1,12.73,100,1,13.64,100,1,12.71,100,1,13.93,100,1,12.50,700,1,13.98,2,1,12.46,200,2,14.28,100,1,12.43,700,1,14.40,100,1,12.42,700,1,14.50,100,1,12.37,700,1,14.53,100,1,ARL,282776733
1370,2025-07-17T15:50:30.046879569Z,2025-07-17T15:50:30.046714265Z,160,2,1108,C,A,0,13.59,15,130,165304,259916670,13.04,2,1,13.60,100,1,13.03,100,1,13.61,15,1,13.02,100,1,13.64,100,1,12.73,100,1,13.93,100,1,12.71,100,1,13.98,2,1,12.50,700,1,14.28,100,1,12.46,200,2,14.40,100,1,12.43,700,1,14.50,100,1,12.42,700,1,14.53,100,1,12.37,700,1,14.54,100,1,ARL,310424077
1371,2025-07-17T15:50:30.047015114Z,2025-07-17T15:50:30.046849726Z,160,2,1108,C,A,1,13.61,15,130,165388,259916674,13.04,2,1,13.60,100,1,13.03,100,1,13.64,100,1,13.02,100,1,13.93,100,1,12.73,100,1,13.98,2,1,12.71,100,1,14.28,100,1,12.50,700,1,14.40,100,1,12.46,200,2,14.50,100,1,12.43,700,1,14.53,100,1,12.42,700,1,14.54,100,1,12.37,700,1,14.56,800,2,ARL,310030465
1372,2025-07-17T15:51:37.986158330Z,2025-07-17T15:51:37.985992174Z,160,2,1108,C,A,3,13.98,2,0,166156,261130345,13.04,2,1,13.60,100,1,13.03,100,1,13.64,100,1,13.02,100,1,13.93,100,1,12.73,100,1,14.28,100,1,12.71,100,1,14.40,100,1,12.50,700,1,14.50,100,1,12.46,200,2,14.53,100,1,12.43,700,1,14.54,100,1,12.42,700,1,14.56,800,2,12.37,700,1,14.60,700,1,ARL,309091513
1373,2025-07-17T15:51:37.986158330Z,2025-07-17T15:51:37.985992174Z,160,2,1108,A,A,2,13.89,2,130,166156,261130345,13.04,2,1,13.60,100,1,13.03,100,1,13.64,100,1,13.02,100,1,13.89,2,1,12.73,100,1,13.93,100,1,12.71,100,1,14.28,100,1,12.50,700,1,14.40,100,1,12.46,200,2,14.50,100,1,12.43,700,1,14.53,100,1,12.42,700,1,14.54,100,1,12.37,700,1,14.56,800,2,ARL,311979125
1374,2025-07-17T15:52:16.372434625Z,2025-07-17T15:52:16.372269170Z,160,2,1108,C,A,0,13.60,100,130,165455,261713790,13.04,2,1,13.64,100,1,13.03,100,1,13.89,2,1,13.02,100,1,13.93,100,1,12.73,100,1,14.28,100,1,12.71,100,1,14.40,100,1,12.50,700,1,14.50,100,1,12.46,200,2,14.53,100,1,12.43,700,1,14.54,100,1,12.42,700,1,14.56,800,2,12.37,700,1,14.60,700,1,ARL,310446249
1375,2025-07-17T15:52:16.373188791Z,2025-07-17T15:52:16.373023186Z,160,2,1108,C,A,10,14.65,100,0,165605,261713830,13.04,2,1,13.64,100,1,13.03,100,1,13.89,2,1,13.02,100,1,13.93,100,1,12.73,100,1,14.28,100,1,12.71,100,1,14.40,100,1,12.50,700,1,14.50,100,1,12.46,200,2,14.53,100,1,12.43,700,1,14.54,100,1,12.42,700,1,14.56,800,2,12.37,700,1,14.60,700,1,ARL,310446269
1376,2025-07-17T15:52:16.373188791Z,2025-07-17T15:52:16.373023186Z,160,2,1108,A,A,12,14.70,100,130,165605,261713830,13.04,2,1,13.64,100,1,13.03,100,1,13.89,2,1,13.02,100,1,13.93,100,1,12.73,100,1,14.28,100,1,12.71,100,1,14.40,100,1,12.50,700,1,14.50,100,1,12.46,200,2,14.53,100,1,12.43,700,1,14.54,100,1,12.42,700,1,14.56,800,2,12.37,700,1,14.60,700,1,ARL,312771573
1377,2025-07-17T15:52:16.374353159Z,2025-07-17T15:52:16.374186508Z,160,2,1108,C,A,0,13.64,100,130,166651,261713870,13.04,2,1,13.89,2,1,13.03,100,1,13.93,100,1,13.02,100,1,14.28,100,1,12.73,100,1,14.40,100,1,12.71,100,1,14.50,100,1,12.50,700,1,14.53,100,1,12.46,200,2,14.54,100,1,12.43,700,1,14.56,800,2,12.42,700,1,14.60,700,1,12.37,700,1,14.66,200,2,ARL,310031625
1378,2025-07-17T15:52:16.374480183Z,2025-07-17T15:52:16.374312976Z,160,2,1108,A,A,17,15.86,100,128,167207,261713880,13.04,2,1,13.89,2,1,13.03,100,1,13.93,100,1,13.02,100,1,14.28,100,1,12.73,100,1,14.40,100,1,12.71,100,1,14.50,100,1,12.50,700,1,14.53,100,1,12.46,200,2,14.54,100,1,12.43,700,1,14.56,800,2,12.42,700,1,14.60,700,1,12.37,700,1,14.66,200,2,ARL,312771645
1379,2025-07-17T15:52:16.374493650Z,2025-07-17T15:52:16.374327668Z,160,2,1108,C,A,15,15.51,100,130,165982,261713884,13.04,2,1,13.89,2,1,13.03,100,1,13.93,100,1,13.02,100,1,14.28,100,1,12.73,100,1,14.40,100,1,12.71,100,1,14.50,100,1,12.50,700,1,14.53,100,1,12.46,200,2,14.54,100,1,12.43,700,1,14.56,800,2,12.42,700,1,14.60,700,1,12.37,700,1,14.66,200,2,ARL,310447441
1380,2025-07-17T15:52:16.375388285Z,2025-07-17T15:52:16.375222836Z,160,2,1108,C,A,6,14.54,100,0,165449,261713944,13.04,2,1,13.89,2,1,13.03,100,1,13.93,100,1,13.02,100,1,14.28,100,1,12.73,100,1,14.40,100,1,12.71,100,1,14.50,100,1,12.50,700,1,14.53,100,1,12.46,200,2,14.56,800,2,12.43,700,1,14.60,700,1,12.42,700,1,14.66,200,2,12.37,700,1,14.68,1400,2,ARL,309823025
1381,2025-07-17T15:52:16.375388285Z,2025-07-17T15:52:16.375222836Z,160,2,1108,A,A,11,14.81,100,130,165449,261713944,13.04,2,1,13.89,2,1,13.03,100,1,13.93,100,1,13.02,100,1,14.28,100,1,12.73,100,1,14.40,100,1,12.71,100,1,14.50,100,1,12.50,700,1,14.53,100,1,12.46,200,2,14.56,800,2,12.43,700,1,14.60,700,1,12.42,700,1,14.66,200,2,12.37,700,1,14.68,1400,2,ARL,312771781
1382,2025-07-17T15:52:16.375414247Z,2025-07-17T15:52:16.375248654Z,160,2,1108,C,A,8,14.66,100,0,165593,261713945,13.04,2,1,13.89,2,1,13.03,100,1,13.93,100,1,13.02,100,1,14.28,100,1,12.73,100,1,14.40,100,1,12.71,100,1,14.50,100,1,12.50,700,1,14.53,100,1,12.46,200,2,14.56,800,2,12.43,700,1,14.60,700,1,12.42,700,1,14.66,100,1,12.37,700,1,14.68,1400,2,ARL,308901981
1383,2025-07-17T15:52:16.375414247Z,2025-07-17T15:52:16.375248654Z,160,2,1108,A,A,12,14.89,100,130,165593,261713945,13.04,2,1,13.89,2,1,13.03,100,1,13.93,100,1,13.02,100,1,14.28,100,1,12.73,100,1,14.40,100,1,12.71,100,1,14.50,100,1,12.50,700,1,14.53,100,1,12.46,200,2,14.56,800,2,12.43,700,1,14.60,700,1,12.42,700,1,14.66,100,1,12.37,700,1,14.68,1400,2,ARL,312771785
1384,2025-07-17T15:52:16.375828154Z,2025-07-17T15:52:16.375662552Z,160,2,1108,C,A,5,14.53,100,0,165602,261713959,13.04,2,1,13.89,2,1,13.03,100,1,13.93,100,1,13.02,100,1,14.28,100,1,12.73,100,1,14.40,100,1,12.71,100,1,14.50,100,1,12.50,700,1,14.56,800,2,12.46,200,2,14.60,700,1,12.43,700,1,14.66,100,1,12.42,700,1,14.68,1400,2,12.37,700,1,14.70,100,1,ARL,309899141
1385,2025-07-17T15:52:16.375828154Z,2025-07-17T15:52:16.375662552Z,160,2,1108,A,A,10,14.76,100,130,165602,261713959,13.04,2,1,13.89,2,1,13.03,100,1,13.93,100,1,13.02,100,1,14.28,100,1,12.73,100,1,14.40,100,1,12.71,100,1,14.50,100,1,12.50,700,1,14.56,800,2,12.46,200,2,14.60,700,1,12.43,700,1,14.66,100,1,12.42,700,1,14.68,1400,2,12.37,700,1,14.70,100,1,ARL,312771829
1386,2025-07-17T15:52:16.377345053Z,2025-07-17T15:52:16.377179230Z,160,2,1108,C,A,20,17.28,100,0,165823,261714104,13.04,2,1,13.89,2,1,13.03,100,1,13.93,100,1,13.02,100,1,14.28,100,1,12.73,100,1,14.40,100,1,12.71,100,1,14.50,100,1,12.50,700,1,14.56,800,2,12.46,200,2,14.60,700,1,12.43,700,1,14.66,100,1,12.42,700,1,14.68,1400,2,12.37,700,1,14.70,100,1,ARL,310446293
1387,2025-07-17T15:52:16.377345053Z,2025-07-17T15:52:16.377179230Z,160,2,1108,A,A,20,17.70,100,130,165823,261714104,13.04,2,1,13.89,2,1,13.03,100,1,13.93,100,1,13.02,100,1,14.28,100,1,12.73,100,1,14.40,100,1,12.71,100,1,14.50,100,1,12.50,700,1,14.56,800,2,12.46,200,2,14.60,700,1,12.43,700,1,14.66,100,1,12.42,700,1,14.68,1400,2,12.37,700,1,14.70,100,1,ARL,312772009
1388,2025-07-17T15:52:16.378239114Z,2025-07-17T15:52:16.378073674Z,160,2,1108,C,A,16,15.76,100,0,165440,261714140,13.04,2,1,13.89,2,1,13.03,100,1,13.93,100,1,13.02,100,1,14.28,100,1,12.73,100,1,14.40,100,1,12.71,100,1,14.50,100,1,12.50,700,1,14.56,800,2,12.46,200,2,14.60,700,1,12.43,700,1,14.66,100,1,12.42,700,1,14.68,1400,2,12.37,700,1,14.70,100,1,ARL,308902229
1389,2025-07-17T15:52:16.378239114Z,2025-07-17T15:52:16.378073674Z,160,2,1108,A,A,17,16.02,100,130,165440,261714140,13.04,2,1,13.89,2,1,13.03,100,1,13.93,100,1,13.02,100,1,14.28,100,1,12.73,100,1,14.40,100,1,12.71,100,1,14.50,100,1,12.50,700,1,14.56,800,2,12.46,200,2,14.60,700,1,12.43,700,1,14.66,100,1,12.42,700,1,14.68,1400,2,12.37,700,1,14.70,100,1,ARL,312772057
1390,2025-07-17T15:52:16.378385943Z,2025-07-17T15:52:16.378220434Z,160,2,1108,C,A,4,14.50,100,0,165509,261714145,13.04,2,1,13.89,2,1,13.03,100,1,13.93,100,1,13.02,100,1,14.28,100,1,12.73,100,1,14.40,100,1,12.71,100,1,14.56,800,2,12.50,700,1,14.60,700,1,12.46,200,2,14.66,100,1,12.43,700,1,14.68,1400,2,12.42,700,1,14.70,100,1,12.37,700,1,14.76,100,1,ARL,308903349
1391,2025-07-17T15:52:16.378385943Z,2025-07-17T15:52:16.378220434Z,160,2,1108,A,A,9,14.72,100,130,165509,261714145,13.04,2,1,13.89,2,1,13.03,100,1,13.93,100,1,13.02,100,1,14.28,100,1,12.73,100,1,14.40,100,1,12.71,100,1,14.56,800,2,12.50,700,1,14.60,700,1,12.46,200,2,14.66,100,1,12.43,700,1,14.68,1400,2,12.42,700,1,14.70,100,1,12.37,700,1,14.72,100,1,ARL,312772061
1392,2025-07-17T15:52:16.378870638Z,2025-07-17T15:52:16.378705201Z,160,2,1108,A,B,0,13.27,10,130,165437,261714171,13.27,10,1,13.89,2,1,13.04,2,1,13.93,100,1,13.03,100,1,14.28,100,1,13.02,100,1,14.40,100,1,12.73,100,1,14.56,800,2,12.71,100,1,14.60,700,1,12.50,700,1,14.66,100,1,12.46,200,2,14.68,1400,2,12.43,700,1,14.70,100,1,12.42,700,1,14.72,100,1,ARL,312772069
1393,2025-07-17T15:52:16.378872385Z,2025-07-17T15:52:16.378707041Z,160,2,1108,A,A,0,13.86,15,130,165344,261714172,13.27,10,1,13.86,15,1,13.04,2,1,13.89,2,1,13.03,100,1,13.93,100,1,13.02,100,1,14.28,100,1,12.73,100,1,14.40,100,1,12.71,100,1,14.56,800,2,12.50,700,1,14.60,700,1,12.46,200,2,14.66,100,1,12.43,700,1,14.68,1400,2,12.42,700,1,14.70,100,1,ARL,312772073
1394,2025-07-17T15:52:16.379127782Z,2025-07-17T15:52:16.378962330Z,160,2,1108,C,B,3,13.02,100,0,165452,261714185,13.27,10,1,13.86,15,1,13.04,2,1,13.89,2,1,13.03,100,1,13.93,100,1,12.73,100,1,14.28,100,1,12.71,100,1,14.40,100,1,12.50,700,1,14.56,800,2,12.46,200,2,14.60,700,1,12.43,700,1,14.66,100,1,12.42,700,1,14.68,1400,2,12.37,700,1,14.70,100,1,ARL,309415429
1395,2025-07-17T15:52:16.379127782Z,2025-07-17T15:52:16.378962330Z,160,2,1108,A,B,1,13.26,100,130,165452,261714185,13.27,10,1,13.86,15,1,13.26,100,1,13.89,2,1,13.04,2,1,13.93,100,1,13.03,100,1,14.28,100,1,12.73,100,1,14.40,100,1,12.71,100,1,14.56,800,2,12.50,700,1,14.60,700,1,12.46,200,2,14.66,100,1,12.43,700,1,14.68,1400,2,12.42,700,1,14.70,100,1,ARL,312772077
1396,2025-07-17T15:52:16.389025469Z,2025-07-17T15:52:16.388859982Z,160,2,1108,C,A,2,13.93,100,130,165487,261714477,13.27,10,1,13.86,15,1,13.26,100,1,13.89,2,1,13.04,2,1,14.28,100,1,13.03,100,1,14.40,100,1,12.73,100,1,14.56,800,2,12.71,100,1,14.60,700,1,12.50,700,1,14.66,100,1,12.46,200,2,14.68,1400,2,12.43,700,1,14.70,100,1,12.42,700,1,14.72,100,1,ARL,309782973
1397,2025-07-17T15:52:16.389082451Z,2025-07-17T15:52:16.388917108Z,160,2,1108,A,A,2,14.19,100,130,165343,261714481,13.27,10,1,13.86,15,1,13.26,100,1,13.89,2,1,13.04,2,1,14.19,100,1,13.03,100,1,14.28,100,1,12.73,100,1,14.40,100,1,12.71,100,1,14.56,800,2,12.50,700,1,14.60,700,1,12.46,200,2,14.66,100,1,12.43,700,1,14.68,1400,2,12.42,700,1,14.70,100,1,ARL,312772501
1398,2025-07-17T15:52:16.396174502Z,2025-07-17T15:52:16.396008715Z,160,2,1108,C,A,7,14.66,100,0,165787,261714603,13.27,10,1,13.86,15,1,13.26,100,1,13.89,2,1,13.04,2,1,14.19,100,1,13.03,100,1,14.28,100,1,12.73,100,1,14.40,100,1,12.71,100,1,14.56,800,2,12.50,700,1,14.60,700,1,12.46,200,2,14.68,1400,2,12.43,700,1,14.70,100,1,12.42,700,1,14.72,100,1,ARL,308903001
1399,2025-07-17T15:52:16.396174502Z,2025-07-17T15:52:16.396008715Z,160,2,1108,A,A,13,14.96,100,130,165787,261714603,13.27,10,1,13.86,15,1,13.26,100,1,13.89,2,1,13.04,2,1,14.19,100,1,13.03,100,1,14.28,100,1,12.73,100,1,14.40,100,1,12.71,100,1,14.56,800,2,12.50,700,1,14.60,700,1,12.46,200,2,14.68,1400,2,12.43,700,1,14.70,100,1,12.42,700,1,14.72,100,1,ARL,312772869
1400,2025-07-17T15:52:16.397677681Z,2025-07-17T15:52:16.397512710Z,160,2,1108,C,A,2,14.19,100,130,164971,261714619,13.27,10,1,13.86,15,1,13.26,100,1,13.89,2,1,13.04,2,1,14.28,100,1,13.03,100,1,14.40,100,1,12.73,100,1,14.56,800,2,12.71,100,1,14.60,700,1,12.50,700,1,14.68,1400,2,12.46,200,2,14.70,100,1,12.43,700,1,14.72,100,1,12.42,700,1,14.76,100,1,ARL,312772501
1401,2025-07-17T15:52:16.397727042Z,2025-07-17T15:52:16.397561691Z,160,2,1108,A,A,2,14.26,100,130,165351,261714620,13.27,10,1,13.86,15,1,13.26,100,1,13.89,2,1,13.04,2,1,14.26,100,1,13.03,100,1,14.28,100,1,12.73,100,1,14.40,100,1,12.71,100,1,14.56,800,2,12.50,700,1,14.60,700,1,12.46,200,2,14.68,1400,2,12.43,700,1,14.70,100,1,12.42,700,1,14.72,100,1,ARL,312772901
1402,2025-07-17T15:52:16.424137423Z,2025-07-17T15:52:16.423972000Z,160,2,1108,C,A,8,14.70,100,0,165423,261714976,13.27,10,1,13.86,15,1,13.26,100,1,13.89,2,1,13.04,2,1,14.26,100,1,13.03,100,1,14.28,100,1,12.73,100,1,14.40,100,1,12.71,100,1,14.56,800,2,12.50,700,1,14.60,700,1,12.46,200,2,14.68,1400,2,12.43,700,1,14.72,100,1,12.42,700,1,14.76,100,1,ARL,312771573
1403,2025-07-17T15:52:16.424137423Z,2025-07-17T15:52:16.423972000Z,160,2,1108,A,A,13,15.06,100,130,165423,261714976,13.27,10,1,13.86,15,1,13.26,100,1,13.89,2,1,13.04,2,1,14.26,100,1,13.03,100,1,14.28,100,1,12.73,100,1,14.40,100,1,12.71,100,1,14.56,800,2,12.50,700,1,14.60,700,1,12.46,200,2,14.68,1400,2,12.43,700,1,14.72,100,1,12.42,700,1,14.76,100,1,ARL,312773353
1404,2025-07-17T15:52:16.464781343Z,2025-07-17T15:52:16.464616142Z,160,2,1108,A,A,1,13.87,100,130,165201,261715303,13.27,10,1,13.86,15,1,13.26,100,1,13.87,100,1,13.04,2,1,13.89,2,1,13.03,100,1,14.26,100,1,12.73,100,1,14.28,100,1,12.71,100,1,14.40,100,1,12.50,700,1,14.56,800,2,12.46,200,2,14.60,700,1,12.43,700,1,14.68,1400,2,12.42,700,1,14.72,100,1,ARL,312773881
1405,2025-07-17T15:52:16.473556948Z,2025-07-17T15:52:16.473391480Z,160,2,1108,C,A,14,15.06,100,0,165468,261715409,13.27,10,1,13.86,15,1,13.26,100,1,13.87,100,1,13.04,2,1,13.89,2,1,13.03,100,1,14.26,100,1,12.73,100,1,14.28,100,1,12.71,100,1,14.40,100,1,12.50,700,1,14.56,800,2,12.46,200,2,14.60,700,1,12.43,700,1,14.68,1400,2,12.42,700,1,14.72,100,1,ARL,312773353
1406,2025-07-17T15:52:16.473556948Z,2025-07-17T15:52:16.473391480Z,160,2,1108,A,A,13,14.95,100,130,165468,261715409,13.27,10,1,13.86,15,1,13.26,100,1,13.87,100,1,13.04,2,1,13.89,2,1,13.03,100,1,14.26,100,1,12.73,100,1,14.28,100,1,12.71,100,1,14.40,100,1,12.50,700,1,14.56,800,2,12.46,200,2,14.60,700,1,12.43,700,1,14.68,1400,2,12.42,700,1,14.72,100,1,ARL,312774001
1407,2025-07-17T15:52:16.480090894Z,2025-07-17T15:52:16.479925781Z,160,2,1108,C,A,3,14.26,100,130,165113,261715467,13.27,10,1,13.86,15,1,13.26,100,1,13.87,100,1,13.04,2,1,13.89,2,1,13.03,100,1,14.28,100,1,12.73,100,1,14.40,100,1,12.71,100,1,14.56,800,2,12.50,700,1,14.60,700,1,12.46,200,2,14.68,1400,2,12.43,700,1,14.72,100,1,12.42,700,1,14.76,100,1,ARL,312772901
1408,2025-07-17T15:52:16.480140131Z,2025-07-17T15:52:16.479974840Z,160,2,1108,A,A,3,14.15,100,130,165291,261715468,13.27,10,1,13.86,15,1,13.26,100,1,13.87,100,1,13.04,2,1,13.89,2,1,13.03,100,1,14.15,100,1,12.73,100,1,14.28,100,1,12.71,100,1,14.40,100,1,12.50,700,1,14.56,800,2,12.46,200,2,14.60,700,1,12.43,700,1,14.68,1400,2,12.42,700,1,14.72,100,1,ARL,312774033
1409,2025-07-17T15:52:28.787316865Z,2025-07-17T15:52:28.787151494Z,160,2,1108,C,B,0,13.27,10,130,165371,261883294,13.26,100,1,13.86,15,1,13.04,2,1,13.87,100,1,13.03,100,1,13.89,2,1,12.73,100,1,14.15,100,1,12.71,100,1,14.28,100,1,12.50,700,1,14.40,100,1,12.46,200,2,14.56,800,2,12.43,700,1,14.60,700,1,12.42,700,1,14.68,1400,2,12.37,700,1,14.72,100,1,ARL,312772069
1410,2025-07-17T15:52:28.787317827Z,2025-07-17T15:52:28.787152437Z,160,2,1108,C,A,0,13.86,15,130,165390,261883295,13.26,100,1,13.87,100,1,13.04,2,1,13.89,2,1,13.03,100,1,14.15,100,1,12.73,100,1,14.28,100,1,12.71,100,1,14.40,100,1,12.50,700,1,14.56,800,2,12.46,200,2,14.60,700,1,12.43,700,1,14.68,1400,2,12.42,700,1,14.72,100,1,12.37,700,1,14.76,100,1,ARL,312772073
1411,2025-07-17T15:52:43.128371033Z,2025-07-17T15:52:43.128203357Z,160,2,1108,C,A,1,13.89,2,0,167676,262115170,13.26,100,1,13.87,100,1,13.04,2,1,14.15,100,1,13.03,100,1,14.28,100,1,12.73,100,1,14.40,100,1,12.71,100,1,14.56,800,2,12.50,700,1,14.60,700,1,12.46,200,2,14.68,1400,2,12.43,700,1,14.72,100,1,12.42,700,1,14.76,100,1,12.37,700,1,14.81,100,1,ARL,311979125
1412,2025-07-17T15:52:43.128371033Z,2025-07-17T15:52:43.128203357Z,160,2,1108,A,A,1,13.99,2,128,167676,262115170,13.26,100,1,13.87,100,1,13.04,2,1,13.99,2,1,13.03,100,1,14.15,100,1,12.73,100,1,14.28,100,1,12.71,100,1,14.40,100,1,12.50,700,1,14.56,800,2,12.46,200,2,14.60,700,1,12.43,700,1,14.68,1400,2,12.42,700,1,14.72,100,1,12.37,700,1,14.76,100,1,ARL,313336713
1413,2025-07-17T15:54:24.908483782Z,2025-07-17T15:54:24.908318259Z,160,2,1108,A,B,0,13.29,10,130,165523,263863872,13.29,10,1,13.87,100,1,13.26,100,1,13.99,2,1,13.04,2,1,14.15,100,1,13.03,100,1,14.28,100,1,12.73,100,1,14.40,100,1,12.71,100,1,14.56,800,2,12.50,700,1,14.60,700,1,12.46,200,2,14.68,1400,2,12.43,700,1,14.72,100,1,12.42,700,1,14.76,100,1,ARL,315581981
1414,2025-07-17T15:54:26.792478456Z,2025-07-17T15:54:26.792313320Z,160,2,1108,C,B,0,13.29,10,130,165136,263895481,13.26,100,1,13.87,100,1,13.04,2,1,13.99,2,1,13.03,100,1,14.15,100,1,12.73,100,1,14.28,100,1,12.71,100,1,14.40,100,1,12.50,700,1,14.56,800,2,12.46,200,2,14.60,700,1,12.43,700,1,14.68,1400,2,12.42,700,1,14.72,100,1,12.37,700,1,14.76,100,1,ARL,315581981
1415,2025-07-17T15:54:52.986116083Z,2025-07-17T15:54:52.985950259Z,160,2,1108,C,A,1,13.99,2,0,165824,264262615,13.26,100,1,13.87,100,1,13.04,2,1,14.15,100,1,13.03,100,1,14.28,100,1,12.73,100,1,14.40,100,1,12.71,100,1,14.56,800,2,12.50,700,1,14.60,700,1,12.46,200,2,14.68,1400,2,12.43,700,1,14.72,100,1,12.42,700,1,14.76,100,1,12.37,700,1,14.81,100,1,ARL,313336713
1416,2025-07-17T15:54:52.986116083Z,2025-07-17T15:54:52.985950259Z,160,2,1108,A,A,1,14.10,2,130,165824,264262615,13.26,100,1,13.87,100,1,13.04,2,1,14.10,2,1,13.03,100,1,14.15,100,1,12.73,100,1,14.28,100,1,12.71,100,1,14.40,100,1,12.50,700,1,14.56,800,2,12.46,200,2,14.60,700,1,12.43,700,1,14.68,1400,2,12.42,700,1,14.72,100,1,12.37,700,1,14.76,100,1,ARL,316098525
1417,2025-07-17T15:55:33.673598252Z,2025-07-17T15:55:33.673432762Z,160,2,1108,A,B,0,13.29,10,130,165490,264905534,13.29,10,1,13.87,100,1,13.26,100,1,14.10,2,1,13.04,2,1,14.15,100,1,13.03,100,1,14.28,100,1,12.73,100,1,14.40,100,1,12.71,100,1,14.56,800,2,12.50,700,1,14.60,700,1,12.46,200,2,14.68,1400,2,12.43,700,1,14.72,100,1,12.42,700,1,14.76,100,1,ARL,316911465
1418,2025-07-17T15:55:34.257417204Z,2025-07-17T15:55:34.257251787Z,160,2,1108,C,B,1,13.26,100,0,165417,264919835,13.29,10,1,13.87,100,1,13.04,2,1,14.10,2,1,13.03,100,1,14.15,100,1,12.73,100,1,14.28,100,1,12.71,100,1,14.40,100,1,12.50,700,1,14.56,800,2,12.46,200,2,14.60,700,1,12.43,700,1,14.68,1400,2,12.42,700,1,14.72,100,1,12.37,700,1,14.76,100,1,ARL,312772077
1419,2025-07-17T15:55:34.257417204Z,2025-07-17T15:55:34.257251787Z,160,2,1108,A,B,1,13.28,100,130,165417,264919835,13.29,10,1,13.87,100,1,13.28,100,1,14.10,2,1,13.04,2,1,14.15,100,1,13.03,100,1,14.28,100,1,12.73,100,1,14.40,100,1,12.71,100,1,14.56,800,2,12.50,700,1,14.60,700,1,12.46,200,2,14.68,1400,2,12.43,700,1,14.72,100,1,12.42,700,1,14.76,100,1,ARL,316924721
1420,2025-07-17T15:55:40.197750400Z,2025-07-17T15:55:40.197584524Z,160,2,1108,C,B,0,13.29,10,130,165876,265015966,13.28,100,1,13.87,100,1,13.04,2,1,14.10,2,1,13.03,100,1,14.15,100,1,12.73,100,1,14.28,100,1,12.71,100,1,14.40,100,1,12.50,700,1,14.56,800,2,12.46,200,2,14.60,700,1,12.43,700,1,14.68,1400,2,12.42,700,1,14.72,100,1,12.37,700,1,14.76,100,1,ARL,316911465
1421,2025-07-17T15:57:51.328863560Z,2025-07-17T15:57:51.328698198Z,160,2,1108,C,A,0,13.87,100,130,165362,267272430,13.28,100,1,14.10,2,1,13.04,2,1,14.15,100,1,13.03,100,1,14.28,100,1,12.73,100,1,14.40,100,1,12.71,100,1,14.56,800,2,12.50,700,1,14.60,700,1,12.46,200,2,14.68,1400,2,12.43,700,1,14.72,100,1,12.42,700,1,14.76,100,1,12.37,700,1,14.81,100,1,ARL,312773881
1422,2025-07-17T15:57:51.329613584Z,2025-07-17T15:57:51.329447325Z,160,2,1108,C,A,11,14.95,100,0,166259,267272438,13.28,100,1,14.10,2,1,13.04,2,1,14.15,100,1,13.03,100,1,14.28,100,1,12.73,100,1,14.40,100,1,12.71,100,1,14.56,800,2,12.50,700,1,14.60,700,1,12.46,200,2,14.68,1400,2,12.43,700,1,14.72,100,1,12.42,700,1,14.76,100,1,12.37,700,1,14.81,100,1,ARL,312774001
1423,2025-07-17T15:57:51.329613584Z,2025-07-17T15:57:51.329447325Z,160,2,1108,A,A,12,15.00,100,130,166259,267272438,13.28,100,1,14.10,2,1,13.04,2,1,14.15,100,1,13.03,100,1,14.28,100,1,12.73,100,1,14.40,100,1,12.71,100,1,14.56,800,2,12.50,700,1,14.60,700,1,12.46,200,2,14.68,1400,2,12.43,700,1,14.72,100,1,12.42,700,1,14.76,100,1,12.37,700,1,14.81,100,1,ARL,319985021
1424,2025-07-17T15:57:51.329857672Z,2025-07-17T15:57:51.329692071Z,160,2,1108,C,A,8,14.76,100,0,165601,267272442,13.28,100,1,14.10,2,1,13.04,2,1,14.15,100,1,13.03,100,1,14.28,100,1,12.73,100,1,14.40,100,1,12.71,100,1,14.56,800,2,12.50,700,1,14.60,700,1,12.46,200,2,14.68,1400,2,12.43,700,1,14.72,100,1,12.42,700,1,14.81,100,1,12.37,700,1,14.89,100,1,ARL,312771829
1425,2025-07-17T15:57:51.329857672Z,2025-07-17T15:57:51.329692071Z,160,2,1108,A,A,9,14.89,100,130,165601,267272442,13.28,100,1,14.10,2,1,13.04,2,1,14.15,100,1,13.03,100,1,14.28,100,1,12.73,100,1,14.40,100,1,12.71,100,1,14.56,800,2,12.50,700,1,14.60,700,1,12.46,200,2,14.68,1400,2,12.43,700,1,14.72,100,1,12.42,700,1,14.81,100,1,12.37,700,1,14.89,200,2,ARL,319985025
1426,2025-07-17T15:57:51.339328219Z,2025-07-17T15:57:51.339162512Z,160,2,1108,C,A,1,14.15,100,130,165707,267272660,13.28,100,1,14.10,2,1,13.04,2,1,14.28,100,1,13.03,100,1,14.40,100,1,12.73,100,1,14.56,800,2,12.71,100,1,14.60,700,1,12.50,700,1,14.68,1400,2,12.46,200,2,14.72,100,1,12.43,700,1,14.81,100,1,12.42,700,1,14.89,200,2,12.37,700,1,14.96,100,1,ARL,312774033
1427,2025-07-17T15:57:51.339382098Z,2025-07-17T15:57:51.339216923Z,160,2,1108,A,A,1,14.26,100,130,165175,267272665,13.28,100,1,14.10,2,1,13.04,2,1,14.26,100,1,13.03,100,1,14.28,100,1,12.73,100,1,14.40,100,1,12.71,100,1,14.56,800,2,12.50,700,1,14.60,700,1,12.46,200,2,14.68,1400,2,12.43,700,1,14.72,100,1,12.42,700,1,14.81,100,1,12.37,700,1,14.89,200,2,ARL,319985165
1428,2025-07-17T15:57:51.379736852Z,2025-07-17T15:57:51.379570470Z,160,2,1108,C,A,11,15.00,100,0,166382,267273071,13.28,100,1,14.10,2,1,13.04,2,1,14.26,100,1,13.03,100,1,14.28,100,1,12.73,100,1,14.40,100,1,12.71,100,1,14.56,800,2,12.50,700,1,14.60,700,1,12.46,200,2,14.68,1400,2,12.43,700,1,14.72,100,1,12.42,700,1,14.81,100,1,12.37,700,1,14.89,200,2,ARL,319985021
1429,2025-07-17T15:57:51.379736852Z,2025-07-17T15:57:51.379570470Z,160,2,1108,A,A,11,15.06,100,128,166382,267273071,13.28,100,1,14.10,2,1,13.04,2,1,14.26,100,1,13.03,100,1,14.28,100,1,12.73,100,1,14.40,100,1,12.71,100,1,14.56,800,2,12.50,700,1,14.60,700,1,12.46,200,2,14.68,1400,2,12.43,700,1,14.72,100,1,12.42,700,1,14.81,100,1,12.37,700,1,14.89,200,2,ARL,319985497
1430,2025-07-17T15:57:52.378369524Z,2025-07-17T15:57:52.378204338Z,160,2,1108,A,A,1,14.11,100,130,165186,267283873,13.28,100,1,14.10,2,1,13.04,2,1,14.11,100,1,13.03,100,1,14.26,100,1,12.73,100,1,14.28,100,1,12.71,100,1,14.40,100,1,12.50,700,1,14.56,800,2,12.46,200,2,14.60,700,1,12.43,700,1,14.68,1400,2,12.42,700,1,14.72,100,1,12.37,700,1,14.81,100,1,ARL,320000233
1431,2025-07-17T15:58:14.483909354Z,2025-07-17T15:58:14.483743947Z,160,2,1108,A,A,0,13.76,4,130,165407,267657011,13.28,100,1,13.76,4,1,13.04,2,1,14.10,2,1,13.03,100,1,14.11,100,1,12.73,100,1,14.26,100,1,12.71,100,1,14.28,100,1,12.50,700,1,14.40,100,1,12.46,200,2,14.56,800,2,12.43,700,1,14.60,700,1,12.42,700,1,14.68,1400,2,12.37,700,1,14.72,100,1,ARL,320484625
1432,2025-07-17T15:58:14.484164551Z,2025-07-17T15:58:14.483999049Z,160,2,1108,C,A,2,14.11,100,0,165502,267657013,13.28,100,1,13.76,4,1,13.04,2,1,14.10,2,1,13.03,100,1,14.26,100,1,12.73,100,1,14.28,100,1,12.71,100,1,14.40,100,1,12.50,700,1,14.56,800,2,12.46,200,2,14.60,700,1,12.43,700,1,14.68,1400,2,12.42,700,1,14.72,100,1,12.37,700,1,14.81,100,1,ARL,320000233
1433,2025-07-17T15:58:14.484164551Z,2025-07-17T15:58:14.483999049Z,160,2,1108,A,A,1,13.77,100,130,165502,267657013,13.28,100,1,13.76,4,1,13.04,2,1,13.77,100,1,13.03,100,1,14.10,2,1,12.73,100,1,14.26,100,1,12.71,100,1,14.28,100,1,12.50,700,1,14.40,100,1,12.46,200,2,14.56,800,2,12.43,700,1,14.60,700,1,12.42,700,1,14.68,1400,2,12.37,700,1,14.72,100,1,ARL,320484637
1434,2025-07-17T15:58:14.484183413Z,2025-07-17T15:58:14.484017806Z,160,2,1108,C,B,0,13.28,100,130,165607,267657014,13.04,2,1,13.76,4,1,13.03,100,1,13.77,100,1,12.73,100,1,14.10,2,1,12.71,100,1,14.26,100,1,12.50,700,1,14.28,100,1,12.46,200,2,14.40,100,1,12.43,700,1,14.56,800,2,12.42,700,1,14.60,700,1,12.37,700,1,14.68,1400,2,12.36,200,2,14.72,100,1,ARL,316924721
1435,2025-07-17T15:58:14.484312532Z,2025-07-17T15:58:14.484147359Z,160,2,1108,A,A,2,13.79,100,130,165173,267657020,13.04,2,1,13.76,4,1,13.03,100,1,13.77,100,1,12.73,100,1,13.79,100,1,12.71,100,1,14.10,2,1,12.50,700,1,14.26,100,1,12.46,200,2,14.28,100,1,12.43,700,1,14.40,100,1,12.42,700,1,14.56,800,2,12.37,700,1,14.60,700,1,12.36,200,2,14.68,1400,2,ARL,320484661
1436,2025-07-17T15:58:14.484902175Z,2025-07-17T15:58:14.484736787Z,160,2,1108,C,A,14,15.06,100,0,165388,267657063,13.04,2,1,13.76,4,1,13.03,100,1,13.77,100,1,12.73,100,1,13.79,100,1,12.71,100,1,14.10,2,1,12.50,700,1,14.26,100,1,12.46,200,2,14.28,100,1,12.43,700,1,14.40,100,1,12.42,700,1,14.56,800,2,12.37,700,1,14.60,700,1,12.36,200,2,14.68,1400,2,ARL,319985497
1437,2025-07-17T15:58:14.484902175Z,2025-07-17T15:58:14.484736787Z,160,2,1108,A,A,12,14.84,100,130,165388,267657063,13.04,2,1,13.76,4,1,13.03,100,1,13.77,100,1,12.73,100,1,13.79,100,1,12.71,100,1,14.10,2,1,12.50,700,1,14.26,100,1,12.46,200,2,14.28,100,1,12.43,700,1,14.40,100,1,12.42,700,1,14.56,800,2,12.37,700,1,14.60,700,1,12.36,200,2,14.68,1400,2,ARL,320484709
1438,2025-07-17T15:58:14.484927848Z,2025-07-17T15:58:14.484761664Z,160,2,1108,C,A,0,13.76,4,128,166184,267657070,13.04,2,1,13.77,100,1,13.03,100,1,13.79,100,1,12.73,100,1,14.10,2,1,12.71,100,1,14.26,100,1,12.50,700,1,14.28,100,1,12.46,200,2,14.40,100,1,12.43,700,1,14.56,800,2,12.42,700,1,14.60,700,1,12.37,700,1,14.68,1400,2,12.36,200,2,14.72,100,1,ARL,320484625
1439,2025-07-17T15:58:14.484963870Z,2025-07-17T15:58:14.484798779Z,160,2,1108,C,A,0,13.77,100,130,165091,267657073,13.04,2,1,13.79,100,1,13.03,100,1,14.10,2,1,12.73,100,1,14.26,100,1,12.71,100,1,14.28,100,1,12.50,700,1,14.40,100,1,12.46,200,2,14.56,800,2,12.43,700,1,14.60,700,1,12.42,700,1,14.68,1400,2,12.37,700,1,14.72,100,1,12.36,200,2,14.81,100,1,ARL,320484637
1440,2025-07-17T15:58:14.485392903Z,2025-07-17T15:58:14.485227487Z,160,2,1108,C,A,9,14.81,100,0,165416,267657092,13.04,2,1,13.79,100,1,13.03,100,1,14.10,2,1,12.73,100,1,14.26,100,1,12.71,100,1,14.28,100,1,12.50,700,1,14.40,100,1,12.46,200,2,14.56,800,2,12.43,700,1,14.60,700,1,12.42,700,1,14.68,1400,2,12.37,700,1,14.72,100,1,12.36,200,2,14.84,100,1,ARL,312771781
1441,2025-07-17T15:58:14.485392903Z,2025-07-17T15:58:14.485227487Z,160,2,1108,A,A,7,14.68,100,130,165416,267657092,13.04,2,1,13.79,100,1,13.03,100,1,14.10,2,1,12.73,100,1,14.26,100,1,12.71,100,1,14.28,100,1,12.50,700,1,14.40,100,1,12.46,200,2,14.56,800,2,12.43,700,1,14.60,700,1,12.42,700,1,14.68,1500,3,12.37,700,1,14.72,100,1,12.36,200,2,14.84,100,1,ARL,320484781
1442,2025-07-17T15:58:14.485831602Z,2025-07-17T15:58:14.485666254Z,160,2,1108,C,A,16,16.02,100,0,165348,267657097,13.04,2,1,13.79,100,1,13.03,100,1,14.10,2,1,12.73,100,1,14.26,100,1,12.71,100,1,14.28,100,1,12.50,700,1,14.40,100,1,12.46,200,2,14.56,800,2,12.43,700,1,14.60,700,1,12.42,700,1,14.68,1500,3,12.37,700,1,14.72,100,1,12.36,200,2,14.84,100,1,ARL,312772057
1443,2025-07-17T15:58:14.485831602Z,2025-07-17T15:58:14.485666254Z,160,2,1108,A,A,15,15.86,100,130,165348,267657097,13.04,2,1,13.79,100,1,13.03,100,1,14.10,2,1,12.73,100,1,14.26,100,1,12.71,100,1,14.28,100,1,12.50,700,1,14.40,100,1,12.46,200,2,14.56,800,2,12.43,700,1,14.60,700,1,12.42,700,1,14.68,1500,3,12.37,700,1,14.72,100,1,12.36,200,2,14.84,100,1,ARL,320484817
1444,2025-07-17T15:58:14.485850874Z,2025-07-17T15:58:14.485685308Z,160,2,1108,C,A,11,14.96,100,0,165566,267657098,13.04,2,1,13.79,100,1,13.03,100,1,14.10,2,1,12.73,100,1,14.26,100,1,12.71,100,1,14.28,100,1,12.50,700,1,14.40,100,1,12.46,200,2,14.56,800,2,12.43,700,1,14.60,700,1,12.42,700,1,14.68,1500,3,12.37,700,1,14.72,100,1,12.36,200,2,14.84,100,1,ARL,312772869
1445,2025-07-17T15:58:14.485850874Z,2025-07-17T15:58:14.485685308Z,160,2,1108,A,A,9,14.76,100,130,165566,267657098,13.04,2,1,13.79,100,1,13.03,100,1,14.10,2,1,12.73,100,1,14.26,100,1,12.71,100,1,14.28,100,1,12.50,700,1,14.40,100,1,12.46,200,2,14.56,800,2,12.43,700,1,14.60,700,1,12.42,700,1,14.68,1500,3,12.37,700,1,14.72,100,1,12.36,200,2,14.76,100,1,ARL,320484821
1446,2025-07-17T15:58:14.485989643Z,2025-07-17T15:58:14.485824228Z,160,2,1108,C,A,11,14.89,100,0,165415,267657101,13.04,2,1,13.79,100,1,13.03,100,1,14.10,2,1,12.73,100,1,14.26,100,1,12.71,100,1,14.28,100,1,12.50,700,1,14.40,100,1,12.46,200,2,14.56,800,2,12.43,700,1,14.60,700,1,12.42,700,1,14.68,1500,3,12.37,700,1,14.72,100,1,12.36,200,2,14.76,100,1,ARL,319985025
1447,2025-07-17T15:58:14.485989643Z,2025-07-17T15:58:14.485824228Z,160,2,1108,A,A,8,14.69,100,130,165415,267657101,13.04,2,1,13.79,100,1,13.03,100,1,14.10,2,1,12.73,100,1,14.26,100,1,12.71,100,1,14.28,100,1,12.50,700,1,14.40,100,1,12.46,200,2,14.56,800,2,12.43,700,1,14.60,700,1,12.42,700,1,14.68,1500,3,12.37,700,1,14.69,100,1,12.36,200,2,14.72,100,1,ARL,320484825
1448,2025-07-17T15:58:14.486406355Z,2025-07-17T15:58:14.486240860Z,160,2,1108,C,A,19,17.70,100,0,165495,267657116,13.04,2,1,13.79,100,1,13.03,100,1,14.10,2,1,12.73,100,1,14.26,100,1,12.71,100,1,14.28,100,1,12.50,700,1,14.40,100,1,12.46,200,2,14.56,800,2,12.43,700,1,14.60,700,1,12.42,700,1,14.68,1500,3,12.37,700,1,14.69,100,1,12.36,200,2,14.72,100,1,ARL,312772009
1449,2025-07-17T15:58:14.486406355Z,2025-07-17T15:58:14.486240860Z,160,2,1108,A,A,19,17.52,100,130,165495,267657116,13.04,2,1,13.79,100,1,13.03,100,1,14.10,2,1,12.73,100,1,14.26,100,1,12.71,100,1,14.28,100,1,12.50,700,1,14.40,100,1,12.46,200,2,14.56,800,2,12.43,700,1,14.60,700,1,12.42,700,1,14.68,1500,3,12.37,700,1,14.69,100,1,12.36,200,2,14.72,100,1,ARL,320484837
1450,2025-07-17T15:58:14.508177256Z,2025-07-17T15:58:14.508012098Z,160,2,1108,C,A,2,14.26,100,130,165158,267657330,13.04,2,1,13.79,100,1,13.03,100,1,14.10,2,1,12.73,100,1,14.28,100,1,12.71,100,1,14.40,100,1,12.50,700,1,14.56,800,2,12.46,200,2,14.60,700,1,12.43,700,1,14.68,1500,3,12.42,700,1,14.69,100,1,12.37,700,1,14.72,100,1,12.36,200,2,14.76,100,1,ARL,319985165
1451,2025-07-17T15:58:14.508227890Z,2025-07-17T15:58:14.508062605Z,160,2,1108,A,A,1,14.05,100,130,165285,267657333,13.04,2,1,13.79,100,1,13.03,100,1,14.05,100,1,12.73,100,1,14.10,2,1,12.71,100,1,14.28,100,1,12.50,700,1,14.40,100,1,12.46,200,2,14.56,800,2,12.43,700,1,14.60,700,1,12.42,700,1,14.68,1500,3,12.37,700,1,14.69,100,1,12.36,200,2,14.72,100,1,ARL,320484985
1452,2025-07-17T15:58:14.529557108Z,2025-07-17T15:58:14.529391743Z,160,2,1108,A,B,2,13.02,100,130,165365,267657561,13.04,2,1,13.79,100,1,13.03,100,1,14.05,100,1,13.02,100,1,14.10,2,1,12.73,100,1,14.28,100,1,12.71,100,1,14.40,100,1,12.50,700,1,14.56,800,2,12.46,200,2,14.60,700,1,12.43,700,1,14.68,1500,3,12.42,700,1,14.69,100,1,12.37,700,1,14.72,100,1,ARL,320485385
1453,2025-07-17T15:58:14.529578291Z,2025-07-17T15:58:14.529413184Z,160,2,1108,A,A,1,13.80,100,130,165107,267657562,13.04,2,1,13.79,100,1,13.03,100,1,13.80,100,1,13.02,100,1,14.05,100,1,12.73,100,1,14.10,2,1,12.71,100,1,14.28,100,1,12.50,700,1,14.40,100,1,12.46,200,2,14.56,800,2,12.43,700,1,14.60,700,1,12.42,700,1,14.68,1500,3,12.37,700,1,14.69,100,1,ARL,320485389
1454,2025-07-17T15:58:14.659899426Z,2025-07-17T15:58:14.659734381Z,160,2,1108,C,A,0,13.79,100,130,165045,267658873,13.04,2,1,13.80,100,1,13.03,100,1,14.05,100,1,13.02,100,1,14.10,2,1,12.73,100,1,14.28,100,1,12.71,100,1,14.40,100,1,12.50,700,1,14.56,800,2,12.46,200,2,14.60,700,1,12.43,700,1,14.68,1500,3,12.42,700,1,14.69,100,1,12.37,700,1,14.72,100,1,ARL,320484661
1455,2025-07-17T15:58:14.659939230Z,2025-07-17T15:58:14.659773896Z,160,2,1108,C,A,0,13.80,100,130,165334,267658879,13.04,2,1,14.05,100,1,13.03,100,1,14.10,2,1,13.02,100,1,14.28,100,1,12.73,100,1,14.40,100,1,12.71,100,1,14.56,800,2,12.50,700,1,14.60,700,1,12.46,200,2,14.68,1500,3,12.43,700,1,14.69,100,1,12.42,700,1,14.72,100,1,12.37,700,1,14.76,100,1,ARL,320485389
1456,2025-07-17T15:58:14.660667636Z,2025-07-17T15:58:14.660502341Z,160,2,1108,C,A,10,14.84,100,0,165295,267658892,13.04,2,1,14.05,100,1,13.03,100,1,14.10,2,1,13.02,100,1,14.28,100,1,12.73,100,1,14.40,100,1,12.71,100,1,14.56,800,2,12.50,700,1,14.60,700,1,12.46,200,2,14.68,1500,3,12.43,700,1,14.69,100,1,12.42,700,1,14.72,100,1,12.37,700,1,14.76,100,1,ARL,320484709
1457,2025-07-17T15:58:14.660667636Z,2025-07-17T15:58:14.660502341Z,160,2,1108,A,A,11,14.91,100,130,165295,267658892,13.04,2,1,14.05,100,1,13.03,100,1,14.10,2,1,13.02,100,1,14.28,100,1,12.73,100,1,14.40,100,1,12.71,100,1,14.56,800,2,12.50,700,1,14.60,700,1,12.46,200,2,14.68,1500,3,12.43,700,1,14.69,100,1,12.42,700,1,14.72,100,1,12.37,700,1,14.76,100,1,ARL,320486925
1458,2025-07-17T15:58:14.664378962Z,2025-07-17T15:58:14.664213722Z,160,2,1108,C,A,18,17.52,100,0,165240,267658928,13.04,2,1,14.05,100,1,13.03,100,1,14.10,2,1,13.02,100,1,14.28,100,1,12.73,100,1,14.40,100,1,12.71,100,1,14.56,800,2,12.50,700,1,14.60,700,1,12.46,200,2,14.68,1500,3,12.43,700,1,14.69,100,1,12.42,700,1,14.72,100,1,12.37,700,1,14.76,100,1,ARL,320484837
1459,2025-07-17T15:58:14.664378962Z,2025-07-17T15:58:14.664213722Z,160,2,1108,A,A,18,17.76,100,130,165240,267658928,13.04,2,1,14.05,100,1,13.03,100,1,14.10,2,1,13.02,100,1,14.28,100,1,12.73,100,1,14.40,100,1,12.71,100,1,14.56,800,2,12.50,700,1,14.60,700,1,12.46,200,2,14.68,1500,3,12.43,700,1,14.69,100,1,12.42,700,1,14.72,100,1,12.37,700,1,14.76,100,1,ARL,320486937
1460,2025-07-17T15:58:14.664939310Z,2025-07-17T15:58:14.664774078Z,160,2,1108,C,A,15,15.86,100,0,165232,267658931,13.04,2,1,14.05,100,1,13.03,100,1,14.10,2,1,13.02,100,1,14.28,100,1,12.73,100,1,14.40,100,1,12.71,100,1,14.56,800,2,12.50,700,1,14.60,700,1,12.46,200,2,14.68,1500,3,12.43,700,1,14.69,100,1,12.42,700,1,14.72,100,1,12.37,700,1,14.76,100,1,ARL,320484817
1461,2025-07-17T15:58:14.664939310Z,2025-07-17T15:58:14.664774078Z,160,2,1108,A,A,16,16.08,100,130,165232,267658931,13.04,2,1,14.05,100,1,13.03,100,1,14.10,2,1,13.02,100,1,14.28,100,1,12.73,100,1,14.40,100,1,12.71,100,1,14.56,800,2,12.50,700,1,14.60,700,1,12.46,200,2,14.68,1500,3,12.43,700,1,14.69,100,1,12.42,700,1,14.72,100,1,12.37,700,1,14.76,100,1,ARL,320486945
1462,2025-07-17T15:58:14.672315806Z,2025-07-17T15:58:14.672150755Z,160,2,1108,C,A,0,14.05,100,130,165051,267658982,13.04,2,1,14.10,2,1,13.03,100,1,14.28,100,1,13.02,100,1,14.40,100,1,12.73,100,1,14.56,800,2,12.71,100,1,14.60,700,1,12.50,700,1,14.68,1500,3,12.46,200,2,14.69,100,1,12.43,700,1,14.72,100,1,12.42,700,1,14.76,100,1,12.37,700,1,14.89,100,1,ARL,320484985
1463,2025-07-17T15:58:14.672365974Z,2025-07-17T15:58:14.672200872Z,160,2,1108,A,A,1,14.12,100,130,165102,267658983,13.04,2,1,14.10,2,1,13.03,100,1,14.12,100,1,13.02,100,1,14.28,100,1,12.73,100,1,14.40,100,1,12.71,100,1,14.56,800,2,12.50,700,1,14.60,700,1,12.46,200,2,14.68,1500,3,12.43,700,1,14.69,100,1,12.42,700,1,14.72,100,1,12.37,700,1,14.76,100,1,ARL,320487017
1464,2025-07-17T15:58:14.673184116Z,2025-07-17T15:58:14.673019194Z,160,2,1108,C,A,1,14.12,100,130,164922,267658989,13.04,2,1,14.10,2,1,13.03,100,1,14.28,100,1,13.02,100,1,14.40,100,1,12.73,100,1,14.56,800,2,12.71,100,1,14.60,700,1,12.50,700,1,14.68,1500,3,12.46,200,2,14.69,100,1,12.43,700,1,14.72,100,1,12.42,700,1,14.76,100,1,12.37,700,1,14.89,100,1,ARL,320487017
1465,2025-07-17T15:58:14.673230480Z,2025-07-17T15:58:14.673065320Z,160,2,1108,A,A,1,14.26,100,130,165160,267658990,13.04,2,1,14.10,2,1,13.03,100,1,14.26,100,1,13.02,100,1,14.28,100,1,12.73,100,1,14.40,100,1,12.71,100,1,14.56,800,2,12.50,700,1,14.60,700,1,12.46,200,2,14.68,1500,3,12.43,700,1,14.69,100,1,12.42,700,1,14.72,100,1,12.37,700,1,14.76,100,1,ARL,320487025
1466,2025-07-17T15:58:14.682945541Z,2025-07-17T15:58:14.682780396Z,160,2,1108,C,A,9,14.76,100,0,165145,267659018,13.04,2,1,14.10,2,1,13.03,100,1,14.26,100,1,13.02,100,1,14.28,100,1,12.73,100,1,14.40,100,1,12.71,100,1,14.56,800,2,12.50,700,1,14.60,700,1,12.46,200,2,14.68,1500,3,12.43,700,1,14.69,100,1,12.42,700,1,14.72,100,1,12.37,700,1,14.89,100,1,ARL,320484821
1467,2025-07-17T15:58:14.682945541Z,2025-07-17T15:58:14.682780396Z,160,2,1108,A,A,11,14.96,100,130,165145,267659018,13.04,2,1,14.10,2,1,13.03,100,1,14.26,100,1,13.02,100,1,14.28,100,1,12.73,100,1,14.40,100,1,12.71,100,1,14.56,800,2,12.50,700,1,14.60,700,1,12.46,200,2,14.68,1500,3,12.43,700,1,14.69,100,1,12.42,700,1,14.72,100,1,12.37,700,1,14.89,100,1,ARL,320487105
1468,2025-07-17T15:58:14.710787891Z,2025-07-17T15:58:14.710622495Z,160,2,1108,C,A,10,14.91,100,0,165396,267659178,13.04,2,1,14.10,2,1,13.03,100,1,14.26,100,1,13.02,100,1,14.28,100,1,12.73,100,1,14.40,100,1,12.71,100,1,14.56,800,2,12.50,700,1,14.60,700,1,12.46,200,2,14.68,1500,3,12.43,700,1,14.69,100,1,12.42,700,1,14.72,100,1,12.37,700,1,14.89,100,1,ARL,320486925
1469,2025-07-17T15:58:14.710787891Z,2025-07-17T15:58:14.710622495Z,160,2,1108,A,A,11,15.06,100,130,165396,267659178,13.04,2,1,14.10,2,1,13.03,100,1,14.26,100,1,13.02,100,1,14.28,100,1,12.73,100,1,14.40,100,1,12.71,100,1,14.56,800,2,12.50,700,1,14.60,700,1,12.46,200,2,14.68,1500,3,12.43,700,1,14.69,100,1,12.42,700,1,14.72,100,1,12.37,700,1,14.89,100,1,ARL,320487357
1470,2025-07-17T15:58:15.564070256Z,2025-07-17T15:58:15.563904700Z,160,2,1108,C,A,6,14.68,100,0,165556,267672469,13.04,2,1,14.10,2,1,13.03,100,1,14.26,100,1,13.02,100,1,14.28,100,1,12.73,100,1,14.40,100,1,12.71,100,1,14.56,800,2,12.50,700,1,14.60,700,1,12.46,200,2,14.68,1400,2,12.43,700,1,14.69,100,1,12.42,700,1,14.72,100,1,12.37,700,1,14.89,100,1,ARL,320484781
1471,2025-07-17T15:58:15.564070256Z,2025-07-17T15:58:15.563904700Z,160,2,1108,A,A,9,14.87,100,130,165556,267672469,13.04,2,1,14.10,2,1,13.03,100,1,14.26,100,1,13.02,100,1,14.28,100,1,12.73,100,1,14.40,100,1,12.71,100,1,14.56,800,2,12.50,700,1,14.60,700,1,12.46,200,2,14.68,1400,2,12.43,700,1,14.69,100,1,12.42,700,1,14.72,100,1,12.37,700,1,14.87,100,1,ARL,320504473
1472,2025-07-17T15:58:15.577719796Z,2025-07-17T15:58:15.577554368Z,160,2,1108,C,A,7,14.69,100,0,165428,267672549,13.04,2,1,14.10,2,1,13.03,100,1,14.26,100,1,13.02,100,1,14.28,100,1,12.73,100,1,14.40,100,1,12.71,100,1,14.56,800,2,12.50,700,1,14.60,700,1,12.46,200,2,14.68,1400,2,12.43,700,1,14.72,100,1,12.42,700,1,14.87,100,1,12.37,700,1,14.89,100,1,ARL,320484825
1473,2025-07-17T15:58:15.577719796Z,2025-07-17T15:58:15.577554368Z,160,2,1108,A,A,9,14.88,100,130,165428,267672549,13.04,2,1,14.10,2,1,13.03,100,1,14.26,100,1,13.02,100,1,14.28,100,1,12.73,100,1,14.40,100,1,12.71,100,1,14.56,800,2,12.50,700,1,14.60,700,1,12.46,200,2,14.68,1400,2,12.43,700,1,14.72,100,1,12.42,700,1,14.87,100,1,12.37,700,1,14.88,100,1,ARL,320504609
1474,2025-07-17T15:58:16.502080515Z,2025-07-17T15:58:16.501915292Z,160,2,1108,A,A,1,14.11,100,130,165223,267685252,13.04,2,1,14.10,2,1,13.03,100,1,14.11,100,1,13.02,100,1,14.26,100,1,12.73,100,1,14.28,100,1,12.71,100,1,14.40,100,1,12.50,700,1,14.56,800,2,12.46,200,2,14.60,700,1,12.43,700,1,14.68,1400,2,12.42,700,1,14.72,100,1,12.37,700,1,14.87,100,1,ARL,320519893
1475,2025-07-17T15:58:19.965200980Z,2025-07-17T15:58:19.965034325Z,160,2,1108,A,A,0,13.94,15,130,166655,267738403,13.04,2,1,13.94,15,1,13.03,100,1,14.10,2,1,13.02,100,1,14.11,100,1,12.73,100,1,14.26,100,1,12.71,100,1,14.28,100,1,12.50,700,1,14.40,100,1,12.46,200,2,14.56,800,2,12.43,700,1,14.60,700,1,12.42,700,1,14.68,1400,2,12.37,700,1,14.72,100,1,ARL,320588689
1476,2025-07-17T15:58:20.237833402Z,2025-07-17T15:58:20.237668047Z,160,2,1108,C,A,2,14.11,100,0,165355,267745213,13.04,2,1,13.94,15,1,13.03,100,1,14.10,2,1,13.02,100,1,14.26,100,1,12.73,100,1,14.28,100,1,12.71,100,1,14.40,100,1,12.50,700,1,14.56,800,2,12.46,200,2,14.60,700,1,12.43,700,1,14.68,1400,2,12.42,700,1,14.72,100,1,12.37,700,1,14.87,100,1,ARL,320519893
1477,2025-07-17T15:58:20.237833402Z,2025-07-17T15:58:20.237668047Z,160,2,1108,A,A,1,13.95,100,130,165355,267745213,13.04,2,1,13.94,15,1,13.03,100,1,13.95,100,1,13.02,100,1,14.10,2,1,12.73,100,1,14.26,100,1,12.71,100,1,14.28,100,1,12.50,700,1,14.40,100,1,12.46,200,2,14.56,800,2,12.43,700,1,14.60,700,1,12.42,700,1,14.68,1400,2,12.37,700,1,14.72,100,1,ARL,320595817
1478,2025-07-17T15:58:20.705512171Z,2025-07-17T15:58:20.705344578Z,160,2,1108,C,A,0,13.94,15,128,167593,267754327,13.04,2,1,13.95,100,1,13.03,100,1,14.10,2,1,13.02,100,1,14.26,100,1,12.73,100,1,14.28,100,1,12.71,100,1,14.40,100,1,12.50,700,1,14.56,800,2,12.46,200,2,14.60,700,1,12.43,700,1,14.68,1400,2,12.42,700,1,14.72,100,1,12.37,700,1,14.87,100,1,ARL,320588689
1479,2025-07-17T15:58:30.800053062Z,2025-07-17T15:58:30.799887713Z,160,2,1108,A,A,0,13.89,15,130,165349,267913947,13.04,2,1,13.89,15,1,13.03,100,1,13.95,100,1,13.02,100,1,14.10,2,1,12.73,100,1,14.26,100,1,12.71,100,1,14.28,100,1,12.50,700,1,14.40,100,1,12.46,200,2,14.56,800,2,12.43,700,1,14.60,700,1,12.42,700,1,14.68,1400,2,12.37,700,1,14.72,100,1,ARL,320833897
1480,2025-07-17T15:58:30.905657319Z,2025-07-17T15:58:30.905491759Z,160,2,1108,C,A,1,13.95,100,0,165560,267919515,13.04,2,1,13.89,15,1,13.03,100,1,14.10,2,1,13.02,100,1,14.26,100,1,12.73,100,1,14.28,100,1,12.71,100,1,14.40,100,1,12.50,700,1,14.56,800,2,12.46,200,2,14.60,700,1,12.43,700,1,14.68,1400,2,12.42,700,1,14.72,100,1,12.37,700,1,14.87,100,1,ARL,320595817
1481,2025-07-17T15:58:30.905657319Z,2025-07-17T15:58:30.905491759Z,160,2,1108,A,A,1,13.90,100,130,165560,267919515,13.04,2,1,13.89,15,1,13.03,100,1,13.90,100,1,13.02,100,1,14.10,2,1,12.73,100,1,14.26,100,1,12.71,100,1,14.28,100,1,12.50,700,1,14.40,100,1,12.46,200,2,14.56,800,2,12.43,700,1,14.60,700,1,12.42,700,1,14.68,1400,2,12.37,700,1,14.72,100,1,ARL,320839125
1482,2025-07-17T15:58:30.906412286Z,2025-07-17T15:58:30.906246950Z,160,2,1108,C,A,14,15.06,100,0,165336,267919540,13.04,2,1,13.89,15,1,13.03,100,1,13.90,100,1,13.02,100,1,14.10,2,1,12.73,100,1,14.26,100,1,12.71,100,1,14.28,100,1,12.50,700,1,14.40,100,1,12.46,200,2,14.56,800,2,12.43,700,1,14.60,700,1,12.42,700,1,14.68,1400,2,12.37,700,1,14.72,100,1,ARL,320487357
1483,2025-07-17T15:58:30.906412286Z,2025-07-17T15:58:30.906246950Z,160,2,1108,A,A,14,14.98,100,130,165336,267919540,13.04,2,1,13.89,15,1,13.03,100,1,13.90,100,1,13.02,100,1,14.10,2,1,12.73,100,1,14.26,100,1,12.71,100,1,14.28,100,1,12.50,700,1,14.40,100,1,12.46,200,2,14.56,800,2,12.43,700,1,14.60,700,1,12.42,700,1,14.68,1400,2,12.37,700,1,14.72,100,1,ARL,320839149
1484,2025-07-17T15:58:30.916726353Z,2025-07-17T15:58:30.916561264Z,160,2,1108,C,A,3,14.26,100,130,165089,267919917,13.04,2,1,13.89,15,1,13.03,100,1,13.90,100,1,13.02,100,1,14.10,2,1,12.73,100,1,14.28,100,1,12.71,100,1,14.40,100,1,12.50,700,1,14.56,800,2,12.46,200,2,14.60,700,1,12.43,700,1,14.68,1400,2,12.42,700,1,14.72,100,1,12.37,700,1,14.87,100,1,ARL,320487025
1485,2025-07-17T15:58:30.916784278Z,2025-07-17T15:58:30.916619122Z,160,2,1108,A,A,3,14.18,100,130,165156,267919919,13.04,2,1,13.89,15,1,13.03,100,1,13.90,100,1,13.02,100,1,14.10,2,1,12.73,100,1,14.18,100,1,12.71,100,1,14.28,100,1,12.50,700,1,14.40,100,1,12.46,200,2,14.56,800,2,12.43,700,1,14.60,700,1,12.42,700,1,14.68,1400,2,12.37,700,1,14.72,100,1,ARL,320839577
1486,2025-07-17T15:58:31.124388717Z,2025-07-17T15:58:31.124222733Z,160,2,1108,C,A,10,14.87,100,0,165984,267925564,13.04,2,1,13.89,15,1,13.03,100,1,13.90,100,1,13.02,100,1,14.10,2,1,12.73,100,1,14.18,100,1,12.71,100,1,14.28,100,1,12.50,700,1,14.40,100,1,12.46,200,2,14.56,800,2,12.43,700,1,14.60,700,1,12.42,700,1,14.68,1400,2,12.37,700,1,14.72,100,1,ARL,320504473
1487,2025-07-17T15:58:31.124388717Z,2025-07-17T15:58:31.124222733Z,160,2,1108,A,A,10,14.76,100,130,165984,267925564,13.04,2,1,13.89,15,1,13.03,100,1,13.90,100,1,13.02,100,1,14.10,2,1,12.73,100,1,14.18,100,1,12.71,100,1,14.28,100,1,12.50,700,1,14.40,100,1,12.46,200,2,14.56,800,2,12.43,700,1,14.60,700,1,12.42,700,1,14.68,1400,2,12.37,700,1,14.72,100,1,ARL,320845893
1488,2025-07-17T15:58:31.136439248Z,2025-07-17T15:58:31.136273403Z,160,2,1108,C,A,11,14.88,100,0,165845,267925951,13.04,2,1,13.89,15,1,13.03,100,1,13.90,100,1,13.02,100,1,14.10,2,1,12.73,100,1,14.18,100,1,12.71,100,1,14.28,100,1,12.50,700,1,14.40,100,1,12.46,200,2,14.56,800,2,12.43,700,1,14.60,700,1,12.42,700,1,14.68,1400,2,12.37,700,1,14.72,100,1,ARL,320504609
1489,2025-07-17T15:58:31.136439248Z,2025-07-17T15:58:31.136273403Z,160,2,1108,A,A,11,14.77,100,130,165845,267925951,13.04,2,1,13.89,15,1,13.03,100,1,13.90,100,1,13.02,100,1,14.10,2,1,12.73,100,1,14.18,100,1,12.71,100,1,14.28,100,1,12.50,700,1,14.40,100,1,12.46,200,2,14.56,800,2,12.43,700,1,14.60,700,1,12.42,700,1,14.68,1400,2,12.37,700,1,14.72,100,1,ARL,320846429
1490,2025-07-17T15:58:40.799952243Z,2025-07-17T15:58:40.799787018Z,160,2,1108,A,A,0,13.83,15,130,165225,268074431,13.04,2,1,13.83,15,1,13.03,100,1,13.89,15,1,13.02,100,1,13.90,100,1,12.73,100,1,14.10,2,1,12.71,100,1,14.18,100,1,12.50,700,1,14.28,100,1,12.46,200,2,14.40,100,1,12.43,700,1,14.56,800,2,12.42,700,1,14.60,700,1,12.37,700,1,14.68,1400,2,ARL,321038033
1491,2025-07-17T15:58:43.690244473Z,2025-07-17T15:58:43.690078924Z,160,2,1108,C,A,2,13.90,100,0,165549,268115228,13.04,2,1,13.83,15,1,13.03,100,1,13.89,15,1,13.02,100,1,14.10,2,1,12.73,100,1,14.18,100,1,12.71,100,1,14.28,100,1,12.50,700,1,14.40,100,1,12.46,200,2,14.56,800,2,12.43,700,1,14.60,700,1,12.42,700,1,14.68,1400,2,12.37,700,1,14.72,100,1,ARL,320839125
1492,2025-07-17T15:58:43.690244473Z,2025-07-17T15:58:43.690078924Z,160,2,1108,A,A,1,13.84,100,130,165549,268115228,13.04,2,1,13.83,15,1,13.03,100,1,13.84,100,1,13.02,100,1,13.89,15,1,12.73,100,1,14.10,2,1,12.71,100,1,14.18,100,1,12.50,700,1,14.28,100,1,12.46,200,2,14.40,100,1,12.43,700,1,14.56,800,2,12.42,700,1,14.60,700,1,12.37,700,1,14.68,1400,2,ARL,321096769
1493,2025-07-17T15:58:43.690988921Z,2025-07-17T15:58:43.690823184Z,160,2,1108,C,A,15,14.98,100,0,165737,268115235,13.04,2,1,13.83,15,1,13.03,100,1,13.84,100,1,13.02,100,1,13.89,15,1,12.73,100,1,14.10,2,1,12.71,100,1,14.18,100,1,12.50,700,1,14.28,100,1,12.46,200,2,14.40,100,1,12.43,700,1,14.56,800,2,12.42,700,1,14.60,700,1,12.37,700,1,14.68,1400,2,ARL,320839149
1494,2025-07-17T15:58:43.690988921Z,2025-07-17T15:58:43.690823184Z,160,2,1108,A,A,14,14.91,100,130,165737,268115235,13.04,2,1,13.83,15,1,13.03,100,1,13.84,100,1,13.02,100,1,13.89,15,1,12.73,100,1,14.10,2,1,12.71,100,1,14.18,100,1,12.50,700,1,14.28,100,1,12.46,200,2,14.40,100,1,12.43,700,1,14.56,800,2,12.42,700,1,14.60,700,1,12.37,700,1,14.68,1400,2,ARL,321096793
1495,2025-07-17T15:58:43.693394500Z,2025-07-17T15:58:43.693228946Z,160,2,1108,C,A,22,17.76,100,0,165554,268115265,13.04,2,1,13.83,15,1,13.03,100,1,13.84,100,1,13.02,100,1,13.89,15,1,12.73,100,1,14.10,2,1,12.71,100,1,14.18,100,1,12.50,700,1,14.28,100,1,12.46,200,2,14.40,100,1,12.43,700,1,14.56,800,2,12.42,700,1,14.60,700,1,12.37,700,1,14.68,1400,2,ARL,320486937
1496,2025-07-17T15:58:43.693394500Z,2025-07-17T15:58:43.693228946Z,160,2,1108,A,A,22,17.58,100,130,165554,268115265,13.04,2,1,13.83,15,1,13.03,100,1,13.84,100,1,13.02,100,1,13.89,15,1,12.73,100,1,14.10,2,1,12.71,100,1,14.18,100,1,12.50,700,1,14.28,100,1,12.46,200,2,14.40,100,1,12.43,700,1,14.56,800,2,12.42,700,1,14.60,700,1,12.37,700,1,14.68,1400,2,ARL,321096825
1497,2025-07-17T15:58:43.695055785Z,2025-07-17T15:58:43.694890264Z,160,2,1108,C,A,20,16.08,100,0,165521,268115287,13.04,2,1,13.83,15,1,13.03,100,1,13.84,100,1,13.02,100,1,13.89,15,1,12.73,100,1,14.10,2,1,12.71,100,1,14.18,100,1,12.50,700,1,14.28,100,1,12.46,200,2,14.40,100,1,12.43,700,1,14.56,800,2,12.42,700,1,14.60,700,1,12.37,700,1,14.68,1400,2,ARL,320486945
1498,2025-07-17T15:58:43.695055785Z,2025-07-17T15:58:43.694890264Z,160,2,1108,A,A,20,15.92,100,130,165521,268115287,13.04,2,1,13.83,15,1,13.03,100,1,13.84,100,1,13.02,100,1,13.89,15,1,12.73,100,1,14.10,2,1,12.71,100,1,14.18,100,1,12.50,700,1,14.28,100,1,12.46,200,2,14.40,100,1,12.43,700,1,14.56,800,2,12.42,700,1,14.60,700,1,12.37,700,1,14.68,1400,2,ARL,321096889
1499,2025-07-17T15:58:43.716437124Z,2025-07-17T15:58:43.716271172Z,160,2,1108,C,A,15,14.96,100,0,165952,268115456,13.04,2,1,13.83,15,1,13.03,100,1,13.84,100,1,13.02,100,1,13.89,15,1,12.73,100,1,14.10,2,1,12.71,100,1,14.18,100,1,12.50,700,1,14.28,100,1,12.46,200,2,14.40,100,1,12.43,700,1,14.56,800,2,12.42,700,1,14.60,700,1,12.37,700,1,14.68,1400,2,ARL,320487105
1500,2025-07-17T15:58:43.716437124Z,2025-07-17T15:58:43.716271172Z,160,2,1108,A,A,13,14.81,100,130,165952,268115456,13.04,2,1,13.83,15,1,13.03,100,1,13.84,100,1,13.02,100,1,13.89,15,1,12.73,100,1,14.10,2,1,12.71,100,1,14.18,100,1,12.50,700,1,14.28,100,1,12.46,200,2,14.40,100,1,12.43,700,1,14.56,800,2,12.42,700,1,14.60,700,1,12.37,700,1,14.68,1400,2,ARL,321097197
1501,2025-07-17T15:58:44.903740109Z,2025-07-17T15:58:44.903574654Z,160,2,1108,A,A,0,13.83,100,130,165455,268129040,13.04,2,1,13.83,115,2,13.03,100,1,13.84,100,1,13.02,100,1,13.89,15,1,12.73,100,1,14.10,2,1,12.71,100,1,14.18,100,1,12.50,700,1,14.28,100,1,12.46,200,2,14.40,100,1,12.43,700,1,14.56,800,2,12.42,700,1,14.60,700,1,12.37,700,1,14.68,1400,2,ARL,321114473
1502,2025-07-17T15:58:44.924114268Z,2025-07-17T15:58:44.923948853Z,160,2,1108,C,A,4,14.18,100,130,165415,268129217,13.04,2,1,13.83,115,2,13.03,100,1,13.84,100,1,13.02,100,1,13.89,15,1,12.73,100,1,14.10,2,1,12.71,100,1,14.28,100,1,12.50,700,1,14.40,100,1,12.46,200,2,14.56,800,2,12.43,700,1,14.60,700,1,12.42,700,1,14.68,1400,2,12.37,700,1,14.72,100,1,ARL,320839577
1503,2025-07-17T15:58:44.924165875Z,2025-07-17T15:58:44.924000519Z,160,2,1108,A,A,4,14.11,100,130,165356,268129218,13.04,2,1,13.83,115,2,13.03,100,1,13.84,100,1,13.02,100,1,13.89,15,1,12.73,100,1,14.10,2,1,12.71,100,1,14.11,100,1,12.50,700,1,14.28,100,1,12.46,200,2,14.40,100,1,12.43,700,1,14.56,800,2,12.42,700,1,14.60,700,1,12.37,700,1,14.68,1400,2,ARL,321114729
1504,2025-07-17T15:58:51.241342265Z,2025-07-17T15:58:51.241176997Z,160,2,1108,C,A,2,13.89,15,130,165268,268212338,13.04,2,1,13.83,115,2,13.03,100,1,13.84,100,1,13.02,100,1,14.10,2,1,12.73,100,1,14.11,100,1,12.71,100,1,14.28,100,1,12.50,700,1,14.40,100,1,12.46,200,2,14.56,800,2,12.43,700,1,14.60,700,1,12.42,700,1,14.68,1400,2,12.37,700,1,14.72,100,1,ARL,320833897
1505,2025-07-17T15:58:51.254127339Z,2025-07-17T15:58:51.253961905Z,160,2,1108,A,A,0,13.80,100,130,165434,268212497,13.04,2,1,13.80,100,1,13.03,100,1,13.83,115,2,13.02,100,1,13.84,100,1,12.73,100,1,14.10,2,1,12.71,100,1,14.11,100,1,12.50,700,1,14.28,100,1,12.46,200,2,14.40,100,1,12.43,700,1,14.56,800,2,12.42,700,1,14.60,700,1,12.37,700,1,14.68,1400,2,ARL,321225725
1506,2025-07-17T15:58:51.254871890Z,2025-07-17T15:58:51.254706004Z,160,2,1108,C,A,15,14.91,100,0,165886,268212499,13.04,2,1,13.80,100,1,13.03,100,1,13.83,115,2,13.02,100,1,13.84,100,1,12.73,100,1,14.10,2,1,12.71,100,1,14.11,100,1,12.50,700,1,14.28,100,1,12.46,200,2,14.40,100,1,12.43,700,1,14.56,800,2,12.42,700,1,14.60,700,1,12.37,700,1,14.68,1400,2,ARL,321096793
1507,2025-07-17T15:58:51.254871890Z,2025-07-17T15:58:51.254706004Z,160,2,1108,A,A,14,14.87,100,130,165886,268212499,13.04,2,1,13.80,100,1,13.03,100,1,13.83,115,2,13.02,100,1,13.84,100,1,12.73,100,1,14.10,2,1,12.71,100,1,14.11,100,1,12.50,700,1,14.28,100,1,12.46,200,2,14.40,100,1,12.43,700,1,14.56,800,2,12.42,700,1,14.60,700,1,12.37,700,1,14.68,1400,2,ARL,321225745
1508,2025-07-17T15:58:51.260753179Z,2025-07-17T15:58:51.260587778Z,160,2,1108,C,A,1,13.83,100,130,165401,268212534,13.04,2,1,13.80,100,1,13.03,100,1,13.83,15,1,13.02,100,1,13.84,100,1,12.73,100,1,14.10,2,1,12.71,100,1,14.11,100,1,12.50,700,1,14.28,100,1,12.46,200,2,14.40,100,1,12.43,700,1,14.56,800,2,12.42,700,1,14.60,700,1,12.37,700,1,14.68,1400,2,ARL,321114473
1509,2025-07-17T15:58:53.579628288Z,2025-07-17T15:58:53.579462029Z,160,2,1108,C,A,1,13.83,15,130,166259,268250290,13.04,2,1,13.80,100,1,13.03,100,1,13.84,100,1,13.02,100,1,14.10,2,1,12.73,100,1,14.11,100,1,12.71,100,1,14.28,100,1,12.50,700,1,14.40,100,1,12.46,200,2,14.56,800,2,12.43,700,1,14.60,700,1,12.42,700,1,14.68,1400,2,12.37,700,1,14.72,100,1,ARL,321038033
1510,2025-07-17T15:58:53.580217445Z,2025-07-17T15:58:53.580052014Z,160,2,1108,C,A,1,13.84,100,0,165431,268250346,13.04,2,1,13.80,100,1,13.03,100,1,14.10,2,1,13.02,100,1,14.11,100,1,12.73,100,1,14.28,100,1,12.71,100,1,14.40,100,1,12.50,700,1,14.56,800,2,12.46,200,2,14.60,700,1,12.43,700,1,14.68,1400,2,12.42,700,1,14.72,100,1,12.37,700,1,14.76,100,1,ARL,321096769
1511,2025-07-17T15:58:53.580217445Z,2025-07-17T15:58:53.580052014Z,160,2,1108,A,A,1,13.81,100,130,165431,268250346,13.04,2,1,13.80,100,1,13.03,100,1,13.81,100,1,13.02,100,1,14.10,2,1,12.73,100,1,14.11,100,1,12.71,100,1,14.28,100,1,12.50,700,1,14.40,100,1,12.46,200,2,14.56,800,2,12.43,700,1,14.60,700,1,12.42,700,1,14.68,1400,2,12.37,700,1,14.72,100,1,ARL,321272581
1512,2025-07-17T15:58:54.584124215Z,2025-07-17T15:58:54.583958582Z,160,2,1108,C,A,11,14.77,100,0,165633,268265585,13.04,2,1,13.80,100,1,13.03,100,1,13.81,100,1,13.02,100,1,14.10,2,1,12.73,100,1,14.11,100,1,12.71,100,1,14.28,100,1,12.50,700,1,14.40,100,1,12.46,200,2,14.56,800,2,12.43,700,1,14.60,700,1,12.42,700,1,14.68,1400,2,12.37,700,1,14.72,100,1,ARL,320846429
1513,2025-07-17T15:58:54.584124215Z,2025-07-17T15:58:54.583958582Z,160,2,1108,A,A,8,14.65,100,130,165633,268265585,13.04,2,1,13.80,100,1,13.03,100,1,13.81,100,1,13.02,100,1,14.10,2,1,12.73,100,1,14.11,100,1,12.71,100,1,14.28,100,1,12.50,700,1,14.40,100,1,12.46,200,2,14.56,800,2,12.43,700,1,14.60,700,1,12.42,700,1,14.65,100,1,12.37,700,1,14.68,1400,2,ARL,321293737
1514,2025-07-17T15:58:54.584260712Z,2025-07-17T15:58:54.584094980Z,160,2,1108,C,A,11,14.76,100,0,165732,268265586,13.04,2,1,13.80,100,1,13.03,100,1,13.81,100,1,13.02,100,1,14.10,2,1,12.73,100,1,14.11,100,1,12.71,100,1,14.28,100,1,12.50,700,1,14.40,100,1,12.46,200,2,14.56,800,2,12.43,700,1,14.60,700,1,12.42,700,1,14.65,100,1,12.37,700,1,14.68,1400,2,ARL,320845893
1515,2025-07-17T15:58:54.584260712Z,2025-07-17T15:58:54.584094980Z,160,2,1108,A,A,8,14.64,100,130,165732,268265586,13.04,2,1,13.80,100,1,13.03,100,1,13.81,100,1,13.02,100,1,14.10,2,1,12.73,100,1,14.11,100,1,12.71,100,1,14.28,100,1,12.50,700,1,14.40,100,1,12.46,200,2,14.56,800,2,12.43,700,1,14.60,700,1,12.42,700,1,14.64,100,1,12.37,700,1,14.65,100,1,ARL,321293741
1516,2025-07-17T15:58:55.305104029Z,2025-07-17T15:58:55.304938318Z,160,2,1108,A,A,0,13.78,100,130,165711,268277940,13.04,2,1,13.78,100,1,13.03,100,1,13.80,100,1,13.02,100,1,13.81,100,1,12.73,100,1,14.10,2,1,12.71,100,1,14.11,100,1,12.50,700,1,14.28,100,1,12.46,200,2,14.40,100,1,12.43,700,1,14.56,800,2,12.42,700,1,14.60,700,1,12.37,700,1,14.64,100,1,ARL,321309865
1517,2025-07-17T15:58:55.307508305Z,2025-07-17T15:58:55.307342971Z,160,2,1108,C,A,12,14.72,100,130,165334,268277999,13.04,2,1,13.78,100,1,13.03,100,1,13.80,100,1,13.02,100,1,13.81,100,1,12.73,100,1,14.10,2,1,12.71,100,1,14.11,100,1,12.50,700,1,14.28,100,1,12.46,200,2,14.40,100,1,12.43,700,1,14.56,800,2,12.42,700,1,14.60,700,1,12.37,700,1,14.64,100,1,ARL,312772061
1518,2025-07-17T15:58:55.307637209Z,2025-07-17T15:58:55.307472032Z,160,2,1108,A,A,8,14.58,100,130,165177,268278004,13.04,2,1,13.78,100,1,13.03,100,1,13.80,100,1,13.02,100,1,13.81,100,1,12.73,100,1,14.10,2,1,12.71,100,1,14.11,100,1,12.50,700,1,14.28,100,1,12.46,200,2,14.40,100,1,12.43,700,1,14.56,800,2,12.42,700,1,14.58,100,1,12.37,700,1,14.60,700,1,ARL,321309941
1519,2025-07-17T15:58:55.311899965Z,2025-07-17T15:58:55.311734700Z,160,2,1108,C,A,1,13.80,100,130,165265,268278030,13.04,2,1,13.78,100,1,13.03,100,1,13.81,100,1,13.02,100,1,14.10,2,1,12.73,100,1,14.11,100,1,12.71,100,1,14.28,100,1,12.50,700,1,14.40,100,1,12.46,200,2,14.56,800,2,12.43,700,1,14.58,100,1,12.42,700,1,14.60,700,1,12.37,700,1,14.64,100,1,ARL,321225725
1520,2025-07-17T15:58:58.668252306Z,2025-07-17T15:58:58.668086788Z,160,2,1108,C,A,1,13.81,100,0,165518,268321684,13.04,2,1,13.78,100,1,13.03,100,1,14.10,2,1,13.02,100,1,14.11,100,1,12.73,100,1,14.28,100,1,12.71,100,1,14.40,100,1,12.50,700,1,14.56,800,2,12.46,200,2,14.58,100,1,12.43,700,1,14.60,700,1,12.42,700,1,14.64,100,1,12.37,700,1,14.65,100,1,ARL,321272581
1521,2025-07-17T15:58:58.668252306Z,2025-07-17T15:58:58.668086788Z,160,2,1108,A,A,1,13.79,100,130,165518,268321684,13.04,2,1,13.78,100,1,13.03,100,1,13.79,100,1,13.02,100,1,14.10,2,1,12.73,100,1,14.11,100,1,12.71,100,1,14.28,100,1,12.50,700,1,14.40,100,1,12.46,200,2,14.56,800,2,12.43,700,1,14.58,100,1,12.42,700,1,14.60,700,1,12.37,700,1,14.64,100,1,ARL,321364281
1522,2025-07-17T15:59:03.613692913Z,2025-07-17T15:59:03.613527621Z,160,2,1108,A,A,0,13.72,15,130,165292,268437919,13.04,2,1,13.72,15,1,13.03,100,1,13.78,100,1,13.02,100,1,13.79,100,1,12.73,100,1,14.10,2,1,12.71,100,1,14.11,100,1,12.50,700,1,14.28,100,1,12.46,200,2,14.40,100,1,12.43,700,1,14.56,800,2,12.42,700,1,14.58,100,1,12.37,700,1,14.60,700,1,ARL,321500117
1523,2025-07-17T15:59:03.626346616Z,2025-07-17T15:59:03.626181384Z,160,2,1108,A,A,1,13.76,100,130,165232,268438110,13.04,2,1,13.72,15,1,13.03,100,1,13.76,100,1,13.02,100,1,13.78,100,1,12.73,100,1,13.79,100,1,12.71,100,1,14.10,2,1,12.50,700,1,14.11,100,1,12.46,200,2,14.28,100,1,12.43,700,1,14.40,100,1,12.42,700,1,14.56,800,2,12.37,700,1,14.58,100,1,ARL,321500317
1524,2025-07-17T15:59:03.627086888Z,2025-07-17T15:59:03.626920954Z,160,2,1108,C,A,15,14.87,100,0,165934,268438112,13.04,2,1,13.72,15,1,13.03,100,1,13.76,100,1,13.02,100,1,13.78,100,1,12.73,100,1,13.79,100,1,12.71,100,1,14.10,2,1,12.50,700,1,14.11,100,1,12.46,200,2,14.28,100,1,12.43,700,1,14.40,100,1,12.42,700,1,14.56,800,2,12.37,700,1,14.58,100,1,ARL,321225745
1525,2025-07-17T15:59:03.627086888Z,2025-07-17T15:59:03.626920954Z,160,2,1108,A,A,15,14.83,100,130,165934,268438112,13.04,2,1,13.72,15,1,13.03,100,1,13.76,100,1,13.02,100,1,13.78,100,1,12.73,100,1,13.79,100,1,12.71,100,1,14.10,2,1,12.50,700,1,14.11,100,1,12.46,200,2,14.28,100,1,12.43,700,1,14.40,100,1,12.42,700,1,14.56,800,2,12.37,700,1,14.58,100,1,ARL,321500333
1526,2025-07-17T15:59:03.628945278Z,2025-07-17T15:59:03.628779364Z,160,2,1108,C,A,16,14.89,100,0,165914,268438129,13.04,2,1,13.72,15,1,13.03,100,1,13.76,100,1,13.02,100,1,13.78,100,1,12.73,100,1,13.79,100,1,12.71,100,1,14.10,2,1,12.50,700,1,14.11,100,1,12.46,200,2,14.28,100,1,12.43,700,1,14.40,100,1,12.42,700,1,14.56,800,2,12.37,700,1,14.58,100,1,ARL,312771785
1527,2025-07-17T15:59:03.628945278Z,2025-07-17T15:59:03.628779364Z,160,2,1108,A,A,14,14.73,100,130,165914,268438129,13.04,2,1,13.72,15,1,13.03,100,1,13.76,100,1,13.02,100,1,13.78,100,1,12.73,100,1,13.79,100,1,12.71,100,1,14.10,2,1,12.50,700,1,14.11,100,1,12.46,200,2,14.28,100,1,12.43,700,1,14.40,100,1,12.42,700,1,14.56,800,2,12.37,700,1,14.58,100,1,ARL,321500349
1528,2025-07-17T15:59:03.633093258Z,2025-07-17T15:59:03.632928023Z,160,2,1108,C,A,2,13.78,100,130,165235,268438149,13.04,2,1,13.72,15,1,13.03,100,1,13.76,100,1,13.02,100,1,13.79,100,1,12.73,100,1,14.10,2,1,12.71,100,1,14.11,100,1,12.50,700,1,14.28,100,1,12.46,200,2,14.40,100,1,12.43,700,1,14.56,800,2,12.42,700,1,14.58,100,1,12.37,700,1,14.60,700,1,ARL,321309865
1529,2025-07-17T15:59:03.649282063Z,2025-07-17T15:59:03.649116452Z,160,2,1108,C,A,4,14.11,100,130,165611,268438330,13.04,2,1,13.72,15,1,13.03,100,1,13.76,100,1,13.02,100,1,13.79,100,1,12.73,100,1,14.10,2,1,12.71,100,1,14.28,100,1,12.50,700,1,14.40,100,1,12.46,200,2,14.56,800,2,12.43,700,1,14.58,100,1,12.42,700,1,14.60,700,1,12.37,700,1,14.64,100,1,ARL,321114729
1530,2025-07-17T15:59:03.649332873Z,2025-07-17T15:59:03.649167617Z,160,2,1108,A,A,3,14.04,100,130,165256,268438331,13.04,2,1,13.72,15,1,13.03,100,1,13.76,100,1,13.02,100,1,13.79,100,1,12.73,100,1,14.04,100,1,12.71,100,1,14.10,2,1,12.50,700,1,14.28,100,1,12.46,200,2,14.40,100,1,12.43,700,1,14.56,800,2,12.42,700,1,14.58,100,1,12.37,700,1,14.60,700,1,ARL,321500957
1531,2025-07-17T15:59:04.224000805Z,2025-07-17T15:59:04.223835151Z,160,2,1108,C,A,2,13.79,100,0,165654,268447989,13.04,2,1,13.72,15,1,13.03,100,1,13.76,100,1,13.02,100,1,14.04,100,1,12.73,100,1,14.10,2,1,12.71,100,1,14.28,100,1,12.50,700,1,14.40,100,1,12.46,200,2,14.56,800,2,12.43,700,1,14.58,100,1,12.42,700,1,14.60,700,1,12.37,700,1,14.64,100,1,ARL,321364281
1532,2025-07-17T15:59:04.224000805Z,2025-07-17T15:59:04.223835151Z,160,2,1108,A,A,1,13.73,100,130,165654,268447989,13.04,2,1,13.72,15,1,13.03,100,1,13.73,100,1,13.02,100,1,13.76,100,1,12.73,100,1,14.04,100,1,12.71,100,1,14.10,2,1,12.50,700,1,14.28,100,1,12.46,200,2,14.40,100,1,12.43,700,1,14.56,800,2,12.42,700,1,14.58,100,1,12.37,700,1,14.60,700,1,ARL,321511377
1533,2025-07-17T15:59:04.224749333Z,2025-07-17T15:59:04.224583946Z,160,2,1108,C,A,15,14.83,100,0,165387,268448014,13.04,2,1,13.72,15,1,13.03,100,1,13.73,100,1,13.02,100,1,13.76,100,1,12.73,100,1,14.04,100,1,12.71,100,1,14.10,2,1,12.50,700,1,14.28,100,1,12.46,200,2,14.40,100,1,12.43,700,1,14.56,800,2,12.42,700,1,14.58,100,1,12.37,700,1,14.60,700,1,ARL,321500333
1534,2025-07-17T15:59:04.224749333Z,2025-07-17T15:59:04.224583946Z,160,2,1108,A,A,14,14.79,100,130,165387,268448014,13.04,2,1,13.72,15,1,13.03,100,1,13.73,100,1,13.02,100,1,13.76,100,1,12.73,100,1,14.04,100,1,12.71,100,1,14.10,2,1,12.50,700,1,14.28,100,1,12.46,200,2,14.40,100,1,12.43,700,1,14.56,800,2,12.42,700,1,14.58,100,1,12.37,700,1,14.60,700,1,ARL,321511477
1535,2025-07-17T15:59:04.799998642Z,2025-07-17T15:59:04.799833206Z,160,2,1108,C,A,0,13.72,15,130,165436,268457531,13.04,2,1,13.73,100,1,13.03,100,1,13.76,100,1,13.02,100,1,14.04,100,1,12.73,100,1,14.10,2,1,12.71,100,1,14.28,100,1,12.50,700,1,14.40,100,1,12.46,200,2,14.56,800,2,12.43,700,1,14.58,100,1,12.42,700,1,14.60,700,1,12.37,700,1,14.64,100,1,ARL,321500117
1536,2025-07-17T16:00:13.989937414Z,2025-07-17T16:00:13.989771852Z,160,2,1108,C,A,3,14.10,2,0,165562,269514876,13.04,2,1,13.73,100,1,13.03,100,1,13.76,100,1,13.02,100,1,14.04,100,1,12.73,100,1,14.28,100,1,12.71,100,1,14.40,100,1,12.50,700,1,14.56,800,2,12.46,200,2,14.58,100,1,12.43,700,1,14.60,700,1,12.42,700,1,14.64,100,1,12.37,700,1,14.65,100,1,ARL,316098525
1537,2025-07-17T16:00:13.989937414Z,2025-07-17T16:00:13.989771852Z,160,2,1108,A,A,2,14.01,2,130,165562,269514876,13.04,2,1,13.73,100,1,13.03,100,1,13.76,100,1,13.02,100,1,14.01,2,1,12.73,100,1,14.04,100,1,12.71,100,1,14.28,100,1,12.50,700,1,14.40,100,1,12.46,200,2,14.56,800,2,12.43,700,1,14.58,100,1,12.42,700,1,14.60,700,1,12.37,700,1,14.64,100,1,ARL,322898193
1538,2025-07-17T16:00:28.803015930Z,2025-07-17T16:00:28.802849928Z,160,2,1108,A,A,0,13.72,15,130,166002,269765653,13.04,2,1,13.72,15,1,13.03,100,1,13.73,100,1,13.02,100,1,13.76,100,1,12.73,100,1,14.01,2,1,12.71,100,1,14.04,100,1,12.50,700,1,14.28,100,1,12.46,200,2,14.40,100,1,12.43,700,1,14.56,800,2,12.42,700,1,14.58,100,1,12.37,700,1,14.60,700,1,ARL,323238809
1539,2025-07-17T16:00:32.549412616Z,2025-07-17T16:00:32.549247168Z,160,2,1108,A,A,2,13.74,100,130,165448,269878282,13.04,2,1,13.72,15,1,13.03,100,1,13.73,100,1,13.02,100,1,13.74,100,1,12.73,100,1,13.76,100,1,12.71,100,1,14.01,2,1,12.50,700,1,14.04,100,1,12.46,200,2,14.28,100,1,12.43,700,1,14.40,100,1,12.42,700,1,14.56,800,2,12.37,700,1,14.58,100,1,ARL,323370569
1540,2025-07-17T16:00:32.560989093Z,2025-07-17T16:00:32.560823786Z,160,2,1108,C,A,3,13.76,100,130,165307,269878639,13.04,2,1,13.72,15,1,13.03,100,1,13.73,100,1,13.02,100,1,13.74,100,1,12.73,100,1,14.01,2,1,12.71,100,1,14.04,100,1,12.50,700,1,14.28,100,1,12.46,200,2,14.40,100,1,12.43,700,1,14.56,800,2,12.42,700,1,14.58,100,1,12.37,700,1,14.60,700,1,ARL,321500317
1541,2025-07-17T16:00:35.513164458Z,2025-07-17T16:00:35.512999155Z,160,2,1108,A,A,0,13.69,15,130,165303,269940539,13.04,2,1,13.69,15,1,13.03,100,1,13.72,15,1,13.02,100,1,13.73,100,1,12.73,100,1,13.74,100,1,12.71,100,1,14.01,2,1,12.50,700,1,14.04,100,1,12.46,200,2,14.28,100,1,12.43,700,1,14.40,100,1,12.42,700,1,14.56,800,2,12.37,700,1,14.58,100,1,ARL,323455221
1542,2025-07-17T16:00:42.614229184Z,2025-07-17T16:00:42.614063415Z,160,2,1108,C,A,2,13.73,100,0,165769,270051089,13.04,2,1,13.69,15,1,13.03,100,1,13.72,15,1,13.02,100,1,13.74,100,1,12.73,100,1,14.01,2,1,12.71,100,1,14.04,100,1,12.50,700,1,14.28,100,1,12.46,200,2,14.40,100,1,12.43,700,1,14.56,800,2,12.42,700,1,14.58,100,1,12.37,700,1,14.60,700,1,ARL,321511377
1543,2025-07-17T16:00:42.614229184Z,2025-07-17T16:00:42.614063415Z,160,2,1108,A,A,1,13.70,100,130,165769,270051089,13.04,2,1,13.69,15,1,13.03,100,1,13.70,100,1,13.02,100,1,13.72,15,1,12.73,100,1,13.74,100,1,12.71,100,1,14.01,2,1,12.50,700,1,14.04,100,1,12.46,200,2,14.28,100,1,12.43,700,1,14.40,100,1,12.42,700,1,14.56,800,2,12.37,700,1,14.58,100,1,ARL,323599605
1544,2025-07-17T16:00:42.614254199Z,2025-07-17T16:00:42.614088947Z,160,2,1108,A,A,2,13.72,100,130,165252,270051090,13.04,2,1,13.69,15,1,13.03,100,1,13.70,100,1,13.02,100,1,13.72,115,2,12.73,100,1,13.74,100,1,12.71,100,1,14.01,2,1,12.50,700,1,14.04,100,1,12.46,200,2,14.28,100,1,12.43,700,1,14.40,100,1,12.42,700,1,14.56,800,2,12.37,700,1,14.58,100,1,ARL,323599609
1545,2025-07-17T16:00:42.614396214Z,2025-07-17T16:00:42.614231125Z,160,2,1108,C,A,3,13.74,100,130,165089,270051092,13.04,2,1,13.69,15,1,13.03,100,1,13.70,100,1,13.02,100,1,13.72,115,2,12.73,100,1,14.01,2,1,12.71,100,1,14.04,100,1,12.50,700,1,14.28,100,1,12.46,200,2,14.40,100,1,12.43,700,1,14.56,800,2,12.42,700,1,14.58,100,1,12.37,700,1,14.60,700,1,ARL,323370569
1546,2025-07-17T16:00:42.616178962Z,2025-07-17T16:00:42.616013371Z,160,2,1108,C,A,15,14.81,100,0,165591,270051093,13.04,2,1,13.69,15,1,13.03,100,1,13.70,100,1,13.02,100,1,13.72,115,2,12.73,100,1,14.01,2,1,12.71,100,1,14.04,100,1,12.50,700,1,14.28,100,1,12.46,200,2,14.40,100,1,12.43,700,1,14.56,800,2,12.42,700,1,14.58,100,1,12.37,700,1,14.60,700,1,ARL,321097197
1547,2025-07-17T16:00:42.616178962Z,2025-07-17T16:00:42.616013371Z,160,2,1108,A,A,12,14.66,100,130,165591,270051093,13.04,2,1,13.69,15,1,13.03,100,1,13.70,100,1,13.02,100,1,13.72,115,2,12.73,100,1,14.01,2,1,12.71,100,1,14.04,100,1,12.50,700,1,14.28,100,1,12.46,200,2,14.40,100,1,12.43,700,1,14.56,800,2,12.42,700,1,14.58,100,1,12.37,700,1,14.60,700,1,ARL,323599625
1548,2025-07-17T16:00:42.616321879Z,2025-07-17T16:00:42.616156310Z,160,2,1108,C,A,20,15.92,100,0,165569,270051094,13.04,2,1,13.69,15,1,13.03,100,1,13.70,100,1,13.02,100,1,13.72,115,2,12.73,100,1,14.01,2,1,12.71,100,1,14.04,100,1,12.50,700,1,14.28,100,1,12.46,200,2,14.40,100,1,12.43,700,1,14.56,800,2,12.42,700,1,14.58,100,1,12.37,700,1,14.60,700,1,ARL,321096889
1549,2025-07-17T16:00:42.616321879Z,2025-07-17T16:00:42.616156310Z,160,2,1108,A,A,19,15.76,100,130,165569,270051094,13.04,2,1,13.69,15,1,13.03,100,1,13.70,100,1,13.02,100,1,13.72,115,2,12.73,100,1,14.01,2,1,12.71,100,1,14.04,100,1,12.50,700,1,14.28,100,1,12.46,200,2,14.40,100,1,12.43,700,1,14.56,800,2,12.42,700,1,14.58,100,1,12.37,700,1,14.60,700,1,ARL,323599629
1550,2025-07-17T16:00:42.616352247Z,2025-07-17T16:00:42.616186901Z,160,2,1108,C,A,23,17.58,100,0,165346,270051095,13.04,2,1,13.69,15,1,13.03,100,1,13.70,100,1,13.02,100,1,13.72,115,2,12.73,100,1,14.01,2,1,12.71,100,1,14.04,100,1,12.50,700,1,14.28,100,1,12.46,200,2,14.40,100,1,12.43,700,1,14.56,800,2,12.42,700,1,14.58,100,1,12.37,700,1,14.60,700,1,ARL,321096825
1551,2025-07-17T16:00:42.616352247Z,2025-07-17T16:00:42.616186901Z,160,2,1108,A,A,23,17.40,100,130,165346,270051095,13.04,2,1,13.69,15,1,13.03,100,1,13.70,100,1,13.02,100,1,13.72,115,2,12.73,100,1,14.01,2,1,12.71,100,1,14.04,100,1,12.50,700,1,14.28,100,1,12.46,200,2,14.40,100,1,12.43,700,1,14.56,800,2,12.42,700,1,14.58,100,1,12.37,700,1,14.60,700,1,ARL,323599633
1552,2025-07-17T16:00:42.636761176Z,2025-07-17T16:00:42.636595817Z,160,2,1108,C,A,4,14.04,100,130,165359,270051179,13.04,2,1,13.69,15,1,13.03,100,1,13.70,100,1,13.02,100,1,13.72,115,2,12.73,100,1,14.01,2,1,12.71,100,1,14.28,100,1,12.50,700,1,14.40,100,1,12.46,200,2,14.56,800,2,12.43,700,1,14.58,100,1,12.42,700,1,14.60,700,1,12.37,700,1,14.64,100,1,ARL,321500957
1553,2025-07-17T16:00:42.636814704Z,2025-07-17T16:00:42.636649389Z,160,2,1108,A,A,3,13.97,100,130,165315,270051181,13.04,2,1,13.69,15,1,13.03,100,1,13.70,100,1,13.02,100,1,13.72,115,2,12.73,100,1,13.97,100,1,12.71,100,1,14.01,2,1,12.50,700,1,14.28,100,1,12.46,200,2,14.40,100,1,12.43,700,1,14.56,800,2,12.42,700,1,14.58,100,1,12.37,700,1,14.60,700,1,ARL,323599765
1554,2025-07-17T16:00:46.803262460Z,2025-07-17T16:00:46.803097192Z,160,2,1108,C,A,2,13.72,15,130,165268,270102799,13.04,2,1,13.69,15,1,13.03,100,1,13.70,100,1,13.02,100,1,13.72,100,1,12.73,100,1,13.97,100,1,12.71,100,1,14.01,2,1,12.50,700,1,14.28,100,1,12.46,200,2,14.40,100,1,12.43,700,1,14.56,800,2,12.42,700,1,14.58,100,1,12.37,700,1,14.60,700,1,ARL,323238809
1555,2025-07-17T16:00:49.255631264Z,2025-07-17T16:00:49.255465939Z,160,2,1108,A,A,0,13.66,15,130,165325,270140405,13.04,2,1,13.66,15,1,13.03,100,1,13.69,15,1,13.02,100,1,13.70,100,1,12.73,100,1,13.72,100,1,12.71,100,1,13.97,100,1,12.50,700,1,14.01,2,1,12.46,200,2,14.28,100,1,12.43,700,1,14.40,100,1,12.42,700,1,14.56,800,2,12.37,700,1,14.58,100,1,ARL,323720189
1556,2025-07-17T16:00:49.739644604Z,2025-07-17T16:00:49.739479408Z,160,2,1108,A,A,2,13.70,100,130,165196,270146528,13.04,2,1,13.66,15,1,13.03,100,1,13.69,15,1,13.02,100,1,13.70,200,2,12.73,100,1,13.72,100,1,12.71,100,1,13.97,100,1,12.50,700,1,14.01,2,1,12.46,200,2,14.28,100,1,12.43,700,1,14.40,100,1,12.42,700,1,14.56,800,2,12.37,700,1,14.58,100,1,ARL,323730309
1557,2025-07-17T16:00:49.745038261Z,2025-07-17T16:00:49.744872763Z,160,2,1108,C,A,2,13.70,100,0,165498,270146577,13.04,2,1,13.66,15,1,13.03,100,1,13.69,15,1,13.02,100,1,13.70,100,1,12.73,100,1,13.72,100,1,12.71,100,1,13.97,100,1,12.50,700,1,14.01,2,1,12.46,200,2,14.28,100,1,12.43,700,1,14.40,100,1,12.42,700,1,14.56,800,2,12.37,700,1,14.58,100,1,ARL,323599605
1558,2025-07-17T16:00:49.745038261Z,2025-07-17T16:00:49.744872763Z,160,2,1108,A,A,1,13.67,100,130,165498,270146577,13.04,2,1,13.66,15,1,13.03,100,1,13.67,100,1,13.02,100,1,13.69,15,1,12.73,100,1,13.70,100,1,12.71,100,1,13.72,100,1,12.50,700,1,13.97,100,1,12.46,200,2,14.01,2,1,12.43,700,1,14.28,100,1,12.42,700,1,14.40,100,1,12.37,700,1,14.56,800,2,ARL,323730353
1559,2025-07-17T16:00:49.745778725Z,2025-07-17T16:00:49.745613051Z,160,2,1108,C,A,17,14.79,100,0,165674,270146581,13.04,2,1,13.66,15,1,13.03,100,1,13.67,100,1,13.02,100,1,13.69,15,1,12.73,100,1,13.70,100,1,12.71,100,1,13.72,100,1,12.50,700,1,13.97,100,1,12.46,200,2,14.01,2,1,12.43,700,1,14.28,100,1,12.42,700,1,14.40,100,1,12.37,700,1,14.56,800,2,ARL,321511477
1560,2025-07-17T16:00:49.745778725Z,2025-07-17T16:00:49.745613051Z,160,2,1108,A,A,16,14.73,100,130,165674,270146581,13.04,2,1,13.66,15,1,13.03,100,1,13.67,100,1,13.02,100,1,13.69,15,1,12.73,100,1,13.70,100,1,12.71,100,1,13.72,100,1,12.50,700,1,13.97,100,1,12.46,200,2,14.01,2,1,12.43,700,1,14.28,100,1,12.42,700,1,14.40,100,1,12.37,700,1,14.56,800,2,ARL,323730369
1561,2025-07-17T16:00:49.746422142Z,2025-07-17T16:00:49.746256906Z,160,2,1108,C,A,4,13.72,100,130,165236,270146586,13.04,2,1,13.66,15,1,13.03,100,1,13.67,100,1,13.02,100,1,13.69,15,1,12.73,100,1,13.70,100,1,12.71,100,1,13.97,100,1,12.50,700,1,14.01,2,1,12.46,200,2,14.28,100,1,12.43,700,1,14.40,100,1,12.42,700,1,14.56,800,2,12.37,700,1,14.58,100,1,ARL,323599609
1562,2025-07-17T16:00:49.772631967Z,2025-07-17T16:00:49.772466772Z,160,2,1108,A,A,19,15.59,100,130,165195,270146838,13.04,2,1,13.66,15,1,13.03,100,1,13.67,100,1,13.02,100,1,13.69,15,1,12.73,100,1,13.70,100,1,12.71,100,1,13.97,100,1,12.50,700,1,14.01,2,1,12.46,200,2,14.28,100,1,12.43,700,1,14.40,100,1,12.42,700,1,14.56,800,2,12.37,700,1,14.58,100,1,ARL,323730697
1563,2025-07-17T16:00:49.772645303Z,2025-07-17T16:00:49.772479921Z,160,2,1108,C,A,21,15.86,100,130,165382,270146839,13.04,2,1,13.66,15,1,13.03,100,1,13.67,100,1,13.02,100,1,13.69,15,1,12.73,100,1,13.70,100,1,12.71,100,1,13.97,100,1,12.50,700,1,14.01,2,1,12.46,200,2,14.28,100,1,12.43,700,1,14.40,100,1,12.42,700,1,14.56,800,2,12.37,700,1,14.58,100,1,ARL,312771645
1564,2025-07-17T16:00:51.624811889Z,2025-07-17T16:00:51.624646272Z,160,2,1108,C,A,12,14.65,100,0,165617,270181394,13.04,2,1,13.66,15,1,13.03,100,1,13.67,100,1,13.02,100,1,13.69,15,1,12.73,100,1,13.70,100,1,12.71,100,1,13.97,100,1,12.50,700,1,14.01,2,1,12.46,200,2,14.28,100,1,12.43,700,1,14.40,100,1,12.42,700,1,14.56,800,2,12.37,700,1,14.58,100,1,ARL,321293737
1565,2025-07-17T16:00:51.624811889Z,2025-07-17T16:00:51.624646272Z,160,2,1108,A,A,8,14.54,100,130,165617,270181394,13.04,2,1,13.66,15,1,13.03,100,1,13.67,100,1,13.02,100,1,13.69,15,1,12.73,100,1,13.70,100,1,12.71,100,1,13.97,100,1,12.50,700,1,14.01,2,1,12.46,200,2,14.28,100,1,12.43,700,1,14.40,100,1,12.42,700,1,14.54,100,1,12.37,700,1,14.56,800,2,ARL,323775433
1566,2025-07-17T16:00:51.625372516Z,2025-07-17T16:00:51.625206675Z,160,2,1108,C,A,12,14.64,100,0,165841,270181399,13.04,2,1,13.66,15,1,13.03,100,1,13.67,100,1,13.02,100,1,13.69,15,1,12.73,100,1,13.70,100,1,12.71,100,1,13.97,100,1,12.50,700,1,14.01,2,1,12.46,200,2,14.28,100,1,12.43,700,1,14.40,100,1,12.42,700,1,14.54,100,1,12.37,700,1,14.56,800,2,ARL,321293741
1567,2025-07-17T16:00:51.625372516Z,2025-07-17T16:00:51.625206675Z,160,2,1108,A,A,8,14.53,100,130,165841,270181399,13.04,2,1,13.66,15,1,13.03,100,1,13.67,100,1,13.02,100,1,13.69,15,1,12.73,100,1,13.70,100,1,12.71,100,1,13.97,100,1,12.50,700,1,14.01,2,1,12.46,200,2,14.28,100,1,12.43,700,1,14.40,100,1,12.42,700,1,14.53,100,1,12.37,700,1,14.54,100,1,ARL,323775457
1568,2025-07-17T16:00:53.749335010Z,2025-07-17T16:00:53.749169565Z,160,2,1108,A,A,1,13.67,100,130,165445,270204567,13.04,2,1,13.66,15,1,13.03,100,1,13.67,200,2,13.02,100,1,13.69,15,1,12.73,100,1,13.70,100,1,12.71,100,1,13.97,100,1,12.50,700,1,14.01,2,1,12.46,200,2,14.28,100,1,12.43,700,1,14.40,100,1,12.42,700,1,14.53,100,1,12.37,700,1,14.54,100,1,ARL,323803301
1569,2025-07-17T16:00:53.755966680Z,2025-07-17T16:00:53.755801462Z,160,2,1108,C,A,3,13.70,100,130,165218,270204616,13.04,2,1,13.66,15,1,13.03,100,1,13.67,200,2,13.02,100,1,13.69,15,1,12.73,100,1,13.97,100,1,12.71,100,1,14.01,2,1,12.50,700,1,14.28,100,1,12.46,200,2,14.40,100,1,12.43,700,1,14.53,100,1,12.42,700,1,14.54,100,1,12.37,700,1,14.56,800,2,ARL,323730309
1570,2025-07-17T16:01:00.801342739Z,2025-07-17T16:01:00.801177403Z,160,2,1108,C,A,2,13.69,15,130,165336,270319932,13.04,2,1,13.66,15,1,13.03,100,1,13.67,200,2,13.02,100,1,13.97,100,1,12.73,100,1,14.01,2,1,12.71,100,1,14.28,100,1,12.50,700,1,14.40,100,1,12.46,200,2,14.53,100,1,12.43,700,1,14.54,100,1,12.42,700,1,14.56,800,2,12.37,700,1,14.58,100,1,ARL,323455221
1571,2025-07-17T16:01:10.802877570Z,2025-07-17T16:01:10.802712247Z,160,2,1108,A,A,0,13.62,15,130,165323,270493149,13.04,2,1,13.62,15,1,13.03,100,1,13.66,15,1,13.02,100,1,13.67,200,2,12.73,100,1,13.97,100,1,12.71,100,1,14.01,2,1,12.50,700,1,14.28,100,1,12.46,200,2,14.40,100,1,12.43,700,1,14.53,100,1,12.42,700,1,14.54,100,1,12.37,700,1,14.56,800,2,ARL,324161541
1572,2025-07-17T16:01:11.418837472Z,2025-07-17T16:01:11.418671671Z,160,2,1108,A,A,1,13.65,100,130,165801,270503944,13.04,2,1,13.62,15,1,13.03,100,1,13.65,100,1,13.02,100,1,13.66,15,1,12.73,100,1,13.67,200,2,12.71,100,1,13.97,100,1,12.50,700,1,14.01,2,1,12.46,200,2,14.28,100,1,12.43,700,1,14.40,100,1,12.42,700,1,14.53,100,1,12.37,700,1,14.54,100,1,ARL,324175569
1573,2025-07-17T16:01:11.425922184Z,2025-07-17T16:01:11.425757014Z,160,2,1108,C,A,3,13.67,100,130,165170,270504009,13.04,2,1,13.62,15,1,13.03,100,1,13.65,100,1,13.02,100,1,13.66,15,1,12.73,100,1,13.67,100,1,12.71,100,1,13.97,100,1,12.50,700,1,14.01,2,1,12.46,200,2,14.28,100,1,12.43,700,1,14.40,100,1,12.42,700,1,14.53,100,1,12.37,700,1,14.54,100,1,ARL,323803301
1574,2025-07-17T16:01:11.820753616Z,2025-07-17T16:01:11.820588141Z,160,2,1108,C,A,3,13.67,100,0,165475,270509970,13.04,2,1,13.62,15,1,13.03,100,1,13.65,100,1,13.02,100,1,13.66,15,1,12.73,100,1,13.97,100,1,12.71,100,1,14.01,2,1,12.50,700,1,14.28,100,1,12.46,200,2,14.40,100,1,12.43,700,1,14.53,100,1,12.42,700,1,14.54,100,1,12.37,700,1,14.56,800,2,ARL,323730353
1575,2025-07-17T16:01:11.820753616Z,2025-07-17T16:01:11.820588141Z,160,2,1108,A,A,1,13.63,100,130,165475,270509970,13.04,2,1,13.62,15,1,13.03,100,1,13.63,100,1,13.02,100,1,13.65,100,1,12.73,100,1,13.66,15,1,12.71,100,1,13.97,100,1,12.50,700,1,14.01,2,1,12.46,200,2,14.28,100,1,12.43,700,1,14.40,100,1,12.42,700,1,14.53,100,1,12.37,700,1,14.54,100,1,ARL,324186213
1576,2025-07-17T16:01:11.821515043Z,2025-07-17T16:01:11.821349600Z,160,2,1108,C,A,15,14.73,100,0,165443,270509983,13.04,2,1,13.62,15,1,13.03,100,1,13.63,100,1,13.02,100,1,13.65,100,1,12.73,100,1,13.66,15,1,12.71,100,1,13.97,100,1,12.50,700,1,14.01,2,1,12.46,200,2,14.28,100,1,12.43,700,1,14.40,100,1,12.42,700,1,14.53,100,1,12.37,700,1,14.54,100,1,ARL,323730369
1577,2025-07-17T16:01:11.821515043Z,2025-07-17T16:01:11.821349600Z,160,2,1108,A,A,15,14.69,100,130,165443,270509983,13.04,2,1,13.62,15,1,13.03,100,1,13.63,100,1,13.02,100,1,13.65,100,1,12.73,100,1,13.66,15,1,12.71,100,1,13.97,100,1,12.50,700,1,14.01,2,1,12.46,200,2,14.28,100,1,12.43,700,1,14.40,100,1,12.42,700,1,14.53,100,1,12.37,700,1,14.54,100,1,ARL,324186233
1578,2025-07-17T16:01:11.826399871Z,2025-07-17T16:01:11.826234488Z,160,2,1108,C,A,4,13.97,100,130,165383,270510142,13.04,2,1,13.62,15,1,13.03,100,1,13.63,100,1,13.02,100,1,13.65,100,1,12.73,100,1,13.66,15,1,12.71,100,1,14.01,2,1,12.50,700,1,14.28,100,1,12.46,200,2,14.40,100,1,12.43,700,1,14.53,100,1,12.42,700,1,14.54,100,1,12.37,700,1,14.56,800,2,ARL,323599765
1579,2025-07-17T16:01:11.826451447Z,2025-07-17T16:01:11.826286284Z,160,2,1108,A,A,4,13.90,100,130,165163,270510143,13.04,2,1,13.62,15,1,13.03,100,1,13.63,100,1,13.02,100,1,13.65,100,1,12.73,100,1,13.66,15,1,12.71,100,1,13.90,100,1,12.50,700,1,14.01,2,1,12.46,200,2,14.28,100,1,12.43,700,1,14.40,100,1,12.42,700,1,14.53,100,1,12.37,700,1,14.54,100,1,ARL,324186721
1580,2025-07-17T16:01:11.828630414Z,2025-07-17T16:01:11.828464891Z,160,2,1108,C,A,11,14.58,100,0,165523,270510182,13.04,2,1,13.62,15,1,13.03,100,1,13.63,100,1,13.02,100,1,13.65,100,1,12.73,100,1,13.66,15,1,12.71,100,1,13.90,100,1,12.50,700,1,14.01,2,1,12.46,200,2,14.28,100,1,12.43,700,1,14.40,100,1,12.42,700,1,14.53,100,1,12.37,700,1,14.54,100,1,ARL,321309941
1581,2025-07-17T16:01:11.828630414Z,2025-07-17T16:01:11.828464891Z,160,2,1108,A,A,8,14.43,100,130,165523,270510182,13.04,2,1,13.62,15,1,13.03,100,1,13.63,100,1,13.02,100,1,13.65,100,1,12.73,100,1,13.66,15,1,12.71,100,1,13.90,100,1,12.50,700,1,14.01,2,1,12.46,200,2,14.28,100,1,12.43,700,1,14.40,100,1,12.42,700,1,14.43,100,1,12.37,700,1,14.53,100,1,ARL,324186781
1582,2025-07-17T16:01:22.802518536Z,2025-07-17T16:01:22.802353061Z,160,2,1108,C,A,3,13.66,15,130,165475,270674903,13.04,2,1,13.62,15,1,13.03,100,1,13.63,100,1,13.02,100,1,13.65,100,1,12.73,100,1,13.90,100,1,12.71,100,1,14.01,2,1,12.50,700,1,14.28,100,1,12.46,200,2,14.40,100,1,12.43,700,1,14.43,100,1,12.42,700,1,14.53,100,1,12.37,700,1,14.54,100,1,ARL,323720189
1583,2025-07-17T16:01:32.804004639Z,2025-07-17T16:01:32.803839043Z,160,2,1108,A,A,0,13.60,15,130,165596,270824320,13.04,2,1,13.60,15,1,13.03,100,1,13.62,15,1,13.02,100,1,13.63,100,1,12.73,100,1,13.65,100,1,12.71,100,1,13.90,100,1,12.50,700,1,14.01,2,1,12.46,200,2,14.28,100,1,12.43,700,1,14.40,100,1,12.42,700,1,14.43,100,1,12.37,700,1,14.53,100,1,ARL,324619361
1584,2025-07-17T16:01:32.804274168Z,2025-07-17T16:01:32.804108576Z,160,2,1108,C,A,2,13.63,100,0,165592,270824323,13.04,2,1,13.60,15,1,13.03,100,1,13.62,15,1,13.02,100,1,13.65,100,1,12.73,100,1,13.90,100,1,12.71,100,1,14.01,2,1,12.50,700,1,14.28,100,1,12.46,200,2,14.40,100,1,12.43,700,1,14.43,100,1,12.42,700,1,14.53,100,1,12.37,700,1,14.54,100,1,ARL,324186213
1585,2025-07-17T16:01:32.804274168Z,2025-07-17T16:01:32.804108576Z,160,2,1108,A,A,1,13.61,100,130,165592,270824323,13.04,2,1,13.60,15,1,13.03,100,1,13.61,100,1,13.02,100,1,13.62,15,1,12.73,100,1,13.65,100,1,12.71,100,1,13.90,100,1,12.50,700,1,14.01,2,1,12.46,200,2,14.28,100,1,12.43,700,1,14.40,100,1,12.42,700,1,14.43,100,1,12.37,700,1,14.53,100,1,ARL,324619369
1586,2025-07-17T16:01:32.806299464Z,2025-07-17T16:01:32.806134020Z,160,2,1108,C,A,16,14.73,100,0,165444,270824400,13.04,2,1,13.60,15,1,13.03,100,1,13.61,100,1,13.02,100,1,13.62,15,1,12.73,100,1,13.65,100,1,12.71,100,1,13.90,100,1,12.50,700,1,14.01,2,1,12.46,200,2,14.28,100,1,12.43,700,1,14.40,100,1,12.42,700,1,14.43,100,1,12.37,700,1,14.53,100,1,ARL,321500349
1587,2025-07-17T16:01:32.806299464Z,2025-07-17T16:01:32.806134020Z,160,2,1108,A,A,12,14.57,100,130,165444,270824400,13.04,2,1,13.60,15,1,13.03,100,1,13.61,100,1,13.02,100,1,13.62,15,1,12.73,100,1,13.65,100,1,12.71,100,1,13.90,100,1,12.50,700,1,14.01,2,1,12.46,200,2,14.28,100,1,12.43,700,1,14.40,100,1,12.42,700,1,14.43,100,1,12.37,700,1,14.53,100,1,ARL,324619409
1588,2025-07-17T16:01:32.815913520Z,2025-07-17T16:01:32.815748258Z,160,2,1108,A,A,3,13.63,100,130,165262,270824657,13.04,2,1,13.60,15,1,13.03,100,1,13.61,100,1,13.02,100,1,13.62,15,1,12.73,100,1,13.63,100,1,12.71,100,1,13.65,100,1,12.50,700,1,13.90,100,1,12.46,200,2,14.01,2,1,12.43,700,1,14.28,100,1,12.42,700,1,14.40,100,1,12.37,700,1,14.43,100,1,ARL,324619837
1589,2025-07-17T16:01:32.822608966Z,2025-07-17T16:01:32.822443626Z,160,2,1108,C,A,4,13.65,100,130,165340,270824747,13.04,2,1,13.60,15,1,13.03,100,1,13.61,100,1,13.02,100,1,13.62,15,1,12.73,100,1,13.63,100,1,12.71,100,1,13.90,100,1,12.50,700,1,14.01,2,1,12.46,200,2,14.28,100,1,12.43,700,1,14.40,100,1,12.42,700,1,14.43,100,1,12.37,700,1,14.53,100,1,ARL,324175569
1590,2025-07-17T16:01:37.242690420Z,2025-07-17T16:01:37.242525208Z,160,2,1108,C,A,2,13.62,15,130,165212,270889017,13.04,2,1,13.60,15,1,13.03,100,1,13.61,100,1,13.02,100,1,13.63,100,1,12.73,100,1,13.90,100,1,12.71,100,1,14.01,2,1,12.50,700,1,14.28,100,1,12.46,200,2,14.40,100,1,12.43,700,1,14.43,100,1,12.42,700,1,14.53,100,1,12.37,700,1,14.54,100,1,ARL,324161541
1591,2025-07-17T16:01:40.605797765Z,2025-07-17T16:01:40.605632399Z,160,2,1108,A,A,1,13.61,100,130,165366,270946497,13.04,2,1,13.60,15,1,13.03,100,1,13.61,200,2,13.02,100,1,13.63,100,1,12.73,100,1,13.90,100,1,12.71,100,1,14.01,2,1,12.50,700,1,14.28,100,1,12.46,200,2,14.40,100,1,12.43,700,1,14.43,100,1,12.42,700,1,14.53,100,1,12.37,700,1,14.54,100,1,ARL,324782841
1592,2025-07-17T16:01:40.653738176Z,2025-07-17T16:01:40.653572805Z,160,2,1108,C,A,2,13.63,100,130,165371,270946779,13.04,2,1,13.60,15,1,13.03,100,1,13.61,200,2,13.02,100,1,13.90,100,1,12.73,100,1,14.01,2,1,12.71,100,1,14.28,100,1,12.50,700,1,14.40,100,1,12.46,200,2,14.43,100,1,12.43,700,1,14.53,100,1,12.42,700,1,14.54,100,1,12.37,700,1,14.56,800,2,ARL,324619837
1593,2025-07-17T16:01:47.565991684Z,2025-07-17T16:01:47.565825466Z,160,2,1108,A,A,0,13.57,15,128,166218,271062350,13.04,2,1,13.57,15,1,13.03,100,1,13.60,15,1,13.02,100,1,13.61,200,2,12.73,100,1,13.90,100,1,12.71,100,1,14.01,2,1,12.50,700,1,14.28,100,1,12.46,200,2,14.40,100,1,12.43,700,1,14.43,100,1,12.42,700,1,14.53,100,1,12.37,700,1,14.54,100,1,ARL,324934601
1594,2025-07-17T16:01:47.902969773Z,2025-07-17T16:01:47.902804446Z,160,2,1108,C,A,2,13.61,100,0,165327,271068098,13.04,2,1,13.57,15,1,13.03,100,1,13.60,15,1,13.02,100,1,13.61,100,1,12.73,100,1,13.90,100,1,12.71,100,1,14.01,2,1,12.50,700,1,14.28,100,1,12.46,200,2,14.40,100,1,12.43,700,1,14.43,100,1,12.42,700,1,14.53,100,1,12.37,700,1,14.54,100,1,ARL,324619369
1595,2025-07-17T16:01:47.902969773Z,2025-07-17T16:01:47.902804446Z,160,2,1108,A,A,1,13.58,100,130,165327,271068098,13.04,2,1,13.57,15,1,13.03,100,1,13.58,100,1,13.02,100,1,13.60,15,1,12.73,100,1,13.61,100,1,12.71,100,1,13.90,100,1,12.50,700,1,14.01,2,1,12.46,200,2,14.28,100,1,12.43,700,1,14.40,100,1,12.42,700,1,14.43,100,1,12.37,700,1,14.53,100,1,ARL,324942229
1596,2025-07-17T16:01:47.903711757Z,2025-07-17T16:01:47.903546622Z,160,2,1108,C,A,7,14.40,100,130,165135,271068105,13.04,2,1,13.57,15,1,13.03,100,1,13.58,100,1,13.02,100,1,13.60,15,1,12.73,100,1,13.61,100,1,12.71,100,1,13.90,100,1,12.50,700,1,14.01,2,1,12.46,200,2,14.28,100,1,12.43,700,1,14.43,100,1,12.42,700,1,14.53,100,1,12.37,700,1,14.54,100,1,ARL,289726421
1597,2025-07-17T16:01:47.903714323Z,2025-07-17T16:01:47.903548861Z,160,2,1108,C,A,15,14.69,100,0,165462,271068106,13.04,2,1,13.57,15,1,13.03,100,1,13.58,100,1,13.02,100,1,13.60,15,1,12.73,100,1,13.61,100,1,12.71,100,1,13.90,100,1,12.50,700,1,14.01,2,1,12.46,200,2,14.28,100,1,12.43,700,1,14.43,100,1,12.42,700,1,14.53,100,1,12.37,700,1,14.54,100,1,ARL,324186233
1598,2025-07-17T16:01:47.903714323Z,2025-07-17T16:01:47.903548861Z,160,2,1108,A,A,13,14.63,100,130,165462,271068106,13.04,2,1,13.57,15,1,13.03,100,1,13.58,100,1,13.02,100,1,13.60,15,1,12.73,100,1,13.61,100,1,12.71,100,1,13.90,100,1,12.50,700,1,14.01,2,1,12.46,200,2,14.28,100,1,12.43,700,1,14.43,100,1,12.42,700,1,14.53,100,1,12.37,700,1,14.54,100,1,ARL,324942257
1599,2025-07-17T16:01:47.904067686Z,2025-07-17T16:01:47.903902473Z,160,2,1108,A,A,6,14.19,100,130,165213,271068115,13.04,2,1,13.57,15,1,13.03,100,1,13.58,100,1,13.02,100,1,13.60,15,1,12.73,100,1,13.61,100,1,12.71,100,1,13.90,100,1,12.50,700,1,14.01,2,1,12.46,200,2,14.19,100,1,12.43,700,1,14.28,100,1,12.42,700,1,14.43,100,1,12.37,700,1,14.53,100,1,ARL,324942273
1600,2025-07-17T16:01:47.905355779Z,2025-07-17T16:01:47.905189816Z,160,2,1108,C,A,18,15.23,100,0,165963,271068134,13.04,2,1,13.57,15,1,13.03,100,1,13.58,100,1,13.02,100,1,13.60,15,1,12.73,100,1,13.61,100,1,12.71,100,1,13.90,100,1,12.50,700,1,14.01,2,1,12.46,200,2,14.19,100,1,12.43,700,1,14.28,100,1,12.42,700,1,14.43,100,1,12.37,700,1,14.53,100,1,ARL,282776017
1601,2025-07-17T16:01:47.905355779Z,2025-07-17T16:01:47.905189816Z,160,2,1108,A,A,17,14.94,100,130,165963,271068134,13.04,2,1,13.57,15,1,13.03,100,1,13.58,100,1,13.02,100,1,13.60,15,1,12.73,100,1,13.61,100,1,12.71,100,1,13.90,100,1,12.50,700,1,14.01,2,1,12.46,200,2,14.19,100,1,12.43,700,1,14.28,100,1,12.42,700,1,14.43,100,1,12.37,700,1,14.53,100,1,ARL,324942277
1602,2025-07-17T16:01:47.909479724Z,2025-07-17T16:01:47.909314303Z,160,2,1108,C,A,24,17.40,100,0,165421,271068173,13.04,2,1,13.57,15,1,13.03,100,1,13.58,100,1,13.02,100,1,13.60,15,1,12.73,100,1,13.61,100,1,12.71,100,1,13.90,100,1,12.50,700,1,14.01,2,1,12.46,200,2,14.19,100,1,12.43,700,1,14.28,100,1,12.42,700,1,14.43,100,1,12.37,700,1,14.53,100,1,ARL,323599633
1603,2025-07-17T16:01:47.909479724Z,2025-07-17T16:01:47.909314303Z,160,2,1108,A,A,24,17.25,100,130,165421,271068173,13.04,2,1,13.57,15,1,13.03,100,1,13.58,100,1,13.02,100,1,13.60,15,1,12.73,100,1,13.61,100,1,12.71,100,1,13.90,100,1,12.50,700,1,14.01,2,1,12.46,200,2,14.19,100,1,12.43,700,1,14.28,100,1,12.42,700,1,14.43,100,1,12.37,700,1,14.53,100,1,ARL,324942361
1604,2025-07-17T16:01:50.799100504Z,2025-07-17T16:01:50.798934838Z,160,2,1108,A,A,2,13.59,100,130,165666,271131418,13.04,2,1,13.57,15,1,13.03,100,1,13.58,100,1,13.02,100,1,13.59,100,1,12.73,100,1,13.60,15,1,12.71,100,1,13.61,100,1,12.50,700,1,13.90,100,1,12.46,200,2,14.01,2,1,12.43,700,1,14.19,100,1,12.42,700,1,14.28,100,1,12.37,700,1,14.43,100,1,ARL,325022101
1605,2025-07-17T16:01:50.805653961Z,2025-07-17T16:01:50.805488726Z,160,2,1108,C,A,4,13.61,100,130,165235,271131583,13.04,2,1,13.57,15,1,13.03,100,1,13.58,100,1,13.02,100,1,13.59,100,1,12.73,100,1,13.60,15,1,12.71,100,1,13.90,100,1,12.50,700,1,14.01,2,1,12.46,200,2,14.19,100,1,12.43,700,1,14.28,100,1,12.42,700,1,14.43,100,1,12.37,700,1,14.53,100,1,ARL,324782841
1606,2025-07-17T16:01:52.133063761Z,2025-07-17T16:01:52.132898568Z,160,2,1108,C,A,3,13.60,15,130,165193,271153294,13.04,2,1,13.57,15,1,13.03,100,1,13.58,100,1,13.02,100,1,13.59,100,1,12.73,100,1,13.90,100,1,12.71,100,1,14.01,2,1,12.50,700,1,14.19,100,1,12.46,200,2,14.28,100,1,12.43,700,1,14.43,100,1,12.42,700,1,14.53,100,1,12.37,700,1,14.54,100,1,ARL,324619361
1607,2025-07-17T16:01:53.137501962Z,2025-07-17T16:01:53.137336077Z,160,2,1108,A,A,0,13.55,15,130,165885,271200452,13.04,2,1,13.55,15,1,13.03,100,1,13.57,15,1,13.02,100,1,13.58,100,1,12.73,100,1,13.59,100,1,12.71,100,1,13.90,100,1,12.50,700,1,14.01,2,1,12.46,200,2,14.19,100,1,12.43,700,1,14.28,100,1,12.42,700,1,14.43,100,1,12.37,700,1,14.53,100,1,ARL,325109165
1608,2025-07-17T16:01:56.264154095Z,2025-07-17T16:01:56.263988198Z,160,2,1108,C,A,2,13.58,100,0,165897,271251019,13.04,2,1,13.55,15,1,13.03,100,1,13.57,15,1,13.02,100,1,13.59,100,1,12.73,100,1,13.90,100,1,12.71,100,1,14.01,2,1,12.50,700,1,14.19,100,1,12.46,200,2,14.28,100,1,12.43,700,1,14.43,100,1,12.42,700,1,14.53,100,1,12.37,700,1,14.54,100,1,ARL,324942229
1609,2025-07-17T16:01:56.264154095Z,2025-07-17T16:01:56.263988198Z,160,2,1108,A,A,1,13.56,100,130,165897,271251019,13.04,2,1,13.55,15,1,13.03,100,1,13.56,100,1,13.02,100,1,13.57,15,1,12.73,100,1,13.59,100,1,12.71,100,1,13.90,100,1,12.50,700,1,14.01,2,1,12.46,200,2,14.19,100,1,12.43,700,1,14.28,100,1,12.42,700,1,14.43,100,1,12.37,700,1,14.53,100,1,ARL,325176181
1610,2025-07-17T16:01:56.269623788Z,2025-07-17T16:01:56.269458197Z,160,2,1108,C,A,4,13.90,100,130,165591,271251357,13.04,2,1,13.55,15,1,13.03,100,1,13.56,100,1,13.02,100,1,13.57,15,1,12.73,100,1,13.59,100,1,12.71,100,1,14.01,2,1,12.50,700,1,14.19,100,1,12.46,200,2,14.28,100,1,12.43,700,1,14.43,100,1,12.42,700,1,14.53,100,1,12.37,700,1,14.54,100,1,ARL,324186721
1611,2025-07-17T16:01:56.269674232Z,2025-07-17T16:01:56.269508928Z,160,2,1108,A,A,4,13.83,100,130,165304,271251358,13.04,2,1,13.55,15,1,13.03,100,1,13.56,100,1,13.02,100,1,13.57,15,1,12.73,100,1,13.59,100,1,12.71,100,1,13.83,100,1,12.50,700,1,14.01,2,1,12.46,200,2,14.19,100,1,12.43,700,1,14.28,100,1,12.42,700,1,14.43,100,1,12.37,700,1,14.53,100,1,ARL,325176373
1612,2025-07-17T16:01:56.272340730Z,2025-07-17T16:01:56.272175169Z,160,2,1108,C,A,21,15.76,100,0,165561,271251490,13.04,2,1,13.55,15,1,13.03,100,1,13.56,100,1,13.02,100,1,13.57,15,1,12.73,100,1,13.59,100,1,12.71,100,1,13.83,100,1,12.50,700,1,14.01,2,1,12.46,200,2,14.19,100,1,12.43,700,1,14.28,100,1,12.42,700,1,14.43,100,1,12.37,700,1,14.53,100,1,ARL,323599629
1613,2025-07-17T16:01:56.272340730Z,2025-07-17T16:01:56.272175169Z,160,2,1108,A,A,21,15.60,100,130,165561,271251490,13.04,2,1,13.55,15,1,13.03,100,1,13.56,100,1,13.02,100,1,13.57,15,1,12.73,100,1,13.59,100,1,12.71,100,1,13.83,100,1,12.50,700,1,14.01,2,1,12.46,200,2,14.19,100,1,12.43,700,1,14.28,100,1,12.42,700,1,14.43,100,1,12.37,700,1,14.53,100,1,ARL,325176677
1614,2025-07-17T16:01:56.300889378Z,2025-07-17T16:01:56.300723805Z,160,2,1108,C,A,15,14.66,100,0,165573,271252044,13.04,2,1,13.55,15,1,13.03,100,1,13.56,100,1,13.02,100,1,13.57,15,1,12.73,100,1,13.59,100,1,12.71,100,1,13.83,100,1,12.50,700,1,14.01,2,1,12.46,200,2,14.19,100,1,12.43,700,1,14.28,100,1,12.42,700,1,14.43,100,1,12.37,700,1,14.53,100,1,ARL,323599625
1615,2025-07-17T16:01:56.300889378Z,2025-07-17T16:01:56.300723805Z,160,2,1108,A,A,9,14.51,100,130,165573,271252044,13.04,2,1,13.55,15,1,13.03,100,1,13.56,100,1,13.02,100,1,13.57,15,1,12.73,100,1,13.59,100,1,12.71,100,1,13.83,100,1,12.50,700,1,14.01,2,1,12.46,200,2,14.19,100,1,12.43,700,1,14.28,100,1,12.42,700,1,14.43,100,1,12.37,700,1,14.51,100,1,ARL,325177757
1616,2025-07-17T16:02:01.992544607Z,2025-07-17T16:02:01.992379223Z,160,2,1108,C,A,5,14.01,2,0,165384,271343251,13.04,2,1,13.55,15,1,13.03,100,1,13.56,100,1,13.02,100,1,13.57,15,1,12.73,100,1,13.59,100,1,12.71,100,1,13.83,100,1,12.50,700,1,14.19,100,1,12.46,200,2,14.28,100,1,12.43,700,1,14.43,100,1,12.42,700,1,14.51,100,1,12.37,700,1,14.53,100,1,ARL,322898193
1617,2025-07-17T16:02:01.992544607Z,2025-07-17T16:02:01.992379223Z,160,2,1108,A,A,5,13.92,2,130,165384,271343251,13.04,2,1,13.55,15,1,13.03,100,1,13.56,100,1,13.02,100,1,13.57,15,1,12.73,100,1,13.59,100,1,12.71,100,1,13.83,100,1,12.50,700,1,13.92,2,1,12.46,200,2,14.19,100,1,12.43,700,1,14.28,100,1,12.42,700,1,14.43,100,1,12.37,700,1,14.51,100,1,ARL,325297093
1618,2025-07-17T16:02:03.207720826Z,2025-07-17T16:02:03.207555626Z,160,2,1108,C,A,2,13.57,15,130,165200,271367066,13.04,2,1,13.55,15,1,13.03,100,1,13.56,100,1,13.02,100,1,13.59,100,1,12.73,100,1,13.83,100,1,12.71,100,1,13.92,2,1,12.50,700,1,14.19,100,1,12.46,200,2,14.28,100,1,12.43,700,1,14.43,100,1,12.42,700,1,14.51,100,1,12.37,700,1,14.53,100,1,ARL,324934601
1619,2025-07-17T16:02:04.212956339Z,2025-07-17T16:02:04.212791108Z,160,2,1108,A,A,0,13.53,15,130,165231,271415821,13.04,2,1,13.53,15,1,13.03,100,1,13.55,15,1,13.02,100,1,13.56,100,1,12.73,100,1,13.59,100,1,12.71,100,1,13.83,100,1,12.50,700,1,13.92,2,1,12.46,200,2,14.19,100,1,12.43,700,1,14.28,100,1,12.42,700,1,14.43,100,1,12.37,700,1,14.51,100,1,ARL,325382429
1620,2025-07-17T16:02:04.214348814Z,2025-07-17T16:02:04.214183279Z,160,2,1108,C,A,11,14.54,100,0,165535,271415834,13.04,2,1,13.53,15,1,13.03,100,1,13.55,15,1,13.02,100,1,13.56,100,1,12.73,100,1,13.59,100,1,12.71,100,1,13.83,100,1,12.50,700,1,13.92,2,1,12.46,200,2,14.19,100,1,12.43,700,1,14.28,100,1,12.42,700,1,14.43,100,1,12.37,700,1,14.51,100,1,ARL,323775433
1621,2025-07-17T16:02:04.214348814Z,2025-07-17T16:02:04.214183279Z,160,2,1108,A,A,8,14.43,100,130,165535,271415834,13.04,2,1,13.53,15,1,13.03,100,1,13.55,15,1,13.02,100,1,13.56,100,1,12.73,100,1,13.59,100,1,12.71,100,1,13.83,100,1,12.50,700,1,13.92,2,1,12.46,200,2,14.19,100,1,12.43,700,1,14.28,100,1,12.42,700,1,14.43,200,2,12.37,700,1,14.51,100,1,ARL,325382437
1622,2025-07-17T16:02:04.840132668Z,2025-07-17T16:02:04.839967173Z,160,2,1108,C,A,2,13.56,100,0,165495,271432190,13.04,2,1,13.53,15,1,13.03,100,1,13.55,15,1,13.02,100,1,13.59,100,1,12.73,100,1,13.83,100,1,12.71,100,1,13.92,2,1,12.50,700,1,14.19,100,1,12.46,200,2,14.28,100,1,12.43,700,1,14.43,200,2,12.42,700,1,14.51,100,1,12.37,700,1,14.53,100,1,ARL,325176181
1623,2025-07-17T16:02:04.840132668Z,2025-07-17T16:02:04.839967173Z,160,2,1108,A,A,1,13.54,100,130,165495,271432190,13.04,2,1,13.53,15,1,13.03,100,1,13.54,100,1,13.02,100,1,13.55,15,1,12.73,100,1,13.59,100,1,12.71,100,1,13.83,100,1,12.50,700,1,13.92,2,1,12.46,200,2,14.19,100,1,12.43,700,1,14.28,100,1,12.42,700,1,14.43,200,2,12.37,700,1,14.51,100,1,ARL,325400045
1624,2025-07-17T16:02:04.840171240Z,2025-07-17T16:02:04.840006082Z,160,2,1108,A,A,7,14.27,700,130,165158,271432192,13.04,2,1,13.53,15,1,13.03,100,1,13.54,100,1,13.02,100,1,13.55,15,1,12.73,100,1,13.59,100,1,12.71,100,1,13.83,100,1,12.50,700,1,13.92,2,1,12.46,200,2,14.19,100,1,12.43,700,1,14.27,700,1,12.42,700,1,14.28,100,1,12.37,700,1,14.43,200,2,ARL,325400053
1625,2025-07-17T16:02:04.840210880Z,2025-07-17T16:02:04.840045694Z,160,2,1108,C,A,16,14.68,700,130,165186,271432193,13.04,2,1,13.53,15,1,13.03,100,1,13.54,100,1,13.02,100,1,13.55,15,1,12.73,100,1,13.59,100,1,12.71,100,1,13.83,100,1,12.50,700,1,13.92,2,1,12.46,200,2,14.19,100,1,12.43,700,1,14.27,700,1,12.42,700,1,14.28,100,1,12.37,700,1,14.43,200,2,ARL,283592941
1626,2025-07-17T16:02:04.840877603Z,2025-07-17T16:02:04.840711803Z,160,2,1108,C,A,15,14.63,100,0,165800,271432231,13.04,2,1,13.53,15,1,13.03,100,1,13.54,100,1,13.02,100,1,13.55,15,1,12.73,100,1,13.59,100,1,12.71,100,1,13.83,100,1,12.50,700,1,13.92,2,1,12.46,200,2,14.19,100,1,12.43,700,1,14.27,700,1,12.42,700,1,14.28,100,1,12.37,700,1,14.43,200,2,ARL,324942257
1627,2025-07-17T16:02:04.840877603Z,2025-07-17T16:02:04.840711803Z,160,2,1108,A,A,14,14.59,100,130,165800,271432231,13.04,2,1,13.53,15,1,13.03,100,1,13.54,100,1,13.02,100,1,13.55,15,1,12.73,100,1,13.59,100,1,12.71,100,1,13.83,100,1,12.50,700,1,13.92,2,1,12.46,200,2,14.19,100,1,12.43,700,1,14.27,700,1,12.42,700,1,14.28,100,1,12.37,700,1,14.43,200,2,ARL,325400105
1628,2025-07-17T16:02:11.249291142Z,2025-07-17T16:02:11.249125653Z,160,2,1108,C,A,11,14.53,100,0,165489,271526467,13.04,2,1,13.53,15,1,13.03,100,1,13.54,100,1,13.02,100,1,13.55,15,1,12.73,100,1,13.59,100,1,12.71,100,1,13.83,100,1,12.50,700,1,13.92,2,1,12.46,200,2,14.19,100,1,12.43,700,1,14.27,700,1,12.42,700,1,14.28,100,1,12.37,700,1,14.43,200,2,ARL,323775457
1629,2025-07-17T16:02:11.249291142Z,2025-07-17T16:02:11.249125653Z,160,2,1108,A,A,9,14.42,100,130,165489,271526467,13.04,2,1,13.53,15,1,13.03,100,1,13.54,100,1,13.02,100,1,13.55,15,1,12.73,100,1,13.59,100,1,12.71,100,1,13.83,100,1,12.50,700,1,13.92,2,1,12.46,200,2,14.19,100,1,12.43,700,1,14.27,700,1,12.42,700,1,14.28,100,1,12.37,700,1,14.42,100,1,ARL,325520705
1630,2025-07-17T16:02:15.062774661Z,2025-07-17T16:02:15.062605521Z,160,2,1108,C,A,0,13.53,15,128,169140,271576282,13.04,2,1,13.54,100,1,13.03,100,1,13.55,15,1,13.02,100,1,13.59,100,1,12.73,100,1,13.83,100,1,12.71,100,1,13.92,2,1,12.50,700,1,14.19,100,1,12.46,200,2,14.27,700,1,12.43,700,1,14.28,100,1,12.42,700,1,14.42,100,1,12.37,700,1,14.43,200,2,ARL,325382429
1631,2025-07-17T16:02:15.068449048Z,2025-07-17T16:02:15.068283706Z,160,2,1108,C,A,1,13.55,15,130,165342,271577104,13.04,2,1,13.54,100,1,13.03,100,1,13.59,100,1,13.02,100,1,13.83,100,1,12.73,100,1,13.92,2,1,12.71,100,1,14.19,100,1,12.50,700,1,14.27,700,1,12.46,200,2,14.28,100,1,12.43,700,1,14.42,100,1,12.42,700,1,14.43,200,2,12.37,700,1,14.51,100,1,ARL,325109165
1632,2025-07-17T16:02:20.635028489Z,2025-07-17T16:02:20.634863301Z,160,2,1108,C,A,0,13.54,100,130,165188,271675842,13.04,2,1,13.59,100,1,13.03,100,1,13.83,100,1,13.02,100,1,13.92,2,1,12.73,100,1,14.19,100,1,12.71,100,1,14.27,700,1,12.50,700,1,14.28,100,1,12.46,200,2,14.42,100,1,12.43,700,1,14.43,200,2,12.42,700,1,14.51,100,1,12.37,700,1,14.56,800,2,ARL,325400045
1633,2025-07-17T16:02:20.635782472Z,2025-07-17T16:02:20.635616654Z,160,2,1108,C,A,11,14.59,100,0,165818,271675858,13.04,2,1,13.59,100,1,13.03,100,1,13.83,100,1,13.02,100,1,13.92,2,1,12.73,100,1,14.19,100,1,12.71,100,1,14.27,700,1,12.50,700,1,14.28,100,1,12.46,200,2,14.42,100,1,12.43,700,1,14.43,200,2,12.42,700,1,14.51,100,1,12.37,700,1,14.56,800,2,ARL,325400105
1634,2025-07-17T16:02:20.635782472Z,2025-07-17T16:02:20.635616654Z,160,2,1108,A,A,12,14.64,100,130,165818,271675858,13.04,2,1,13.59,100,1,13.03,100,1,13.83,100,1,13.02,100,1,13.92,2,1,12.73,100,1,14.19,100,1,12.71,100,1,14.27,700,1,12.50,700,1,14.28,100,1,12.46,200,2,14.42,100,1,12.43,700,1,14.43,200,2,12.42,700,1,14.51,100,1,12.37,700,1,14.56,800,2,ARL,325714169
1635,2025-07-17T16:02:20.650466751Z,2025-07-17T16:02:20.650301212Z,160,2,1108,C,A,0,13.59,100,130,165539,271676032,13.04,2,1,13.83,100,1,13.03,100,1,13.92,2,1,13.02,100,1,14.19,100,1,12.73,100,1,14.27,700,1,12.71,100,1,14.28,100,1,12.50,700,1,14.42,100,1,12.46,200,2,14.43,200,2,12.43,700,1,14.51,100,1,12.42,700,1,14.56,800,2,12.37,700,1,14.57,100,1,ARL,325022101
1636,2025-07-17T16:02:20.650501448Z,2025-07-17T16:02:20.650335946Z,160,2,1108,C,A,3,14.27,700,130,165502,271676033,13.04,2,1,13.83,100,1,13.03,100,1,13.92,2,1,13.02,100,1,14.19,100,1,12.73,100,1,14.28,100,1,12.71,100,1,14.42,100,1,12.50,700,1,14.43,200,2,12.46,200,2,14.51,100,1,12.43,700,1,14.56,800,2,12.42,700,1,14.57,100,1,12.37,700,1,14.60,700,1,ARL,325400053
1637,2025-07-17T16:02:20.650546483Z,2025-07-17T16:02:20.650381040Z,160,2,1108,A,A,7,14.53,700,130,165443,271676035,13.04,2,1,13.83,100,1,13.03,100,1,13.92,2,1,13.02,100,1,14.19,100,1,12.73,100,1,14.28,100,1,12.71,100,1,14.42,100,1,12.50,700,1,14.43,200,2,12.46,200,2,14.51,100,1,12.43,700,1,14.53,700,1,12.42,700,1,14.56,800,2,12.37,700,1,14.57,100,1,ARL,325714545
1638,2025-07-17T16:02:20.651186537Z,2025-07-17T16:02:20.651020858Z,160,2,1108,C,A,4,14.42,100,0,165679,271676048,13.04,2,1,13.83,100,1,13.03,100,1,13.92,2,1,13.02,100,1,14.19,100,1,12.73,100,1,14.28,100,1,12.71,100,1,14.43,200,2,12.50,700,1,14.51,100,1,12.46,200,2,14.53,700,1,12.43,700,1,14.56,800,2,12.42,700,1,14.57,100,1,12.37,700,1,14.60,700,1,ARL,325520705
1639,2025-07-17T16:02:20.651186537Z,2025-07-17T16:02:20.651020858Z,160,2,1108,A,A,12,14.73,100,130,165679,271676048,13.04,2,1,13.83,100,1,13.03,100,1,13.92,2,1,13.02,100,1,14.19,100,1,12.73,100,1,14.28,100,1,12.71,100,1,14.43,200,2,12.50,700,1,14.51,100,1,12.46,200,2,14.53,700,1,12.43,700,1,14.56,800,2,12.42,700,1,14.57,100,1,12.37,700,1,14.60,700,1,ARL,325714577
1640,2025-07-17T16:02:20.651201182Z,2025-07-17T16:02:20.651035000Z,160,2,1108,C,A,2,14.19,100,130,166182,271676049,13.04,2,1,13.83,100,1,13.03,100,1,13.92,2,1,13.02,100,1,14.28,100,1,12.73,100,1,14.43,200,2,12.71,100,1,14.51,100,1,12.50,700,1,14.53,700,1,12.46,200,2,14.56,800,2,12.43,700,1,14.57,100,1,12.42,700,1,14.60,700,1,12.37,700,1,14.64,100,1,ARL,324942273
1641,2025-07-17T16:02:20.651459317Z,2025-07-17T16:02:20.651293729Z,160,2,1108,C,A,19,17.25,100,0,165588,271676055,13.04,2,1,13.83,100,1,13.03,100,1,13.92,2,1,13.02,100,1,14.28,100,1,12.73,100,1,14.43,200,2,12.71,100,1,14.51,100,1,12.50,700,1,14.53,700,1,12.46,200,2,14.56,800,2,12.43,700,1,14.57,100,1,12.42,700,1,14.60,700,1,12.37,700,1,14.64,100,1,ARL,324942361
1642,2025-07-17T16:02:20.651459317Z,2025-07-17T16:02:20.651293729Z,160,2,1108,A,A,19,17.57,100,130,165588,271676055,13.04,2,1,13.83,100,1,13.03,100,1,13.92,2,1,13.02,100,1,14.28,100,1,12.73,100,1,14.43,200,2,12.71,100,1,14.51,100,1,12.50,700,1,14.53,700,1,12.46,200,2,14.56,800,2,12.43,700,1,14.57,100,1,12.42,700,1,14.60,700,1,12.37,700,1,14.64,100,1,ARL,325714589
1643,2025-07-17T16:02:20.651558948Z,2025-07-17T16:02:20.651393708Z,160,2,1108,A,A,4,14.45,100,130,165240,271676057,13.04,2,1,13.83,100,1,13.03,100,1,13.92,2,1,13.02,100,1,14.28,100,1,12.73,100,1,14.43,200,2,12.71,100,1,14.45,100,1,12.50,700,1,14.51,100,1,12.46,200,2,14.53,700,1,12.43,700,1,14.56,800,2,12.42,700,1,14.57,100,1,12.37,700,1,14.60,700,1,ARL,325714601
1644,2025-07-17T16:02:20.651787813Z,2025-07-17T16:02:20.651618897Z,160,2,1108,C,A,3,14.43,100,0,168916,271676089,13.04,2,1,13.83,100,1,13.03,100,1,13.92,2,1,13.02,100,1,14.28,100,1,12.73,100,1,14.43,100,1,12.71,100,1,14.45,100,1,12.50,700,1,14.51,100,1,12.46,200,2,14.53,700,1,12.43,700,1,14.56,800,2,12.42,700,1,14.57,100,1,12.37,700,1,14.60,700,1,ARL,325382437
1645,2025-07-17T16:02:20.651787813Z,2025-07-17T16:02:20.651618897Z,160,2,1108,A,A,12,14.73,100,128,168916,271676089,13.04,2,1,13.83,100,1,13.03,100,1,13.92,2,1,13.02,100,1,14.28,100,1,12.73,100,1,14.43,100,1,12.71,100,1,14.45,100,1,12.50,700,1,14.51,100,1,12.46,200,2,14.53,700,1,12.43,700,1,14.56,800,2,12.42,700,1,14.57,100,1,12.37,700,1,14.60,700,1,ARL,325714613
1646,2025-07-17T16:02:20.652021618Z,2025-07-17T16:02:20.651854531Z,160,2,1108,C,A,8,14.57,100,0,167087,271676104,13.04,2,1,13.83,100,1,13.03,100,1,13.92,2,1,13.02,100,1,14.28,100,1,12.73,100,1,14.43,100,1,12.71,100,1,14.45,100,1,12.50,700,1,14.51,100,1,12.46,200,2,14.53,700,1,12.43,700,1,14.56,800,2,12.42,700,1,14.60,700,1,12.37,700,1,14.64,100,1,ARL,324619409
1647,2025-07-17T16:02:20.652021618Z,2025-07-17T16:02:20.651854531Z,160,2,1108,A,A,12,14.80,100,130,167087,271676104,13.04,2,1,13.83,100,1,13.03,100,1,13.92,2,1,13.02,100,1,14.28,100,1,12.73,100,1,14.43,100,1,12.71,100,1,14.45,100,1,12.50,700,1,14.51,100,1,12.46,200,2,14.53,700,1,12.43,700,1,14.56,800,2,12.42,700,1,14.60,700,1,12.37,700,1,14.64,100,1,ARL,325714629
1648,2025-07-17T16:02:20.652097288Z,2025-07-17T16:02:20.651932129Z,160,2,1108,C,A,3,14.43,100,130,165159,271676110,13.04,2,1,13.83,100,1,13.03,100,1,13.92,2,1,13.02,100,1,14.28,100,1,12.73,100,1,14.45,100,1,12.71,100,1,14.51,100,1,12.50,700,1,14.53,700,1,12.46,200,2,14.56,800,2,12.43,700,1,14.60,700,1,12.42,700,1,14.64,100,1,12.37,700,1,14.68,700,1,ARL,324186781
1649,2025-07-17T16:02:20.652160470Z,2025-07-17T16:02:20.651994883Z,160,2,1108,C,A,16,15.60,100,0,165587,271676111,13.04,2,1,13.83,100,1,13.03,100,1,13.92,2,1,13.02,100,1,14.28,100,1,12.73,100,1,14.45,100,1,12.71,100,1,14.51,100,1,12.50,700,1,14.53,700,1,12.46,200,2,14.56,800,2,12.43,700,1,14.60,700,1,12.42,700,1,14.64,100,1,12.37,700,1,14.68,700,1,ARL,325176677
1650,2025-07-17T16:02:20.652160470Z,2025-07-17T16:02:20.651994883Z,160,2,1108,A,A,16,15.91,100,130,165587,271676111,13.04,2,1,13.83,100,1,13.03,100,1,13.92,2,1,13.02,100,1,14.28,100,1,12.73,100,1,14.45,100,1,12.71,100,1,14.51,100,1,12.50,700,1,14.53,700,1,12.46,200,2,14.56,800,2,12.43,700,1,14.60,700,1,12.42,700,1,14.64,100,1,12.37,700,1,14.68,700,1,ARL,325714633
1651,2025-07-17T16:02:20.652259931Z,2025-07-17T16:02:20.652094426Z,160,2,1108,A,A,8,14.63,100,130,165505,271676118,13.04,2,1,13.83,100,1,13.03,100,1,13.92,2,1,13.02,100,1,14.28,100,1,12.73,100,1,14.45,100,1,12.71,100,1,14.51,100,1,12.50,700,1,14.53,700,1,12.46,200,2,14.56,800,2,12.43,700,1,14.60,700,1,12.42,700,1,14.63,100,1,12.37,700,1,14.64,100,1,ARL,325714653
1652,2025-07-17T16:02:20.653626391Z,2025-07-17T16:02:20.653460814Z,160,2,1108,A,B,0,13.27,10,130,165577,271676147,13.27,10,1,13.83,100,1,13.04,2,1,13.92,2,1,13.03,100,1,14.28,100,1,13.02,100,1,14.45,100,1,12.73,100,1,14.51,100,1,12.71,100,1,14.53,700,1,12.50,700,1,14.56,800,2,12.46,200,2,14.60,700,1,12.43,700,1,14.63,100,1,12.42,700,1,14.64,100,1,ARL,325714717
1653,2025-07-17T16:02:20.653627232Z,2025-07-17T16:02:20.653461966Z,160,2,1108,A,A,0,13.83,15,130,165266,271676148,13.27,10,1,13.83,115,2,13.04,2,1,13.92,2,1,13.03,100,1,14.28,100,1,13.02,100,1,14.45,100,1,12.73,100,1,14.51,100,1,12.71,100,1,14.53,700,1,12.50,700,1,14.56,800,2,12.46,200,2,14.60,700,1,12.43,700,1,14.63,100,1,12.42,700,1,14.64,100,1,ARL,325714721
1654,2025-07-17T16:02:20.653886896Z,2025-07-17T16:02:20.653721185Z,160,2,1108,C,B,3,13.02,100,0,165711,271676153,13.27,10,1,13.83,115,2,13.04,2,1,13.92,2,1,13.03,100,1,14.28,100,1,12.73,100,1,14.45,100,1,12.71,100,1,14.51,100,1,12.50,700,1,14.53,700,1,12.46,200,2,14.56,800,2,12.43,700,1,14.60,700,1,12.42,700,1,14.63,100,1,12.37,700,1,14.64,100,1,ARL,320485385
1655,2025-07-17T16:02:20.653886896Z,2025-07-17T16:02:20.653721185Z,160,2,1108,A,B,1,13.26,100,130,165711,271676153,13.27,10,1,13.83,115,2,13.26,100,1,13.92,2,1,13.04,2,1,14.28,100,1,13.03,100,1,14.45,100,1,12.73,100,1,14.51,100,1,12.71,100,1,14.53,700,1,12.50,700,1,14.56,800,2,12.46,200,2,14.60,700,1,12.43,700,1,14.63,100,1,12.42,700,1,14.64,100,1,ARL,325714729
1656,2025-07-17T16:02:20.655277066Z,2025-07-17T16:02:20.655111649Z,160,2,1108,C,B,2,13.04,2,0,165417,271676165,13.27,10,1,13.83,115,2,13.26,100,1,13.92,2,1,13.03,100,1,14.28,100,1,12.73,100,1,14.45,100,1,12.71,100,1,14.51,100,1,12.50,700,1,14.53,700,1,12.46,200,2,14.56,800,2,12.43,700,1,14.60,700,1,12.42,700,1,14.63,100,1,12.37,700,1,14.64,100,1,ARL,293594281
1657,2025-07-17T16:02:20.655277066Z,2025-07-17T16:02:20.655111649Z,160,2,1108,A,B,3,12.91,2,130,165417,271676165,13.27,10,1,13.83,115,2,13.26,100,1,13.92,2,1,13.03,100,1,14.28,100,1,12.91,2,1,14.45,100,1,12.73,100,1,14.51,100,1,12.71,100,1,14.53,700,1,12.50,700,1,14.56,800,2,12.46,200,2,14.60,700,1,12.43,700,1,14.63,100,1,12.42,700,1,14.64,100,1,ARL,325714741
1658,2025-07-17T16:02:20.663374576Z,2025-07-17T16:02:20.663209235Z,160,2,1108,C,A,0,13.83,100,130,165341,271676274,13.27,10,1,13.83,15,1,13.26,100,1,13.92,2,1,13.03,100,1,14.28,100,1,12.91,2,1,14.45,100,1,12.73,100,1,14.51,100,1,12.71,100,1,14.53,700,1,12.50,700,1,14.56,800,2,12.46,200,2,14.60,700,1,12.43,700,1,14.63,100,1,12.42,700,1,14.64,100,1,ARL,325176373
1659,2025-07-17T16:02:20.663406861Z,2025-07-17T16:02:20.663241882Z,160,2,1108,C,A,5,14.53,700,130,164979,271676275,13.27,10,1,13.83,15,1,13.26,100,1,13.92,2,1,13.03,100,1,14.28,100,1,12.91,2,1,14.45,100,1,12.73,100,1,14.51,100,1,12.71,100,1,14.56,800,2,12.50,700,1,14.60,700,1,12.46,200,2,14.63,100,1,12.43,700,1,14.64,100,1,12.42,700,1,14.68,700,1,ARL,325714545
1660,2025-07-17T16:02:20.663426974Z,2025-07-17T16:02:20.663261632Z,160,2,1108,A,A,2,14.11,100,130,165342,271676276,13.27,10,1,13.83,15,1,13.26,100,1,13.92,2,1,13.03,100,1,14.11,100,1,12.91,2,1,14.28,100,1,12.73,100,1,14.45,100,1,12.71,100,1,14.51,100,1,12.50,700,1,14.56,800,2,12.46,200,2,14.60,700,1,12.43,700,1,14.63,100,1,12.42,700,1,14.64,100,1,ARL,325714905
1661,2025-07-17T16:02:20.663559466Z,2025-07-17T16:02:20.663394059Z,160,2,1108,A,A,18,15.94,100,130,165407,271676277,13.27,10,1,13.83,15,1,13.26,100,1,13.92,2,1,13.03,100,1,14.11,100,1,12.91,2,1,14.28,100,1,12.73,100,1,14.45,100,1,12.71,100,1,14.51,100,1,12.50,700,1,14.56,800,2,12.46,200,2,14.60,700,1,12.43,700,1,14.63,100,1,12.42,700,1,14.64,100,1,ARL,325714909
1662,2025-07-17T16:02:20.663572634Z,2025-07-17T16:02:20.663407337Z,160,2,1108,C,A,16,15.59,100,130,165297,271676278,13.27,10,1,13.83,15,1,13.26,100,1,13.92,2,1,13.03,100,1,14.11,100,1,12.91,2,1,14.28,100,1,12.73,100,1,14.45,100,1,12.71,100,1,14.51,100,1,12.50,700,1,14.56,800,2,12.46,200,2,14.60,700,1,12.43,700,1,14.63,100,1,12.42,700,1,14.64,100,1,ARL,323730697
1663,2025-07-17T16:02:20.664956400Z,2025-07-17T16:02:20.664790768Z,160,2,1108,C,A,20,17.57,100,0,165632,271676310,13.27,10,1,13.83,15,1,13.26,100,1,13.92,2,1,13.03,100,1,14.11,100,1,12.91,2,1,14.28,100,1,12.73,100,1,14.45,100,1,12.71,100,1,14.51,100,1,12.50,700,1,14.56,800,2,12.46,200,2,14.60,700,1,12.43,700,1,14.63,100,1,12.42,700,1,14.64,100,1,ARL,325714589
1664,2025-07-17T16:02:20.664956400Z,2025-07-17T16:02:20.664790768Z,160,2,1108,A,A,20,17.76,100,130,165632,271676310,13.27,10,1,13.83,15,1,13.26,100,1,13.92,2,1,13.03,100,1,14.11,100,1,12.91,2,1,14.28,100,1,12.73,100,1,14.45,100,1,12.71,100,1,14.51,100,1,12.50,700,1,14.56,800,2,12.46,200,2,14.60,700,1,12.43,700,1,14.63,100,1,12.42,700,1,14.64,100,1,ARL,325714949
1665,2025-07-17T16:02:20.665129279Z,2025-07-17T16:02:20.664963386Z,160,2,1108,C,A,12,14.80,100,0,165893,271676320,13.27,10,1,13.83,15,1,13.26,100,1,13.92,2,1,13.03,100,1,14.11,100,1,12.91,2,1,14.28,100,1,12.73,100,1,14.45,100,1,12.71,100,1,14.51,100,1,12.50,700,1,14.56,800,2,12.46,200,2,14.60,700,1,12.43,700,1,14.63,100,1,12.42,700,1,14.64,100,1,ARL,325714629
1666,2025-07-17T16:02:20.665129279Z,2025-07-17T16:02:20.664963386Z,160,2,1108,A,A,13,14.96,100,130,165893,271676320,13.27,10,1,13.83,15,1,13.26,100,1,13.92,2,1,13.03,100,1,14.11,100,1,12.91,2,1,14.28,100,1,12.73,100,1,14.45,100,1,12.71,100,1,14.51,100,1,12.50,700,1,14.56,800,2,12.46,200,2,14.60,700,1,12.43,700,1,14.63,100,1,12.42,700,1,14.64,100,1,ARL,325714953
1667,2025-07-17T16:02:20.665200392Z,2025-07-17T16:02:20.665034825Z,160,2,1108,C,A,16,15.91,100,0,165567,271676330,13.27,10,1,13.83,15,1,13.26,100,1,13.92,2,1,13.03,100,1,14.11,100,1,12.91,2,1,14.28,100,1,12.73,100,1,14.45,100,1,12.71,100,1,14.51,100,1,12.50,700,1,14.56,800,2,12.46,200,2,14.60,700,1,12.43,700,1,14.63,100,1,12.42,700,1,14.64,100,1,ARL,325714633
1668,2025-07-17T16:02:20.665200392Z,2025-07-17T16:02:20.665034825Z,160,2,1108,A,A,17,16.08,100,130,165567,271676330,13.27,10,1,13.83,15,1,13.26,100,1,13.92,2,1,13.03,100,1,14.11,100,1,12.91,2,1,14.28,100,1,12.73,100,1,14.45,100,1,12.71,100,1,14.51,100,1,12.50,700,1,14.56,800,2,12.46,200,2,14.60,700,1,12.43,700,1,14.63,100,1,12.42,700,1,14.64,100,1,ARL,325714957
1669,2025-07-17T16:02:20.665457595Z,2025-07-17T16:02:20.665292049Z,160,2,1108,C,A,12,14.94,100,0,165546,271676355,13.27,10,1,13.83,15,1,13.26,100,1,13.92,2,1,13.03,100,1,14.11,100,1,12.91,2,1,14.28,100,1,12.73,100,1,14.45,100,1,12.71,100,1,14.51,100,1,12.50,700,1,14.56,800,2,12.46,200,2,14.60,700,1,12.43,700,1,14.63,100,1,12.42,700,1,14.64,100,1,ARL,324942277
1670,2025-07-17T16:02:20.665457595Z,2025-07-17T16:02:20.665292049Z,160,2,1108,A,A,15,15.38,100,130,165546,271676355,13.27,10,1,13.83,15,1,13.26,100,1,13.92,2,1,13.03,100,1,14.11,100,1,12.91,2,1,14.28,100,1,12.73,100,1,14.45,100,1,12.71,100,1,14.51,100,1,12.50,700,1,14.56,800,2,12.46,200,2,14.60,700,1,12.43,700,1,14.63,100,1,12.42,700,1,14.64,100,1,ARL,325714965
1671,2025-07-17T16:02:20.669701452Z,2025-07-17T16:02:20.669536385Z,160,2,1108,C,A,2,14.11,100,130,165067,271676398,13.27,10,1,13.83,15,1,13.26,100,1,13.92,2,1,13.03,100,1,14.28,100,1,12.91,2,1,14.45,100,1,12.73,100,1,14.51,100,1,12.71,100,1,14.56,800,2,12.50,700,1,14.60,700,1,12.46,200,2,14.63,100,1,12.43,700,1,14.64,100,1,12.42,700,1,14.68,700,1,ARL,325714905
1672,2025-07-17T16:02:20.669748954Z,2025-07-17T16:02:20.669583810Z,160,2,1108,A,A,2,14.26,100,130,165144,271676399,13.27,10,1,13.83,15,1,13.26,100,1,13.92,2,1,13.03,100,1,14.26,100,1,12.91,2,1,14.28,100,1,12.73,100,1,14.45,100,1,12.71,100,1,14.51,100,1,12.50,700,1,14.56,800,2,12.46,200,2,14.60,700,1,12.43,700,1,14.63,100,1,12.42,700,1,14.64,100,1,ARL,325715045
1673,2025-07-17T16:02:20.669752979Z,2025-07-17T16:02:20.669587514Z,160,2,1108,C,A,5,14.51,100,0,165465,271676400,13.27,10,1,13.83,15,1,13.26,100,1,13.92,2,1,13.03,100,1,14.26,100,1,12.91,2,1,14.28,100,1,12.73,100,1,14.45,100,1,12.71,100,1,14.56,800,2,12.50,700,1,14.60,700,1,12.46,200,2,14.63,100,1,12.43,700,1,14.64,100,1,12.42,700,1,14.68,700,1,ARL,325177757
1674,2025-07-17T16:02:20.669752979Z,2025-07-17T16:02:20.669587514Z,160,2,1108,A,A,11,14.96,100,130,165465,271676400,13.27,10,1,13.83,15,1,13.26,100,1,13.92,2,1,13.03,100,1,14.26,100,1,12.91,2,1,14.28,100,1,12.73,100,1,14.45,100,1,12.71,100,1,14.56,800,2,12.50,700,1,14.60,700,1,12.46,200,2,14.63,100,1,12.43,700,1,14.64,100,1,12.42,700,1,14.68,700,1,ARL,325715053
1675,2025-07-17T16:02:20.685252049Z,2025-07-17T16:02:20.685086585Z,160,2,1108,C,A,8,14.64,100,0,165464,271676621,13.27,10,1,13.83,15,1,13.26,100,1,13.92,2,1,13.03,100,1,14.26,100,1,12.91,2,1,14.28,100,1,12.73,100,1,14.45,100,1,12.71,100,1,14.56,800,2,12.50,700,1,14.60,700,1,12.46,200,2,14.63,100,1,12.43,700,1,14.68,700,1,12.42,700,1,14.73,200,2,ARL,325714169
1676,2025-07-17T16:02:20.685252049Z,2025-07-17T16:02:20.685086585Z,160,2,1108,A,A,11,15.06,100,130,165464,271676621,13.27,10,1,13.83,15,1,13.26,100,1,13.92,2,1,13.03,100,1,14.26,100,1,12.91,2,1,14.28,100,1,12.73,100,1,14.45,100,1,12.71,100,1,14.56,800,2,12.50,700,1,14.60,700,1,12.46,200,2,14.63,100,1,12.43,700,1,14.68,700,1,12.42,700,1,14.73,200,2,ARL,325715113
1677,2025-07-17T16:02:20.832112637Z,2025-07-17T16:02:20.831947250Z,160,2,1108,A,A,8,14.68,700,130,165387,271678584,13.27,10,1,13.83,15,1,13.26,100,1,13.92,2,1,13.03,100,1,14.26,100,1,12.91,2,1,14.28,100,1,12.73,100,1,14.45,100,1,12.71,100,1,14.56,800,2,12.50,700,1,14.60,700,1,12.46,200,2,14.63,100,1,12.43,700,1,14.68,1400,2,12.42,700,1,14.73,200,2,ARL,325716945
