 ,ts_recv,ts_event,rtype,publisher_id,instrument_id,action,side,depth,price,size,flags,ts_in_delta,sequence,bid_px_00,bid_sz_00,bid_ct_00,ask_px_00,ask_sz_00,ask_ct_00,bid_px_01,bid_sz_01,bid_ct_01,ask_px_01,ask_sz_01,ask_ct_01,bid_px_02,bid_sz_02,bid_ct_02,ask_px_02,ask_sz_02,ask_ct_02,bid_px_03,bid_sz_03,bid_ct_03,ask_px_03,ask_sz_03,ask_ct_03,bid_px_04,bid_sz_04,bid_ct_04,ask_px_04,ask_sz_04,ask_ct_04,bid_px_05,bid_sz_05,bid_ct_05,ask_px_05,ask_sz_05,ask_ct_05,bid_px_06,bid_sz_06,bid_ct_06,ask_px_06,ask_sz_06,ask_ct_06,bid_px_07,bid_sz_07,bid_ct_07,ask_px_07,ask_sz_07,ask_ct_07,bid_px_08,bid_sz_08,bid_ct_08,ask_px_08,ask_sz_08,ask_ct_08,bid_px_09,bid_sz_09,bid_ct_09,ask_px_09,ask_sz_09,ask_ct_09,symbol,order_id
2227,2025-07-17T16:11:50.033010798Z,2025-07-17T16:11:50.032845393Z,160,2,1108,A,A,16,15.60,100,130,165405,281078903,13.11,100,1,13.55,15,1,13.01,2,1,13.56,100,1,12.98,200,2,13.82,2,1,12.86,100,1,13.86,100,1,12.73,100,1,14.25,100,1,12.71,100,1,14.27,700,1,12.50,700,1,14.28,100,1,12.46,100,1,14.47,100,1,12.43,700,1,14.48,700,1,12.42,700,1,14.51,200,2,ARL,337690641
2228,2025-07-17T16:11:53.859909462Z,2025-07-17T16:11:53.859743991Z,160,2,1108,A,A,0,13.53,15,130,165471,281142794,13.11,100,1,13.53,15,1,13.01,2,1,13.55,15,1,12.98,200,2,13.56,100,1,12.86,100,1,13.82,2,1,12.73,100,1,13.86,100,1,12.71,100,1,14.25,100,1,12.50,700,1,14.27,700,1,12.46,100,1,14.28,100,1,12.43,700,1,14.47,100,1,12.42,700,1,14.48,700,1,ARL,337772837
2229,2025-07-17T16:11:54.662527332Z,2025-07-17T16:11:54.662361841Z,160,2,1108,C,A,2,13.56,100,0,165491,281156215,13.11,100,1,13.53,15,1,13.01,2,1,13.55,15,1,12.98,200,2,13.82,2,1,12.86,100,1,13.86,100,1,12.73,100,1,14.25,100,1,12.71,100,1,14.27,700,1,12.50,700,1,14.28,100,1,12.46,100,1,14.47,100,1,12.43,700,1,14.48,700,1,12.42,700,1,14.51,200,2,ARL,337690193
2230,2025-07-17T16:11:54.662527332Z,2025-07-17T16:11:54.662361841Z,160,2,1108,A,A,1,13.54,100,130,165491,281156215,13.11,100,1,13.53,15,1,13.01,2,1,13.54,100,1,12.98,200,2,13.55,15,1,12.86,100,1,13.82,2,1,12.73,100,1,13.86,100,1,12.71,100,1,14.25,100,1,12.50,700,1,14.27,700,1,12.46,100,1,14.28,100,1,12.43,700,1,14.47,100,1,12.42,700,1,14.48,700,1,ARL,337790717
2231,2025-07-17T16:11:54.663278200Z,2025-07-17T16:11:54.663112543Z,160,2,1108,C,A,13,14.64,100,0,165657,281156222,13.11,100,1,13.53,15,1,13.01,2,1,13.54,100,1,12.98,200,2,13.55,15,1,12.86,100,1,13.82,2,1,12.73,100,1,13.86,100,1,12.71,100,1,14.25,100,1,12.50,700,1,14.27,700,1,12.46,100,1,14.28,100,1,12.43,700,1,14.47,100,1,12.42,700,1,14.48,700,1,ARL,336567213
2232,2025-07-17T16:11:54.663278200Z,2025-07-17T16:11:54.663112543Z,160,2,1108,A,A,12,14.59,100,130,165657,281156222,13.11,100,1,13.53,15,1,13.01,2,1,13.54,100,1,12.98,200,2,13.55,15,1,12.86,100,1,13.82,2,1,12.73,100,1,13.86,100,1,12.71,100,1,14.25,100,1,12.50,700,1,14.27,700,1,12.46,100,1,14.28,100,1,12.43,700,1,14.47,100,1,12.42,700,1,14.48,700,1,ARL,337790737
2233,2025-07-17T16:11:54.664134026Z,2025-07-17T16:11:54.663968656Z,160,2,1108,C,A,14,14.64,100,0,165370,281156223,13.11,100,1,13.53,15,1,13.01,2,1,13.54,100,1,12.98,200,2,13.55,15,1,12.86,100,1,13.82,2,1,12.73,100,1,13.86,100,1,12.71,100,1,14.25,100,1,12.50,700,1,14.27,700,1,12.46,100,1,14.28,100,1,12.43,700,1,14.47,100,1,12.42,700,1,14.48,700,1,ARL,335220525
2234,2025-07-17T16:11:54.664134026Z,2025-07-17T16:11:54.663968656Z,160,2,1108,A,A,10,14.49,100,130,165370,281156223,13.11,100,1,13.53,15,1,13.01,2,1,13.54,100,1,12.98,200,2,13.55,15,1,12.86,100,1,13.82,2,1,12.73,100,1,13.86,100,1,12.71,100,1,14.25,100,1,12.50,700,1,14.27,700,1,12.46,100,1,14.28,100,1,12.43,700,1,14.47,100,1,12.42,700,1,14.48,700,1,ARL,337790745
2235,2025-07-17T16:11:54.666326600Z,2025-07-17T16:11:54.666160990Z,160,2,1108,C,A,8,14.47,100,0,165610,281156243,13.11,100,1,13.53,15,1,13.01,2,1,13.54,100,1,12.98,200,2,13.55,15,1,12.86,100,1,13.82,2,1,12.73,100,1,13.86,100,1,12.71,100,1,14.25,100,1,12.50,700,1,14.27,700,1,12.46,100,1,14.28,100,1,12.43,700,1,14.48,700,1,12.42,700,1,14.49,100,1,ARL,335220561
2236,2025-07-17T16:11:54.666326600Z,2025-07-17T16:11:54.666160990Z,160,2,1108,A,A,8,14.33,100,130,165610,281156243,13.11,100,1,13.53,15,1,13.01,2,1,13.54,100,1,12.98,200,2,13.55,15,1,12.86,100,1,13.82,2,1,12.73,100,1,13.86,100,1,12.71,100,1,14.25,100,1,12.50,700,1,14.27,700,1,12.46,100,1,14.28,100,1,12.43,700,1,14.33,100,1,12.42,700,1,14.48,700,1,ARL,337790761
2237,2025-07-17T16:11:54.667504546Z,2025-07-17T16:11:54.667339002Z,160,2,1108,C,A,15,14.64,100,0,165544,281156250,13.11,100,1,13.53,15,1,13.01,2,1,13.54,100,1,12.98,200,2,13.55,15,1,12.86,100,1,13.82,2,1,12.73,100,1,13.86,100,1,12.71,100,1,14.25,100,1,12.50,700,1,14.27,700,1,12.46,100,1,14.28,100,1,12.43,700,1,14.33,100,1,12.42,700,1,14.48,700,1,ARL,335220629
2238,2025-07-17T16:11:54.667504546Z,2025-07-17T16:11:54.667339002Z,160,2,1108,A,A,10,14.49,100,130,165544,281156250,13.11,100,1,13.53,15,1,13.01,2,1,13.54,100,1,12.98,200,2,13.55,15,1,12.86,100,1,13.82,2,1,12.73,100,1,13.86,100,1,12.71,100,1,14.25,100,1,12.50,700,1,14.27,700,1,12.46,100,1,14.28,100,1,12.43,700,1,14.33,100,1,12.42,700,1,14.48,700,1,ARL,337790777
2239,2025-07-17T16:11:59.382515678Z,2025-07-17T16:11:59.382350338Z,160,2,1108,C,A,2,13.55,15,130,165340,281270010,13.11,100,1,13.53,15,1,13.01,2,1,13.54,100,1,12.98,200,2,13.82,2,1,12.86,100,1,13.86,100,1,12.73,100,1,14.25,100,1,12.71,100,1,14.27,700,1,12.50,700,1,14.28,100,1,12.46,100,1,14.33,100,1,12.43,700,1,14.48,700,1,12.42,700,1,14.49,200,2,ARL,337690189
2240,2025-07-17T16:12:02.982078719Z,2025-07-17T16:12:02.981913204Z,160,2,1108,A,A,0,13.51,15,130,165515,281348152,13.11,100,1,13.51,15,1,13.01,2,1,13.53,15,1,12.98,200,2,13.54,100,1,12.86,100,1,13.82,2,1,12.73,100,1,13.86,100,1,12.71,100,1,14.25,100,1,12.50,700,1,14.27,700,1,12.46,100,1,14.28,100,1,12.43,700,1,14.33,100,1,12.42,700,1,14.48,700,1,ARL,338041605
2241,2025-07-17T16:12:03.064162605Z,2025-07-17T16:12:03.063997054Z,160,2,1108,C,A,2,13.54,100,0,165551,281351122,13.11,100,1,13.51,15,1,13.01,2,1,13.53,15,1,12.98,200,2,13.82,2,1,12.86,100,1,13.86,100,1,12.73,100,1,14.25,100,1,12.71,100,1,14.27,700,1,12.50,700,1,14.28,100,1,12.46,100,1,14.33,100,1,12.43,700,1,14.48,700,1,12.42,700,1,14.49,200,2,ARL,337790717
2242,2025-07-17T16:12:03.064162605Z,2025-07-17T16:12:03.063997054Z,160,2,1108,A,A,1,13.52,100,130,165551,281351122,13.11,100,1,13.51,15,1,13.01,2,1,13.52,100,1,12.98,200,2,13.53,15,1,12.86,100,1,13.82,2,1,12.73,100,1,13.86,100,1,12.71,100,1,14.25,100,1,12.50,700,1,14.27,700,1,12.46,100,1,14.28,100,1,12.43,700,1,14.33,100,1,12.42,700,1,14.48,700,1,ARL,338044041
2243,2025-07-17T16:12:03.068467146Z,2025-07-17T16:12:03.068301745Z,160,2,1108,C,B,1,13.01,2,0,165401,281351235,13.11,100,1,13.51,15,1,12.98,200,2,13.52,100,1,12.86,100,1,13.53,15,1,12.73,100,1,13.82,2,1,12.71,100,1,13.86,100,1,12.50,700,1,14.25,100,1,12.46,100,1,14.27,700,1,12.43,700,1,14.28,100,1,12.42,700,1,14.33,100,1,12.37,700,1,14.48,700,1,ARL,332494213
2244,2025-07-17T16:12:03.068467146Z,2025-07-17T16:12:03.068301745Z,160,2,1108,A,B,2,12.92,2,130,165401,281351235,13.11,100,1,13.51,15,1,12.98,200,2,13.52,100,1,12.92,2,1,13.53,15,1,12.86,100,1,13.82,2,1,12.73,100,1,13.86,100,1,12.71,100,1,14.25,100,1,12.50,700,1,14.27,700,1,12.46,100,1,14.28,100,1,12.43,700,1,14.33,100,1,12.42,700,1,14.48,700,1,ARL,338044113
2245,2025-07-17T16:12:03.075200038Z,2025-07-17T16:12:03.075034550Z,160,2,1108,C,A,4,13.86,100,130,165488,281351372,13.11,100,1,13.51,15,1,12.98,200,2,13.52,100,1,12.92,2,1,13.53,15,1,12.86,100,1,13.82,2,1,12.73,100,1,14.25,100,1,12.71,100,1,14.27,700,1,12.50,700,1,14.28,100,1,12.46,100,1,14.33,100,1,12.43,700,1,14.48,700,1,12.42,700,1,14.49,200,2,ARL,336567333
2246,2025-07-17T16:12:03.075260529Z,2025-07-17T16:12:03.075095341Z,160,2,1108,A,A,3,13.79,100,130,165188,281351373,13.11,100,1,13.51,15,1,12.98,200,2,13.52,100,1,12.92,2,1,13.53,15,1,12.86,100,1,13.79,100,1,12.73,100,1,13.82,2,1,12.71,100,1,14.25,100,1,12.50,700,1,14.27,700,1,12.46,100,1,14.28,100,1,12.43,700,1,14.33,100,1,12.42,700,1,14.48,700,1,ARL,338044233
2247,2025-07-17T16:12:06.775177637Z,2025-07-17T16:12:06.775011783Z,160,2,1108,C,A,11,14.51,100,0,165854,281422697,13.11,100,1,13.51,15,1,12.98,200,2,13.52,100,1,12.92,2,1,13.53,15,1,12.86,100,1,13.79,100,1,12.73,100,1,13.82,2,1,12.71,100,1,14.25,100,1,12.50,700,1,14.27,700,1,12.46,100,1,14.28,100,1,12.43,700,1,14.33,100,1,12.42,700,1,14.48,700,1,ARL,336259225
2248,2025-07-17T16:12:06.775177637Z,2025-07-17T16:12:06.775011783Z,160,2,1108,A,A,9,14.40,100,130,165854,281422697,13.11,100,1,13.51,15,1,12.98,200,2,13.52,100,1,12.92,2,1,13.53,15,1,12.86,100,1,13.79,100,1,12.73,100,1,13.82,2,1,12.71,100,1,14.25,100,1,12.50,700,1,14.27,700,1,12.46,100,1,14.28,100,1,12.43,700,1,14.33,100,1,12.42,700,1,14.40,100,1,ARL,338139585
2249,2025-07-17T16:12:06.775614536Z,2025-07-17T16:12:06.775449017Z,160,2,1108,C,A,12,14.51,100,0,165519,281422702,13.11,100,1,13.51,15,1,12.98,200,2,13.52,100,1,12.92,2,1,13.53,15,1,12.86,100,1,13.79,100,1,12.73,100,1,13.82,2,1,12.71,100,1,14.25,100,1,12.50,700,1,14.27,700,1,12.46,100,1,14.28,100,1,12.43,700,1,14.33,100,1,12.42,700,1,14.40,100,1,ARL,336261905
2250,2025-07-17T16:12:06.775614536Z,2025-07-17T16:12:06.775449017Z,160,2,1108,A,A,9,14.40,100,130,165519,281422702,13.11,100,1,13.51,15,1,12.98,200,2,13.52,100,1,12.92,2,1,13.53,15,1,12.86,100,1,13.79,100,1,12.73,100,1,13.82,2,1,12.71,100,1,14.25,100,1,12.50,700,1,14.27,700,1,12.46,100,1,14.28,100,1,12.43,700,1,14.33,100,1,12.42,700,1,14.40,200,2,ARL,338139601
2251,2025-07-17T16:12:06.779705717Z,2025-07-17T16:12:06.779540143Z,160,2,1108,C,A,2,13.53,15,130,165574,281422782,13.11,100,1,13.51,15,1,12.98,200,2,13.52,100,1,12.92,2,1,13.79,100,1,12.86,100,1,13.82,2,1,12.73,100,1,14.25,100,1,12.71,100,1,14.27,700,1,12.50,700,1,14.28,100,1,12.46,100,1,14.33,100,1,12.43,700,1,14.40,200,2,12.42,700,1,14.48,700,1,ARL,337772837
2252,2025-07-17T16:12:07.784698893Z,2025-07-17T16:12:07.784533539Z,160,2,1108,A,A,0,13.49,15,130,165354,281443568,13.11,100,1,13.49,15,1,12.98,200,2,13.51,15,1,12.92,2,1,13.52,100,1,12.86,100,1,13.79,100,1,12.73,100,1,13.82,2,1,12.71,100,1,14.25,100,1,12.50,700,1,14.27,700,1,12.46,100,1,14.28,100,1,12.43,700,1,14.33,100,1,12.42,700,1,14.40,200,2,ARL,338167057
2253,2025-07-17T16:12:08.585194585Z,2025-07-17T16:12:08.585029039Z,160,2,1108,C,A,2,13.52,100,0,165546,281451898,13.11,100,1,13.49,15,1,12.98,200,2,13.51,15,1,12.92,2,1,13.79,100,1,12.86,100,1,13.82,2,1,12.73,100,1,14.25,100,1,12.71,100,1,14.27,700,1,12.50,700,1,14.28,100,1,12.46,100,1,14.33,100,1,12.43,700,1,14.40,200,2,12.42,700,1,14.48,700,1,ARL,338044041
2254,2025-07-17T16:12:08.585194585Z,2025-07-17T16:12:08.585029039Z,160,2,1108,A,A,1,13.50,100,130,165546,281451898,13.11,100,1,13.49,15,1,12.98,200,2,13.50,100,1,12.92,2,1,13.51,15,1,12.86,100,1,13.79,100,1,12.73,100,1,13.82,2,1,12.71,100,1,14.25,100,1,12.50,700,1,14.27,700,1,12.46,100,1,14.28,100,1,12.43,700,1,14.33,100,1,12.42,700,1,14.40,200,2,ARL,338180793
2255,2025-07-17T16:12:08.585942049Z,2025-07-17T16:12:08.585776508Z,160,2,1108,C,A,13,14.59,100,0,165541,281451903,13.11,100,1,13.49,15,1,12.98,200,2,13.50,100,1,12.92,2,1,13.51,15,1,12.86,100,1,13.79,100,1,12.73,100,1,13.82,2,1,12.71,100,1,14.25,100,1,12.50,700,1,14.27,700,1,12.46,100,1,14.28,100,1,12.43,700,1,14.33,100,1,12.42,700,1,14.40,200,2,ARL,337790737
2256,2025-07-17T16:12:08.585942049Z,2025-07-17T16:12:08.585776508Z,160,2,1108,A,A,12,14.55,100,130,165541,281451903,13.11,100,1,13.49,15,1,12.98,200,2,13.50,100,1,12.92,2,1,13.51,15,1,12.86,100,1,13.79,100,1,12.73,100,1,13.82,2,1,12.71,100,1,14.25,100,1,12.50,700,1,14.27,700,1,12.46,100,1,14.28,100,1,12.43,700,1,14.33,100,1,12.42,700,1,14.40,200,2,ARL,338180841
2257,2025-07-17T16:12:18.789922022Z,2025-07-17T16:12:18.789756367Z,160,2,1108,C,A,4,13.82,2,0,165655,281613266,13.11,100,1,13.49,15,1,12.98,200,2,13.50,100,1,12.92,2,1,13.51,15,1,12.86,100,1,13.79,100,1,12.73,100,1,14.25,100,1,12.71,100,1,14.27,700,1,12.50,700,1,14.28,100,1,12.46,100,1,14.33,100,1,12.43,700,1,14.40,200,2,12.42,700,1,14.48,700,1,ARL,336447325
2258,2025-07-17T16:12:18.789922022Z,2025-07-17T16:12:18.789756367Z,160,2,1108,A,A,3,13.74,2,130,165655,281613266,13.11,100,1,13.49,15,1,12.98,200,2,13.50,100,1,12.92,2,1,13.51,15,1,12.86,100,1,13.74,2,1,12.73,100,1,13.79,100,1,12.71,100,1,14.25,100,1,12.50,700,1,14.27,700,1,12.46,100,1,14.28,100,1,12.43,700,1,14.33,100,1,12.42,700,1,14.40,200,2,ARL,338371797
2259,2025-07-17T16:12:19.370986404Z,2025-07-17T16:12:19.370820933Z,160,2,1108,A,A,6,14.27,700,130,165471,281622545,13.11,100,1,13.49,15,1,12.98,200,2,13.50,100,1,12.92,2,1,13.51,15,1,12.86,100,1,13.74,2,1,12.73,100,1,13.79,100,1,12.71,100,1,14.25,100,1,12.50,700,1,14.27,1400,2,12.46,100,1,14.28,100,1,12.43,700,1,14.33,100,1,12.42,700,1,14.40,200,2,ARL,338382329
2260,2025-07-17T16:12:19.371041049Z,2025-07-17T16:12:19.370875240Z,160,2,1108,C,A,14,14.60,700,130,165809,281622547,13.11,100,1,13.49,15,1,12.98,200,2,13.50,100,1,12.92,2,1,13.51,15,1,12.86,100,1,13.74,2,1,12.73,100,1,13.79,100,1,12.71,100,1,14.25,100,1,12.50,700,1,14.27,1400,2,12.46,100,1,14.28,100,1,12.43,700,1,14.33,100,1,12.42,700,1,14.40,200,2,ARL,282920685
2261,2025-07-17T16:12:19.696689718Z,2025-07-17T16:12:19.696521343Z,160,2,1108,C,A,0,13.49,15,128,168375,281630053,13.11,100,1,13.50,100,1,12.98,200,2,13.51,15,1,12.92,2,1,13.74,2,1,12.86,100,1,13.79,100,1,12.73,100,1,14.25,100,1,12.71,100,1,14.27,1400,2,12.50,700,1,14.28,100,1,12.46,100,1,14.33,100,1,12.43,700,1,14.40,200,2,12.42,700,1,14.48,700,1,ARL,338167057
2262,2025-07-17T16:12:19.711773364Z,2025-07-17T16:12:19.711591494Z,160,2,1108,C,A,1,13.51,15,128,181870,281634812,13.11,100,1,13.50,100,1,12.98,200,2,13.74,2,1,12.92,2,1,13.79,100,1,12.86,100,1,14.25,100,1,12.73,100,1,14.27,1400,2,12.71,100,1,14.28,100,1,12.50,700,1,14.33,100,1,12.46,100,1,14.40,200,2,12.43,700,1,14.48,700,1,12.42,700,1,14.49,200,2,ARL,338041605
2263,2025-07-17T16:12:32.761277424Z,2025-07-17T16:12:32.761112078Z,160,2,1108,A,A,0,13.48,15,130,165346,281880398,13.11,100,1,13.48,15,1,12.98,200,2,13.50,100,1,12.92,2,1,13.74,2,1,12.86,100,1,13.79,100,1,12.73,100,1,14.25,100,1,12.71,100,1,14.27,1400,2,12.50,700,1,14.28,100,1,12.46,100,1,14.33,100,1,12.43,700,1,14.40,200,2,12.42,700,1,14.48,700,1,ARL,338707945
2264,2025-07-17T16:12:32.761413202Z,2025-07-17T16:12:32.761246859Z,160,2,1108,C,A,1,13.50,100,0,166343,281880409,13.11,100,1,13.48,15,1,12.98,200,2,13.74,2,1,12.92,2,1,13.79,100,1,12.86,100,1,14.25,100,1,12.73,100,1,14.27,1400,2,12.71,100,1,14.28,100,1,12.50,700,1,14.33,100,1,12.46,100,1,14.40,200,2,12.43,700,1,14.48,700,1,12.42,700,1,14.49,200,2,ARL,338180793
2265,2025-07-17T16:12:32.761413202Z,2025-07-17T16:12:32.761246859Z,160,2,1108,A,A,1,13.49,100,130,166343,281880409,13.11,100,1,13.48,15,1,12.98,200,2,13.49,100,1,12.92,2,1,13.74,2,1,12.86,100,1,13.79,100,1,12.73,100,1,14.25,100,1,12.71,100,1,14.27,1400,2,12.50,700,1,14.28,100,1,12.46,100,1,14.33,100,1,12.43,700,1,14.40,200,2,12.42,700,1,14.48,700,1,ARL,338707949
2266,2025-07-17T16:12:32.779055996Z,2025-07-17T16:12:32.778890447Z,160,2,1108,C,A,14,15.12,100,0,165549,281880579,13.11,100,1,13.48,15,1,12.98,200,2,13.49,100,1,12.92,2,1,13.74,2,1,12.86,100,1,13.79,100,1,12.73,100,1,14.25,100,1,12.71,100,1,14.27,1400,2,12.50,700,1,14.28,100,1,12.46,100,1,14.33,100,1,12.43,700,1,14.40,200,2,12.42,700,1,14.48,700,1,ARL,296387089
2267,2025-07-17T16:12:32.779055996Z,2025-07-17T16:12:32.778890447Z,160,2,1108,A,A,13,14.84,100,130,165549,281880579,13.11,100,1,13.48,15,1,12.98,200,2,13.49,100,1,12.92,2,1,13.74,2,1,12.86,100,1,13.79,100,1,12.73,100,1,14.25,100,1,12.71,100,1,14.27,1400,2,12.50,700,1,14.28,100,1,12.46,100,1,14.33,100,1,12.43,700,1,14.40,200,2,12.42,700,1,14.48,700,1,ARL,338708241
2268,2025-07-17T16:12:32.804318005Z,2025-07-17T16:12:32.804152457Z,160,2,1108,A,A,16,15.38,100,130,165548,281880972,13.11,100,1,13.48,15,1,12.98,200,2,13.49,100,1,12.92,2,1,13.74,2,1,12.86,100,1,13.79,100,1,12.73,100,1,14.25,100,1,12.71,100,1,14.27,1400,2,12.50,700,1,14.28,100,1,12.46,100,1,14.33,100,1,12.43,700,1,14.40,200,2,12.42,700,1,14.48,700,1,ARL,338709513
2269,2025-07-17T16:12:32.804332586Z,2025-07-17T16:12:32.804166092Z,160,2,1108,C,A,18,15.66,100,130,166494,281880973,13.11,100,1,13.48,15,1,12.98,200,2,13.49,100,1,12.92,2,1,13.74,2,1,12.86,100,1,13.79,100,1,12.73,100,1,14.25,100,1,12.71,100,1,14.27,1400,2,12.50,700,1,14.28,100,1,12.46,100,1,14.33,100,1,12.43,700,1,14.40,200,2,12.42,700,1,14.48,700,1,ARL,326730513
2270,2025-07-17T16:12:40.993064296Z,2025-07-17T16:12:40.992898990Z,160,2,1108,C,A,1,13.49,100,130,165306,282007871,13.11,100,1,13.48,15,1,12.98,200,2,13.74,2,1,12.92,2,1,13.79,100,1,12.86,100,1,14.25,100,1,12.73,100,1,14.27,1400,2,12.71,100,1,14.28,100,1,12.50,700,1,14.33,100,1,12.46,100,1,14.40,200,2,12.43,700,1,14.48,700,1,12.42,700,1,14.49,200,2,ARL,338707949
2271,2025-07-17T16:12:40.993332664Z,2025-07-17T16:12:40.993167418Z,160,2,1108,C,A,4,14.27,700,130,165246,282007875,13.11,100,1,13.48,15,1,12.98,200,2,13.74,2,1,12.92,2,1,13.79,100,1,12.86,100,1,14.25,100,1,12.73,100,1,14.27,700,1,12.71,100,1,14.28,100,1,12.50,700,1,14.33,100,1,12.46,100,1,14.40,200,2,12.43,700,1,14.48,700,1,12.42,700,1,14.49,200,2,ARL,338382329
2272,2025-07-17T16:12:40.993333790Z,2025-07-17T16:12:40.993168470Z,160,2,1108,C,A,4,14.27,700,130,165320,282007876,13.11,100,1,13.48,15,1,12.98,200,2,13.74,2,1,12.92,2,1,13.79,100,1,12.86,100,1,14.25,100,1,12.73,100,1,14.28,100,1,12.71,100,1,14.33,100,1,12.50,700,1,14.40,200,2,12.46,100,1,14.48,700,1,12.43,700,1,14.49,200,2,12.42,700,1,14.55,100,1,ARL,336747457
2273,2025-07-17T16:12:40.993379626Z,2025-07-17T16:12:40.993214193Z,160,2,1108,A,A,9,14.54,700,130,165433,282007877,13.11,100,1,13.48,15,1,12.98,200,2,13.74,2,1,12.92,2,1,13.79,100,1,12.86,100,1,14.25,100,1,12.73,100,1,14.28,100,1,12.71,100,1,14.33,100,1,12.50,700,1,14.40,200,2,12.46,100,1,14.48,700,1,12.43,700,1,14.49,200,2,12.42,700,1,14.54,700,1,ARL,338864169
2274,2025-07-17T16:12:40.993393440Z,2025-07-17T16:12:40.993227993Z,160,2,1108,A,A,7,14.47,700,130,165447,282007878,13.11,100,1,13.48,15,1,12.98,200,2,13.74,2,1,12.92,2,1,13.79,100,1,12.86,100,1,14.25,100,1,12.73,100,1,14.28,100,1,12.71,100,1,14.33,100,1,12.50,700,1,14.40,200,2,12.46,100,1,14.47,700,1,12.43,700,1,14.48,700,1,12.42,700,1,14.49,200,2,ARL,338864173
2275,2025-07-17T16:12:40.993432115Z,2025-07-17T16:12:40.993266591Z,160,2,1108,A,A,18,15.71,100,130,165524,282007879,13.11,100,1,13.48,15,1,12.98,200,2,13.74,2,1,12.92,2,1,13.79,100,1,12.86,100,1,14.25,100,1,12.73,100,1,14.28,100,1,12.71,100,1,14.33,100,1,12.50,700,1,14.40,200,2,12.46,100,1,14.47,700,1,12.43,700,1,14.48,700,1,12.42,700,1,14.49,200,2,ARL,338864177
2276,2025-07-17T16:12:40.993445042Z,2025-07-17T16:12:40.993279810Z,160,2,1108,C,A,16,15.38,100,130,165232,282007880,13.11,100,1,13.48,15,1,12.98,200,2,13.74,2,1,12.92,2,1,13.79,100,1,12.86,100,1,14.25,100,1,12.73,100,1,14.28,100,1,12.71,100,1,14.33,100,1,12.50,700,1,14.40,200,2,12.46,100,1,14.47,700,1,12.43,700,1,14.48,700,1,12.42,700,1,14.49,200,2,ARL,338709513
2277,2025-07-17T16:12:40.993818130Z,2025-07-17T16:12:40.993652511Z,160,2,1108,C,A,11,14.55,100,0,165619,282007882,13.11,100,1,13.48,15,1,12.98,200,2,13.74,2,1,12.92,2,1,13.79,100,1,12.86,100,1,14.25,100,1,12.73,100,1,14.28,100,1,12.71,100,1,14.33,100,1,12.50,700,1,14.40,200,2,12.46,100,1,14.47,700,1,12.43,700,1,14.48,700,1,12.42,700,1,14.49,200,2,ARL,338180841
2278,2025-07-17T16:12:40.993818130Z,2025-07-17T16:12:40.993652511Z,160,2,1108,A,A,13,14.85,100,130,165619,282007882,13.11,100,1,13.48,15,1,12.98,200,2,13.74,2,1,12.92,2,1,13.79,100,1,12.86,100,1,14.25,100,1,12.73,100,1,14.28,100,1,12.71,100,1,14.33,100,1,12.50,700,1,14.40,200,2,12.46,100,1,14.47,700,1,12.43,700,1,14.48,700,1,12.42,700,1,14.49,200,2,ARL,338864189
2279,2025-07-17T16:12:40.994783297Z,2025-07-17T16:12:40.994617858Z,160,2,1108,C,A,9,14.49,100,0,165439,282007892,13.11,100,1,13.48,15,1,12.98,200,2,13.74,2,1,12.92,2,1,13.79,100,1,12.86,100,1,14.25,100,1,12.73,100,1,14.28,100,1,12.71,100,1,14.33,100,1,12.50,700,1,14.40,200,2,12.46,100,1,14.47,700,1,12.43,700,1,14.48,700,1,12.42,700,1,14.49,100,1,ARL,337790745
2280,2025-07-17T16:12:40.994783297Z,2025-07-17T16:12:40.994617858Z,160,2,1108,A,A,12,14.76,100,130,165439,282007892,13.11,100,1,13.48,15,1,12.98,200,2,13.74,2,1,12.92,2,1,13.79,100,1,12.86,100,1,14.25,100,1,12.73,100,1,14.28,100,1,12.71,100,1,14.33,100,1,12.50,700,1,14.40,200,2,12.46,100,1,14.47,700,1,12.43,700,1,14.48,700,1,12.42,700,1,14.49,100,1,ARL,338864217
2281,2025-07-17T16:12:40.995078856Z,2025-07-17T16:12:40.994913404Z,160,2,1108,C,A,13,14.84,100,0,165452,282007894,13.11,100,1,13.48,15,1,12.98,200,2,13.74,2,1,12.92,2,1,13.79,100,1,12.86,100,1,14.25,100,1,12.73,100,1,14.28,100,1,12.71,100,1,14.33,100,1,12.50,700,1,14.40,200,2,12.46,100,1,14.47,700,1,12.43,700,1,14.48,700,1,12.42,700,1,14.49,100,1,ARL,338708241
2282,2025-07-17T16:12:40.995078856Z,2025-07-17T16:12:40.994913404Z,160,2,1108,A,A,15,15.17,100,130,165452,282007894,13.11,100,1,13.48,15,1,12.98,200,2,13.74,2,1,12.92,2,1,13.79,100,1,12.86,100,1,14.25,100,1,12.73,100,1,14.28,100,1,12.71,100,1,14.33,100,1,12.50,700,1,14.40,200,2,12.46,100,1,14.47,700,1,12.43,700,1,14.48,700,1,12.42,700,1,14.49,100,1,ARL,338864221
2283,2025-07-17T16:12:40.995349303Z,2025-07-17T16:12:40.995183768Z,160,2,1108,C,A,17,15.60,100,0,165535,282007898,13.11,100,1,13.48,15,1,12.98,200,2,13.74,2,1,12.92,2,1,13.79,100,1,12.86,100,1,14.25,100,1,12.73,100,1,14.28,100,1,12.71,100,1,14.33,100,1,12.50,700,1,14.40,200,2,12.46,100,1,14.47,700,1,12.43,700,1,14.48,700,1,12.42,700,1,14.49,100,1,ARL,337690641
2284,2025-07-17T16:12:40.995349303Z,2025-07-17T16:12:40.995183768Z,160,2,1108,A,A,18,15.86,100,130,165535,282007898,13.11,100,1,13.48,15,1,12.98,200,2,13.74,2,1,12.92,2,1,13.79,100,1,12.86,100,1,14.25,100,1,12.73,100,1,14.28,100,1,12.71,100,1,14.33,100,1,12.50,700,1,14.40,200,2,12.46,100,1,14.47,700,1,12.43,700,1,14.48,700,1,12.42,700,1,14.49,100,1,ARL,338864245
2285,2025-07-17T16:12:40.996460080Z,2025-07-17T16:12:40.996294601Z,160,2,1108,C,A,21,17.26,100,0,165479,282007909,13.11,100,1,13.48,15,1,12.98,200,2,13.74,2,1,12.92,2,1,13.79,100,1,12.86,100,1,14.25,100,1,12.73,100,1,14.28,100,1,12.71,100,1,14.33,100,1,12.50,700,1,14.40,200,2,12.46,100,1,14.47,700,1,12.43,700,1,14.48,700,1,12.42,700,1,14.49,100,1,ARL,336570921
2286,2025-07-17T16:12:40.996460080Z,2025-07-17T16:12:40.996294601Z,160,2,1108,A,A,21,17.52,100,130,165479,282007909,13.11,100,1,13.48,15,1,12.98,200,2,13.74,2,1,12.92,2,1,13.79,100,1,12.86,100,1,14.25,100,1,12.73,100,1,14.28,100,1,12.71,100,1,14.33,100,1,12.50,700,1,14.40,200,2,12.46,100,1,14.47,700,1,12.43,700,1,14.48,700,1,12.42,700,1,14.49,100,1,ARL,338864289
2287,2025-07-17T16:12:40.997300700Z,2025-07-17T16:12:40.997135307Z,160,2,1108,C,A,5,14.33,100,130,165393,282007914,13.11,100,1,13.48,15,1,12.98,200,2,13.74,2,1,12.92,2,1,13.79,100,1,12.86,100,1,14.25,100,1,12.73,100,1,14.28,100,1,12.71,100,1,14.40,200,2,12.50,700,1,14.47,700,1,12.46,100,1,14.48,700,1,12.43,700,1,14.49,100,1,12.42,700,1,14.54,700,1,ARL,337790761
2288,2025-07-17T16:12:40.997422356Z,2025-07-17T16:12:40.997257014Z,160,2,1108,A,A,11,14.58,100,130,165342,282007916,13.11,100,1,13.48,15,1,12.98,200,2,13.74,2,1,12.92,2,1,13.79,100,1,12.86,100,1,14.25,100,1,12.73,100,1,14.28,100,1,12.71,100,1,14.40,200,2,12.50,700,1,14.47,700,1,12.46,100,1,14.48,700,1,12.43,700,1,14.49,100,1,12.42,700,1,14.54,700,1,ARL,338864317
2289,2025-07-17T16:12:41.004229622Z,2025-07-17T16:12:41.004063876Z,160,2,1108,C,A,8,14.49,100,0,165746,282007959,13.11,100,1,13.48,15,1,12.98,200,2,13.74,2,1,12.92,2,1,13.79,100,1,12.86,100,1,14.25,100,1,12.73,100,1,14.28,100,1,12.71,100,1,14.40,200,2,12.50,700,1,14.47,700,1,12.46,100,1,14.48,700,1,12.43,700,1,14.54,700,1,12.42,700,1,14.56,800,2,ARL,337790777
2290,2025-07-17T16:12:41.004229622Z,2025-07-17T16:12:41.004063876Z,160,2,1108,A,A,11,14.76,100,130,165746,282007959,13.11,100,1,13.48,15,1,12.98,200,2,13.74,2,1,12.92,2,1,13.79,100,1,12.86,100,1,14.25,100,1,12.73,100,1,14.28,100,1,12.71,100,1,14.40,200,2,12.50,700,1,14.47,700,1,12.46,100,1,14.48,700,1,12.43,700,1,14.54,700,1,12.42,700,1,14.56,800,2,ARL,338864405
2291,2025-07-17T16:12:41.005576053Z,2025-07-17T16:12:41.005406614Z,160,2,1108,A,A,1,13.49,100,128,169439,282008256,13.11,100,1,13.48,15,1,12.98,200,2,13.49,100,1,12.92,2,1,13.74,2,1,12.86,100,1,13.79,100,1,12.73,100,1,14.25,100,1,12.71,100,1,14.28,100,1,12.50,700,1,14.40,200,2,12.46,100,1,14.47,700,1,12.43,700,1,14.48,700,1,12.42,700,1,14.54,700,1,ARL,338864581
2292,2025-07-17T16:12:41.010638351Z,2025-07-17T16:12:41.010473041Z,160,2,1108,C,A,12,14.76,100,0,165310,282008884,13.11,100,1,13.48,15,1,12.98,200,2,13.49,100,1,12.92,2,1,13.74,2,1,12.86,100,1,13.79,100,1,12.73,100,1,14.25,100,1,12.71,100,1,14.28,100,1,12.50,700,1,14.40,200,2,12.46,100,1,14.47,700,1,12.43,700,1,14.48,700,1,12.42,700,1,14.54,700,1,ARL,338864405
2293,2025-07-17T16:12:41.010638351Z,2025-07-17T16:12:41.010473041Z,160,2,1108,A,A,7,14.44,100,130,165310,282008884,13.11,100,1,13.48,15,1,12.98,200,2,13.49,100,1,12.92,2,1,13.74,2,1,12.86,100,1,13.79,100,1,12.73,100,1,14.25,100,1,12.71,100,1,14.28,100,1,12.50,700,1,14.40,200,2,12.46,100,1,14.44,100,1,12.43,700,1,14.47,700,1,12.42,700,1,14.48,700,1,ARL,338865133
2294,2025-07-17T16:12:41.011160341Z,2025-07-17T16:12:41.010994859Z,160,2,1108,C,A,3,13.79,100,130,165482,282008914,13.11,100,1,13.48,15,1,12.98,200,2,13.49,100,1,12.92,2,1,13.74,2,1,12.86,100,1,14.25,100,1,12.73,100,1,14.28,100,1,12.71,100,1,14.40,200,2,12.50,700,1,14.44,100,1,12.46,100,1,14.47,700,1,12.43,700,1,14.48,700,1,12.42,700,1,14.54,700,1,ARL,338044233
2295,2025-07-17T16:12:41.011211986Z,2025-07-17T16:12:41.011046717Z,160,2,1108,A,A,3,14.06,100,130,165269,282008916,13.11,100,1,13.48,15,1,12.98,200,2,13.49,100,1,12.92,2,1,13.74,2,1,12.86,100,1,14.06,100,1,12.73,100,1,14.25,100,1,12.71,100,1,14.28,100,1,12.50,700,1,14.40,200,2,12.46,100,1,14.44,100,1,12.43,700,1,14.47,700,1,12.42,700,1,14.48,700,1,ARL,338865141
2296,2025-07-17T16:12:41.011555342Z,2025-07-17T16:12:41.011390077Z,160,2,1108,C,A,13,14.76,100,0,165265,282008942,13.11,100,1,13.48,15,1,12.98,200,2,13.49,100,1,12.92,2,1,13.74,2,1,12.86,100,1,14.06,100,1,12.73,100,1,14.25,100,1,12.71,100,1,14.28,100,1,12.50,700,1,14.40,200,2,12.46,100,1,14.44,100,1,12.43,700,1,14.47,700,1,12.42,700,1,14.48,700,1,ARL,338864217
2297,2025-07-17T16:12:41.011555342Z,2025-07-17T16:12:41.011390077Z,160,2,1108,A,A,7,14.44,100,130,165265,282008942,13.11,100,1,13.48,15,1,12.98,200,2,13.49,100,1,12.92,2,1,13.74,2,1,12.86,100,1,14.06,100,1,12.73,100,1,14.25,100,1,12.71,100,1,14.28,100,1,12.50,700,1,14.40,200,2,12.46,100,1,14.44,200,2,12.43,700,1,14.47,700,1,12.42,700,1,14.48,700,1,ARL,338865165
2298,2025-07-17T16:12:41.012044919Z,2025-07-17T16:12:41.011879795Z,160,2,1108,C,A,3,14.06,100,130,165124,282008953,13.11,100,1,13.48,15,1,12.98,200,2,13.49,100,1,12.92,2,1,13.74,2,1,12.86,100,1,14.25,100,1,12.73,100,1,14.28,100,1,12.71,100,1,14.40,200,2,12.50,700,1,14.44,200,2,12.46,100,1,14.47,700,1,12.43,700,1,14.48,700,1,12.42,700,1,14.54,700,1,ARL,338865141
2299,2025-07-17T16:12:41.012094494Z,2025-07-17T16:12:41.011929033Z,160,2,1108,A,A,3,13.76,100,130,165461,282008954,13.11,100,1,13.48,15,1,12.98,200,2,13.49,100,1,12.92,2,1,13.74,2,1,12.86,100,1,13.76,100,1,12.73,100,1,14.25,100,1,12.71,100,1,14.28,100,1,12.50,700,1,14.40,200,2,12.46,100,1,14.44,200,2,12.43,700,1,14.47,700,1,12.42,700,1,14.48,700,1,ARL,338865177
2300,2025-07-17T16:12:41.014974491Z,2025-07-17T16:12:41.014809197Z,160,2,1108,C,A,21,17.52,100,0,165294,282008990,13.11,100,1,13.48,15,1,12.98,200,2,13.49,100,1,12.92,2,1,13.74,2,1,12.86,100,1,13.76,100,1,12.73,100,1,14.25,100,1,12.71,100,1,14.28,100,1,12.50,700,1,14.40,200,2,12.46,100,1,14.44,200,2,12.43,700,1,14.47,700,1,12.42,700,1,14.48,700,1,ARL,338864289
2301,2025-07-17T16:12:41.014974491Z,2025-07-17T16:12:41.014809197Z,160,2,1108,A,A,20,17.14,100,130,165294,282008990,13.11,100,1,13.48,15,1,12.98,200,2,13.49,100,1,12.92,2,1,13.74,2,1,12.86,100,1,13.76,100,1,12.73,100,1,14.25,100,1,12.71,100,1,14.28,100,1,12.50,700,1,14.40,200,2,12.46,100,1,14.44,200,2,12.43,700,1,14.47,700,1,12.42,700,1,14.48,700,1,ARL,338865253
2302,2025-07-17T16:12:41.017837378Z,2025-07-17T16:12:41.017672033Z,160,2,1108,C,A,18,15.86,100,0,165345,282009053,13.11,100,1,13.48,15,1,12.98,200,2,13.49,100,1,12.92,2,1,13.74,2,1,12.86,100,1,13.76,100,1,12.73,100,1,14.25,100,1,12.71,100,1,14.28,100,1,12.50,700,1,14.40,200,2,12.46,100,1,14.44,200,2,12.43,700,1,14.47,700,1,12.42,700,1,14.48,700,1,ARL,338864245
2303,2025-07-17T16:12:41.017837378Z,2025-07-17T16:12:41.017672033Z,160,2,1108,A,A,17,15.52,100,130,165345,282009053,13.11,100,1,13.48,15,1,12.98,200,2,13.49,100,1,12.92,2,1,13.74,2,1,12.86,100,1,13.76,100,1,12.73,100,1,14.25,100,1,12.71,100,1,14.28,100,1,12.50,700,1,14.40,200,2,12.46,100,1,14.44,200,2,12.43,700,1,14.47,700,1,12.42,700,1,14.48,700,1,ARL,338865301
2304,2025-07-17T16:12:41.032270817Z,2025-07-17T16:12:41.032105565Z,160,2,1108,C,A,15,15.17,100,0,165252,282009412,13.11,100,1,13.48,15,1,12.98,200,2,13.49,100,1,12.92,2,1,13.74,2,1,12.86,100,1,13.76,100,1,12.73,100,1,14.25,100,1,12.71,100,1,14.28,100,1,12.50,700,1,14.40,200,2,12.46,100,1,14.44,200,2,12.43,700,1,14.47,700,1,12.42,700,1,14.48,700,1,ARL,338864221
2305,2025-07-17T16:12:41.032270817Z,2025-07-17T16:12:41.032105565Z,160,2,1108,A,A,13,14.84,100,130,165252,282009412,13.11,100,1,13.48,15,1,12.98,200,2,13.49,100,1,12.92,2,1,13.74,2,1,12.86,100,1,13.76,100,1,12.73,100,1,14.25,100,1,12.71,100,1,14.28,100,1,12.50,700,1,14.40,200,2,12.46,100,1,14.44,200,2,12.43,700,1,14.47,700,1,12.42,700,1,14.48,700,1,ARL,338866081
2306,2025-07-17T16:12:41.032312420Z,2025-07-17T16:12:41.032147083Z,160,2,1108,A,A,17,15.38,100,130,165337,282009414,13.11,100,1,13.48,15,1,12.98,200,2,13.49,100,1,12.92,2,1,13.74,2,1,12.86,100,1,13.76,100,1,12.73,100,1,14.25,100,1,12.71,100,1,14.28,100,1,12.50,700,1,14.40,200,2,12.46,100,1,14.44,200,2,12.43,700,1,14.47,700,1,12.42,700,1,14.48,700,1,ARL,338866089
2307,2025-07-17T16:12:41.032324438Z,2025-07-17T16:12:41.032159348Z,160,2,1108,C,A,19,15.71,100,130,165090,282009415,13.11,100,1,13.48,15,1,12.98,200,2,13.49,100,1,12.92,2,1,13.74,2,1,12.86,100,1,13.76,100,1,12.73,100,1,14.25,100,1,12.71,100,1,14.28,100,1,12.50,700,1,14.40,200,2,12.46,100,1,14.44,200,2,12.43,700,1,14.47,700,1,12.42,700,1,14.48,700,1,ARL,338864177
2308,2025-07-17T16:12:41.043406383Z,2025-07-17T16:12:41.043241012Z,160,2,1108,C,A,14,14.85,100,0,165371,282009482,13.11,100,1,13.48,15,1,12.98,200,2,13.49,100,1,12.92,2,1,13.74,2,1,12.86,100,1,13.76,100,1,12.73,100,1,14.25,100,1,12.71,100,1,14.28,100,1,12.50,700,1,14.40,200,2,12.46,100,1,14.44,200,2,12.43,700,1,14.47,700,1,12.42,700,1,14.48,700,1,ARL,338864189
2309,2025-07-17T16:12:41.043406383Z,2025-07-17T16:12:41.043241012Z,160,2,1108,A,A,10,14.54,100,130,165371,282009482,13.11,100,1,13.48,15,1,12.98,200,2,13.49,100,1,12.92,2,1,13.74,2,1,12.86,100,1,13.76,100,1,12.73,100,1,14.25,100,1,12.71,100,1,14.28,100,1,12.50,700,1,14.40,200,2,12.46,100,1,14.44,200,2,12.43,700,1,14.47,700,1,12.42,700,1,14.48,700,1,ARL,338866245
2310,2025-07-17T16:12:42.001347844Z,2025-07-17T16:12:42.001182016Z,160,2,1108,C,A,12,14.58,100,0,165828,282033913,13.11,100,1,13.48,15,1,12.98,200,2,13.49,100,1,12.92,2,1,13.74,2,1,12.86,100,1,13.76,100,1,12.73,100,1,14.25,100,1,12.71,100,1,14.28,100,1,12.50,700,1,14.40,200,2,12.46,100,1,14.44,200,2,12.43,700,1,14.47,700,1,12.42,700,1,14.48,700,1,ARL,338864317
2311,2025-07-17T16:12:42.001347844Z,2025-07-17T16:12:42.001182016Z,160,2,1108,A,A,5,14.28,100,130,165828,282033913,13.11,100,1,13.48,15,1,12.98,200,2,13.49,100,1,12.92,2,1,13.74,2,1,12.86,100,1,13.76,100,1,12.73,100,1,14.25,100,1,12.71,100,1,14.28,200,2,12.50,700,1,14.40,200,2,12.46,100,1,14.44,200,2,12.43,700,1,14.47,700,1,12.42,700,1,14.48,700,1,ARL,338894329
2312,2025-07-17T16:12:42.762154469Z,2025-07-17T16:12:42.761989222Z,160,2,1108,A,A,0,13.46,15,130,165247,282042242,13.11,100,1,13.46,15,1,12.98,200,2,13.48,15,1,12.92,2,1,13.49,100,1,12.86,100,1,13.74,2,1,12.73,100,1,13.76,100,1,12.71,100,1,14.25,100,1,12.50,700,1,14.28,200,2,12.46,100,1,14.40,200,2,12.43,700,1,14.44,200,2,12.42,700,1,14.47,700,1,ARL,338904977
2313,2025-07-17T16:12:43.022127902Z,2025-07-17T16:12:43.021951997Z,160,2,1108,C,A,2,13.49,100,0,175905,282057719,13.11,100,1,13.46,15,1,12.98,200,2,13.48,15,1,12.92,2,1,13.74,2,1,12.86,100,1,13.76,100,1,12.73,100,1,14.25,100,1,12.71,100,1,14.28,200,2,12.50,700,1,14.40,200,2,12.46,100,1,14.44,200,2,12.43,700,1,14.47,700,1,12.42,700,1,14.48,700,1,ARL,338864581
2314,2025-07-17T16:12:43.022127902Z,2025-07-17T16:12:43.021951997Z,160,2,1108,A,A,1,13.47,100,128,175905,282057719,13.11,100,1,13.46,15,1,12.98,200,2,13.47,100,1,12.92,2,1,13.48,15,1,12.86,100,1,13.74,2,1,12.73,100,1,13.76,100,1,12.71,100,1,14.25,100,1,12.50,700,1,14.28,200,2,12.46,100,1,14.40,200,2,12.43,700,1,14.44,200,2,12.42,700,1,14.47,700,1,ARL,338918217
2315,2025-07-17T16:12:43.022612177Z,2025-07-17T16:12:43.022444956Z,160,2,1108,A,A,18,15.69,100,128,167221,282058085,13.11,100,1,13.46,15,1,12.98,200,2,13.47,100,1,12.92,2,1,13.48,15,1,12.86,100,1,13.74,2,1,12.73,100,1,13.76,100,1,12.71,100,1,14.25,100,1,12.50,700,1,14.28,200,2,12.46,100,1,14.40,200,2,12.43,700,1,14.44,200,2,12.42,700,1,14.47,700,1,ARL,338918553
2316,2025-07-17T16:12:43.022627592Z,2025-07-17T16:12:43.022461725Z,160,2,1108,C,A,16,15.38,100,130,165867,282058088,13.11,100,1,13.46,15,1,12.98,200,2,13.47,100,1,12.92,2,1,13.48,15,1,12.86,100,1,13.74,2,1,12.73,100,1,13.76,100,1,12.71,100,1,14.25,100,1,12.50,700,1,14.28,200,2,12.46,100,1,14.40,200,2,12.43,700,1,14.44,200,2,12.42,700,1,14.47,700,1,ARL,338866089
2317,2025-07-17T16:12:43.049284355Z,2025-07-17T16:12:43.049119139Z,160,2,1108,A,A,16,15.36,100,130,165216,282065940,13.11,100,1,13.46,15,1,12.98,200,2,13.47,100,1,12.92,2,1,13.48,15,1,12.86,100,1,13.74,2,1,12.73,100,1,13.76,100,1,12.71,100,1,14.25,100,1,12.50,700,1,14.28,200,2,12.46,100,1,14.40,200,2,12.43,700,1,14.44,200,2,12.42,700,1,14.47,700,1,ARL,338926929
2318,2025-07-17T16:12:43.049298989Z,2025-07-17T16:12:43.049132842Z,160,2,1108,C,A,18,15.69,100,128,166147,282065943,13.11,100,1,13.46,15,1,12.98,200,2,13.47,100,1,12.92,2,1,13.48,15,1,12.86,100,1,13.74,2,1,12.73,100,1,13.76,100,1,12.71,100,1,14.25,100,1,12.50,700,1,14.28,200,2,12.46,100,1,14.40,200,2,12.43,700,1,14.44,200,2,12.42,700,1,14.47,700,1,ARL,338918553
2319,2025-07-17T16:12:43.154952375Z,2025-07-17T16:12:43.154787212Z,160,2,1108,A,A,6,14.27,100,130,165163,282073056,13.11,100,1,13.46,15,1,12.98,200,2,13.47,100,1,12.92,2,1,13.48,15,1,12.86,100,1,13.74,2,1,12.73,100,1,13.76,100,1,12.71,100,1,14.25,100,1,12.50,700,1,14.27,100,1,12.46,100,1,14.28,200,2,12.43,700,1,14.40,200,2,12.42,700,1,14.44,200,2,ARL,338932853
2320,2025-07-17T16:12:43.154965183Z,2025-07-17T16:12:43.154800020Z,160,2,1108,C,A,13,14.56,100,130,165163,282073058,13.11,100,1,13.46,15,1,12.98,200,2,13.47,100,1,12.92,2,1,13.48,15,1,12.86,100,1,13.74,2,1,12.73,100,1,13.76,100,1,12.71,100,1,14.25,100,1,12.50,700,1,14.27,100,1,12.46,100,1,14.28,200,2,12.43,700,1,14.40,200,2,12.42,700,1,14.44,200,2,ARL,296391881
2321,2025-07-17T16:12:43.915552526Z,2025-07-17T16:12:43.915387059Z,160,2,1108,C,A,7,14.28,100,130,165467,282085822,13.11,100,1,13.46,15,1,12.98,200,2,13.47,100,1,12.92,2,1,13.48,15,1,12.86,100,1,13.74,2,1,12.73,100,1,13.76,100,1,12.71,100,1,14.25,100,1,12.50,700,1,14.27,100,1,12.46,100,1,14.28,100,1,12.43,700,1,14.40,200,2,12.42,700,1,14.44,200,2,ARL,302681357
2322,2025-07-17T16:12:43.915555340Z,2025-07-17T16:12:43.915389642Z,160,2,1108,A,A,5,14.00,100,130,165698,282085823,13.11,100,1,13.46,15,1,12.98,200,2,13.47,100,1,12.92,2,1,13.48,15,1,12.86,100,1,13.74,2,1,12.73,100,1,13.76,100,1,12.71,100,1,14.00,100,1,12.50,700,1,14.25,100,1,12.46,100,1,14.27,100,1,12.43,700,1,14.28,100,1,12.42,700,1,14.40,200,2,ARL,338945933
2323,2025-07-17T16:12:50.729244449Z,2025-07-17T16:12:50.729079105Z,160,2,1108,C,A,0,13.46,15,130,165344,282168721,13.11,100,1,13.47,100,1,12.98,200,2,13.48,15,1,12.92,2,1,13.74,2,1,12.86,100,1,13.76,100,1,12.73,100,1,14.00,100,1,12.71,100,1,14.25,100,1,12.50,700,1,14.27,100,1,12.46,100,1,14.28,100,1,12.43,700,1,14.40,200,2,12.42,700,1,14.44,200,2,ARL,338904977
2324,2025-07-17T16:12:50.729418237Z,2025-07-17T16:12:50.729252907Z,160,2,1108,C,A,1,13.48,15,130,165330,282168744,13.11,100,1,13.47,100,1,12.98,200,2,13.74,2,1,12.92,2,1,13.76,100,1,12.86,100,1,14.00,100,1,12.73,100,1,14.25,100,1,12.71,100,1,14.27,100,1,12.50,700,1,14.28,100,1,12.46,100,1,14.40,200,2,12.43,700,1,14.44,200,2,12.42,700,1,14.47,700,1,ARL,338707945
2325,2025-07-17T16:12:50.729575741Z,2025-07-17T16:12:50.729409745Z,160,2,1108,A,A,0,13.47,96,130,165996,282168754,13.11,100,1,13.47,196,2,12.98,200,2,13.74,2,1,12.92,2,1,13.76,100,1,12.86,100,1,14.00,100,1,12.73,100,1,14.25,100,1,12.71,100,1,14.27,100,1,12.50,700,1,14.28,100,1,12.46,100,1,14.40,200,2,12.43,700,1,14.44,200,2,12.42,700,1,14.47,700,1,ARL,339054149
2326,2025-07-17T16:12:53.021914652Z,2025-07-17T16:12:53.021749348Z,160,2,1108,A,A,0,13.46,15,130,165304,282194154,13.11,100,1,13.46,15,1,12.98,200,2,13.47,196,2,12.92,2,1,13.74,2,1,12.86,100,1,13.76,100,1,12.73,100,1,14.00,100,1,12.71,100,1,14.25,100,1,12.50,700,1,14.27,100,1,12.46,100,1,14.28,100,1,12.43,700,1,14.40,200,2,12.42,700,1,14.44,200,2,ARL,339096733
2327,2025-07-17T16:12:53.021959141Z,2025-07-17T16:12:53.021793735Z,160,2,1108,C,A,1,13.47,100,130,165406,282194157,13.11,100,1,13.46,15,1,12.98,200,2,13.47,96,1,12.92,2,1,13.74,2,1,12.86,100,1,13.76,100,1,12.73,100,1,14.00,100,1,12.71,100,1,14.25,100,1,12.50,700,1,14.27,100,1,12.46,100,1,14.28,100,1,12.43,700,1,14.40,200,2,12.42,700,1,14.44,200,2,ARL,338918217
2328,2025-07-17T16:12:53.022230122Z,2025-07-17T16:12:53.022064745Z,160,2,1108,C,A,1,13.47,96,130,165377,282194159,13.11,100,1,13.46,15,1,12.98,200,2,13.74,2,1,12.92,2,1,13.76,100,1,12.86,100,1,14.00,100,1,12.73,100,1,14.25,100,1,12.71,100,1,14.27,100,1,12.50,700,1,14.28,100,1,12.46,100,1,14.40,200,2,12.43,700,1,14.44,200,2,12.42,700,1,14.47,700,1,ARL,339054149
2329,2025-07-17T16:12:53.022572023Z,2025-07-17T16:12:53.022406202Z,160,2,1108,A,A,18,15.69,100,130,165821,282194161,13.11,100,1,13.46,15,1,12.98,200,2,13.74,2,1,12.92,2,1,13.76,100,1,12.86,100,1,14.00,100,1,12.73,100,1,14.25,100,1,12.71,100,1,14.27,100,1,12.50,700,1,14.28,100,1,12.46,100,1,14.40,200,2,12.43,700,1,14.44,200,2,12.42,700,1,14.47,700,1,ARL,339096757
2330,2025-07-17T16:12:53.022584264Z,2025-07-17T16:12:53.022418950Z,160,2,1108,C,A,16,15.36,100,130,165314,282194162,13.11,100,1,13.46,15,1,12.98,200,2,13.74,2,1,12.92,2,1,13.76,100,1,12.86,100,1,14.00,100,1,12.73,100,1,14.25,100,1,12.71,100,1,14.27,100,1,12.50,700,1,14.28,100,1,12.46,100,1,14.40,200,2,12.43,700,1,14.44,200,2,12.42,700,1,14.47,700,1,ARL,338926929
2331,2025-07-17T16:12:53.022962940Z,2025-07-17T16:12:53.022797046Z,160,2,1108,C,A,11,14.54,100,0,165894,282194167,13.11,100,1,13.46,15,1,12.98,200,2,13.74,2,1,12.92,2,1,13.76,100,1,12.86,100,1,14.00,100,1,12.73,100,1,14.25,100,1,12.71,100,1,14.27,100,1,12.50,700,1,14.28,100,1,12.46,100,1,14.40,200,2,12.43,700,1,14.44,200,2,12.42,700,1,14.47,700,1,ARL,338866245
2332,2025-07-17T16:12:53.022962940Z,2025-07-17T16:12:53.022797046Z,160,2,1108,A,A,13,14.83,100,130,165894,282194167,13.11,100,1,13.46,15,1,12.98,200,2,13.74,2,1,12.92,2,1,13.76,100,1,12.86,100,1,14.00,100,1,12.73,100,1,14.25,100,1,12.71,100,1,14.27,100,1,12.50,700,1,14.28,100,1,12.46,100,1,14.40,200,2,12.43,700,1,14.44,200,2,12.42,700,1,14.47,700,1,ARL,339096773
2333,2025-07-17T16:12:53.023589530Z,2025-07-17T16:12:53.023423468Z,160,2,1108,C,A,8,14.44,100,0,166062,282194181,13.11,100,1,13.46,15,1,12.98,200,2,13.74,2,1,12.92,2,1,13.76,100,1,12.86,100,1,14.00,100,1,12.73,100,1,14.25,100,1,12.71,100,1,14.27,100,1,12.50,700,1,14.28,100,1,12.46,100,1,14.40,200,2,12.43,700,1,14.44,100,1,12.42,700,1,14.47,700,1,ARL,338865165
2334,2025-07-17T16:12:53.023589530Z,2025-07-17T16:12:53.023423468Z,160,2,1108,A,A,13,14.73,100,130,166062,282194181,13.11,100,1,13.46,15,1,12.98,200,2,13.74,2,1,12.92,2,1,13.76,100,1,12.86,100,1,14.00,100,1,12.73,100,1,14.25,100,1,12.71,100,1,14.27,100,1,12.50,700,1,14.28,100,1,12.46,100,1,14.40,200,2,12.43,700,1,14.44,100,1,12.42,700,1,14.47,700,1,ARL,339096797
2335,2025-07-17T16:12:53.024069153Z,2025-07-17T16:12:53.023903582Z,160,2,1108,C,A,21,17.14,100,0,165571,282194183,13.11,100,1,13.46,15,1,12.98,200,2,13.74,2,1,12.92,2,1,13.76,100,1,12.86,100,1,14.00,100,1,12.73,100,1,14.25,100,1,12.71,100,1,14.27,100,1,12.50,700,1,14.28,100,1,12.46,100,1,14.40,200,2,12.43,700,1,14.44,100,1,12.42,700,1,14.47,700,1,ARL,338865253
2336,2025-07-17T16:12:53.024069153Z,2025-07-17T16:12:53.023903582Z,160,2,1108,A,A,22,17.48,100,130,165571,282194183,13.11,100,1,13.46,15,1,12.98,200,2,13.74,2,1,12.92,2,1,13.76,100,1,12.86,100,1,14.00,100,1,12.73,100,1,14.25,100,1,12.71,100,1,14.27,100,1,12.50,700,1,14.28,100,1,12.46,100,1,14.40,200,2,12.43,700,1,14.44,100,1,12.42,700,1,14.47,700,1,ARL,339096809
2337,2025-07-17T16:12:53.025583784Z,2025-07-17T16:12:53.025418159Z,160,2,1108,C,A,15,14.84,100,0,165625,282194188,13.11,100,1,13.46,15,1,12.98,200,2,13.74,2,1,12.92,2,1,13.76,100,1,12.86,100,1,14.00,100,1,12.73,100,1,14.25,100,1,12.71,100,1,14.27,100,1,12.50,700,1,14.28,100,1,12.46,100,1,14.40,200,2,12.43,700,1,14.44,100,1,12.42,700,1,14.47,700,1,ARL,338866081
2338,2025-07-17T16:12:53.025583784Z,2025-07-17T16:12:53.025418159Z,160,2,1108,A,A,16,15.14,100,130,165625,282194188,13.11,100,1,13.46,15,1,12.98,200,2,13.74,2,1,12.92,2,1,13.76,100,1,12.86,100,1,14.00,100,1,12.73,100,1,14.25,100,1,12.71,100,1,14.27,100,1,12.50,700,1,14.28,100,1,12.46,100,1,14.40,200,2,12.43,700,1,14.44,100,1,12.42,700,1,14.47,700,1,ARL,339096813
2339,2025-07-17T16:12:53.025651983Z,2025-07-17T16:12:53.025486466Z,160,2,1108,C,A,8,14.44,100,0,165517,282194189,13.11,100,1,13.46,15,1,12.98,200,2,13.74,2,1,12.92,2,1,13.76,100,1,12.86,100,1,14.00,100,1,12.73,100,1,14.25,100,1,12.71,100,1,14.27,100,1,12.50,700,1,14.28,100,1,12.46,100,1,14.40,200,2,12.43,700,1,14.47,700,1,12.42,700,1,14.48,700,1,ARL,338865133
2340,2025-07-17T16:12:53.025651983Z,2025-07-17T16:12:53.025486466Z,160,2,1108,A,A,12,14.73,100,130,165517,282194189,13.11,100,1,13.46,15,1,12.98,200,2,13.74,2,1,12.92,2,1,13.76,100,1,12.86,100,1,14.00,100,1,12.73,100,1,14.25,100,1,12.71,100,1,14.27,100,1,12.50,700,1,14.28,100,1,12.46,100,1,14.40,200,2,12.43,700,1,14.47,700,1,12.42,700,1,14.48,700,1,ARL,339096817
2341,2025-07-17T16:12:53.027715026Z,2025-07-17T16:12:53.027549524Z,160,2,1108,C,A,6,14.28,100,130,165502,282194224,13.11,100,1,13.46,15,1,12.98,200,2,13.74,2,1,12.92,2,1,13.76,100,1,12.86,100,1,14.00,100,1,12.73,100,1,14.25,100,1,12.71,100,1,14.27,100,1,12.50,700,1,14.40,200,2,12.46,100,1,14.47,700,1,12.43,700,1,14.48,700,1,12.42,700,1,14.54,700,1,ARL,338894329
2342,2025-07-17T16:12:53.027866777Z,2025-07-17T16:12:53.027701439Z,160,2,1108,A,A,10,14.55,100,130,165338,282194226,13.11,100,1,13.46,15,1,12.98,200,2,13.74,2,1,12.92,2,1,13.76,100,1,12.86,100,1,14.00,100,1,12.73,100,1,14.25,100,1,12.71,100,1,14.27,100,1,12.50,700,1,14.40,200,2,12.46,100,1,14.47,700,1,12.43,700,1,14.48,700,1,12.42,700,1,14.54,700,1,ARL,339096833
2343,2025-07-17T16:12:53.027987030Z,2025-07-17T16:12:53.027821450Z,160,2,1108,C,A,17,15.52,100,0,165580,282194228,13.11,100,1,13.46,15,1,12.98,200,2,13.74,2,1,12.92,2,1,13.76,100,1,12.86,100,1,14.00,100,1,12.73,100,1,14.25,100,1,12.71,100,1,14.27,100,1,12.50,700,1,14.40,200,2,12.46,100,1,14.47,700,1,12.43,700,1,14.48,700,1,12.42,700,1,14.54,700,1,ARL,338865301
2344,2025-07-17T16:12:53.027987030Z,2025-07-17T16:12:53.027821450Z,160,2,1108,A,A,18,15.83,100,130,165580,282194228,13.11,100,1,13.46,15,1,12.98,200,2,13.74,2,1,12.92,2,1,13.76,100,1,12.86,100,1,14.00,100,1,12.73,100,1,14.25,100,1,12.71,100,1,14.27,100,1,12.50,700,1,14.40,200,2,12.46,100,1,14.47,700,1,12.43,700,1,14.48,700,1,12.42,700,1,14.54,700,1,ARL,339096837
2345,2025-07-17T16:12:53.033266537Z,2025-07-17T16:12:53.033101265Z,160,2,1108,C,A,2,13.76,100,130,165272,282194348,13.11,100,1,13.46,15,1,12.98,200,2,13.74,2,1,12.92,2,1,14.00,100,1,12.86,100,1,14.25,100,1,12.73,100,1,14.27,100,1,12.71,100,1,14.40,200,2,12.50,700,1,14.47,700,1,12.46,100,1,14.48,700,1,12.43,700,1,14.54,700,1,12.42,700,1,14.55,100,1,ARL,338865177
2346,2025-07-17T16:12:53.033302848Z,2025-07-17T16:12:53.033137644Z,160,2,1108,C,A,6,14.47,700,130,165204,282194349,13.11,100,1,13.46,15,1,12.98,200,2,13.74,2,1,12.92,2,1,14.00,100,1,12.86,100,1,14.25,100,1,12.73,100,1,14.27,100,1,12.71,100,1,14.40,200,2,12.50,700,1,14.48,700,1,12.46,100,1,14.54,700,1,12.43,700,1,14.55,100,1,12.42,700,1,14.56,700,1,ARL,338864173
2347,2025-07-17T16:12:53.033318818Z,2025-07-17T16:12:53.033153612Z,160,2,1108,A,A,3,14.04,100,130,165206,282194350,13.11,100,1,13.46,15,1,12.98,200,2,13.74,2,1,12.92,2,1,14.00,100,1,12.86,100,1,14.04,100,1,12.73,100,1,14.25,100,1,12.71,100,1,14.27,100,1,12.50,700,1,14.40,200,2,12.46,100,1,14.48,700,1,12.43,700,1,14.54,700,1,12.42,700,1,14.55,100,1,ARL,339096893
2348,2025-07-17T16:12:53.033349323Z,2025-07-17T16:12:53.033183560Z,160,2,1108,A,A,11,14.68,700,130,165763,282194351,13.11,100,1,13.46,15,1,12.98,200,2,13.74,2,1,12.92,2,1,14.00,100,1,12.86,100,1,14.04,100,1,12.73,100,1,14.25,100,1,12.71,100,1,14.27,100,1,12.50,700,1,14.40,200,2,12.46,100,1,14.48,700,1,12.43,700,1,14.54,700,1,12.42,700,1,14.55,100,1,ARL,339096897
2349,2025-07-17T16:12:53.033762072Z,2025-07-17T16:12:53.033596046Z,160,2,1108,C,A,1,13.74,2,0,166026,282194354,13.11,100,1,13.46,15,1,12.98,200,2,14.00,100,1,12.92,2,1,14.04,100,1,12.86,100,1,14.25,100,1,12.73,100,1,14.27,100,1,12.71,100,1,14.40,200,2,12.50,700,1,14.48,700,1,12.46,100,1,14.54,700,1,12.43,700,1,14.55,100,1,12.42,700,1,14.56,700,1,ARL,338371797
2350,2025-07-17T16:12:53.033762072Z,2025-07-17T16:12:53.033596046Z,160,2,1108,A,A,1,13.98,2,130,166026,282194354,13.11,100,1,13.46,15,1,12.98,200,2,13.98,2,1,12.92,2,1,14.00,100,1,12.86,100,1,14.04,100,1,12.73,100,1,14.25,100,1,12.71,100,1,14.27,100,1,12.50,700,1,14.40,200,2,12.46,100,1,14.48,700,1,12.43,700,1,14.54,700,1,12.42,700,1,14.55,100,1,ARL,339096909
2351,2025-07-17T16:12:53.034000646Z,2025-07-17T16:12:53.033835120Z,160,2,1108,C,A,4,14.25,100,130,165526,282194360,13.11,100,1,13.46,15,1,12.98,200,2,13.98,2,1,12.92,2,1,14.00,100,1,12.86,100,1,14.04,100,1,12.73,100,1,14.27,100,1,12.71,100,1,14.40,200,2,12.50,700,1,14.48,700,1,12.46,100,1,14.54,700,1,12.43,700,1,14.55,100,1,12.42,700,1,14.56,700,1,ARL,336161365
2352,2025-07-17T16:12:53.034142471Z,2025-07-17T16:12:53.033977054Z,160,2,1108,C,A,11,14.73,100,0,165417,282194361,13.11,100,1,13.46,15,1,12.98,200,2,13.98,2,1,12.92,2,1,14.00,100,1,12.86,100,1,14.04,100,1,12.73,100,1,14.27,100,1,12.71,100,1,14.40,200,2,12.50,700,1,14.48,700,1,12.46,100,1,14.54,700,1,12.43,700,1,14.55,100,1,12.42,700,1,14.56,700,1,ARL,339096797
2353,2025-07-17T16:12:53.034142471Z,2025-07-17T16:12:53.033977054Z,160,2,1108,A,A,13,14.96,100,130,165417,282194361,13.11,100,1,13.46,15,1,12.98,200,2,13.98,2,1,12.92,2,1,14.00,100,1,12.86,100,1,14.04,100,1,12.73,100,1,14.27,100,1,12.71,100,1,14.40,200,2,12.50,700,1,14.48,700,1,12.46,100,1,14.54,700,1,12.43,700,1,14.55,100,1,12.42,700,1,14.56,700,1,ARL,339096917
2354,2025-07-17T16:12:53.034178176Z,2025-07-17T16:12:53.034012618Z,160,2,1108,C,A,18,15.83,100,0,165558,282194362,13.11,100,1,13.46,15,1,12.98,200,2,13.98,2,1,12.92,2,1,14.00,100,1,12.86,100,1,14.04,100,1,12.73,100,1,14.27,100,1,12.71,100,1,14.40,200,2,12.50,700,1,14.48,700,1,12.46,100,1,14.54,700,1,12.43,700,1,14.55,100,1,12.42,700,1,14.56,700,1,ARL,339096837
2355,2025-07-17T16:12:53.034178176Z,2025-07-17T16:12:53.034012618Z,160,2,1108,A,A,18,16.08,100,130,165558,282194362,13.11,100,1,13.46,15,1,12.98,200,2,13.98,2,1,12.92,2,1,14.00,100,1,12.86,100,1,14.04,100,1,12.73,100,1,14.27,100,1,12.71,100,1,14.40,200,2,12.50,700,1,14.48,700,1,12.46,100,1,14.54,700,1,12.43,700,1,14.55,100,1,12.42,700,1,14.56,700,1,ARL,339096921
2356,2025-07-17T16:12:53.034353140Z,2025-07-17T16:12:53.034187864Z,160,2,1108,A,A,10,14.60,100,130,165276,282194365,13.11,100,1,13.46,15,1,12.98,200,2,13.98,2,1,12.92,2,1,14.00,100,1,12.86,100,1,14.04,100,1,12.73,100,1,14.27,100,1,12.71,100,1,14.40,200,2,12.50,700,1,14.48,700,1,12.46,100,1,14.54,700,1,12.43,700,1,14.55,100,1,12.42,700,1,14.56,700,1,ARL,339096925
2357,2025-07-17T16:12:53.035411748Z,2025-07-17T16:12:53.035246187Z,160,2,1108,C,A,15,15.05,100,0,165561,282194373,13.11,100,1,13.46,15,1,12.98,200,2,13.98,2,1,12.92,2,1,14.00,100,1,12.86,100,1,14.04,100,1,12.73,100,1,14.27,100,1,12.71,100,1,14.40,200,2,12.50,700,1,14.48,700,1,12.46,100,1,14.54,700,1,12.43,700,1,14.55,100,1,12.42,700,1,14.56,700,1,ARL,335220549
2358,2025-07-17T16:12:53.035411748Z,2025-07-17T16:12:53.035246187Z,160,2,1108,A,A,17,15.38,100,130,165561,282194373,13.11,100,1,13.46,15,1,12.98,200,2,13.98,2,1,12.92,2,1,14.00,100,1,12.86,100,1,14.04,100,1,12.73,100,1,14.27,100,1,12.71,100,1,14.40,200,2,12.50,700,1,14.48,700,1,12.46,100,1,14.54,700,1,12.43,700,1,14.55,100,1,12.42,700,1,14.56,700,1,ARL,339096929
2359,2025-07-17T16:12:53.036307382Z,2025-07-17T16:12:53.036142164Z,160,2,1108,C,A,21,17.48,100,0,165218,282194381,13.11,100,1,13.46,15,1,12.98,200,2,13.98,2,1,12.92,2,1,14.00,100,1,12.86,100,1,14.04,100,1,12.73,100,1,14.27,100,1,12.71,100,1,14.40,200,2,12.50,700,1,14.48,700,1,12.46,100,1,14.54,700,1,12.43,700,1,14.55,100,1,12.42,700,1,14.56,700,1,ARL,339096809
2360,2025-07-17T16:12:53.036307382Z,2025-07-17T16:12:53.036142164Z,160,2,1108,A,A,21,17.76,100,130,165218,282194381,13.11,100,1,13.46,15,1,12.98,200,2,13.98,2,1,12.92,2,1,14.00,100,1,12.86,100,1,14.04,100,1,12.73,100,1,14.27,100,1,12.71,100,1,14.40,200,2,12.50,700,1,14.48,700,1,12.46,100,1,14.54,700,1,12.43,700,1,14.55,100,1,12.42,700,1,14.56,700,1,ARL,339096949
2361,2025-07-17T16:12:53.040045217Z,2025-07-17T16:12:53.039879965Z,160,2,1108,C,A,12,14.73,100,0,165252,282194416,13.11,100,1,13.46,15,1,12.98,200,2,13.98,2,1,12.92,2,1,14.00,100,1,12.86,100,1,14.04,100,1,12.73,100,1,14.27,100,1,12.71,100,1,14.40,200,2,12.50,700,1,14.48,700,1,12.46,100,1,14.54,700,1,12.43,700,1,14.55,100,1,12.42,700,1,14.56,700,1,ARL,339096817
2362,2025-07-17T16:12:53.040045217Z,2025-07-17T16:12:53.039879965Z,160,2,1108,A,A,13,14.96,100,130,165252,282194416,13.11,100,1,13.46,15,1,12.98,200,2,13.98,2,1,12.92,2,1,14.00,100,1,12.86,100,1,14.04,100,1,12.73,100,1,14.27,100,1,12.71,100,1,14.40,200,2,12.50,700,1,14.48,700,1,12.46,100,1,14.54,700,1,12.43,700,1,14.55,100,1,12.42,700,1,14.56,700,1,ARL,339096977
2363,2025-07-17T16:12:53.043727225Z,2025-07-17T16:12:53.043562198Z,160,2,1108,C,A,3,14.04,100,130,165027,282194436,13.11,100,1,13.46,15,1,12.98,200,2,13.98,2,1,12.92,2,1,14.00,100,1,12.86,100,1,14.27,100,1,12.73,100,1,14.40,200,2,12.71,100,1,14.48,700,1,12.50,700,1,14.54,700,1,12.46,100,1,14.55,100,1,12.43,700,1,14.56,700,1,12.42,700,1,14.60,100,1,ARL,339096893
2364,2025-07-17T16:12:53.043775299Z,2025-07-17T16:12:53.043610101Z,160,2,1108,A,A,3,14.26,100,130,165198,282194438,13.11,100,1,13.46,15,1,12.98,200,2,13.98,2,1,12.92,2,1,14.00,100,1,12.86,100,1,14.26,100,1,12.73,100,1,14.27,100,1,12.71,100,1,14.40,200,2,12.50,700,1,14.48,700,1,12.46,100,1,14.54,700,1,12.43,700,1,14.55,100,1,12.42,700,1,14.56,700,1,ARL,339097005
2365,2025-07-17T16:12:53.073052597Z,2025-07-17T16:12:53.072887133Z,160,2,1108,C,A,12,14.83,100,0,165464,282194725,13.11,100,1,13.46,15,1,12.98,200,2,13.98,2,1,12.92,2,1,14.00,100,1,12.86,100,1,14.26,100,1,12.73,100,1,14.27,100,1,12.71,100,1,14.40,200,2,12.50,700,1,14.48,700,1,12.46,100,1,14.54,700,1,12.43,700,1,14.55,100,1,12.42,700,1,14.56,700,1,ARL,339096773
2366,2025-07-17T16:12:53.073052597Z,2025-07-17T16:12:53.072887133Z,160,2,1108,A,A,13,15.06,100,130,165464,282194725,13.11,100,1,13.46,15,1,12.98,200,2,13.98,2,1,12.92,2,1,14.00,100,1,12.86,100,1,14.26,100,1,12.73,100,1,14.27,100,1,12.71,100,1,14.40,200,2,12.50,700,1,14.48,700,1,12.46,100,1,14.54,700,1,12.43,700,1,14.55,100,1,12.42,700,1,14.56,700,1,ARL,339097245
2367,2025-07-17T16:12:53.332729487Z,2025-07-17T16:12:53.332564148Z,160,2,1108,C,A,2,14.00,100,130,165339,282196976,13.11,100,1,13.46,15,1,12.98,200,2,13.98,2,1,12.92,2,1,14.26,100,1,12.86,100,1,14.27,100,1,12.73,100,1,14.40,200,2,12.71,100,1,14.48,700,1,12.50,700,1,14.54,700,1,12.46,100,1,14.55,100,1,12.43,700,1,14.56,700,1,12.42,700,1,14.60,100,1,ARL,338945933
2368,2025-07-17T16:12:53.332730508Z,2025-07-17T16:12:53.332565150Z,160,2,1108,A,A,6,14.53,100,130,165358,282196977,13.11,100,1,13.46,15,1,12.98,200,2,13.98,2,1,12.92,2,1,14.26,100,1,12.86,100,1,14.27,100,1,12.73,100,1,14.40,200,2,12.71,100,1,14.48,700,1,12.50,700,1,14.53,100,1,12.46,100,1,14.54,700,1,12.43,700,1,14.55,100,1,12.42,700,1,14.56,700,1,ARL,339100477
2369,2025-07-17T16:12:53.587788615Z,2025-07-17T16:12:53.587623157Z,160,2,1108,A,A,12,14.81,100,130,165458,282200199,13.11,100,1,13.46,15,1,12.98,200,2,13.98,2,1,12.92,2,1,14.26,100,1,12.86,100,1,14.27,100,1,12.73,100,1,14.40,200,2,12.71,100,1,14.48,700,1,12.50,700,1,14.53,100,1,12.46,100,1,14.54,700,1,12.43,700,1,14.55,100,1,12.42,700,1,14.56,700,1,ARL,339103269
2370,2025-07-17T16:12:53.587810242Z,2025-07-17T16:12:53.587644886Z,160,2,1108,C,A,3,14.27,100,130,165356,282200200,13.11,100,1,13.46,15,1,12.98,200,2,13.98,2,1,12.92,2,1,14.26,100,1,12.86,100,1,14.40,200,2,12.73,100,1,14.48,700,1,12.71,100,1,14.53,100,1,12.50,700,1,14.54,700,1,12.46,100,1,14.55,100,1,12.43,700,1,14.56,700,1,12.42,700,1,14.60,100,1,ARL,338932853
2371,2025-07-17T16:12:54.015217279Z,2025-07-17T16:12:54.015051915Z,160,2,1108,A,A,1,13.47,100,130,165364,282207405,13.11,100,1,13.46,15,1,12.98,200,2,13.47,100,1,12.92,2,1,13.98,2,1,12.86,100,1,14.26,100,1,12.73,100,1,14.40,200,2,12.71,100,1,14.48,700,1,12.50,700,1,14.53,100,1,12.46,100,1,14.54,700,1,12.43,700,1,14.55,100,1,12.42,700,1,14.56,700,1,ARL,339110853
2372,2025-07-17T16:12:54.015951319Z,2025-07-17T16:12:54.015785325Z,160,2,1108,C,A,10,14.60,100,130,165994,282207428,13.11,100,1,13.46,15,1,12.98,200,2,13.47,100,1,12.92,2,1,13.98,2,1,12.86,100,1,14.26,100,1,12.73,100,1,14.40,200,2,12.71,100,1,14.48,700,1,12.50,700,1,14.53,100,1,12.46,100,1,14.54,700,1,12.43,700,1,14.55,100,1,12.42,700,1,14.56,700,1,ARL,339096925
2373,2025-07-17T16:12:54.015954059Z,2025-07-17T16:12:54.015788678Z,160,2,1108,C,A,13,15.06,100,0,165381,282207429,13.11,100,1,13.46,15,1,12.98,200,2,13.47,100,1,12.92,2,1,13.98,2,1,12.86,100,1,14.26,100,1,12.73,100,1,14.40,200,2,12.71,100,1,14.48,700,1,12.50,700,1,14.53,100,1,12.46,100,1,14.54,700,1,12.43,700,1,14.55,100,1,12.42,700,1,14.56,700,1,ARL,339097245
2374,2025-07-17T16:12:54.015954059Z,2025-07-17T16:12:54.015788678Z,160,2,1108,A,A,6,14.52,100,130,165381,282207429,13.11,100,1,13.46,15,1,12.98,200,2,13.47,100,1,12.92,2,1,13.98,2,1,12.86,100,1,14.26,100,1,12.73,100,1,14.40,200,2,12.71,100,1,14.48,700,1,12.50,700,1,14.52,100,1,12.46,100,1,14.53,100,1,12.43,700,1,14.54,700,1,12.42,700,1,14.55,100,1,ARL,339110897
2375,2025-07-17T16:12:54.016305036Z,2025-07-17T16:12:54.016139684Z,160,2,1108,A,A,3,14.07,100,130,165352,282207437,13.11,100,1,13.46,15,1,12.98,200,2,13.47,100,1,12.92,2,1,13.98,2,1,12.86,100,1,14.07,100,1,12.73,100,1,14.26,100,1,12.71,100,1,14.40,200,2,12.50,700,1,14.48,700,1,12.46,100,1,14.52,100,1,12.43,700,1,14.53,100,1,12.42,700,1,14.54,700,1,ARL,339110909
2376,2025-07-17T16:12:54.017154493Z,2025-07-17T16:12:54.016988897Z,160,2,1108,C,A,14,14.96,100,0,165596,282207488,13.11,100,1,13.46,15,1,12.98,200,2,13.47,100,1,12.92,2,1,13.98,2,1,12.86,100,1,14.07,100,1,12.73,100,1,14.26,100,1,12.71,100,1,14.40,200,2,12.50,700,1,14.48,700,1,12.46,100,1,14.52,100,1,12.43,700,1,14.53,100,1,12.42,700,1,14.54,700,1,ARL,339096917
2377,2025-07-17T16:12:54.017154493Z,2025-07-17T16:12:54.016988897Z,160,2,1108,A,A,6,14.42,100,130,165596,282207488,13.11,100,1,13.46,15,1,12.98,200,2,13.47,100,1,12.92,2,1,13.98,2,1,12.86,100,1,14.07,100,1,12.73,100,1,14.26,100,1,12.71,100,1,14.40,200,2,12.50,700,1,14.42,100,1,12.46,100,1,14.48,700,1,12.43,700,1,14.52,100,1,12.42,700,1,14.53,100,1,ARL,339110981
2378,2025-07-17T16:12:54.017381126Z,2025-07-17T16:12:54.017215883Z,160,2,1108,C,A,2,13.98,2,0,165243,282207495,13.11,100,1,13.46,15,1,12.98,200,2,13.47,100,1,12.92,2,1,14.07,100,1,12.86,100,1,14.26,100,1,12.73,100,1,14.40,200,2,12.71,100,1,14.42,100,1,12.50,700,1,14.48,700,1,12.46,100,1,14.52,100,1,12.43,700,1,14.53,100,1,12.42,700,1,14.54,700,1,ARL,339096909
2379,2025-07-17T16:12:54.017381126Z,2025-07-17T16:12:54.017215883Z,160,2,1108,A,A,2,13.73,2,130,165243,282207495,13.11,100,1,13.46,15,1,12.98,200,2,13.47,100,1,12.92,2,1,13.73,2,1,12.86,100,1,14.07,100,1,12.73,100,1,14.26,100,1,12.71,100,1,14.40,200,2,12.50,700,1,14.42,100,1,12.46,100,1,14.48,700,1,12.43,700,1,14.52,100,1,12.42,700,1,14.53,100,1,ARL,339110993
2380,2025-07-17T16:12:54.017787766Z,2025-07-17T16:12:54.017622232Z,160,2,1108,C,A,18,15.38,100,0,165534,282207502,13.11,100,1,13.46,15,1,12.98,200,2,13.47,100,1,12.92,2,1,13.73,2,1,12.86,100,1,14.07,100,1,12.73,100,1,14.26,100,1,12.71,100,1,14.40,200,2,12.50,700,1,14.42,100,1,12.46,100,1,14.48,700,1,12.43,700,1,14.52,100,1,12.42,700,1,14.53,100,1,ARL,339096929
2381,2025-07-17T16:12:54.017787766Z,2025-07-17T16:12:54.017622232Z,160,2,1108,A,A,15,14.82,100,130,165534,282207502,13.11,100,1,13.46,15,1,12.98,200,2,13.47,100,1,12.92,2,1,13.73,2,1,12.86,100,1,14.07,100,1,12.73,100,1,14.26,100,1,12.71,100,1,14.40,200,2,12.50,700,1,14.42,100,1,12.46,100,1,14.48,700,1,12.43,700,1,14.52,100,1,12.42,700,1,14.53,100,1,ARL,339111005
2382,2025-07-17T16:12:54.020179178Z,2025-07-17T16:12:54.020013940Z,160,2,1108,C,A,4,14.26,100,130,165238,282207539,13.11,100,1,13.46,15,1,12.98,200,2,13.47,100,1,12.92,2,1,13.73,2,1,12.86,100,1,14.07,100,1,12.73,100,1,14.40,200,2,12.71,100,1,14.42,100,1,12.50,700,1,14.48,700,1,12.46,100,1,14.52,100,1,12.43,700,1,14.53,100,1,12.42,700,1,14.54,700,1,ARL,339097005
2383,2025-07-17T16:12:54.020233019Z,2025-07-17T16:12:54.020067630Z,160,2,1108,A,A,3,13.74,100,130,165389,282207540,13.11,100,1,13.46,15,1,12.98,200,2,13.47,100,1,12.92,2,1,13.73,2,1,12.86,100,1,13.74,100,1,12.73,100,1,14.07,100,1,12.71,100,1,14.40,200,2,12.50,700,1,14.42,100,1,12.46,100,1,14.48,700,1,12.43,700,1,14.52,100,1,12.42,700,1,14.53,100,1,ARL,339111029
2384,2025-07-17T16:12:54.023027943Z,2025-07-17T16:12:54.022862493Z,160,2,1108,C,A,22,17.76,100,0,165450,282207651,13.11,100,1,13.46,15,1,12.98,200,2,13.47,100,1,12.92,2,1,13.73,2,1,12.86,100,1,13.74,100,1,12.73,100,1,14.07,100,1,12.71,100,1,14.40,200,2,12.50,700,1,14.42,100,1,12.46,100,1,14.48,700,1,12.43,700,1,14.52,100,1,12.42,700,1,14.53,100,1,ARL,339096949
2385,2025-07-17T16:12:54.023027943Z,2025-07-17T16:12:54.022862493Z,160,2,1108,A,A,21,17.11,100,130,165450,282207651,13.11,100,1,13.46,15,1,12.98,200,2,13.47,100,1,12.92,2,1,13.73,2,1,12.86,100,1,13.74,100,1,12.73,100,1,14.07,100,1,12.71,100,1,14.40,200,2,12.50,700,1,14.42,100,1,12.46,100,1,14.48,700,1,12.43,700,1,14.52,100,1,12.42,700,1,14.53,100,1,ARL,339111097
2386,2025-07-17T16:12:54.026187354Z,2025-07-17T16:12:54.026021681Z,160,2,1108,C,A,20,16.08,100,0,165673,282207700,13.11,100,1,13.46,15,1,12.98,200,2,13.47,100,1,12.92,2,1,13.73,2,1,12.86,100,1,13.74,100,1,12.73,100,1,14.07,100,1,12.71,100,1,14.40,200,2,12.50,700,1,14.42,100,1,12.46,100,1,14.48,700,1,12.43,700,1,14.52,100,1,12.42,700,1,14.53,100,1,ARL,339096921
2387,2025-07-17T16:12:54.026187354Z,2025-07-17T16:12:54.026021681Z,160,2,1108,A,A,19,15.50,100,130,165673,282207700,13.11,100,1,13.46,15,1,12.98,200,2,13.47,100,1,12.92,2,1,13.73,2,1,12.86,100,1,13.74,100,1,12.73,100,1,14.07,100,1,12.71,100,1,14.40,200,2,12.50,700,1,14.42,100,1,12.46,100,1,14.48,700,1,12.43,700,1,14.52,100,1,12.42,700,1,14.53,100,1,ARL,339111149
2388,2025-07-17T16:12:54.029232379Z,2025-07-17T16:12:54.029066847Z,160,2,1108,C,A,11,14.55,100,0,165532,282207737,13.11,100,1,13.46,15,1,12.98,200,2,13.47,100,1,12.92,2,1,13.73,2,1,12.86,100,1,13.74,100,1,12.73,100,1,14.07,100,1,12.71,100,1,14.40,200,2,12.50,700,1,14.42,100,1,12.46,100,1,14.48,700,1,12.43,700,1,14.52,100,1,12.42,700,1,14.53,100,1,ARL,339096833
2389,2025-07-17T16:12:54.029232379Z,2025-07-17T16:12:54.029066847Z,160,2,1108,A,A,5,14.26,100,130,165532,282207737,13.11,100,1,13.46,15,1,12.98,200,2,13.47,100,1,12.92,2,1,13.73,2,1,12.86,100,1,13.74,100,1,12.73,100,1,14.07,100,1,12.71,100,1,14.26,100,1,12.50,700,1,14.40,200,2,12.46,100,1,14.42,100,1,12.43,700,1,14.48,700,1,12.42,700,1,14.52,100,1,ARL,339111189
2390,2025-07-17T16:12:54.055257401Z,2025-07-17T16:12:54.055092122Z,160,2,1108,A,A,19,15.36,100,130,165279,282209385,13.11,100,1,13.46,15,1,12.98,200,2,13.47,100,1,12.92,2,1,13.73,2,1,12.86,100,1,13.74,100,1,12.73,100,1,14.07,100,1,12.71,100,1,14.26,100,1,12.50,700,1,14.40,200,2,12.46,100,1,14.42,100,1,12.43,700,1,14.48,700,1,12.42,700,1,14.52,100,1,ARL,339112469
2391,2025-07-17T16:12:54.055269406Z,2025-07-17T16:12:54.055104415Z,160,2,1108,C,A,21,15.69,100,130,164991,282209392,13.11,100,1,13.46,15,1,12.98,200,2,13.47,100,1,12.92,2,1,13.73,2,1,12.86,100,1,13.74,100,1,12.73,100,1,14.07,100,1,12.71,100,1,14.26,100,1,12.50,700,1,14.40,200,2,12.46,100,1,14.42,100,1,12.43,700,1,14.48,700,1,12.42,700,1,14.52,100,1,ARL,339096757
2392,2025-07-17T16:12:54.069779810Z,2025-07-17T16:12:54.069614114Z,160,2,1108,C,A,16,14.96,100,0,165696,282210148,13.11,100,1,13.46,15,1,12.98,200,2,13.47,100,1,12.92,2,1,13.73,2,1,12.86,100,1,13.74,100,1,12.73,100,1,14.07,100,1,12.71,100,1,14.26,100,1,12.50,700,1,14.40,200,2,12.46,100,1,14.42,100,1,12.43,700,1,14.48,700,1,12.42,700,1,14.52,100,1,ARL,339096977
2393,2025-07-17T16:12:54.069779810Z,2025-07-17T16:12:54.069614114Z,160,2,1108,A,A,7,14.42,100,130,165696,282210148,13.11,100,1,13.46,15,1,12.98,200,2,13.47,100,1,12.92,2,1,13.73,2,1,12.86,100,1,13.74,100,1,12.73,100,1,14.07,100,1,12.71,100,1,14.26,100,1,12.50,700,1,14.40,200,2,12.46,100,1,14.42,200,2,12.43,700,1,14.48,700,1,12.42,700,1,14.52,100,1,ARL,339112945
2394,2025-07-17T16:12:54.072881596Z,2025-07-17T16:12:54.072716256Z,160,2,1108,C,A,16,15.14,100,0,165340,282210181,13.11,100,1,13.46,15,1,12.98,200,2,13.47,100,1,12.92,2,1,13.73,2,1,12.86,100,1,13.74,100,1,12.73,100,1,14.07,100,1,12.71,100,1,14.26,100,1,12.50,700,1,14.40,200,2,12.46,100,1,14.42,200,2,12.43,700,1,14.48,700,1,12.42,700,1,14.52,100,1,ARL,339096813
2395,2025-07-17T16:12:54.072881596Z,2025-07-17T16:12:54.072716256Z,160,2,1108,A,A,15,14.82,100,130,165340,282210181,13.11,100,1,13.46,15,1,12.98,200,2,13.47,100,1,12.92,2,1,13.73,2,1,12.86,100,1,13.74,100,1,12.73,100,1,14.07,100,1,12.71,100,1,14.26,100,1,12.50,700,1,14.40,200,2,12.46,100,1,14.42,200,2,12.43,700,1,14.48,700,1,12.42,700,1,14.52,100,1,ARL,339112981
2396,2025-07-17T16:12:54.694796063Z,2025-07-17T16:12:54.694630780Z,160,2,1108,A,A,6,14.27,100,130,165283,282224916,13.11,100,1,13.46,15,1,12.98,200,2,13.47,100,1,12.92,2,1,13.73,2,1,12.86,100,1,13.74,100,1,12.73,100,1,14.07,100,1,12.71,100,1,14.26,100,1,12.50,700,1,14.27,100,1,12.46,100,1,14.40,200,2,12.43,700,1,14.42,200,2,12.42,700,1,14.48,700,1,ARL,339126221
2397,2025-07-17T16:12:54.694809520Z,2025-07-17T16:12:54.694644316Z,160,2,1108,C,A,15,14.81,100,130,165204,282224917,13.11,100,1,13.46,15,1,12.98,200,2,13.47,100,1,12.92,2,1,13.73,2,1,12.86,100,1,13.74,100,1,12.73,100,1,14.07,100,1,12.71,100,1,14.26,100,1,12.50,700,1,14.27,100,1,12.46,100,1,14.40,200,2,12.43,700,1,14.42,200,2,12.42,700,1,14.48,700,1,ARL,339103269
2398,2025-07-17T16:12:55.255327586Z,2025-07-17T16:12:55.255162003Z,160,2,1108,A,A,4,14.00,100,130,165583,282231441,13.11,100,1,13.46,15,1,12.98,200,2,13.47,100,1,12.92,2,1,13.73,2,1,12.86,100,1,13.74,100,1,12.73,100,1,14.00,100,1,12.71,100,1,14.07,100,1,12.50,700,1,14.26,100,1,12.46,100,1,14.27,100,1,12.43,700,1,14.40,200,2,12.42,700,1,14.42,200,2,ARL,339133353
2399,2025-07-17T16:12:55.255328269Z,2025-07-17T16:12:55.255163083Z,160,2,1108,C,A,12,14.53,100,130,165186,282231442,13.11,100,1,13.46,15,1,12.98,200,2,13.47,100,1,12.92,2,1,13.73,2,1,12.86,100,1,13.74,100,1,12.73,100,1,14.00,100,1,12.71,100,1,14.07,100,1,12.50,700,1,14.26,100,1,12.46,100,1,14.27,100,1,12.43,700,1,14.40,200,2,12.42,700,1,14.42,200,2,ARL,339100477
2400,2025-07-17T16:12:58.302183447Z,2025-07-17T16:12:58.302017238Z,160,2,1108,C,A,0,13.46,15,128,166209,282279351,13.11,100,1,13.47,100,1,12.98,200,2,13.73,2,1,12.92,2,1,13.74,100,1,12.86,100,1,14.00,100,1,12.73,100,1,14.07,100,1,12.71,100,1,14.26,100,1,12.50,700,1,14.27,100,1,12.46,100,1,14.40,200,2,12.43,700,1,14.42,200,2,12.42,700,1,14.48,700,1,ARL,339096733
2401,2025-07-17T16:12:58.420887746Z,2025-07-17T16:12:58.420710579Z,160,2,1108,C,A,0,13.47,100,128,177167,282288716,13.11,100,1,13.73,2,1,12.98,200,2,13.74,100,1,12.92,2,1,14.00,100,1,12.86,100,1,14.07,100,1,12.73,100,1,14.26,100,1,12.71,100,1,14.27,100,1,12.50,700,1,14.40,200,2,12.46,100,1,14.42,200,2,12.43,700,1,14.48,700,1,12.42,700,1,14.52,100,1,ARL,339110853
2402,2025-07-17T16:12:58.420950587Z,2025-07-17T16:12:58.420776003Z,160,2,1108,A,A,0,13.47,96,128,174584,282288757,13.11,100,1,13.47,96,1,12.98,200,2,13.73,2,1,12.92,2,1,13.74,100,1,12.86,100,1,14.00,100,1,12.73,100,1,14.07,100,1,12.71,100,1,14.26,100,1,12.50,700,1,14.27,100,1,12.46,100,1,14.40,200,2,12.43,700,1,14.42,200,2,12.42,700,1,14.48,700,1,ARL,339201549
2403,2025-07-17T16:12:58.421338553Z,2025-07-17T16:12:58.421165414Z,160,2,1108,C,A,0,13.47,96,130,173139,282289082,13.11,100,1,13.73,2,1,12.98,200,2,13.74,100,1,12.92,2,1,14.00,100,1,12.86,100,1,14.07,100,1,12.73,100,1,14.26,100,1,12.71,100,1,14.27,100,1,12.50,700,1,14.40,200,2,12.46,100,1,14.42,200,2,12.43,700,1,14.48,700,1,12.42,700,1,14.52,100,1,ARL,339201549
2404,2025-07-17T16:12:58.421379924Z,2025-07-17T16:12:58.421205027Z,160,2,1108,A,A,17,15.67,100,128,174897,282289111,13.11,100,1,13.73,2,1,12.98,200,2,13.74,100,1,12.92,2,1,14.00,100,1,12.86,100,1,14.07,100,1,12.73,100,1,14.26,100,1,12.71,100,1,14.27,100,1,12.50,700,1,14.40,200,2,12.46,100,1,14.42,200,2,12.43,700,1,14.48,700,1,12.42,700,1,14.52,100,1,ARL,339202065
2405,2025-07-17T16:12:58.421423275Z,2025-07-17T16:12:58.421248082Z,160,2,1108,C,A,15,15.36,100,128,175193,282289154,13.11,100,1,13.73,2,1,12.98,200,2,13.74,100,1,12.92,2,1,14.00,100,1,12.86,100,1,14.07,100,1,12.73,100,1,14.26,100,1,12.71,100,1,14.27,100,1,12.50,700,1,14.40,200,2,12.46,100,1,14.42,200,2,12.43,700,1,14.48,700,1,12.42,700,1,14.52,100,1,ARL,339112469
2406,2025-07-17T16:12:58.421756726Z,2025-07-17T16:12:58.421581692Z,160,2,1108,C,A,3,14.07,100,130,175034,282289338,13.11,100,1,13.73,2,1,12.98,200,2,13.74,100,1,12.92,2,1,14.00,100,1,12.86,100,1,14.26,100,1,12.73,100,1,14.27,100,1,12.71,100,1,14.40,200,2,12.50,700,1,14.42,200,2,12.46,100,1,14.48,700,1,12.43,700,1,14.52,100,1,12.42,700,1,14.54,700,1,ARL,339110909
2407,2025-07-17T16:12:58.422145785Z,2025-07-17T16:12:58.421969675Z,160,2,1108,A,A,5,14.35,100,128,176110,282289650,13.11,100,1,13.73,2,1,12.98,200,2,13.74,100,1,12.92,2,1,14.00,100,1,12.86,100,1,14.26,100,1,12.73,100,1,14.27,100,1,12.71,100,1,14.35,100,1,12.50,700,1,14.40,200,2,12.46,100,1,14.42,200,2,12.43,700,1,14.48,700,1,12.42,700,1,14.52,100,1,ARL,339202733
2408,2025-07-17T16:12:58.422247877Z,2025-07-17T16:12:58.422073305Z,160,2,1108,C,A,9,14.52,100,0,174572,282289747,13.11,100,1,13.73,2,1,12.98,200,2,13.74,100,1,12.92,2,1,14.00,100,1,12.86,100,1,14.26,100,1,12.73,100,1,14.27,100,1,12.71,100,1,14.35,100,1,12.50,700,1,14.40,200,2,12.46,100,1,14.42,200,2,12.43,700,1,14.48,700,1,12.42,700,1,14.54,700,1,ARL,339110897
2409,2025-07-17T16:12:58.422247877Z,2025-07-17T16:12:58.422073305Z,160,2,1108,A,A,12,14.81,100,128,174572,282289747,13.11,100,1,13.73,2,1,12.98,200,2,13.74,100,1,12.92,2,1,14.00,100,1,12.86,100,1,14.26,100,1,12.73,100,1,14.27,100,1,12.71,100,1,14.35,100,1,12.50,700,1,14.40,200,2,12.46,100,1,14.42,200,2,12.43,700,1,14.48,700,1,12.42,700,1,14.54,700,1,ARL,339202805
2410,2025-07-17T16:12:58.424958370Z,2025-07-17T16:12:58.424789366Z,160,2,1108,C,A,6,14.40,100,0,169004,282290622,13.11,100,1,13.73,2,1,12.98,200,2,13.74,100,1,12.92,2,1,14.00,100,1,12.86,100,1,14.26,100,1,12.73,100,1,14.27,100,1,12.71,100,1,14.35,100,1,12.50,700,1,14.40,100,1,12.46,100,1,14.42,200,2,12.43,700,1,14.48,700,1,12.42,700,1,14.54,700,1,ARL,338139585
2411,2025-07-17T16:12:58.424958370Z,2025-07-17T16:12:58.424789366Z,160,2,1108,A,A,11,14.57,100,128,169004,282290622,13.11,100,1,13.73,2,1,12.98,200,2,13.74,100,1,12.92,2,1,14.00,100,1,12.86,100,1,14.26,100,1,12.73,100,1,14.27,100,1,12.71,100,1,14.35,100,1,12.50,700,1,14.40,100,1,12.46,100,1,14.42,200,2,12.43,700,1,14.48,700,1,12.42,700,1,14.54,700,1,ARL,339203693
2412,2025-07-17T16:12:58.425450176Z,2025-07-17T16:12:58.425283932Z,160,2,1108,C,A,6,14.40,100,0,166244,282290769,13.11,100,1,13.73,2,1,12.98,200,2,13.74,100,1,12.92,2,1,14.00,100,1,12.86,100,1,14.26,100,1,12.73,100,1,14.27,100,1,12.71,100,1,14.35,100,1,12.50,700,1,14.42,200,2,12.46,100,1,14.48,700,1,12.43,700,1,14.54,700,1,12.42,700,1,14.56,700,1,ARL,338139601
2413,2025-07-17T16:12:58.425450176Z,2025-07-17T16:12:58.425283932Z,160,2,1108,A,A,10,14.57,100,128,166244,282290769,13.11,100,1,13.73,2,1,12.98,200,2,13.74,100,1,12.92,2,1,14.00,100,1,12.86,100,1,14.26,100,1,12.73,100,1,14.27,100,1,12.71,100,1,14.35,100,1,12.50,700,1,14.42,200,2,12.46,100,1,14.48,700,1,12.43,700,1,14.54,700,1,12.42,700,1,14.56,700,1,ARL,339203897
2414,2025-07-17T16:12:58.426423622Z,2025-07-17T16:12:58.426258092Z,160,2,1108,C,A,3,14.26,100,130,165530,282290946,13.11,100,1,13.73,2,1,12.98,200,2,13.74,100,1,12.92,2,1,14.00,100,1,12.86,100,1,14.27,100,1,12.73,100,1,14.35,100,1,12.71,100,1,14.42,200,2,12.50,700,1,14.48,700,1,12.46,100,1,14.54,700,1,12.43,700,1,14.56,700,1,12.42,700,1,14.57,200,2,ARL,339111189
2415,2025-07-17T16:12:58.426544477Z,2025-07-17T16:12:58.426378483Z,160,2,1108,A,A,7,14.53,100,130,165994,282290959,13.11,100,1,13.73,2,1,12.98,200,2,13.74,100,1,12.92,2,1,14.00,100,1,12.86,100,1,14.27,100,1,12.73,100,1,14.35,100,1,12.71,100,1,14.42,200,2,12.50,700,1,14.48,700,1,12.46,100,1,14.53,100,1,12.43,700,1,14.54,700,1,12.42,700,1,14.56,700,1,ARL,339204077
2416,2025-07-17T16:12:58.430830694Z,2025-07-17T16:12:58.430665639Z,160,2,1108,C,A,1,13.74,100,130,165055,282291933,13.11,100,1,13.73,2,1,12.98,200,2,14.00,100,1,12.92,2,1,14.27,100,1,12.86,100,1,14.35,100,1,12.73,100,1,14.42,200,2,12.71,100,1,14.48,700,1,12.50,700,1,14.53,100,1,12.46,100,1,14.54,700,1,12.43,700,1,14.56,700,1,12.42,700,1,14.57,200,2,ARL,339111029
2417,2025-07-17T16:12:58.430888526Z,2025-07-17T16:12:58.430720526Z,160,2,1108,A,A,2,14.01,100,128,168000,282291946,13.11,100,1,13.73,2,1,12.98,200,2,14.00,100,1,12.92,2,1,14.01,100,1,12.86,100,1,14.27,100,1,12.73,100,1,14.35,100,1,12.71,100,1,14.42,200,2,12.50,700,1,14.48,700,1,12.46,100,1,14.53,100,1,12.43,700,1,14.54,700,1,12.42,700,1,14.56,700,1,ARL,339205213
2418,2025-07-17T16:12:58.432901795Z,2025-07-17T16:12:58.432736189Z,160,2,1108,C,A,13,14.82,100,0,165606,282292390,13.11,100,1,13.73,2,1,12.98,200,2,14.00,100,1,12.92,2,1,14.01,100,1,12.86,100,1,14.27,100,1,12.73,100,1,14.35,100,1,12.71,100,1,14.42,200,2,12.50,700,1,14.48,700,1,12.46,100,1,14.53,100,1,12.43,700,1,14.54,700,1,12.42,700,1,14.56,700,1,ARL,339111005
2419,2025-07-17T16:12:58.432901795Z,2025-07-17T16:12:58.432736189Z,160,2,1108,A,A,15,15.38,100,130,165606,282292390,13.11,100,1,13.73,2,1,12.98,200,2,14.00,100,1,12.92,2,1,14.01,100,1,12.86,100,1,14.27,100,1,12.73,100,1,14.35,100,1,12.71,100,1,14.42,200,2,12.50,700,1,14.48,700,1,12.46,100,1,14.53,100,1,12.43,700,1,14.54,700,1,12.42,700,1,14.56,700,1,ARL,339206141
2420,2025-07-17T16:12:58.438073339Z,2025-07-17T16:12:58.437907652Z,160,2,1108,C,B,2,12.92,2,0,165687,282292938,13.11,100,1,13.73,2,1,12.98,200,2,14.00,100,1,12.86,100,1,14.01,100,1,12.73,100,1,14.27,100,1,12.71,100,1,14.35,100,1,12.50,700,1,14.42,200,2,12.46,100,1,14.48,700,1,12.43,700,1,14.53,100,1,12.42,700,1,14.54,700,1,12.37,700,1,14.56,700,1,ARL,338044113
2421,2025-07-17T16:12:58.438073339Z,2025-07-17T16:12:58.437907652Z,160,2,1108,A,B,1,13.02,2,130,165687,282292938,13.11,100,1,13.73,2,1,13.02,2,1,14.00,100,1,12.98,200,2,14.01,100,1,12.86,100,1,14.27,100,1,12.73,100,1,14.35,100,1,12.71,100,1,14.42,200,2,12.50,700,1,14.48,700,1,12.46,100,1,14.53,100,1,12.43,700,1,14.54,700,1,12.42,700,1,14.56,700,1,ARL,339207125
2422,2025-07-17T16:12:58.438076762Z,2025-07-17T16:12:58.437911392Z,160,2,1108,C,A,0,13.73,2,0,165370,282292939,13.11,100,1,14.00,100,1,13.02,2,1,14.01,100,1,12.98,200,2,14.27,100,1,12.86,100,1,14.35,100,1,12.73,100,1,14.42,200,2,12.71,100,1,14.48,700,1,12.50,700,1,14.53,100,1,12.46,100,1,14.54,700,1,12.43,700,1,14.56,700,1,12.42,700,1,14.57,200,2,ARL,339110993
2423,2025-07-17T16:12:58.438076762Z,2025-07-17T16:12:58.437911392Z,160,2,1108,A,A,0,13.98,2,130,165370,282292939,13.11,100,1,13.98,2,1,13.02,2,1,14.00,100,1,12.98,200,2,14.01,100,1,12.86,100,1,14.27,100,1,12.73,100,1,14.35,100,1,12.71,100,1,14.42,200,2,12.50,700,1,14.48,700,1,12.46,100,1,14.53,100,1,12.43,700,1,14.54,700,1,12.42,700,1,14.56,700,1,ARL,339207129
2424,2025-07-17T16:12:58.438843944Z,2025-07-17T16:12:58.438678961Z,160,2,1108,C,A,2,14.01,100,130,164983,282293023,13.11,100,1,13.98,2,1,13.02,2,1,14.00,100,1,12.98,200,2,14.27,100,1,12.86,100,1,14.35,100,1,12.73,100,1,14.42,200,2,12.71,100,1,14.48,700,1,12.50,700,1,14.53,100,1,12.46,100,1,14.54,700,1,12.43,700,1,14.56,700,1,12.42,700,1,14.57,200,2,ARL,339205213
2425,2025-07-17T16:12:58.438894336Z,2025-07-17T16:12:58.438728994Z,160,2,1108,A,A,2,14.24,100,130,165342,282293026,13.11,100,1,13.98,2,1,13.02,2,1,14.00,100,1,12.98,200,2,14.24,100,1,12.86,100,1,14.27,100,1,12.73,100,1,14.35,100,1,12.71,100,1,14.42,200,2,12.50,700,1,14.48,700,1,12.46,100,1,14.53,100,1,12.43,700,1,14.54,700,1,12.42,700,1,14.56,700,1,ARL,339207197
2426,2025-07-17T16:12:58.441834497Z,2025-07-17T16:12:58.441669159Z,160,2,1108,C,A,5,14.42,100,0,165338,282293191,13.11,100,1,13.98,2,1,13.02,2,1,14.00,100,1,12.98,200,2,14.24,100,1,12.86,100,1,14.27,100,1,12.73,100,1,14.35,100,1,12.71,100,1,14.42,100,1,12.50,700,1,14.48,700,1,12.46,100,1,14.53,100,1,12.43,700,1,14.54,700,1,12.42,700,1,14.56,700,1,ARL,339110981
2427,2025-07-17T16:12:58.441834497Z,2025-07-17T16:12:58.441669159Z,160,2,1108,A,A,14,14.96,100,130,165338,282293191,13.11,100,1,13.98,2,1,13.02,2,1,14.00,100,1,12.98,200,2,14.24,100,1,12.86,100,1,14.27,100,1,12.73,100,1,14.35,100,1,12.71,100,1,14.42,100,1,12.50,700,1,14.48,700,1,12.46,100,1,14.53,100,1,12.43,700,1,14.54,700,1,12.42,700,1,14.56,700,1,ARL,339207505
2428,2025-07-17T16:12:58.454376675Z,2025-07-17T16:12:58.454211242Z,160,2,1108,C,A,20,17.11,100,0,165433,282293811,13.11,100,1,13.98,2,1,13.02,2,1,14.00,100,1,12.98,200,2,14.24,100,1,12.86,100,1,14.27,100,1,12.73,100,1,14.35,100,1,12.71,100,1,14.42,100,1,12.50,700,1,14.48,700,1,12.46,100,1,14.53,100,1,12.43,700,1,14.54,700,1,12.42,700,1,14.56,700,1,ARL,339111097
2429,2025-07-17T16:12:58.454376675Z,2025-07-17T16:12:58.454211242Z,160,2,1108,A,A,21,17.76,100,130,165433,282293811,13.11,100,1,13.98,2,1,13.02,2,1,14.00,100,1,12.98,200,2,14.24,100,1,12.86,100,1,14.27,100,1,12.73,100,1,14.35,100,1,12.71,100,1,14.42,100,1,12.50,700,1,14.48,700,1,12.46,100,1,14.53,100,1,12.43,700,1,14.54,700,1,12.42,700,1,14.56,700,1,ARL,339208377
2430,2025-07-17T16:12:58.472292476Z,2025-07-17T16:12:58.472126777Z,160,2,1108,C,A,17,15.50,100,0,165699,282294411,13.11,100,1,13.98,2,1,13.02,2,1,14.00,100,1,12.98,200,2,14.24,100,1,12.86,100,1,14.27,100,1,12.73,100,1,14.35,100,1,12.71,100,1,14.42,100,1,12.50,700,1,14.48,700,1,12.46,100,1,14.53,100,1,12.43,700,1,14.54,700,1,12.42,700,1,14.56,700,1,ARL,339111149
2431,2025-07-17T16:12:58.472292476Z,2025-07-17T16:12:58.472126777Z,160,2,1108,A,A,18,16.08,100,130,165699,282294411,13.11,100,1,13.98,2,1,13.02,2,1,14.00,100,1,12.98,200,2,14.24,100,1,12.86,100,1,14.27,100,1,12.73,100,1,14.35,100,1,12.71,100,1,14.42,100,1,12.50,700,1,14.48,700,1,12.46,100,1,14.53,100,1,12.43,700,1,14.54,700,1,12.42,700,1,14.56,700,1,ARL,339209241
2432,2025-07-17T16:12:58.472624779Z,2025-07-17T16:12:58.472458830Z,160,2,1108,C,A,12,14.81,100,0,165949,282294423,13.11,100,1,13.98,2,1,13.02,2,1,14.00,100,1,12.98,200,2,14.24,100,1,12.86,100,1,14.27,100,1,12.73,100,1,14.35,100,1,12.71,100,1,14.42,100,1,12.50,700,1,14.48,700,1,12.46,100,1,14.53,100,1,12.43,700,1,14.54,700,1,12.42,700,1,14.56,700,1,ARL,339202805
2433,2025-07-17T16:12:58.472624779Z,2025-07-17T16:12:58.472458830Z,160,2,1108,A,A,14,15.04,100,130,165949,282294423,13.11,100,1,13.98,2,1,13.02,2,1,14.00,100,1,12.98,200,2,14.24,100,1,12.86,100,1,14.27,100,1,12.73,100,1,14.35,100,1,12.71,100,1,14.42,100,1,12.50,700,1,14.48,700,1,12.46,100,1,14.53,100,1,12.43,700,1,14.54,700,1,12.42,700,1,14.56,700,1,ARL,339209257
2434,2025-07-17T16:12:58.571845708Z,2025-07-17T16:12:58.571679985Z,160,2,1108,C,A,12,14.82,100,0,165723,282298942,13.11,100,1,13.98,2,1,13.02,2,1,14.00,100,1,12.98,200,2,14.24,100,1,12.86,100,1,14.27,100,1,12.73,100,1,14.35,100,1,12.71,100,1,14.42,100,1,12.50,700,1,14.48,700,1,12.46,100,1,14.53,100,1,12.43,700,1,14.54,700,1,12.42,700,1,14.56,700,1,ARL,339112981
2435,2025-07-17T16:12:58.571845708Z,2025-07-17T16:12:58.571679985Z,160,2,1108,A,A,15,15.38,100,130,165723,282298942,13.11,100,1,13.98,2,1,13.02,2,1,14.00,100,1,12.98,200,2,14.24,100,1,12.86,100,1,14.27,100,1,12.73,100,1,14.35,100,1,12.71,100,1,14.42,100,1,12.50,700,1,14.48,700,1,12.46,100,1,14.53,100,1,12.43,700,1,14.54,700,1,12.42,700,1,14.56,700,1,ARL,339215205
2436,2025-07-17T16:12:58.619404102Z,2025-07-17T16:12:58.619238614Z,160,2,1108,C,A,5,14.42,100,0,165488,282299781,13.11,100,1,13.98,2,1,13.02,2,1,14.00,100,1,12.98,200,2,14.24,100,1,12.86,100,1,14.27,100,1,12.73,100,1,14.35,100,1,12.71,100,1,14.48,700,1,12.50,700,1,14.53,100,1,12.46,100,1,14.54,700,1,12.43,700,1,14.56,700,1,12.42,700,1,14.57,200,2,ARL,339112945
2437,2025-07-17T16:12:58.619404102Z,2025-07-17T16:12:58.619238614Z,160,2,1108,A,A,11,14.96,100,130,165488,282299781,13.11,100,1,13.98,2,1,13.02,2,1,14.00,100,1,12.98,200,2,14.24,100,1,12.86,100,1,14.27,100,1,12.73,100,1,14.35,100,1,12.71,100,1,14.48,700,1,12.50,700,1,14.53,100,1,12.46,100,1,14.54,700,1,12.43,700,1,14.56,700,1,12.42,700,1,14.57,200,2,ARL,339216161
2438,2025-07-17T16:12:58.986093948Z,2025-07-17T16:12:58.985928594Z,160,2,1108,C,B,1,13.02,2,0,165354,282305386,13.11,100,1,13.98,2,1,12.98,200,2,14.00,100,1,12.86,100,1,14.24,100,1,12.73,100,1,14.27,100,1,12.71,100,1,14.35,100,1,12.50,700,1,14.48,700,1,12.46,100,1,14.53,100,1,12.43,700,1,14.54,700,1,12.42,700,1,14.56,700,1,12.37,700,1,14.57,200,2,ARL,339207125
2439,2025-07-17T16:12:58.986093948Z,2025-07-17T16:12:58.985928594Z,160,2,1108,A,B,2,12.86,2,130,165354,282305386,13.11,100,1,13.98,2,1,12.98,200,2,14.00,100,1,12.86,102,2,14.24,100,1,12.73,100,1,14.27,100,1,12.71,100,1,14.35,100,1,12.50,700,1,14.48,700,1,12.46,100,1,14.53,100,1,12.43,700,1,14.54,700,1,12.42,700,1,14.56,700,1,12.37,700,1,14.57,200,2,ARL,339222617
2440,2025-07-17T16:12:59.063108412Z,2025-07-17T16:12:59.062943193Z,160,2,1108,A,A,1,13.99,100,130,165219,282306400,13.11,100,1,13.98,2,1,12.98,200,2,13.99,100,1,12.86,102,2,14.00,100,1,12.73,100,1,14.24,100,1,12.71,100,1,14.27,100,1,12.50,700,1,14.35,100,1,12.46,100,1,14.48,700,1,12.43,700,1,14.53,100,1,12.42,700,1,14.54,700,1,12.37,700,1,14.56,700,1,ARL,339224109
2441,2025-07-17T16:12:59.082855570Z,2025-07-17T16:12:59.082690430Z,160,2,1108,C,A,2,14.00,100,130,165140,282307908,13.11,100,1,13.98,2,1,12.98,200,2,13.99,100,1,12.86,102,2,14.24,100,1,12.73,100,1,14.27,100,1,12.71,100,1,14.35,100,1,12.50,700,1,14.48,700,1,12.46,100,1,14.53,100,1,12.43,700,1,14.54,700,1,12.42,700,1,14.56,700,1,12.37,700,1,14.57,200,2,ARL,339133353
2442,2025-07-17T16:12:59.082856640Z,2025-07-17T16:12:59.082691385Z,160,2,1108,A,A,6,14.53,100,130,165255,282307909,13.11,100,1,13.98,2,1,12.98,200,2,13.99,100,1,12.86,102,2,14.24,100,1,12.73,100,1,14.27,100,1,12.71,100,1,14.35,100,1,12.50,700,1,14.48,700,1,12.46,100,1,14.53,200,2,12.43,700,1,14.54,700,1,12.42,700,1,14.56,700,1,12.37,700,1,14.57,200,2,ARL,339225769
2443,2025-07-17T16:12:59.088794570Z,2025-07-17T16:12:59.088629294Z,160,2,1108,A,A,11,14.81,100,130,165276,282308093,13.11,100,1,13.98,2,1,12.98,200,2,13.99,100,1,12.86,102,2,14.24,100,1,12.73,100,1,14.27,100,1,12.71,100,1,14.35,100,1,12.50,700,1,14.48,700,1,12.46,100,1,14.53,200,2,12.43,700,1,14.54,700,1,12.42,700,1,14.56,700,1,12.37,700,1,14.57,200,2,ARL,339225885
2444,2025-07-17T16:12:59.088808117Z,2025-07-17T16:12:59.088642718Z,160,2,1108,C,A,3,14.27,100,130,165399,282308094,13.11,100,1,13.98,2,1,12.98,200,2,13.99,100,1,12.86,102,2,14.24,100,1,12.73,100,1,14.35,100,1,12.71,100,1,14.48,700,1,12.50,700,1,14.53,200,2,12.46,100,1,14.54,700,1,12.43,700,1,14.56,700,1,12.42,700,1,14.57,200,2,12.37,700,1,14.68,700,1,ARL,339126221
2445,2025-07-17T16:12:59.092927842Z,2025-07-17T16:12:59.092762564Z,160,2,1108,C,A,3,14.35,100,130,165278,282308154,13.11,100,1,13.98,2,1,12.98,200,2,13.99,100,1,12.86,102,2,14.24,100,1,12.73,100,1,14.48,700,1,12.71,100,1,14.53,200,2,12.50,700,1,14.54,700,1,12.46,100,1,14.56,700,1,12.43,700,1,14.57,200,2,12.42,700,1,14.68,700,1,12.37,700,1,14.81,100,1,ARL,339202733
2446,2025-07-17T16:12:59.093278915Z,2025-07-17T16:12:59.093113488Z,160,2,1108,A,A,8,14.60,100,130,165427,282308163,13.11,100,1,13.98,2,1,12.98,200,2,13.99,100,1,12.86,102,2,14.24,100,1,12.73,100,1,14.48,700,1,12.71,100,1,14.53,200,2,12.50,700,1,14.54,700,1,12.46,100,1,14.56,700,1,12.43,700,1,14.57,200,2,12.42,700,1,14.60,100,1,12.37,700,1,14.68,700,1,ARL,339226021
2447,2025-07-17T16:12:59.430486012Z,2025-07-17T16:12:59.430320610Z,160,2,1108,C,A,4,14.53,100,0,165402,282313368,13.11,100,1,13.98,2,1,12.98,200,2,13.99,100,1,12.86,102,2,14.24,100,1,12.73,100,1,14.48,700,1,12.71,100,1,14.53,100,1,12.50,700,1,14.54,700,1,12.46,100,1,14.56,700,1,12.43,700,1,14.57,200,2,12.42,700,1,14.60,100,1,12.37,700,1,14.68,700,1,ARL,339204077
2448,2025-07-17T16:12:59.430486012Z,2025-07-17T16:12:59.430320610Z,160,2,1108,A,A,10,14.77,100,130,165402,282313368,13.11,100,1,13.98,2,1,12.98,200,2,13.99,100,1,12.86,102,2,14.24,100,1,12.73,100,1,14.48,700,1,12.71,100,1,14.53,100,1,12.50,700,1,14.54,700,1,12.46,100,1,14.56,700,1,12.43,700,1,14.57,200,2,12.42,700,1,14.60,100,1,12.37,700,1,14.68,700,1,ARL,339232213
2449,2025-07-17T16:13:04.825902166Z,2025-07-17T16:13:04.825736034Z,160,2,1108,A,A,0,13.66,15,128,166132,282392593,13.11,100,1,13.66,15,1,12.98,200,2,13.98,2,1,12.86,102,2,13.99,100,1,12.73,100,1,14.24,100,1,12.71,100,1,14.48,700,1,12.50,700,1,14.53,100,1,12.46,100,1,14.54,700,1,12.43,700,1,14.56,700,1,12.42,700,1,14.57,200,2,12.37,700,1,14.60,100,1,ARL,339332865
2450,2025-07-17T16:13:06.189275812Z,2025-07-17T16:13:06.189110140Z,160,2,1108,C,B,2,12.86,2,0,165672,282411935,13.11,100,1,13.66,15,1,12.98,200,2,13.98,2,1,12.86,100,1,13.99,100,1,12.73,100,1,14.24,100,1,12.71,100,1,14.48,700,1,12.50,700,1,14.53,100,1,12.46,100,1,14.54,700,1,12.43,700,1,14.56,700,1,12.42,700,1,14.57,200,2,12.37,700,1,14.60,100,1,ARL,339222617
2451,2025-07-17T16:13:06.189275812Z,2025-07-17T16:13:06.189110140Z,160,2,1108,A,B,2,12.96,2,130,165672,282411935,13.11,100,1,13.66,15,1,12.98,200,2,13.98,2,1,12.96,2,1,13.99,100,1,12.86,100,1,14.24,100,1,12.73,100,1,14.48,700,1,12.71,100,1,14.53,100,1,12.50,700,1,14.54,700,1,12.46,100,1,14.56,700,1,12.43,700,1,14.57,200,2,12.42,700,1,14.60,100,1,ARL,339356397
2452,2025-07-17T16:13:06.224898389Z,2025-07-17T16:13:06.224732787Z,160,2,1108,C,A,2,13.99,100,0,165602,282413599,13.11,100,1,13.66,15,1,12.98,200,2,13.98,2,1,12.96,2,1,14.24,100,1,12.86,100,1,14.48,700,1,12.73,100,1,14.53,100,1,12.71,100,1,14.54,700,1,12.50,700,1,14.56,700,1,12.46,100,1,14.57,200,2,12.43,700,1,14.60,100,1,12.42,700,1,14.68,700,1,ARL,339224109
2453,2025-07-17T16:13:06.224898389Z,2025-07-17T16:13:06.224732787Z,160,2,1108,A,A,1,13.67,100,130,165602,282413599,13.11,100,1,13.66,15,1,12.98,200,2,13.67,100,1,12.96,2,1,13.98,2,1,12.86,100,1,14.24,100,1,12.73,100,1,14.48,700,1,12.71,100,1,14.53,100,1,12.50,700,1,14.54,700,1,12.46,100,1,14.56,700,1,12.43,700,1,14.57,200,2,12.42,700,1,14.60,100,1,ARL,339358233
2454,2025-07-17T16:13:06.225642781Z,2025-07-17T16:13:06.225475518Z,160,2,1108,C,A,14,15.04,100,0,167263,282413677,13.11,100,1,13.66,15,1,12.98,200,2,13.67,100,1,12.96,2,1,13.98,2,1,12.86,100,1,14.24,100,1,12.73,100,1,14.48,700,1,12.71,100,1,14.53,100,1,12.50,700,1,14.54,700,1,12.46,100,1,14.56,700,1,12.43,700,1,14.57,200,2,12.42,700,1,14.60,100,1,ARL,339209257
2455,2025-07-17T16:13:06.225642781Z,2025-07-17T16:13:06.225475518Z,160,2,1108,A,A,11,14.73,100,0,167263,282413677,13.11,100,1,13.66,15,1,12.98,200,2,13.67,100,1,12.96,2,1,13.98,2,1,12.86,100,1,14.24,100,1,12.73,100,1,14.48,700,1,12.71,100,1,14.53,100,1,12.50,700,1,14.54,700,1,12.46,100,1,14.56,700,1,12.43,700,1,14.57,200,2,12.42,700,1,14.60,100,1,ARL,339358293
2456,2025-07-17T16:13:06.225642781Z,2025-07-17T16:13:06.225475906Z,160,2,1108,C,A,9,14.60,100,128,166875,282413678,13.11,100,1,13.66,15,1,12.98,200,2,13.67,100,1,12.96,2,1,13.98,2,1,12.86,100,1,14.24,100,1,12.73,100,1,14.48,700,1,12.71,100,1,14.53,100,1,12.50,700,1,14.54,700,1,12.46,100,1,14.56,700,1,12.43,700,1,14.57,200,2,12.42,700,1,14.68,700,1,ARL,339226021
2457,2025-07-17T16:13:06.225995297Z,2025-07-17T16:13:06.225829921Z,160,2,1108,A,A,4,14.28,100,130,165376,282413699,13.11,100,1,13.66,15,1,12.98,200,2,13.67,100,1,12.96,2,1,13.98,2,1,12.86,100,1,14.24,100,1,12.73,100,1,14.28,100,1,12.71,100,1,14.48,700,1,12.50,700,1,14.53,100,1,12.46,100,1,14.54,700,1,12.43,700,1,14.56,700,1,12.42,700,1,14.57,200,2,ARL,339358333
2458,2025-07-17T16:13:06.226789913Z,2025-07-17T16:13:06.226624084Z,160,2,1108,C,A,16,15.38,100,0,165829,282413738,13.11,100,1,13.66,15,1,12.98,200,2,13.67,100,1,12.96,2,1,13.98,2,1,12.86,100,1,14.24,100,1,12.73,100,1,14.28,100,1,12.71,100,1,14.48,700,1,12.50,700,1,14.53,100,1,12.46,100,1,14.54,700,1,12.43,700,1,14.56,700,1,12.42,700,1,14.57,200,2,ARL,339206141
2459,2025-07-17T16:13:06.226789913Z,2025-07-17T16:13:06.226624084Z,160,2,1108,A,A,15,15.04,100,130,165829,282413738,13.11,100,1,13.66,15,1,12.98,200,2,13.67,100,1,12.96,2,1,13.98,2,1,12.86,100,1,14.24,100,1,12.73,100,1,14.28,100,1,12.71,100,1,14.48,700,1,12.50,700,1,14.53,100,1,12.46,100,1,14.54,700,1,12.43,700,1,14.56,700,1,12.42,700,1,14.57,200,2,ARL,339358349
2460,2025-07-17T16:13:06.226882302Z,2025-07-17T16:13:06.226716697Z,160,2,1108,C,A,14,14.96,100,0,165605,282413745,13.11,100,1,13.66,15,1,12.98,200,2,13.67,100,1,12.96,2,1,13.98,2,1,12.86,100,1,14.24,100,1,12.73,100,1,14.28,100,1,12.71,100,1,14.48,700,1,12.50,700,1,14.53,100,1,12.46,100,1,14.54,700,1,12.43,700,1,14.56,700,1,12.42,700,1,14.57,200,2,ARL,339207505
2461,2025-07-17T16:13:06.226882302Z,2025-07-17T16:13:06.226716697Z,160,2,1108,A,A,10,14.63,100,130,165605,282413745,13.11,100,1,13.66,15,1,12.98,200,2,13.67,100,1,12.96,2,1,13.98,2,1,12.86,100,1,14.24,100,1,12.73,100,1,14.28,100,1,12.71,100,1,14.48,700,1,12.50,700,1,14.53,100,1,12.46,100,1,14.54,700,1,12.43,700,1,14.56,700,1,12.42,700,1,14.57,200,2,ARL,339358353
2462,2025-07-17T16:13:06.229858538Z,2025-07-17T16:13:06.229693020Z,160,2,1108,C,A,2,13.98,2,0,165518,282413801,13.11,100,1,13.66,15,1,12.98,200,2,13.67,100,1,12.96,2,1,14.24,100,1,12.86,100,1,14.28,100,1,12.73,100,1,14.48,700,1,12.71,100,1,14.53,100,1,12.50,700,1,14.54,700,1,12.46,100,1,14.56,700,1,12.43,700,1,14.57,200,2,12.42,700,1,14.63,100,1,ARL,339207129
2463,2025-07-17T16:13:06.229858538Z,2025-07-17T16:13:06.229693020Z,160,2,1108,A,A,2,13.81,2,130,165518,282413801,13.11,100,1,13.66,15,1,12.98,200,2,13.67,100,1,12.96,2,1,13.81,2,1,12.86,100,1,14.24,100,1,12.73,100,1,14.28,100,1,12.71,100,1,14.48,700,1,12.50,700,1,14.53,100,1,12.46,100,1,14.54,700,1,12.43,700,1,14.56,700,1,12.42,700,1,14.57,200,2,ARL,339358409
2464,2025-07-17T16:13:06.235594115Z,2025-07-17T16:13:06.235428434Z,160,2,1108,C,A,22,17.76,100,0,165681,282414050,13.11,100,1,13.66,15,1,12.98,200,2,13.67,100,1,12.96,2,1,13.81,2,1,12.86,100,1,14.24,100,1,12.73,100,1,14.28,100,1,12.71,100,1,14.48,700,1,12.50,700,1,14.53,100,1,12.46,100,1,14.54,700,1,12.43,700,1,14.56,700,1,12.42,700,1,14.57,200,2,ARL,339208377
2465,2025-07-17T16:13:06.235594115Z,2025-07-17T16:13:06.235428434Z,160,2,1108,A,A,22,17.37,100,130,165681,282414050,13.11,100,1,13.66,15,1,12.98,200,2,13.67,100,1,12.96,2,1,13.81,2,1,12.86,100,1,14.24,100,1,12.73,100,1,14.28,100,1,12.71,100,1,14.48,700,1,12.50,700,1,14.53,100,1,12.46,100,1,14.54,700,1,12.43,700,1,14.56,700,1,12.42,700,1,14.57,200,2,ARL,339358609
2466,2025-07-17T16:13:06.236567790Z,2025-07-17T16:13:06.236401579Z,160,2,1108,C,A,3,14.24,100,130,166211,282414131,13.11,100,1,13.66,15,1,12.98,200,2,13.67,100,1,12.96,2,1,13.81,2,1,12.86,100,1,14.28,100,1,12.73,100,1,14.48,700,1,12.71,100,1,14.53,100,1,12.50,700,1,14.54,700,1,12.46,100,1,14.56,700,1,12.43,700,1,14.57,200,2,12.42,700,1,14.63,100,1,ARL,339207197
2467,2025-07-17T16:13:06.236621535Z,2025-07-17T16:13:06.236456489Z,160,2,1108,A,A,3,13.94,100,130,165046,282414141,13.11,100,1,13.66,15,1,12.98,200,2,13.67,100,1,12.96,2,1,13.81,2,1,12.86,100,1,13.94,100,1,12.73,100,1,14.28,100,1,12.71,100,1,14.48,700,1,12.50,700,1,14.53,100,1,12.46,100,1,14.54,700,1,12.43,700,1,14.56,700,1,12.42,700,1,14.57,200,2,ARL,339358741
2468,2025-07-17T16:13:06.243909112Z,2025-07-17T16:13:06.243743642Z,160,2,1108,C,A,20,16.08,100,0,165470,282414340,13.11,100,1,13.66,15,1,12.98,200,2,13.67,100,1,12.96,2,1,13.81,2,1,12.86,100,1,13.94,100,1,12.73,100,1,14.28,100,1,12.71,100,1,14.48,700,1,12.50,700,1,14.53,100,1,12.46,100,1,14.54,700,1,12.43,700,1,14.56,700,1,12.42,700,1,14.57,200,2,ARL,339209241
2469,2025-07-17T16:13:06.243909112Z,2025-07-17T16:13:06.243743642Z,160,2,1108,A,A,20,15.73,100,130,165470,282414340,13.11,100,1,13.66,15,1,12.98,200,2,13.67,100,1,12.96,2,1,13.81,2,1,12.86,100,1,13.94,100,1,12.73,100,1,14.28,100,1,12.71,100,1,14.48,700,1,12.50,700,1,14.53,100,1,12.46,100,1,14.54,700,1,12.43,700,1,14.56,700,1,12.42,700,1,14.57,200,2,ARL,339359077
2470,2025-07-17T16:13:06.268052093Z,2025-07-17T16:13:06.267886189Z,160,2,1108,C,A,18,15.38,100,0,165904,282414570,13.11,100,1,13.66,15,1,12.98,200,2,13.67,100,1,12.96,2,1,13.81,2,1,12.86,100,1,13.94,100,1,12.73,100,1,14.28,100,1,12.71,100,1,14.48,700,1,12.50,700,1,14.53,100,1,12.46,100,1,14.54,700,1,12.43,700,1,14.56,700,1,12.42,700,1,14.57,200,2,ARL,339215205
2471,2025-07-17T16:13:06.268052093Z,2025-07-17T16:13:06.267886189Z,160,2,1108,A,A,16,15.04,100,130,165904,282414570,13.11,100,1,13.66,15,1,12.98,200,2,13.67,100,1,12.96,2,1,13.81,2,1,12.86,100,1,13.94,100,1,12.73,100,1,14.28,100,1,12.71,100,1,14.48,700,1,12.50,700,1,14.53,100,1,12.46,100,1,14.54,700,1,12.43,700,1,14.56,700,1,12.42,700,1,14.57,200,2,ARL,339359357
2472,2025-07-17T16:13:06.275886461Z,2025-07-17T16:13:06.275720866Z,160,2,1108,C,A,15,14.96,100,0,165595,282414642,13.11,100,1,13.66,15,1,12.98,200,2,13.67,100,1,12.96,2,1,13.81,2,1,12.86,100,1,13.94,100,1,12.73,100,1,14.28,100,1,12.71,100,1,14.48,700,1,12.50,700,1,14.53,100,1,12.46,100,1,14.54,700,1,12.43,700,1,14.56,700,1,12.42,700,1,14.57,200,2,ARL,339216161
2473,2025-07-17T16:13:06.275886461Z,2025-07-17T16:13:06.275720866Z,160,2,1108,A,A,10,14.63,100,130,165595,282414642,13.11,100,1,13.66,15,1,12.98,200,2,13.67,100,1,12.96,2,1,13.81,2,1,12.86,100,1,13.94,100,1,12.73,100,1,14.28,100,1,12.71,100,1,14.48,700,1,12.50,700,1,14.53,100,1,12.46,100,1,14.54,700,1,12.43,700,1,14.56,700,1,12.42,700,1,14.57,200,2,ARL,339359401
2474,2025-07-17T16:13:06.277048260Z,2025-07-17T16:13:06.276882863Z,160,2,1108,C,A,13,14.77,100,130,165397,282414659,13.11,100,1,13.66,15,1,12.98,200,2,13.67,100,1,12.96,2,1,13.81,2,1,12.86,100,1,13.94,100,1,12.73,100,1,14.28,100,1,12.71,100,1,14.48,700,1,12.50,700,1,14.53,100,1,12.46,100,1,14.54,700,1,12.43,700,1,14.56,700,1,12.42,700,1,14.57,200,2,ARL,339232213
2475,2025-07-17T16:13:06.277178914Z,2025-07-17T16:13:06.277013512Z,160,2,1108,A,A,5,14.46,100,130,165402,282414660,13.11,100,1,13.66,15,1,12.98,200,2,13.67,100,1,12.96,2,1,13.81,2,1,12.86,100,1,13.94,100,1,12.73,100,1,14.28,100,1,12.71,100,1,14.46,100,1,12.50,700,1,14.48,700,1,12.46,100,1,14.53,100,1,12.43,700,1,14.54,700,1,12.42,700,1,14.56,700,1,ARL,339359421
2476,2025-07-17T16:13:06.622659102Z,2025-07-17T16:13:06.622493734Z,160,2,1108,A,A,4,14.22,100,130,165368,282418746,13.11,100,1,13.66,15,1,12.98,200,2,13.67,100,1,12.96,2,1,13.81,2,1,12.86,100,1,13.94,100,1,12.73,100,1,14.22,100,1,12.71,100,1,14.28,100,1,12.50,700,1,14.46,100,1,12.46,100,1,14.48,700,1,12.43,700,1,14.53,100,1,12.42,700,1,14.54,700,1,ARL,339365193
2477,2025-07-17T16:13:06.663836744Z,2025-07-17T16:13:06.663671305Z,160,2,1108,C,A,8,14.53,100,130,165439,282418921,13.11,100,1,13.66,15,1,12.98,200,2,13.67,100,1,12.96,2,1,13.81,2,1,12.86,100,1,13.94,100,1,12.73,100,1,14.22,100,1,12.71,100,1,14.28,100,1,12.50,700,1,14.46,100,1,12.46,100,1,14.48,700,1,12.43,700,1,14.54,700,1,12.42,700,1,14.56,700,1,ARL,339225769
2478,2025-07-17T16:13:06.759791103Z,2025-07-17T16:13:06.759625628Z,160,2,1108,A,A,8,14.49,100,130,165475,282419471,13.11,100,1,13.66,15,1,12.98,200,2,13.67,100,1,12.96,2,1,13.81,2,1,12.86,100,1,13.94,100,1,12.73,100,1,14.22,100,1,12.71,100,1,14.28,100,1,12.50,700,1,14.46,100,1,12.46,100,1,14.48,700,1,12.43,700,1,14.49,100,1,12.42,700,1,14.54,700,1,ARL,339366385
2479,2025-07-17T16:13:06.759804641Z,2025-07-17T16:13:06.759638890Z,160,2,1108,C,A,15,14.81,100,130,165751,282419472,13.11,100,1,13.66,15,1,12.98,200,2,13.67,100,1,12.96,2,1,13.81,2,1,12.86,100,1,13.94,100,1,12.73,100,1,14.22,100,1,12.71,100,1,14.28,100,1,12.50,700,1,14.46,100,1,12.46,100,1,14.48,700,1,12.43,700,1,14.49,100,1,12.42,700,1,14.54,700,1,ARL,339225885
2480,2025-07-17T16:13:09.354048740Z,2025-07-17T16:13:09.353883614Z,160,2,1108,A,A,0,13.64,15,130,165126,282469242,13.11,100,1,13.64,15,1,12.98,200,2,13.66,15,1,12.96,2,1,13.67,100,1,12.86,100,1,13.81,2,1,12.73,100,1,13.94,100,1,12.71,100,1,14.22,100,1,12.50,700,1,14.28,100,1,12.46,100,1,14.46,100,1,12.43,700,1,14.48,700,1,12.42,700,1,14.49,100,1,ARL,339425837
2481,2025-07-17T16:13:09.368197659Z,2025-07-17T16:13:09.368030843Z,160,2,1108,C,A,2,13.67,100,0,166816,282470466,13.11,100,1,13.64,15,1,12.98,200,2,13.66,15,1,12.96,2,1,13.81,2,1,12.86,100,1,13.94,100,1,12.73,100,1,14.22,100,1,12.71,100,1,14.28,100,1,12.50,700,1,14.46,100,1,12.46,100,1,14.48,700,1,12.43,700,1,14.49,100,1,12.42,700,1,14.54,700,1,ARL,339358233
2482,2025-07-17T16:13:09.368197659Z,2025-07-17T16:13:09.368030843Z,160,2,1108,A,A,1,13.65,100,128,166816,282470466,13.11,100,1,13.64,15,1,12.98,200,2,13.65,100,1,12.96,2,1,13.66,15,1,12.86,100,1,13.81,2,1,12.73,100,1,13.94,100,1,12.71,100,1,14.22,100,1,12.50,700,1,14.28,100,1,12.46,100,1,14.46,100,1,12.43,700,1,14.48,700,1,12.42,700,1,14.49,100,1,ARL,339427217
2483,2025-07-17T16:13:14.046267875Z,2025-07-17T16:13:14.046102556Z,160,2,1108,C,A,2,13.66,15,130,165319,282563502,13.11,100,1,13.64,15,1,12.98,200,2,13.65,100,1,12.96,2,1,13.81,2,1,12.86,100,1,13.94,100,1,12.73,100,1,14.22,100,1,12.71,100,1,14.28,100,1,12.50,700,1,14.46,100,1,12.46,100,1,14.48,700,1,12.43,700,1,14.49,100,1,12.42,700,1,14.54,700,1,ARL,339332865
2484,2025-07-17T16:13:17.775210916Z,2025-07-17T16:13:17.775045316Z,160,2,1108,A,A,0,13.57,15,130,165600,282616566,13.11,100,1,13.57,15,1,12.98,200,2,13.64,15,1,12.96,2,1,13.65,100,1,12.86,100,1,13.81,2,1,12.73,100,1,13.94,100,1,12.71,100,1,14.22,100,1,12.50,700,1,14.28,100,1,12.46,100,1,14.46,100,1,12.43,700,1,14.48,700,1,12.42,700,1,14.49,100,1,ARL,339610637
2485,2025-07-17T16:13:19.781143691Z,2025-07-17T16:13:19.780978185Z,160,2,1108,C,A,2,13.65,100,0,165506,282644181,13.11,100,1,13.57,15,1,12.98,200,2,13.64,15,1,12.96,2,1,13.81,2,1,12.86,100,1,13.94,100,1,12.73,100,1,14.22,100,1,12.71,100,1,14.28,100,1,12.50,700,1,14.46,100,1,12.46,100,1,14.48,700,1,12.43,700,1,14.49,100,1,12.42,700,1,14.54,700,1,ARL,339427217
2486,2025-07-17T16:13:19.781143691Z,2025-07-17T16:13:19.780978185Z,160,2,1108,A,A,1,13.58,100,130,165506,282644181,13.11,100,1,13.57,15,1,12.98,200,2,13.58,100,1,12.96,2,1,13.64,15,1,12.86,100,1,13.81,2,1,12.73,100,1,13.94,100,1,12.71,100,1,14.22,100,1,12.50,700,1,14.28,100,1,12.46,100,1,14.46,100,1,12.43,700,1,14.48,700,1,12.42,700,1,14.49,100,1,ARL,339641813
2487,2025-07-17T16:13:19.781889805Z,2025-07-17T16:13:19.781723964Z,160,2,1108,C,A,15,14.73,100,0,165841,282644189,13.11,100,1,13.57,15,1,12.98,200,2,13.58,100,1,12.96,2,1,13.64,15,1,12.86,100,1,13.81,2,1,12.73,100,1,13.94,100,1,12.71,100,1,14.22,100,1,12.50,700,1,14.28,100,1,12.46,100,1,14.46,100,1,12.43,700,1,14.48,700,1,12.42,700,1,14.49,100,1,ARL,339358293
2488,2025-07-17T16:13:19.781889805Z,2025-07-17T16:13:19.781723964Z,160,2,1108,A,A,13,14.63,100,130,165841,282644189,13.11,100,1,13.57,15,1,12.98,200,2,13.58,100,1,12.96,2,1,13.64,15,1,12.86,100,1,13.81,2,1,12.73,100,1,13.94,100,1,12.71,100,1,14.22,100,1,12.50,700,1,14.28,100,1,12.46,100,1,14.46,100,1,12.43,700,1,14.48,700,1,12.42,700,1,14.49,100,1,ARL,339641865
2489,2025-07-17T16:13:19.789771458Z,2025-07-17T16:13:19.789606057Z,160,2,1108,C,A,4,13.94,100,130,165401,282644321,13.11,100,1,13.57,15,1,12.98,200,2,13.58,100,1,12.96,2,1,13.64,15,1,12.86,100,1,13.81,2,1,12.73,100,1,14.22,100,1,12.71,100,1,14.28,100,1,12.50,700,1,14.46,100,1,12.46,100,1,14.48,700,1,12.43,700,1,14.49,100,1,12.42,700,1,14.54,700,1,ARL,339358741
2490,2025-07-17T16:13:19.789822010Z,2025-07-17T16:13:19.789656689Z,160,2,1108,A,A,4,13.85,100,130,165321,282644322,13.11,100,1,13.57,15,1,12.98,200,2,13.58,100,1,12.96,2,1,13.64,15,1,12.86,100,1,13.81,2,1,12.73,100,1,13.85,100,1,12.71,100,1,14.22,100,1,12.50,700,1,14.28,100,1,12.46,100,1,14.46,100,1,12.43,700,1,14.48,700,1,12.42,700,1,14.49,100,1,ARL,339642033
2491,2025-07-17T16:13:19.863618706Z,2025-07-17T16:13:19.863452537Z,160,2,1108,C,A,0,13.57,15,130,166169,282645966,13.11,100,1,13.58,100,1,12.98,200,2,13.64,15,1,12.96,2,1,13.81,2,1,12.86,100,1,13.85,100,1,12.73,100,1,14.22,100,1,12.71,100,1,14.28,100,1,12.50,700,1,14.46,100,1,12.46,100,1,14.48,700,1,12.43,700,1,14.49,100,1,12.42,700,1,14.54,700,1,ARL,339610637
2492,2025-07-17T16:13:19.863790083Z,2025-07-17T16:13:19.863624798Z,160,2,1108,C,A,1,13.64,15,130,165285,282646001,13.11,100,1,13.58,100,1,12.98,200,2,13.81,2,1,12.96,2,1,13.85,100,1,12.86,100,1,14.22,100,1,12.73,100,1,14.28,100,1,12.71,100,1,14.46,100,1,12.50,700,1,14.48,700,1,12.46,100,1,14.49,100,1,12.43,700,1,14.54,700,1,12.42,700,1,14.56,700,1,ARL,339425837
2493,2025-07-17T16:13:19.863968792Z,2025-07-17T16:13:19.863803503Z,160,2,1108,A,A,0,13.58,96,130,165289,282646014,13.11,100,1,13.58,196,2,12.98,200,2,13.81,2,1,12.96,2,1,13.85,100,1,12.86,100,1,14.22,100,1,12.73,100,1,14.28,100,1,12.71,100,1,14.46,100,1,12.50,700,1,14.48,700,1,12.46,100,1,14.49,100,1,12.43,700,1,14.54,700,1,12.42,700,1,14.56,700,1,ARL,339643285
2494,2025-07-17T16:13:24.182625011Z,2025-07-17T16:13:24.182459676Z,160,2,1108,A,A,0,13.57,15,130,165335,282694909,13.11,100,1,13.57,15,1,12.98,200,2,13.58,196,2,12.96,2,1,13.81,2,1,12.86,100,1,13.85,100,1,12.73,100,1,14.22,100,1,12.71,100,1,14.28,100,1,12.50,700,1,14.46,100,1,12.46,100,1,14.48,700,1,12.43,700,1,14.49,100,1,12.42,700,1,14.54,700,1,ARL,339710089
2495,2025-07-17T16:13:24.182918202Z,2025-07-17T16:13:24.182753004Z,160,2,1108,C,A,1,13.58,96,130,165198,282694924,13.11,100,1,13.57,15,1,12.98,200,2,13.58,100,1,12.96,2,1,13.81,2,1,12.86,100,1,13.85,100,1,12.73,100,1,14.22,100,1,12.71,100,1,14.28,100,1,12.50,700,1,14.46,100,1,12.46,100,1,14.48,700,1,12.43,700,1,14.49,100,1,12.42,700,1,14.54,700,1,ARL,339643285
2496,2025-07-17T16:13:24.627374514Z,2025-07-17T16:13:24.627209125Z,160,2,1108,A,A,5,14.26,700,130,165389,282700118,13.11,100,1,13.57,15,1,12.98,200,2,13.58,100,1,12.96,2,1,13.81,2,1,12.86,100,1,13.85,100,1,12.73,100,1,14.22,100,1,12.71,100,1,14.26,700,1,12.50,700,1,14.28,100,1,12.46,100,1,14.46,100,1,12.43,700,1,14.48,700,1,12.42,700,1,14.49,100,1,ARL,339716321
2497,2025-07-17T16:13:24.627430447Z,2025-07-17T16:13:24.627265040Z,160,2,1108,C,A,14,14.68,700,130,165407,282700120,13.11,100,1,13.57,15,1,12.98,200,2,13.58,100,1,12.96,2,1,13.81,2,1,12.86,100,1,13.85,100,1,12.73,100,1,14.22,100,1,12.71,100,1,14.26,700,1,12.50,700,1,14.28,100,1,12.46,100,1,14.46,100,1,12.43,700,1,14.48,700,1,12.42,700,1,14.49,100,1,ARL,339096897
2498,2025-07-17T16:13:25.962717944Z,2025-07-17T16:13:25.962552288Z,160,2,1108,C,A,12,14.57,100,0,165656,282719507,13.11,100,1,13.57,15,1,12.98,200,2,13.58,100,1,12.96,2,1,13.81,2,1,12.86,100,1,13.85,100,1,12.73,100,1,14.22,100,1,12.71,100,1,14.26,700,1,12.50,700,1,14.28,100,1,12.46,100,1,14.46,100,1,12.43,700,1,14.48,700,1,12.42,700,1,14.49,100,1,ARL,339203693
2499,2025-07-17T16:13:25.962717944Z,2025-07-17T16:13:25.962552288Z,160,2,1108,A,A,7,14.46,100,130,165656,282719507,13.11,100,1,13.57,15,1,12.98,200,2,13.58,100,1,12.96,2,1,13.81,2,1,12.86,100,1,13.85,100,1,12.73,100,1,14.22,100,1,12.71,100,1,14.26,700,1,12.50,700,1,14.28,100,1,12.46,100,1,14.46,200,2,12.43,700,1,14.48,700,1,12.42,700,1,14.49,100,1,ARL,339739285
2500,2025-07-17T16:13:25.963209328Z,2025-07-17T16:13:25.963043858Z,160,2,1108,C,A,12,14.57,100,0,165470,282719515,13.11,100,1,13.57,15,1,12.98,200,2,13.58,100,1,12.96,2,1,13.81,2,1,12.86,100,1,13.85,100,1,12.73,100,1,14.22,100,1,12.71,100,1,14.26,700,1,12.50,700,1,14.28,100,1,12.46,100,1,14.46,200,2,12.43,700,1,14.48,700,1,12.42,700,1,14.49,100,1,ARL,339203897
2501,2025-07-17T16:13:25.963209328Z,2025-07-17T16:13:25.963043858Z,160,2,1108,A,A,7,14.46,100,130,165470,282719515,13.11,100,1,13.57,15,1,12.98,200,2,13.58,100,1,12.96,2,1,13.81,2,1,12.86,100,1,13.85,100,1,12.73,100,1,14.22,100,1,12.71,100,1,14.26,700,1,12.50,700,1,14.28,100,1,12.46,100,1,14.46,300,3,12.43,700,1,14.48,700,1,12.42,700,1,14.49,100,1,ARL,339739297
2502,2025-07-17T16:13:34.825229037Z,2025-07-17T16:13:34.825063658Z,160,2,1108,A,A,0,13.55,15,130,165379,282849136,13.11,100,1,13.55,15,1,12.98,200,2,13.57,15,1,12.96,2,1,13.58,100,1,12.86,100,1,13.81,2,1,12.73,100,1,13.85,100,1,12.71,100,1,14.22,100,1,12.50,700,1,14.26,700,1,12.46,100,1,14.28,100,1,12.43,700,1,14.46,300,3,12.42,700,1,14.48,700,1,ARL,339897885
2503,2025-07-17T16:13:36.525450545Z,2025-07-17T16:13:36.525285006Z,160,2,1108,C,A,2,13.58,100,0,165539,282880671,13.11,100,1,13.55,15,1,12.98,200,2,13.57,15,1,12.96,2,1,13.81,2,1,12.86,100,1,13.85,100,1,12.73,100,1,14.22,100,1,12.71,100,1,14.26,700,1,12.50,700,1,14.28,100,1,12.46,100,1,14.46,300,3,12.43,700,1,14.48,700,1,12.42,700,1,14.49,100,1,ARL,339641813
2504,2025-07-17T16:13:36.525450545Z,2025-07-17T16:13:36.525285006Z,160,2,1108,A,A,1,13.56,100,130,165539,282880671,13.11,100,1,13.55,15,1,12.98,200,2,13.56,100,1,12.96,2,1,13.57,15,1,12.86,100,1,13.81,2,1,12.73,100,1,13.85,100,1,12.71,100,1,14.22,100,1,12.50,700,1,14.26,700,1,12.46,100,1,14.28,100,1,12.43,700,1,14.46,300,3,12.42,700,1,14.48,700,1,ARL,339937253
2505,2025-07-17T16:13:36.528326337Z,2025-07-17T16:13:36.528160728Z,160,2,1108,C,A,20,17.37,100,0,165609,282880690,13.11,100,1,13.55,15,1,12.98,200,2,13.56,100,1,12.96,2,1,13.57,15,1,12.86,100,1,13.81,2,1,12.73,100,1,13.85,100,1,12.71,100,1,14.22,100,1,12.50,700,1,14.26,700,1,12.46,100,1,14.28,100,1,12.43,700,1,14.46,300,3,12.42,700,1,14.48,700,1,ARL,339358609
2506,2025-07-17T16:13:36.528326337Z,2025-07-17T16:13:36.528160728Z,160,2,1108,A,A,20,17.23,100,130,165609,282880690,13.11,100,1,13.55,15,1,12.98,200,2,13.56,100,1,12.96,2,1,13.57,15,1,12.86,100,1,13.81,2,1,12.73,100,1,13.85,100,1,12.71,100,1,14.22,100,1,12.50,700,1,14.26,700,1,12.46,100,1,14.28,100,1,12.43,700,1,14.46,300,3,12.42,700,1,14.48,700,1,ARL,339937293
2507,2025-07-17T16:13:40.166698198Z,2025-07-17T16:13:40.166532673Z,160,2,1108,C,A,2,13.57,15,130,165525,282934517,13.11,100,1,13.55,15,1,12.98,200,2,13.56,100,1,12.96,2,1,13.81,2,1,12.86,100,1,13.85,100,1,12.73,100,1,14.22,100,1,12.71,100,1,14.26,700,1,12.50,700,1,14.28,100,1,12.46,100,1,14.46,300,3,12.43,700,1,14.48,700,1,12.42,700,1,14.49,100,1,ARL,339710089
2508,2025-07-17T16:13:41.168681977Z,2025-07-17T16:13:41.168516592Z,160,2,1108,A,A,0,13.53,15,130,165385,282947373,13.11,100,1,13.53,15,1,12.98,200,2,13.55,15,1,12.96,2,1,13.56,100,1,12.86,100,1,13.81,2,1,12.73,100,1,13.85,100,1,12.71,100,1,14.22,100,1,12.50,700,1,14.26,700,1,12.46,100,1,14.28,100,1,12.43,700,1,14.46,300,3,12.42,700,1,14.48,700,1,ARL,340027925
2509,2025-07-17T16:13:41.810648775Z,2025-07-17T16:13:41.810482971Z,160,2,1108,C,A,2,13.56,100,0,165804,282959674,13.11,100,1,13.53,15,1,12.98,200,2,13.55,15,1,12.96,2,1,13.81,2,1,12.86,100,1,13.85,100,1,12.73,100,1,14.22,100,1,12.71,100,1,14.26,700,1,12.50,700,1,14.28,100,1,12.46,100,1,14.46,300,3,12.43,700,1,14.48,700,1,12.42,700,1,14.49,100,1,ARL,339937253
2510,2025-07-17T16:13:41.810648775Z,2025-07-17T16:13:41.810482971Z,160,2,1108,A,A,1,13.54,100,130,165804,282959674,13.11,100,1,13.53,15,1,12.98,200,2,13.54,100,1,12.96,2,1,13.55,15,1,12.86,100,1,13.81,2,1,12.73,100,1,13.85,100,1,12.71,100,1,14.22,100,1,12.50,700,1,14.26,700,1,12.46,100,1,14.28,100,1,12.43,700,1,14.46,300,3,12.42,700,1,14.48,700,1,ARL,340046965
2511,2025-07-17T16:13:41.811397213Z,2025-07-17T16:13:41.811231743Z,160,2,1108,C,A,13,14.63,100,0,165470,282959705,13.11,100,1,13.53,15,1,12.98,200,2,13.54,100,1,12.96,2,1,13.55,15,1,12.86,100,1,13.81,2,1,12.73,100,1,13.85,100,1,12.71,100,1,14.22,100,1,12.50,700,1,14.26,700,1,12.46,100,1,14.28,100,1,12.43,700,1,14.46,300,3,12.42,700,1,14.48,700,1,ARL,339641865
2512,2025-07-17T16:13:41.811397213Z,2025-07-17T16:13:41.811231743Z,160,2,1108,A,A,13,14.59,100,130,165470,282959705,13.11,100,1,13.53,15,1,12.98,200,2,13.54,100,1,12.96,2,1,13.55,15,1,12.86,100,1,13.81,2,1,12.73,100,1,13.85,100,1,12.71,100,1,14.22,100,1,12.50,700,1,14.26,700,1,12.46,100,1,14.28,100,1,12.43,700,1,14.46,300,3,12.42,700,1,14.48,700,1,ARL,340047001
2513,2025-07-17T16:13:41.846549822Z,2025-07-17T16:13:41.846384162Z,160,2,1108,C,A,18,15.73,100,0,165660,282960440,13.11,100,1,13.53,15,1,12.98,200,2,13.54,100,1,12.96,2,1,13.55,15,1,12.86,100,1,13.81,2,1,12.73,100,1,13.85,100,1,12.71,100,1,14.22,100,1,12.50,700,1,14.26,700,1,12.46,100,1,14.28,100,1,12.43,700,1,14.46,300,3,12.42,700,1,14.48,700,1,ARL,339359077
2514,2025-07-17T16:13:41.846549822Z,2025-07-17T16:13:41.846384162Z,160,2,1108,A,A,17,15.58,100,130,165660,282960440,13.11,100,1,13.53,15,1,12.98,200,2,13.54,100,1,12.96,2,1,13.55,15,1,12.86,100,1,13.81,2,1,12.73,100,1,13.85,100,1,12.71,100,1,14.22,100,1,12.50,700,1,14.26,700,1,12.46,100,1,14.28,100,1,12.43,700,1,14.46,300,3,12.42,700,1,14.48,700,1,ARL,340047805
2515,2025-07-17T16:13:53.138391930Z,2025-07-17T16:13:53.138226660Z,160,2,1108,C,A,0,13.53,15,130,165270,283090735,13.11,100,1,13.54,100,1,12.98,200,2,13.55,15,1,12.96,2,1,13.81,2,1,12.86,100,1,13.85,100,1,12.73,100,1,14.22,100,1,12.71,100,1,14.26,700,1,12.50,700,1,14.28,100,1,12.46,100,1,14.46,300,3,12.43,700,1,14.48,700,1,12.42,700,1,14.49,100,1,ARL,340027925
2516,2025-07-17T16:13:53.784302227Z,2025-07-17T16:13:53.784124590Z,160,2,1108,C,A,1,13.55,15,128,177637,283098338,13.11,100,1,13.54,100,1,12.98,200,2,13.81,2,1,12.96,2,1,13.85,100,1,12.86,100,1,14.22,100,1,12.73,100,1,14.26,700,1,12.71,100,1,14.28,100,1,12.50,700,1,14.46,300,3,12.46,100,1,14.48,700,1,12.43,700,1,14.49,100,1,12.42,700,1,14.54,700,1,ARL,339897885
2517,2025-07-17T16:14:06.190866982Z,2025-07-17T16:14:06.190701389Z,160,2,1108,C,A,1,13.81,2,0,165593,283262191,13.11,100,1,13.54,100,1,12.98,200,2,13.85,100,1,12.96,2,1,14.22,100,1,12.86,100,1,14.26,700,1,12.73,100,1,14.28,100,1,12.71,100,1,14.46,300,3,12.50,700,1,14.48,700,1,12.46,100,1,14.49,100,1,12.43,700,1,14.54,700,1,12.42,700,1,14.56,700,1,ARL,339358409
2518,2025-07-17T16:14:06.190866982Z,2025-07-17T16:14:06.190701389Z,160,2,1108,A,A,1,13.74,2,130,165593,283262191,13.11,100,1,13.54,100,1,12.98,200,2,13.74,2,1,12.96,2,1,13.85,100,1,12.86,100,1,14.22,100,1,12.73,100,1,14.26,700,1,12.71,100,1,14.28,100,1,12.50,700,1,14.46,300,3,12.46,100,1,14.48,700,1,12.43,700,1,14.49,100,1,12.42,700,1,14.54,700,1,ARL,340449865
2519,2025-07-17T16:14:10.827419207Z,2025-07-17T16:14:10.827253317Z,160,2,1108,A,A,0,13.51,15,130,165890,283315922,13.11,100,1,13.51,15,1,12.98,200,2,13.54,100,1,12.96,2,1,13.74,2,1,12.86,100,1,13.85,100,1,12.73,100,1,14.22,100,1,12.71,100,1,14.26,700,1,12.50,700,1,14.28,100,1,12.46,100,1,14.46,300,3,12.43,700,1,14.48,700,1,12.42,700,1,14.49,100,1,ARL,340526285
2520,2025-07-17T16:14:10.876894854Z,2025-07-17T16:14:10.876729278Z,160,2,1108,C,A,1,13.54,100,0,165576,283317356,13.11,100,1,13.51,15,1,12.98,200,2,13.74,2,1,12.96,2,1,13.85,100,1,12.86,100,1,14.22,100,1,12.73,100,1,14.26,700,1,12.71,100,1,14.28,100,1,12.50,700,1,14.46,300,3,12.46,100,1,14.48,700,1,12.43,700,1,14.49,100,1,12.42,700,1,14.54,700,1,ARL,340046965
2521,2025-07-17T16:14:10.876894854Z,2025-07-17T16:14:10.876729278Z,160,2,1108,A,A,1,13.52,100,130,165576,283317356,13.11,100,1,13.51,15,1,12.98,200,2,13.52,100,1,12.96,2,1,13.74,2,1,12.86,100,1,13.85,100,1,12.73,100,1,14.22,100,1,12.71,100,1,14.26,700,1,12.50,700,1,14.28,100,1,12.46,100,1,14.46,300,3,12.43,700,1,14.48,700,1,12.42,700,1,14.49,100,1,ARL,340527921
2522,2025-07-17T16:14:10.878601199Z,2025-07-17T16:14:10.878435316Z,160,2,1108,C,A,13,14.63,100,0,165883,283317367,13.11,100,1,13.51,15,1,12.98,200,2,13.52,100,1,12.96,2,1,13.74,2,1,12.86,100,1,13.85,100,1,12.73,100,1,14.22,100,1,12.71,100,1,14.26,700,1,12.50,700,1,14.28,100,1,12.46,100,1,14.46,300,3,12.43,700,1,14.48,700,1,12.42,700,1,14.49,100,1,ARL,339358353
2523,2025-07-17T16:14:10.878601199Z,2025-07-17T16:14:10.878435316Z,160,2,1108,A,A,8,14.47,100,130,165883,283317367,13.11,100,1,13.51,15,1,12.98,200,2,13.52,100,1,12.96,2,1,13.74,2,1,12.86,100,1,13.85,100,1,12.73,100,1,14.22,100,1,12.71,100,1,14.26,700,1,12.50,700,1,14.28,100,1,12.46,100,1,14.46,300,3,12.43,700,1,14.47,100,1,12.42,700,1,14.48,700,1,ARL,340527969
2524,2025-07-17T16:14:10.892679514Z,2025-07-17T16:14:10.892513823Z,160,2,1108,C,A,14,14.63,100,0,165691,283317451,13.11,100,1,13.51,15,1,12.98,200,2,13.52,100,1,12.96,2,1,13.74,2,1,12.86,100,1,13.85,100,1,12.73,100,1,14.22,100,1,12.71,100,1,14.26,700,1,12.50,700,1,14.28,100,1,12.46,100,1,14.46,300,3,12.43,700,1,14.47,100,1,12.42,700,1,14.48,700,1,ARL,339359401
2525,2025-07-17T16:14:10.892679514Z,2025-07-17T16:14:10.892513823Z,160,2,1108,A,A,8,14.47,100,130,165691,283317451,13.11,100,1,13.51,15,1,12.98,200,2,13.52,100,1,12.96,2,1,13.74,2,1,12.86,100,1,13.85,100,1,12.73,100,1,14.22,100,1,12.71,100,1,14.26,700,1,12.50,700,1,14.28,100,1,12.46,100,1,14.46,300,3,12.43,700,1,14.47,200,2,12.42,700,1,14.48,700,1,ARL,340528121
2526,2025-07-17T16:14:10.985507716Z,2025-07-17T16:14:10.985342000Z,160,2,1108,C,A,7,14.46,100,0,165716,283318181,13.11,100,1,13.51,15,1,12.98,200,2,13.52,100,1,12.96,2,1,13.74,2,1,12.86,100,1,13.85,100,1,12.73,100,1,14.22,100,1,12.71,100,1,14.26,700,1,12.50,700,1,14.28,100,1,12.46,100,1,14.46,200,2,12.43,700,1,14.47,200,2,12.42,700,1,14.48,700,1,ARL,339359421
2527,2025-07-17T16:14:10.985507716Z,2025-07-17T16:14:10.985342000Z,160,2,1108,A,A,7,14.31,100,130,165716,283318181,13.11,100,1,13.51,15,1,12.98,200,2,13.52,100,1,12.96,2,1,13.74,2,1,12.86,100,1,13.85,100,1,12.73,100,1,14.22,100,1,12.71,100,1,14.26,700,1,12.50,700,1,14.28,100,1,12.46,100,1,14.31,100,1,12.43,700,1,14.46,200,2,12.42,700,1,14.47,200,2,ARL,340529021
2528,2025-07-17T16:14:19.528488233Z,2025-07-17T16:14:19.528322793Z,160,2,1108,A,A,0,13.49,15,130,165440,283419160,13.11,100,1,13.49,15,1,12.98,200,2,13.51,15,1,12.96,2,1,13.52,100,1,12.86,100,1,13.74,2,1,12.73,100,1,13.85,100,1,12.71,100,1,14.22,100,1,12.50,700,1,14.26,700,1,12.46,100,1,14.28,100,1,12.43,700,1,14.31,100,1,12.42,700,1,14.46,200,2,ARL,340664453
2529,2025-07-17T16:14:21.306764970Z,2025-07-17T16:14:21.306599291Z,160,2,1108,C,A,2,13.52,100,0,165679,283454179,13.11,100,1,13.49,15,1,12.98,200,2,13.51,15,1,12.96,2,1,13.74,2,1,12.86,100,1,13.85,100,1,12.73,100,1,14.22,100,1,12.71,100,1,14.26,700,1,12.50,700,1,14.28,100,1,12.46,100,1,14.31,100,1,12.43,700,1,14.46,200,2,12.42,700,1,14.47,200,2,ARL,340527921
2530,2025-07-17T16:14:21.306764970Z,2025-07-17T16:14:21.306599291Z,160,2,1108,A,A,1,13.50,100,130,165679,283454179,13.11,100,1,13.49,15,1,12.98,200,2,13.50,100,1,12.96,2,1,13.51,15,1,12.86,100,1,13.74,2,1,12.73,100,1,13.85,100,1,12.71,100,1,14.22,100,1,12.50,700,1,14.26,700,1,12.46,100,1,14.28,100,1,12.43,700,1,14.31,100,1,12.42,700,1,14.46,200,2,ARL,340704401
2531,2025-07-17T16:14:21.307512009Z,2025-07-17T16:14:21.307346403Z,160,2,1108,C,A,15,14.59,100,0,165606,283454259,13.11,100,1,13.49,15,1,12.98,200,2,13.50,100,1,12.96,2,1,13.51,15,1,12.86,100,1,13.74,2,1,12.73,100,1,13.85,100,1,12.71,100,1,14.22,100,1,12.50,700,1,14.26,700,1,12.46,100,1,14.28,100,1,12.43,700,1,14.31,100,1,12.42,700,1,14.46,200,2,ARL,340047001
2532,2025-07-17T16:14:21.307512009Z,2025-07-17T16:14:21.307346403Z,160,2,1108,A,A,14,14.55,100,130,165606,283454259,13.11,100,1,13.49,15,1,12.98,200,2,13.50,100,1,12.96,2,1,13.51,15,1,12.86,100,1,13.74,2,1,12.73,100,1,13.85,100,1,12.71,100,1,14.22,100,1,12.50,700,1,14.26,700,1,12.46,100,1,14.28,100,1,12.43,700,1,14.31,100,1,12.42,700,1,14.46,200,2,ARL,340704465
2533,2025-07-17T16:14:21.317261991Z,2025-07-17T16:14:21.317096752Z,160,2,1108,C,A,4,13.85,100,130,165239,283454878,13.11,100,1,13.49,15,1,12.98,200,2,13.50,100,1,12.96,2,1,13.51,15,1,12.86,100,1,13.74,2,1,12.73,100,1,14.22,100,1,12.71,100,1,14.26,700,1,12.50,700,1,14.28,100,1,12.46,100,1,14.31,100,1,12.43,700,1,14.46,200,2,12.42,700,1,14.47,200,2,ARL,339642033
2534,2025-07-17T16:14:21.317314136Z,2025-07-17T16:14:21.317148983Z,160,2,1108,A,A,4,13.77,100,130,165153,283454882,13.11,100,1,13.49,15,1,12.98,200,2,13.50,100,1,12.96,2,1,13.51,15,1,12.86,100,1,13.74,2,1,12.73,100,1,13.77,100,1,12.71,100,1,14.22,100,1,12.50,700,1,14.26,700,1,12.46,100,1,14.28,100,1,12.43,700,1,14.31,100,1,12.42,700,1,14.46,200,2,ARL,340705133
2535,2025-07-17T16:14:21.343294261Z,2025-07-17T16:14:21.343129166Z,160,2,1108,A,A,18,15.39,100,130,165095,283455758,13.11,100,1,13.49,15,1,12.98,200,2,13.50,100,1,12.96,2,1,13.51,15,1,12.86,100,1,13.74,2,1,12.73,100,1,13.77,100,1,12.71,100,1,14.22,100,1,12.50,700,1,14.26,700,1,12.46,100,1,14.28,100,1,12.43,700,1,14.31,100,1,12.42,700,1,14.46,200,2,ARL,340706373
2536,2025-07-17T16:14:21.343307836Z,2025-07-17T16:14:21.343142096Z,160,2,1108,C,A,20,15.67,100,130,165740,283455759,13.11,100,1,13.49,15,1,12.98,200,2,13.50,100,1,12.96,2,1,13.51,15,1,12.86,100,1,13.74,2,1,12.73,100,1,13.77,100,1,12.71,100,1,14.22,100,1,12.50,700,1,14.26,700,1,12.46,100,1,14.28,100,1,12.43,700,1,14.31,100,1,12.42,700,1,14.46,200,2,ARL,339202065
2537,2025-07-17T16:14:36.523553349Z,2025-07-17T16:14:36.523382949Z,160,2,1108,C,A,0,13.49,15,128,170400,283655411,13.11,100,1,13.50,100,1,12.98,200,2,13.51,15,1,12.96,2,1,13.74,2,1,12.86,100,1,13.77,100,1,12.73,100,1,14.22,100,1,12.71,100,1,14.26,700,1,12.50,700,1,14.28,100,1,12.46,100,1,14.31,100,1,12.43,700,1,14.46,200,2,12.42,700,1,14.47,200,2,ARL,340664453
2538,2025-07-17T16:14:36.523730500Z,2025-07-17T16:14:36.523564373Z,160,2,1108,C,A,1,13.51,15,128,166127,283655455,13.11,100,1,13.50,100,1,12.98,200,2,13.74,2,1,12.96,2,1,13.77,100,1,12.86,100,1,14.22,100,1,12.73,100,1,14.26,700,1,12.71,100,1,14.28,100,1,12.50,700,1,14.31,100,1,12.46,100,1,14.46,200,2,12.43,700,1,14.47,200,2,12.42,700,1,14.48,700,1,ARL,340526285
2539,2025-07-17T16:14:36.523862340Z,2025-07-17T16:14:36.523696080Z,160,2,1108,A,A,0,13.50,99,128,166260,283655477,13.11,100,1,13.50,199,2,12.98,200,2,13.74,2,1,12.96,2,1,13.77,100,1,12.86,100,1,14.22,100,1,12.73,100,1,14.26,700,1,12.71,100,1,14.28,100,1,12.50,700,1,14.31,100,1,12.46,100,1,14.46,200,2,12.43,700,1,14.47,200,2,12.42,700,1,14.48,700,1,ARL,340971661
2540,2025-07-17T16:14:52.280593678Z,2025-07-17T16:14:52.280428336Z,160,2,1108,C,A,0,13.50,99,130,165342,283870929,13.11,100,1,13.50,100,1,12.98,200,2,13.74,2,1,12.96,2,1,13.77,100,1,12.86,100,1,14.22,100,1,12.73,100,1,14.26,700,1,12.71,100,1,14.28,100,1,12.50,700,1,14.31,100,1,12.46,100,1,14.46,200,2,12.43,700,1,14.47,200,2,12.42,700,1,14.48,700,1,ARL,340971661
2541,2025-07-17T16:14:52.297037125Z,2025-07-17T16:14:52.296871817Z,160,2,1108,A,A,0,13.48,15,130,165308,283871393,13.11,100,1,13.48,15,1,12.98,200,2,13.50,100,1,12.96,2,1,13.74,2,1,12.86,100,1,13.77,100,1,12.73,100,1,14.22,100,1,12.71,100,1,14.26,700,1,12.50,700,1,14.28,100,1,12.46,100,1,14.31,100,1,12.43,700,1,14.46,200,2,12.42,700,1,14.47,200,2,ARL,341248825
2542,2025-07-17T16:14:52.828721867Z,2025-07-17T16:14:52.828556785Z,160,2,1108,C,A,0,13.48,15,130,165082,283875146,13.11,100,1,13.50,100,1,12.98,200,2,13.74,2,1,12.96,2,1,13.77,100,1,12.86,100,1,14.22,100,1,12.73,100,1,14.26,700,1,12.71,100,1,14.28,100,1,12.50,700,1,14.31,100,1,12.46,100,1,14.46,200,2,12.43,700,1,14.47,200,2,12.42,700,1,14.48,700,1,ARL,341248825
2543,2025-07-17T16:14:52.829033713Z,2025-07-17T16:14:52.828868258Z,160,2,1108,A,A,0,13.50,99,130,165455,283875150,13.11,100,1,13.50,199,2,12.98,200,2,13.74,2,1,12.96,2,1,13.77,100,1,12.86,100,1,14.22,100,1,12.73,100,1,14.26,700,1,12.71,100,1,14.28,100,1,12.50,700,1,14.31,100,1,12.46,100,1,14.46,200,2,12.43,700,1,14.47,200,2,12.42,700,1,14.48,700,1,ARL,341253573
2544,2025-07-17T16:15:16.987369971Z,2025-07-17T16:15:16.987204735Z,160,2,1108,C,A,0,13.50,99,130,165236,284194889,13.11,100,1,13.50,100,1,12.98,200,2,13.74,2,1,12.96,2,1,13.77,100,1,12.86,100,1,14.22,100,1,12.73,100,1,14.26,700,1,12.71,100,1,14.28,100,1,12.50,700,1,14.31,100,1,12.46,100,1,14.46,200,2,12.43,700,1,14.47,200,2,12.42,700,1,14.48,700,1,ARL,341253573
2545,2025-07-17T16:15:16.987414675Z,2025-07-17T16:15:16.987249289Z,160,2,1108,C,A,0,13.50,100,130,165386,284194891,13.11,100,1,13.74,2,1,12.98,200,2,13.77,100,1,12.96,2,1,14.22,100,1,12.86,100,1,14.26,700,1,12.73,100,1,14.28,100,1,12.71,100,1,14.31,100,1,12.50,700,1,14.46,200,2,12.46,100,1,14.47,200,2,12.43,700,1,14.48,700,1,12.42,700,1,14.49,100,1,ARL,340704401
2546,2025-07-17T16:15:16.987689493Z,2025-07-17T16:15:16.987524101Z,160,2,1108,C,A,3,14.26,700,130,165392,284194901,13.11,100,1,13.74,2,1,12.98,200,2,13.77,100,1,12.96,2,1,14.22,100,1,12.86,100,1,14.28,100,1,12.73,100,1,14.31,100,1,12.71,100,1,14.46,200,2,12.50,700,1,14.47,200,2,12.46,100,1,14.48,700,1,12.43,700,1,14.49,100,1,12.42,700,1,14.54,700,1,ARL,339716321
2547,2025-07-17T16:15:16.987744468Z,2025-07-17T16:15:16.987579177Z,160,2,1108,A,A,5,14.46,700,130,165291,284194908,13.11,100,1,13.74,2,1,12.98,200,2,13.77,100,1,12.96,2,1,14.22,100,1,12.86,100,1,14.28,100,1,12.73,100,1,14.31,100,1,12.71,100,1,14.46,900,3,12.50,700,1,14.47,200,2,12.46,100,1,14.48,700,1,12.43,700,1,14.49,100,1,12.42,700,1,14.54,700,1,ARL,341661841
2548,2025-07-17T16:15:16.987772549Z,2025-07-17T16:15:16.987607468Z,160,2,1108,A,A,16,15.70,100,130,165081,284194910,13.11,100,1,13.74,2,1,12.98,200,2,13.77,100,1,12.96,2,1,14.22,100,1,12.86,100,1,14.28,100,1,12.73,100,1,14.31,100,1,12.71,100,1,14.46,900,3,12.50,700,1,14.47,200,2,12.46,100,1,14.48,700,1,12.43,700,1,14.49,100,1,12.42,700,1,14.54,700,1,ARL,341661849
2549,2025-07-17T16:15:16.987786087Z,2025-07-17T16:15:16.987620573Z,160,2,1108,C,A,14,15.39,100,130,165514,284194911,13.11,100,1,13.74,2,1,12.98,200,2,13.77,100,1,12.96,2,1,14.22,100,1,12.86,100,1,14.28,100,1,12.73,100,1,14.31,100,1,12.71,100,1,14.46,900,3,12.50,700,1,14.47,200,2,12.46,100,1,14.48,700,1,12.43,700,1,14.49,100,1,12.42,700,1,14.54,700,1,ARL,340706373
2550,2025-07-17T16:15:16.988145770Z,2025-07-17T16:15:16.987980299Z,160,2,1108,C,A,10,14.55,100,0,165471,284194935,13.11,100,1,13.74,2,1,12.98,200,2,13.77,100,1,12.96,2,1,14.22,100,1,12.86,100,1,14.28,100,1,12.73,100,1,14.31,100,1,12.71,100,1,14.46,900,3,12.50,700,1,14.47,200,2,12.46,100,1,14.48,700,1,12.43,700,1,14.49,100,1,12.42,700,1,14.54,700,1,ARL,340704465
2551,2025-07-17T16:15:16.988145770Z,2025-07-17T16:15:16.987980299Z,160,2,1108,A,A,11,14.60,100,130,165471,284194935,13.11,100,1,13.74,2,1,12.98,200,2,13.77,100,1,12.96,2,1,14.22,100,1,12.86,100,1,14.28,100,1,12.73,100,1,14.31,100,1,12.71,100,1,14.46,900,3,12.50,700,1,14.47,200,2,12.46,100,1,14.48,700,1,12.43,700,1,14.49,100,1,12.42,700,1,14.54,700,1,ARL,341661869
2552,2025-07-17T16:15:16.988410269Z,2025-07-17T16:15:16.988244795Z,160,2,1108,C,A,6,14.47,100,0,165474,284194952,13.11,100,1,13.74,2,1,12.98,200,2,13.77,100,1,12.96,2,1,14.22,100,1,12.86,100,1,14.28,100,1,12.73,100,1,14.31,100,1,12.71,100,1,14.46,900,3,12.50,700,1,14.47,100,1,12.46,100,1,14.48,700,1,12.43,700,1,14.49,100,1,12.42,700,1,14.54,700,1,ARL,340527969
2553,2025-07-17T16:15:16.988410269Z,2025-07-17T16:15:16.988244795Z,160,2,1108,A,A,12,14.74,100,130,165474,284194952,13.11,100,1,13.74,2,1,12.98,200,2,13.77,100,1,12.96,2,1,14.22,100,1,12.86,100,1,14.28,100,1,12.73,100,1,14.31,100,1,12.71,100,1,14.46,900,3,12.50,700,1,14.47,100,1,12.46,100,1,14.48,700,1,12.43,700,1,14.49,100,1,12.42,700,1,14.54,700,1,ARL,341661877
2554,2025-07-17T16:15:16.989313102Z,2025-07-17T16:15:16.989147294Z,160,2,1108,C,A,15,15.58,100,0,165808,284195117,13.11,100,1,13.74,2,1,12.98,200,2,13.77,100,1,12.96,2,1,14.22,100,1,12.86,100,1,14.28,100,1,12.73,100,1,14.31,100,1,12.71,100,1,14.46,900,3,12.50,700,1,14.47,100,1,12.46,100,1,14.48,700,1,12.43,700,1,14.49,100,1,12.42,700,1,14.54,700,1,ARL,340047805
2555,2025-07-17T16:15:16.989313102Z,2025-07-17T16:15:16.989147294Z,160,2,1108,A,A,16,15.84,100,130,165808,284195117,13.11,100,1,13.74,2,1,12.98,200,2,13.77,100,1,12.96,2,1,14.22,100,1,12.86,100,1,14.28,100,1,12.73,100,1,14.31,100,1,12.71,100,1,14.46,900,3,12.50,700,1,14.47,100,1,12.46,100,1,14.48,700,1,12.43,700,1,14.49,100,1,12.42,700,1,14.54,700,1,ARL,341661893
2556,2025-07-17T16:15:16.989763697Z,2025-07-17T16:15:16.989598095Z,160,2,1108,C,A,19,17.23,100,0,165602,284195176,13.11,100,1,13.74,2,1,12.98,200,2,13.77,100,1,12.96,2,1,14.22,100,1,12.86,100,1,14.28,100,1,12.73,100,1,14.31,100,1,12.71,100,1,14.46,900,3,12.50,700,1,14.47,100,1,12.46,100,1,14.48,700,1,12.43,700,1,14.49,100,1,12.42,700,1,14.54,700,1,ARL,339937293
2557,2025-07-17T16:15:16.989763697Z,2025-07-17T16:15:16.989598095Z,160,2,1108,A,A,19,17.49,100,130,165602,284195176,13.11,100,1,13.74,2,1,12.98,200,2,13.77,100,1,12.96,2,1,14.22,100,1,12.86,100,1,14.28,100,1,12.73,100,1,14.31,100,1,12.71,100,1,14.46,900,3,12.50,700,1,14.47,100,1,12.46,100,1,14.48,700,1,12.43,700,1,14.49,100,1,12.42,700,1,14.54,700,1,ARL,341661901
2558,2025-07-17T16:15:16.989886697Z,2025-07-17T16:15:16.989720957Z,160,2,1108,C,A,6,14.47,100,0,165740,284195185,13.11,100,1,13.74,2,1,12.98,200,2,13.77,100,1,12.96,2,1,14.22,100,1,12.86,100,1,14.28,100,1,12.73,100,1,14.31,100,1,12.71,100,1,14.46,900,3,12.50,700,1,14.48,700,1,12.46,100,1,14.49,100,1,12.43,700,1,14.54,700,1,12.42,700,1,14.56,700,1,ARL,340528121
2559,2025-07-17T16:15:16.989886697Z,2025-07-17T16:15:16.989720957Z,160,2,1108,A,A,11,14.74,100,130,165740,284195185,13.11,100,1,13.74,2,1,12.98,200,2,13.77,100,1,12.96,2,1,14.22,100,1,12.86,100,1,14.28,100,1,12.73,100,1,14.31,100,1,12.71,100,1,14.46,900,3,12.50,700,1,14.48,700,1,12.46,100,1,14.49,100,1,12.43,700,1,14.54,700,1,12.42,700,1,14.56,700,1,ARL,341661905
2560,2025-07-17T16:15:16.992804347Z,2025-07-17T16:15:16.992638952Z,160,2,1108,C,A,4,14.31,100,130,165395,284195309,13.11,100,1,13.74,2,1,12.98,200,2,13.77,100,1,12.96,2,1,14.22,100,1,12.86,100,1,14.28,100,1,12.73,100,1,14.46,900,3,12.71,100,1,14.48,700,1,12.50,700,1,14.49,100,1,12.46,100,1,14.54,700,1,12.43,700,1,14.56,700,1,12.42,700,1,14.60,100,1,ARL,340529021
2561,2025-07-17T16:15:16.992941967Z,2025-07-17T16:15:16.992776612Z,160,2,1108,A,A,8,14.56,100,130,165355,284195310,13.11,100,1,13.74,2,1,12.98,200,2,13.77,100,1,12.96,2,1,14.22,100,1,12.86,100,1,14.28,100,1,12.73,100,1,14.46,900,3,12.71,100,1,14.48,700,1,12.50,700,1,14.49,100,1,12.46,100,1,14.54,700,1,12.43,700,1,14.56,800,2,12.42,700,1,14.60,100,1,ARL,341661985
2562,2025-07-17T16:15:17.000588174Z,2025-07-17T16:15:17.000422944Z,160,2,1108,C,A,1,13.77,100,130,165230,284195454,13.11,100,1,13.74,2,1,12.98,200,2,14.22,100,1,12.96,2,1,14.28,100,1,12.86,100,1,14.46,900,3,12.73,100,1,14.48,700,1,12.71,100,1,14.49,100,1,12.50,700,1,14.54,700,1,12.46,100,1,14.56,800,2,12.43,700,1,14.60,100,1,12.42,700,1,14.74,200,2,ARL,340705133
2563,2025-07-17T16:15:17.000621056Z,2025-07-17T16:15:17.000456046Z,160,2,1108,C,A,3,14.46,700,130,165010,284195456,13.11,100,1,13.74,2,1,12.98,200,2,14.22,100,1,12.96,2,1,14.28,100,1,12.86,100,1,14.46,200,2,12.73,100,1,14.48,700,1,12.71,100,1,14.49,100,1,12.50,700,1,14.54,700,1,12.46,100,1,14.56,800,2,12.43,700,1,14.60,100,1,12.42,700,1,14.74,200,2,ARL,341661841
2564,2025-07-17T16:15:17.000640033Z,2025-07-17T16:15:17.000474862Z,160,2,1108,A,A,1,14.05,100,130,165171,284195458,13.11,100,1,13.74,2,1,12.98,200,2,14.05,100,1,12.96,2,1,14.22,100,1,12.86,100,1,14.28,100,1,12.73,100,1,14.46,200,2,12.71,100,1,14.48,700,1,12.50,700,1,14.49,100,1,12.46,100,1,14.54,700,1,12.43,700,1,14.56,800,2,12.42,700,1,14.60,100,1,ARL,341662085
2565,2025-07-17T16:15:17.001323406Z,2025-07-17T16:15:17.001158038Z,160,2,1108,C,A,3,14.28,100,130,165368,284195476,13.11,100,1,13.74,2,1,12.98,200,2,14.05,100,1,12.96,2,1,14.22,100,1,12.86,100,1,14.46,200,2,12.73,100,1,14.48,700,1,12.71,100,1,14.49,100,1,12.50,700,1,14.54,700,1,12.46,100,1,14.56,800,2,12.43,700,1,14.60,100,1,12.42,700,1,14.74,200,2,ARL,339358333
2566,2025-07-17T16:15:17.001687312Z,2025-07-17T16:15:17.001522171Z,160,2,1108,A,A,8,14.60,100,130,165141,284195477,13.11,100,1,13.74,2,1,12.98,200,2,14.05,100,1,12.96,2,1,14.22,100,1,12.86,100,1,14.46,200,2,12.73,100,1,14.48,700,1,12.71,100,1,14.49,100,1,12.50,700,1,14.54,700,1,12.46,100,1,14.56,800,2,12.43,700,1,14.60,200,2,12.42,700,1,14.74,200,2,ARL,341662113
2567,2025-07-17T16:15:17.002229963Z,2025-07-17T16:15:17.002064284Z,160,2,1108,C,A,9,14.74,100,0,165679,284195479,13.11,100,1,13.74,2,1,12.98,200,2,14.05,100,1,12.96,2,1,14.22,100,1,12.86,100,1,14.46,200,2,12.73,100,1,14.48,700,1,12.71,100,1,14.49,100,1,12.50,700,1,14.54,700,1,12.46,100,1,14.56,800,2,12.43,700,1,14.60,200,2,12.42,700,1,14.74,100,1,ARL,341661905
2568,2025-07-17T16:15:17.002229963Z,2025-07-17T16:15:17.002064284Z,160,2,1108,A,A,10,14.96,100,130,165679,284195479,13.11,100,1,13.74,2,1,12.98,200,2,14.05,100,1,12.96,2,1,14.22,100,1,12.86,100,1,14.46,200,2,12.73,100,1,14.48,700,1,12.71,100,1,14.49,100,1,12.50,700,1,14.54,700,1,12.46,100,1,14.56,800,2,12.43,700,1,14.60,200,2,12.42,700,1,14.74,100,1,ARL,341662117
2569,2025-07-17T16:15:17.002790290Z,2025-07-17T16:15:17.002625119Z,160,2,1108,C,A,17,17.49,100,0,165171,284195482,13.11,100,1,13.74,2,1,12.98,200,2,14.05,100,1,12.96,2,1,14.22,100,1,12.86,100,1,14.46,200,2,12.73,100,1,14.48,700,1,12.71,100,1,14.49,100,1,12.50,700,1,14.54,700,1,12.46,100,1,14.56,800,2,12.43,700,1,14.60,200,2,12.42,700,1,14.74,100,1,ARL,341661901
2570,2025-07-17T16:15:17.002790290Z,2025-07-17T16:15:17.002625119Z,160,2,1108,A,A,17,17.76,100,130,165171,284195482,13.11,100,1,13.74,2,1,12.98,200,2,14.05,100,1,12.96,2,1,14.22,100,1,12.86,100,1,14.46,200,2,12.73,100,1,14.48,700,1,12.71,100,1,14.49,100,1,12.50,700,1,14.54,700,1,12.46,100,1,14.56,800,2,12.43,700,1,14.60,200,2,12.42,700,1,14.74,100,1,ARL,341662125
2571,2025-07-17T16:15:17.003246802Z,2025-07-17T16:15:17.003081581Z,160,2,1108,C,A,9,14.74,100,0,165221,284195486,13.11,100,1,13.74,2,1,12.98,200,2,14.05,100,1,12.96,2,1,14.22,100,1,12.86,100,1,14.46,200,2,12.73,100,1,14.48,700,1,12.71,100,1,14.49,100,1,12.50,700,1,14.54,700,1,12.46,100,1,14.56,800,2,12.43,700,1,14.60,200,2,12.42,700,1,14.96,100,1,ARL,341661877
2572,2025-07-17T16:15:17.003246802Z,2025-07-17T16:15:17.003081581Z,160,2,1108,A,A,9,14.96,100,130,165221,284195486,13.11,100,1,13.74,2,1,12.98,200,2,14.05,100,1,12.96,2,1,14.22,100,1,12.86,100,1,14.46,200,2,12.73,100,1,14.48,700,1,12.71,100,1,14.49,100,1,12.50,700,1,14.54,700,1,12.46,100,1,14.56,800,2,12.43,700,1,14.60,200,2,12.42,700,1,14.96,200,2,ARL,341662133
2573,2025-07-17T16:15:17.003381863Z,2025-07-17T16:15:17.003216492Z,160,2,1108,C,A,13,15.84,100,0,165371,284195487,13.11,100,1,13.74,2,1,12.98,200,2,14.05,100,1,12.96,2,1,14.22,100,1,12.86,100,1,14.46,200,2,12.73,100,1,14.48,700,1,12.71,100,1,14.49,100,1,12.50,700,1,14.54,700,1,12.46,100,1,14.56,800,2,12.43,700,1,14.60,200,2,12.42,700,1,14.96,200,2,ARL,341661893
2574,2025-07-17T16:15:17.003381863Z,2025-07-17T16:15:17.003216492Z,160,2,1108,A,A,13,16.08,100,130,165371,284195487,13.11,100,1,13.74,2,1,12.98,200,2,14.05,100,1,12.96,2,1,14.22,100,1,12.86,100,1,14.46,200,2,12.73,100,1,14.48,700,1,12.71,100,1,14.49,100,1,12.50,700,1,14.54,700,1,12.46,100,1,14.56,800,2,12.43,700,1,14.60,200,2,12.42,700,1,14.96,200,2,ARL,341662137
2575,2025-07-17T16:15:17.003874553Z,2025-07-17T16:15:17.003708485Z,160,2,1108,C,A,10,15.04,100,0,166068,284195498,13.11,100,1,13.74,2,1,12.98,200,2,14.05,100,1,12.96,2,1,14.22,100,1,12.86,100,1,14.46,200,2,12.73,100,1,14.48,700,1,12.71,100,1,14.49,100,1,12.50,700,1,14.54,700,1,12.46,100,1,14.56,800,2,12.43,700,1,14.60,200,2,12.42,700,1,14.96,200,2,ARL,339358349
2576,2025-07-17T16:15:17.003874553Z,2025-07-17T16:15:17.003708485Z,160,2,1108,A,A,12,15.38,100,130,166068,284195498,13.11,100,1,13.74,2,1,12.98,200,2,14.05,100,1,12.96,2,1,14.22,100,1,12.86,100,1,14.46,200,2,12.73,100,1,14.48,700,1,12.71,100,1,14.49,100,1,12.50,700,1,14.54,700,1,12.46,100,1,14.56,800,2,12.43,700,1,14.60,200,2,12.42,700,1,14.96,200,2,ARL,341662145
2577,2025-07-17T16:15:17.003883470Z,2025-07-17T16:15:17.003717832Z,160,2,1108,C,A,10,15.04,100,0,165638,284195499,13.11,100,1,13.74,2,1,12.98,200,2,14.05,100,1,12.96,2,1,14.22,100,1,12.86,100,1,14.46,200,2,12.73,100,1,14.48,700,1,12.71,100,1,14.49,100,1,12.50,700,1,14.54,700,1,12.46,100,1,14.56,800,2,12.43,700,1,14.60,200,2,12.42,700,1,14.96,200,2,ARL,339359357
2578,2025-07-17T16:15:17.003883470Z,2025-07-17T16:15:17.003717832Z,160,2,1108,A,A,11,15.38,100,130,165638,284195499,13.11,100,1,13.74,2,1,12.98,200,2,14.05,100,1,12.96,2,1,14.22,100,1,12.86,100,1,14.46,200,2,12.73,100,1,14.48,700,1,12.71,100,1,14.49,100,1,12.50,700,1,14.54,700,1,12.46,100,1,14.56,800,2,12.43,700,1,14.60,200,2,12.42,700,1,14.96,200,2,ARL,341662149
2579,2025-07-17T16:15:17.019567564Z,2025-07-17T16:15:17.019402521Z,160,2,1108,C,A,1,14.05,100,130,165043,284195602,13.11,100,1,13.74,2,1,12.98,200,2,14.22,100,1,12.96,2,1,14.46,200,2,12.86,100,1,14.48,700,1,12.73,100,1,14.49,100,1,12.71,100,1,14.54,700,1,12.50,700,1,14.56,800,2,12.46,100,1,14.60,200,2,12.43,700,1,14.96,200,2,12.42,700,1,15.30,100,1,ARL,341662085
2580,2025-07-17T16:15:17.019617602Z,2025-07-17T16:15:17.019452245Z,160,2,1108,A,A,2,14.26,100,130,165357,284195603,13.11,100,1,13.74,2,1,12.98,200,2,14.22,100,1,12.96,2,1,14.26,100,1,12.86,100,1,14.46,200,2,12.73,100,1,14.48,700,1,12.71,100,1,14.49,100,1,12.50,700,1,14.54,700,1,12.46,100,1,14.56,800,2,12.43,700,1,14.60,200,2,12.42,700,1,14.96,200,2,ARL,341662313
2581,2025-07-17T16:15:17.037261626Z,2025-07-17T16:15:17.037096157Z,160,2,1108,C,A,8,14.60,100,0,165469,284195665,13.11,100,1,13.74,2,1,12.98,200,2,14.22,100,1,12.96,2,1,14.26,100,1,12.86,100,1,14.46,200,2,12.73,100,1,14.48,700,1,12.71,100,1,14.49,100,1,12.50,700,1,14.54,700,1,12.46,100,1,14.56,800,2,12.43,700,1,14.60,100,1,12.42,700,1,14.96,200,2,ARL,341661869
2582,2025-07-17T16:15:17.037261626Z,2025-07-17T16:15:17.037096157Z,160,2,1108,A,A,10,15.06,100,130,165469,284195665,13.11,100,1,13.74,2,1,12.98,200,2,14.22,100,1,12.96,2,1,14.26,100,1,12.86,100,1,14.46,200,2,12.73,100,1,14.48,700,1,12.71,100,1,14.49,100,1,12.50,700,1,14.54,700,1,12.46,100,1,14.56,800,2,12.43,700,1,14.60,100,1,12.42,700,1,14.96,200,2,ARL,341662429
2583,2025-07-17T16:15:17.049066370Z,2025-07-17T16:15:17.048901142Z,160,2,1108,A,A,1,13.75,100,130,165228,284196195,13.11,100,1,13.74,2,1,12.98,200,2,13.75,100,1,12.96,2,1,14.22,100,1,12.86,100,1,14.26,100,1,12.73,100,1,14.46,200,2,12.71,100,1,14.48,700,1,12.50,700,1,14.49,100,1,12.46,100,1,14.54,700,1,12.43,700,1,14.56,800,2,12.42,700,1,14.60,100,1,ARL,341663101
2584,2025-07-17T16:15:17.049108554Z,2025-07-17T16:15:17.048943087Z,160,2,1108,A,A,10,14.68,700,130,165467,284196196,13.11,100,1,13.74,2,1,12.98,200,2,13.75,100,1,12.96,2,1,14.22,100,1,12.86,100,1,14.26,100,1,12.73,100,1,14.46,200,2,12.71,100,1,14.48,700,1,12.50,700,1,14.49,100,1,12.46,100,1,14.54,700,1,12.43,700,1,14.56,800,2,12.42,700,1,14.60,100,1,ARL,341663105
2585,2025-07-17T16:15:17.050812161Z,2025-07-17T16:15:17.050646751Z,160,2,1108,C,A,11,14.96,100,0,165410,284196235,13.11,100,1,13.74,2,1,12.98,200,2,13.75,100,1,12.96,2,1,14.22,100,1,12.86,100,1,14.26,100,1,12.73,100,1,14.46,200,2,12.71,100,1,14.48,700,1,12.50,700,1,14.49,100,1,12.46,100,1,14.54,700,1,12.43,700,1,14.56,800,2,12.42,700,1,14.60,100,1,ARL,341662133
2586,2025-07-17T16:15:17.050812161Z,2025-07-17T16:15:17.050646751Z,160,2,1108,A,A,11,14.72,100,130,165410,284196235,13.11,100,1,13.74,2,1,12.98,200,2,13.75,100,1,12.96,2,1,14.22,100,1,12.86,100,1,14.26,100,1,12.73,100,1,14.46,200,2,12.71,100,1,14.48,700,1,12.50,700,1,14.49,100,1,12.46,100,1,14.54,700,1,12.43,700,1,14.56,800,2,12.42,700,1,14.60,100,1,ARL,341663261
2587,2025-07-17T16:15:17.051644859Z,2025-07-17T16:15:17.051479522Z,160,2,1108,C,A,19,17.76,100,0,165337,284196242,13.11,100,1,13.74,2,1,12.98,200,2,13.75,100,1,12.96,2,1,14.22,100,1,12.86,100,1,14.26,100,1,12.73,100,1,14.46,200,2,12.71,100,1,14.48,700,1,12.50,700,1,14.49,100,1,12.46,100,1,14.54,700,1,12.43,700,1,14.56,800,2,12.42,700,1,14.60,100,1,ARL,341662125
2588,2025-07-17T16:15:17.051644859Z,2025-07-17T16:15:17.051479522Z,160,2,1108,A,A,19,17.47,100,130,165337,284196242,13.11,100,1,13.74,2,1,12.98,200,2,13.75,100,1,12.96,2,1,14.22,100,1,12.86,100,1,14.26,100,1,12.73,100,1,14.46,200,2,12.71,100,1,14.48,700,1,12.50,700,1,14.49,100,1,12.46,100,1,14.54,700,1,12.43,700,1,14.56,800,2,12.42,700,1,14.60,100,1,ARL,341663289
2589,2025-07-17T16:15:17.054159307Z,2025-07-17T16:15:17.053993491Z,160,2,1108,C,A,17,16.08,100,0,165816,284196273,13.11,100,1,13.74,2,1,12.98,200,2,13.75,100,1,12.96,2,1,14.22,100,1,12.86,100,1,14.26,100,1,12.73,100,1,14.46,200,2,12.71,100,1,14.48,700,1,12.50,700,1,14.49,100,1,12.46,100,1,14.54,700,1,12.43,700,1,14.56,800,2,12.42,700,1,14.60,100,1,ARL,341662137
2590,2025-07-17T16:15:17.054159307Z,2025-07-17T16:15:17.053993491Z,160,2,1108,A,A,17,15.82,100,130,165816,284196273,13.11,100,1,13.74,2,1,12.98,200,2,13.75,100,1,12.96,2,1,14.22,100,1,12.86,100,1,14.26,100,1,12.73,100,1,14.46,200,2,12.71,100,1,14.48,700,1,12.50,700,1,14.49,100,1,12.46,100,1,14.54,700,1,12.43,700,1,14.56,800,2,12.42,700,1,14.60,100,1,ARL,341663317
2591,2025-07-17T16:15:17.059504149Z,2025-07-17T16:15:17.059338704Z,160,2,1108,C,A,3,14.26,100,130,165445,284196314,13.11,100,1,13.74,2,1,12.98,200,2,13.75,100,1,12.96,2,1,14.22,100,1,12.86,100,1,14.46,200,2,12.73,100,1,14.48,700,1,12.71,100,1,14.49,100,1,12.50,700,1,14.54,700,1,12.46,100,1,14.56,800,2,12.43,700,1,14.60,100,1,12.42,700,1,14.68,700,1,ARL,341662313
2592,2025-07-17T16:15:17.059552653Z,2025-07-17T16:15:17.059387360Z,160,2,1108,A,A,2,14.03,100,130,165293,284196315,13.11,100,1,13.74,2,1,12.98,200,2,13.75,100,1,12.96,2,1,14.03,100,1,12.86,100,1,14.22,100,1,12.73,100,1,14.46,200,2,12.71,100,1,14.48,700,1,12.50,700,1,14.49,100,1,12.46,100,1,14.54,700,1,12.43,700,1,14.56,800,2,12.42,700,1,14.60,100,1,ARL,341663401
2593,2025-07-17T16:15:17.084101480Z,2025-07-17T16:15:17.083936164Z,160,2,1108,C,A,12,14.96,100,0,165316,284196410,13.11,100,1,13.74,2,1,12.98,200,2,13.75,100,1,12.96,2,1,14.03,100,1,12.86,100,1,14.22,100,1,12.73,100,1,14.46,200,2,12.71,100,1,14.48,700,1,12.50,700,1,14.49,100,1,12.46,100,1,14.54,700,1,12.43,700,1,14.56,800,2,12.42,700,1,14.60,100,1,ARL,341662117
2594,2025-07-17T16:15:17.084101480Z,2025-07-17T16:15:17.083936164Z,160,2,1108,A,A,11,14.72,100,130,165316,284196410,13.11,100,1,13.74,2,1,12.98,200,2,13.75,100,1,12.96,2,1,14.03,100,1,12.86,100,1,14.22,100,1,12.73,100,1,14.46,200,2,12.71,100,1,14.48,700,1,12.50,700,1,14.49,100,1,12.46,100,1,14.54,700,1,12.43,700,1,14.56,800,2,12.42,700,1,14.60,100,1,ARL,341663737
2595,2025-07-17T16:15:17.087853488Z,2025-07-17T16:15:17.087688271Z,160,2,1108,C,A,12,15.06,100,0,165217,284196429,13.11,100,1,13.74,2,1,12.98,200,2,13.75,100,1,12.96,2,1,14.03,100,1,12.86,100,1,14.22,100,1,12.73,100,1,14.46,200,2,12.71,100,1,14.48,700,1,12.50,700,1,14.49,100,1,12.46,100,1,14.54,700,1,12.43,700,1,14.56,800,2,12.42,700,1,14.60,100,1,ARL,341662429
2596,2025-07-17T16:15:17.087853488Z,2025-07-17T16:15:17.087688271Z,160,2,1108,A,A,12,14.82,100,130,165217,284196429,13.11,100,1,13.74,2,1,12.98,200,2,13.75,100,1,12.96,2,1,14.03,100,1,12.86,100,1,14.22,100,1,12.73,100,1,14.46,200,2,12.71,100,1,14.48,700,1,12.50,700,1,14.49,100,1,12.46,100,1,14.54,700,1,12.43,700,1,14.56,800,2,12.42,700,1,14.60,100,1,ARL,341663749
2597,2025-07-17T16:15:17.643818240Z,2025-07-17T16:15:17.643653020Z,160,2,1108,C,A,9,14.60,100,130,165220,284202090,13.11,100,1,13.74,2,1,12.98,200,2,13.75,100,1,12.96,2,1,14.03,100,1,12.86,100,1,14.22,100,1,12.73,100,1,14.46,200,2,12.71,100,1,14.48,700,1,12.50,700,1,14.49,100,1,12.46,100,1,14.54,700,1,12.43,700,1,14.56,800,2,12.42,700,1,14.68,700,1,ARL,341662113
2598,2025-07-17T16:15:17.644168944Z,2025-07-17T16:15:17.644003726Z,160,2,1108,A,A,4,14.36,100,130,165218,284202091,13.11,100,1,13.74,2,1,12.98,200,2,13.75,100,1,12.96,2,1,14.03,100,1,12.86,100,1,14.22,100,1,12.73,100,1,14.36,100,1,12.71,100,1,14.46,200,2,12.50,700,1,14.48,700,1,12.46,100,1,14.49,100,1,12.43,700,1,14.54,700,1,12.42,700,1,14.56,800,2,ARL,341671053
2599,2025-07-17T16:15:35.999140348Z,2025-07-17T16:15:35.998974923Z,160,2,1108,C,B,11,12.36,100,0,165425,284480502,13.11,100,1,13.74,2,1,12.98,200,2,13.75,100,1,12.96,2,1,14.03,100,1,12.86,100,1,14.22,100,1,12.73,100,1,14.36,100,1,12.71,100,1,14.46,200,2,12.50,700,1,14.48,700,1,12.46,100,1,14.49,100,1,12.43,700,1,14.54,700,1,12.42,700,1,14.56,800,2,ARL,336572057
2600,2025-07-17T16:15:35.999140348Z,2025-07-17T16:15:35.998974923Z,160,2,1108,A,B,13,12.22,100,130,165425,284480502,13.11,100,1,13.74,2,1,12.98,200,2,13.75,100,1,12.96,2,1,14.03,100,1,12.86,100,1,14.22,100,1,12.73,100,1,14.36,100,1,12.71,100,1,14.46,200,2,12.50,700,1,14.48,700,1,12.46,100,1,14.49,100,1,12.43,700,1,14.54,700,1,12.42,700,1,14.56,800,2,ARL,342029561
2601,2025-07-17T16:15:35.999762137Z,2025-07-17T16:15:35.999596382Z,160,2,1108,C,B,11,12.36,100,0,165755,284480519,13.11,100,1,13.74,2,1,12.98,200,2,13.75,100,1,12.96,2,1,14.03,100,1,12.86,100,1,14.22,100,1,12.73,100,1,14.36,100,1,12.71,100,1,14.46,200,2,12.50,700,1,14.48,700,1,12.46,100,1,14.49,100,1,12.43,700,1,14.54,700,1,12.42,700,1,14.56,800,2,ARL,336572069
2602,2025-07-17T16:15:35.999762137Z,2025-07-17T16:15:35.999596382Z,160,2,1108,A,B,12,12.22,100,130,165755,284480519,13.11,100,1,13.74,2,1,12.98,200,2,13.75,100,1,12.96,2,1,14.03,100,1,12.86,100,1,14.22,100,1,12.73,100,1,14.36,100,1,12.71,100,1,14.46,200,2,12.50,700,1,14.48,700,1,12.46,100,1,14.49,100,1,12.43,700,1,14.54,700,1,12.42,700,1,14.56,800,2,ARL,342029581
2603,2025-07-17T16:16:30.787448429Z,2025-07-17T16:16:30.787282866Z,160,2,1108,C,B,2,12.96,2,0,165563,285308466,13.11,100,1,13.74,2,1,12.98,200,2,13.75,100,1,12.86,100,1,14.03,100,1,12.73,100,1,14.22,100,1,12.71,100,1,14.36,100,1,12.50,700,1,14.46,200,2,12.46,100,1,14.48,700,1,12.43,700,1,14.49,100,1,12.42,700,1,14.54,700,1,12.37,700,1,14.56,800,2,ARL,339356397
2604,2025-07-17T16:16:30.787448429Z,2025-07-17T16:16:30.787282866Z,160,2,1108,A,B,1,13.03,2,130,165563,285308466,13.11,100,1,13.74,2,1,13.03,2,1,13.75,100,1,12.98,200,2,14.03,100,1,12.86,100,1,14.22,100,1,12.73,100,1,14.36,100,1,12.71,100,1,14.46,200,2,12.50,700,1,14.48,700,1,12.46,100,1,14.49,100,1,12.43,700,1,14.54,700,1,12.42,700,1,14.56,800,2,ARL,343084165
2605,2025-07-17T16:17:22.832948558Z,2025-07-17T16:17:22.832783132Z,160,2,1108,A,A,0,13.47,15,130,165426,286207282,13.11,100,1,13.47,15,1,13.03,2,1,13.74,2,1,12.98,200,2,13.75,100,1,12.86,100,1,14.03,100,1,12.73,100,1,14.22,100,1,12.71,100,1,14.36,100,1,12.50,700,1,14.46,200,2,12.46,100,1,14.48,700,1,12.43,700,1,14.49,100,1,12.42,700,1,14.54,700,1,ARL,344211173
2606,2025-07-17T16:17:23.620456421Z,2025-07-17T16:17:23.620290881Z,160,2,1108,C,A,2,13.75,100,0,165540,286219821,13.11,100,1,13.47,15,1,13.03,2,1,13.74,2,1,12.98,200,2,14.03,100,1,12.86,100,1,14.22,100,1,12.73,100,1,14.36,100,1,12.71,100,1,14.46,200,2,12.50,700,1,14.48,700,1,12.46,100,1,14.49,100,1,12.43,700,1,14.54,700,1,12.42,700,1,14.56,800,2,ARL,341663101
2607,2025-07-17T16:17:23.620456421Z,2025-07-17T16:17:23.620290881Z,160,2,1108,A,A,1,13.48,100,130,165540,286219821,13.11,100,1,13.47,15,1,13.03,2,1,13.48,100,1,12.98,200,2,13.74,2,1,12.86,100,1,14.03,100,1,12.73,100,1,14.22,100,1,12.71,100,1,14.36,100,1,12.50,700,1,14.46,200,2,12.46,100,1,14.48,700,1,12.43,700,1,14.49,100,1,12.42,700,1,14.54,700,1,ARL,344225341
2608,2025-07-17T16:17:23.621199578Z,2025-07-17T16:17:23.621034171Z,160,2,1108,C,A,5,14.36,100,130,165407,286219868,13.11,100,1,13.47,15,1,13.03,2,1,13.48,100,1,12.98,200,2,13.74,2,1,12.86,100,1,14.03,100,1,12.73,100,1,14.22,100,1,12.71,100,1,14.46,200,2,12.50,700,1,14.48,700,1,12.46,100,1,14.49,100,1,12.43,700,1,14.54,700,1,12.42,700,1,14.56,800,2,ARL,341671053
2609,2025-07-17T16:17:23.621205573Z,2025-07-17T16:17:23.621040069Z,160,2,1108,C,A,12,14.82,100,0,165504,286219869,13.11,100,1,13.47,15,1,13.03,2,1,13.48,100,1,12.98,200,2,13.74,2,1,12.86,100,1,14.03,100,1,12.73,100,1,14.22,100,1,12.71,100,1,14.46,200,2,12.50,700,1,14.48,700,1,12.46,100,1,14.49,100,1,12.43,700,1,14.54,700,1,12.42,700,1,14.56,800,2,ARL,341663749
2610,2025-07-17T16:17:23.621205573Z,2025-07-17T16:17:23.621040069Z,160,2,1108,A,A,8,14.53,100,130,165504,286219869,13.11,100,1,13.47,15,1,13.03,2,1,13.48,100,1,12.98,200,2,13.74,2,1,12.86,100,1,14.03,100,1,12.73,100,1,14.22,100,1,12.71,100,1,14.46,200,2,12.50,700,1,14.48,700,1,12.46,100,1,14.49,100,1,12.43,700,1,14.53,100,1,12.42,700,1,14.54,700,1,ARL,344225385
2611,2025-07-17T16:17:23.621387062Z,2025-07-17T16:17:23.621221535Z,160,2,1108,C,A,16,15.82,100,0,165527,286219879,13.11,100,1,13.47,15,1,13.03,2,1,13.48,100,1,12.98,200,2,13.74,2,1,12.86,100,1,14.03,100,1,12.73,100,1,14.22,100,1,12.71,100,1,14.46,200,2,12.50,700,1,14.48,700,1,12.46,100,1,14.49,100,1,12.43,700,1,14.53,100,1,12.42,700,1,14.54,700,1,ARL,341663317
2612,2025-07-17T16:17:23.621387062Z,2025-07-17T16:17:23.621221535Z,160,2,1108,A,A,15,15.51,100,130,165527,286219879,13.11,100,1,13.47,15,1,13.03,2,1,13.48,100,1,12.98,200,2,13.74,2,1,12.86,100,1,14.03,100,1,12.73,100,1,14.22,100,1,12.71,100,1,14.46,200,2,12.50,700,1,14.48,700,1,12.46,100,1,14.49,100,1,12.43,700,1,14.53,100,1,12.42,700,1,14.54,700,1,ARL,344225393
2613,2025-07-17T16:17:23.621555609Z,2025-07-17T16:17:23.621389325Z,160,2,1108,A,A,4,14.08,100,130,166284,286219881,13.11,100,1,13.47,15,1,13.03,2,1,13.48,100,1,12.98,200,2,13.74,2,1,12.86,100,1,14.03,100,1,12.73,100,1,14.08,100,1,12.71,100,1,14.22,100,1,12.50,700,1,14.46,200,2,12.46,100,1,14.48,700,1,12.43,700,1,14.49,100,1,12.42,700,1,14.53,100,1,ARL,344225397
2614,2025-07-17T16:17:23.621978089Z,2025-07-17T16:17:23.621812403Z,160,2,1108,C,A,15,15.38,100,0,165686,286219887,13.11,100,1,13.47,15,1,13.03,2,1,13.48,100,1,12.98,200,2,13.74,2,1,12.86,100,1,14.03,100,1,12.73,100,1,14.08,100,1,12.71,100,1,14.22,100,1,12.50,700,1,14.46,200,2,12.46,100,1,14.48,700,1,12.43,700,1,14.49,100,1,12.42,700,1,14.53,100,1,ARL,341662145
2615,2025-07-17T16:17:23.621978089Z,2025-07-17T16:17:23.621812403Z,160,2,1108,A,A,14,14.83,100,130,165686,286219887,13.11,100,1,13.47,15,1,13.03,2,1,13.48,100,1,12.98,200,2,13.74,2,1,12.86,100,1,14.03,100,1,12.73,100,1,14.08,100,1,12.71,100,1,14.22,100,1,12.50,700,1,14.46,200,2,12.46,100,1,14.48,700,1,12.43,700,1,14.49,100,1,12.42,700,1,14.53,100,1,ARL,344225405
2616,2025-07-17T16:17:23.622834183Z,2025-07-17T16:17:23.622668656Z,160,2,1108,C,A,13,14.72,100,0,165527,286219894,13.11,100,1,13.47,15,1,13.03,2,1,13.48,100,1,12.98,200,2,13.74,2,1,12.86,100,1,14.03,100,1,12.73,100,1,14.08,100,1,12.71,100,1,14.22,100,1,12.50,700,1,14.46,200,2,12.46,100,1,14.48,700,1,12.43,700,1,14.49,100,1,12.42,700,1,14.53,100,1,ARL,341663261
2617,2025-07-17T16:17:23.622834183Z,2025-07-17T16:17:23.622668656Z,160,2,1108,A,A,6,14.43,100,130,165527,286219894,13.11,100,1,13.47,15,1,13.03,2,1,13.48,100,1,12.98,200,2,13.74,2,1,12.86,100,1,14.03,100,1,12.73,100,1,14.08,100,1,12.71,100,1,14.22,100,1,12.50,700,1,14.43,100,1,12.46,100,1,14.46,200,2,12.43,700,1,14.48,700,1,12.42,700,1,14.49,100,1,ARL,344225449
2618,2025-07-17T16:17:23.623011421Z,2025-07-17T16:17:23.622845856Z,160,2,1108,C,A,12,14.56,100,0,165565,286219895,13.11,100,1,13.47,15,1,13.03,2,1,13.48,100,1,12.98,200,2,13.74,2,1,12.86,100,1,14.03,100,1,12.73,100,1,14.08,100,1,12.71,100,1,14.22,100,1,12.50,700,1,14.43,100,1,12.46,100,1,14.46,200,2,12.43,700,1,14.48,700,1,12.42,700,1,14.49,100,1,ARL,341661985
2619,2025-07-17T16:17:23.623011421Z,2025-07-17T16:17:23.622845856Z,160,2,1108,A,A,6,14.27,100,130,165565,286219895,13.11,100,1,13.47,15,1,13.03,2,1,13.48,100,1,12.98,200,2,13.74,2,1,12.86,100,1,14.03,100,1,12.73,100,1,14.08,100,1,12.71,100,1,14.22,100,1,12.50,700,1,14.27,100,1,12.46,100,1,14.43,100,1,12.43,700,1,14.46,200,2,12.42,700,1,14.48,700,1,ARL,344225453
2620,2025-07-17T16:17:23.623052802Z,2025-07-17T16:17:23.622887237Z,160,2,1108,C,A,23,17.47,100,0,165565,286219896,13.11,100,1,13.47,15,1,13.03,2,1,13.48,100,1,12.98,200,2,13.74,2,1,12.86,100,1,14.03,100,1,12.73,100,1,14.08,100,1,12.71,100,1,14.22,100,1,12.50,700,1,14.27,100,1,12.46,100,1,14.43,100,1,12.43,700,1,14.46,200,2,12.42,700,1,14.48,700,1,ARL,341663289
2621,2025-07-17T16:17:23.623052802Z,2025-07-17T16:17:23.622887237Z,160,2,1108,A,A,22,17.12,100,130,165565,286219896,13.11,100,1,13.47,15,1,13.03,2,1,13.48,100,1,12.98,200,2,13.74,2,1,12.86,100,1,14.03,100,1,12.73,100,1,14.08,100,1,12.71,100,1,14.22,100,1,12.50,700,1,14.27,100,1,12.46,100,1,14.43,100,1,12.43,700,1,14.46,200,2,12.42,700,1,14.48,700,1,ARL,344225457
2622,2025-07-17T16:17:23.624578699Z,2025-07-17T16:17:23.624413295Z,160,2,1108,C,A,18,15.38,100,0,165404,286219909,13.11,100,1,13.47,15,1,13.03,2,1,13.48,100,1,12.98,200,2,13.74,2,1,12.86,100,1,14.03,100,1,12.73,100,1,14.08,100,1,12.71,100,1,14.22,100,1,12.50,700,1,14.27,100,1,12.46,100,1,14.43,100,1,12.43,700,1,14.46,200,2,12.42,700,1,14.48,700,1,ARL,341662149
2623,2025-07-17T16:17:23.624578699Z,2025-07-17T16:17:23.624413295Z,160,2,1108,A,A,16,14.83,100,130,165404,286219909,13.11,100,1,13.47,15,1,13.03,2,1,13.48,100,1,12.98,200,2,13.74,2,1,12.86,100,1,14.03,100,1,12.73,100,1,14.08,100,1,12.71,100,1,14.22,100,1,12.50,700,1,14.27,100,1,12.46,100,1,14.43,100,1,12.43,700,1,14.46,200,2,12.42,700,1,14.48,700,1,ARL,344225485
2624,2025-07-17T16:17:23.624638111Z,2025-07-17T16:17:23.624472504Z,160,2,1108,C,A,15,14.72,100,0,165607,286219911,13.11,100,1,13.47,15,1,13.03,2,1,13.48,100,1,12.98,200,2,13.74,2,1,12.86,100,1,14.03,100,1,12.73,100,1,14.08,100,1,12.71,100,1,14.22,100,1,12.50,700,1,14.27,100,1,12.46,100,1,14.43,100,1,12.43,700,1,14.46,200,2,12.42,700,1,14.48,700,1,ARL,341663737
2625,2025-07-17T16:17:23.624638111Z,2025-07-17T16:17:23.624472504Z,160,2,1108,A,A,7,14.43,100,130,165607,286219911,13.11,100,1,13.47,15,1,13.03,2,1,13.48,100,1,12.98,200,2,13.74,2,1,12.86,100,1,14.03,100,1,12.73,100,1,14.08,100,1,12.71,100,1,14.22,100,1,12.50,700,1,14.27,100,1,12.46,100,1,14.43,200,2,12.43,700,1,14.46,200,2,12.42,700,1,14.48,700,1,ARL,344225489
2626,2025-07-17T16:17:23.627653611Z,2025-07-17T16:17:23.627488304Z,160,2,1108,C,A,3,14.03,100,130,165307,286219940,13.11,100,1,13.47,15,1,13.03,2,1,13.48,100,1,12.98,200,2,13.74,2,1,12.86,100,1,14.08,100,1,12.73,100,1,14.22,100,1,12.71,100,1,14.27,100,1,12.50,700,1,14.43,200,2,12.46,100,1,14.46,200,2,12.43,700,1,14.48,700,1,12.42,700,1,14.49,100,1,ARL,341663401
2627,2025-07-17T16:17:23.627704598Z,2025-07-17T16:17:23.627539425Z,160,2,1108,A,A,3,13.75,100,130,165173,286219941,13.11,100,1,13.47,15,1,13.03,2,1,13.48,100,1,12.98,200,2,13.74,2,1,12.86,100,1,13.75,100,1,12.73,100,1,14.08,100,1,12.71,100,1,14.22,100,1,12.50,700,1,14.27,100,1,12.46,100,1,14.43,200,2,12.43,700,1,14.46,200,2,12.42,700,1,14.48,700,1,ARL,344225533
2628,2025-07-17T16:17:23.653807815Z,2025-07-17T16:17:23.653641816Z,160,2,1108,A,A,17,15.37,100,130,165999,286220138,13.11,100,1,13.47,15,1,13.03,2,1,13.48,100,1,12.98,200,2,13.74,2,1,12.86,100,1,13.75,100,1,12.73,100,1,14.08,100,1,12.71,100,1,14.22,100,1,12.50,700,1,14.27,100,1,12.46,100,1,14.43,200,2,12.43,700,1,14.46,200,2,12.42,700,1,14.48,700,1,ARL,344225829
2629,2025-07-17T16:17:23.653821034Z,2025-07-17T16:17:23.653655443Z,160,2,1108,C,A,19,15.70,100,130,165591,286220139,13.11,100,1,13.47,15,1,13.03,2,1,13.48,100,1,12.98,200,2,13.74,2,1,12.86,100,1,13.75,100,1,12.73,100,1,14.08,100,1,12.71,100,1,14.22,100,1,12.50,700,1,14.27,100,1,12.46,100,1,14.43,200,2,12.43,700,1,14.46,200,2,12.42,700,1,14.48,700,1,ARL,341661849
2630,2025-07-17T16:17:24.832340976Z,2025-07-17T16:17:24.832175508Z,160,2,1108,C,A,0,13.47,15,130,165468,286237340,13.11,100,1,13.48,100,1,13.03,2,1,13.74,2,1,12.98,200,2,13.75,100,1,12.86,100,1,14.08,100,1,12.73,100,1,14.22,100,1,12.71,100,1,14.27,100,1,12.50,700,1,14.43,200,2,12.46,100,1,14.46,200,2,12.43,700,1,14.48,700,1,12.42,700,1,14.49,100,1,ARL,344211173
2631,2025-07-17T16:17:26.823562625Z,2025-07-17T16:17:26.823396428Z,160,2,1108,C,A,0,13.48,100,130,166197,286261717,13.11,100,1,13.74,2,1,13.03,2,1,13.75,100,1,12.98,200,2,14.08,100,1,12.86,100,1,14.22,100,1,12.73,100,1,14.27,100,1,12.71,100,1,14.43,200,2,12.50,700,1,14.46,200,2,12.46,100,1,14.48,700,1,12.43,700,1,14.49,100,1,12.42,700,1,14.53,100,1,ARL,344225341
2632,2025-07-17T16:17:26.823923686Z,2025-07-17T16:17:26.823758552Z,160,2,1108,A,A,17,15.68,100,130,165134,286261727,13.11,100,1,13.74,2,1,13.03,2,1,13.75,100,1,12.98,200,2,14.08,100,1,12.86,100,1,14.22,100,1,12.73,100,1,14.27,100,1,12.71,100,1,14.43,200,2,12.50,700,1,14.46,200,2,12.46,100,1,14.48,700,1,12.43,700,1,14.49,100,1,12.42,700,1,14.53,100,1,ARL,344280537
2633,2025-07-17T16:17:26.823937553Z,2025-07-17T16:17:26.823771696Z,160,2,1108,C,A,15,15.37,100,130,165857,286261728,13.11,100,1,13.74,2,1,13.03,2,1,13.75,100,1,12.98,200,2,14.08,100,1,12.86,100,1,14.22,100,1,12.73,100,1,14.27,100,1,12.71,100,1,14.43,200,2,12.50,700,1,14.46,200,2,12.46,100,1,14.48,700,1,12.43,700,1,14.49,100,1,12.42,700,1,14.53,100,1,ARL,344225829
2634,2025-07-17T16:17:26.824304510Z,2025-07-17T16:17:26.824137854Z,160,2,1108,C,A,9,14.53,100,0,166656,286261743,13.11,100,1,13.74,2,1,13.03,2,1,13.75,100,1,12.98,200,2,14.08,100,1,12.86,100,1,14.22,100,1,12.73,100,1,14.27,100,1,12.71,100,1,14.43,200,2,12.50,700,1,14.46,200,2,12.46,100,1,14.48,700,1,12.43,700,1,14.49,100,1,12.42,700,1,14.54,700,1,ARL,344225385
2635,2025-07-17T16:17:26.824304510Z,2025-07-17T16:17:26.824137854Z,160,2,1108,A,A,11,14.58,100,0,166656,286261743,13.11,100,1,13.74,2,1,13.03,2,1,13.75,100,1,12.98,200,2,14.08,100,1,12.86,100,1,14.22,100,1,12.73,100,1,14.27,100,1,12.71,100,1,14.43,200,2,12.50,700,1,14.46,200,2,12.46,100,1,14.48,700,1,12.43,700,1,14.49,100,1,12.42,700,1,14.54,700,1,ARL,344280577
2636,2025-07-17T16:17:26.824304510Z,2025-07-17T16:17:26.824138799Z,160,2,1108,C,A,2,14.08,100,130,165711,286261744,13.11,100,1,13.74,2,1,13.03,2,1,13.75,100,1,12.98,200,2,14.22,100,1,12.86,100,1,14.27,100,1,12.73,100,1,14.43,200,2,12.71,100,1,14.46,200,2,12.50,700,1,14.48,700,1,12.46,100,1,14.49,100,1,12.43,700,1,14.54,700,1,12.42,700,1,14.56,700,1,ARL,344225397
2637,2025-07-17T16:17:26.824657956Z,2025-07-17T16:17:26.824492765Z,160,2,1108,A,A,4,14.36,100,130,165191,286261759,13.11,100,1,13.74,2,1,13.03,2,1,13.75,100,1,12.98,200,2,14.22,100,1,12.86,100,1,14.27,100,1,12.73,100,1,14.36,100,1,12.71,100,1,14.43,200,2,12.50,700,1,14.46,200,2,12.46,100,1,14.48,700,1,12.43,700,1,14.49,100,1,12.42,700,1,14.54,700,1,ARL,344280617
2638,2025-07-17T16:17:26.825988253Z,2025-07-17T16:17:26.825823014Z,160,2,1108,C,A,3,14.27,100,130,165239,286261769,13.11,100,1,13.74,2,1,13.03,2,1,13.75,100,1,12.98,200,2,14.22,100,1,12.86,100,1,14.36,100,1,12.73,100,1,14.43,200,2,12.71,100,1,14.46,200,2,12.50,700,1,14.48,700,1,12.46,100,1,14.49,100,1,12.43,700,1,14.54,700,1,12.42,700,1,14.56,700,1,ARL,344225453
2639,2025-07-17T16:17:26.826051208Z,2025-07-17T16:17:26.825885765Z,160,2,1108,C,A,4,14.43,100,0,165443,286261770,13.11,100,1,13.74,2,1,13.03,2,1,13.75,100,1,12.98,200,2,14.22,100,1,12.86,100,1,14.36,100,1,12.73,100,1,14.43,100,1,12.71,100,1,14.46,200,2,12.50,700,1,14.48,700,1,12.46,100,1,14.49,100,1,12.43,700,1,14.54,700,1,12.42,700,1,14.56,700,1,ARL,344225449
2640,2025-07-17T16:17:26.826051208Z,2025-07-17T16:17:26.825885765Z,160,2,1108,A,A,12,14.72,100,130,165443,286261770,13.11,100,1,13.74,2,1,13.03,2,1,13.75,100,1,12.98,200,2,14.22,100,1,12.86,100,1,14.36,100,1,12.73,100,1,14.43,100,1,12.71,100,1,14.46,200,2,12.50,700,1,14.48,700,1,12.46,100,1,14.49,100,1,12.43,700,1,14.54,700,1,12.42,700,1,14.56,700,1,ARL,344280641
2641,2025-07-17T16:17:26.826159189Z,2025-07-17T16:17:26.825993909Z,160,2,1108,A,A,8,14.54,100,130,165280,286261771,13.11,100,1,13.74,2,1,13.03,2,1,13.75,100,1,12.98,200,2,14.22,100,1,12.86,100,1,14.36,100,1,12.73,100,1,14.43,100,1,12.71,100,1,14.46,200,2,12.50,700,1,14.48,700,1,12.46,100,1,14.49,100,1,12.43,700,1,14.54,800,2,12.42,700,1,14.56,700,1,ARL,344280645
2642,2025-07-17T16:17:26.826294122Z,2025-07-17T16:17:26.826128663Z,160,2,1108,C,A,13,14.83,100,0,165459,286261775,13.11,100,1,13.74,2,1,13.03,2,1,13.75,100,1,12.98,200,2,14.22,100,1,12.86,100,1,14.36,100,1,12.73,100,1,14.43,100,1,12.71,100,1,14.46,200,2,12.50,700,1,14.48,700,1,12.46,100,1,14.49,100,1,12.43,700,1,14.54,800,2,12.42,700,1,14.56,700,1,ARL,344225405
2643,2025-07-17T16:17:26.826294122Z,2025-07-17T16:17:26.826128663Z,160,2,1108,A,A,14,15.13,100,130,165459,286261775,13.11,100,1,13.74,2,1,13.03,2,1,13.75,100,1,12.98,200,2,14.22,100,1,12.86,100,1,14.36,100,1,12.73,100,1,14.43,100,1,12.71,100,1,14.46,200,2,12.50,700,1,14.48,700,1,12.46,100,1,14.49,100,1,12.43,700,1,14.54,800,2,12.42,700,1,14.56,700,1,ARL,344280653
2644,2025-07-17T16:17:26.828538841Z,2025-07-17T16:17:26.828373551Z,160,2,1108,C,A,1,13.75,100,130,165290,286261785,13.11,100,1,13.74,2,1,13.03,2,1,14.22,100,1,12.98,200,2,14.36,100,1,12.86,100,1,14.43,100,1,12.73,100,1,14.46,200,2,12.71,100,1,14.48,700,1,12.50,700,1,14.49,100,1,12.46,100,1,14.54,800,2,12.43,700,1,14.56,700,1,12.42,700,1,14.58,100,1,ARL,344225533
2645,2025-07-17T16:17:26.828589142Z,2025-07-17T16:17:26.828423432Z,160,2,1108,A,A,1,14.03,100,130,165710,286261786,13.11,100,1,13.74,2,1,13.03,2,1,14.03,100,1,12.98,200,2,14.22,100,1,12.86,100,1,14.36,100,1,12.73,100,1,14.43,100,1,12.71,100,1,14.46,200,2,12.50,700,1,14.48,700,1,12.46,100,1,14.49,100,1,12.43,700,1,14.54,800,2,12.42,700,1,14.56,700,1,ARL,344280689
2646,2025-07-17T16:17:26.828846606Z,2025-07-17T16:17:26.828681062Z,160,2,1108,C,A,0,13.74,2,0,165544,286261788,13.11,100,1,14.03,100,1,13.03,2,1,14.22,100,1,12.98,200,2,14.36,100,1,12.86,100,1,14.43,100,1,12.73,100,1,14.46,200,2,12.71,100,1,14.48,700,1,12.50,700,1,14.49,100,1,12.46,100,1,14.54,800,2,12.43,700,1,14.56,700,1,12.42,700,1,14.58,100,1,ARL,340449865
2647,2025-07-17T16:17:26.828846606Z,2025-07-17T16:17:26.828681062Z,160,2,1108,A,A,0,13.97,2,130,165544,286261788,13.11,100,1,13.97,2,1,13.03,2,1,14.03,100,1,12.98,200,2,14.22,100,1,12.86,100,1,14.36,100,1,12.73,100,1,14.43,100,1,12.71,100,1,14.46,200,2,12.50,700,1,14.48,700,1,12.46,100,1,14.49,100,1,12.43,700,1,14.54,800,2,12.42,700,1,14.56,700,1,ARL,344280721
2648,2025-07-17T16:17:26.830066702Z,2025-07-17T16:17:26.829901530Z,160,2,1108,C,A,12,14.72,100,0,165172,286262023,13.11,100,1,13.97,2,1,13.03,2,1,14.03,100,1,12.98,200,2,14.22,100,1,12.86,100,1,14.36,100,1,12.73,100,1,14.43,100,1,12.71,100,1,14.46,200,2,12.50,700,1,14.48,700,1,12.46,100,1,14.49,100,1,12.43,700,1,14.54,800,2,12.42,700,1,14.56,700,1,ARL,344280641
2649,2025-07-17T16:17:26.830066702Z,2025-07-17T16:17:26.829901530Z,160,2,1108,A,A,13,14.96,100,130,165172,286262023,13.11,100,1,13.97,2,1,13.03,2,1,14.03,100,1,12.98,200,2,14.22,100,1,12.86,100,1,14.36,100,1,12.73,100,1,14.43,100,1,12.71,100,1,14.46,200,2,12.50,700,1,14.48,700,1,12.46,100,1,14.49,100,1,12.43,700,1,14.54,800,2,12.42,700,1,14.56,700,1,ARL,344280825
2650,2025-07-17T16:17:26.832026257Z,2025-07-17T16:17:26.831860798Z,160,2,1108,C,A,19,17.12,100,0,165459,286262118,13.11,100,1,13.97,2,1,13.03,2,1,14.03,100,1,12.98,200,2,14.22,100,1,12.86,100,1,14.36,100,1,12.73,100,1,14.43,100,1,12.71,100,1,14.46,200,2,12.50,700,1,14.48,700,1,12.46,100,1,14.49,100,1,12.43,700,1,14.54,800,2,12.42,700,1,14.56,700,1,ARL,344225457
2651,2025-07-17T16:17:26.832026257Z,2025-07-17T16:17:26.831860798Z,160,2,1108,A,A,20,17.76,100,130,165459,286262118,13.11,100,1,13.97,2,1,13.03,2,1,14.03,100,1,12.98,200,2,14.22,100,1,12.86,100,1,14.36,100,1,12.73,100,1,14.43,100,1,12.71,100,1,14.46,200,2,12.50,700,1,14.48,700,1,12.46,100,1,14.49,100,1,12.43,700,1,14.54,800,2,12.42,700,1,14.56,700,1,ARL,344280917
2652,2025-07-17T16:17:26.833194882Z,2025-07-17T16:17:26.833029512Z,160,2,1108,C,A,16,15.51,100,0,165370,286262137,13.11,100,1,13.97,2,1,13.03,2,1,14.03,100,1,12.98,200,2,14.22,100,1,12.86,100,1,14.36,100,1,12.73,100,1,14.43,100,1,12.71,100,1,14.46,200,2,12.50,700,1,14.48,700,1,12.46,100,1,14.49,100,1,12.43,700,1,14.54,800,2,12.42,700,1,14.56,700,1,ARL,344225393
2653,2025-07-17T16:17:26.833194882Z,2025-07-17T16:17:26.833029512Z,160,2,1108,A,A,17,16.08,100,130,165370,286262137,13.11,100,1,13.97,2,1,13.03,2,1,14.03,100,1,12.98,200,2,14.22,100,1,12.86,100,1,14.36,100,1,12.73,100,1,14.43,100,1,12.71,100,1,14.46,200,2,12.50,700,1,14.48,700,1,12.46,100,1,14.49,100,1,12.43,700,1,14.54,800,2,12.42,700,1,14.56,700,1,ARL,344280941
2654,2025-07-17T16:17:26.834911649Z,2025-07-17T16:17:26.834746475Z,160,2,1108,C,A,1,14.03,100,130,165174,286262165,13.11,100,1,13.97,2,1,13.03,2,1,14.22,100,1,12.98,200,2,14.36,100,1,12.86,100,1,14.43,100,1,12.73,100,1,14.46,200,2,12.71,100,1,14.48,700,1,12.50,700,1,14.49,100,1,12.46,100,1,14.54,800,2,12.43,700,1,14.56,700,1,12.42,700,1,14.58,100,1,ARL,344280689
2655,2025-07-17T16:17:26.834961494Z,2025-07-17T16:17:26.834796238Z,160,2,1108,A,A,2,14.25,100,130,165256,286262166,13.11,100,1,13.97,2,1,13.03,2,1,14.22,100,1,12.98,200,2,14.25,100,1,12.86,100,1,14.36,100,1,12.73,100,1,14.43,100,1,12.71,100,1,14.46,200,2,12.50,700,1,14.48,700,1,12.46,100,1,14.49,100,1,12.43,700,1,14.54,800,2,12.42,700,1,14.56,700,1,ARL,344280953
2656,2025-07-17T16:17:26.846567340Z,2025-07-17T16:17:26.846401696Z,160,2,1108,C,A,12,14.83,100,0,165644,286262231,13.11,100,1,13.97,2,1,13.03,2,1,14.22,100,1,12.98,200,2,14.25,100,1,12.86,100,1,14.36,100,1,12.73,100,1,14.43,100,1,12.71,100,1,14.46,200,2,12.50,700,1,14.48,700,1,12.46,100,1,14.49,100,1,12.43,700,1,14.54,800,2,12.42,700,1,14.56,700,1,ARL,344225485
2657,2025-07-17T16:17:26.846567340Z,2025-07-17T16:17:26.846401696Z,160,2,1108,A,A,15,15.38,100,130,165644,286262231,13.11,100,1,13.97,2,1,13.03,2,1,14.22,100,1,12.98,200,2,14.25,100,1,12.86,100,1,14.36,100,1,12.73,100,1,14.43,100,1,12.71,100,1,14.46,200,2,12.50,700,1,14.48,700,1,12.46,100,1,14.49,100,1,12.43,700,1,14.54,800,2,12.42,700,1,14.56,700,1,ARL,344281229
2658,2025-07-17T16:17:26.849670659Z,2025-07-17T16:17:26.849505109Z,160,2,1108,C,A,4,14.43,100,0,165550,286262262,13.11,100,1,13.97,2,1,13.03,2,1,14.22,100,1,12.98,200,2,14.25,100,1,12.86,100,1,14.36,100,1,12.73,100,1,14.46,200,2,12.71,100,1,14.48,700,1,12.50,700,1,14.49,100,1,12.46,100,1,14.54,800,2,12.43,700,1,14.56,700,1,12.42,700,1,14.58,100,1,ARL,344225489
2659,2025-07-17T16:17:26.849670659Z,2025-07-17T16:17:26.849505109Z,160,2,1108,A,A,11,14.96,100,130,165550,286262262,13.11,100,1,13.97,2,1,13.03,2,1,14.22,100,1,12.98,200,2,14.25,100,1,12.86,100,1,14.36,100,1,12.73,100,1,14.46,200,2,12.71,100,1,14.48,700,1,12.50,700,1,14.49,100,1,12.46,100,1,14.54,800,2,12.43,700,1,14.56,700,1,12.42,700,1,14.58,100,1,ARL,344281257
2660,2025-07-17T16:17:26.874430238Z,2025-07-17T16:17:26.874264677Z,160,2,1108,C,A,9,14.58,100,0,165561,286262413,13.11,100,1,13.97,2,1,13.03,2,1,14.22,100,1,12.98,200,2,14.25,100,1,12.86,100,1,14.36,100,1,12.73,100,1,14.46,200,2,12.71,100,1,14.48,700,1,12.50,700,1,14.49,100,1,12.46,100,1,14.54,800,2,12.43,700,1,14.56,700,1,12.42,700,1,14.68,700,1,ARL,344280577
2661,2025-07-17T16:17:26.874430238Z,2025-07-17T16:17:26.874264677Z,160,2,1108,A,A,11,15.05,100,130,165561,286262413,13.11,100,1,13.97,2,1,13.03,2,1,14.22,100,1,12.98,200,2,14.25,100,1,12.86,100,1,14.36,100,1,12.73,100,1,14.46,200,2,12.71,100,1,14.48,700,1,12.50,700,1,14.49,100,1,12.46,100,1,14.54,800,2,12.43,700,1,14.56,700,1,12.42,700,1,14.68,700,1,ARL,344281457
2662,2025-07-17T16:17:27.000782790Z,2025-07-17T16:17:27.000617575Z,160,2,1108,A,A,1,13.98,100,130,165215,286264622,13.11,100,1,13.97,2,1,13.03,2,1,13.98,100,1,12.98,200,2,14.22,100,1,12.86,100,1,14.25,100,1,12.73,100,1,14.36,100,1,12.71,100,1,14.46,200,2,12.50,700,1,14.48,700,1,12.46,100,1,14.49,100,1,12.43,700,1,14.54,800,2,12.42,700,1,14.56,700,1,ARL,344283633
2663,2025-07-17T16:17:27.204893988Z,2025-07-17T16:17:27.204728176Z,160,2,1108,C,A,2,14.22,100,130,165812,286267644,13.11,100,1,13.97,2,1,13.03,2,1,13.98,100,1,12.98,200,2,14.25,100,1,12.86,100,1,14.36,100,1,12.73,100,1,14.46,200,2,12.71,100,1,14.48,700,1,12.50,700,1,14.49,100,1,12.46,100,1,14.54,800,2,12.43,700,1,14.56,700,1,12.42,700,1,14.68,700,1,ARL,339365193
2664,2025-07-17T16:17:27.204895267Z,2025-07-17T16:17:27.204730160Z,160,2,1108,A,A,7,14.53,100,130,165107,286267645,13.11,100,1,13.97,2,1,13.03,2,1,13.98,100,1,12.98,200,2,14.25,100,1,12.86,100,1,14.36,100,1,12.73,100,1,14.46,200,2,12.71,100,1,14.48,700,1,12.50,700,1,14.49,100,1,12.46,100,1,14.53,100,1,12.43,700,1,14.54,800,2,12.42,700,1,14.56,700,1,ARL,344288585
2665,2025-07-17T16:17:27.381792167Z,2025-07-17T16:17:27.381626601Z,160,2,1108,A,A,11,14.81,100,130,165566,286271009,13.11,100,1,13.97,2,1,13.03,2,1,13.98,100,1,12.98,200,2,14.25,100,1,12.86,100,1,14.36,100,1,12.73,100,1,14.46,200,2,12.71,100,1,14.48,700,1,12.50,700,1,14.49,100,1,12.46,100,1,14.53,100,1,12.43,700,1,14.54,800,2,12.42,700,1,14.56,700,1,ARL,344292849
2666,2025-07-17T16:17:27.381809823Z,2025-07-17T16:17:27.381644366Z,160,2,1108,C,A,6,14.49,100,130,165457,286271010,13.11,100,1,13.97,2,1,13.03,2,1,13.98,100,1,12.98,200,2,14.25,100,1,12.86,100,1,14.36,100,1,12.73,100,1,14.46,200,2,12.71,100,1,14.48,700,1,12.50,700,1,14.53,100,1,12.46,100,1,14.54,800,2,12.43,700,1,14.56,700,1,12.42,700,1,14.68,700,1,ARL,339366385
2667,2025-07-17T16:17:27.443162448Z,2025-07-17T16:17:27.442997426Z,160,2,1108,C,A,3,14.36,100,130,165022,286271749,13.11,100,1,13.97,2,1,13.03,2,1,13.98,100,1,12.98,200,2,14.25,100,1,12.86,100,1,14.46,200,2,12.73,100,1,14.48,700,1,12.71,100,1,14.53,100,1,12.50,700,1,14.54,800,2,12.46,100,1,14.56,700,1,12.43,700,1,14.68,700,1,12.42,700,1,14.81,100,1,ARL,344280617
2668,2025-07-17T16:17:27.443512590Z,2025-07-17T16:17:27.443347265Z,160,2,1108,A,A,8,14.60,100,130,165325,286271751,13.11,100,1,13.97,2,1,13.03,2,1,13.98,100,1,12.98,200,2,14.25,100,1,12.86,100,1,14.46,200,2,12.73,100,1,14.48,700,1,12.71,100,1,14.53,100,1,12.50,700,1,14.54,800,2,12.46,100,1,14.56,700,1,12.43,700,1,14.60,100,1,12.42,700,1,14.68,700,1,ARL,344294245
2669,2025-07-17T16:17:27.829055288Z,2025-07-17T16:17:27.828890080Z,160,2,1108,C,A,6,14.54,100,0,165208,286275353,13.11,100,1,13.97,2,1,13.03,2,1,13.98,100,1,12.98,200,2,14.25,100,1,12.86,100,1,14.46,200,2,12.73,100,1,14.48,700,1,12.71,100,1,14.53,100,1,12.50,700,1,14.54,700,1,12.46,100,1,14.56,700,1,12.43,700,1,14.60,100,1,12.42,700,1,14.68,700,1,ARL,344280645
2670,2025-07-17T16:17:27.829055288Z,2025-07-17T16:17:27.828890080Z,160,2,1108,A,A,10,14.77,100,130,165208,286275353,13.11,100,1,13.97,2,1,13.03,2,1,13.98,100,1,12.98,200,2,14.25,100,1,12.86,100,1,14.46,200,2,12.73,100,1,14.48,700,1,12.71,100,1,14.53,100,1,12.50,700,1,14.54,700,1,12.46,100,1,14.56,700,1,12.43,700,1,14.60,100,1,12.42,700,1,14.68,700,1,ARL,344300085
2671,2025-07-17T16:17:39.514690751Z,2025-07-17T16:17:39.514525397Z,160,2,1108,A,A,0,13.47,15,130,165354,286508705,13.11,100,1,13.47,15,1,13.03,2,1,13.97,2,1,12.98,200,2,13.98,100,1,12.86,100,1,14.25,100,1,12.73,100,1,14.46,200,2,12.71,100,1,14.48,700,1,12.50,700,1,14.53,100,1,12.46,100,1,14.54,700,1,12.43,700,1,14.56,700,1,12.42,700,1,14.60,100,1,ARL,344587533
2672,2025-07-17T16:17:39.829017289Z,2025-07-17T16:17:39.828851797Z,160,2,1108,C,A,4,14.46,100,0,165492,286513833,13.11,100,1,13.47,15,1,13.03,2,1,13.97,2,1,12.98,200,2,13.98,100,1,12.86,100,1,14.25,100,1,12.73,100,1,14.46,100,1,12.71,100,1,14.48,700,1,12.50,700,1,14.53,100,1,12.46,100,1,14.54,700,1,12.43,700,1,14.56,700,1,12.42,700,1,14.60,100,1,ARL,339739285
2673,2025-07-17T16:17:39.829017289Z,2025-07-17T16:17:39.828851797Z,160,2,1108,A,A,4,14.35,100,130,165492,286513833,13.11,100,1,13.47,15,1,13.03,2,1,13.97,2,1,12.98,200,2,13.98,100,1,12.86,100,1,14.25,100,1,12.73,100,1,14.35,100,1,12.71,100,1,14.46,100,1,12.50,700,1,14.48,700,1,12.46,100,1,14.53,100,1,12.43,700,1,14.54,700,1,12.42,700,1,14.56,700,1,ARL,344593405
2674,2025-07-17T16:17:39.829247357Z,2025-07-17T16:17:39.829081898Z,160,2,1108,C,A,5,14.46,100,0,165459,286513835,13.11,100,1,13.47,15,1,13.03,2,1,13.97,2,1,12.98,200,2,13.98,100,1,12.86,100,1,14.25,100,1,12.73,100,1,14.35,100,1,12.71,100,1,14.48,700,1,12.50,700,1,14.53,100,1,12.46,100,1,14.54,700,1,12.43,700,1,14.56,700,1,12.42,700,1,14.60,100,1,ARL,339739297
2675,2025-07-17T16:17:39.829247357Z,2025-07-17T16:17:39.829081898Z,160,2,1108,A,A,4,14.35,100,130,165459,286513835,13.11,100,1,13.47,15,1,13.03,2,1,13.97,2,1,12.98,200,2,13.98,100,1,12.86,100,1,14.25,100,1,12.73,100,1,14.35,200,2,12.71,100,1,14.48,700,1,12.50,700,1,14.53,100,1,12.46,100,1,14.54,700,1,12.43,700,1,14.56,700,1,12.42,700,1,14.60,100,1,ARL,344593409
2676,2025-07-17T16:17:40.321326768Z,2025-07-17T16:17:40.321161439Z,160,2,1108,C,A,2,13.98,100,0,165329,286524785,13.11,100,1,13.47,15,1,13.03,2,1,13.97,2,1,12.98,200,2,14.25,100,1,12.86,100,1,14.35,200,2,12.73,100,1,14.48,700,1,12.71,100,1,14.53,100,1,12.50,700,1,14.54,700,1,12.46,100,1,14.56,700,1,12.43,700,1,14.60,100,1,12.42,700,1,14.68,700,1,ARL,344283633
2677,2025-07-17T16:17:40.321326768Z,2025-07-17T16:17:40.321161439Z,160,2,1108,A,A,1,13.48,100,130,165329,286524785,13.11,100,1,13.47,15,1,13.03,2,1,13.48,100,1,12.98,200,2,13.97,2,1,12.86,100,1,14.25,100,1,12.73,100,1,14.35,200,2,12.71,100,1,14.48,700,1,12.50,700,1,14.53,100,1,12.46,100,1,14.54,700,1,12.43,700,1,14.56,700,1,12.42,700,1,14.60,100,1,ARL,344607833
2678,2025-07-17T16:17:40.322064038Z,2025-07-17T16:17:40.321898765Z,160,2,1108,C,A,9,14.60,100,130,165273,286524815,13.11,100,1,13.47,15,1,13.03,2,1,13.48,100,1,12.98,200,2,13.97,2,1,12.86,100,1,14.25,100,1,12.73,100,1,14.35,200,2,12.71,100,1,14.48,700,1,12.50,700,1,14.53,100,1,12.46,100,1,14.54,700,1,12.43,700,1,14.56,700,1,12.42,700,1,14.68,700,1,ARL,344294245
2679,2025-07-17T16:17:40.322069742Z,2025-07-17T16:17:40.321903984Z,160,2,1108,C,A,13,15.05,100,0,165758,286524817,13.11,100,1,13.47,15,1,13.03,2,1,13.48,100,1,12.98,200,2,13.97,2,1,12.86,100,1,14.25,100,1,12.73,100,1,14.35,200,2,12.71,100,1,14.48,700,1,12.50,700,1,14.53,100,1,12.46,100,1,14.54,700,1,12.43,700,1,14.56,700,1,12.42,700,1,14.68,700,1,ARL,344281457
2680,2025-07-17T16:17:40.322069742Z,2025-07-17T16:17:40.321903984Z,160,2,1108,A,A,6,14.53,100,130,165758,286524817,13.11,100,1,13.47,15,1,13.03,2,1,13.48,100,1,12.98,200,2,13.97,2,1,12.86,100,1,14.25,100,1,12.73,100,1,14.35,200,2,12.71,100,1,14.48,700,1,12.50,700,1,14.53,200,2,12.46,100,1,14.54,700,1,12.43,700,1,14.56,700,1,12.42,700,1,14.68,700,1,ARL,344607889
2681,2025-07-17T16:17:40.322416015Z,2025-07-17T16:17:40.322250847Z,160,2,1108,A,A,3,14.08,100,130,165168,286524822,13.11,100,1,13.47,15,1,13.03,2,1,13.48,100,1,12.98,200,2,13.97,2,1,12.86,100,1,14.08,100,1,12.73,100,1,14.25,100,1,12.71,100,1,14.35,200,2,12.50,700,1,14.48,700,1,12.46,100,1,14.53,200,2,12.43,700,1,14.54,700,1,12.42,700,1,14.56,700,1,ARL,344607893
2682,2025-07-17T16:17:40.329180897Z,2025-07-17T16:17:40.329015669Z,160,2,1108,C,A,4,14.25,100,130,165228,286524967,13.11,100,1,13.47,15,1,13.03,2,1,13.48,100,1,12.98,200,2,13.97,2,1,12.86,100,1,14.08,100,1,12.73,100,1,14.35,200,2,12.71,100,1,14.48,700,1,12.50,700,1,14.53,200,2,12.46,100,1,14.54,700,1,12.43,700,1,14.56,700,1,12.42,700,1,14.68,700,1,ARL,344280953
2683,2025-07-17T16:17:40.329233157Z,2025-07-17T16:17:40.329067996Z,160,2,1108,A,A,2,13.75,100,130,165161,286524969,13.11,100,1,13.47,15,1,13.03,2,1,13.48,100,1,12.98,200,2,13.75,100,1,12.86,100,1,13.97,2,1,12.73,100,1,14.08,100,1,12.71,100,1,14.35,200,2,12.50,700,1,14.48,700,1,12.46,100,1,14.53,200,2,12.43,700,1,14.54,700,1,12.42,700,1,14.56,700,1,ARL,344608193
2684,2025-07-17T16:17:40.330448099Z,2025-07-17T16:17:40.330282519Z,160,2,1108,C,A,14,15.13,100,0,165580,286524982,13.11,100,1,13.47,15,1,13.03,2,1,13.48,100,1,12.98,200,2,13.75,100,1,12.86,100,1,13.97,2,1,12.73,100,1,14.08,100,1,12.71,100,1,14.35,200,2,12.50,700,1,14.48,700,1,12.46,100,1,14.53,200,2,12.43,700,1,14.54,700,1,12.42,700,1,14.56,700,1,ARL,344280653
2685,2025-07-17T16:17:40.330448099Z,2025-07-17T16:17:40.330282519Z,160,2,1108,A,A,13,14.83,100,130,165580,286524982,13.11,100,1,13.47,15,1,13.03,2,1,13.48,100,1,12.98,200,2,13.75,100,1,12.86,100,1,13.97,2,1,12.73,100,1,14.08,100,1,12.71,100,1,14.35,200,2,12.50,700,1,14.48,700,1,12.46,100,1,14.53,200,2,12.43,700,1,14.54,700,1,12.42,700,1,14.56,700,1,ARL,344608205
2686,2025-07-17T16:17:40.331429414Z,2025-07-17T16:17:40.331264268Z,160,2,1108,C,A,11,14.77,100,130,165146,286524998,13.11,100,1,13.47,15,1,13.03,2,1,13.48,100,1,12.98,200,2,13.75,100,1,12.86,100,1,13.97,2,1,12.73,100,1,14.08,100,1,12.71,100,1,14.35,200,2,12.50,700,1,14.48,700,1,12.46,100,1,14.53,200,2,12.43,700,1,14.54,700,1,12.42,700,1,14.56,700,1,ARL,344300085
2687,2025-07-17T16:17:40.331551656Z,2025-07-17T16:17:40.331386492Z,160,2,1108,A,A,5,14.27,100,130,165164,286525005,13.11,100,1,13.47,15,1,13.03,2,1,13.48,100,1,12.98,200,2,13.75,100,1,12.86,100,1,13.97,2,1,12.73,100,1,14.08,100,1,12.71,100,1,14.27,100,1,12.50,700,1,14.35,200,2,12.46,100,1,14.48,700,1,12.43,700,1,14.53,200,2,12.42,700,1,14.54,700,1,ARL,344608225
2688,2025-07-17T16:17:40.333679181Z,2025-07-17T16:17:40.333513866Z,160,2,1108,C,A,14,14.96,100,0,165315,286525029,13.11,100,1,13.47,15,1,13.03,2,1,13.48,100,1,12.98,200,2,13.75,100,1,12.86,100,1,13.97,2,1,12.73,100,1,14.08,100,1,12.71,100,1,14.27,100,1,12.50,700,1,14.35,200,2,12.46,100,1,14.48,700,1,12.43,700,1,14.53,200,2,12.42,700,1,14.54,700,1,ARL,344280825
2689,2025-07-17T16:17:40.333679181Z,2025-07-17T16:17:40.333513866Z,160,2,1108,A,A,7,14.43,100,130,165315,286525029,13.11,100,1,13.47,15,1,13.03,2,1,13.48,100,1,12.98,200,2,13.75,100,1,12.86,100,1,13.97,2,1,12.73,100,1,14.08,100,1,12.71,100,1,14.27,100,1,12.50,700,1,14.35,200,2,12.46,100,1,14.43,100,1,12.43,700,1,14.48,700,1,12.42,700,1,14.53,200,2,ARL,344608253
2690,2025-07-17T16:17:40.348996221Z,2025-07-17T16:17:40.348830748Z,160,2,1108,C,A,21,17.76,100,0,165473,286525170,13.11,100,1,13.47,15,1,13.03,2,1,13.48,100,1,12.98,200,2,13.75,100,1,12.86,100,1,13.97,2,1,12.73,100,1,14.08,100,1,12.71,100,1,14.27,100,1,12.50,700,1,14.35,200,2,12.46,100,1,14.43,100,1,12.43,700,1,14.48,700,1,12.42,700,1,14.53,200,2,ARL,344280917
2691,2025-07-17T16:17:40.348996221Z,2025-07-17T16:17:40.348830748Z,160,2,1108,A,A,20,17.12,100,130,165473,286525170,13.11,100,1,13.47,15,1,13.03,2,1,13.48,100,1,12.98,200,2,13.75,100,1,12.86,100,1,13.97,2,1,12.73,100,1,14.08,100,1,12.71,100,1,14.27,100,1,12.50,700,1,14.35,200,2,12.46,100,1,14.43,100,1,12.43,700,1,14.48,700,1,12.42,700,1,14.53,200,2,ARL,344608637
2692,2025-07-17T16:17:40.349081921Z,2025-07-17T16:17:40.348916703Z,160,2,1108,A,A,17,15.37,100,130,165218,286525175,13.11,100,1,13.47,15,1,13.03,2,1,13.48,100,1,12.98,200,2,13.75,100,1,12.86,100,1,13.97,2,1,12.73,100,1,14.08,100,1,12.71,100,1,14.27,100,1,12.50,700,1,14.35,200,2,12.46,100,1,14.43,100,1,12.43,700,1,14.48,700,1,12.42,700,1,14.53,200,2,ARL,344608641
2693,2025-07-17T16:17:40.349095477Z,2025-07-17T16:17:40.348930117Z,160,2,1108,C,A,19,15.68,100,130,165360,286525177,13.11,100,1,13.47,15,1,13.03,2,1,13.48,100,1,12.98,200,2,13.75,100,1,12.86,100,1,13.97,2,1,12.73,100,1,14.08,100,1,12.71,100,1,14.27,100,1,12.50,700,1,14.35,200,2,12.46,100,1,14.43,100,1,12.43,700,1,14.48,700,1,12.42,700,1,14.53,200,2,ARL,344280537
2694,2025-07-17T16:17:40.357367234Z,2025-07-17T16:17:40.357201846Z,160,2,1108,C,A,19,16.08,100,0,165388,286525428,13.11,100,1,13.47,15,1,13.03,2,1,13.48,100,1,12.98,200,2,13.75,100,1,12.86,100,1,13.97,2,1,12.73,100,1,14.08,100,1,12.71,100,1,14.27,100,1,12.50,700,1,14.35,200,2,12.46,100,1,14.43,100,1,12.43,700,1,14.48,700,1,12.42,700,1,14.53,200,2,ARL,344280941
2695,2025-07-17T16:17:40.357367234Z,2025-07-17T16:17:40.357201846Z,160,2,1108,A,A,19,15.51,100,130,165388,286525428,13.11,100,1,13.47,15,1,13.03,2,1,13.48,100,1,12.98,200,2,13.75,100,1,12.86,100,1,13.97,2,1,12.73,100,1,14.08,100,1,12.71,100,1,14.27,100,1,12.50,700,1,14.35,200,2,12.46,100,1,14.43,100,1,12.43,700,1,14.48,700,1,12.42,700,1,14.53,200,2,ARL,344608797
2696,2025-07-17T16:17:40.403239477Z,2025-07-17T16:17:40.403073956Z,160,2,1108,C,A,18,15.38,100,0,165521,286526316,13.11,100,1,13.47,15,1,13.03,2,1,13.48,100,1,12.98,200,2,13.75,100,1,12.86,100,1,13.97,2,1,12.73,100,1,14.08,100,1,12.71,100,1,14.27,100,1,12.50,700,1,14.35,200,2,12.46,100,1,14.43,100,1,12.43,700,1,14.48,700,1,12.42,700,1,14.53,200,2,ARL,344281229
2697,2025-07-17T16:17:40.403239477Z,2025-07-17T16:17:40.403073956Z,160,2,1108,A,A,14,14.83,100,130,165521,286526316,13.11,100,1,13.47,15,1,13.03,2,1,13.48,100,1,12.98,200,2,13.75,100,1,12.86,100,1,13.97,2,1,12.73,100,1,14.08,100,1,12.71,100,1,14.27,100,1,12.50,700,1,14.35,200,2,12.46,100,1,14.43,100,1,12.43,700,1,14.48,700,1,12.42,700,1,14.53,200,2,ARL,344609897
2698,2025-07-17T16:17:40.426590567Z,2025-07-17T16:17:40.426425205Z,160,2,1108,C,A,15,14.96,100,0,165362,286526540,13.11,100,1,13.47,15,1,13.03,2,1,13.48,100,1,12.98,200,2,13.75,100,1,12.86,100,1,13.97,2,1,12.73,100,1,14.08,100,1,12.71,100,1,14.27,100,1,12.50,700,1,14.35,200,2,12.46,100,1,14.43,100,1,12.43,700,1,14.48,700,1,12.42,700,1,14.53,200,2,ARL,344281257
2699,2025-07-17T16:17:40.426590567Z,2025-07-17T16:17:40.426425205Z,160,2,1108,A,A,7,14.43,100,130,165362,286526540,13.11,100,1,13.47,15,1,13.03,2,1,13.48,100,1,12.98,200,2,13.75,100,1,12.86,100,1,13.97,2,1,12.73,100,1,14.08,100,1,12.71,100,1,14.27,100,1,12.50,700,1,14.35,200,2,12.46,100,1,14.43,200,2,12.43,700,1,14.48,700,1,12.42,700,1,14.53,200,2,ARL,344610073
2700,2025-07-17T16:17:40.474841118Z,2025-07-17T16:17:40.474675991Z,160,2,1108,A,A,4,14.01,100,130,165127,286527611,13.11,100,1,13.47,15,1,13.03,2,1,13.48,100,1,12.98,200,2,13.75,100,1,12.86,100,1,13.97,2,1,12.73,100,1,14.01,100,1,12.71,100,1,14.08,100,1,12.50,700,1,14.27,100,1,12.46,100,1,14.35,200,2,12.43,700,1,14.43,200,2,12.42,700,1,14.48,700,1,ARL,344612049
2701,2025-07-17T16:17:40.474842468Z,2025-07-17T16:17:40.474677082Z,160,2,1108,C,A,10,14.53,100,130,165386,286527612,13.11,100,1,13.47,15,1,13.03,2,1,13.48,100,1,12.98,200,2,13.75,100,1,12.86,100,1,13.97,2,1,12.73,100,1,14.01,100,1,12.71,100,1,14.08,100,1,12.50,700,1,14.27,100,1,12.46,100,1,14.35,200,2,12.43,700,1,14.43,200,2,12.42,700,1,14.48,700,1,ARL,344288585
2702,2025-07-17T16:17:40.697721205Z,2025-07-17T16:17:40.697555911Z,160,2,1108,A,A,7,14.28,100,130,165294,286530329,13.11,100,1,13.47,15,1,13.03,2,1,13.48,100,1,12.98,200,2,13.75,100,1,12.86,100,1,13.97,2,1,12.73,100,1,14.01,100,1,12.71,100,1,14.08,100,1,12.50,700,1,14.27,100,1,12.46,100,1,14.28,100,1,12.43,700,1,14.35,200,2,12.42,700,1,14.43,200,2,ARL,344615393
2703,2025-07-17T16:17:40.697733924Z,2025-07-17T16:17:40.697568713Z,160,2,1108,C,A,15,14.81,100,130,165211,286530330,13.11,100,1,13.47,15,1,13.03,2,1,13.48,100,1,12.98,200,2,13.75,100,1,12.86,100,1,13.97,2,1,12.73,100,1,14.01,100,1,12.71,100,1,14.08,100,1,12.50,700,1,14.27,100,1,12.46,100,1,14.28,100,1,12.43,700,1,14.35,200,2,12.42,700,1,14.43,200,2,ARL,344292849
2704,2025-07-17T16:17:41.586151161Z,2025-07-17T16:17:41.585985709Z,160,2,1108,C,A,3,13.97,2,0,165452,286543225,13.11,100,1,13.47,15,1,13.03,2,1,13.48,100,1,12.98,200,2,13.75,100,1,12.86,100,1,14.01,100,1,12.73,100,1,14.08,100,1,12.71,100,1,14.27,100,1,12.50,700,1,14.28,100,1,12.46,100,1,14.35,200,2,12.43,700,1,14.43,200,2,12.42,700,1,14.48,700,1,ARL,344280721
2705,2025-07-17T16:17:41.586151161Z,2025-07-17T16:17:41.585985709Z,160,2,1108,A,A,3,13.87,2,130,165452,286543225,13.11,100,1,13.47,15,1,13.03,2,1,13.48,100,1,12.98,200,2,13.75,100,1,12.86,100,1,13.87,2,1,12.73,100,1,14.01,100,1,12.71,100,1,14.08,100,1,12.50,700,1,14.27,100,1,12.46,100,1,14.28,100,1,12.43,700,1,14.35,200,2,12.42,700,1,14.43,200,2,ARL,344631921
2706,2025-07-17T16:17:42.553133650Z,2025-07-17T16:17:42.552968542Z,160,2,1108,A,A,0,13.45,15,130,165108,286561347,13.11,100,1,13.45,15,1,13.03,2,1,13.47,15,1,12.98,200,2,13.48,100,1,12.86,100,1,13.75,100,1,12.73,100,1,13.87,2,1,12.71,100,1,14.01,100,1,12.50,700,1,14.08,100,1,12.46,100,1,14.27,100,1,12.43,700,1,14.28,100,1,12.42,700,1,14.35,200,2,ARL,344653009
2707,2025-07-17T16:17:44.014614049Z,2025-07-17T16:17:44.014448587Z,160,2,1108,C,A,2,13.48,100,0,165462,286577648,13.11,100,1,13.45,15,1,13.03,2,1,13.47,15,1,12.98,200,2,13.75,100,1,12.86,100,1,13.87,2,1,12.73,100,1,14.01,100,1,12.71,100,1,14.08,100,1,12.50,700,1,14.27,100,1,12.46,100,1,14.28,100,1,12.43,700,1,14.35,200,2,12.42,700,1,14.43,200,2,ARL,344607833
2708,2025-07-17T16:17:44.014614049Z,2025-07-17T16:17:44.014448587Z,160,2,1108,A,A,1,13.46,100,130,165462,286577648,13.11,100,1,13.45,15,1,13.03,2,1,13.46,100,1,12.98,200,2,13.47,15,1,12.86,100,1,13.75,100,1,12.73,100,1,13.87,2,1,12.71,100,1,14.01,100,1,12.50,700,1,14.08,100,1,12.46,100,1,14.27,100,1,12.43,700,1,14.28,100,1,12.42,700,1,14.35,200,2,ARL,344673481
2709,2025-07-17T16:17:44.014977545Z,2025-07-17T16:17:44.014812396Z,160,2,1108,A,A,20,15.68,100,130,165149,286577651,13.11,100,1,13.45,15,1,13.03,2,1,13.46,100,1,12.98,200,2,13.47,15,1,12.86,100,1,13.75,100,1,12.73,100,1,13.87,2,1,12.71,100,1,14.01,100,1,12.50,700,1,14.08,100,1,12.46,100,1,14.27,100,1,12.43,700,1,14.28,100,1,12.42,700,1,14.35,200,2,ARL,344673501
2710,2025-07-17T16:17:44.014991037Z,2025-07-17T16:17:44.014825581Z,160,2,1108,C,A,18,15.37,100,130,165456,286577652,13.11,100,1,13.45,15,1,13.03,2,1,13.46,100,1,12.98,200,2,13.47,15,1,12.86,100,1,13.75,100,1,12.73,100,1,13.87,2,1,12.71,100,1,14.01,100,1,12.50,700,1,14.08,100,1,12.46,100,1,14.27,100,1,12.43,700,1,14.28,100,1,12.42,700,1,14.35,200,2,ARL,344608641
2711,2025-07-17T16:17:44.042976984Z,2025-07-17T16:17:44.042811526Z,160,2,1108,A,A,18,15.35,100,130,165458,286578356,13.11,100,1,13.45,15,1,13.03,2,1,13.46,100,1,12.98,200,2,13.47,15,1,12.86,100,1,13.75,100,1,12.73,100,1,13.87,2,1,12.71,100,1,14.01,100,1,12.50,700,1,14.08,100,1,12.46,100,1,14.27,100,1,12.43,700,1,14.28,100,1,12.42,700,1,14.35,200,2,ARL,344674517
2712,2025-07-17T16:17:44.042989197Z,2025-07-17T16:17:44.042824242Z,160,2,1108,C,A,20,15.68,100,130,164955,286578357,13.11,100,1,13.45,15,1,13.03,2,1,13.46,100,1,12.98,200,2,13.47,15,1,12.86,100,1,13.75,100,1,12.73,100,1,13.87,2,1,12.71,100,1,14.01,100,1,12.50,700,1,14.08,100,1,12.46,100,1,14.27,100,1,12.43,700,1,14.28,100,1,12.42,700,1,14.35,200,2,ARL,344673501
2713,2025-07-17T16:17:46.828260391Z,2025-07-17T16:17:46.828095134Z,160,2,1108,A,A,7,14.18,700,130,165257,286618024,13.11,100,1,13.45,15,1,13.03,2,1,13.46,100,1,12.98,200,2,13.47,15,1,12.86,100,1,13.75,100,1,12.73,100,1,13.87,2,1,12.71,100,1,14.01,100,1,12.50,700,1,14.08,100,1,12.46,100,1,14.18,700,1,12.43,700,1,14.27,100,1,12.42,700,1,14.28,100,1,ARL,344724301
2714,2025-07-17T16:17:46.828325564Z,2025-07-17T16:17:46.828160338Z,160,2,1108,C,A,16,14.68,700,130,165226,286618025,13.11,100,1,13.45,15,1,13.03,2,1,13.46,100,1,12.98,200,2,13.47,15,1,12.86,100,1,13.75,100,1,12.73,100,1,13.87,2,1,12.71,100,1,14.01,100,1,12.50,700,1,14.08,100,1,12.46,100,1,14.18,700,1,12.43,700,1,14.27,100,1,12.42,700,1,14.28,100,1,ARL,341663105
2715,2025-07-17T16:17:49.387530942Z,2025-07-17T16:17:49.387365405Z,160,2,1108,C,A,4,13.87,2,0,165537,286651544,13.11,100,1,13.45,15,1,13.03,2,1,13.46,100,1,12.98,200,2,13.47,15,1,12.86,100,1,13.75,100,1,12.73,100,1,14.01,100,1,12.71,100,1,14.08,100,1,12.50,700,1,14.18,700,1,12.46,100,1,14.27,100,1,12.43,700,1,14.28,100,1,12.42,700,1,14.35,200,2,ARL,344631921
2716,2025-07-17T16:17:49.387530942Z,2025-07-17T16:17:49.387365405Z,160,2,1108,A,A,4,13.79,2,130,165537,286651544,13.11,100,1,13.45,15,1,13.03,2,1,13.46,100,1,12.98,200,2,13.47,15,1,12.86,100,1,13.75,100,1,12.73,100,1,13.79,2,1,12.71,100,1,14.01,100,1,12.50,700,1,14.08,100,1,12.46,100,1,14.18,700,1,12.43,700,1,14.27,100,1,12.42,700,1,14.28,100,1,ARL,344765077
2717,2025-07-17T16:17:52.834173973Z,2025-07-17T16:17:52.834008196Z,160,2,1108,C,A,2,13.47,15,130,165777,286689853,13.11,100,1,13.45,15,1,13.03,2,1,13.46,100,1,12.98,200,2,13.75,100,1,12.86,100,1,13.79,2,1,12.73,100,1,14.01,100,1,12.71,100,1,14.08,100,1,12.50,700,1,14.18,700,1,12.46,100,1,14.27,100,1,12.43,700,1,14.28,100,1,12.42,700,1,14.35,200,2,ARL,344587533
2718,2025-07-17T16:17:58.033327053Z,2025-07-17T16:17:58.033161898Z,160,2,1108,C,A,0,13.45,15,130,165155,286753046,13.11,100,1,13.46,100,1,13.03,2,1,13.75,100,1,12.98,200,2,13.79,2,1,12.86,100,1,14.01,100,1,12.73,100,1,14.08,100,1,12.71,100,1,14.18,700,1,12.50,700,1,14.27,100,1,12.46,100,1,14.28,100,1,12.43,700,1,14.35,200,2,12.42,700,1,14.43,200,2,ARL,344653009
2719,2025-07-17T16:17:58.036588469Z,2025-07-17T16:17:58.036423237Z,160,2,1108,C,A,0,13.46,100,130,165232,286753126,13.11,100,1,13.75,100,1,13.03,2,1,13.79,2,1,12.98,200,2,14.01,100,1,12.86,100,1,14.08,100,1,12.73,100,1,14.18,700,1,12.71,100,1,14.27,100,1,12.50,700,1,14.28,100,1,12.46,100,1,14.35,200,2,12.43,700,1,14.43,200,2,12.42,700,1,14.48,700,1,ARL,344673481
2720,2025-07-17T16:17:58.036861922Z,2025-07-17T16:17:58.036696806Z,160,2,1108,C,A,4,14.18,700,130,165116,286753127,13.11,100,1,13.75,100,1,13.03,2,1,13.79,2,1,12.98,200,2,14.01,100,1,12.86,100,1,14.08,100,1,12.73,100,1,14.27,100,1,12.71,100,1,14.28,100,1,12.50,700,1,14.35,200,2,12.46,100,1,14.43,200,2,12.43,700,1,14.48,700,1,12.42,700,1,14.53,100,1,ARL,344724301
2721,2025-07-17T16:17:58.036914002Z,2025-07-17T16:17:58.036748831Z,160,2,1108,A,A,8,14.44,700,130,165171,286753128,13.11,100,1,13.75,100,1,13.03,2,1,13.79,2,1,12.98,200,2,14.01,100,1,12.86,100,1,14.08,100,1,12.73,100,1,14.27,100,1,12.71,100,1,14.28,100,1,12.50,700,1,14.35,200,2,12.46,100,1,14.43,200,2,12.43,700,1,14.44,700,1,12.42,700,1,14.48,700,1,ARL,344897921
2722,2025-07-17T16:17:58.036971455Z,2025-07-17T16:17:58.036806229Z,160,2,1108,A,A,17,15.68,100,130,165226,286753129,13.11,100,1,13.75,100,1,13.03,2,1,13.79,2,1,12.98,200,2,14.01,100,1,12.86,100,1,14.08,100,1,12.73,100,1,14.27,100,1,12.71,100,1,14.28,100,1,12.50,700,1,14.35,200,2,12.46,100,1,14.43,200,2,12.43,700,1,14.44,700,1,12.42,700,1,14.48,700,1,ARL,344897933
2723,2025-07-17T16:17:58.036983460Z,2025-07-17T16:17:58.036818196Z,160,2,1108,C,A,15,15.35,100,130,165264,286753132,13.11,100,1,13.75,100,1,13.03,2,1,13.79,2,1,12.98,200,2,14.01,100,1,12.86,100,1,14.08,100,1,12.73,100,1,14.27,100,1,12.71,100,1,14.28,100,1,12.50,700,1,14.35,200,2,12.46,100,1,14.43,200,2,12.43,700,1,14.44,700,1,12.42,700,1,14.48,700,1,ARL,344674517
2724,2025-07-17T16:17:58.037325671Z,2025-07-17T16:17:58.037160197Z,160,2,1108,C,A,10,14.53,100,0,165474,286753136,13.11,100,1,13.75,100,1,13.03,2,1,13.79,2,1,12.98,200,2,14.01,100,1,12.86,100,1,14.08,100,1,12.73,100,1,14.27,100,1,12.71,100,1,14.28,100,1,12.50,700,1,14.35,200,2,12.46,100,1,14.43,200,2,12.43,700,1,14.44,700,1,12.42,700,1,14.48,700,1,ARL,344607889
2725,2025-07-17T16:17:58.037325671Z,2025-07-17T16:17:58.037160197Z,160,2,1108,A,A,12,14.82,100,130,165474,286753136,13.11,100,1,13.75,100,1,13.03,2,1,13.79,2,1,12.98,200,2,14.01,100,1,12.86,100,1,14.08,100,1,12.73,100,1,14.27,100,1,12.71,100,1,14.28,100,1,12.50,700,1,14.35,200,2,12.46,100,1,14.43,200,2,12.43,700,1,14.44,700,1,12.42,700,1,14.48,700,1,ARL,344897945
2726,2025-07-17T16:17:58.037330946Z,2025-07-17T16:17:58.037165870Z,160,2,1108,C,A,3,14.08,100,130,165076,286753137,13.11,100,1,13.75,100,1,13.03,2,1,13.79,2,1,12.98,200,2,14.01,100,1,12.86,100,1,14.27,100,1,12.73,100,1,14.28,100,1,12.71,100,1,14.35,200,2,12.50,700,1,14.43,200,2,12.46,100,1,14.44,700,1,12.43,700,1,14.48,700,1,12.42,700,1,14.54,700,1,ARL,344607893
2727,2025-07-17T16:17:58.037686676Z,2025-07-17T16:17:58.037521442Z,160,2,1108,A,A,6,14.36,100,130,165234,286753149,13.11,100,1,13.75,100,1,13.03,2,1,13.79,2,1,12.98,200,2,14.01,100,1,12.86,100,1,14.27,100,1,12.73,100,1,14.28,100,1,12.71,100,1,14.35,200,2,12.50,700,1,14.36,100,1,12.46,100,1,14.43,200,2,12.43,700,1,14.44,700,1,12.42,700,1,14.48,700,1,ARL,344897953
2728,2025-07-17T16:17:58.038759735Z,2025-07-17T16:17:58.038594284Z,160,2,1108,C,A,7,14.43,100,0,165451,286753168,13.11,100,1,13.75,100,1,13.03,2,1,13.79,2,1,12.98,200,2,14.01,100,1,12.86,100,1,14.27,100,1,12.73,100,1,14.28,100,1,12.71,100,1,14.35,200,2,12.50,700,1,14.36,100,1,12.46,100,1,14.43,100,1,12.43,700,1,14.44,700,1,12.42,700,1,14.48,700,1,ARL,344608253
2729,2025-07-17T16:17:58.038759735Z,2025-07-17T16:17:58.038594284Z,160,2,1108,A,A,12,14.72,100,130,165451,286753168,13.11,100,1,13.75,100,1,13.03,2,1,13.79,2,1,12.98,200,2,14.01,100,1,12.86,100,1,14.27,100,1,12.73,100,1,14.28,100,1,12.71,100,1,14.35,200,2,12.50,700,1,14.36,100,1,12.46,100,1,14.43,100,1,12.43,700,1,14.44,700,1,12.42,700,1,14.48,700,1,ARL,344897989
2730,2025-07-17T16:17:58.039381900Z,2025-07-17T16:17:58.039215838Z,160,2,1108,C,A,14,14.83,100,0,166062,286753172,13.11,100,1,13.75,100,1,13.03,2,1,13.79,2,1,12.98,200,2,14.01,100,1,12.86,100,1,14.27,100,1,12.73,100,1,14.28,100,1,12.71,100,1,14.35,200,2,12.50,700,1,14.36,100,1,12.46,100,1,14.43,100,1,12.43,700,1,14.44,700,1,12.42,700,1,14.48,700,1,ARL,344608205
2731,2025-07-17T16:17:58.039381900Z,2025-07-17T16:17:58.039215838Z,160,2,1108,A,A,15,15.13,100,130,166062,286753172,13.11,100,1,13.75,100,1,13.03,2,1,13.79,2,1,12.98,200,2,14.01,100,1,12.86,100,1,14.27,100,1,12.73,100,1,14.28,100,1,12.71,100,1,14.35,200,2,12.50,700,1,14.36,100,1,12.46,100,1,14.43,100,1,12.43,700,1,14.44,700,1,12.42,700,1,14.48,700,1,ARL,344897997
2732,2025-07-17T16:17:58.047862207Z,2025-07-17T16:17:58.047696769Z,160,2,1108,C,A,20,17.12,100,0,165438,286753519,13.11,100,1,13.75,100,1,13.03,2,1,13.79,2,1,12.98,200,2,14.01,100,1,12.86,100,1,14.27,100,1,12.73,100,1,14.28,100,1,12.71,100,1,14.35,200,2,12.50,700,1,14.36,100,1,12.46,100,1,14.43,100,1,12.43,700,1,14.44,700,1,12.42,700,1,14.48,700,1,ARL,344608637
2733,2025-07-17T16:17:58.047862207Z,2025-07-17T16:17:58.047696769Z,160,2,1108,A,A,21,17.47,100,130,165438,286753519,13.11,100,1,13.75,100,1,13.03,2,1,13.79,2,1,12.98,200,2,14.01,100,1,12.86,100,1,14.27,100,1,12.73,100,1,14.28,100,1,12.71,100,1,14.35,200,2,12.50,700,1,14.36,100,1,12.46,100,1,14.43,100,1,12.43,700,1,14.44,700,1,12.42,700,1,14.48,700,1,ARL,344898485
2734,2025-07-17T16:17:58.051632876Z,2025-07-17T16:17:58.051466948Z,160,2,1108,C,A,17,15.51,100,0,165928,286753581,13.11,100,1,13.75,100,1,13.03,2,1,13.79,2,1,12.98,200,2,14.01,100,1,12.86,100,1,14.27,100,1,12.73,100,1,14.28,100,1,12.71,100,1,14.35,200,2,12.50,700,1,14.36,100,1,12.46,100,1,14.43,100,1,12.43,700,1,14.44,700,1,12.42,700,1,14.48,700,1,ARL,344608797
2735,2025-07-17T16:17:58.051632876Z,2025-07-17T16:17:58.051466948Z,160,2,1108,A,A,18,15.82,100,130,165928,286753581,13.11,100,1,13.75,100,1,13.03,2,1,13.79,2,1,12.98,200,2,14.01,100,1,12.86,100,1,14.27,100,1,12.73,100,1,14.28,100,1,12.71,100,1,14.35,200,2,12.50,700,1,14.36,100,1,12.46,100,1,14.43,100,1,12.43,700,1,14.44,700,1,12.42,700,1,14.48,700,1,ARL,344898677
2736,2025-07-17T16:17:58.054049362Z,2025-07-17T16:17:58.053883828Z,160,2,1108,C,A,0,13.75,100,130,165534,286753747,13.11,100,1,13.79,2,1,13.03,2,1,14.01,100,1,12.98,200,2,14.27,100,1,12.86,100,1,14.28,100,1,12.73,100,1,14.35,200,2,12.71,100,1,14.36,100,1,12.50,700,1,14.43,100,1,12.46,100,1,14.44,700,1,12.43,700,1,14.48,700,1,12.42,700,1,14.54,700,1,ARL,344608193
2737,2025-07-17T16:17:58.054100805Z,2025-07-17T16:17:58.053934652Z,160,2,1108,C,A,7,14.44,700,130,166153,286753751,13.11,100,1,13.79,2,1,13.03,2,1,14.01,100,1,12.98,200,2,14.27,100,1,12.86,100,1,14.28,100,1,12.73,100,1,14.35,200,2,12.71,100,1,14.36,100,1,12.50,700,1,14.43,100,1,12.46,100,1,14.48,700,1,12.43,700,1,14.54,700,1,12.42,700,1,14.56,700,1,ARL,344897921
2738,2025-07-17T16:17:58.054101429Z,2025-07-17T16:17:58.053935872Z,160,2,1108,A,A,2,14.03,100,130,165557,286753752,13.11,100,1,13.79,2,1,13.03,2,1,14.01,100,1,12.98,200,2,14.03,100,1,12.86,100,1,14.27,100,1,12.73,100,1,14.28,100,1,12.71,100,1,14.35,200,2,12.50,700,1,14.36,100,1,12.46,100,1,14.43,100,1,12.43,700,1,14.48,700,1,12.42,700,1,14.54,700,1,ARL,344898949
2739,2025-07-17T16:17:58.056965001Z,2025-07-17T16:17:58.056799769Z,160,2,1108,C,A,11,14.72,100,0,165232,286753926,13.11,100,1,13.79,2,1,13.03,2,1,14.01,100,1,12.98,200,2,14.03,100,1,12.86,100,1,14.27,100,1,12.73,100,1,14.28,100,1,12.71,100,1,14.35,200,2,12.50,700,1,14.36,100,1,12.46,100,1,14.43,100,1,12.43,700,1,14.48,700,1,12.42,700,1,14.54,700,1,ARL,344897989
2740,2025-07-17T16:17:58.056965001Z,2025-07-17T16:17:58.056799769Z,160,2,1108,A,A,13,14.96,100,130,165232,286753926,13.11,100,1,13.79,2,1,13.03,2,1,14.01,100,1,12.98,200,2,14.03,100,1,12.86,100,1,14.27,100,1,12.73,100,1,14.28,100,1,12.71,100,1,14.35,200,2,12.50,700,1,14.36,100,1,12.46,100,1,14.43,100,1,12.43,700,1,14.48,700,1,12.42,700,1,14.54,700,1,ARL,344899081
2741,2025-07-17T16:17:58.057809322Z,2025-07-17T16:17:58.057644161Z,160,2,1108,C,A,17,15.82,100,0,165161,286753935,13.11,100,1,13.79,2,1,13.03,2,1,14.01,100,1,12.98,200,2,14.03,100,1,12.86,100,1,14.27,100,1,12.73,100,1,14.28,100,1,12.71,100,1,14.35,200,2,12.50,700,1,14.36,100,1,12.46,100,1,14.43,100,1,12.43,700,1,14.48,700,1,12.42,700,1,14.54,700,1,ARL,344898677
2742,2025-07-17T16:17:58.057809322Z,2025-07-17T16:17:58.057644161Z,160,2,1108,A,A,17,16.08,100,130,165161,286753935,13.11,100,1,13.79,2,1,13.03,2,1,14.01,100,1,12.98,200,2,14.03,100,1,12.86,100,1,14.27,100,1,12.73,100,1,14.28,100,1,12.71,100,1,14.35,200,2,12.50,700,1,14.36,100,1,12.46,100,1,14.43,100,1,12.43,700,1,14.48,700,1,12.42,700,1,14.54,700,1,ARL,344899093
2743,2025-07-17T16:17:58.061670860Z,2025-07-17T16:17:58.061505885Z,160,2,1108,C,A,2,14.03,100,130,164975,286754272,13.11,100,1,13.79,2,1,13.03,2,1,14.01,100,1,12.98,200,2,14.27,100,1,12.86,100,1,14.28,100,1,12.73,100,1,14.35,200,2,12.71,100,1,14.36,100,1,12.50,700,1,14.43,100,1,12.46,100,1,14.48,700,1,12.43,700,1,14.54,700,1,12.42,700,1,14.56,700,1,ARL,344898949
2744,2025-07-17T16:17:58.061730836Z,2025-07-17T16:17:58.061563628Z,160,2,1108,A,A,2,14.25,100,130,167208,286754286,13.11,100,1,13.79,2,1,13.03,2,1,14.01,100,1,12.98,200,2,14.25,100,1,12.86,100,1,14.27,100,1,12.73,100,1,14.28,100,1,12.71,100,1,14.35,200,2,12.50,700,1,14.36,100,1,12.46,100,1,14.43,100,1,12.43,700,1,14.48,700,1,12.42,700,1,14.54,700,1,ARL,344899417
2745,2025-07-17T16:17:58.062137122Z,2025-07-17T16:17:58.061971960Z,160,2,1108,C,A,19,17.47,100,0,165162,286754339,13.11,100,1,13.79,2,1,13.03,2,1,14.01,100,1,12.98,200,2,14.25,100,1,12.86,100,1,14.27,100,1,12.73,100,1,14.28,100,1,12.71,100,1,14.35,200,2,12.50,700,1,14.36,100,1,12.46,100,1,14.43,100,1,12.43,700,1,14.48,700,1,12.42,700,1,14.54,700,1,ARL,344898485
2746,2025-07-17T16:17:58.062137122Z,2025-07-17T16:17:58.061971960Z,160,2,1108,A,A,19,17.76,100,130,165162,286754339,13.11,100,1,13.79,2,1,13.03,2,1,14.01,100,1,12.98,200,2,14.25,100,1,12.86,100,1,14.27,100,1,12.73,100,1,14.28,100,1,12.71,100,1,14.35,200,2,12.50,700,1,14.36,100,1,12.46,100,1,14.43,100,1,12.43,700,1,14.48,700,1,12.42,700,1,14.54,700,1,ARL,344899449
2747,2025-07-17T16:17:58.086582033Z,2025-07-17T16:17:58.086415950Z,160,2,1108,C,A,3,14.27,100,0,166083,286754819,13.11,100,1,13.79,2,1,13.03,2,1,14.01,100,1,12.98,200,2,14.25,100,1,12.86,100,1,14.28,100,1,12.73,100,1,14.35,200,2,12.71,100,1,14.36,100,1,12.50,700,1,14.43,100,1,12.46,100,1,14.48,700,1,12.43,700,1,14.54,700,1,12.42,700,1,14.56,700,1,ARL,344608225
2748,2025-07-17T16:17:58.086582033Z,2025-07-17T16:17:58.086415950Z,160,2,1108,A,A,8,14.54,100,130,166083,286754819,13.11,100,1,13.79,2,1,13.03,2,1,14.01,100,1,12.98,200,2,14.25,100,1,12.86,100,1,14.28,100,1,12.73,100,1,14.35,200,2,12.71,100,1,14.36,100,1,12.50,700,1,14.43,100,1,12.46,100,1,14.48,700,1,12.43,700,1,14.54,800,2,12.42,700,1,14.56,700,1,ARL,344899913
2749,2025-07-17T16:17:58.087829372Z,2025-07-17T16:17:58.087663773Z,160,2,1108,C,A,10,14.82,100,0,165599,286754826,13.11,100,1,13.79,2,1,13.03,2,1,14.01,100,1,12.98,200,2,14.25,100,1,12.86,100,1,14.28,100,1,12.73,100,1,14.35,200,2,12.71,100,1,14.36,100,1,12.50,700,1,14.43,100,1,12.46,100,1,14.48,700,1,12.43,700,1,14.54,800,2,12.42,700,1,14.56,700,1,ARL,344897945
2750,2025-07-17T16:17:58.087829372Z,2025-07-17T16:17:58.087663773Z,160,2,1108,A,A,12,15.05,100,130,165599,286754826,13.11,100,1,13.79,2,1,13.03,2,1,14.01,100,1,12.98,200,2,14.25,100,1,12.86,100,1,14.28,100,1,12.73,100,1,14.35,200,2,12.71,100,1,14.36,100,1,12.50,700,1,14.43,100,1,12.46,100,1,14.48,700,1,12.43,700,1,14.54,800,2,12.42,700,1,14.56,700,1,ARL,344899937
2751,2025-07-17T16:17:58.113382320Z,2025-07-17T16:17:58.113216665Z,160,2,1108,C,A,10,14.83,100,0,165655,286755076,13.11,100,1,13.79,2,1,13.03,2,1,14.01,100,1,12.98,200,2,14.25,100,1,12.86,100,1,14.28,100,1,12.73,100,1,14.35,200,2,12.71,100,1,14.36,100,1,12.50,700,1,14.43,100,1,12.46,100,1,14.48,700,1,12.43,700,1,14.54,800,2,12.42,700,1,14.56,700,1,ARL,344609897
2752,2025-07-17T16:17:58.113382320Z,2025-07-17T16:17:58.113216665Z,160,2,1108,A,A,14,15.38,100,130,165655,286755076,13.11,100,1,13.79,2,1,13.03,2,1,14.01,100,1,12.98,200,2,14.25,100,1,12.86,100,1,14.28,100,1,12.73,100,1,14.35,200,2,12.71,100,1,14.36,100,1,12.50,700,1,14.43,100,1,12.46,100,1,14.48,700,1,12.43,700,1,14.54,800,2,12.42,700,1,14.56,700,1,ARL,344900289
2753,2025-07-17T16:17:58.145548497Z,2025-07-17T16:17:58.145382853Z,160,2,1108,C,A,6,14.43,100,0,165644,286755340,13.11,100,1,13.79,2,1,13.03,2,1,14.01,100,1,12.98,200,2,14.25,100,1,12.86,100,1,14.28,100,1,12.73,100,1,14.35,200,2,12.71,100,1,14.36,100,1,12.50,700,1,14.48,700,1,12.46,100,1,14.54,800,2,12.43,700,1,14.56,700,1,12.42,700,1,14.96,100,1,ARL,344610073
2754,2025-07-17T16:17:58.145548497Z,2025-07-17T16:17:58.145382853Z,160,2,1108,A,A,9,14.96,100,130,165644,286755340,13.11,100,1,13.79,2,1,13.03,2,1,14.01,100,1,12.98,200,2,14.25,100,1,12.86,100,1,14.28,100,1,12.73,100,1,14.35,200,2,12.71,100,1,14.36,100,1,12.50,700,1,14.48,700,1,12.46,100,1,14.54,800,2,12.43,700,1,14.56,700,1,12.42,700,1,14.96,200,2,ARL,344900597
2755,2025-07-17T16:17:58.173831273Z,2025-07-17T16:17:58.173665745Z,160,2,1108,A,A,9,14.81,100,130,165528,286755602,13.11,100,1,13.79,2,1,13.03,2,1,14.01,100,1,12.98,200,2,14.25,100,1,12.86,100,1,14.28,100,1,12.73,100,1,14.35,200,2,12.71,100,1,14.36,100,1,12.50,700,1,14.48,700,1,12.46,100,1,14.54,800,2,12.43,700,1,14.56,700,1,12.42,700,1,14.81,100,1,ARL,344900925
2756,2025-07-17T16:17:58.173852767Z,2025-07-17T16:17:58.173687330Z,160,2,1108,C,A,3,14.28,100,130,165437,286755603,13.11,100,1,13.79,2,1,13.03,2,1,14.01,100,1,12.98,200,2,14.25,100,1,12.86,100,1,14.35,200,2,12.73,100,1,14.36,100,1,12.71,100,1,14.48,700,1,12.50,700,1,14.54,800,2,12.46,100,1,14.56,700,1,12.43,700,1,14.81,100,1,12.42,700,1,14.96,200,2,ARL,344615393
2757,2025-07-17T16:17:58.235788576Z,2025-07-17T16:17:58.235623452Z,160,2,1108,A,A,8,14.68,700,130,165124,286756143,13.11,100,1,13.79,2,1,13.03,2,1,14.01,100,1,12.98,200,2,14.25,100,1,12.86,100,1,14.35,200,2,12.73,100,1,14.36,100,1,12.71,100,1,14.48,700,1,12.50,700,1,14.54,800,2,12.46,100,1,14.56,700,1,12.43,700,1,14.68,700,1,12.42,700,1,14.81,100,1,ARL,344902153
2758,2025-07-17T16:17:58.502856372Z,2025-07-17T16:17:58.502691073Z,160,2,1108,A,A,6,14.53,100,130,165299,286758830,13.11,100,1,13.79,2,1,13.03,2,1,14.01,100,1,12.98,200,2,14.25,100,1,12.86,100,1,14.35,200,2,12.73,100,1,14.36,100,1,12.71,100,1,14.48,700,1,12.50,700,1,14.53,100,1,12.46,100,1,14.54,800,2,12.43,700,1,14.56,700,1,12.42,700,1,14.68,700,1,ARL,344905321
2759,2025-07-17T16:17:58.502858100Z,2025-07-17T16:17:58.502692641Z,160,2,1108,C,A,1,14.01,100,130,165459,286758831,13.11,100,1,13.79,2,1,13.03,2,1,14.25,100,1,12.98,200,2,14.35,200,2,12.86,100,1,14.36,100,1,12.73,100,1,14.48,700,1,12.71,100,1,14.53,100,1,12.50,700,1,14.54,800,2,12.46,100,1,14.56,700,1,12.43,700,1,14.68,700,1,12.42,700,1,14.81,100,1,ARL,344612049
2760,2025-07-17T16:17:58.704865076Z,2025-07-17T16:17:58.704699676Z,160,2,1108,C,A,3,14.36,100,130,165400,286760091,13.11,100,1,13.79,2,1,13.03,2,1,14.25,100,1,12.98,200,2,14.35,200,2,12.86,100,1,14.48,700,1,12.73,100,1,14.53,100,1,12.71,100,1,14.54,800,2,12.50,700,1,14.56,700,1,12.46,100,1,14.68,700,1,12.43,700,1,14.81,100,1,12.42,700,1,14.96,200,2,ARL,344897953
2761,2025-07-17T16:17:58.705216838Z,2025-07-17T16:17:58.705051532Z,160,2,1108,A,A,7,14.60,100,130,165306,286760096,13.11,100,1,13.79,2,1,13.03,2,1,14.25,100,1,12.98,200,2,14.35,200,2,12.86,100,1,14.48,700,1,12.73,100,1,14.53,100,1,12.71,100,1,14.54,800,2,12.50,700,1,14.56,700,1,12.46,100,1,14.60,100,1,12.43,700,1,14.68,700,1,12.42,700,1,14.81,100,1,ARL,344906945
2762,2025-07-17T16:17:59.086439158Z,2025-07-17T16:17:59.086273873Z,160,2,1108,C,A,5,14.54,100,130,165285,286766349,13.11,100,1,13.79,2,1,13.03,2,1,14.25,100,1,12.98,200,2,14.35,200,2,12.86,100,1,14.48,700,1,12.73,100,1,14.53,100,1,12.71,100,1,14.54,700,1,12.50,700,1,14.56,700,1,12.46,100,1,14.60,100,1,12.43,700,1,14.68,700,1,12.42,700,1,14.81,100,1,ARL,344899913
2763,2025-07-17T16:17:59.086561438Z,2025-07-17T16:17:59.086395964Z,160,2,1108,A,A,9,14.77,100,130,165474,286766355,13.11,100,1,13.79,2,1,13.03,2,1,14.25,100,1,12.98,200,2,14.35,200,2,12.86,100,1,14.48,700,1,12.73,100,1,14.53,100,1,12.71,100,1,14.54,700,1,12.50,700,1,14.56,700,1,12.46,100,1,14.60,100,1,12.43,700,1,14.68,700,1,12.42,700,1,14.77,100,1,ARL,344914361
2764,2025-07-17T16:18:02.178629167Z,2025-07-17T16:18:02.178463984Z,160,2,1108,A,A,1,13.80,100,130,165183,286829047,13.11,100,1,13.79,2,1,13.03,2,1,13.80,100,1,12.98,200,2,14.25,100,1,12.86,100,1,14.35,200,2,12.73,100,1,14.48,700,1,12.71,100,1,14.53,100,1,12.50,700,1,14.54,700,1,12.46,100,1,14.56,700,1,12.43,700,1,14.60,100,1,12.42,700,1,14.68,700,1,ARL,344989393
2765,2025-07-17T16:18:02.179379565Z,2025-07-17T16:18:02.179214149Z,160,2,1108,C,A,13,15.05,100,0,165416,286829057,13.11,100,1,13.79,2,1,13.03,2,1,13.80,100,1,12.98,200,2,14.25,100,1,12.86,100,1,14.35,200,2,12.73,100,1,14.48,700,1,12.71,100,1,14.53,100,1,12.50,700,1,14.54,700,1,12.46,100,1,14.56,700,1,12.43,700,1,14.60,100,1,12.42,700,1,14.68,700,1,ARL,344899937
2766,2025-07-17T16:18:02.179379565Z,2025-07-17T16:18:02.179214149Z,160,2,1108,A,A,12,14.87,100,130,165416,286829057,13.11,100,1,13.79,2,1,13.03,2,1,13.80,100,1,12.98,200,2,14.25,100,1,12.86,100,1,14.35,200,2,12.73,100,1,14.48,700,1,12.71,100,1,14.53,100,1,12.50,700,1,14.54,700,1,12.46,100,1,14.56,700,1,12.43,700,1,14.60,100,1,12.42,700,1,14.68,700,1,ARL,344989421
2767,2025-07-17T16:18:02.181473898Z,2025-07-17T16:18:02.181307241Z,160,2,1108,C,A,13,14.96,100,0,166657,286829106,13.11,100,1,13.79,2,1,13.03,2,1,13.80,100,1,12.98,200,2,14.25,100,1,12.86,100,1,14.35,200,2,12.73,100,1,14.48,700,1,12.71,100,1,14.53,100,1,12.50,700,1,14.54,700,1,12.46,100,1,14.56,700,1,12.43,700,1,14.60,100,1,12.42,700,1,14.68,700,1,ARL,344899081
2768,2025-07-17T16:18:02.181473898Z,2025-07-17T16:18:02.181307241Z,160,2,1108,A,A,10,14.77,100,128,166657,286829106,13.11,100,1,13.79,2,1,13.03,2,1,13.80,100,1,12.98,200,2,14.25,100,1,12.86,100,1,14.35,200,2,12.73,100,1,14.48,700,1,12.71,100,1,14.53,100,1,12.50,700,1,14.54,700,1,12.46,100,1,14.56,700,1,12.43,700,1,14.60,100,1,12.42,700,1,14.68,700,1,ARL,344989525
2769,2025-07-17T16:18:02.182474498Z,2025-07-17T16:18:02.182309015Z,160,2,1108,C,A,20,17.76,100,0,165483,286829137,13.11,100,1,13.79,2,1,13.03,2,1,13.80,100,1,12.98,200,2,14.25,100,1,12.86,100,1,14.35,200,2,12.73,100,1,14.48,700,1,12.71,100,1,14.53,100,1,12.50,700,1,14.54,700,1,12.46,100,1,14.56,700,1,12.43,700,1,14.60,100,1,12.42,700,1,14.68,700,1,ARL,344899449
2770,2025-07-17T16:18:02.182474498Z,2025-07-17T16:18:02.182309015Z,160,2,1108,A,A,20,17.53,100,130,165483,286829137,13.11,100,1,13.79,2,1,13.03,2,1,13.80,100,1,12.98,200,2,14.25,100,1,12.86,100,1,14.35,200,2,12.73,100,1,14.48,700,1,12.71,100,1,14.53,100,1,12.50,700,1,14.54,700,1,12.46,100,1,14.56,700,1,12.43,700,1,14.60,100,1,12.42,700,1,14.68,700,1,ARL,344989557
2771,2025-07-17T16:18:02.184788371Z,2025-07-17T16:18:02.184622698Z,160,2,1108,C,A,2,14.25,100,130,165673,286829173,13.11,100,1,13.79,2,1,13.03,2,1,13.80,100,1,12.98,200,2,14.35,200,2,12.86,100,1,14.48,700,1,12.73,100,1,14.53,100,1,12.71,100,1,14.54,700,1,12.50,700,1,14.56,700,1,12.46,100,1,14.60,100,1,12.43,700,1,14.68,700,1,12.42,700,1,14.77,200,2,ARL,344899417
2772,2025-07-17T16:18:02.184840010Z,2025-07-17T16:18:02.184674810Z,160,2,1108,A,A,2,14.08,100,130,165200,286829174,13.11,100,1,13.79,2,1,13.03,2,1,13.80,100,1,12.98,200,2,14.08,100,1,12.86,100,1,14.35,200,2,12.73,100,1,14.48,700,1,12.71,100,1,14.53,100,1,12.50,700,1,14.54,700,1,12.46,100,1,14.56,700,1,12.43,700,1,14.60,100,1,12.42,700,1,14.68,700,1,ARL,344989601
2773,2025-07-17T16:18:02.186910586Z,2025-07-17T16:18:02.186745185Z,160,2,1108,C,A,10,14.77,100,0,165401,286829206,13.11,100,1,13.79,2,1,13.03,2,1,13.80,100,1,12.98,200,2,14.08,100,1,12.86,100,1,14.35,200,2,12.73,100,1,14.48,700,1,12.71,100,1,14.53,100,1,12.50,700,1,14.54,700,1,12.46,100,1,14.56,700,1,12.43,700,1,14.60,100,1,12.42,700,1,14.68,700,1,ARL,344914361
2774,2025-07-17T16:18:02.186910586Z,2025-07-17T16:18:02.186745185Z,160,2,1108,A,A,8,14.59,100,130,165401,286829206,13.11,100,1,13.79,2,1,13.03,2,1,13.80,100,1,12.98,200,2,14.08,100,1,12.86,100,1,14.35,200,2,12.73,100,1,14.48,700,1,12.71,100,1,14.53,100,1,12.50,700,1,14.54,700,1,12.46,100,1,14.56,700,1,12.43,700,1,14.59,100,1,12.42,700,1,14.60,100,1,ARL,344989661
2775,2025-07-17T16:18:02.189536873Z,2025-07-17T16:18:02.189371317Z,160,2,1108,C,A,19,16.08,100,0,165556,286829251,13.11,100,1,13.79,2,1,13.03,2,1,13.80,100,1,12.98,200,2,14.08,100,1,12.86,100,1,14.35,200,2,12.73,100,1,14.48,700,1,12.71,100,1,14.53,100,1,12.50,700,1,14.54,700,1,12.46,100,1,14.56,700,1,12.43,700,1,14.59,100,1,12.42,700,1,14.60,100,1,ARL,344899093
