 ,ts_recv,ts_event,rtype,publisher_id,instrument_id,action,side,depth,price,size,flags,ts_in_delta,sequence,bid_px_00,bid_sz_00,bid_ct_00,ask_px_00,ask_sz_00,ask_ct_00,bid_px_01,bid_sz_01,bid_ct_01,ask_px_01,ask_sz_01,ask_ct_01,bid_px_02,bid_sz_02,bid_ct_02,ask_px_02,ask_sz_02,ask_ct_02,bid_px_03,bid_sz_03,bid_ct_03,ask_px_03,ask_sz_03,ask_ct_03,bid_px_04,bid_sz_04,bid_ct_04,ask_px_04,ask_sz_04,ask_ct_04,bid_px_05,bid_sz_05,bid_ct_05,ask_px_05,ask_sz_05,ask_ct_05,bid_px_06,bid_sz_06,bid_ct_06,ask_px_06,ask_sz_06,ask_ct_06,bid_px_07,bid_sz_07,bid_ct_07,ask_px_07,ask_sz_07,ask_ct_07,bid_px_08,bid_sz_08,bid_ct_08,ask_px_08,ask_sz_08,ask_ct_08,bid_px_09,bid_sz_09,bid_ct_09,ask_px_09,ask_sz_09,ask_ct_09,symbol,order_id
578,2025-07-17T13:46:10.551481906Z,2025-07-17T13:46:10.551316402Z,160,2,1108,C,A,2,14.47,100,0,165504,69614455,13.25,11,1,14.20,2,1,12.99,100,1,14.30,200,2,12.88,2,1,14.48,100,1,12.73,100,1,14.59,100,1,12.67,100,1,14.76,100,1,12.47,100,1,14.83,100,1,12.46,100,1,14.91,700,1,12.43,700,1,14.95,700,1,12.42,700,1,14.99,700,1,12.37,700,1,15.14,700,1,ARL,84608321
579,2025-07-17T13:46:10.551481906Z,2025-07-17T13:46:10.551316402Z,160,2,1108,A,A,9,15.09,100,130,165504,69614455,13.25,11,1,14.20,2,1,12.99,100,1,14.30,200,2,12.88,2,1,14.48,100,1,12.73,100,1,14.59,100,1,12.67,100,1,14.76,100,1,12.47,100,1,14.83,100,1,12.46,100,1,14.91,700,1,12.43,700,1,14.95,700,1,12.42,700,1,14.99,700,1,12.37,700,1,15.09,100,1,ARL,84650629
580,2025-07-17T13:46:10.904838107Z,2025-07-17T13:46:10.904672934Z,160,2,1108,A,A,11,15.16,100,130,165173,69628781,13.25,11,1,14.20,2,1,12.99,100,1,14.30,200,2,12.88,2,1,14.48,100,1,12.73,100,1,14.59,100,1,12.67,100,1,14.76,100,1,12.47,100,1,14.83,100,1,12.46,100,1,14.91,700,1,12.43,700,1,14.95,700,1,12.42,700,1,14.99,700,1,12.37,700,1,15.09,100,1,ARL,84668677
581,2025-07-17T13:46:10.904858553Z,2025-07-17T13:46:10.904693578Z,160,2,1108,C,A,4,14.76,100,130,164975,69628783,13.25,11,1,14.20,2,1,12.99,100,1,14.30,200,2,12.88,2,1,14.48,100,1,12.73,100,1,14.59,100,1,12.67,100,1,14.83,100,1,12.47,100,1,14.91,700,1,12.46,100,1,14.95,700,1,12.43,700,1,14.99,700,1,12.42,700,1,15.09,100,1,12.37,700,1,15.14,700,1,ARL,84618189
582,2025-07-17T13:46:11.840882444Z,2025-07-17T13:46:11.840717150Z,160,2,1108,A,A,5,14.87,100,130,165294,69663346,13.25,11,1,14.20,2,1,12.99,100,1,14.30,200,2,12.88,2,1,14.48,100,1,12.73,100,1,14.59,100,1,12.67,100,1,14.83,100,1,12.47,100,1,14.87,100,1,12.46,100,1,14.91,700,1,12.43,700,1,14.95,700,1,12.42,700,1,14.99,700,1,12.37,700,1,15.09,100,1,ARL,84708037
583,2025-07-17T13:46:11.840894787Z,2025-07-17T13:46:11.840729407Z,160,2,1108,C,A,2,14.48,100,130,165380,69663347,13.25,11,1,14.20,2,1,12.99,100,1,14.30,200,2,12.88,2,1,14.59,100,1,12.73,100,1,14.83,100,1,12.67,100,1,14.87,100,1,12.47,100,1,14.91,700,1,12.46,100,1,14.95,700,1,12.43,700,1,14.99,700,1,12.42,700,1,15.09,100,1,12.37,700,1,15.14,700,1,ARL,84624129
584,2025-07-17T13:46:23.920813185Z,2025-07-17T13:46:23.920647302Z,160,2,1108,C,B,2,12.88,2,0,165883,70104076,13.25,11,1,14.20,2,1,12.99,100,1,14.30,200,2,12.73,100,1,14.59,100,1,12.67,100,1,14.83,100,1,12.47,100,1,14.87,100,1,12.46,100,1,14.91,700,1,12.43,700,1,14.95,700,1,12.42,700,1,14.99,700,1,12.37,700,1,15.09,100,1,12.36,200,2,15.14,700,1,ARL,58709193
585,2025-07-17T13:46:23.920813185Z,2025-07-17T13:46:23.920647302Z,160,2,1108,A,B,1,13.12,2,130,165883,70104076,13.25,11,1,14.20,2,1,13.12,2,1,14.30,200,2,12.99,100,1,14.59,100,1,12.73,100,1,14.83,100,1,12.67,100,1,14.87,100,1,12.47,100,1,14.91,700,1,12.46,100,1,14.95,700,1,12.43,700,1,14.99,700,1,12.42,700,1,15.09,100,1,12.37,700,1,15.14,700,1,ARL,85194077
586,2025-07-17T13:46:45.786579604Z,2025-07-17T13:46:45.786413307Z,160,2,1108,C,B,1,13.12,2,0,166297,70834235,13.25,11,1,14.20,2,1,12.99,100,1,14.30,200,2,12.73,100,1,14.59,100,1,12.67,100,1,14.83,100,1,12.47,100,1,14.87,100,1,12.46,100,1,14.91,700,1,12.43,700,1,14.95,700,1,12.42,700,1,14.99,700,1,12.37,700,1,15.09,100,1,12.36,200,2,15.14,700,1,ARL,85194077
587,2025-07-17T13:46:45.786579604Z,2025-07-17T13:46:45.786413307Z,160,2,1108,A,B,1,13.20,2,130,166297,70834235,13.25,11,1,14.20,2,1,13.20,2,1,14.30,200,2,12.99,100,1,14.59,100,1,12.73,100,1,14.83,100,1,12.67,100,1,14.87,100,1,12.47,100,1,14.91,700,1,12.46,100,1,14.95,700,1,12.43,700,1,14.99,700,1,12.42,700,1,15.09,100,1,12.37,700,1,15.14,700,1,ARL,86056033
588,2025-07-17T13:47:34.987167177Z,2025-07-17T13:47:34.987001473Z,160,2,1108,C,B,1,13.20,2,0,165704,72269967,13.25,11,1,14.20,2,1,12.99,100,1,14.30,200,2,12.73,100,1,14.59,100,1,12.67,100,1,14.83,100,1,12.47,100,1,14.87,100,1,12.46,100,1,14.91,700,1,12.43,700,1,14.95,700,1,12.42,700,1,14.99,700,1,12.37,700,1,15.09,100,1,12.36,200,2,15.14,700,1,ARL,86056033
589,2025-07-17T13:47:34.987167177Z,2025-07-17T13:47:34.987001473Z,160,2,1108,A,B,0,13.26,2,130,165704,72269967,13.26,2,1,14.20,2,1,13.25,11,1,14.30,200,2,12.99,100,1,14.59,100,1,12.73,100,1,14.83,100,1,12.67,100,1,14.87,100,1,12.47,100,1,14.91,700,1,12.46,100,1,14.95,700,1,12.43,700,1,14.99,700,1,12.42,700,1,15.09,100,1,12.37,700,1,15.14,700,1,ARL,87750309
590,2025-07-17T13:49:46.533586484Z,2025-07-17T13:49:46.533420775Z,160,2,1108,C,A,1,14.30,100,0,165709,76393090,13.26,2,1,14.20,2,1,13.25,11,1,14.30,100,1,12.99,100,1,14.59,100,1,12.73,100,1,14.83,100,1,12.67,100,1,14.87,100,1,12.47,100,1,14.91,700,1,12.46,100,1,14.95,700,1,12.43,700,1,14.99,700,1,12.42,700,1,15.09,100,1,12.37,700,1,15.14,700,1,ARL,77910357
591,2025-07-17T13:49:46.533586484Z,2025-07-17T13:49:46.533420775Z,160,2,1108,A,A,12,15.26,100,130,165709,76393090,13.26,2,1,14.20,2,1,13.25,11,1,14.30,100,1,12.99,100,1,14.59,100,1,12.73,100,1,14.83,100,1,12.67,100,1,14.87,100,1,12.47,100,1,14.91,700,1,12.46,100,1,14.95,700,1,12.43,700,1,14.99,700,1,12.42,700,1,15.09,100,1,12.37,700,1,15.14,700,1,ARL,92510725
592,2025-07-17T13:49:46.533732414Z,2025-07-17T13:49:46.533566805Z,160,2,1108,C,A,1,14.30,100,0,165609,76393092,13.26,2,1,14.20,2,1,13.25,11,1,14.59,100,1,12.99,100,1,14.83,100,1,12.73,100,1,14.87,100,1,12.67,100,1,14.91,700,1,12.47,100,1,14.95,700,1,12.46,100,1,14.99,700,1,12.43,700,1,15.09,100,1,12.42,700,1,15.14,700,1,12.37,700,1,15.16,100,1,ARL,74589605
593,2025-07-17T13:49:46.533732414Z,2025-07-17T13:49:46.533566805Z,160,2,1108,A,A,11,15.26,100,130,165609,76393092,13.26,2,1,14.20,2,1,13.25,11,1,14.59,100,1,12.99,100,1,14.83,100,1,12.73,100,1,14.87,100,1,12.67,100,1,14.91,700,1,12.47,100,1,14.95,700,1,12.46,100,1,14.99,700,1,12.43,700,1,15.09,100,1,12.42,700,1,15.14,700,1,12.37,700,1,15.16,100,1,ARL,92510729
594,2025-07-17T13:49:46.533768662Z,2025-07-17T13:49:46.533603070Z,160,2,1108,C,A,4,14.91,700,130,165592,76393093,13.26,2,1,14.20,2,1,13.25,11,1,14.59,100,1,12.99,100,1,14.83,100,1,12.73,100,1,14.87,100,1,12.67,100,1,14.95,700,1,12.47,100,1,14.99,700,1,12.46,100,1,15.09,100,1,12.43,700,1,15.14,700,1,12.42,700,1,15.16,100,1,12.37,700,1,15.20,100,1,ARL,84628761
595,2025-07-17T13:49:46.533810238Z,2025-07-17T13:49:46.533644528Z,160,2,1108,A,A,6,15.07,700,130,165710,76393094,13.26,2,1,14.20,2,1,13.25,11,1,14.59,100,1,12.99,100,1,14.83,100,1,12.73,100,1,14.87,100,1,12.67,100,1,14.95,700,1,12.47,100,1,14.99,700,1,12.46,100,1,15.07,700,1,12.43,700,1,15.09,100,1,12.42,700,1,15.14,700,1,12.37,700,1,15.16,100,1,ARL,92510741
596,2025-07-17T13:49:46.534488891Z,2025-07-17T13:49:46.534323177Z,160,2,1108,C,A,14,15.41,100,0,165714,76393099,13.26,2,1,14.20,2,1,13.25,11,1,14.59,100,1,12.99,100,1,14.83,100,1,12.73,100,1,14.87,100,1,12.67,100,1,14.95,700,1,12.47,100,1,14.99,700,1,12.46,100,1,15.07,700,1,12.43,700,1,15.09,100,1,12.42,700,1,15.14,700,1,12.37,700,1,15.16,100,1,ARL,84630217
597,2025-07-17T13:49:46.534488891Z,2025-07-17T13:49:46.534323177Z,160,2,1108,A,A,14,15.46,100,130,165714,76393099,13.26,2,1,14.20,2,1,13.25,11,1,14.59,100,1,12.99,100,1,14.83,100,1,12.73,100,1,14.87,100,1,12.67,100,1,14.95,700,1,12.47,100,1,14.99,700,1,12.46,100,1,15.07,700,1,12.43,700,1,15.09,100,1,12.42,700,1,15.14,700,1,12.37,700,1,15.16,100,1,ARL,92510753
598,2025-07-17T13:49:46.534555834Z,2025-07-17T13:49:46.534390219Z,160,2,1108,C,A,10,15.20,100,0,165615,76393100,13.26,2,1,14.20,2,1,13.25,11,1,14.59,100,1,12.99,100,1,14.83,100,1,12.73,100,1,14.87,100,1,12.67,100,1,14.95,700,1,12.47,100,1,14.99,700,1,12.46,100,1,15.07,700,1,12.43,700,1,15.09,100,1,12.42,700,1,15.14,700,1,12.37,700,1,15.16,100,1,ARL,84628801
599,2025-07-17T13:49:46.534555834Z,2025-07-17T13:49:46.534390219Z,160,2,1108,A,A,13,15.36,100,130,165615,76393100,13.26,2,1,14.20,2,1,13.25,11,1,14.59,100,1,12.99,100,1,14.83,100,1,12.73,100,1,14.87,100,1,12.67,100,1,14.95,700,1,12.47,100,1,14.99,700,1,12.46,100,1,15.07,700,1,12.43,700,1,15.09,100,1,12.42,700,1,15.14,700,1,12.37,700,1,15.16,100,1,ARL,92510761
600,2025-07-17T13:49:46.535182699Z,2025-07-17T13:49:46.535017084Z,160,2,1108,C,A,19,16.35,100,0,165615,76393115,13.26,2,1,14.20,2,1,13.25,11,1,14.59,100,1,12.99,100,1,14.83,100,1,12.73,100,1,14.87,100,1,12.67,100,1,14.95,700,1,12.47,100,1,14.99,700,1,12.46,100,1,15.07,700,1,12.43,700,1,15.09,100,1,12.42,700,1,15.14,700,1,12.37,700,1,15.16,100,1,ARL,84629065
601,2025-07-17T13:49:46.535182699Z,2025-07-17T13:49:46.535017084Z,160,2,1108,A,A,19,16.51,100,130,165615,76393115,13.26,2,1,14.20,2,1,13.25,11,1,14.59,100,1,12.99,100,1,14.83,100,1,12.73,100,1,14.87,100,1,12.67,100,1,14.95,700,1,12.47,100,1,14.99,700,1,12.46,100,1,15.07,700,1,12.43,700,1,15.09,100,1,12.42,700,1,15.14,700,1,12.37,700,1,15.16,100,1,ARL,92510813
602,2025-07-17T13:49:46.535737854Z,2025-07-17T13:49:46.535572067Z,160,2,1108,C,A,21,18.05,100,0,165787,76393138,13.26,2,1,14.20,2,1,13.25,11,1,14.59,100,1,12.99,100,1,14.83,100,1,12.73,100,1,14.87,100,1,12.67,100,1,14.95,700,1,12.47,100,1,14.99,700,1,12.46,100,1,15.07,700,1,12.43,700,1,15.09,100,1,12.42,700,1,15.14,700,1,12.37,700,1,15.16,100,1,ARL,84628913
603,2025-07-17T13:49:46.535737854Z,2025-07-17T13:49:46.535572067Z,160,2,1108,A,A,21,18.23,100,130,165787,76393138,13.26,2,1,14.20,2,1,13.25,11,1,14.59,100,1,12.99,100,1,14.83,100,1,12.73,100,1,14.87,100,1,12.67,100,1,14.95,700,1,12.47,100,1,14.99,700,1,12.46,100,1,15.07,700,1,12.43,700,1,15.09,100,1,12.42,700,1,15.14,700,1,12.37,700,1,15.16,100,1,ARL,92510841
604,2025-07-17T13:56:11.001810226Z,2025-07-17T13:56:11.001642441Z,160,2,1108,A,B,0,13.28,1,128,167785,89819278,13.28,1,1,14.20,2,1,13.26,2,1,14.59,100,1,13.25,11,1,14.83,100,1,12.99,100,1,14.87,100,1,12.73,100,1,14.95,700,1,12.67,100,1,14.99,700,1,12.47,100,1,15.07,700,1,12.46,100,1,15.09,100,1,12.43,700,1,15.14,700,1,12.42,700,1,15.16,100,1,ARL,107702381
605,2025-07-17T13:56:11.005550129Z,2025-07-17T13:56:11.005384065Z,160,2,1108,A,B,0,13.28,10,130,166064,89819705,13.28,11,2,14.20,2,1,13.26,2,1,14.59,100,1,13.25,11,1,14.83,100,1,12.99,100,1,14.87,100,1,12.73,100,1,14.95,700,1,12.67,100,1,14.99,700,1,12.47,100,1,15.07,700,1,12.46,100,1,15.09,100,1,12.43,700,1,15.14,700,1,12.42,700,1,15.16,100,1,ARL,107702861
606,2025-07-17T13:56:11.005550669Z,2025-07-17T13:56:11.005385425Z,160,2,1108,A,A,0,13.94,10,130,165244,89819706,13.28,11,2,13.94,10,1,13.26,2,1,14.20,2,1,13.25,11,1,14.59,100,1,12.99,100,1,14.83,100,1,12.73,100,1,14.87,100,1,12.67,100,1,14.95,700,1,12.47,100,1,14.99,700,1,12.46,100,1,15.07,700,1,12.43,700,1,15.09,100,1,12.42,700,1,15.14,700,1,ARL,107702865
607,2025-07-17T13:56:11.013819857Z,2025-07-17T13:56:11.013654317Z,160,2,1108,C,A,11,15.26,100,0,165540,89820163,13.28,11,2,13.94,10,1,13.26,2,1,14.20,2,1,13.25,11,1,14.59,100,1,12.99,100,1,14.83,100,1,12.73,100,1,14.87,100,1,12.67,100,1,14.95,700,1,12.47,100,1,14.99,700,1,12.46,100,1,15.07,700,1,12.43,700,1,15.09,100,1,12.42,700,1,15.14,700,1,ARL,92510729
608,2025-07-17T13:56:11.013819857Z,2025-07-17T13:56:11.013654317Z,160,2,1108,A,A,4,14.84,100,130,165540,89820163,13.28,11,2,13.94,10,1,13.26,2,1,14.20,2,1,13.25,11,1,14.59,100,1,12.99,100,1,14.83,100,1,12.73,100,1,14.84,100,1,12.67,100,1,14.87,100,1,12.47,100,1,14.95,700,1,12.46,100,1,14.99,700,1,12.43,700,1,15.07,700,1,12.42,700,1,15.09,100,1,ARL,107703205
609,2025-07-17T13:56:11.026680779Z,2025-07-17T13:56:11.026515306Z,160,2,1108,C,A,12,15.26,100,0,165473,89820408,13.28,11,2,13.94,10,1,13.26,2,1,14.20,2,1,13.25,11,1,14.59,100,1,12.99,100,1,14.83,100,1,12.73,100,1,14.84,100,1,12.67,100,1,14.87,100,1,12.47,100,1,14.95,700,1,12.46,100,1,14.99,700,1,12.43,700,1,15.07,700,1,12.42,700,1,15.09,100,1,ARL,92510725
610,2025-07-17T13:56:11.026680779Z,2025-07-17T13:56:11.026515306Z,160,2,1108,A,A,4,14.84,100,130,165473,89820408,13.28,11,2,13.94,10,1,13.26,2,1,14.20,2,1,13.25,11,1,14.59,100,1,12.99,100,1,14.83,100,1,12.73,100,1,14.84,200,2,12.67,100,1,14.87,100,1,12.47,100,1,14.95,700,1,12.46,100,1,14.99,700,1,12.43,700,1,15.07,700,1,12.42,700,1,15.09,100,1,ARL,107703433
611,2025-07-17T13:56:11.101916770Z,2025-07-17T13:56:11.101751649Z,160,2,1108,C,B,0,13.28,1,130,165121,89823845,13.28,10,1,13.94,10,1,13.26,2,1,14.20,2,1,13.25,11,1,14.59,100,1,12.99,100,1,14.83,100,1,12.73,100,1,14.84,200,2,12.67,100,1,14.87,100,1,12.47,100,1,14.95,700,1,12.46,100,1,14.99,700,1,12.43,700,1,15.07,700,1,12.42,700,1,15.09,100,1,ARL,107702381
612,2025-07-17T13:56:19.511755342Z,2025-07-17T13:56:19.511590204Z,160,2,1108,C,B,0,13.28,10,130,165138,90148349,13.26,2,1,13.94,10,1,13.25,11,1,14.20,2,1,12.99,100,1,14.59,100,1,12.73,100,1,14.83,100,1,12.67,100,1,14.84,200,2,12.47,100,1,14.87,100,1,12.46,100,1,14.95,700,1,12.43,700,1,14.99,700,1,12.42,700,1,15.07,700,1,12.37,700,1,15.09,100,1,ARL,107702861
613,2025-07-17T13:56:22.512134723Z,2025-07-17T13:56:22.511968820Z,160,2,1108,C,A,0,13.94,10,130,165903,90281309,13.26,2,1,14.20,2,1,13.25,11,1,14.59,100,1,12.99,100,1,14.83,100,1,12.73,100,1,14.84,200,2,12.67,100,1,14.87,100,1,12.47,100,1,14.95,700,1,12.46,100,1,14.99,700,1,12.43,700,1,15.07,700,1,12.42,700,1,15.09,100,1,12.37,700,1,15.14,700,1,ARL,107702865
614,2025-07-17T13:56:22.517155918Z,2025-07-17T13:56:22.516990420Z,160,2,1108,C,A,3,14.84,100,0,165498,90281853,13.26,2,1,14.20,2,1,13.25,11,1,14.59,100,1,12.99,100,1,14.83,100,1,12.73,100,1,14.84,100,1,12.67,100,1,14.87,100,1,12.47,100,1,14.95,700,1,12.46,100,1,14.99,700,1,12.43,700,1,15.07,700,1,12.42,700,1,15.09,100,1,12.37,700,1,15.14,700,1,ARL,107703205
615,2025-07-17T13:56:22.517155918Z,2025-07-17T13:56:22.516990420Z,160,2,1108,A,A,11,15.26,100,130,165498,90281853,13.26,2,1,14.20,2,1,13.25,11,1,14.59,100,1,12.99,100,1,14.83,100,1,12.73,100,1,14.84,100,1,12.67,100,1,14.87,100,1,12.47,100,1,14.95,700,1,12.46,100,1,14.99,700,1,12.43,700,1,15.07,700,1,12.42,700,1,15.09,100,1,12.37,700,1,15.14,700,1,ARL,108217045
616,2025-07-17T13:56:22.517527654Z,2025-07-17T13:56:22.517362170Z,160,2,1108,C,A,3,14.84,100,0,165484,90281893,13.26,2,1,14.20,2,1,13.25,11,1,14.59,100,1,12.99,100,1,14.83,100,1,12.73,100,1,14.87,100,1,12.67,100,1,14.95,700,1,12.47,100,1,14.99,700,1,12.46,100,1,15.07,700,1,12.43,700,1,15.09,100,1,12.42,700,1,15.14,700,1,12.37,700,1,15.16,100,1,ARL,107703433
617,2025-07-17T13:56:22.517527654Z,2025-07-17T13:56:22.517362170Z,160,2,1108,A,A,10,15.26,100,130,165484,90281893,13.26,2,1,14.20,2,1,13.25,11,1,14.59,100,1,12.99,100,1,14.83,100,1,12.73,100,1,14.87,100,1,12.67,100,1,14.95,700,1,12.47,100,1,14.99,700,1,12.46,100,1,15.07,700,1,12.43,700,1,15.09,100,1,12.42,700,1,15.14,700,1,12.37,700,1,15.16,100,1,ARL,108217173
618,2025-07-17T13:56:40.757800894Z,2025-07-17T13:56:40.757635216Z,160,2,1108,C,A,0,14.20,2,0,165678,90866180,13.26,2,1,14.59,100,1,13.25,11,1,14.83,100,1,12.99,100,1,14.87,100,1,12.73,100,1,14.95,700,1,12.67,100,1,14.99,700,1,12.47,100,1,15.07,700,1,12.46,100,1,15.09,100,1,12.43,700,1,15.14,700,1,12.42,700,1,15.16,100,1,12.37,700,1,15.26,200,2,ARL,84628773
619,2025-07-17T13:56:40.757800894Z,2025-07-17T13:56:40.757635216Z,160,2,1108,A,A,0,14.36,2,130,165678,90866180,13.26,2,1,14.36,2,1,13.25,11,1,14.59,100,1,12.99,100,1,14.83,100,1,12.73,100,1,14.87,100,1,12.67,100,1,14.95,700,1,12.47,100,1,14.99,700,1,12.46,100,1,15.07,700,1,12.43,700,1,15.09,100,1,12.42,700,1,15.14,700,1,12.37,700,1,15.16,100,1,ARL,108872153
620,2025-07-17T13:57:40.142022323Z,2025-07-17T13:57:40.141855674Z,160,2,1108,C,B,0,13.26,2,0,166649,92821039,13.25,11,1,14.36,2,1,12.99,100,1,14.59,100,1,12.73,100,1,14.83,100,1,12.67,100,1,14.87,100,1,12.47,100,1,14.95,700,1,12.46,100,1,14.99,700,1,12.43,700,1,15.07,700,1,12.42,700,1,15.09,100,1,12.37,700,1,15.14,700,1,12.36,200,2,15.16,100,1,ARL,87750309
621,2025-07-17T13:57:40.142022323Z,2025-07-17T13:57:40.141855674Z,160,2,1108,A,B,1,13.12,2,128,166649,92821039,13.25,11,1,14.36,2,1,13.12,2,1,14.59,100,1,12.99,100,1,14.83,100,1,12.73,100,1,14.87,100,1,12.67,100,1,14.95,700,1,12.47,100,1,14.99,700,1,12.46,100,1,15.07,700,1,12.43,700,1,15.09,100,1,12.42,700,1,15.14,700,1,12.37,700,1,15.16,100,1,ARL,111169049
622,2025-07-17T13:57:44.947757237Z,2025-07-17T13:57:44.947591620Z,160,2,1108,C,A,0,14.36,2,0,165617,92961696,13.25,11,1,14.59,100,1,13.12,2,1,14.83,100,1,12.99,100,1,14.87,100,1,12.73,100,1,14.95,700,1,12.67,100,1,14.99,700,1,12.47,100,1,15.07,700,1,12.46,100,1,15.09,100,1,12.43,700,1,15.14,700,1,12.42,700,1,15.16,100,1,12.37,700,1,15.26,200,2,ARL,108872153
623,2025-07-17T13:57:44.947757237Z,2025-07-17T13:57:44.947591620Z,160,2,1108,A,A,0,14.50,2,130,165617,92961696,13.25,11,1,14.50,2,1,13.12,2,1,14.59,100,1,12.99,100,1,14.83,100,1,12.73,100,1,14.87,100,1,12.67,100,1,14.95,700,1,12.47,100,1,14.99,700,1,12.46,100,1,15.07,700,1,12.43,700,1,15.09,100,1,12.42,700,1,15.14,700,1,12.37,700,1,15.16,100,1,ARL,111347121
624,2025-07-17T13:59:50.477911158Z,2025-07-17T13:59:50.477745739Z,160,2,1108,C,B,0,13.25,11,130,165419,96389796,13.12,2,1,14.50,2,1,12.99,100,1,14.59,100,1,12.73,100,1,14.83,100,1,12.67,100,1,14.87,100,1,12.47,100,1,14.95,700,1,12.46,100,1,14.99,700,1,12.43,700,1,15.07,700,1,12.42,700,1,15.09,100,1,12.37,700,1,15.14,700,1,12.36,200,2,15.16,100,1,ARL,44586753
625,2025-07-17T13:59:50.479576984Z,2025-07-17T13:59:50.479411482Z,160,2,1108,C,B,9,12.36,100,0,165502,96389821,13.12,2,1,14.50,2,1,12.99,100,1,14.59,100,1,12.73,100,1,14.83,100,1,12.67,100,1,14.87,100,1,12.47,100,1,14.95,700,1,12.46,100,1,14.99,700,1,12.43,700,1,15.07,700,1,12.42,700,1,15.09,100,1,12.37,700,1,15.14,700,1,12.36,100,1,15.16,100,1,ARL,43787977
626,2025-07-17T13:59:50.479576984Z,2025-07-17T13:59:50.479411482Z,160,2,1108,A,B,4,12.51,100,130,165502,96389821,13.12,2,1,14.50,2,1,12.99,100,1,14.59,100,1,12.73,100,1,14.83,100,1,12.67,100,1,14.87,100,1,12.51,100,1,14.95,700,1,12.47,100,1,14.99,700,1,12.46,100,1,15.07,700,1,12.43,700,1,15.09,100,1,12.42,700,1,15.14,700,1,12.37,700,1,15.16,100,1,ARL,115474337
627,2025-07-17T13:59:50.480863637Z,2025-07-17T13:59:50.480698233Z,160,2,1108,C,B,10,12.36,100,0,165404,96389845,13.12,2,1,14.50,2,1,12.99,100,1,14.59,100,1,12.73,100,1,14.83,100,1,12.67,100,1,14.87,100,1,12.51,100,1,14.95,700,1,12.47,100,1,14.99,700,1,12.46,100,1,15.07,700,1,12.43,700,1,15.09,100,1,12.42,700,1,15.14,700,1,12.37,700,1,15.16,100,1,ARL,43781537
628,2025-07-17T13:59:50.480863637Z,2025-07-17T13:59:50.480698233Z,160,2,1108,A,B,4,12.51,100,130,165404,96389845,13.12,2,1,14.50,2,1,12.99,100,1,14.59,100,1,12.73,100,1,14.83,100,1,12.67,100,1,14.87,100,1,12.51,200,2,14.95,700,1,12.47,100,1,14.99,700,1,12.46,100,1,15.07,700,1,12.43,700,1,15.09,100,1,12.42,700,1,15.14,700,1,12.37,700,1,15.16,100,1,ARL,115474357
629,2025-07-17T14:00:00.063037446Z,2025-07-17T14:00:00.062872132Z,160,2,1108,A,B,1,13.11,100,130,165314,96673952,13.12,2,1,14.50,2,1,13.11,100,1,14.59,100,1,12.99,100,1,14.83,100,1,12.73,100,1,14.87,100,1,12.67,100,1,14.95,700,1,12.51,200,2,14.99,700,1,12.47,100,1,15.07,700,1,12.46,100,1,15.09,100,1,12.43,700,1,15.14,700,1,12.42,700,1,15.16,100,1,ARL,115813253
630,2025-07-17T14:00:00.063056200Z,2025-07-17T14:00:00.062890891Z,160,2,1108,A,A,1,14.51,100,130,165309,96673954,13.12,2,1,14.50,2,1,13.11,100,1,14.51,100,1,12.99,100,1,14.59,100,1,12.73,100,1,14.83,100,1,12.67,100,1,14.87,100,1,12.51,200,2,14.95,700,1,12.47,100,1,14.99,700,1,12.46,100,1,15.07,700,1,12.43,700,1,15.09,100,1,12.42,700,1,15.14,700,1,ARL,115813261
631,2025-07-17T14:02:01.157985602Z,2025-07-17T14:02:01.157819863Z,160,2,1108,C,B,0,13.12,2,0,165739,101310413,13.11,100,1,14.50,2,1,12.99,100,1,14.51,100,1,12.73,100,1,14.59,100,1,12.67,100,1,14.83,100,1,12.51,200,2,14.87,100,1,12.47,100,1,14.95,700,1,12.46,100,1,14.99,700,1,12.43,700,1,15.07,700,1,12.42,700,1,15.09,100,1,12.37,700,1,15.14,700,1,ARL,111169049
632,2025-07-17T14:02:01.157985602Z,2025-07-17T14:02:01.157819863Z,160,2,1108,A,B,0,13.26,2,130,165739,101310413,13.26,2,1,14.50,2,1,13.11,100,1,14.51,100,1,12.99,100,1,14.59,100,1,12.73,100,1,14.83,100,1,12.67,100,1,14.87,100,1,12.51,200,2,14.95,700,1,12.47,100,1,14.99,700,1,12.46,100,1,15.07,700,1,12.43,700,1,15.09,100,1,12.42,700,1,15.14,700,1,ARL,121098337
633,2025-07-17T14:02:01.157986499Z,2025-07-17T14:02:01.157820985Z,160,2,1108,C,A,0,14.50,2,0,165514,101310414,13.26,2,1,14.51,100,1,13.11,100,1,14.59,100,1,12.99,100,1,14.83,100,1,12.73,100,1,14.87,100,1,12.67,100,1,14.95,700,1,12.51,200,2,14.99,700,1,12.47,100,1,15.07,700,1,12.46,100,1,15.09,100,1,12.43,700,1,15.14,700,1,12.42,700,1,15.16,100,1,ARL,111347121
634,2025-07-17T14:02:01.157986499Z,2025-07-17T14:02:01.157820985Z,160,2,1108,A,A,0,14.36,2,130,165514,101310414,13.26,2,1,14.36,2,1,13.11,100,1,14.51,100,1,12.99,100,1,14.59,100,1,12.73,100,1,14.83,100,1,12.67,100,1,14.87,100,1,12.51,200,2,14.95,700,1,12.47,100,1,14.99,700,1,12.46,100,1,15.07,700,1,12.43,700,1,15.09,100,1,12.42,700,1,15.14,700,1,ARL,121098341
635,2025-07-17T14:02:01.283528838Z,2025-07-17T14:02:01.283363185Z,160,2,1108,C,B,1,13.11,100,0,165653,101317376,13.26,2,1,14.36,2,1,12.99,100,1,14.51,100,1,12.73,100,1,14.59,100,1,12.67,100,1,14.83,100,1,12.51,200,2,14.87,100,1,12.47,100,1,14.95,700,1,12.46,100,1,14.99,700,1,12.43,700,1,15.07,700,1,12.42,700,1,15.09,100,1,12.37,700,1,15.14,700,1,ARL,115813253
636,2025-07-17T14:02:01.283528838Z,2025-07-17T14:02:01.283363185Z,160,2,1108,A,B,1,13.25,100,130,165653,101317376,13.26,2,1,14.36,2,1,13.25,100,1,14.51,100,1,12.99,100,1,14.59,100,1,12.73,100,1,14.83,100,1,12.67,100,1,14.87,100,1,12.51,200,2,14.95,700,1,12.47,100,1,14.99,700,1,12.46,100,1,15.07,700,1,12.43,700,1,15.09,100,1,12.42,700,1,15.14,700,1,ARL,121107957
637,2025-07-17T14:02:01.283544588Z,2025-07-17T14:02:01.283378637Z,160,2,1108,C,A,1,14.51,100,0,165951,101317377,13.26,2,1,14.36,2,1,13.25,100,1,14.59,100,1,12.99,100,1,14.83,100,1,12.73,100,1,14.87,100,1,12.67,100,1,14.95,700,1,12.51,200,2,14.99,700,1,12.47,100,1,15.07,700,1,12.46,100,1,15.09,100,1,12.43,700,1,15.14,700,1,12.42,700,1,15.16,100,1,ARL,115813261
638,2025-07-17T14:02:01.283544588Z,2025-07-17T14:02:01.283378637Z,160,2,1108,A,A,1,14.37,100,130,165951,101317377,13.26,2,1,14.36,2,1,13.25,100,1,14.37,100,1,12.99,100,1,14.59,100,1,12.73,100,1,14.83,100,1,12.67,100,1,14.87,100,1,12.51,200,2,14.95,700,1,12.47,100,1,14.99,700,1,12.46,100,1,15.07,700,1,12.43,700,1,15.09,100,1,12.42,700,1,15.14,700,1,ARL,121107961
639,2025-07-17T14:04:21.248906318Z,2025-07-17T14:04:21.248740930Z,160,2,1108,A,A,0,14.35,1,130,165388,106336852,13.26,2,1,14.35,1,1,13.25,100,1,14.36,2,1,12.99,100,1,14.37,100,1,12.73,100,1,14.59,100,1,12.67,100,1,14.83,100,1,12.51,200,2,14.87,100,1,12.47,100,1,14.95,700,1,12.46,100,1,14.99,700,1,12.43,700,1,15.07,700,1,12.42,700,1,15.09,100,1,ARL,126872197
640,2025-07-17T14:04:21.250325900Z,2025-07-17T14:04:21.250160548Z,160,2,1108,C,B,5,12.51,100,0,165352,106336976,13.26,2,1,14.35,1,1,13.25,100,1,14.36,2,1,12.99,100,1,14.37,100,1,12.73,100,1,14.59,100,1,12.67,100,1,14.83,100,1,12.51,100,1,14.87,100,1,12.47,100,1,14.95,700,1,12.46,100,1,14.99,700,1,12.43,700,1,15.07,700,1,12.42,700,1,15.09,100,1,ARL,115474357
641,2025-07-17T14:04:21.250325900Z,2025-07-17T14:04:21.250160548Z,160,2,1108,A,B,11,12.36,100,130,165352,106336976,13.26,2,1,14.35,1,1,13.25,100,1,14.36,2,1,12.99,100,1,14.37,100,1,12.73,100,1,14.59,100,1,12.67,100,1,14.83,100,1,12.51,100,1,14.87,100,1,12.47,100,1,14.95,700,1,12.46,100,1,14.99,700,1,12.43,700,1,15.07,700,1,12.42,700,1,15.09,100,1,ARL,126872345
642,2025-07-17T14:04:21.250797741Z,2025-07-17T14:04:21.250632048Z,160,2,1108,C,B,5,12.51,100,0,165693,106337002,13.26,2,1,14.35,1,1,13.25,100,1,14.36,2,1,12.99,100,1,14.37,100,1,12.73,100,1,14.59,100,1,12.67,100,1,14.83,100,1,12.47,100,1,14.87,100,1,12.46,100,1,14.95,700,1,12.43,700,1,14.99,700,1,12.42,700,1,15.07,700,1,12.37,700,1,15.09,100,1,ARL,115474337
643,2025-07-17T14:04:21.250797741Z,2025-07-17T14:04:21.250632048Z,160,2,1108,A,B,10,12.36,100,130,165693,106337002,13.26,2,1,14.35,1,1,13.25,100,1,14.36,2,1,12.99,100,1,14.37,100,1,12.73,100,1,14.59,100,1,12.67,100,1,14.83,100,1,12.47,100,1,14.87,100,1,12.46,100,1,14.95,700,1,12.43,700,1,14.99,700,1,12.42,700,1,15.07,700,1,12.37,700,1,15.09,100,1,ARL,126872361
644,2025-07-17T14:04:21.350207939Z,2025-07-17T14:04:21.350041949Z,160,2,1108,C,A,0,14.35,1,128,165990,106339204,13.26,2,1,14.36,2,1,13.25,100,1,14.37,100,1,12.99,100,1,14.59,100,1,12.73,100,1,14.83,100,1,12.67,100,1,14.87,100,1,12.47,100,1,14.95,700,1,12.46,100,1,14.99,700,1,12.43,700,1,15.07,700,1,12.42,700,1,15.09,100,1,12.37,700,1,15.14,700,1,ARL,126872197
645,2025-07-17T14:04:54.699926747Z,2025-07-17T14:04:54.699761263Z,160,2,1108,C,A,15,15.46,100,0,165484,107313441,13.26,2,1,14.36,2,1,13.25,100,1,14.37,100,1,12.99,100,1,14.59,100,1,12.73,100,1,14.83,100,1,12.67,100,1,14.87,100,1,12.47,100,1,14.95,700,1,12.46,100,1,14.99,700,1,12.43,700,1,15.07,700,1,12.42,700,1,15.09,100,1,12.37,700,1,15.14,700,1,ARL,92510753
646,2025-07-17T14:04:54.699926747Z,2025-07-17T14:04:54.699761263Z,160,2,1108,A,A,14,15.34,100,130,165484,107313441,13.26,2,1,14.36,2,1,13.25,100,1,14.37,100,1,12.99,100,1,14.59,100,1,12.73,100,1,14.83,100,1,12.67,100,1,14.87,100,1,12.47,100,1,14.95,700,1,12.46,100,1,14.99,700,1,12.43,700,1,15.07,700,1,12.42,700,1,15.09,100,1,12.37,700,1,15.14,700,1,ARL,127999501
647,2025-07-17T14:05:10.258855609Z,2025-07-17T14:05:10.258689253Z,160,2,1108,A,A,0,14.08,1,130,166356,107833096,13.26,2,1,14.08,1,1,13.25,100,1,14.36,2,1,12.99,100,1,14.37,100,1,12.73,100,1,14.59,100,1,12.67,100,1,14.83,100,1,12.47,100,1,14.87,100,1,12.46,100,1,14.95,700,1,12.43,700,1,14.99,700,1,12.42,700,1,15.07,700,1,12.37,700,1,15.09,100,1,ARL,128570149
648,2025-07-17T14:05:10.259513876Z,2025-07-17T14:05:10.259348471Z,160,2,1108,C,A,12,15.26,100,0,165405,107833168,13.26,2,1,14.08,1,1,13.25,100,1,14.36,2,1,12.99,100,1,14.37,100,1,12.73,100,1,14.59,100,1,12.67,100,1,14.83,100,1,12.47,100,1,14.87,100,1,12.46,100,1,14.95,700,1,12.43,700,1,14.99,700,1,12.42,700,1,15.07,700,1,12.37,700,1,15.09,100,1,ARL,108217173
649,2025-07-17T14:05:10.259513876Z,2025-07-17T14:05:10.259348471Z,160,2,1108,A,A,7,14.98,100,130,165405,107833168,13.26,2,1,14.08,1,1,13.25,100,1,14.36,2,1,12.99,100,1,14.37,100,1,12.73,100,1,14.59,100,1,12.67,100,1,14.83,100,1,12.47,100,1,14.87,100,1,12.46,100,1,14.95,700,1,12.43,700,1,14.98,100,1,12.42,700,1,14.99,700,1,12.37,700,1,15.07,700,1,ARL,128570229
650,2025-07-17T14:05:10.259895236Z,2025-07-17T14:05:10.259729446Z,160,2,1108,C,A,13,15.26,100,0,165790,107833188,13.26,2,1,14.08,1,1,13.25,100,1,14.36,2,1,12.99,100,1,14.37,100,1,12.73,100,1,14.59,100,1,12.67,100,1,14.83,100,1,12.47,100,1,14.87,100,1,12.46,100,1,14.95,700,1,12.43,700,1,14.98,100,1,12.42,700,1,14.99,700,1,12.37,700,1,15.07,700,1,ARL,108217045
651,2025-07-17T14:05:10.259895236Z,2025-07-17T14:05:10.259729446Z,160,2,1108,A,A,7,14.98,100,130,165790,107833188,13.26,2,1,14.08,1,1,13.25,100,1,14.36,2,1,12.99,100,1,14.37,100,1,12.73,100,1,14.59,100,1,12.67,100,1,14.83,100,1,12.47,100,1,14.87,100,1,12.46,100,1,14.95,700,1,12.43,700,1,14.98,200,2,12.42,700,1,14.99,700,1,12.37,700,1,15.07,700,1,ARL,128570237
652,2025-07-17T14:05:10.262461863Z,2025-07-17T14:05:10.262295631Z,160,2,1108,C,A,2,14.37,100,0,166232,107833310,13.26,2,1,14.08,1,1,13.25,100,1,14.36,2,1,12.99,100,1,14.59,100,1,12.73,100,1,14.83,100,1,12.67,100,1,14.87,100,1,12.47,100,1,14.95,700,1,12.46,100,1,14.98,200,2,12.43,700,1,14.99,700,1,12.42,700,1,15.07,700,1,12.37,700,1,15.09,100,1,ARL,121107961
653,2025-07-17T14:05:10.262461863Z,2025-07-17T14:05:10.262295631Z,160,2,1108,A,A,1,14.09,100,130,166232,107833310,13.26,2,1,14.08,1,1,13.25,100,1,14.09,100,1,12.99,100,1,14.36,2,1,12.73,100,1,14.59,100,1,12.67,100,1,14.83,100,1,12.47,100,1,14.87,100,1,12.46,100,1,14.95,700,1,12.43,700,1,14.98,200,2,12.42,700,1,14.99,700,1,12.37,700,1,15.07,700,1,ARL,128570317
654,2025-07-17T14:05:10.262866527Z,2025-07-17T14:05:10.262701351Z,160,2,1108,C,A,0,14.08,1,130,165176,107833359,13.26,2,1,14.09,100,1,13.25,100,1,14.36,2,1,12.99,100,1,14.59,100,1,12.73,100,1,14.83,100,1,12.67,100,1,14.87,100,1,12.47,100,1,14.95,700,1,12.46,100,1,14.98,200,2,12.43,700,1,14.99,700,1,12.42,700,1,15.07,700,1,12.37,700,1,15.09,100,1,ARL,128570149
655,2025-07-17T14:05:10.263188035Z,2025-07-17T14:05:10.263022539Z,160,2,1108,C,A,14,15.34,100,0,165496,107833371,13.26,2,1,14.09,100,1,13.25,100,1,14.36,2,1,12.99,100,1,14.59,100,1,12.73,100,1,14.83,100,1,12.67,100,1,14.87,100,1,12.47,100,1,14.95,700,1,12.46,100,1,14.98,200,2,12.43,700,1,14.99,700,1,12.42,700,1,15.07,700,1,12.37,700,1,15.09,100,1,ARL,127999501
656,2025-07-17T14:05:10.263188035Z,2025-07-17T14:05:10.263022539Z,160,2,1108,A,A,12,15.18,100,130,165496,107833371,13.26,2,1,14.09,100,1,13.25,100,1,14.36,2,1,12.99,100,1,14.59,100,1,12.73,100,1,14.83,100,1,12.67,100,1,14.87,100,1,12.47,100,1,14.95,700,1,12.46,100,1,14.98,200,2,12.43,700,1,14.99,700,1,12.42,700,1,15.07,700,1,12.37,700,1,15.09,100,1,ARL,128570417
657,2025-07-17T14:05:10.264495078Z,2025-07-17T14:05:10.264329670Z,160,2,1108,C,A,15,15.36,100,0,165408,107833404,13.26,2,1,14.09,100,1,13.25,100,1,14.36,2,1,12.99,100,1,14.59,100,1,12.73,100,1,14.83,100,1,12.67,100,1,14.87,100,1,12.47,100,1,14.95,700,1,12.46,100,1,14.98,200,2,12.43,700,1,14.99,700,1,12.42,700,1,15.07,700,1,12.37,700,1,15.09,100,1,ARL,92510761
658,2025-07-17T14:05:10.264495078Z,2025-07-17T14:05:10.264329670Z,160,2,1108,A,A,9,15.08,100,130,165408,107833404,13.26,2,1,14.09,100,1,13.25,100,1,14.36,2,1,12.99,100,1,14.59,100,1,12.73,100,1,14.83,100,1,12.67,100,1,14.87,100,1,12.47,100,1,14.95,700,1,12.46,100,1,14.98,200,2,12.43,700,1,14.99,700,1,12.42,700,1,15.07,700,1,12.37,700,1,15.08,100,1,ARL,128570449
659,2025-07-17T14:05:10.264590318Z,2025-07-17T14:05:10.264425026Z,160,2,1108,C,A,10,15.09,100,130,165292,107833406,13.26,2,1,14.09,100,1,13.25,100,1,14.36,2,1,12.99,100,1,14.59,100,1,12.73,100,1,14.83,100,1,12.67,100,1,14.87,100,1,12.47,100,1,14.95,700,1,12.46,100,1,14.98,200,2,12.43,700,1,14.99,700,1,12.42,700,1,15.07,700,1,12.37,700,1,15.08,100,1,ARL,84650629
660,2025-07-17T14:05:10.264715723Z,2025-07-17T14:05:10.264550510Z,160,2,1108,A,A,5,14.89,100,130,165213,107833407,13.26,2,1,14.09,100,1,13.25,100,1,14.36,2,1,12.99,100,1,14.59,100,1,12.73,100,1,14.83,100,1,12.67,100,1,14.87,100,1,12.47,100,1,14.89,100,1,12.46,100,1,14.95,700,1,12.43,700,1,14.98,200,2,12.42,700,1,14.99,700,1,12.37,700,1,15.07,700,1,ARL,128570453
661,2025-07-17T14:05:10.269943051Z,2025-07-17T14:05:10.269777131Z,160,2,1108,C,A,2,14.59,100,128,165920,107833716,13.26,2,1,14.09,100,1,13.25,100,1,14.36,2,1,12.99,100,1,14.83,100,1,12.73,100,1,14.87,100,1,12.67,100,1,14.89,100,1,12.47,100,1,14.95,700,1,12.46,100,1,14.98,200,2,12.43,700,1,14.99,700,1,12.42,700,1,15.07,700,1,12.37,700,1,15.08,100,1,ARL,84629329
662,2025-07-17T14:05:10.269997960Z,2025-07-17T14:05:10.269832842Z,160,2,1108,A,A,2,14.37,100,130,165118,107833720,13.26,2,1,14.09,100,1,13.25,100,1,14.36,2,1,12.99,100,1,14.37,100,1,12.73,100,1,14.83,100,1,12.67,100,1,14.87,100,1,12.47,100,1,14.89,100,1,12.46,100,1,14.95,700,1,12.43,700,1,14.98,200,2,12.42,700,1,14.99,700,1,12.37,700,1,15.07,700,1,ARL,128570621
663,2025-07-17T14:05:10.271865423Z,2025-07-17T14:05:10.271699633Z,160,2,1108,C,A,22,18.23,100,0,165790,107833881,13.26,2,1,14.09,100,1,13.25,100,1,14.36,2,1,12.99,100,1,14.37,100,1,12.73,100,1,14.83,100,1,12.67,100,1,14.87,100,1,12.47,100,1,14.89,100,1,12.46,100,1,14.95,700,1,12.43,700,1,14.98,200,2,12.42,700,1,14.99,700,1,12.37,700,1,15.07,700,1,ARL,92510841
664,2025-07-17T14:05:10.271865423Z,2025-07-17T14:05:10.271699633Z,160,2,1108,A,A,22,17.90,100,130,165790,107833881,13.26,2,1,14.09,100,1,13.25,100,1,14.36,2,1,12.99,100,1,14.37,100,1,12.73,100,1,14.83,100,1,12.67,100,1,14.87,100,1,12.47,100,1,14.89,100,1,12.46,100,1,14.95,700,1,12.43,700,1,14.98,200,2,12.42,700,1,14.99,700,1,12.37,700,1,15.07,700,1,ARL,128570685
665,2025-07-17T14:05:10.276320920Z,2025-07-17T14:05:10.276155439Z,160,2,1108,C,A,20,16.51,100,0,165481,107834635,13.26,2,1,14.09,100,1,13.25,100,1,14.36,2,1,12.99,100,1,14.37,100,1,12.73,100,1,14.83,100,1,12.67,100,1,14.87,100,1,12.47,100,1,14.89,100,1,12.46,100,1,14.95,700,1,12.43,700,1,14.98,200,2,12.42,700,1,14.99,700,1,12.37,700,1,15.07,700,1,ARL,92510813
666,2025-07-17T14:05:10.276320920Z,2025-07-17T14:05:10.276155439Z,160,2,1108,A,A,20,16.21,100,130,165481,107834635,13.26,2,1,14.09,100,1,13.25,100,1,14.36,2,1,12.99,100,1,14.37,100,1,12.73,100,1,14.83,100,1,12.67,100,1,14.87,100,1,12.47,100,1,14.89,100,1,12.46,100,1,14.95,700,1,12.43,700,1,14.98,200,2,12.42,700,1,14.99,700,1,12.37,700,1,15.07,700,1,ARL,128570977
667,2025-07-17T14:05:10.342982797Z,2025-07-17T14:05:10.342817229Z,160,2,1108,C,A,15,15.31,100,0,165568,107837761,13.26,2,1,14.09,100,1,13.25,100,1,14.36,2,1,12.99,100,1,14.37,100,1,12.73,100,1,14.83,100,1,12.67,100,1,14.87,100,1,12.47,100,1,14.89,100,1,12.46,100,1,14.95,700,1,12.43,700,1,14.98,200,2,12.42,700,1,14.99,700,1,12.37,700,1,15.07,700,1,ARL,84630849
668,2025-07-17T14:05:10.342982797Z,2025-07-17T14:05:10.342817229Z,160,2,1108,A,A,10,15.08,100,130,165568,107837761,13.26,2,1,14.09,100,1,13.25,100,1,14.36,2,1,12.99,100,1,14.37,100,1,12.73,100,1,14.83,100,1,12.67,100,1,14.87,100,1,12.47,100,1,14.89,100,1,12.46,100,1,14.95,700,1,12.43,700,1,14.98,200,2,12.42,700,1,14.99,700,1,12.37,700,1,15.07,700,1,ARL,128573957
669,2025-07-17T14:05:31.418741362Z,2025-07-17T14:05:31.418575692Z,160,2,1108,C,A,1,14.36,2,0,165670,108664911,13.26,2,1,14.09,100,1,13.25,100,1,14.37,100,1,12.99,100,1,14.83,100,1,12.73,100,1,14.87,100,1,12.67,100,1,14.89,100,1,12.47,100,1,14.95,700,1,12.46,100,1,14.98,200,2,12.43,700,1,14.99,700,1,12.42,700,1,15.07,700,1,12.37,700,1,15.08,200,2,ARL,121098341
670,2025-07-17T14:05:31.418741362Z,2025-07-17T14:05:31.418575692Z,160,2,1108,A,A,1,14.26,2,130,165670,108664911,13.26,2,1,14.09,100,1,13.25,100,1,14.26,2,1,12.99,100,1,14.37,100,1,12.73,100,1,14.83,100,1,12.67,100,1,14.87,100,1,12.47,100,1,14.89,100,1,12.46,100,1,14.95,700,1,12.43,700,1,14.98,200,2,12.42,700,1,14.99,700,1,12.37,700,1,15.07,700,1,ARL,129518753
671,2025-07-17T14:06:01.386006059Z,2025-07-17T14:06:01.385840471Z,160,2,1108,C,B,0,13.26,2,0,165588,109685525,13.25,100,1,14.09,100,1,12.99,100,1,14.26,2,1,12.73,100,1,14.37,100,1,12.67,100,1,14.83,100,1,12.47,100,1,14.87,100,1,12.46,100,1,14.89,100,1,12.43,700,1,14.95,700,1,12.42,700,1,14.98,200,2,12.37,700,1,14.99,700,1,12.36,200,2,15.07,700,1,ARL,121098337
672,2025-07-17T14:06:01.386006059Z,2025-07-17T14:06:01.385840471Z,160,2,1108,A,B,1,13.15,2,130,165588,109685525,13.25,100,1,14.09,100,1,13.15,2,1,14.26,2,1,12.99,100,1,14.37,100,1,12.73,100,1,14.83,100,1,12.67,100,1,14.87,100,1,12.47,100,1,14.89,100,1,12.46,100,1,14.95,700,1,12.43,700,1,14.98,200,2,12.42,700,1,14.99,700,1,12.37,700,1,15.07,700,1,ARL,130693973
673,2025-07-17T14:13:11.346377890Z,2025-07-17T14:13:11.346212166Z,160,2,1108,C,A,13,15.18,100,0,165724,123937587,13.25,100,1,14.09,100,1,13.15,2,1,14.26,2,1,12.99,100,1,14.37,100,1,12.73,100,1,14.83,100,1,12.67,100,1,14.87,100,1,12.47,100,1,14.89,100,1,12.46,100,1,14.95,700,1,12.43,700,1,14.98,200,2,12.42,700,1,14.99,700,1,12.37,700,1,15.07,700,1,ARL,128570417
674,2025-07-17T14:13:11.346377890Z,2025-07-17T14:13:11.346212166Z,160,2,1108,A,A,11,15.09,100,130,165724,123937587,13.25,100,1,14.09,100,1,13.15,2,1,14.26,2,1,12.99,100,1,14.37,100,1,12.73,100,1,14.83,100,1,12.67,100,1,14.87,100,1,12.47,100,1,14.89,100,1,12.46,100,1,14.95,700,1,12.43,700,1,14.98,200,2,12.42,700,1,14.99,700,1,12.37,700,1,15.07,700,1,ARL,146955361
675,2025-07-17T14:13:11.358916626Z,2025-07-17T14:13:11.358751092Z,160,2,1108,C,A,2,14.37,100,130,165534,123938202,13.25,100,1,14.09,100,1,13.15,2,1,14.26,2,1,12.99,100,1,14.83,100,1,12.73,100,1,14.87,100,1,12.67,100,1,14.89,100,1,12.47,100,1,14.95,700,1,12.46,100,1,14.98,200,2,12.43,700,1,14.99,700,1,12.42,700,1,15.07,700,1,12.37,700,1,15.08,200,2,ARL,128570621
676,2025-07-17T14:13:11.358968656Z,2025-07-17T14:13:11.358802966Z,160,2,1108,A,A,2,14.28,100,130,165690,123938203,13.25,100,1,14.09,100,1,13.15,2,1,14.26,2,1,12.99,100,1,14.28,100,1,12.73,100,1,14.83,100,1,12.67,100,1,14.87,100,1,12.47,100,1,14.89,100,1,12.46,100,1,14.95,700,1,12.43,700,1,14.98,200,2,12.42,700,1,14.99,700,1,12.37,700,1,15.07,700,1,ARL,146956357
677,2025-07-17T14:13:11.393088913Z,2025-07-17T14:13:11.392923396Z,160,2,1108,C,A,16,15.73,100,0,165517,123939815,13.25,100,1,14.09,100,1,13.15,2,1,14.26,2,1,12.99,100,1,14.28,100,1,12.73,100,1,14.83,100,1,12.67,100,1,14.87,100,1,12.47,100,1,14.89,100,1,12.46,100,1,14.95,700,1,12.43,700,1,14.98,200,2,12.42,700,1,14.99,700,1,12.37,700,1,15.07,700,1,ARL,84629953
678,2025-07-17T14:13:11.393088913Z,2025-07-17T14:13:11.392923396Z,160,2,1108,A,A,15,15.40,100,130,165517,123939815,13.25,100,1,14.09,100,1,13.15,2,1,14.26,2,1,12.99,100,1,14.28,100,1,12.73,100,1,14.83,100,1,12.67,100,1,14.87,100,1,12.47,100,1,14.89,100,1,12.46,100,1,14.95,700,1,12.43,700,1,14.98,200,2,12.42,700,1,14.99,700,1,12.37,700,1,15.07,700,1,ARL,146959177
679,2025-07-17T14:13:11.423482323Z,2025-07-17T14:13:11.423316840Z,160,2,1108,A,A,3,14.56,100,130,165483,123940437,13.25,100,1,14.09,100,1,13.15,2,1,14.26,2,1,12.99,100,1,14.28,100,1,12.73,100,1,14.56,100,1,12.67,100,1,14.83,100,1,12.47,100,1,14.87,100,1,12.46,100,1,14.89,100,1,12.43,700,1,14.95,700,1,12.42,700,1,14.98,200,2,12.37,700,1,14.99,700,1,ARL,146960005
680,2025-07-17T14:13:11.423483431Z,2025-07-17T14:13:11.423317922Z,160,2,1108,C,A,5,14.87,100,130,165509,123940438,13.25,100,1,14.09,100,1,13.15,2,1,14.26,2,1,12.99,100,1,14.28,100,1,12.73,100,1,14.56,100,1,12.67,100,1,14.83,100,1,12.47,100,1,14.89,100,1,12.46,100,1,14.95,700,1,12.43,700,1,14.98,200,2,12.42,700,1,14.99,700,1,12.37,700,1,15.07,700,1,ARL,84708037
681,2025-07-17T14:13:11.555808541Z,2025-07-17T14:13:11.555642984Z,160,2,1108,A,A,5,14.84,100,130,165557,123942727,13.25,100,1,14.09,100,1,13.15,2,1,14.26,2,1,12.99,100,1,14.28,100,1,12.73,100,1,14.56,100,1,12.67,100,1,14.83,100,1,12.47,100,1,14.84,100,1,12.46,100,1,14.89,100,1,12.43,700,1,14.95,700,1,12.42,700,1,14.98,200,2,12.37,700,1,14.99,700,1,ARL,146962993
682,2025-07-17T14:13:11.555828856Z,2025-07-17T14:13:11.555663413Z,160,2,1108,C,A,14,15.16,100,130,165443,123942728,13.25,100,1,14.09,100,1,13.15,2,1,14.26,2,1,12.99,100,1,14.28,100,1,12.73,100,1,14.56,100,1,12.67,100,1,14.83,100,1,12.47,100,1,14.84,100,1,12.46,100,1,14.89,100,1,12.43,700,1,14.95,700,1,12.42,700,1,14.98,200,2,12.37,700,1,14.99,700,1,ARL,84668677
683,2025-07-17T14:13:19.230983072Z,2025-07-17T14:13:19.230817808Z,160,2,1108,A,A,7,14.91,700,130,165264,124169794,13.25,100,1,14.09,100,1,13.15,2,1,14.26,2,1,12.99,100,1,14.28,100,1,12.73,100,1,14.56,100,1,12.67,100,1,14.83,100,1,12.47,100,1,14.84,100,1,12.46,100,1,14.89,100,1,12.43,700,1,14.91,700,1,12.42,700,1,14.95,700,1,12.37,700,1,14.98,200,2,ARL,147217629
684,2025-07-17T14:13:19.231778755Z,2025-07-17T14:13:19.231613044Z,160,2,1108,C,A,14,15.14,700,130,165711,124169802,13.25,100,1,14.09,100,1,13.15,2,1,14.26,2,1,12.99,100,1,14.28,100,1,12.73,100,1,14.56,100,1,12.67,100,1,14.83,100,1,12.47,100,1,14.84,100,1,12.46,100,1,14.89,100,1,12.43,700,1,14.91,700,1,12.42,700,1,14.95,700,1,12.37,700,1,14.98,200,2,ARL,84628829
685,2025-07-17T14:22:28.338174848Z,2025-07-17T14:22:28.338009329Z,160,2,1108,A,A,0,14.00,1,130,165519,142657338,13.25,100,1,14.00,1,1,13.15,2,1,14.09,100,1,12.99,100,1,14.26,2,1,12.73,100,1,14.28,100,1,12.67,100,1,14.56,100,1,12.47,100,1,14.83,100,1,12.46,100,1,14.84,100,1,12.43,700,1,14.89,100,1,12.42,700,1,14.91,700,1,12.37,700,1,14.95,700,1,ARL,168073025
686,2025-07-17T14:22:29.994011311Z,2025-07-17T14:22:29.993845812Z,160,2,1108,C,A,1,14.09,100,0,165499,142715813,13.25,100,1,14.00,1,1,13.15,2,1,14.26,2,1,12.99,100,1,14.28,100,1,12.73,100,1,14.56,100,1,12.67,100,1,14.83,100,1,12.47,100,1,14.84,100,1,12.46,100,1,14.89,100,1,12.43,700,1,14.91,700,1,12.42,700,1,14.95,700,1,12.37,700,1,14.98,200,2,ARL,128570317
687,2025-07-17T14:22:29.994011311Z,2025-07-17T14:22:29.993845812Z,160,2,1108,A,A,1,14.01,100,130,165499,142715813,13.25,100,1,14.00,1,1,13.15,2,1,14.01,100,1,12.99,100,1,14.26,2,1,12.73,100,1,14.28,100,1,12.67,100,1,14.56,100,1,12.47,100,1,14.83,100,1,12.46,100,1,14.84,100,1,12.43,700,1,14.89,100,1,12.42,700,1,14.91,700,1,12.37,700,1,14.95,700,1,ARL,168141389
688,2025-07-17T14:32:58.233129156Z,2025-07-17T14:32:58.232963791Z,160,2,1108,C,B,0,13.25,100,130,165365,162140358,13.15,2,1,14.00,1,1,12.99,100,1,14.01,100,1,12.73,100,1,14.26,2,1,12.67,100,1,14.28,100,1,12.47,100,1,14.56,100,1,12.46,100,1,14.83,100,1,12.43,700,1,14.84,100,1,12.42,700,1,14.89,100,1,12.37,700,1,14.91,700,1,12.36,200,2,14.95,700,1,ARL,121107957
689,2025-07-17T14:32:58.714015555Z,2025-07-17T14:32:58.713850212Z,160,2,1108,A,B,1,13.14,100,130,165343,162149922,13.15,2,1,14.00,1,1,13.14,100,1,14.01,100,1,12.99,100,1,14.26,2,1,12.73,100,1,14.28,100,1,12.67,100,1,14.56,100,1,12.47,100,1,14.83,100,1,12.46,100,1,14.84,100,1,12.43,700,1,14.89,100,1,12.42,700,1,14.91,700,1,12.37,700,1,14.95,700,1,ARL,190326921
690,2025-07-17T14:34:48.346344959Z,2025-07-17T14:34:48.346179643Z,160,2,1108,C,A,0,14.00,1,130,165316,164925706,13.15,2,1,14.01,100,1,13.14,100,1,14.26,2,1,12.99,100,1,14.28,100,1,12.73,100,1,14.56,100,1,12.67,100,1,14.83,100,1,12.47,100,1,14.84,100,1,12.46,100,1,14.89,100,1,12.43,700,1,14.91,700,1,12.42,700,1,14.95,700,1,12.37,700,1,14.98,200,2,ARL,168073025
691,2025-07-17T14:47:30.548081358Z,2025-07-17T14:47:30.547915870Z,160,2,1108,A,B,0,13.38,33,130,165488,183466992,13.38,33,1,14.01,100,1,13.15,2,1,14.26,2,1,13.14,100,1,14.28,100,1,12.99,100,1,14.56,100,1,12.73,100,1,14.83,100,1,12.67,100,1,14.84,100,1,12.47,100,1,14.89,100,1,12.46,100,1,14.91,700,1,12.43,700,1,14.95,700,1,12.42,700,1,14.98,200,2,ARL,215999733
692,2025-07-17T14:47:30.548346701Z,2025-07-17T14:47:30.548180936Z,160,2,1108,C,B,2,13.14,100,0,165765,183466994,13.38,33,1,14.01,100,1,13.15,2,1,14.26,2,1,12.99,100,1,14.28,100,1,12.73,100,1,14.56,100,1,12.67,100,1,14.83,100,1,12.47,100,1,14.84,100,1,12.46,100,1,14.89,100,1,12.43,700,1,14.91,700,1,12.42,700,1,14.95,700,1,12.37,700,1,14.98,200,2,ARL,190326921
693,2025-07-17T14:47:30.548346701Z,2025-07-17T14:47:30.548180936Z,160,2,1108,A,B,1,13.37,100,130,165765,183466994,13.38,33,1,14.01,100,1,13.37,100,1,14.26,2,1,13.15,2,1,14.28,100,1,12.99,100,1,14.56,100,1,12.73,100,1,14.83,100,1,12.67,100,1,14.84,100,1,12.47,100,1,14.89,100,1,12.46,100,1,14.91,700,1,12.43,700,1,14.95,700,1,12.42,700,1,14.98,200,2,ARL,215999737
694,2025-07-17T14:47:30.548831608Z,2025-07-17T14:47:30.548666035Z,160,2,1108,C,B,11,12.36,100,0,165573,183467001,13.38,33,1,14.01,100,1,13.37,100,1,14.26,2,1,13.15,2,1,14.28,100,1,12.99,100,1,14.56,100,1,12.73,100,1,14.83,100,1,12.67,100,1,14.84,100,1,12.47,100,1,14.89,100,1,12.46,100,1,14.91,700,1,12.43,700,1,14.95,700,1,12.42,700,1,14.98,200,2,ARL,126872345
695,2025-07-17T14:47:30.548831608Z,2025-07-17T14:47:30.548666035Z,160,2,1108,A,B,6,12.48,100,130,165573,183467001,13.38,33,1,14.01,100,1,13.37,100,1,14.26,2,1,13.15,2,1,14.28,100,1,12.99,100,1,14.56,100,1,12.73,100,1,14.83,100,1,12.67,100,1,14.84,100,1,12.48,100,1,14.89,100,1,12.47,100,1,14.91,700,1,12.46,100,1,14.95,700,1,12.43,700,1,14.98,200,2,ARL,215999741
696,2025-07-17T14:47:30.549090785Z,2025-07-17T14:47:30.548925394Z,160,2,1108,C,B,15,12.23,100,0,165391,183467002,13.38,33,1,14.01,100,1,13.37,100,1,14.26,2,1,13.15,2,1,14.28,100,1,12.99,100,1,14.56,100,1,12.73,100,1,14.83,100,1,12.67,100,1,14.84,100,1,12.48,100,1,14.89,100,1,12.47,100,1,14.91,700,1,12.46,100,1,14.95,700,1,12.43,700,1,14.98,200,2,ARL,43317473
697,2025-07-17T14:47:30.549090785Z,2025-07-17T14:47:30.548925394Z,160,2,1108,A,B,13,12.33,100,130,165391,183467002,13.38,33,1,14.01,100,1,13.37,100,1,14.26,2,1,13.15,2,1,14.28,100,1,12.99,100,1,14.56,100,1,12.73,100,1,14.83,100,1,12.67,100,1,14.84,100,1,12.48,100,1,14.89,100,1,12.47,100,1,14.91,700,1,12.46,100,1,14.95,700,1,12.43,700,1,14.98,200,2,ARL,215999753
698,2025-07-17T14:47:30.549341156Z,2025-07-17T14:47:30.549175659Z,160,2,1108,C,B,12,12.36,100,0,165497,183467004,13.38,33,1,14.01,100,1,13.37,100,1,14.26,2,1,13.15,2,1,14.28,100,1,12.99,100,1,14.56,100,1,12.73,100,1,14.83,100,1,12.67,100,1,14.84,100,1,12.48,100,1,14.89,100,1,12.47,100,1,14.91,700,1,12.46,100,1,14.95,700,1,12.43,700,1,14.98,200,2,ARL,126872361
699,2025-07-17T14:47:30.549341156Z,2025-07-17T14:47:30.549175659Z,160,2,1108,A,B,6,12.48,100,130,165497,183467004,13.38,33,1,14.01,100,1,13.37,100,1,14.26,2,1,13.15,2,1,14.28,100,1,12.99,100,1,14.56,100,1,12.73,100,1,14.83,100,1,12.67,100,1,14.84,100,1,12.48,200,2,14.89,100,1,12.47,100,1,14.91,700,1,12.46,100,1,14.95,700,1,12.43,700,1,14.98,200,2,ARL,215999761
700,2025-07-17T14:47:30.571385383Z,2025-07-17T14:47:30.571220121Z,160,2,1108,C,B,3,12.99,100,130,165262,183468111,13.38,33,1,14.01,100,1,13.37,100,1,14.26,2,1,13.15,2,1,14.28,100,1,12.73,100,1,14.56,100,1,12.67,100,1,14.83,100,1,12.48,200,2,14.84,100,1,12.47,100,1,14.89,100,1,12.46,100,1,14.91,700,1,12.43,700,1,14.95,700,1,12.42,700,1,14.98,200,2,ARL,43805737
701,2025-07-17T14:47:30.571436944Z,2025-07-17T14:47:30.571271737Z,160,2,1108,A,B,3,13.10,100,130,165207,183468112,13.38,33,1,14.01,100,1,13.37,100,1,14.26,2,1,13.15,2,1,14.28,100,1,13.10,100,1,14.56,100,1,12.73,100,1,14.83,100,1,12.67,100,1,14.84,100,1,12.48,200,2,14.89,100,1,12.47,100,1,14.91,700,1,12.46,100,1,14.95,700,1,12.43,700,1,14.98,200,2,ARL,216001413
702,2025-07-17T14:47:37.384610677Z,2025-07-17T14:47:37.384441232Z,160,2,1108,A,B,6,12.50,700,130,169445,183649796,13.38,33,1,14.01,100,1,13.37,100,1,14.26,2,1,13.15,2,1,14.28,100,1,13.10,100,1,14.56,100,1,12.73,100,1,14.83,100,1,12.67,100,1,14.84,100,1,12.50,700,1,14.89,100,1,12.48,200,2,14.91,700,1,12.47,100,1,14.95,700,1,12.46,100,1,14.98,200,2,ARL,216223005
703,2025-07-17T14:47:37.385400265Z,2025-07-17T14:47:37.385234288Z,160,2,1108,C,B,14,12.26,700,130,165977,183649801,13.38,33,1,14.01,100,1,13.37,100,1,14.26,2,1,13.15,2,1,14.28,100,1,13.10,100,1,14.56,100,1,12.73,100,1,14.83,100,1,12.67,100,1,14.84,100,1,12.50,700,1,14.89,100,1,12.48,200,2,14.91,700,1,12.47,100,1,14.95,700,1,12.46,100,1,14.98,200,2,ARL,44570585
704,2025-07-17T14:52:02.610509102Z,2025-07-17T14:52:02.610343819Z,160,2,1108,A,A,0,13.71,1,130,165283,189559141,13.38,33,1,13.71,1,1,13.37,100,1,14.01,100,1,13.15,2,1,14.26,2,1,13.10,100,1,14.28,100,1,12.73,100,1,14.56,100,1,12.67,100,1,14.83,100,1,12.50,700,1,14.84,100,1,12.48,200,2,14.89,100,1,12.47,100,1,14.91,700,1,12.46,100,1,14.95,700,1,ARL,223347833
705,2025-07-17T14:52:02.611701408Z,2025-07-17T14:52:02.611536221Z,160,2,1108,C,A,0,13.71,1,130,165187,189559156,13.38,33,1,14.01,100,1,13.37,100,1,14.26,2,1,13.15,2,1,14.28,100,1,13.10,100,1,14.56,100,1,12.73,100,1,14.83,100,1,12.67,100,1,14.84,100,1,12.50,700,1,14.89,100,1,12.48,200,2,14.91,700,1,12.47,100,1,14.95,700,1,12.46,100,1,14.98,200,2,ARL,223347833
706,2025-07-17T15:00:11.560678862Z,2025-07-17T15:00:11.560513555Z,160,2,1108,C,B,0,13.38,33,130,165307,200140364,13.37,100,1,14.01,100,1,13.15,2,1,14.26,2,1,13.10,100,1,14.28,100,1,12.73,100,1,14.56,100,1,12.67,100,1,14.83,100,1,12.50,700,1,14.84,100,1,12.48,200,2,14.89,100,1,12.47,100,1,14.91,700,1,12.46,100,1,14.95,700,1,12.43,700,1,14.98,200,2,ARL,215999733
707,2025-07-17T15:00:11.563053782Z,2025-07-17T15:00:11.562887948Z,160,2,1108,C,B,6,12.48,100,0,165834,200140389,13.37,100,1,14.01,100,1,13.15,2,1,14.26,2,1,13.10,100,1,14.28,100,1,12.73,100,1,14.56,100,1,12.67,100,1,14.83,100,1,12.50,700,1,14.84,100,1,12.48,100,1,14.89,100,1,12.47,100,1,14.91,700,1,12.46,100,1,14.95,700,1,12.43,700,1,14.98,200,2,ARL,215999761
708,2025-07-17T15:00:11.563053782Z,2025-07-17T15:00:11.562887948Z,160,2,1108,A,B,5,12.65,100,130,165834,200140389,13.37,100,1,14.01,100,1,13.15,2,1,14.26,2,1,13.10,100,1,14.28,100,1,12.73,100,1,14.56,100,1,12.67,100,1,14.83,100,1,12.65,100,1,14.84,100,1,12.50,700,1,14.89,100,1,12.48,100,1,14.91,700,1,12.47,100,1,14.95,700,1,12.46,100,1,14.98,200,2,ARL,236179089
709,2025-07-17T15:00:12.536218524Z,2025-07-17T15:00:12.536052536Z,160,2,1108,C,B,7,12.48,100,0,165988,200161810,13.37,100,1,14.01,100,1,13.15,2,1,14.26,2,1,13.10,100,1,14.28,100,1,12.73,100,1,14.56,100,1,12.67,100,1,14.83,100,1,12.65,100,1,14.84,100,1,12.50,700,1,14.89,100,1,12.47,100,1,14.91,700,1,12.46,100,1,14.95,700,1,12.43,700,1,14.98,200,2,ARL,215999741
710,2025-07-17T15:00:12.536218524Z,2025-07-17T15:00:12.536052536Z,160,2,1108,A,B,5,12.65,100,130,165988,200161810,13.37,100,1,14.01,100,1,13.15,2,1,14.26,2,1,13.10,100,1,14.28,100,1,12.73,100,1,14.56,100,1,12.67,100,1,14.83,100,1,12.65,200,2,14.84,100,1,12.50,700,1,14.89,100,1,12.47,100,1,14.91,700,1,12.46,100,1,14.95,700,1,12.43,700,1,14.98,200,2,ARL,236206261
711,2025-07-17T15:01:11.658789910Z,2025-07-17T15:01:11.658624662Z,160,2,1108,A,A,0,13.98,10,130,165248,201616674,13.37,100,1,13.98,10,1,13.15,2,1,14.01,100,1,13.10,100,1,14.26,2,1,12.73,100,1,14.28,100,1,12.67,100,1,14.56,100,1,12.65,200,2,14.83,100,1,12.50,700,1,14.84,100,1,12.47,100,1,14.89,100,1,12.46,100,1,14.91,700,1,12.43,700,1,14.95,700,1,ARL,237940713
712,2025-07-17T15:01:12.948386121Z,2025-07-17T15:01:12.948220412Z,160,2,1108,C,A,1,14.01,100,0,165709,201642675,13.37,100,1,13.98,10,1,13.15,2,1,14.26,2,1,13.10,100,1,14.28,100,1,12.73,100,1,14.56,100,1,12.67,100,1,14.83,100,1,12.65,200,2,14.84,100,1,12.50,700,1,14.89,100,1,12.47,100,1,14.91,700,1,12.46,100,1,14.95,700,1,12.43,700,1,14.98,200,2,ARL,168141389
713,2025-07-17T15:01:12.948386121Z,2025-07-17T15:01:12.948220412Z,160,2,1108,A,A,1,13.99,100,130,165709,201642675,13.37,100,1,13.98,10,1,13.15,2,1,13.99,100,1,13.10,100,1,14.26,2,1,12.73,100,1,14.28,100,1,12.67,100,1,14.56,100,1,12.65,200,2,14.83,100,1,12.50,700,1,14.84,100,1,12.47,100,1,14.89,100,1,12.46,100,1,14.91,700,1,12.43,700,1,14.95,700,1,ARL,237978541
714,2025-07-17T15:01:12.949124493Z,2025-07-17T15:01:12.948959226Z,160,2,1108,C,A,5,14.83,100,130,165267,201642712,13.37,100,1,13.98,10,1,13.15,2,1,13.99,100,1,13.10,100,1,14.26,2,1,12.73,100,1,14.28,100,1,12.67,100,1,14.56,100,1,12.65,200,2,14.84,100,1,12.50,700,1,14.89,100,1,12.47,100,1,14.91,700,1,12.46,100,1,14.95,700,1,12.43,700,1,14.98,200,2,ARL,84628793
715,2025-07-17T15:01:12.949484115Z,2025-07-17T15:01:12.949317198Z,160,2,1108,A,A,5,14.61,100,130,166917,201642747,13.37,100,1,13.98,10,1,13.15,2,1,13.99,100,1,13.10,100,1,14.26,2,1,12.73,100,1,14.28,100,1,12.67,100,1,14.56,100,1,12.65,200,2,14.61,100,1,12.50,700,1,14.84,100,1,12.47,100,1,14.89,100,1,12.46,100,1,14.91,700,1,12.43,700,1,14.95,700,1,ARL,237978629
716,2025-07-17T15:01:26.963916368Z,2025-07-17T15:01:26.963746832Z,160,2,1108,C,A,0,13.98,10,128,169536,201984003,13.37,100,1,13.99,100,1,13.15,2,1,14.26,2,1,13.10,100,1,14.28,100,1,12.73,100,1,14.56,100,1,12.67,100,1,14.61,100,1,12.65,200,2,14.84,100,1,12.50,700,1,14.89,100,1,12.47,100,1,14.91,700,1,12.46,100,1,14.95,700,1,12.43,700,1,14.98,200,2,ARL,237940713
717,2025-07-17T15:01:37.513312432Z,2025-07-17T15:01:37.513147090Z,160,2,1108,A,A,0,13.98,10,130,165342,202186180,13.37,100,1,13.98,10,1,13.15,2,1,13.99,100,1,13.10,100,1,14.26,2,1,12.73,100,1,14.28,100,1,12.67,100,1,14.56,100,1,12.65,200,2,14.61,100,1,12.50,700,1,14.84,100,1,12.47,100,1,14.89,100,1,12.46,100,1,14.91,700,1,12.43,700,1,14.95,700,1,ARL,238668633
718,2025-07-17T15:05:36.047202557Z,2025-07-17T15:05:36.047029298Z,160,2,1108,C,A,0,13.98,10,128,173259,207097179,13.37,100,1,13.99,100,1,13.15,2,1,14.26,2,1,13.10,100,1,14.28,100,1,12.73,100,1,14.56,100,1,12.67,100,1,14.61,100,1,12.65,200,2,14.84,100,1,12.50,700,1,14.89,100,1,12.47,100,1,14.91,700,1,12.46,100,1,14.95,700,1,12.43,700,1,14.98,200,2,ARL,238668633
719,2025-07-17T15:10:34.469866273Z,2025-07-17T15:10:34.469700487Z,160,2,1108,C,A,1,14.26,2,0,165786,213735006,13.37,100,1,13.99,100,1,13.15,2,1,14.28,100,1,13.10,100,1,14.56,100,1,12.73,100,1,14.61,100,1,12.67,100,1,14.84,100,1,12.65,200,2,14.89,100,1,12.50,700,1,14.91,700,1,12.47,100,1,14.95,700,1,12.46,100,1,14.98,200,2,12.43,700,1,14.99,700,1,ARL,129518753
720,2025-07-17T15:10:34.469866273Z,2025-07-17T15:10:34.469700487Z,160,2,1108,A,A,1,14.17,2,130,165786,213735006,13.37,100,1,13.99,100,1,13.15,2,1,14.17,2,1,13.10,100,1,14.28,100,1,12.73,100,1,14.56,100,1,12.67,100,1,14.61,100,1,12.65,200,2,14.84,100,1,12.50,700,1,14.89,100,1,12.47,100,1,14.91,700,1,12.46,100,1,14.95,700,1,12.43,700,1,14.98,200,2,ARL,252720897
721,2025-07-17T15:12:52.735414592Z,2025-07-17T15:12:52.735249178Z,160,2,1108,A,A,1,14.03,100,130,165414,216651092,13.37,100,1,13.99,100,1,13.15,2,1,14.03,100,1,13.10,100,1,14.17,2,1,12.73,100,1,14.28,100,1,12.67,100,1,14.56,100,1,12.65,200,2,14.61,100,1,12.50,700,1,14.84,100,1,12.47,100,1,14.89,100,1,12.46,100,1,14.91,700,1,12.43,700,1,14.95,700,1,ARL,256325129
722,2025-07-17T15:13:06.511853457Z,2025-07-17T15:13:06.511687613Z,160,2,1108,A,A,0,13.98,10,130,165844,216995105,13.37,100,1,13.98,10,1,13.15,2,1,13.99,100,1,13.10,100,1,14.03,100,1,12.73,100,1,14.17,2,1,12.67,100,1,14.28,100,1,12.65,200,2,14.56,100,1,12.50,700,1,14.61,100,1,12.47,100,1,14.84,100,1,12.46,100,1,14.89,100,1,12.43,700,1,14.91,700,1,ARL,256739841
723,2025-07-17T15:13:08.654089411Z,2025-07-17T15:13:08.653923821Z,160,2,1108,A,A,2,14.01,100,130,165590,217058300,13.37,100,1,13.98,10,1,13.15,2,1,13.99,100,1,13.10,100,1,14.01,100,1,12.73,100,1,14.03,100,1,12.67,100,1,14.17,2,1,12.65,200,2,14.28,100,1,12.50,700,1,14.56,100,1,12.47,100,1,14.61,100,1,12.46,100,1,14.84,100,1,12.43,700,1,14.89,100,1,ARL,256818881
724,2025-07-17T15:13:08.661686458Z,2025-07-17T15:13:08.661521116Z,160,2,1108,C,A,3,14.03,100,130,165342,217058550,13.37,100,1,13.98,10,1,13.15,2,1,13.99,100,1,13.10,100,1,14.01,100,1,12.73,100,1,14.17,2,1,12.67,100,1,14.28,100,1,12.65,200,2,14.56,100,1,12.50,700,1,14.61,100,1,12.47,100,1,14.84,100,1,12.46,100,1,14.89,100,1,12.43,700,1,14.91,700,1,ARL,256325129
725,2025-07-17T15:14:00.440728359Z,2025-07-17T15:14:00.440563034Z,160,2,1108,C,A,0,13.98,10,130,165325,218096891,13.37,100,1,13.99,100,1,13.15,2,1,14.01,100,1,13.10,100,1,14.17,2,1,12.73,100,1,14.28,100,1,12.67,100,1,14.56,100,1,12.65,200,2,14.61,100,1,12.50,700,1,14.84,100,1,12.47,100,1,14.89,100,1,12.46,100,1,14.91,700,1,12.43,700,1,14.95,700,1,ARL,256739841
726,2025-07-17T15:14:52.382139830Z,2025-07-17T15:14:52.381974473Z,160,2,1108,A,A,0,13.98,10,130,165357,219204095,13.37,100,1,13.98,10,1,13.15,2,1,13.99,100,1,13.10,100,1,14.01,100,1,12.73,100,1,14.17,2,1,12.67,100,1,14.28,100,1,12.65,200,2,14.56,100,1,12.50,700,1,14.61,100,1,12.47,100,1,14.84,100,1,12.46,100,1,14.89,100,1,12.43,700,1,14.91,700,1,ARL,259546169
727,2025-07-17T15:14:56.683309707Z,2025-07-17T15:14:56.683144163Z,160,2,1108,C,A,2,14.01,100,130,165544,219317677,13.37,100,1,13.98,10,1,13.15,2,1,13.99,100,1,13.10,100,1,14.17,2,1,12.73,100,1,14.28,100,1,12.67,100,1,14.56,100,1,12.65,200,2,14.61,100,1,12.50,700,1,14.84,100,1,12.47,100,1,14.89,100,1,12.46,100,1,14.91,700,1,12.43,700,1,14.95,700,1,ARL,256818881
728,2025-07-17T15:15:11.661118778Z,2025-07-17T15:15:11.660953613Z,160,2,1108,A,A,2,14.02,100,130,165165,219726276,13.37,100,1,13.98,10,1,13.15,2,1,13.99,100,1,13.10,100,1,14.02,100,1,12.73,100,1,14.17,2,1,12.67,100,1,14.28,100,1,12.65,200,2,14.56,100,1,12.50,700,1,14.61,100,1,12.47,100,1,14.84,100,1,12.46,100,1,14.89,100,1,12.43,700,1,14.91,700,1,ARL,260184621
729,2025-07-17T15:15:32.408863263Z,2025-07-17T15:15:32.408694312Z,160,2,1108,C,A,0,13.98,10,128,168951,220152194,13.37,100,1,13.99,100,1,13.15,2,1,14.02,100,1,13.10,100,1,14.17,2,1,12.73,100,1,14.28,100,1,12.67,100,1,14.56,100,1,12.65,200,2,14.61,100,1,12.50,700,1,14.84,100,1,12.47,100,1,14.89,100,1,12.46,100,1,14.91,700,1,12.43,700,1,14.95,700,1,ARL,259546169
730,2025-07-17T15:16:31.607242914Z,2025-07-17T15:16:31.607077080Z,160,2,1108,A,A,1,14.00,100,130,165834,221423516,13.37,100,1,13.99,100,1,13.15,2,1,14.00,100,1,13.10,100,1,14.02,100,1,12.73,100,1,14.17,2,1,12.67,100,1,14.28,100,1,12.65,200,2,14.56,100,1,12.50,700,1,14.61,100,1,12.47,100,1,14.84,100,1,12.46,100,1,14.89,100,1,12.43,700,1,14.91,700,1,ARL,262279553
731,2025-07-17T15:16:31.614370696Z,2025-07-17T15:16:31.614205345Z,160,2,1108,C,A,2,14.02,100,130,165351,221423706,13.37,100,1,13.99,100,1,13.15,2,1,14.00,100,1,13.10,100,1,14.17,2,1,12.73,100,1,14.28,100,1,12.67,100,1,14.56,100,1,12.65,200,2,14.61,100,1,12.50,700,1,14.84,100,1,12.47,100,1,14.89,100,1,12.46,100,1,14.91,700,1,12.43,700,1,14.95,700,1,ARL,260184621
732,2025-07-17T15:16:39.373467449Z,2025-07-17T15:16:39.373301585Z,160,2,1108,A,A,0,13.98,10,130,165864,221549244,13.37,100,1,13.98,10,1,13.15,2,1,13.99,100,1,13.10,100,1,14.00,100,1,12.73,100,1,14.17,2,1,12.67,100,1,14.28,100,1,12.65,200,2,14.56,100,1,12.50,700,1,14.61,100,1,12.47,100,1,14.84,100,1,12.46,100,1,14.89,100,1,12.43,700,1,14.91,700,1,ARL,262432821
733,2025-07-17T15:17:50.916325497Z,2025-07-17T15:17:50.916157330Z,160,2,1108,C,A,0,13.98,10,130,168167,223060323,13.37,100,1,13.99,100,1,13.15,2,1,14.00,100,1,13.10,100,1,14.17,2,1,12.73,100,1,14.28,100,1,12.67,100,1,14.56,100,1,12.65,200,2,14.61,100,1,12.50,700,1,14.84,100,1,12.47,100,1,14.89,100,1,12.46,100,1,14.91,700,1,12.43,700,1,14.95,700,1,ARL,262432821
734,2025-07-17T15:17:51.938467389Z,2025-07-17T15:17:51.938301087Z,160,2,1108,C,A,1,14.00,100,130,166302,223092013,13.37,100,1,13.99,100,1,13.15,2,1,14.17,2,1,13.10,100,1,14.28,100,1,12.73,100,1,14.56,100,1,12.67,100,1,14.61,100,1,12.65,200,2,14.84,100,1,12.50,700,1,14.89,100,1,12.47,100,1,14.91,700,1,12.46,100,1,14.95,700,1,12.43,700,1,14.98,200,2,ARL,262279553
735,2025-07-17T15:17:55.957423821Z,2025-07-17T15:17:55.957258362Z,160,2,1108,A,A,1,14.01,100,130,165459,223181022,13.37,100,1,13.99,100,1,13.15,2,1,14.01,100,1,13.10,100,1,14.17,2,1,12.73,100,1,14.28,100,1,12.67,100,1,14.56,100,1,12.65,200,2,14.61,100,1,12.50,700,1,14.84,100,1,12.47,100,1,14.89,100,1,12.46,100,1,14.91,700,1,12.43,700,1,14.95,700,1,ARL,264420961
736,2025-07-17T15:19:23.618380576Z,2025-07-17T15:19:23.618215364Z,160,2,1108,C,A,1,14.01,100,130,165212,224925658,13.37,100,1,13.99,100,1,13.15,2,1,14.17,2,1,13.10,100,1,14.28,100,1,12.73,100,1,14.56,100,1,12.67,100,1,14.61,100,1,12.65,200,2,14.84,100,1,12.50,700,1,14.89,100,1,12.47,100,1,14.91,700,1,12.46,100,1,14.95,700,1,12.43,700,1,14.98,200,2,ARL,264420961
737,2025-07-17T15:19:27.663790911Z,2025-07-17T15:19:27.663625107Z,160,2,1108,A,A,1,14.03,100,130,165804,224999109,13.37,100,1,13.99,100,1,13.15,2,1,14.03,100,1,13.10,100,1,14.17,2,1,12.73,100,1,14.28,100,1,12.67,100,1,14.56,100,1,12.65,200,2,14.61,100,1,12.50,700,1,14.84,100,1,12.47,100,1,14.89,100,1,12.46,100,1,14.91,700,1,12.43,700,1,14.95,700,1,ARL,266714557
738,2025-07-17T15:20:46.705145876Z,2025-07-17T15:20:46.704980311Z,160,2,1108,A,A,1,14.01,100,130,165565,226851430,13.37,100,1,13.99,100,1,13.15,2,1,14.01,100,1,13.10,100,1,14.03,100,1,12.73,100,1,14.17,2,1,12.67,100,1,14.28,100,1,12.65,200,2,14.56,100,1,12.50,700,1,14.61,100,1,12.47,100,1,14.84,100,1,12.46,100,1,14.89,100,1,12.43,700,1,14.91,700,1,ARL,269075833
739,2025-07-17T15:20:46.716698477Z,2025-07-17T15:20:46.716532886Z,160,2,1108,C,A,2,14.03,100,130,165591,226851533,13.37,100,1,13.99,100,1,13.15,2,1,14.01,100,1,13.10,100,1,14.17,2,1,12.73,100,1,14.28,100,1,12.67,100,1,14.56,100,1,12.65,200,2,14.61,100,1,12.50,700,1,14.84,100,1,12.47,100,1,14.89,100,1,12.46,100,1,14.91,700,1,12.43,700,1,14.95,700,1,ARL,266714557
740,2025-07-17T15:23:00.249962772Z,2025-07-17T15:23:00.249796874Z,160,2,1108,C,B,1,13.15,2,0,165898,229397485,13.37,100,1,13.99,100,1,13.10,100,1,14.01,100,1,12.73,100,1,14.17,2,1,12.67,100,1,14.28,100,1,12.65,200,2,14.56,100,1,12.50,700,1,14.61,100,1,12.47,100,1,14.84,100,1,12.46,100,1,14.89,100,1,12.43,700,1,14.91,700,1,12.42,700,1,14.95,700,1,ARL,130693973
741,2025-07-17T15:23:00.249962772Z,2025-07-17T15:23:00.249796874Z,160,2,1108,A,B,1,13.23,2,130,165898,229397485,13.37,100,1,13.99,100,1,13.23,2,1,14.01,100,1,13.10,100,1,14.17,2,1,12.73,100,1,14.28,100,1,12.67,100,1,14.56,100,1,12.65,200,2,14.61,100,1,12.50,700,1,14.84,100,1,12.47,100,1,14.89,100,1,12.46,100,1,14.91,700,1,12.43,700,1,14.95,700,1,ARL,272263853
742,2025-07-17T15:26:04.666158860Z,2025-07-17T15:26:04.665993515Z,160,2,1108,C,A,2,14.17,2,0,165345,232977340,13.37,100,1,13.99,100,1,13.23,2,1,14.01,100,1,13.10,100,1,14.28,100,1,12.73,100,1,14.56,100,1,12.67,100,1,14.61,100,1,12.65,200,2,14.84,100,1,12.50,700,1,14.89,100,1,12.47,100,1,14.91,700,1,12.46,100,1,14.95,700,1,12.43,700,1,14.98,200,2,ARL,252720897
743,2025-07-17T15:26:04.666158860Z,2025-07-17T15:26:04.665993515Z,160,2,1108,A,A,2,14.09,2,130,165345,232977340,13.37,100,1,13.99,100,1,13.23,2,1,14.01,100,1,13.10,100,1,14.09,2,1,12.73,100,1,14.28,100,1,12.67,100,1,14.56,100,1,12.65,200,2,14.61,100,1,12.50,700,1,14.84,100,1,12.47,100,1,14.89,100,1,12.46,100,1,14.91,700,1,12.43,700,1,14.95,700,1,ARL,276751517
744,2025-07-17T15:28:38.882985923Z,2025-07-17T15:28:38.882820591Z,160,2,1108,A,A,0,13.99,100,130,165332,235874491,13.37,100,1,13.99,200,2,13.23,2,1,14.01,100,1,13.10,100,1,14.09,2,1,12.73,100,1,14.28,100,1,12.67,100,1,14.56,100,1,12.65,200,2,14.61,100,1,12.50,700,1,14.84,100,1,12.47,100,1,14.89,100,1,12.46,100,1,14.91,700,1,12.43,700,1,14.95,700,1,ARL,280387693
745,2025-07-17T15:28:38.890789214Z,2025-07-17T15:28:38.890623989Z,160,2,1108,C,A,1,14.01,100,130,165225,235874556,13.37,100,1,13.99,200,2,13.23,2,1,14.09,2,1,13.10,100,1,14.28,100,1,12.73,100,1,14.56,100,1,12.67,100,1,14.61,100,1,12.65,200,2,14.84,100,1,12.50,700,1,14.89,100,1,12.47,100,1,14.91,700,1,12.46,100,1,14.95,700,1,12.43,700,1,14.98,200,2,ARL,269075833
746,2025-07-17T15:28:44.820934614Z,2025-07-17T15:28:44.820769301Z,160,2,1108,C,A,0,13.99,100,130,165313,235961324,13.37,100,1,13.99,100,1,13.23,2,1,14.09,2,1,13.10,100,1,14.28,100,1,12.73,100,1,14.56,100,1,12.67,100,1,14.61,100,1,12.65,200,2,14.84,100,1,12.50,700,1,14.89,100,1,12.47,100,1,14.91,700,1,12.46,100,1,14.95,700,1,12.43,700,1,14.98,200,2,ARL,280387693
747,2025-07-17T15:28:48.918811203Z,2025-07-17T15:28:48.918645728Z,160,2,1108,A,A,1,14.01,100,130,165475,236028551,13.37,100,1,13.99,100,1,13.23,2,1,14.01,100,1,13.10,100,1,14.09,2,1,12.73,100,1,14.28,100,1,12.67,100,1,14.56,100,1,12.65,200,2,14.61,100,1,12.50,700,1,14.84,100,1,12.47,100,1,14.89,100,1,12.46,100,1,14.91,700,1,12.43,700,1,14.95,700,1,ARL,280580873
748,2025-07-17T15:30:23.573233259Z,2025-07-17T15:30:23.573067851Z,160,2,1108,A,A,0,13.82,10,130,165408,237754758,13.37,100,1,13.82,10,1,13.23,2,1,13.99,100,1,13.10,100,1,14.01,100,1,12.73,100,1,14.09,2,1,12.67,100,1,14.28,100,1,12.65,200,2,14.56,100,1,12.50,700,1,14.61,100,1,12.47,100,1,14.84,100,1,12.46,100,1,14.89,100,1,12.43,700,1,14.91,700,1,ARL,282775557
749,2025-07-17T15:30:23.573528359Z,2025-07-17T15:30:23.573362522Z,160,2,1108,C,A,11,14.98,100,0,165837,237754762,13.37,100,1,13.82,10,1,13.23,2,1,13.99,100,1,13.10,100,1,14.01,100,1,12.73,100,1,14.09,2,1,12.67,100,1,14.28,100,1,12.65,200,2,14.56,100,1,12.50,700,1,14.61,100,1,12.47,100,1,14.84,100,1,12.46,100,1,14.89,100,1,12.43,700,1,14.91,700,1,ARL,128570237
750,2025-07-17T15:30:23.573528359Z,2025-07-17T15:30:23.573362522Z,160,2,1108,A,A,7,14.72,100,130,165837,237754762,13.37,100,1,13.82,10,1,13.23,2,1,13.99,100,1,13.10,100,1,14.01,100,1,12.73,100,1,14.09,2,1,12.67,100,1,14.28,100,1,12.65,200,2,14.56,100,1,12.50,700,1,14.61,100,1,12.47,100,1,14.72,100,1,12.46,100,1,14.84,100,1,12.43,700,1,14.89,100,1,ARL,282775561
751,2025-07-17T15:30:23.574854165Z,2025-07-17T15:30:23.574688647Z,160,2,1108,C,A,12,14.98,100,0,165518,237754776,13.37,100,1,13.82,10,1,13.23,2,1,13.99,100,1,13.10,100,1,14.01,100,1,12.73,100,1,14.09,2,1,12.67,100,1,14.28,100,1,12.65,200,2,14.56,100,1,12.50,700,1,14.61,100,1,12.47,100,1,14.72,100,1,12.46,100,1,14.84,100,1,12.43,700,1,14.89,100,1,ARL,128570229
752,2025-07-17T15:30:23.574854165Z,2025-07-17T15:30:23.574688647Z,160,2,1108,A,A,7,14.72,100,130,165518,237754776,13.37,100,1,13.82,10,1,13.23,2,1,13.99,100,1,13.10,100,1,14.01,100,1,12.73,100,1,14.09,2,1,12.67,100,1,14.28,100,1,12.65,200,2,14.56,100,1,12.50,700,1,14.61,100,1,12.47,100,1,14.72,200,2,12.46,100,1,14.84,100,1,12.43,700,1,14.89,100,1,ARL,282775577
753,2025-07-17T15:30:23.585191081Z,2025-07-17T15:30:23.585025490Z,160,2,1108,A,A,1,13.84,100,130,165591,237755075,13.37,100,1,13.82,10,1,13.23,2,1,13.84,100,1,13.10,100,1,13.99,100,1,12.73,100,1,14.01,100,1,12.67,100,1,14.09,2,1,12.65,200,2,14.28,100,1,12.50,700,1,14.56,100,1,12.47,100,1,14.61,100,1,12.46,100,1,14.72,200,2,12.43,700,1,14.84,100,1,ARL,282775973
754,2025-07-17T15:30:23.585960886Z,2025-07-17T15:30:23.585795327Z,160,2,1108,C,A,16,15.09,100,0,165559,237755081,13.37,100,1,13.82,10,1,13.23,2,1,13.84,100,1,13.10,100,1,13.99,100,1,12.73,100,1,14.01,100,1,12.67,100,1,14.09,2,1,12.65,200,2,14.28,100,1,12.50,700,1,14.56,100,1,12.47,100,1,14.61,100,1,12.46,100,1,14.72,200,2,12.43,700,1,14.84,100,1,ARL,146955361
755,2025-07-17T15:30:23.585960886Z,2025-07-17T15:30:23.585795327Z,160,2,1108,A,A,11,14.91,100,130,165559,237755081,13.37,100,1,13.82,10,1,13.23,2,1,13.84,100,1,13.10,100,1,13.99,100,1,12.73,100,1,14.01,100,1,12.67,100,1,14.09,2,1,12.65,200,2,14.28,100,1,12.50,700,1,14.56,100,1,12.47,100,1,14.61,100,1,12.46,100,1,14.72,200,2,12.43,700,1,14.84,100,1,ARL,282776009
756,2025-07-17T15:30:23.586719371Z,2025-07-17T15:30:23.586553674Z,160,2,1108,C,A,10,14.89,100,0,165697,237755086,13.37,100,1,13.82,10,1,13.23,2,1,13.84,100,1,13.10,100,1,13.99,100,1,12.73,100,1,14.01,100,1,12.67,100,1,14.09,2,1,12.65,200,2,14.28,100,1,12.50,700,1,14.56,100,1,12.47,100,1,14.61,100,1,12.46,100,1,14.72,200,2,12.43,700,1,14.84,100,1,ARL,128570453
757,2025-07-17T15:30:23.586719371Z,2025-07-17T15:30:23.586553674Z,160,2,1108,A,A,8,14.65,100,130,165697,237755086,13.37,100,1,13.82,10,1,13.23,2,1,13.84,100,1,13.10,100,1,13.99,100,1,12.73,100,1,14.01,100,1,12.67,100,1,14.09,2,1,12.65,200,2,14.28,100,1,12.50,700,1,14.56,100,1,12.47,100,1,14.61,100,1,12.46,100,1,14.65,100,1,12.43,700,1,14.72,200,2,ARL,282776013
758,2025-07-17T15:30:23.586762105Z,2025-07-17T15:30:23.586596452Z,160,2,1108,C,A,18,15.64,100,0,165653,237755087,13.37,100,1,13.82,10,1,13.23,2,1,13.84,100,1,13.10,100,1,13.99,100,1,12.73,100,1,14.01,100,1,12.67,100,1,14.09,2,1,12.65,200,2,14.28,100,1,12.50,700,1,14.56,100,1,12.47,100,1,14.61,100,1,12.46,100,1,14.65,100,1,12.43,700,1,14.72,200,2,ARL,84628833
759,2025-07-17T15:30:23.586762105Z,2025-07-17T15:30:23.586596452Z,160,2,1108,A,A,16,15.23,100,130,165653,237755087,13.37,100,1,13.82,10,1,13.23,2,1,13.84,100,1,13.10,100,1,13.99,100,1,12.73,100,1,14.01,100,1,12.67,100,1,14.09,2,1,12.65,200,2,14.28,100,1,12.50,700,1,14.56,100,1,12.47,100,1,14.61,100,1,12.46,100,1,14.65,100,1,12.43,700,1,14.72,200,2,ARL,282776017
760,2025-07-17T15:30:23.587432517Z,2025-07-17T15:30:23.587267064Z,160,2,1108,C,A,23,17.90,100,0,165453,237755097,13.37,100,1,13.82,10,1,13.23,2,1,13.84,100,1,13.10,100,1,13.99,100,1,12.73,100,1,14.01,100,1,12.67,100,1,14.09,2,1,12.65,200,2,14.28,100,1,12.50,700,1,14.56,100,1,12.47,100,1,14.61,100,1,12.46,100,1,14.65,100,1,12.43,700,1,14.72,200,2,ARL,128570685
761,2025-07-17T15:30:23.587432517Z,2025-07-17T15:30:23.587267064Z,160,2,1108,A,A,23,17.58,100,130,165453,237755097,13.37,100,1,13.82,10,1,13.23,2,1,13.84,100,1,13.10,100,1,13.99,100,1,12.73,100,1,14.01,100,1,12.67,100,1,14.09,2,1,12.65,200,2,14.28,100,1,12.50,700,1,14.56,100,1,12.47,100,1,14.61,100,1,12.46,100,1,14.65,100,1,12.43,700,1,14.72,200,2,ARL,282776025
762,2025-07-17T15:30:23.587581881Z,2025-07-17T15:30:23.587416236Z,160,2,1108,C,A,15,15.08,100,0,165645,237755098,13.37,100,1,13.82,10,1,13.23,2,1,13.84,100,1,13.10,100,1,13.99,100,1,12.73,100,1,14.01,100,1,12.67,100,1,14.09,2,1,12.65,200,2,14.28,100,1,12.50,700,1,14.56,100,1,12.47,100,1,14.61,100,1,12.46,100,1,14.65,100,1,12.43,700,1,14.72,200,2,ARL,128570449
763,2025-07-17T15:30:23.587581881Z,2025-07-17T15:30:23.587416236Z,160,2,1108,A,A,10,14.81,100,130,165645,237755098,13.37,100,1,13.82,10,1,13.23,2,1,13.84,100,1,13.10,100,1,13.99,100,1,12.73,100,1,14.01,100,1,12.67,100,1,14.09,2,1,12.65,200,2,14.28,100,1,12.50,700,1,14.56,100,1,12.47,100,1,14.61,100,1,12.46,100,1,14.65,100,1,12.43,700,1,14.72,200,2,ARL,282776029
764,2025-07-17T15:30:23.587611440Z,2025-07-17T15:30:23.587445922Z,160,2,1108,C,A,22,16.21,100,0,165518,237755099,13.37,100,1,13.82,10,1,13.23,2,1,13.84,100,1,13.10,100,1,13.99,100,1,12.73,100,1,14.01,100,1,12.67,100,1,14.09,2,1,12.65,200,2,14.28,100,1,12.50,700,1,14.56,100,1,12.47,100,1,14.61,100,1,12.46,100,1,14.65,100,1,12.43,700,1,14.72,200,2,ARL,128570977
765,2025-07-17T15:30:23.587611440Z,2025-07-17T15:30:23.587445922Z,160,2,1108,A,A,20,15.92,100,130,165518,237755099,13.37,100,1,13.82,10,1,13.23,2,1,13.84,100,1,13.10,100,1,13.99,100,1,12.73,100,1,14.01,100,1,12.67,100,1,14.09,2,1,12.65,200,2,14.28,100,1,12.50,700,1,14.56,100,1,12.47,100,1,14.61,100,1,12.46,100,1,14.65,100,1,12.43,700,1,14.72,200,2,ARL,282776033
766,2025-07-17T15:30:23.590261792Z,2025-07-17T15:30:23.590096343Z,160,2,1108,C,A,16,15.08,100,0,165449,237755128,13.37,100,1,13.82,10,1,13.23,2,1,13.84,100,1,13.10,100,1,13.99,100,1,12.73,100,1,14.01,100,1,12.67,100,1,14.09,2,1,12.65,200,2,14.28,100,1,12.50,700,1,14.56,100,1,12.47,100,1,14.61,100,1,12.46,100,1,14.65,100,1,12.43,700,1,14.72,200,2,ARL,128573957
767,2025-07-17T15:30:23.590261792Z,2025-07-17T15:30:23.590096343Z,160,2,1108,A,A,10,14.81,100,130,165449,237755128,13.37,100,1,13.82,10,1,13.23,2,1,13.84,100,1,13.10,100,1,13.99,100,1,12.73,100,1,14.01,100,1,12.67,100,1,14.09,2,1,12.65,200,2,14.28,100,1,12.50,700,1,14.56,100,1,12.47,100,1,14.61,100,1,12.46,100,1,14.65,100,1,12.43,700,1,14.72,200,2,ARL,282776089
768,2025-07-17T15:30:23.591959120Z,2025-07-17T15:30:23.591793735Z,160,2,1108,C,A,3,14.01,100,130,165385,237755138,13.37,100,1,13.82,10,1,13.23,2,1,13.84,100,1,13.10,100,1,13.99,100,1,12.73,100,1,14.09,2,1,12.67,100,1,14.28,100,1,12.65,200,2,14.56,100,1,12.50,700,1,14.61,100,1,12.47,100,1,14.65,100,1,12.46,100,1,14.72,200,2,12.43,700,1,14.81,200,2,ARL,280580873
769,2025-07-17T15:30:23.602992439Z,2025-07-17T15:30:23.602827102Z,160,2,1108,C,A,4,14.28,100,130,165337,237755229,13.37,100,1,13.82,10,1,13.23,2,1,13.84,100,1,13.10,100,1,13.99,100,1,12.73,100,1,14.09,2,1,12.67,100,1,14.56,100,1,12.65,200,2,14.61,100,1,12.50,700,1,14.65,100,1,12.47,100,1,14.72,200,2,12.46,100,1,14.81,200,2,12.43,700,1,14.84,100,1,ARL,146956357
770,2025-07-17T15:30:23.603046460Z,2025-07-17T15:30:23.602881129Z,160,2,1108,A,A,4,14.12,100,130,165331,237755230,13.37,100,1,13.82,10,1,13.23,2,1,13.84,100,1,13.10,100,1,13.99,100,1,12.73,100,1,14.09,2,1,12.67,100,1,14.12,100,1,12.65,200,2,14.56,100,1,12.50,700,1,14.61,100,1,12.47,100,1,14.65,100,1,12.46,100,1,14.72,200,2,12.43,700,1,14.81,200,2,ARL,282776285
771,2025-07-17T15:30:23.628720816Z,2025-07-17T15:30:23.628555135Z,160,2,1108,A,A,18,15.78,100,130,165681,237755415,13.37,100,1,13.82,10,1,13.23,2,1,13.84,100,1,13.10,100,1,13.99,100,1,12.73,100,1,14.09,2,1,12.67,100,1,14.12,100,1,12.65,200,2,14.56,100,1,12.50,700,1,14.61,100,1,12.47,100,1,14.65,100,1,12.46,100,1,14.72,200,2,12.43,700,1,14.81,200,2,ARL,282776733
772,2025-07-17T15:30:23.628732597Z,2025-07-17T15:30:23.628567293Z,160,2,1108,C,A,21,16.20,100,130,165304,237755416,13.37,100,1,13.82,10,1,13.23,2,1,13.84,100,1,13.10,100,1,13.99,100,1,12.73,100,1,14.09,2,1,12.67,100,1,14.12,100,1,12.65,200,2,14.56,100,1,12.50,700,1,14.61,100,1,12.47,100,1,14.65,100,1,12.46,100,1,14.72,200,2,12.43,700,1,14.81,200,2,ARL,84628765
773,2025-07-17T15:30:23.952122580Z,2025-07-17T15:30:23.951957017Z,160,2,1108,C,A,2,13.99,100,0,165563,237759683,13.37,100,1,13.82,10,1,13.23,2,1,13.84,100,1,13.10,100,1,14.09,2,1,12.73,100,1,14.12,100,1,12.67,100,1,14.56,100,1,12.65,200,2,14.61,100,1,12.50,700,1,14.65,100,1,12.47,100,1,14.72,200,2,12.46,100,1,14.81,200,2,12.43,700,1,14.84,100,1,ARL,237978541
774,2025-07-17T15:30:23.952122580Z,2025-07-17T15:30:23.951957017Z,160,2,1108,A,A,1,13.83,100,130,165563,237759683,13.37,100,1,13.82,10,1,13.23,2,1,13.83,100,1,13.10,100,1,13.84,100,1,12.73,100,1,14.09,2,1,12.67,100,1,14.12,100,1,12.65,200,2,14.56,100,1,12.50,700,1,14.61,100,1,12.47,100,1,14.65,100,1,12.46,100,1,14.72,200,2,12.43,700,1,14.81,200,2,ARL,282781741
775,2025-07-17T15:30:24.769074814Z,2025-07-17T15:30:24.768909757Z,160,2,1108,C,A,0,13.82,10,130,165057,237771822,13.37,100,1,13.83,100,1,13.23,2,1,13.84,100,1,13.10,100,1,14.09,2,1,12.73,100,1,14.12,100,1,12.67,100,1,14.56,100,1,12.65,200,2,14.61,100,1,12.50,700,1,14.65,100,1,12.47,100,1,14.72,200,2,12.46,100,1,14.81,200,2,12.43,700,1,14.84,100,1,ARL,282775557
776,2025-07-17T15:30:28.617337198Z,2025-07-17T15:30:28.617171810Z,160,2,1108,A,A,4,14.53,700,130,165388,237840336,13.37,100,1,13.83,100,1,13.23,2,1,13.84,100,1,13.10,100,1,14.09,2,1,12.73,100,1,14.12,100,1,12.67,100,1,14.53,700,1,12.65,200,2,14.56,100,1,12.50,700,1,14.61,100,1,12.47,100,1,14.65,100,1,12.46,100,1,14.72,200,2,12.43,700,1,14.81,200,2,ARL,282881853
777,2025-07-17T15:30:28.617387294Z,2025-07-17T15:30:28.617221981Z,160,2,1108,C,A,14,15.07,700,130,165313,237840337,13.37,100,1,13.83,100,1,13.23,2,1,13.84,100,1,13.10,100,1,14.09,2,1,12.73,100,1,14.12,100,1,12.67,100,1,14.53,700,1,12.65,200,2,14.56,100,1,12.50,700,1,14.61,100,1,12.47,100,1,14.65,100,1,12.46,100,1,14.72,200,2,12.43,700,1,14.81,200,2,ARL,92510741
778,2025-07-17T15:30:30.767213907Z,2025-07-17T15:30:30.767048606Z,160,2,1108,A,A,6,14.60,700,130,165301,237873135,13.37,100,1,13.83,100,1,13.23,2,1,13.84,100,1,13.10,100,1,14.09,2,1,12.73,100,1,14.12,100,1,12.67,100,1,14.53,700,1,12.65,200,2,14.56,100,1,12.50,700,1,14.60,700,1,12.47,100,1,14.61,100,1,12.46,100,1,14.65,100,1,12.43,700,1,14.72,200,2,ARL,282920685
779,2025-07-17T15:30:30.767267001Z,2025-07-17T15:30:30.767101317Z,160,2,1108,C,A,14,14.99,700,130,165684,237873136,13.37,100,1,13.83,100,1,13.23,2,1,13.84,100,1,13.10,100,1,14.09,2,1,12.73,100,1,14.12,100,1,12.67,100,1,14.53,700,1,12.65,200,2,14.56,100,1,12.50,700,1,14.60,700,1,12.47,100,1,14.61,100,1,12.46,100,1,14.65,100,1,12.43,700,1,14.72,200,2,ARL,84628757
780,2025-07-17T15:30:33.016987097Z,2025-07-17T15:30:33.016821395Z,160,2,1108,A,A,5,14.56,700,130,165702,237915946,13.37,100,1,13.83,100,1,13.23,2,1,13.84,100,1,13.10,100,1,14.09,2,1,12.73,100,1,14.12,100,1,12.67,100,1,14.53,700,1,12.65,200,2,14.56,800,2,12.50,700,1,14.60,700,1,12.47,100,1,14.61,100,1,12.46,100,1,14.65,100,1,12.43,700,1,14.72,200,2,ARL,282969973
781,2025-07-17T15:30:33.017384279Z,2025-07-17T15:30:33.017218657Z,160,2,1108,C,A,13,14.95,700,130,165622,237915951,13.37,100,1,13.83,100,1,13.23,2,1,13.84,100,1,13.10,100,1,14.09,2,1,12.73,100,1,14.12,100,1,12.67,100,1,14.53,700,1,12.65,200,2,14.56,800,2,12.50,700,1,14.60,700,1,12.47,100,1,14.61,100,1,12.46,100,1,14.65,100,1,12.43,700,1,14.72,200,2,ARL,84628797
782,2025-07-17T15:30:49.985906754Z,2025-07-17T15:30:49.985741094Z,160,2,1108,C,A,2,14.09,2,0,165660,238230724,13.37,100,1,13.83,100,1,13.23,2,1,13.84,100,1,13.10,100,1,14.12,100,1,12.73,100,1,14.53,700,1,12.67,100,1,14.56,800,2,12.65,200,2,14.60,700,1,12.50,700,1,14.61,100,1,12.47,100,1,14.65,100,1,12.46,100,1,14.72,200,2,12.43,700,1,14.81,200,2,ARL,276751517
783,2025-07-17T15:30:49.985906754Z,2025-07-17T15:30:49.985741094Z,160,2,1108,A,A,2,14.02,2,130,165660,238230724,13.37,100,1,13.83,100,1,13.23,2,1,13.84,100,1,13.10,100,1,14.02,2,1,12.73,100,1,14.12,100,1,12.67,100,1,14.53,700,1,12.65,200,2,14.56,800,2,12.50,700,1,14.60,700,1,12.47,100,1,14.61,100,1,12.46,100,1,14.65,100,1,12.43,700,1,14.72,200,2,ARL,283348193
784,2025-07-17T15:30:59.996516554Z,2025-07-17T15:30:59.996351383Z,160,2,1108,C,A,0,13.83,100,130,165171,238442318,13.37,100,1,13.84,100,1,13.23,2,1,14.02,2,1,13.10,100,1,14.12,100,1,12.73,100,1,14.53,700,1,12.67,100,1,14.56,800,2,12.65,200,2,14.60,700,1,12.50,700,1,14.61,100,1,12.47,100,1,14.65,100,1,12.46,100,1,14.72,200,2,12.43,700,1,14.81,200,2,ARL,282781741
785,2025-07-17T15:31:00.002203922Z,2025-07-17T15:31:00.002038446Z,160,2,1108,C,A,0,13.84,100,130,165476,238442443,13.37,100,1,14.02,2,1,13.23,2,1,14.12,100,1,13.10,100,1,14.53,700,1,12.73,100,1,14.56,800,2,12.67,100,1,14.60,700,1,12.65,200,2,14.61,100,1,12.50,700,1,14.65,100,1,12.47,100,1,14.72,200,2,12.46,100,1,14.81,200,2,12.43,700,1,14.84,100,1,ARL,282775973
786,2025-07-17T15:31:00.002478393Z,2025-07-17T15:31:00.002313250Z,160,2,1108,C,A,2,14.53,700,130,165143,238442461,13.37,100,1,14.02,2,1,13.23,2,1,14.12,100,1,13.10,100,1,14.56,800,2,12.73,100,1,14.60,700,1,12.67,100,1,14.61,100,1,12.65,200,2,14.65,100,1,12.50,700,1,14.72,200,2,12.47,100,1,14.81,200,2,12.46,100,1,14.84,100,1,12.43,700,1,14.91,800,2,ARL,282881853
787,2025-07-17T15:31:00.002525213Z,2025-07-17T15:31:00.002359969Z,160,2,1108,A,A,6,14.68,700,130,165244,238442467,13.37,100,1,14.02,2,1,13.23,2,1,14.12,100,1,13.10,100,1,14.56,800,2,12.73,100,1,14.60,700,1,12.67,100,1,14.61,100,1,12.65,200,2,14.65,100,1,12.50,700,1,14.68,700,1,12.47,100,1,14.72,200,2,12.46,100,1,14.81,200,2,12.43,700,1,14.84,100,1,ARL,283592941
788,2025-07-17T15:31:00.002938332Z,2025-07-17T15:31:00.002772683Z,160,2,1108,C,A,7,14.72,100,0,165649,238442486,13.37,100,1,14.02,2,1,13.23,2,1,14.12,100,1,13.10,100,1,14.56,800,2,12.73,100,1,14.60,700,1,12.67,100,1,14.61,100,1,12.65,200,2,14.65,100,1,12.50,700,1,14.68,700,1,12.47,100,1,14.72,100,1,12.46,100,1,14.81,200,2,12.43,700,1,14.84,100,1,ARL,282775577
789,2025-07-17T15:31:00.002938332Z,2025-07-17T15:31:00.002772683Z,160,2,1108,A,A,11,14.97,100,130,165649,238442486,13.37,100,1,14.02,2,1,13.23,2,1,14.12,100,1,13.10,100,1,14.56,800,2,12.73,100,1,14.60,700,1,12.67,100,1,14.61,100,1,12.65,200,2,14.65,100,1,12.50,700,1,14.68,700,1,12.47,100,1,14.72,100,1,12.46,100,1,14.81,200,2,12.43,700,1,14.84,100,1,ARL,283592993
790,2025-07-17T15:31:00.002953704Z,2025-07-17T15:31:00.002788190Z,160,2,1108,C,A,10,14.91,100,0,165514,238442490,13.37,100,1,14.02,2,1,13.23,2,1,14.12,100,1,13.10,100,1,14.56,800,2,12.73,100,1,14.60,700,1,12.67,100,1,14.61,100,1,12.65,200,2,14.65,100,1,12.50,700,1,14.68,700,1,12.47,100,1,14.72,100,1,12.46,100,1,14.81,200,2,12.43,700,1,14.84,100,1,ARL,282776009
791,2025-07-17T15:31:00.002953704Z,2025-07-17T15:31:00.002788190Z,160,2,1108,A,A,11,14.96,100,130,165514,238442490,13.37,100,1,14.02,2,1,13.23,2,1,14.12,100,1,13.10,100,1,14.56,800,2,12.73,100,1,14.60,700,1,12.67,100,1,14.61,100,1,12.65,200,2,14.65,100,1,12.50,700,1,14.68,700,1,12.47,100,1,14.72,100,1,12.46,100,1,14.81,200,2,12.43,700,1,14.84,100,1,ARL,283592997
792,2025-07-17T15:31:00.003368272Z,2025-07-17T15:31:00.003202003Z,160,2,1108,C,A,7,14.72,100,0,166269,238442510,13.37,100,1,14.02,2,1,13.23,2,1,14.12,100,1,13.10,100,1,14.56,800,2,12.73,100,1,14.60,700,1,12.67,100,1,14.61,100,1,12.65,200,2,14.65,100,1,12.50,700,1,14.68,700,1,12.47,100,1,14.81,200,2,12.46,100,1,14.84,100,1,12.43,700,1,14.91,700,1,ARL,282775561
793,2025-07-17T15:31:00.003368272Z,2025-07-17T15:31:00.003202003Z,160,2,1108,A,A,11,14.97,100,130,166269,238442510,13.37,100,1,14.02,2,1,13.23,2,1,14.12,100,1,13.10,100,1,14.56,800,2,12.73,100,1,14.60,700,1,12.67,100,1,14.61,100,1,12.65,200,2,14.65,100,1,12.50,700,1,14.68,700,1,12.47,100,1,14.81,200,2,12.46,100,1,14.84,100,1,12.43,700,1,14.91,700,1,ARL,283593041
794,2025-07-17T15:31:00.006784947Z,2025-07-17T15:31:00.006618398Z,160,2,1108,C,A,5,14.65,100,130,166549,238442608,13.37,100,1,14.02,2,1,13.23,2,1,14.12,100,1,13.10,100,1,14.56,800,2,12.73,100,1,14.60,700,1,12.67,100,1,14.61,100,1,12.65,200,2,14.68,700,1,12.50,700,1,14.81,200,2,12.47,100,1,14.84,100,1,12.46,100,1,14.91,700,1,12.43,700,1,14.96,100,1,ARL,282776013
795,2025-07-17T15:31:00.006950491Z,2025-07-17T15:31:00.006784814Z,160,2,1108,A,A,6,14.79,100,130,165677,238442616,13.37,100,1,14.02,2,1,13.23,2,1,14.12,100,1,13.10,100,1,14.56,800,2,12.73,100,1,14.60,700,1,12.67,100,1,14.61,100,1,12.65,200,2,14.68,700,1,12.50,700,1,14.79,100,1,12.47,100,1,14.81,200,2,12.46,100,1,14.84,100,1,12.43,700,1,14.91,700,1,ARL,283593313
796,2025-07-17T15:31:00.017759891Z,2025-07-17T15:31:00.017594312Z,160,2,1108,C,A,19,17.58,100,0,165579,238443214,13.37,100,1,14.02,2,1,13.23,2,1,14.12,100,1,13.10,100,1,14.56,800,2,12.73,100,1,14.60,700,1,12.67,100,1,14.61,100,1,12.65,200,2,14.68,700,1,12.50,700,1,14.79,100,1,12.47,100,1,14.81,200,2,12.46,100,1,14.84,100,1,12.43,700,1,14.91,700,1,ARL,282776025
797,2025-07-17T15:31:00.017759891Z,2025-07-17T15:31:00.017594312Z,160,2,1108,A,A,19,17.76,100,130,165579,238443214,13.37,100,1,14.02,2,1,13.23,2,1,14.12,100,1,13.10,100,1,14.56,800,2,12.73,100,1,14.60,700,1,12.67,100,1,14.61,100,1,12.65,200,2,14.68,700,1,12.50,700,1,14.79,100,1,12.47,100,1,14.81,200,2,12.46,100,1,14.84,100,1,12.43,700,1,14.91,700,1,ARL,283594173
798,2025-07-17T15:31:00.028894478Z,2025-07-17T15:31:00.028729168Z,160,2,1108,C,A,1,14.12,100,130,165310,238443996,13.37,100,1,14.02,2,1,13.23,2,1,14.56,800,2,13.10,100,1,14.60,700,1,12.73,100,1,14.61,100,1,12.67,100,1,14.68,700,1,12.65,200,2,14.79,100,1,12.50,700,1,14.81,200,2,12.47,100,1,14.84,100,1,12.46,100,1,14.91,700,1,12.43,700,1,14.96,100,1,ARL,282776285
799,2025-07-17T15:31:00.028947312Z,2025-07-17T15:31:00.028782030Z,160,2,1108,A,A,1,14.26,100,130,165282,238443998,13.37,100,1,14.02,2,1,13.23,2,1,14.26,100,1,13.10,100,1,14.56,800,2,12.73,100,1,14.60,700,1,12.67,100,1,14.61,100,1,12.65,200,2,14.68,700,1,12.50,700,1,14.79,100,1,12.47,100,1,14.81,200,2,12.46,100,1,14.84,100,1,12.43,700,1,14.91,700,1,ARL,283595181
800,2025-07-17T15:31:00.053107210Z,2025-07-17T15:31:00.052941898Z,160,2,1108,C,A,10,14.96,100,0,165312,238444735,13.37,100,1,14.02,2,1,13.23,2,1,14.26,100,1,13.10,100,1,14.56,800,2,12.73,100,1,14.60,700,1,12.67,100,1,14.61,100,1,12.65,200,2,14.68,700,1,12.50,700,1,14.79,100,1,12.47,100,1,14.81,200,2,12.46,100,1,14.84,100,1,12.43,700,1,14.91,700,1,ARL,283592997
801,2025-07-17T15:31:00.053107210Z,2025-07-17T15:31:00.052941898Z,160,2,1108,A,A,11,15.06,100,130,165312,238444735,13.37,100,1,14.02,2,1,13.23,2,1,14.26,100,1,13.10,100,1,14.56,800,2,12.73,100,1,14.60,700,1,12.67,100,1,14.61,100,1,12.65,200,2,14.68,700,1,12.50,700,1,14.79,100,1,12.47,100,1,14.81,200,2,12.46,100,1,14.84,100,1,12.43,700,1,14.91,700,1,ARL,283596673
802,2025-07-17T15:31:00.054830847Z,2025-07-17T15:31:00.054665340Z,160,2,1108,C,A,7,14.81,100,0,165507,238444759,13.37,100,1,14.02,2,1,13.23,2,1,14.26,100,1,13.10,100,1,14.56,800,2,12.73,100,1,14.60,700,1,12.67,100,1,14.61,100,1,12.65,200,2,14.68,700,1,12.50,700,1,14.79,100,1,12.47,100,1,14.81,100,1,12.46,100,1,14.84,100,1,12.43,700,1,14.91,700,1,ARL,282776089
803,2025-07-17T15:31:00.054830847Z,2025-07-17T15:31:00.054665340Z,160,2,1108,A,A,10,14.96,100,130,165507,238444759,13.37,100,1,14.02,2,1,13.23,2,1,14.26,100,1,13.10,100,1,14.56,800,2,12.73,100,1,14.60,700,1,12.67,100,1,14.61,100,1,12.65,200,2,14.68,700,1,12.50,700,1,14.79,100,1,12.47,100,1,14.81,100,1,12.46,100,1,14.84,100,1,12.43,700,1,14.91,700,1,ARL,283596721
804,2025-07-17T15:31:00.071409275Z,2025-07-17T15:31:00.071243665Z,160,2,1108,C,A,7,14.81,100,0,165610,238444961,13.37,100,1,14.02,2,1,13.23,2,1,14.26,100,1,13.10,100,1,14.56,800,2,12.73,100,1,14.60,700,1,12.67,100,1,14.61,100,1,12.65,200,2,14.68,700,1,12.50,700,1,14.79,100,1,12.47,100,1,14.84,100,1,12.46,100,1,14.91,700,1,12.43,700,1,14.96,100,1,ARL,282776029
805,2025-07-17T15:31:00.071409275Z,2025-07-17T15:31:00.071243665Z,160,2,1108,A,A,9,14.96,100,130,165610,238444961,13.37,100,1,14.02,2,1,13.23,2,1,14.26,100,1,13.10,100,1,14.56,800,2,12.73,100,1,14.60,700,1,12.67,100,1,14.61,100,1,12.65,200,2,14.68,700,1,12.50,700,1,14.79,100,1,12.47,100,1,14.84,100,1,12.46,100,1,14.91,700,1,12.43,700,1,14.96,200,2,ARL,283596945
806,2025-07-17T15:31:00.243369582Z,2025-07-17T15:31:00.243203860Z,160,2,1108,C,A,16,15.92,100,0,165722,238447595,13.37,100,1,14.02,2,1,13.23,2,1,14.26,100,1,13.10,100,1,14.56,800,2,12.73,100,1,14.60,700,1,12.67,100,1,14.61,100,1,12.65,200,2,14.68,700,1,12.50,700,1,14.79,100,1,12.47,100,1,14.84,100,1,12.46,100,1,14.91,700,1,12.43,700,1,14.96,200,2,ARL,282776033
807,2025-07-17T15:31:00.243369582Z,2025-07-17T15:31:00.243203860Z,160,2,1108,A,A,16,16.08,100,130,165722,238447595,13.37,100,1,14.02,2,1,13.23,2,1,14.26,100,1,13.10,100,1,14.56,800,2,12.73,100,1,14.60,700,1,12.67,100,1,14.61,100,1,12.65,200,2,14.68,700,1,12.50,700,1,14.79,100,1,12.47,100,1,14.84,100,1,12.46,100,1,14.91,700,1,12.43,700,1,14.96,200,2,ARL,283599609
808,2025-07-17T15:31:00.347828545Z,2025-07-17T15:31:00.347663441Z,160,2,1108,A,A,1,14.03,100,130,165104,238450791,13.37,100,1,14.02,2,1,13.23,2,1,14.03,100,1,13.10,100,1,14.26,100,1,12.73,100,1,14.56,800,2,12.67,100,1,14.60,700,1,12.65,200,2,14.61,100,1,12.50,700,1,14.68,700,1,12.47,100,1,14.79,100,1,12.46,100,1,14.84,100,1,12.43,700,1,14.91,700,1,ARL,283604173
809,2025-07-17T15:31:04.014590575Z,2025-07-17T15:31:04.014425425Z,160,2,1108,A,A,0,14.00,100,130,165150,238529875,13.37,100,1,14.00,100,1,13.23,2,1,14.02,2,1,13.10,100,1,14.03,100,1,12.73,100,1,14.26,100,1,12.67,100,1,14.56,800,2,12.65,200,2,14.60,700,1,12.50,700,1,14.61,100,1,12.47,100,1,14.68,700,1,12.46,100,1,14.79,100,1,12.43,700,1,14.84,100,1,ARL,283694233
810,2025-07-17T15:31:04.124577845Z,2025-07-17T15:31:04.124411850Z,160,2,1108,C,A,2,14.03,100,0,165995,238531822,13.37,100,1,14.00,100,1,13.23,2,1,14.02,2,1,13.10,100,1,14.26,100,1,12.73,100,1,14.56,800,2,12.67,100,1,14.60,700,1,12.65,200,2,14.61,100,1,12.50,700,1,14.68,700,1,12.47,100,1,14.79,100,1,12.46,100,1,14.84,100,1,12.43,700,1,14.91,700,1,ARL,283604173
811,2025-07-17T15:31:04.124577845Z,2025-07-17T15:31:04.124411850Z,160,2,1108,A,A,1,14.01,100,130,165995,238531822,13.37,100,1,14.00,100,1,13.23,2,1,14.01,100,1,13.10,100,1,14.02,2,1,12.73,100,1,14.26,100,1,12.67,100,1,14.56,800,2,12.65,200,2,14.60,700,1,12.50,700,1,14.61,100,1,12.47,100,1,14.68,700,1,12.46,100,1,14.79,100,1,12.43,700,1,14.84,100,1,ARL,283695933
812,2025-07-17T15:32:28.644506279Z,2025-07-17T15:32:28.644335983Z,160,2,1108,A,B,0,13.55,10,128,170296,239938946,13.55,10,1,14.00,100,1,13.37,100,1,14.01,100,1,13.23,2,1,14.02,2,1,13.10,100,1,14.26,100,1,12.73,100,1,14.56,800,2,12.67,100,1,14.60,700,1,12.65,200,2,14.61,100,1,12.50,700,1,14.68,700,1,12.47,100,1,14.79,100,1,12.46,100,1,14.84,100,1,ARL,285545121
813,2025-07-17T15:32:28.653238729Z,2025-07-17T15:32:28.653073176Z,160,2,1108,C,B,1,13.37,100,0,165553,239940048,13.55,10,1,14.00,100,1,13.23,2,1,14.01,100,1,13.10,100,1,14.02,2,1,12.73,100,1,14.26,100,1,12.67,100,1,14.56,800,2,12.65,200,2,14.60,700,1,12.50,700,1,14.61,100,1,12.47,100,1,14.68,700,1,12.46,100,1,14.79,100,1,12.43,700,1,14.84,100,1,ARL,215999737
814,2025-07-17T15:32:28.653238729Z,2025-07-17T15:32:28.653073176Z,160,2,1108,A,B,1,13.54,100,130,165553,239940048,13.55,10,1,14.00,100,1,13.54,100,1,14.01,100,1,13.23,2,1,14.02,2,1,13.10,100,1,14.26,100,1,12.73,100,1,14.56,800,2,12.67,100,1,14.60,700,1,12.65,200,2,14.61,100,1,12.50,700,1,14.68,700,1,12.47,100,1,14.79,100,1,12.46,100,1,14.84,100,1,ARL,285545885
815,2025-07-17T15:32:28.653978501Z,2025-07-17T15:32:28.653812889Z,160,2,1108,C,B,13,12.33,100,0,165612,239940096,13.55,10,1,14.00,100,1,13.54,100,1,14.01,100,1,13.23,2,1,14.02,2,1,13.10,100,1,14.26,100,1,12.73,100,1,14.56,800,2,12.67,100,1,14.60,700,1,12.65,200,2,14.61,100,1,12.50,700,1,14.68,700,1,12.47,100,1,14.79,100,1,12.46,100,1,14.84,100,1,ARL,215999753
816,2025-07-17T15:32:28.653978501Z,2025-07-17T15:32:28.653812889Z,160,2,1108,A,B,8,12.49,100,130,165612,239940096,13.55,10,1,14.00,100,1,13.54,100,1,14.01,100,1,13.23,2,1,14.02,2,1,13.10,100,1,14.26,100,1,12.73,100,1,14.56,800,2,12.67,100,1,14.60,700,1,12.65,200,2,14.61,100,1,12.50,700,1,14.68,700,1,12.49,100,1,14.79,100,1,12.47,100,1,14.84,100,1,ARL,285545945
817,2025-07-17T15:32:28.653980648Z,2025-07-17T15:32:28.653815154Z,160,2,1108,C,B,5,12.67,100,130,165494,239940097,13.55,10,1,14.00,100,1,13.54,100,1,14.01,100,1,13.23,2,1,14.02,2,1,13.10,100,1,14.26,100,1,12.73,100,1,14.56,800,2,12.65,200,2,14.60,700,1,12.50,700,1,14.61,100,1,12.49,100,1,14.68,700,1,12.47,100,1,14.79,100,1,12.46,100,1,14.84,100,1,ARL,43663229
818,2025-07-17T15:32:28.654336987Z,2025-07-17T15:32:28.654171723Z,160,2,1108,A,B,4,12.94,100,130,165264,239940109,13.55,10,1,14.00,100,1,13.54,100,1,14.01,100,1,13.23,2,1,14.02,2,1,13.10,100,1,14.26,100,1,12.94,100,1,14.56,800,2,12.73,100,1,14.60,700,1,12.65,200,2,14.61,100,1,12.50,700,1,14.68,700,1,12.49,100,1,14.79,100,1,12.47,100,1,14.84,100,1,ARL,285545953
819,2025-07-17T15:32:28.657073743Z,2025-07-17T15:32:28.656908386Z,160,2,1108,C,B,9,12.47,100,130,165357,239940358,13.55,10,1,14.00,100,1,13.54,100,1,14.01,100,1,13.23,2,1,14.02,2,1,13.10,100,1,14.26,100,1,12.94,100,1,14.56,800,2,12.73,100,1,14.60,700,1,12.65,200,2,14.61,100,1,12.50,700,1,14.68,700,1,12.49,100,1,14.79,100,1,12.46,100,1,14.84,100,1,ARL,43554133
820,2025-07-17T15:32:28.657173856Z,2025-07-17T15:32:28.657008222Z,160,2,1108,A,B,5,12.73,100,130,165634,239940359,13.55,10,1,14.00,100,1,13.54,100,1,14.01,100,1,13.23,2,1,14.02,2,1,13.10,100,1,14.26,100,1,12.94,100,1,14.56,800,2,12.73,200,2,14.60,700,1,12.65,200,2,14.61,100,1,12.50,700,1,14.68,700,1,12.49,100,1,14.79,100,1,12.46,100,1,14.84,100,1,ARL,285546061
821,2025-07-17T15:32:28.667074437Z,2025-07-17T15:32:28.666909194Z,160,2,1108,C,B,3,13.10,100,130,165243,239940810,13.55,10,1,14.00,100,1,13.54,100,1,14.01,100,1,13.23,2,1,14.02,2,1,12.94,100,1,14.26,100,1,12.73,200,2,14.56,800,2,12.65,200,2,14.60,700,1,12.50,700,1,14.61,100,1,12.49,100,1,14.68,700,1,12.46,100,1,14.79,100,1,12.43,700,1,14.84,100,1,ARL,216001413
822,2025-07-17T15:32:28.667126637Z,2025-07-17T15:32:28.666961018Z,160,2,1108,A,B,2,13.27,100,130,165619,239940813,13.55,10,1,14.00,100,1,13.54,100,1,14.01,100,1,13.27,100,1,14.02,2,1,13.23,2,1,14.26,100,1,12.94,100,1,14.56,800,2,12.73,200,2,14.60,700,1,12.65,200,2,14.61,100,1,12.50,700,1,14.68,700,1,12.49,100,1,14.79,100,1,12.46,100,1,14.84,100,1,ARL,285546673
823,2025-07-17T15:32:28.674444711Z,2025-07-17T15:32:28.674279259Z,160,2,1108,C,B,13,12.33,100,0,165452,239941057,13.55,10,1,14.00,100,1,13.54,100,1,14.01,100,1,13.27,100,1,14.02,2,1,13.23,2,1,14.26,100,1,12.94,100,1,14.56,800,2,12.73,200,2,14.60,700,1,12.65,200,2,14.61,100,1,12.50,700,1,14.68,700,1,12.49,100,1,14.79,100,1,12.46,100,1,14.84,100,1,ARL,43755813
824,2025-07-17T15:32:28.674444711Z,2025-07-17T15:32:28.674279259Z,160,2,1108,A,B,7,12.59,100,130,165452,239941057,13.55,10,1,14.00,100,1,13.54,100,1,14.01,100,1,13.27,100,1,14.02,2,1,13.23,2,1,14.26,100,1,12.94,100,1,14.56,800,2,12.73,200,2,14.60,700,1,12.65,200,2,14.61,100,1,12.59,100,1,14.68,700,1,12.50,700,1,14.79,100,1,12.49,100,1,14.84,100,1,ARL,285546893
825,2025-07-17T15:32:28.691264796Z,2025-07-17T15:32:28.691099298Z,160,2,1108,C,B,20,9.67,100,0,165498,239941825,13.55,10,1,14.00,100,1,13.54,100,1,14.01,100,1,13.27,100,1,14.02,2,1,13.23,2,1,14.26,100,1,12.94,100,1,14.56,800,2,12.73,200,2,14.60,700,1,12.65,200,2,14.61,100,1,12.59,100,1,14.68,700,1,12.50,700,1,14.79,100,1,12.49,100,1,14.84,100,1,ARL,44082961
826,2025-07-17T15:32:28.691264796Z,2025-07-17T15:32:28.691099298Z,160,2,1108,A,B,20,9.88,100,130,165498,239941825,13.55,10,1,14.00,100,1,13.54,100,1,14.01,100,1,13.27,100,1,14.02,2,1,13.23,2,1,14.26,100,1,12.94,100,1,14.56,800,2,12.73,200,2,14.60,700,1,12.65,200,2,14.61,100,1,12.59,100,1,14.68,700,1,12.50,700,1,14.79,100,1,12.49,100,1,14.84,100,1,ARL,285548137
827,2025-07-17T15:32:28.711494526Z,2025-07-17T15:32:28.711329066Z,160,2,1108,C,B,18,11.27,100,0,165460,239942732,13.55,10,1,14.00,100,1,13.54,100,1,14.01,100,1,13.27,100,1,14.02,2,1,13.23,2,1,14.26,100,1,12.94,100,1,14.56,800,2,12.73,200,2,14.60,700,1,12.65,200,2,14.61,100,1,12.59,100,1,14.68,700,1,12.50,700,1,14.79,100,1,12.49,100,1,14.84,100,1,ARL,43826785
828,2025-07-17T15:32:28.711494526Z,2025-07-17T15:32:28.711329066Z,160,2,1108,A,B,17,11.50,100,130,165460,239942732,13.55,10,1,14.00,100,1,13.54,100,1,14.01,100,1,13.27,100,1,14.02,2,1,13.23,2,1,14.26,100,1,12.94,100,1,14.56,800,2,12.73,200,2,14.60,700,1,12.65,200,2,14.61,100,1,12.59,100,1,14.68,700,1,12.50,700,1,14.79,100,1,12.49,100,1,14.84,100,1,ARL,285549537
829,2025-07-17T15:32:28.771995987Z,2025-07-17T15:32:28.771830554Z,160,2,1108,C,B,0,13.55,10,128,165433,239945992,13.54,100,1,14.00,100,1,13.27,100,1,14.01,100,1,13.23,2,1,14.02,2,1,12.94,100,1,14.26,100,1,12.73,200,2,14.56,800,2,12.65,200,2,14.60,700,1,12.59,100,1,14.61,100,1,12.50,700,1,14.68,700,1,12.49,100,1,14.79,100,1,12.46,100,1,14.84,100,1,ARL,285545121
830,2025-07-17T15:32:28.806930722Z,2025-07-17T15:32:28.806765209Z,160,2,1108,C,B,13,12.33,100,0,165513,239948319,13.54,100,1,14.00,100,1,13.27,100,1,14.01,100,1,13.23,2,1,14.02,2,1,12.94,100,1,14.26,100,1,12.73,200,2,14.56,800,2,12.65,200,2,14.60,700,1,12.59,100,1,14.61,100,1,12.50,700,1,14.68,700,1,12.49,100,1,14.79,100,1,12.46,100,1,14.84,100,1,ARL,44088633
831,2025-07-17T15:32:28.806930722Z,2025-07-17T15:32:28.806765209Z,160,2,1108,A,B,6,12.59,100,130,165513,239948319,13.54,100,1,14.00,100,1,13.27,100,1,14.01,100,1,13.23,2,1,14.02,2,1,12.94,100,1,14.26,100,1,12.73,200,2,14.56,800,2,12.65,200,2,14.60,700,1,12.59,200,2,14.61,100,1,12.50,700,1,14.68,700,1,12.49,100,1,14.79,100,1,12.46,100,1,14.84,100,1,ARL,285553901
832,2025-07-17T15:32:28.850288215Z,2025-07-17T15:32:28.850122877Z,160,2,1108,A,A,0,13.98,100,130,165338,239950805,13.54,100,1,13.98,100,1,13.27,100,1,14.00,100,1,13.23,2,1,14.01,100,1,12.94,100,1,14.02,2,1,12.73,200,2,14.26,100,1,12.65,200,2,14.56,800,2,12.59,200,2,14.60,700,1,12.50,700,1,14.61,100,1,12.49,100,1,14.68,700,1,12.46,100,1,14.79,100,1,ARL,285556869
833,2025-07-17T15:32:28.857140107Z,2025-07-17T15:32:28.856973845Z,160,2,1108,C,A,1,14.00,100,130,166262,239951361,13.54,100,1,13.98,100,1,13.27,100,1,14.01,100,1,13.23,2,1,14.02,2,1,12.94,100,1,14.26,100,1,12.73,200,2,14.56,800,2,12.65,200,2,14.60,700,1,12.59,200,2,14.61,100,1,12.50,700,1,14.68,700,1,12.49,100,1,14.79,100,1,12.46,100,1,14.84,100,1,ARL,283694233
834,2025-07-17T15:32:29.573634202Z,2025-07-17T15:32:29.573469021Z,160,2,1108,C,B,0,13.54,100,130,165181,239975997,13.27,100,1,13.98,100,1,13.23,2,1,14.01,100,1,12.94,100,1,14.02,2,1,12.73,200,2,14.26,100,1,12.65,200,2,14.56,800,2,12.59,200,2,14.60,700,1,12.50,700,1,14.61,100,1,12.49,100,1,14.68,700,1,12.46,100,1,14.79,100,1,12.43,700,1,14.84,100,1,ARL,285545885
835,2025-07-17T15:32:29.574368326Z,2025-07-17T15:32:29.574202467Z,160,2,1108,C,B,7,12.49,100,0,165859,239976004,13.27,100,1,13.98,100,1,13.23,2,1,14.01,100,1,12.94,100,1,14.02,2,1,12.73,200,2,14.26,100,1,12.65,200,2,14.56,800,2,12.59,200,2,14.60,700,1,12.50,700,1,14.61,100,1,12.46,100,1,14.68,700,1,12.43,700,1,14.79,100,1,12.42,700,1,14.84,100,1,ARL,285545945
836,2025-07-17T15:32:29.574368326Z,2025-07-17T15:32:29.574202467Z,160,2,1108,A,B,11,12.27,100,130,165859,239976004,13.27,100,1,13.98,100,1,13.23,2,1,14.01,100,1,12.94,100,1,14.02,2,1,12.73,200,2,14.26,100,1,12.65,200,2,14.56,800,2,12.59,200,2,14.60,700,1,12.50,700,1,14.61,100,1,12.46,100,1,14.68,700,1,12.43,700,1,14.79,100,1,12.42,700,1,14.84,100,1,ARL,285586089
837,2025-07-17T15:32:29.574371866Z,2025-07-17T15:32:29.574206685Z,160,2,1108,C,B,2,12.94,100,130,165181,239976005,13.27,100,1,13.98,100,1,13.23,2,1,14.01,100,1,12.73,200,2,14.02,2,1,12.65,200,2,14.26,100,1,12.59,200,2,14.56,800,2,12.50,700,1,14.60,700,1,12.46,100,1,14.61,100,1,12.43,700,1,14.68,700,1,12.42,700,1,14.79,100,1,12.37,700,1,14.84,100,1,ARL,285545953
838,2025-07-17T15:32:29.574722141Z,2025-07-17T15:32:29.574556760Z,160,2,1108,A,B,3,12.71,100,130,165381,239976069,13.27,100,1,13.98,100,1,13.23,2,1,14.01,100,1,12.73,200,2,14.02,2,1,12.71,100,1,14.26,100,1,12.65,200,2,14.56,800,2,12.59,200,2,14.60,700,1,12.50,700,1,14.61,100,1,12.46,100,1,14.68,700,1,12.43,700,1,14.79,100,1,12.42,700,1,14.84,100,1,ARL,285586093
839,2025-07-17T15:32:29.575134655Z,2025-07-17T15:32:29.574968914Z,160,2,1108,C,B,5,12.59,100,0,165741,239976143,13.27,100,1,13.98,100,1,13.23,2,1,14.01,100,1,12.73,200,2,14.02,2,1,12.71,100,1,14.26,100,1,12.65,200,2,14.56,800,2,12.59,100,1,14.60,700,1,12.50,700,1,14.61,100,1,12.46,100,1,14.68,700,1,12.43,700,1,14.79,100,1,12.42,700,1,14.84,100,1,ARL,285546893
840,2025-07-17T15:32:29.575134655Z,2025-07-17T15:32:29.574968914Z,160,2,1108,A,B,11,12.34,100,130,165741,239976143,13.27,100,1,13.98,100,1,13.23,2,1,14.01,100,1,12.73,200,2,14.02,2,1,12.71,100,1,14.26,100,1,12.65,200,2,14.56,800,2,12.59,100,1,14.60,700,1,12.50,700,1,14.61,100,1,12.46,100,1,14.68,700,1,12.43,700,1,14.79,100,1,12.42,700,1,14.84,100,1,ARL,285586113
841,2025-07-17T15:32:29.575550333Z,2025-07-17T15:32:29.575384940Z,160,2,1108,C,B,15,11.50,100,0,165393,239976173,13.27,100,1,13.98,100,1,13.23,2,1,14.01,100,1,12.73,200,2,14.02,2,1,12.71,100,1,14.26,100,1,12.65,200,2,14.56,800,2,12.59,100,1,14.60,700,1,12.50,700,1,14.61,100,1,12.46,100,1,14.68,700,1,12.43,700,1,14.79,100,1,12.42,700,1,14.84,100,1,ARL,285549537
842,2025-07-17T15:32:29.575550333Z,2025-07-17T15:32:29.575384940Z,160,2,1108,A,B,16,11.27,100,130,165393,239976173,13.27,100,1,13.98,100,1,13.23,2,1,14.01,100,1,12.73,200,2,14.02,2,1,12.71,100,1,14.26,100,1,12.65,200,2,14.56,800,2,12.59,100,1,14.60,700,1,12.50,700,1,14.61,100,1,12.46,100,1,14.68,700,1,12.43,700,1,14.79,100,1,12.42,700,1,14.84,100,1,ARL,285586145
843,2025-07-17T15:32:29.575821091Z,2025-07-17T15:32:29.575655631Z,160,2,1108,C,B,18,9.88,100,0,165460,239976183,13.27,100,1,13.98,100,1,13.23,2,1,14.01,100,1,12.73,200,2,14.02,2,1,12.71,100,1,14.26,100,1,12.65,200,2,14.56,800,2,12.59,100,1,14.60,700,1,12.50,700,1,14.61,100,1,12.46,100,1,14.68,700,1,12.43,700,1,14.79,100,1,12.42,700,1,14.84,100,1,ARL,285548137
844,2025-07-17T15:32:29.575821091Z,2025-07-17T15:32:29.575655631Z,160,2,1108,A,B,18,9.68,100,130,165460,239976183,13.27,100,1,13.98,100,1,13.23,2,1,14.01,100,1,12.73,200,2,14.02,2,1,12.71,100,1,14.26,100,1,12.65,200,2,14.56,800,2,12.59,100,1,14.60,700,1,12.50,700,1,14.61,100,1,12.46,100,1,14.68,700,1,12.43,700,1,14.79,100,1,12.42,700,1,14.84,100,1,ARL,285586157
845,2025-07-17T15:32:29.578317238Z,2025-07-17T15:32:29.578151593Z,160,2,1108,C,B,5,12.59,100,0,165645,239976225,13.27,100,1,13.98,100,1,13.23,2,1,14.01,100,1,12.73,200,2,14.02,2,1,12.71,100,1,14.26,100,1,12.65,200,2,14.56,800,2,12.50,700,1,14.60,700,1,12.46,100,1,14.61,100,1,12.43,700,1,14.68,700,1,12.42,700,1,14.79,100,1,12.37,700,1,14.84,100,1,ARL,285553901
846,2025-07-17T15:32:29.578317238Z,2025-07-17T15:32:29.578151593Z,160,2,1108,A,B,10,12.34,100,130,165645,239976225,13.27,100,1,13.98,100,1,13.23,2,1,14.01,100,1,12.73,200,2,14.02,2,1,12.71,100,1,14.26,100,1,12.65,200,2,14.56,800,2,12.50,700,1,14.60,700,1,12.46,100,1,14.61,100,1,12.43,700,1,14.68,700,1,12.42,700,1,14.79,100,1,12.37,700,1,14.84,100,1,ARL,285586189
847,2025-07-17T15:32:29.580933155Z,2025-07-17T15:32:29.580767960Z,160,2,1108,A,B,1,13.26,100,130,165195,239976262,13.27,100,1,13.98,100,1,13.26,100,1,14.01,100,1,13.23,2,1,14.02,2,1,12.73,200,2,14.26,100,1,12.71,100,1,14.56,800,2,12.65,200,2,14.60,700,1,12.50,700,1,14.61,100,1,12.46,100,1,14.68,700,1,12.43,700,1,14.79,100,1,12.42,700,1,14.84,100,1,ARL,285586221
848,2025-07-17T15:32:29.580952045Z,2025-07-17T15:32:29.580786478Z,160,2,1108,C,A,1,14.01,100,0,165567,239976263,13.27,100,1,13.98,100,1,13.26,100,1,14.02,2,1,13.23,2,1,14.26,100,1,12.73,200,2,14.56,800,2,12.71,100,1,14.60,700,1,12.65,200,2,14.61,100,1,12.50,700,1,14.68,700,1,12.46,100,1,14.79,100,1,12.43,700,1,14.84,100,1,12.42,700,1,14.91,700,1,ARL,283695933
849,2025-07-17T15:32:29.580952045Z,2025-07-17T15:32:29.580786478Z,160,2,1108,A,A,1,13.99,100,130,165567,239976263,13.27,100,1,13.98,100,1,13.26,100,1,13.99,100,1,13.23,2,1,14.02,2,1,12.73,200,2,14.26,100,1,12.71,100,1,14.56,800,2,12.65,200,2,14.60,700,1,12.50,700,1,14.61,100,1,12.46,100,1,14.68,700,1,12.43,700,1,14.79,100,1,12.42,700,1,14.84,100,1,ARL,285586225
850,2025-07-17T15:32:29.587192852Z,2025-07-17T15:32:29.587027681Z,160,2,1108,C,B,0,13.27,100,130,165171,239976327,13.26,100,1,13.98,100,1,13.23,2,1,13.99,100,1,12.73,200,2,14.02,2,1,12.71,100,1,14.26,100,1,12.65,200,2,14.56,800,2,12.50,700,1,14.60,700,1,12.46,100,1,14.61,100,1,12.43,700,1,14.68,700,1,12.42,700,1,14.79,100,1,12.37,700,1,14.84,100,1,ARL,285546673
851,2025-07-17T15:32:29.587246470Z,2025-07-17T15:32:29.587081086Z,160,2,1108,A,B,2,13.03,100,130,165384,239976336,13.26,100,1,13.98,100,1,13.23,2,1,13.99,100,1,13.03,100,1,14.02,2,1,12.73,200,2,14.26,100,1,12.71,100,1,14.56,800,2,12.65,200,2,14.60,700,1,12.50,700,1,14.61,100,1,12.46,100,1,14.68,700,1,12.43,700,1,14.79,100,1,12.42,700,1,14.84,100,1,ARL,285586293
852,2025-07-17T15:32:29.659679280Z,2025-07-17T15:32:29.659513918Z,160,2,1108,C,B,3,12.73,100,0,165362,239977574,13.26,100,1,13.98,100,1,13.23,2,1,13.99,100,1,13.03,100,1,14.02,2,1,12.73,100,1,14.26,100,1,12.71,100,1,14.56,800,2,12.65,200,2,14.60,700,1,12.50,700,1,14.61,100,1,12.46,100,1,14.68,700,1,12.43,700,1,14.79,100,1,12.42,700,1,14.84,100,1,ARL,285546061
853,2025-07-17T15:32:29.659679280Z,2025-07-17T15:32:29.659513918Z,160,2,1108,A,B,7,12.46,100,130,165362,239977574,13.26,100,1,13.98,100,1,13.23,2,1,13.99,100,1,13.03,100,1,14.02,2,1,12.73,100,1,14.26,100,1,12.71,100,1,14.56,800,2,12.65,200,2,14.60,700,1,12.50,700,1,14.61,100,1,12.46,200,2,14.68,700,1,12.43,700,1,14.79,100,1,12.42,700,1,14.84,100,1,ARL,285587281
854,2025-07-17T15:33:04.248156868Z,2025-07-17T15:33:04.247990788Z,160,2,1108,C,A,12,14.97,100,0,166080,240885845,13.26,100,1,13.98,100,1,13.23,2,1,13.99,100,1,13.03,100,1,14.02,2,1,12.73,100,1,14.26,100,1,12.71,100,1,14.56,800,2,12.65,200,2,14.60,700,1,12.50,700,1,14.61,100,1,12.46,200,2,14.68,700,1,12.43,700,1,14.79,100,1,12.42,700,1,14.84,100,1,ARL,283592993
855,2025-07-17T15:33:04.248156868Z,2025-07-17T15:33:04.247990788Z,160,2,1108,A,A,8,14.72,100,130,166080,240885845,13.26,100,1,13.98,100,1,13.23,2,1,13.99,100,1,13.03,100,1,14.02,2,1,12.73,100,1,14.26,100,1,12.71,100,1,14.56,800,2,12.65,200,2,14.60,700,1,12.50,700,1,14.61,100,1,12.46,200,2,14.68,700,1,12.43,700,1,14.72,100,1,12.42,700,1,14.79,100,1,ARL,286680573
856,2025-07-17T15:33:04.248189408Z,2025-07-17T15:33:04.248023883Z,160,2,1108,C,A,13,14.97,100,0,165525,240885847,13.26,100,1,13.98,100,1,13.23,2,1,13.99,100,1,13.03,100,1,14.02,2,1,12.73,100,1,14.26,100,1,12.71,100,1,14.56,800,2,12.65,200,2,14.60,700,1,12.50,700,1,14.61,100,1,12.46,200,2,14.68,700,1,12.43,700,1,14.72,100,1,12.42,700,1,14.79,100,1,ARL,283593041
857,2025-07-17T15:33:04.248189408Z,2025-07-17T15:33:04.248023883Z,160,2,1108,A,A,8,14.72,100,130,165525,240885847,13.26,100,1,13.98,100,1,13.23,2,1,13.99,100,1,13.03,100,1,14.02,2,1,12.73,100,1,14.26,100,1,12.71,100,1,14.56,800,2,12.65,200,2,14.60,700,1,12.50,700,1,14.61,100,1,12.46,200,2,14.68,700,1,12.43,700,1,14.72,200,2,12.42,700,1,14.79,100,1,ARL,286680577
858,2025-07-17T15:33:04.255712050Z,2025-07-17T15:33:04.255546094Z,160,2,1108,A,A,0,13.84,100,130,165956,240886132,13.26,100,1,13.84,100,1,13.23,2,1,13.98,100,1,13.03,100,1,13.99,100,1,12.73,100,1,14.02,2,1,12.71,100,1,14.26,100,1,12.65,200,2,14.56,800,2,12.50,700,1,14.60,700,1,12.46,200,2,14.61,100,1,12.43,700,1,14.68,700,1,12.42,700,1,14.72,200,2,ARL,286680685
859,2025-07-17T15:33:04.255777981Z,2025-07-17T15:33:04.255612126Z,160,2,1108,C,B,12,12.27,100,0,165855,240886133,13.26,100,1,13.84,100,1,13.23,2,1,13.98,100,1,13.03,100,1,13.99,100,1,12.73,100,1,14.02,2,1,12.71,100,1,14.26,100,1,12.65,200,2,14.56,800,2,12.50,700,1,14.60,700,1,12.46,200,2,14.61,100,1,12.43,700,1,14.68,700,1,12.42,700,1,14.72,200,2,ARL,285586089
860,2025-07-17T15:33:04.255777981Z,2025-07-17T15:33:04.255612126Z,160,2,1108,A,B,12,12.23,100,130,165855,240886133,13.26,100,1,13.84,100,1,13.23,2,1,13.98,100,1,13.03,100,1,13.99,100,1,12.73,100,1,14.02,2,1,12.71,100,1,14.26,100,1,12.65,200,2,14.56,800,2,12.50,700,1,14.60,700,1,12.46,200,2,14.61,100,1,12.43,700,1,14.68,700,1,12.42,700,1,14.72,200,2,ARL,286680693
861,2025-07-17T15:33:04.256438228Z,2025-07-17T15:33:04.256272676Z,160,2,1108,C,A,14,15.06,100,0,165552,240886147,13.26,100,1,13.84,100,1,13.23,2,1,13.98,100,1,13.03,100,1,13.99,100,1,12.73,100,1,14.02,2,1,12.71,100,1,14.26,100,1,12.65,200,2,14.56,800,2,12.50,700,1,14.60,700,1,12.46,200,2,14.61,100,1,12.43,700,1,14.68,700,1,12.42,700,1,14.72,200,2,ARL,283596673
862,2025-07-17T15:33:04.256438228Z,2025-07-17T15:33:04.256272676Z,160,2,1108,A,A,12,14.91,100,130,165552,240886147,13.26,100,1,13.84,100,1,13.23,2,1,13.98,100,1,13.03,100,1,13.99,100,1,12.73,100,1,14.02,2,1,12.71,100,1,14.26,100,1,12.65,200,2,14.56,800,2,12.50,700,1,14.60,700,1,12.46,200,2,14.61,100,1,12.43,700,1,14.68,700,1,12.42,700,1,14.72,200,2,ARL,286680721
863,2025-07-17T15:33:04.258080504Z,2025-07-17T15:33:04.257914956Z,160,2,1108,C,A,13,14.96,100,0,165548,240886188,13.26,100,1,13.84,100,1,13.23,2,1,13.98,100,1,13.03,100,1,13.99,100,1,12.73,100,1,14.02,2,1,12.71,100,1,14.26,100,1,12.65,200,2,14.56,800,2,12.50,700,1,14.60,700,1,12.46,200,2,14.61,100,1,12.43,700,1,14.68,700,1,12.42,700,1,14.72,200,2,ARL,283596945
864,2025-07-17T15:33:04.258080504Z,2025-07-17T15:33:04.257914956Z,160,2,1108,A,A,11,14.81,100,130,165548,240886188,13.26,100,1,13.84,100,1,13.23,2,1,13.98,100,1,13.03,100,1,13.99,100,1,12.73,100,1,14.02,2,1,12.71,100,1,14.26,100,1,12.65,200,2,14.56,800,2,12.50,700,1,14.60,700,1,12.46,200,2,14.61,100,1,12.43,700,1,14.68,700,1,12.42,700,1,14.72,200,2,ARL,286680741
865,2025-07-17T15:33:04.261684319Z,2025-07-17T15:33:04.261518776Z,160,2,1108,C,A,10,14.79,100,0,165543,240886271,13.26,100,1,13.84,100,1,13.23,2,1,13.98,100,1,13.03,100,1,13.99,100,1,12.73,100,1,14.02,2,1,12.71,100,1,14.26,100,1,12.65,200,2,14.56,800,2,12.50,700,1,14.60,700,1,12.46,200,2,14.61,100,1,12.43,700,1,14.68,700,1,12.42,700,1,14.72,200,2,ARL,283593313
866,2025-07-17T15:33:04.261684319Z,2025-07-17T15:33:04.261518776Z,160,2,1108,A,A,8,14.65,100,130,165543,240886271,13.26,100,1,13.84,100,1,13.23,2,1,13.98,100,1,13.03,100,1,13.99,100,1,12.73,100,1,14.02,2,1,12.71,100,1,14.26,100,1,12.65,200,2,14.56,800,2,12.50,700,1,14.60,700,1,12.46,200,2,14.61,100,1,12.43,700,1,14.65,100,1,12.42,700,1,14.68,700,1,ARL,286680905
867,2025-07-17T15:33:04.263011314Z,2025-07-17T15:33:04.262845834Z,160,2,1108,C,A,4,14.26,100,130,165480,240886294,13.26,100,1,13.84,100,1,13.23,2,1,13.98,100,1,13.03,100,1,13.99,100,1,12.73,100,1,14.02,2,1,12.71,100,1,14.56,800,2,12.65,200,2,14.60,700,1,12.50,700,1,14.61,100,1,12.46,200,2,14.65,100,1,12.43,700,1,14.68,700,1,12.42,700,1,14.72,200,2,ARL,283595181
868,2025-07-17T15:33:04.263052660Z,2025-07-17T15:33:04.262887184Z,160,2,1108,C,A,1,13.98,100,130,165476,240886296,13.26,100,1,13.84,100,1,13.23,2,1,13.99,100,1,13.03,100,1,14.02,2,1,12.73,100,1,14.56,800,2,12.71,100,1,14.60,700,1,12.65,200,2,14.61,100,1,12.50,700,1,14.65,100,1,12.46,200,2,14.68,700,1,12.43,700,1,14.72,200,2,12.42,700,1,14.81,100,1,ARL,285556869
869,2025-07-17T15:33:04.263065252Z,2025-07-17T15:33:04.262899981Z,160,2,1108,A,A,3,14.12,100,130,165271,240886297,13.26,100,1,13.84,100,1,13.23,2,1,13.99,100,1,13.03,100,1,14.02,2,1,12.73,100,1,14.12,100,1,12.71,100,1,14.56,800,2,12.65,200,2,14.60,700,1,12.50,700,1,14.61,100,1,12.46,200,2,14.65,100,1,12.43,700,1,14.68,700,1,12.42,700,1,14.72,200,2,ARL,286680917
870,2025-07-17T15:33:04.271212113Z,2025-07-17T15:33:04.271046430Z,160,2,1108,C,A,20,17.76,100,0,165683,240886583,13.26,100,1,13.84,100,1,13.23,2,1,13.99,100,1,13.03,100,1,14.02,2,1,12.73,100,1,14.12,100,1,12.71,100,1,14.56,800,2,12.65,200,2,14.60,700,1,12.50,700,1,14.61,100,1,12.46,200,2,14.65,100,1,12.43,700,1,14.68,700,1,12.42,700,1,14.72,200,2,ARL,283594173
871,2025-07-17T15:33:04.271212113Z,2025-07-17T15:33:04.271046430Z,160,2,1108,A,A,20,17.58,100,130,165683,240886583,13.26,100,1,13.84,100,1,13.23,2,1,13.99,100,1,13.03,100,1,14.02,2,1,12.73,100,1,14.12,100,1,12.71,100,1,14.56,800,2,12.65,200,2,14.60,700,1,12.50,700,1,14.61,100,1,12.46,200,2,14.65,100,1,12.43,700,1,14.68,700,1,12.42,700,1,14.72,200,2,ARL,286681057
872,2025-07-17T15:33:04.277880725Z,2025-07-17T15:33:04.277715123Z,160,2,1108,C,A,18,16.08,100,0,165602,240886720,13.26,100,1,13.84,100,1,13.23,2,1,13.99,100,1,13.03,100,1,14.02,2,1,12.73,100,1,14.12,100,1,12.71,100,1,14.56,800,2,12.65,200,2,14.60,700,1,12.50,700,1,14.61,100,1,12.46,200,2,14.65,100,1,12.43,700,1,14.68,700,1,12.42,700,1,14.72,200,2,ARL,283599609
873,2025-07-17T15:33:04.277880725Z,2025-07-17T15:33:04.277715123Z,160,2,1108,A,A,18,15.92,100,130,165602,240886720,13.26,100,1,13.84,100,1,13.23,2,1,13.99,100,1,13.03,100,1,14.02,2,1,12.73,100,1,14.12,100,1,12.71,100,1,14.56,800,2,12.65,200,2,14.60,700,1,12.50,700,1,14.61,100,1,12.46,200,2,14.65,100,1,12.43,700,1,14.68,700,1,12.42,700,1,14.72,200,2,ARL,286681229
874,2025-07-17T15:33:04.418840148Z,2025-07-17T15:33:04.418674487Z,160,2,1108,C,A,13,14.96,100,0,165661,240888774,13.26,100,1,13.84,100,1,13.23,2,1,13.99,100,1,13.03,100,1,14.02,2,1,12.73,100,1,14.12,100,1,12.71,100,1,14.56,800,2,12.65,200,2,14.60,700,1,12.50,700,1,14.61,100,1,12.46,200,2,14.65,100,1,12.43,700,1,14.68,700,1,12.42,700,1,14.72,200,2,ARL,283596721
875,2025-07-17T15:33:04.418840148Z,2025-07-17T15:33:04.418674487Z,160,2,1108,A,A,10,14.81,100,130,165661,240888774,13.26,100,1,13.84,100,1,13.23,2,1,13.99,100,1,13.03,100,1,14.02,2,1,12.73,100,1,14.12,100,1,12.71,100,1,14.56,800,2,12.65,200,2,14.60,700,1,12.50,700,1,14.61,100,1,12.46,200,2,14.65,100,1,12.43,700,1,14.68,700,1,12.42,700,1,14.72,200,2,ARL,286684005
876,2025-07-17T15:33:05.330854217Z,2025-07-17T15:33:05.330688486Z,160,2,1108,C,A,1,13.99,100,0,165731,240911093,13.26,100,1,13.84,100,1,13.23,2,1,14.02,2,1,13.03,100,1,14.12,100,1,12.73,100,1,14.56,800,2,12.71,100,1,14.60,700,1,12.65,200,2,14.61,100,1,12.50,700,1,14.65,100,1,12.46,200,2,14.68,700,1,12.43,700,1,14.72,200,2,12.42,700,1,14.81,200,2,ARL,285586225
877,2025-07-17T15:33:05.330854217Z,2025-07-17T15:33:05.330688486Z,160,2,1108,A,A,1,13.85,100,130,165731,240911093,13.26,100,1,13.84,100,1,13.23,2,1,13.85,100,1,13.03,100,1,14.02,2,1,12.73,100,1,14.12,100,1,12.71,100,1,14.56,800,2,12.65,200,2,14.60,700,1,12.50,700,1,14.61,100,1,12.46,200,2,14.65,100,1,12.43,700,1,14.68,700,1,12.42,700,1,14.72,200,2,ARL,286704785
878,2025-07-17T15:33:06.455979270Z,2025-07-17T15:33:06.455814002Z,160,2,1108,C,A,0,13.84,100,130,165268,240936407,13.26,100,1,13.85,100,1,13.23,2,1,14.02,2,1,13.03,100,1,14.12,100,1,12.73,100,1,14.56,800,2,12.71,100,1,14.60,700,1,12.65,200,2,14.61,100,1,12.50,700,1,14.65,100,1,12.46,200,2,14.68,700,1,12.43,700,1,14.72,200,2,12.42,700,1,14.81,200,2,ARL,286680685
879,2025-07-17T15:33:10.468005342Z,2025-07-17T15:33:10.467840054Z,160,2,1108,A,A,1,13.87,100,130,165288,241000095,13.26,100,1,13.85,100,1,13.23,2,1,13.87,100,1,13.03,100,1,14.02,2,1,12.73,100,1,14.12,100,1,12.71,100,1,14.56,800,2,12.65,200,2,14.60,700,1,12.50,700,1,14.61,100,1,12.46,200,2,14.65,100,1,12.43,700,1,14.68,700,1,12.42,700,1,14.72,200,2,ARL,286828253
880,2025-07-17T15:33:40.986585803Z,2025-07-17T15:33:40.986420127Z,160,2,1108,C,A,2,14.02,2,0,165676,241593788,13.26,100,1,13.85,100,1,13.23,2,1,13.87,100,1,13.03,100,1,14.12,100,1,12.73,100,1,14.56,800,2,12.71,100,1,14.60,700,1,12.65,200,2,14.61,100,1,12.50,700,1,14.65,100,1,12.46,200,2,14.68,700,1,12.43,700,1,14.72,200,2,12.42,700,1,14.81,200,2,ARL,283348193
881,2025-07-17T15:33:40.986585803Z,2025-07-17T15:33:40.986420127Z,160,2,1108,A,A,2,13.95,2,130,165676,241593788,13.26,100,1,13.85,100,1,13.23,2,1,13.87,100,1,13.03,100,1,13.95,2,1,12.73,100,1,14.12,100,1,12.71,100,1,14.56,800,2,12.65,200,2,14.60,700,1,12.50,700,1,14.61,100,1,12.46,200,2,14.65,100,1,12.43,700,1,14.68,700,1,12.42,700,1,14.72,200,2,ARL,287540393
882,2025-07-17T15:33:41.766184571Z,2025-07-17T15:33:41.766018916Z,160,2,1108,A,A,0,13.82,10,130,165655,241612289,13.26,100,1,13.82,10,1,13.23,2,1,13.85,100,1,13.03,100,1,13.87,100,1,12.73,100,1,13.95,2,1,12.71,100,1,14.12,100,1,12.65,200,2,14.56,800,2,12.50,700,1,14.60,700,1,12.46,200,2,14.61,100,1,12.43,700,1,14.65,100,1,12.42,700,1,14.68,700,1,ARL,287560109
883,2025-07-17T15:33:41.766265703Z,2025-07-17T15:33:41.766100204Z,160,2,1108,C,A,1,13.85,100,0,165499,241612294,13.26,100,1,13.82,10,1,13.23,2,1,13.87,100,1,13.03,100,1,13.95,2,1,12.73,100,1,14.12,100,1,12.71,100,1,14.56,800,2,12.65,200,2,14.60,700,1,12.50,700,1,14.61,100,1,12.46,200,2,14.65,100,1,12.43,700,1,14.68,700,1,12.42,700,1,14.72,200,2,ARL,286704785
884,2025-07-17T15:33:41.766265703Z,2025-07-17T15:33:41.766100204Z,160,2,1108,A,A,1,13.83,100,130,165499,241612294,13.26,100,1,13.82,10,1,13.23,2,1,13.83,100,1,13.03,100,1,13.87,100,1,12.73,100,1,13.95,2,1,12.71,100,1,14.12,100,1,12.65,200,2,14.56,800,2,12.50,700,1,14.60,700,1,12.46,200,2,14.61,100,1,12.43,700,1,14.65,100,1,12.42,700,1,14.68,700,1,ARL,287560121
885,2025-07-17T15:33:41.777404666Z,2025-07-17T15:33:41.777239400Z,160,2,1108,A,A,2,13.85,100,130,165266,241612426,13.26,100,1,13.82,10,1,13.23,2,1,13.83,100,1,13.03,100,1,13.85,100,1,12.73,100,1,13.87,100,1,12.71,100,1,13.95,2,1,12.65,200,2,14.12,100,1,12.50,700,1,14.56,800,2,12.46,200,2,14.60,700,1,12.43,700,1,14.61,100,1,12.42,700,1,14.65,100,1,ARL,287560333
886,2025-07-17T15:33:41.784121031Z,2025-07-17T15:33:41.783955668Z,160,2,1108,C,A,3,13.87,100,130,165363,241612450,13.26,100,1,13.82,10,1,13.23,2,1,13.83,100,1,13.03,100,1,13.85,100,1,12.73,100,1,13.95,2,1,12.71,100,1,14.12,100,1,12.65,200,2,14.56,800,2,12.50,700,1,14.60,700,1,12.46,200,2,14.61,100,1,12.43,700,1,14.65,100,1,12.42,700,1,14.68,700,1,ARL,286828253
887,2025-07-17T15:33:42.773141775Z,2025-07-17T15:33:42.772976862Z,160,2,1108,C,A,0,13.82,10,130,164913,241630390,13.26,100,1,13.83,100,1,13.23,2,1,13.85,100,1,13.03,100,1,13.95,2,1,12.73,100,1,14.12,100,1,12.71,100,1,14.56,800,2,12.65,200,2,14.60,700,1,12.50,700,1,14.61,100,1,12.46,200,2,14.65,100,1,12.43,700,1,14.68,700,1,12.42,700,1,14.72,200,2,ARL,287560109
888,2025-07-17T15:34:28.155773560Z,2025-07-17T15:34:28.155608087Z,160,2,1108,A,A,4,14.20,50,130,165473,242513312,13.26,100,1,13.83,100,1,13.23,2,1,13.85,100,1,13.03,100,1,13.95,2,1,12.73,100,1,14.12,100,1,12.71,100,1,14.20,50,1,12.65,200,2,14.56,800,2,12.50,700,1,14.60,700,1,12.46,200,2,14.61,100,1,12.43,700,1,14.65,100,1,12.42,700,1,14.68,700,1,ARL,288723725
889,2025-07-17T15:34:28.156815057Z,2025-07-17T15:34:28.156649544Z,160,2,1108,C,B,5,12.65,100,0,165513,242513329,13.26,100,1,13.83,100,1,13.23,2,1,13.85,100,1,13.03,100,1,13.95,2,1,12.73,100,1,14.12,100,1,12.71,100,1,14.20,50,1,12.65,100,1,14.56,800,2,12.50,700,1,14.60,700,1,12.46,200,2,14.61,100,1,12.43,700,1,14.65,100,1,12.42,700,1,14.68,700,1,ARL,236206261
890,2025-07-17T15:34:28.156815057Z,2025-07-17T15:34:28.156649544Z,160,2,1108,A,B,11,12.36,100,130,165513,242513329,13.26,100,1,13.83,100,1,13.23,2,1,13.85,100,1,13.03,100,1,13.95,2,1,12.73,100,1,14.12,100,1,12.71,100,1,14.20,50,1,12.65,100,1,14.56,800,2,12.50,700,1,14.60,700,1,12.46,200,2,14.61,100,1,12.43,700,1,14.65,100,1,12.42,700,1,14.68,700,1,ARL,288723813
891,2025-07-17T15:34:28.156884900Z,2025-07-17T15:34:28.156719339Z,160,2,1108,C,B,5,12.65,100,0,165561,242513330,13.26,100,1,13.83,100,1,13.23,2,1,13.85,100,1,13.03,100,1,13.95,2,1,12.73,100,1,14.12,100,1,12.71,100,1,14.20,50,1,12.50,700,1,14.56,800,2,12.46,200,2,14.60,700,1,12.43,700,1,14.61,100,1,12.42,700,1,14.65,100,1,12.37,700,1,14.68,700,1,ARL,236179089
892,2025-07-17T15:34:28.156884900Z,2025-07-17T15:34:28.156719339Z,160,2,1108,A,B,10,12.36,100,130,165561,242513330,13.26,100,1,13.83,100,1,13.23,2,1,13.85,100,1,13.03,100,1,13.95,2,1,12.73,100,1,14.12,100,1,12.71,100,1,14.20,50,1,12.50,700,1,14.56,800,2,12.46,200,2,14.60,700,1,12.43,700,1,14.61,100,1,12.42,700,1,14.65,100,1,12.37,700,1,14.68,700,1,ARL,288723817
893,2025-07-17T15:34:28.170740864Z,2025-07-17T15:34:28.170575785Z,160,2,1108,A,A,0,13.81,50,130,165079,242513651,13.26,100,1,13.81,50,1,13.23,2,1,13.83,100,1,13.03,100,1,13.85,100,1,12.73,100,1,13.95,2,1,12.71,100,1,14.12,100,1,12.50,700,1,14.20,50,1,12.46,200,2,14.56,800,2,12.43,700,1,14.60,700,1,12.42,700,1,14.61,100,1,12.37,700,1,14.65,100,1,ARL,288724173
894,2025-07-17T15:34:28.170792211Z,2025-07-17T15:34:28.170626756Z,160,2,1108,C,B,0,13.26,100,130,165455,242513653,13.23,2,1,13.81,50,1,13.03,100,1,13.83,100,1,12.73,100,1,13.85,100,1,12.71,100,1,13.95,2,1,12.50,700,1,14.12,100,1,12.46,200,2,14.20,50,1,12.43,700,1,14.56,800,2,12.42,700,1,14.60,700,1,12.37,700,1,14.61,100,1,12.36,200,2,14.65,100,1,ARL,285586221
895,2025-07-17T15:34:28.171437442Z,2025-07-17T15:34:28.171272157Z,160,2,1108,A,A,0,13.78,2,130,165285,242513665,13.23,2,1,13.78,2,1,13.03,100,1,13.81,50,1,12.73,100,1,13.83,100,1,12.71,100,1,13.85,100,1,12.50,700,1,13.95,2,1,12.46,200,2,14.12,100,1,12.43,700,1,14.20,50,1,12.42,700,1,14.56,800,2,12.37,700,1,14.60,700,1,12.36,200,2,14.61,100,1,ARL,288724201
896,2025-07-17T15:34:28.172057926Z,2025-07-17T15:34:28.171892519Z,160,2,1108,A,B,0,13.31,10,130,165407,242513691,13.31,10,1,13.78,2,1,13.23,2,1,13.81,50,1,13.03,100,1,13.83,100,1,12.73,100,1,13.85,100,1,12.71,100,1,13.95,2,1,12.50,700,1,14.12,100,1,12.46,200,2,14.20,50,1,12.43,700,1,14.56,800,2,12.42,700,1,14.60,700,1,12.37,700,1,14.61,100,1,ARL,288724225
897,2025-07-17T15:34:28.172058708Z,2025-07-17T15:34:28.171893498Z,160,2,1108,A,A,2,13.82,10,130,165210,242513692,13.31,10,1,13.78,2,1,13.23,2,1,13.81,50,1,13.03,100,1,13.82,10,1,12.73,100,1,13.83,100,1,12.71,100,1,13.85,100,1,12.50,700,1,13.95,2,1,12.46,200,2,14.12,100,1,12.43,700,1,14.20,50,1,12.42,700,1,14.56,800,2,12.37,700,1,14.60,700,1,ARL,288724229
898,2025-07-17T15:34:28.175011712Z,2025-07-17T15:34:28.174846475Z,160,2,1108,A,B,1,13.30,100,130,165237,242513742,13.31,10,1,13.78,2,1,13.30,100,1,13.81,50,1,13.23,2,1,13.82,10,1,13.03,100,1,13.83,100,1,12.73,100,1,13.85,100,1,12.71,100,1,13.95,2,1,12.50,700,1,14.12,100,1,12.46,200,2,14.20,50,1,12.43,700,1,14.56,800,2,12.42,700,1,14.60,700,1,ARL,288724429
899,2025-07-17T15:34:28.175030125Z,2025-07-17T15:34:28.174864618Z,160,2,1108,C,A,3,13.83,100,0,165507,242513743,13.31,10,1,13.78,2,1,13.30,100,1,13.81,50,1,13.23,2,1,13.82,10,1,13.03,100,1,13.85,100,1,12.73,100,1,13.95,2,1,12.71,100,1,14.12,100,1,12.50,700,1,14.20,50,1,12.46,200,2,14.56,800,2,12.43,700,1,14.60,700,1,12.42,700,1,14.61,100,1,ARL,287560121
900,2025-07-17T15:34:28.175030125Z,2025-07-17T15:34:28.174864618Z,160,2,1108,A,A,1,13.79,100,130,165507,242513743,13.31,10,1,13.78,2,1,13.30,100,1,13.79,100,1,13.23,2,1,13.81,50,1,13.03,100,1,13.82,10,1,12.73,100,1,13.85,100,1,12.71,100,1,13.95,2,1,12.50,700,1,14.12,100,1,12.46,200,2,14.20,50,1,12.43,700,1,14.56,800,2,12.42,700,1,14.60,700,1,ARL,288724433
901,2025-07-17T15:34:28.175329569Z,2025-07-17T15:34:28.175164464Z,160,2,1108,C,A,0,13.78,2,130,165105,242513747,13.31,10,1,13.79,100,1,13.30,100,1,13.81,50,1,13.23,2,1,13.82,10,1,13.03,100,1,13.85,100,1,12.73,100,1,13.95,2,1,12.71,100,1,14.12,100,1,12.50,700,1,14.20,50,1,12.46,200,2,14.56,800,2,12.43,700,1,14.60,700,1,12.42,700,1,14.61,100,1,ARL,288724201
902,2025-07-17T15:34:28.175752130Z,2025-07-17T15:34:28.175586497Z,160,2,1108,C,B,13,12.23,100,0,165633,242513748,13.31,10,1,13.79,100,1,13.30,100,1,13.81,50,1,13.23,2,1,13.82,10,1,13.03,100,1,13.85,100,1,12.73,100,1,13.95,2,1,12.71,100,1,14.12,100,1,12.50,700,1,14.20,50,1,12.46,200,2,14.56,800,2,12.43,700,1,14.60,700,1,12.42,700,1,14.61,100,1,ARL,286680693
903,2025-07-17T15:34:28.175752130Z,2025-07-17T15:34:28.175586497Z,160,2,1108,A,B,13,12.27,100,130,165633,242513748,13.31,10,1,13.79,100,1,13.30,100,1,13.81,50,1,13.23,2,1,13.82,10,1,13.03,100,1,13.85,100,1,12.73,100,1,13.95,2,1,12.71,100,1,14.12,100,1,12.50,700,1,14.20,50,1,12.46,200,2,14.56,800,2,12.43,700,1,14.60,700,1,12.42,700,1,14.61,100,1,ARL,288724485
904,2025-07-17T15:34:28.175767666Z,2025-07-17T15:34:28.175602100Z,160,2,1108,C,A,15,14.91,100,0,165566,242513749,13.31,10,1,13.79,100,1,13.30,100,1,13.81,50,1,13.23,2,1,13.82,10,1,13.03,100,1,13.85,100,1,12.73,100,1,13.95,2,1,12.71,100,1,14.12,100,1,12.50,700,1,14.20,50,1,12.46,200,2,14.56,800,2,12.43,700,1,14.60,700,1,12.42,700,1,14.61,100,1,ARL,286680721
905,2025-07-17T15:34:28.175767666Z,2025-07-17T15:34:28.175602100Z,160,2,1108,A,A,15,14.86,100,130,165566,242513749,13.31,10,1,13.79,100,1,13.30,100,1,13.81,50,1,13.23,2,1,13.82,10,1,13.03,100,1,13.85,100,1,12.73,100,1,13.95,2,1,12.71,100,1,14.12,100,1,12.50,700,1,14.20,50,1,12.46,200,2,14.56,800,2,12.43,700,1,14.60,700,1,12.42,700,1,14.61,100,1,ARL,288724489
906,2025-07-17T15:34:28.180356536Z,2025-07-17T15:34:28.180191067Z,160,2,1108,A,A,1,13.80,100,130,165469,242513781,13.31,10,1,13.79,100,1,13.30,100,1,13.80,100,1,13.23,2,1,13.81,50,1,13.03,100,1,13.82,10,1,12.73,100,1,13.85,100,1,12.71,100,1,13.95,2,1,12.50,700,1,14.12,100,1,12.46,200,2,14.20,50,1,12.43,700,1,14.56,800,2,12.42,700,1,14.60,700,1,ARL,288724565
907,2025-07-17T15:34:28.187237384Z,2025-07-17T15:34:28.187072050Z,160,2,1108,C,A,4,13.85,100,130,165334,242513907,13.31,10,1,13.79,100,1,13.30,100,1,13.80,100,1,13.23,2,1,13.81,50,1,13.03,100,1,13.82,10,1,12.73,100,1,13.95,2,1,12.71,100,1,14.12,100,1,12.50,700,1,14.20,50,1,12.46,200,2,14.56,800,2,12.43,700,1,14.60,700,1,12.42,700,1,14.61,100,1,ARL,287560333
908,2025-07-17T15:34:28.192269421Z,2025-07-17T15:34:28.192104387Z,160,2,1108,C,A,0,13.79,100,130,165034,242513974,13.31,10,1,13.80,100,1,13.30,100,1,13.81,50,1,13.23,2,1,13.82,10,1,13.03,100,1,13.95,2,1,12.73,100,1,14.12,100,1,12.71,100,1,14.20,50,1,12.50,700,1,14.56,800,2,12.46,200,2,14.60,700,1,12.43,700,1,14.61,100,1,12.42,700,1,14.65,100,1,ARL,288724433
909,2025-07-17T15:34:28.231601320Z,2025-07-17T15:34:28.231436134Z,160,2,1108,A,A,3,13.83,100,130,165186,242514372,13.31,10,1,13.80,100,1,13.30,100,1,13.81,50,1,13.23,2,1,13.82,10,1,13.03,100,1,13.83,100,1,12.73,100,1,13.95,2,1,12.71,100,1,14.12,100,1,12.50,700,1,14.20,50,1,12.46,200,2,14.56,800,2,12.43,700,1,14.60,700,1,12.42,700,1,14.61,100,1,ARL,288725173
910,2025-07-17T15:34:28.256123809Z,2025-07-17T15:34:28.255958718Z,160,2,1108,C,A,6,14.20,50,130,165091,242514761,13.31,10,1,13.80,100,1,13.30,100,1,13.81,50,1,13.23,2,1,13.82,10,1,13.03,100,1,13.83,100,1,12.73,100,1,13.95,2,1,12.71,100,1,14.12,100,1,12.50,700,1,14.56,800,2,12.46,200,2,14.60,700,1,12.43,700,1,14.61,100,1,12.42,700,1,14.65,100,1,ARL,288723725
911,2025-07-17T15:34:28.271275449Z,2025-07-17T15:34:28.271110273Z,160,2,1108,C,A,1,13.81,50,130,165176,242515164,13.31,10,1,13.80,100,1,13.30,100,1,13.82,10,1,13.23,2,1,13.83,100,1,13.03,100,1,13.95,2,1,12.73,100,1,14.12,100,1,12.71,100,1,14.56,800,2,12.50,700,1,14.60,700,1,12.46,200,2,14.61,100,1,12.43,700,1,14.65,100,1,12.42,700,1,14.68,700,1,ARL,288724173
912,2025-07-17T15:34:28.281217370Z,2025-07-17T15:34:28.281052249Z,160,2,1108,C,A,0,13.80,100,130,165121,242515254,13.31,10,1,13.82,10,1,13.30,100,1,13.83,100,1,13.23,2,1,13.95,2,1,13.03,100,1,14.12,100,1,12.73,100,1,14.56,800,2,12.71,100,1,14.60,700,1,12.50,700,1,14.61,100,1,12.46,200,2,14.65,100,1,12.43,700,1,14.68,700,1,12.42,700,1,14.72,200,2,ARL,288724565
913,2025-07-17T15:34:28.281945481Z,2025-07-17T15:34:28.281780230Z,160,2,1108,C,A,12,14.86,100,0,165251,242515263,13.31,10,1,13.82,10,1,13.30,100,1,13.83,100,1,13.23,2,1,13.95,2,1,13.03,100,1,14.12,100,1,12.73,100,1,14.56,800,2,12.71,100,1,14.60,700,1,12.50,700,1,14.61,100,1,12.46,200,2,14.65,100,1,12.43,700,1,14.68,700,1,12.42,700,1,14.72,200,2,ARL,288724489
914,2025-07-17T15:34:28.281945481Z,2025-07-17T15:34:28.281780230Z,160,2,1108,A,A,12,14.90,100,130,165251,242515263,13.31,10,1,13.82,10,1,13.30,100,1,13.83,100,1,13.23,2,1,13.95,2,1,13.03,100,1,14.12,100,1,12.73,100,1,14.56,800,2,12.71,100,1,14.60,700,1,12.50,700,1,14.61,100,1,12.46,200,2,14.65,100,1,12.43,700,1,14.68,700,1,12.42,700,1,14.72,200,2,ARL,288726085
915,2025-07-17T15:34:32.289409612Z,2025-07-17T15:34:32.289244370Z,160,2,1108,A,A,2,13.84,100,130,165242,242598225,13.31,10,1,13.82,10,1,13.30,100,1,13.83,100,1,13.23,2,1,13.84,100,1,13.03,100,1,13.95,2,1,12.73,100,1,14.12,100,1,12.71,100,1,14.56,800,2,12.50,700,1,14.60,700,1,12.46,200,2,14.61,100,1,12.43,700,1,14.65,100,1,12.42,700,1,14.68,700,1,ARL,288845417
916,2025-07-17T15:34:39.864692027Z,2025-07-17T15:34:39.864526516Z,160,2,1108,A,A,0,13.80,15,130,165511,242774235,13.31,10,1,13.80,15,1,13.30,100,1,13.82,10,1,13.23,2,1,13.83,100,1,13.03,100,1,13.84,100,1,12.73,100,1,13.95,2,1,12.71,100,1,14.12,100,1,12.50,700,1,14.56,800,2,12.46,200,2,14.60,700,1,12.43,700,1,14.61,100,1,12.42,700,1,14.65,100,1,ARL,289055901
917,2025-07-17T15:34:39.865337932Z,2025-07-17T15:34:39.865171719Z,160,2,1108,C,A,2,13.83,100,0,166213,242774299,13.31,10,1,13.80,15,1,13.30,100,1,13.82,10,1,13.23,2,1,13.84,100,1,13.03,100,1,13.95,2,1,12.73,100,1,14.12,100,1,12.71,100,1,14.56,800,2,12.50,700,1,14.60,700,1,12.46,200,2,14.61,100,1,12.43,700,1,14.65,100,1,12.42,700,1,14.68,700,1,ARL,288725173
918,2025-07-17T15:34:39.865337932Z,2025-07-17T15:34:39.865171719Z,160,2,1108,A,A,1,13.81,100,130,166213,242774299,13.31,10,1,13.80,15,1,13.30,100,1,13.81,100,1,13.23,2,1,13.82,10,1,13.03,100,1,13.84,100,1,12.73,100,1,13.95,2,1,12.71,100,1,14.12,100,1,12.50,700,1,14.56,800,2,12.46,200,2,14.60,700,1,12.43,700,1,14.61,100,1,12.42,700,1,14.65,100,1,ARL,289056097
919,2025-07-17T15:34:39.871606986Z,2025-07-17T15:34:39.871441822Z,160,2,1108,A,A,1,13.81,100,130,165164,242774468,13.31,10,1,13.80,15,1,13.30,100,1,13.81,200,2,13.23,2,1,13.82,10,1,13.03,100,1,13.84,100,1,12.73,100,1,13.95,2,1,12.71,100,1,14.12,100,1,12.50,700,1,14.56,800,2,12.46,200,2,14.60,700,1,12.43,700,1,14.61,100,1,12.42,700,1,14.65,100,1,ARL,289056353
920,2025-07-17T15:34:39.878645012Z,2025-07-17T15:34:39.878479562Z,160,2,1108,C,A,3,13.84,100,130,165450,242774619,13.31,10,1,13.80,15,1,13.30,100,1,13.81,200,2,13.23,2,1,13.82,10,1,13.03,100,1,13.95,2,1,12.73,100,1,14.12,100,1,12.71,100,1,14.56,800,2,12.50,700,1,14.60,700,1,12.46,200,2,14.61,100,1,12.43,700,1,14.65,100,1,12.42,700,1,14.68,700,1,ARL,288845417
921,2025-07-17T15:34:42.774190041Z,2025-07-17T15:34:42.774024574Z,160,2,1108,C,B,0,13.31,10,130,165467,242816556,13.30,100,1,13.80,15,1,13.23,2,1,13.81,200,2,13.03,100,1,13.82,10,1,12.73,100,1,13.95,2,1,12.71,100,1,14.12,100,1,12.50,700,1,14.56,800,2,12.46,200,2,14.60,700,1,12.43,700,1,14.61,100,1,12.42,700,1,14.65,100,1,12.37,700,1,14.68,700,1,ARL,288724225
922,2025-07-17T15:34:42.775304741Z,2025-07-17T15:34:42.775139521Z,160,2,1108,C,A,1,13.81,100,130,165220,242816563,13.30,100,1,13.80,15,1,13.23,2,1,13.81,100,1,13.03,100,1,13.82,10,1,12.73,100,1,13.95,2,1,12.71,100,1,14.12,100,1,12.50,700,1,14.56,800,2,12.46,200,2,14.60,700,1,12.43,700,1,14.61,100,1,12.42,700,1,14.65,100,1,12.37,700,1,14.68,700,1,ARL,289056353
923,2025-07-17T15:34:46.774087945Z,2025-07-17T15:34:46.773922586Z,160,2,1108,C,A,0,13.80,15,130,165359,242893860,13.30,100,1,13.81,100,1,13.23,2,1,13.82,10,1,13.03,100,1,13.95,2,1,12.73,100,1,14.12,100,1,12.71,100,1,14.56,800,2,12.50,700,1,14.60,700,1,12.46,200,2,14.61,100,1,12.43,700,1,14.65,100,1,12.42,700,1,14.68,700,1,12.37,700,1,14.72,200,2,ARL,289055901
924,2025-07-17T15:34:46.800955057Z,2025-07-17T15:34:46.800789632Z,160,2,1108,A,A,2,13.83,100,130,165425,242894153,13.30,100,1,13.81,100,1,13.23,2,1,13.82,10,1,13.03,100,1,13.83,100,1,12.73,100,1,13.95,2,1,12.71,100,1,14.12,100,1,12.50,700,1,14.56,800,2,12.46,200,2,14.60,700,1,12.43,700,1,14.61,100,1,12.42,700,1,14.65,100,1,12.37,700,1,14.68,700,1,ARL,289199221
925,2025-07-17T15:34:53.545830704Z,2025-07-17T15:34:53.545665068Z,160,2,1108,C,A,1,13.82,10,130,165636,243011340,13.30,100,1,13.81,100,1,13.23,2,1,13.83,100,1,13.03,100,1,13.95,2,1,12.73,100,1,14.12,100,1,12.71,100,1,14.56,800,2,12.50,700,1,14.60,700,1,12.46,200,2,14.61,100,1,12.43,700,1,14.65,100,1,12.42,700,1,14.68,700,1,12.37,700,1,14.72,200,2,ARL,288724229
926,2025-07-17T15:35:05.620763928Z,2025-07-17T15:35:05.620598378Z,160,2,1108,A,A,0,13.77,15,130,165550,243344672,13.30,100,1,13.77,15,1,13.23,2,1,13.81,100,1,13.03,100,1,13.83,100,1,12.73,100,1,13.95,2,1,12.71,100,1,14.12,100,1,12.50,700,1,14.56,800,2,12.46,200,2,14.60,700,1,12.43,700,1,14.61,100,1,12.42,700,1,14.65,100,1,12.37,700,1,14.68,700,1,ARL,289722397
927,2025-07-17T15:35:05.712575243Z,2025-07-17T15:35:05.712409728Z,160,2,1108,C,A,1,13.81,100,0,165515,243347940,13.30,100,1,13.77,15,1,13.23,2,1,13.83,100,1,13.03,100,1,13.95,2,1,12.73,100,1,14.12,100,1,12.71,100,1,14.56,800,2,12.50,700,1,14.60,700,1,12.46,200,2,14.61,100,1,12.43,700,1,14.65,100,1,12.42,700,1,14.68,700,1,12.37,700,1,14.72,200,2,ARL,289056097
928,2025-07-17T15:35:05.712575243Z,2025-07-17T15:35:05.712409728Z,160,2,1108,A,A,1,13.78,100,130,165515,243347940,13.30,100,1,13.77,15,1,13.23,2,1,13.78,100,1,13.03,100,1,13.83,100,1,12.73,100,1,13.95,2,1,12.71,100,1,14.12,100,1,12.50,700,1,14.56,800,2,12.46,200,2,14.60,700,1,12.43,700,1,14.61,100,1,12.42,700,1,14.65,100,1,12.37,700,1,14.68,700,1,ARL,289726281
929,2025-07-17T15:35:05.713315450Z,2025-07-17T15:35:05.713150123Z,160,2,1108,C,A,7,14.61,100,130,165327,243347987,13.30,100,1,13.77,15,1,13.23,2,1,13.78,100,1,13.03,100,1,13.83,100,1,12.73,100,1,13.95,2,1,12.71,100,1,14.12,100,1,12.50,700,1,14.56,800,2,12.46,200,2,14.60,700,1,12.43,700,1,14.65,100,1,12.42,700,1,14.68,700,1,12.37,700,1,14.72,200,2,ARL,237978629
930,2025-07-17T15:35:05.713322577Z,2025-07-17T15:35:05.713157077Z,160,2,1108,C,A,12,14.90,100,0,165500,243347988,13.30,100,1,13.77,15,1,13.23,2,1,13.78,100,1,13.03,100,1,13.83,100,1,12.73,100,1,13.95,2,1,12.71,100,1,14.12,100,1,12.50,700,1,14.56,800,2,12.46,200,2,14.60,700,1,12.43,700,1,14.65,100,1,12.42,700,1,14.68,700,1,12.37,700,1,14.72,200,2,ARL,288726085
931,2025-07-17T15:35:05.713322577Z,2025-07-17T15:35:05.713157077Z,160,2,1108,A,A,12,14.85,100,130,165500,243347988,13.30,100,1,13.77,15,1,13.23,2,1,13.78,100,1,13.03,100,1,13.83,100,1,12.73,100,1,13.95,2,1,12.71,100,1,14.12,100,1,12.50,700,1,14.56,800,2,12.46,200,2,14.60,700,1,12.43,700,1,14.65,100,1,12.42,700,1,14.68,700,1,12.37,700,1,14.72,200,2,ARL,289726349
932,2025-07-17T15:35:05.713677091Z,2025-07-17T15:35:05.713508657Z,160,2,1108,A,A,5,14.40,100,128,168434,243348032,13.30,100,1,13.77,15,1,13.23,2,1,13.78,100,1,13.03,100,1,13.83,100,1,12.73,100,1,13.95,2,1,12.71,100,1,14.12,100,1,12.50,700,1,14.40,100,1,12.46,200,2,14.56,800,2,12.43,700,1,14.60,700,1,12.42,700,1,14.65,100,1,12.37,700,1,14.68,700,1,ARL,289726421
933,2025-07-17T15:35:05.729568877Z,2025-07-17T15:35:05.729398505Z,160,2,1108,A,A,2,13.80,100,128,170372,243351264,13.30,100,1,13.77,15,1,13.23,2,1,13.78,100,1,13.03,100,1,13.80,100,1,12.73,100,1,13.83,100,1,12.71,100,1,13.95,2,1,12.50,700,1,14.12,100,1,12.46,200,2,14.40,100,1,12.43,700,1,14.56,800,2,12.42,700,1,14.60,700,1,12.37,700,1,14.65,100,1,ARL,289730309
934,2025-07-17T15:35:05.737967956Z,2025-07-17T15:35:05.737802616Z,160,2,1108,C,A,3,13.83,100,130,165340,243352644,13.30,100,1,13.77,15,1,13.23,2,1,13.78,100,1,13.03,100,1,13.80,100,1,12.73,100,1,13.95,2,1,12.71,100,1,14.12,100,1,12.50,700,1,14.40,100,1,12.46,200,2,14.56,800,2,12.43,700,1,14.60,700,1,12.42,700,1,14.65,100,1,12.37,700,1,14.68,700,1,ARL,289199221
935,2025-07-17T15:35:06.286572335Z,2025-07-17T15:35:06.286407017Z,160,2,1108,C,A,0,13.77,15,130,165318,243362628,13.30,100,1,13.78,100,1,13.23,2,1,13.80,100,1,13.03,100,1,13.95,2,1,12.73,100,1,14.12,100,1,12.71,100,1,14.40,100,1,12.50,700,1,14.56,800,2,12.46,200,2,14.60,700,1,12.43,700,1,14.65,100,1,12.42,700,1,14.68,700,1,12.37,700,1,14.72,200,2,ARL,289722397
936,2025-07-17T15:35:09.788280931Z,2025-07-17T15:35:09.788115219Z,160,2,1108,C,B,1,13.23,2,0,165712,243432828,13.30,100,1,13.78,100,1,13.03,100,1,13.80,100,1,12.73,100,1,13.95,2,1,12.71,100,1,14.12,100,1,12.50,700,1,14.40,100,1,12.46,200,2,14.56,800,2,12.43,700,1,14.60,700,1,12.42,700,1,14.65,100,1,12.37,700,1,14.68,700,1,12.36,200,2,14.72,200,2,ARL,272263853
937,2025-07-17T15:35:09.788280931Z,2025-07-17T15:35:09.788115219Z,160,2,1108,A,B,1,13.14,2,130,165712,243432828,13.30,100,1,13.78,100,1,13.14,2,1,13.80,100,1,13.03,100,1,13.95,2,1,12.73,100,1,14.12,100,1,12.71,100,1,14.40,100,1,12.50,700,1,14.56,800,2,12.46,200,2,14.60,700,1,12.43,700,1,14.65,100,1,12.42,700,1,14.68,700,1,12.37,700,1,14.72,200,2,ARL,289828293
938,2025-07-17T15:35:11.891867009Z,2025-07-17T15:35:11.891701845Z,160,2,1108,C,A,1,13.80,100,130,165164,243482295,13.30,100,1,13.78,100,1,13.14,2,1,13.95,2,1,13.03,100,1,14.12,100,1,12.73,100,1,14.40,100,1,12.71,100,1,14.56,800,2,12.50,700,1,14.60,700,1,12.46,200,2,14.65,100,1,12.43,700,1,14.68,700,1,12.42,700,1,14.72,200,2,12.37,700,1,14.81,200,2,ARL,289730309
939,2025-07-17T15:35:14.301647013Z,2025-07-17T15:35:14.301481698Z,160,2,1108,A,A,7,14.68,700,130,165315,243521615,13.30,100,1,13.78,100,1,13.14,2,1,13.95,2,1,13.03,100,1,14.12,100,1,12.73,100,1,14.40,100,1,12.71,100,1,14.56,800,2,12.50,700,1,14.60,700,1,12.46,200,2,14.65,100,1,12.43,700,1,14.68,1400,2,12.42,700,1,14.72,200,2,12.37,700,1,14.81,200,2,ARL,289932801
940,2025-07-17T15:35:14.302443648Z,2025-07-17T15:35:14.302278179Z,160,2,1108,C,A,12,14.91,700,130,165469,243521616,13.30,100,1,13.78,100,1,13.14,2,1,13.95,2,1,13.03,100,1,14.12,100,1,12.73,100,1,14.40,100,1,12.71,100,1,14.56,800,2,12.50,700,1,14.60,700,1,12.46,200,2,14.65,100,1,12.43,700,1,14.68,1400,2,12.42,700,1,14.72,200,2,12.37,700,1,14.81,200,2,ARL,147217629
941,2025-07-17T15:35:15.940644416Z,2025-07-17T15:35:15.940479233Z,160,2,1108,A,A,1,13.82,100,130,165183,243557058,13.30,100,1,13.78,100,1,13.14,2,1,13.82,100,1,13.03,100,1,13.95,2,1,12.73,100,1,14.12,100,1,12.71,100,1,14.40,100,1,12.50,700,1,14.56,800,2,12.46,200,2,14.60,700,1,12.43,700,1,14.65,100,1,12.42,700,1,14.68,1400,2,12.37,700,1,14.72,200,2,ARL,289976125
942,2025-07-17T15:35:23.746674314Z,2025-07-17T15:35:23.746509184Z,160,2,1108,A,A,1,13.80,100,130,165130,243692012,13.30,100,1,13.78,100,1,13.14,2,1,13.80,100,1,13.03,100,1,13.82,100,1,12.73,100,1,13.95,2,1,12.71,100,1,14.12,100,1,12.50,700,1,14.40,100,1,12.46,200,2,14.56,800,2,12.43,700,1,14.60,700,1,12.42,700,1,14.65,100,1,12.37,700,1,14.68,1400,2,ARL,290159301
943,2025-07-17T15:35:23.754618546Z,2025-07-17T15:35:23.754453294Z,160,2,1108,C,A,2,13.82,100,130,165252,243692501,13.30,100,1,13.78,100,1,13.14,2,1,13.80,100,1,13.03,100,1,13.95,2,1,12.73,100,1,14.12,100,1,12.71,100,1,14.40,100,1,12.50,700,1,14.56,800,2,12.46,200,2,14.60,700,1,12.43,700,1,14.65,100,1,12.42,700,1,14.68,1400,2,12.37,700,1,14.72,200,2,ARL,289976125
944,2025-07-17T15:35:39.056679600Z,2025-07-17T15:35:39.056513985Z,160,2,1108,C,A,1,13.80,100,130,165615,243992725,13.30,100,1,13.78,100,1,13.14,2,1,13.95,2,1,13.03,100,1,14.12,100,1,12.73,100,1,14.40,100,1,12.71,100,1,14.56,800,2,12.50,700,1,14.60,700,1,12.46,200,2,14.65,100,1,12.43,700,1,14.68,1400,2,12.42,700,1,14.72,200,2,12.37,700,1,14.81,200,2,ARL,290159301
945,2025-07-17T15:35:43.128809717Z,2025-07-17T15:35:43.128644252Z,160,2,1108,A,A,1,13.82,100,130,165465,244078096,13.30,100,1,13.78,100,1,13.14,2,1,13.82,100,1,13.03,100,1,13.95,2,1,12.73,100,1,14.12,100,1,12.71,100,1,14.40,100,1,12.50,700,1,14.56,800,2,12.46,200,2,14.60,700,1,12.43,700,1,14.65,100,1,12.42,700,1,14.68,1400,2,12.37,700,1,14.72,200,2,ARL,290630573
946,2025-07-17T15:36:30.044094509Z,2025-07-17T15:36:30.043928872Z,160,2,1108,A,A,1,13.80,100,130,165637,245013624,13.30,100,1,13.78,100,1,13.14,2,1,13.80,100,1,13.03,100,1,13.82,100,1,12.73,100,1,13.95,2,1,12.71,100,1,14.12,100,1,12.50,700,1,14.40,100,1,12.46,200,2,14.56,800,2,12.43,700,1,14.60,700,1,12.42,700,1,14.65,100,1,12.37,700,1,14.68,1400,2,ARL,291778909
947,2025-07-17T15:36:30.051045453Z,2025-07-17T15:36:30.050880126Z,160,2,1108,C,A,2,13.82,100,130,165327,245013914,13.30,100,1,13.78,100,1,13.14,2,1,13.80,100,1,13.03,100,1,13.95,2,1,12.73,100,1,14.12,100,1,12.71,100,1,14.40,100,1,12.50,700,1,14.56,800,2,12.46,200,2,14.60,700,1,12.43,700,1,14.65,100,1,12.42,700,1,14.68,1400,2,12.37,700,1,14.72,200,2,ARL,290630573
948,2025-07-17T15:36:34.298010005Z,2025-07-17T15:36:34.297844579Z,160,2,1108,C,B,0,13.30,100,130,165426,245144122,13.14,2,1,13.78,100,1,13.03,100,1,13.80,100,1,12.73,100,1,13.95,2,1,12.71,100,1,14.12,100,1,12.50,700,1,14.40,100,1,12.46,200,2,14.56,800,2,12.43,700,1,14.60,700,1,12.42,700,1,14.65,100,1,12.37,700,1,14.68,1400,2,12.36,200,2,14.72,200,2,ARL,288724429
949,2025-07-17T15:36:35.381330809Z,2025-07-17T15:36:35.381165559Z,160,2,1108,A,B,1,13.13,100,130,165250,245161447,13.14,2,1,13.78,100,1,13.13,100,1,13.80,100,1,13.03,100,1,13.95,2,1,12.73,100,1,14.12,100,1,12.71,100,1,14.40,100,1,12.50,700,1,14.56,800,2,12.46,200,2,14.60,700,1,12.43,700,1,14.65,100,1,12.42,700,1,14.68,1400,2,12.37,700,1,14.72,200,2,ARL,291951937
950,2025-07-17T15:36:35.532851032Z,2025-07-17T15:36:35.532685683Z,160,2,1108,A,B,0,13.27,10,130,165349,245174454,13.27,10,1,13.78,100,1,13.14,2,1,13.80,100,1,13.13,100,1,13.95,2,1,13.03,100,1,14.12,100,1,12.73,100,1,14.40,100,1,12.71,100,1,14.56,800,2,12.50,700,1,14.60,700,1,12.46,200,2,14.65,100,1,12.43,700,1,14.68,1400,2,12.42,700,1,14.72,200,2,ARL,291964737
951,2025-07-17T15:36:35.532926951Z,2025-07-17T15:36:35.532761335Z,160,2,1108,C,B,13,12.27,100,0,165616,245174461,13.27,10,1,13.78,100,1,13.14,2,1,13.80,100,1,13.13,100,1,13.95,2,1,13.03,100,1,14.12,100,1,12.73,100,1,14.40,100,1,12.71,100,1,14.56,800,2,12.50,700,1,14.60,700,1,12.46,200,2,14.65,100,1,12.43,700,1,14.68,1400,2,12.42,700,1,14.72,200,2,ARL,288724485
952,2025-07-17T15:36:35.532926951Z,2025-07-17T15:36:35.532761335Z,160,2,1108,A,B,13,12.23,100,130,165616,245174461,13.27,10,1,13.78,100,1,13.14,2,1,13.80,100,1,13.13,100,1,13.95,2,1,13.03,100,1,14.12,100,1,12.73,100,1,14.40,100,1,12.71,100,1,14.56,800,2,12.50,700,1,14.60,700,1,12.46,200,2,14.65,100,1,12.43,700,1,14.68,1400,2,12.42,700,1,14.72,200,2,ARL,291964745
953,2025-07-17T15:36:36.152132527Z,2025-07-17T15:36:36.151966883Z,160,2,1108,C,B,2,13.13,100,0,165644,245183955,13.27,10,1,13.78,100,1,13.14,2,1,13.80,100,1,13.03,100,1,13.95,2,1,12.73,100,1,14.12,100,1,12.71,100,1,14.40,100,1,12.50,700,1,14.56,800,2,12.46,200,2,14.60,700,1,12.43,700,1,14.65,100,1,12.42,700,1,14.68,1400,2,12.37,700,1,14.72,200,2,ARL,291951937
954,2025-07-17T15:36:36.152132527Z,2025-07-17T15:36:36.151966883Z,160,2,1108,A,B,1,13.26,100,130,165644,245183955,13.27,10,1,13.78,100,1,13.26,100,1,13.80,100,1,13.14,2,1,13.95,2,1,13.03,100,1,14.12,100,1,12.73,100,1,14.40,100,1,12.71,100,1,14.56,800,2,12.50,700,1,14.60,700,1,12.46,200,2,14.65,100,1,12.43,700,1,14.68,1400,2,12.42,700,1,14.72,200,2,ARL,291975017
955,2025-07-17T15:36:46.889917278Z,2025-07-17T15:36:46.889749756Z,160,2,1108,C,B,0,13.27,10,128,167522,245499598,13.26,100,1,13.78,100,1,13.14,2,1,13.80,100,1,13.03,100,1,13.95,2,1,12.73,100,1,14.12,100,1,12.71,100,1,14.40,100,1,12.50,700,1,14.56,800,2,12.46,200,2,14.60,700,1,12.43,700,1,14.65,100,1,12.42,700,1,14.68,1400,2,12.37,700,1,14.72,200,2,ARL,291964737
956,2025-07-17T15:36:46.986820391Z,2025-07-17T15:36:46.986655137Z,160,2,1108,C,A,1,13.80,100,130,165254,245503745,13.26,100,1,13.78,100,1,13.14,2,1,13.95,2,1,13.03,100,1,14.12,100,1,12.73,100,1,14.40,100,1,12.71,100,1,14.56,800,2,12.50,700,1,14.60,700,1,12.46,200,2,14.65,100,1,12.43,700,1,14.68,1400,2,12.42,700,1,14.72,200,2,12.37,700,1,14.81,200,2,ARL,291778909
957,2025-07-17T15:36:50.997434689Z,2025-07-17T15:36:50.997269299Z,160,2,1108,A,A,1,13.82,100,130,165390,245564901,13.26,100,1,13.78,100,1,13.14,2,1,13.82,100,1,13.03,100,1,13.95,2,1,12.73,100,1,14.12,100,1,12.71,100,1,14.40,100,1,12.50,700,1,14.56,800,2,12.46,200,2,14.60,700,1,12.43,700,1,14.65,100,1,12.42,700,1,14.68,1400,2,12.37,700,1,14.72,200,2,ARL,292434813
958,2025-07-17T15:37:40.389737573Z,2025-07-17T15:37:40.389572053Z,160,2,1108,C,B,1,13.14,2,0,165520,246491394,13.26,100,1,13.78,100,1,13.03,100,1,13.82,100,1,12.73,100,1,13.95,2,1,12.71,100,1,14.12,100,1,12.50,700,1,14.40,100,1,12.46,200,2,14.56,800,2,12.43,700,1,14.60,700,1,12.42,700,1,14.65,100,1,12.37,700,1,14.68,1400,2,12.36,200,2,14.72,200,2,ARL,289828293
959,2025-07-17T15:37:40.389737573Z,2025-07-17T15:37:40.389572053Z,160,2,1108,A,B,1,13.04,2,130,165520,246491394,13.26,100,1,13.78,100,1,13.04,2,1,13.82,100,1,13.03,100,1,13.95,2,1,12.73,100,1,14.12,100,1,12.71,100,1,14.40,100,1,12.50,700,1,14.56,800,2,12.46,200,2,14.60,700,1,12.43,700,1,14.65,100,1,12.42,700,1,14.68,1400,2,12.37,700,1,14.72,200,2,ARL,293594281
960,2025-07-17T15:39:27.070109669Z,2025-07-17T15:39:27.069942913Z,160,2,1108,A,A,1,13.80,100,128,166756,248436908,13.26,100,1,13.78,100,1,13.04,2,1,13.80,100,1,13.03,100,1,13.82,100,1,12.73,100,1,13.95,2,1,12.71,100,1,14.12,100,1,12.50,700,1,14.40,100,1,12.46,200,2,14.56,800,2,12.43,700,1,14.60,700,1,12.42,700,1,14.65,100,1,12.37,700,1,14.68,1400,2,ARL,296059685
961,2025-07-17T15:39:27.077565902Z,2025-07-17T15:39:27.077400388Z,160,2,1108,C,A,2,13.82,100,130,165514,248437548,13.26,100,1,13.78,100,1,13.04,2,1,13.80,100,1,13.03,100,1,13.95,2,1,12.73,100,1,14.12,100,1,12.71,100,1,14.40,100,1,12.50,700,1,14.56,800,2,12.46,200,2,14.60,700,1,12.43,700,1,14.65,100,1,12.42,700,1,14.68,1400,2,12.37,700,1,14.72,200,2,ARL,292434813
962,2025-07-17T15:39:30.509853083Z,2025-07-17T15:39:30.509687817Z,160,2,1108,A,A,0,13.76,15,130,165266,248491930,13.26,100,1,13.76,15,1,13.04,2,1,13.78,100,1,13.03,100,1,13.80,100,1,12.73,100,1,13.95,2,1,12.71,100,1,14.12,100,1,12.50,700,1,14.40,100,1,12.46,200,2,14.56,800,2,12.43,700,1,14.60,700,1,12.42,700,1,14.65,100,1,12.37,700,1,14.68,1400,2,ARL,296136617
963,2025-07-17T15:39:30.573217843Z,2025-07-17T15:39:30.573052284Z,160,2,1108,C,A,1,13.78,100,0,165559,248492793,13.26,100,1,13.76,15,1,13.04,2,1,13.80,100,1,13.03,100,1,13.95,2,1,12.73,100,1,14.12,100,1,12.71,100,1,14.40,100,1,12.50,700,1,14.56,800,2,12.46,200,2,14.60,700,1,12.43,700,1,14.65,100,1,12.42,700,1,14.68,1400,2,12.37,700,1,14.72,200,2,ARL,289726281
964,2025-07-17T15:39:30.573217843Z,2025-07-17T15:39:30.573052284Z,160,2,1108,A,A,1,13.77,100,130,165559,248492793,13.26,100,1,13.76,15,1,13.04,2,1,13.77,100,1,13.03,100,1,13.80,100,1,12.73,100,1,13.95,2,1,12.71,100,1,14.12,100,1,12.50,700,1,14.40,100,1,12.46,200,2,14.56,800,2,12.43,700,1,14.60,700,1,12.42,700,1,14.65,100,1,12.37,700,1,14.68,1400,2,ARL,296137537
965,2025-07-17T15:39:30.589169820Z,2025-07-17T15:39:30.589004378Z,160,2,1108,C,A,4,14.12,100,130,165442,248493012,13.26,100,1,13.76,15,1,13.04,2,1,13.77,100,1,13.03,100,1,13.80,100,1,12.73,100,1,13.95,2,1,12.71,100,1,14.40,100,1,12.50,700,1,14.56,800,2,12.46,200,2,14.60,700,1,12.43,700,1,14.65,100,1,12.42,700,1,14.68,1400,2,12.37,700,1,14.72,200,2,ARL,286680917
966,2025-07-17T15:39:30.589224596Z,2025-07-17T15:39:30.589059301Z,160,2,1108,A,A,4,14.05,100,130,165295,248493014,13.26,100,1,13.76,15,1,13.04,2,1,13.77,100,1,13.03,100,1,13.80,100,1,12.73,100,1,13.95,2,1,12.71,100,1,14.05,100,1,12.50,700,1,14.40,100,1,12.46,200,2,14.56,800,2,12.43,700,1,14.60,700,1,12.42,700,1,14.65,100,1,12.37,700,1,14.68,1400,2,ARL,296137769
967,2025-07-17T15:39:31.092010369Z,2025-07-17T15:39:31.091844988Z,160,2,1108,A,A,2,13.78,100,130,165381,248502203,13.26,100,1,13.76,15,1,13.04,2,1,13.77,100,1,13.03,100,1,13.78,100,1,12.73,100,1,13.80,100,1,12.71,100,1,13.95,2,1,12.50,700,1,14.05,100,1,12.46,200,2,14.40,100,1,12.43,700,1,14.56,800,2,12.42,700,1,14.60,700,1,12.37,700,1,14.65,100,1,ARL,296149845
968,2025-07-17T15:39:31.098856641Z,2025-07-17T15:39:31.098691429Z,160,2,1108,C,A,3,13.80,100,130,165212,248502510,13.26,100,1,13.76,15,1,13.04,2,1,13.77,100,1,13.03,100,1,13.78,100,1,12.73,100,1,13.95,2,1,12.71,100,1,14.05,100,1,12.50,700,1,14.40,100,1,12.46,200,2,14.56,800,2,12.43,700,1,14.60,700,1,12.42,700,1,14.65,100,1,12.37,700,1,14.68,1400,2,ARL,296059685
969,2025-07-17T15:39:40.691151435Z,2025-07-17T15:39:40.690971606Z,160,2,1108,A,A,0,13.73,15,128,179829,248666930,13.26,100,1,13.73,15,1,13.04,2,1,13.76,15,1,13.03,100,1,13.77,100,1,12.73,100,1,13.78,100,1,12.71,100,1,13.95,2,1,12.50,700,1,14.05,100,1,12.46,200,2,14.40,100,1,12.43,700,1,14.56,800,2,12.42,700,1,14.60,700,1,12.37,700,1,14.65,100,1,ARL,296365029
970,2025-07-17T15:39:40.696349429Z,2025-07-17T15:39:40.696182148Z,160,2,1108,C,A,2,13.77,100,0,167281,248669978,13.26,100,1,13.73,15,1,13.04,2,1,13.76,15,1,13.03,100,1,13.78,100,1,12.73,100,1,13.95,2,1,12.71,100,1,14.05,100,1,12.50,700,1,14.40,100,1,12.46,200,2,14.56,800,2,12.43,700,1,14.60,700,1,12.42,700,1,14.65,100,1,12.37,700,1,14.68,1400,2,ARL,296137537
971,2025-07-17T15:39:40.696349429Z,2025-07-17T15:39:40.696182148Z,160,2,1108,A,A,1,13.74,100,130,167281,248669978,13.26,100,1,13.73,15,1,13.04,2,1,13.74,100,1,13.03,100,1,13.76,15,1,12.73,100,1,13.78,100,1,12.71,100,1,13.95,2,1,12.50,700,1,14.05,100,1,12.46,200,2,14.40,100,1,12.43,700,1,14.56,800,2,12.42,700,1,14.60,700,1,12.37,700,1,14.65,100,1,ARL,296368281
972,2025-07-17T15:39:40.697414147Z,2025-07-17T15:39:40.697247480Z,160,2,1108,C,A,14,14.85,100,0,166667,248670386,13.26,100,1,13.73,15,1,13.04,2,1,13.74,100,1,13.03,100,1,13.76,15,1,12.73,100,1,13.78,100,1,12.71,100,1,13.95,2,1,12.50,700,1,14.05,100,1,12.46,200,2,14.40,100,1,12.43,700,1,14.56,800,2,12.42,700,1,14.60,700,1,12.37,700,1,14.65,100,1,ARL,289726349
973,2025-07-17T15:39:40.697414147Z,2025-07-17T15:39:40.697247480Z,160,2,1108,A,A,12,14.81,100,128,166667,248670386,13.26,100,1,13.73,15,1,13.04,2,1,13.74,100,1,13.03,100,1,13.76,15,1,12.73,100,1,13.78,100,1,12.71,100,1,13.95,2,1,12.50,700,1,14.05,100,1,12.46,200,2,14.40,100,1,12.43,700,1,14.56,800,2,12.42,700,1,14.60,700,1,12.37,700,1,14.65,100,1,ARL,296368709
974,2025-07-17T15:39:40.708810377Z,2025-07-17T15:39:40.708645114Z,160,2,1108,A,A,2,13.76,100,130,165263,248674504,13.26,100,1,13.73,15,1,13.04,2,1,13.74,100,1,13.03,100,1,13.76,115,2,12.73,100,1,13.78,100,1,12.71,100,1,13.95,2,1,12.50,700,1,14.05,100,1,12.46,200,2,14.40,100,1,12.43,700,1,14.56,800,2,12.42,700,1,14.60,700,1,12.37,700,1,14.65,100,1,ARL,296372577
975,2025-07-17T15:39:40.731431547Z,2025-07-17T15:39:40.731266408Z,160,2,1108,C,A,3,13.78,100,130,165139,248676672,13.26,100,1,13.73,15,1,13.04,2,1,13.74,100,1,13.03,100,1,13.76,115,2,12.73,100,1,13.95,2,1,12.71,100,1,14.05,100,1,12.50,700,1,14.40,100,1,12.46,200,2,14.56,800,2,12.43,700,1,14.60,700,1,12.42,700,1,14.65,100,1,12.37,700,1,14.68,1400,2,ARL,296149845
976,2025-07-17T15:39:40.908095999Z,2025-07-17T15:39:40.907929975Z,160,2,1108,C,A,15,15.40,100,0,166024,248685584,13.26,100,1,13.73,15,1,13.04,2,1,13.74,100,1,13.03,100,1,13.76,115,2,12.73,100,1,13.95,2,1,12.71,100,1,14.05,100,1,12.50,700,1,14.40,100,1,12.46,200,2,14.56,800,2,12.43,700,1,14.60,700,1,12.42,700,1,14.65,100,1,12.37,700,1,14.68,1400,2,ARL,146959177
977,2025-07-17T15:39:40.908095999Z,2025-07-17T15:39:40.907929975Z,160,2,1108,A,A,13,15.12,100,130,166024,248685584,13.26,100,1,13.73,15,1,13.04,2,1,13.74,100,1,13.03,100,1,13.76,115,2,12.73,100,1,13.95,2,1,12.71,100,1,14.05,100,1,12.50,700,1,14.40,100,1,12.46,200,2,14.56,800,2,12.43,700,1,14.60,700,1,12.42,700,1,14.65,100,1,12.37,700,1,14.68,1400,2,ARL,296387089
978,2025-07-17T15:39:41.085864728Z,2025-07-17T15:39:41.085699437Z,160,2,1108,A,A,6,14.56,100,130,165291,248688410,13.26,100,1,13.73,15,1,13.04,2,1,13.74,100,1,13.03,100,1,13.76,115,2,12.73,100,1,13.95,2,1,12.71,100,1,14.05,100,1,12.50,700,1,14.40,100,1,12.46,200,2,14.56,900,3,12.43,700,1,14.60,700,1,12.42,700,1,14.65,100,1,12.37,700,1,14.68,1400,2,ARL,296391881
979,2025-07-17T15:39:41.085877317Z,2025-07-17T15:39:41.085711985Z,160,2,1108,C,A,12,14.84,100,130,165332,248688411,13.26,100,1,13.73,15,1,13.04,2,1,13.74,100,1,13.03,100,1,13.76,115,2,12.73,100,1,13.95,2,1,12.71,100,1,14.05,100,1,12.50,700,1,14.40,100,1,12.46,200,2,14.56,900,3,12.43,700,1,14.60,700,1,12.42,700,1,14.65,100,1,12.37,700,1,14.68,1400,2,ARL,146962993
980,2025-07-17T15:39:43.773811774Z,2025-07-17T15:39:43.773645905Z,160,2,1108,C,A,10,14.72,100,0,165869,248737506,13.26,100,1,13.73,15,1,13.04,2,1,13.74,100,1,13.03,100,1,13.76,115,2,12.73,100,1,13.95,2,1,12.71,100,1,14.05,100,1,12.50,700,1,14.40,100,1,12.46,200,2,14.56,900,3,12.43,700,1,14.60,700,1,12.42,700,1,14.65,100,1,12.37,700,1,14.68,1400,2,ARL,286680577
981,2025-07-17T15:39:43.773811774Z,2025-07-17T15:39:43.773645905Z,160,2,1108,A,A,8,14.61,100,130,165869,248737506,13.26,100,1,13.73,15,1,13.04,2,1,13.74,100,1,13.03,100,1,13.76,115,2,12.73,100,1,13.95,2,1,12.71,100,1,14.05,100,1,12.50,700,1,14.40,100,1,12.46,200,2,14.56,900,3,12.43,700,1,14.60,700,1,12.42,700,1,14.61,100,1,12.37,700,1,14.65,100,1,ARL,296455037
982,2025-07-17T15:39:43.773904473Z,2025-07-17T15:39:43.773738855Z,160,2,1108,C,A,11,14.72,100,0,165618,248737508,13.26,100,1,13.73,15,1,13.04,2,1,13.74,100,1,13.03,100,1,13.76,115,2,12.73,100,1,13.95,2,1,12.71,100,1,14.05,100,1,12.50,700,1,14.40,100,1,12.46,200,2,14.56,900,3,12.43,700,1,14.60,700,1,12.42,700,1,14.61,100,1,12.37,700,1,14.65,100,1,ARL,286680573
983,2025-07-17T15:39:43.773904473Z,2025-07-17T15:39:43.773738855Z,160,2,1108,A,A,8,14.61,100,130,165618,248737508,13.26,100,1,13.73,15,1,13.04,2,1,13.74,100,1,13.03,100,1,13.76,115,2,12.73,100,1,13.95,2,1,12.71,100,1,14.05,100,1,12.50,700,1,14.40,100,1,12.46,200,2,14.56,900,3,12.43,700,1,14.60,700,1,12.42,700,1,14.61,200,2,12.37,700,1,14.65,100,1,ARL,296455041
984,2025-07-17T15:39:44.428670900Z,2025-07-17T15:39:44.428505546Z,160,2,1108,C,A,2,13.76,15,130,165354,248751670,13.26,100,1,13.73,15,1,13.04,2,1,13.74,100,1,13.03,100,1,13.76,100,1,12.73,100,1,13.95,2,1,12.71,100,1,14.05,100,1,12.50,700,1,14.40,100,1,12.46,200,2,14.56,900,3,12.43,700,1,14.60,700,1,12.42,700,1,14.61,200,2,12.37,700,1,14.65,100,1,ARL,296136617
985,2025-07-17T15:39:44.433539292Z,2025-07-17T15:39:44.433372235Z,160,2,1108,C,A,0,13.73,15,128,167057,248752483,13.26,100,1,13.74,100,1,13.04,2,1,13.76,100,1,13.03,100,1,13.95,2,1,12.73,100,1,14.05,100,1,12.71,100,1,14.40,100,1,12.50,700,1,14.56,900,3,12.46,200,2,14.60,700,1,12.43,700,1,14.61,200,2,12.42,700,1,14.65,100,1,12.37,700,1,14.68,1400,2,ARL,296365029
986,2025-07-17T15:39:44.436054885Z,2025-07-17T15:39:44.435889060Z,160,2,1108,C,A,0,13.74,100,130,165825,248752938,13.26,100,1,13.76,100,1,13.04,2,1,13.95,2,1,13.03,100,1,14.05,100,1,12.73,100,1,14.40,100,1,12.71,100,1,14.56,900,3,12.50,700,1,14.60,700,1,12.46,200,2,14.61,200,2,12.43,700,1,14.65,100,1,12.42,700,1,14.68,1400,2,12.37,700,1,14.81,300,3,ARL,296368281
987,2025-07-17T15:39:44.450239090Z,2025-07-17T15:39:44.450073949Z,160,2,1108,C,A,0,13.76,100,130,165141,248753643,13.26,100,1,13.95,2,1,13.04,2,1,14.05,100,1,13.03,100,1,14.40,100,1,12.73,100,1,14.56,900,3,12.71,100,1,14.60,700,1,12.50,700,1,14.61,200,2,12.46,200,2,14.65,100,1,12.43,700,1,14.68,1400,2,12.42,700,1,14.81,300,3,12.37,700,1,15.12,100,1,ARL,296372577
988,2025-07-17T15:39:44.450972330Z,2025-07-17T15:39:44.450806746Z,160,2,1108,C,A,8,14.81,100,0,165584,248753673,13.26,100,1,13.95,2,1,13.04,2,1,14.05,100,1,13.03,100,1,14.40,100,1,12.73,100,1,14.56,900,3,12.71,100,1,14.60,700,1,12.50,700,1,14.61,200,2,12.46,200,2,14.65,100,1,12.43,700,1,14.68,1400,2,12.42,700,1,14.81,200,2,12.37,700,1,15.12,100,1,ARL,296368709
989,2025-07-17T15:39:44.450972330Z,2025-07-17T15:39:44.450806746Z,160,2,1108,A,A,9,15.06,100,130,165584,248753673,13.26,100,1,13.95,2,1,13.04,2,1,14.05,100,1,13.03,100,1,14.40,100,1,12.73,100,1,14.56,900,3,12.71,100,1,14.60,700,1,12.50,700,1,14.61,200,2,12.46,200,2,14.65,100,1,12.43,700,1,14.68,1400,2,12.42,700,1,14.81,200,2,12.37,700,1,15.06,100,1,ARL,296478965
990,2025-07-17T15:39:44.451075992Z,2025-07-17T15:39:44.450910591Z,160,2,1108,C,A,0,13.95,2,0,165401,248753678,13.26,100,1,14.05,100,1,13.04,2,1,14.40,100,1,13.03,100,1,14.56,900,3,12.73,100,1,14.60,700,1,12.71,100,1,14.61,200,2,12.50,700,1,14.65,100,1,12.46,200,2,14.68,1400,2,12.43,700,1,14.81,200,2,12.42,700,1,15.06,100,1,12.37,700,1,15.12,100,1,ARL,287540393
991,2025-07-17T15:39:44.451075992Z,2025-07-17T15:39:44.450910591Z,160,2,1108,A,A,1,14.07,2,130,165401,248753678,13.26,100,1,14.05,100,1,13.04,2,1,14.07,2,1,13.03,100,1,14.40,100,1,12.73,100,1,14.56,900,3,12.71,100,1,14.60,700,1,12.50,700,1,14.61,200,2,12.46,200,2,14.65,100,1,12.43,700,1,14.68,1400,2,12.42,700,1,14.81,200,2,12.37,700,1,15.06,100,1,ARL,296478973
992,2025-07-17T15:39:44.455130297Z,2025-07-17T15:39:44.454964327Z,160,2,1108,C,A,8,14.81,100,0,165970,248753748,13.26,100,1,14.05,100,1,13.04,2,1,14.07,2,1,13.03,100,1,14.40,100,1,12.73,100,1,14.56,900,3,12.71,100,1,14.60,700,1,12.50,700,1,14.61,200,2,12.46,200,2,14.65,100,1,12.43,700,1,14.68,1400,2,12.42,700,1,14.81,100,1,12.37,700,1,15.06,100,1,ARL,286680741
993,2025-07-17T15:39:44.455130297Z,2025-07-17T15:39:44.454964327Z,160,2,1108,A,A,9,14.96,100,130,165970,248753748,13.26,100,1,14.05,100,1,13.04,2,1,14.07,2,1,13.03,100,1,14.40,100,1,12.73,100,1,14.56,900,3,12.71,100,1,14.60,700,1,12.50,700,1,14.61,200,2,12.46,200,2,14.65,100,1,12.43,700,1,14.68,1400,2,12.42,700,1,14.81,100,1,12.37,700,1,14.96,100,1,ARL,296479053
994,2025-07-17T15:39:44.456288062Z,2025-07-17T15:39:44.456122660Z,160,2,1108,C,A,6,14.65,100,130,165402,248753812,13.26,100,1,14.05,100,1,13.04,2,1,14.07,2,1,13.03,100,1,14.40,100,1,12.73,100,1,14.56,900,3,12.71,100,1,14.60,700,1,12.50,700,1,14.61,200,2,12.46,200,2,14.68,1400,2,12.43,700,1,14.81,100,1,12.42,700,1,14.96,100,1,12.37,700,1,15.06,100,1,ARL,286680905
995,2025-07-17T15:39:44.456377500Z,2025-07-17T15:39:44.456211953Z,160,2,1108,A,A,7,14.78,100,130,165547,248753815,13.26,100,1,14.05,100,1,13.04,2,1,14.07,2,1,13.03,100,1,14.40,100,1,12.73,100,1,14.56,900,3,12.71,100,1,14.60,700,1,12.50,700,1,14.61,200,2,12.46,200,2,14.68,1400,2,12.43,700,1,14.78,100,1,12.42,700,1,14.81,100,1,12.37,700,1,14.96,100,1,ARL,296479285
996,2025-07-17T15:39:44.462055094Z,2025-07-17T15:39:44.461889886Z,160,2,1108,C,A,0,14.05,100,130,165208,248753947,13.26,100,1,14.07,2,1,13.04,2,1,14.40,100,1,13.03,100,1,14.56,900,3,12.73,100,1,14.60,700,1,12.71,100,1,14.61,200,2,12.50,700,1,14.68,1400,2,12.46,200,2,14.78,100,1,12.43,700,1,14.81,100,1,12.42,700,1,14.96,100,1,12.37,700,1,15.06,100,1,ARL,296137769
997,2025-07-17T15:39:44.462108809Z,2025-07-17T15:39:44.461943584Z,160,2,1108,A,A,1,14.26,100,130,165225,248753952,13.26,100,1,14.07,2,1,13.04,2,1,14.26,100,1,13.03,100,1,14.40,100,1,12.73,100,1,14.56,900,3,12.71,100,1,14.60,700,1,12.50,700,1,14.61,200,2,12.46,200,2,14.68,1400,2,12.43,700,1,14.78,100,1,12.42,700,1,14.81,100,1,12.37,700,1,14.96,100,1,ARL,296479425
998,2025-07-17T15:39:44.478923366Z,2025-07-17T15:39:44.478757958Z,160,2,1108,C,A,18,17.58,100,0,165408,248754361,13.26,100,1,14.07,2,1,13.04,2,1,14.26,100,1,13.03,100,1,14.40,100,1,12.73,100,1,14.56,900,3,12.71,100,1,14.60,700,1,12.50,700,1,14.61,200,2,12.46,200,2,14.68,1400,2,12.43,700,1,14.78,100,1,12.42,700,1,14.81,100,1,12.37,700,1,14.96,100,1,ARL,286681057
999,2025-07-17T15:39:44.478923366Z,2025-07-17T15:39:44.478757958Z,160,2,1108,A,A,18,17.76,100,130,165408,248754361,13.26,100,1,14.07,2,1,13.04,2,1,14.26,100,1,13.03,100,1,14.40,100,1,12.73,100,1,14.56,900,3,12.71,100,1,14.60,700,1,12.50,700,1,14.61,200,2,12.46,200,2,14.68,1400,2,12.43,700,1,14.78,100,1,12.42,700,1,14.81,100,1,12.37,700,1,14.96,100,1,ARL,296479893
1000,2025-07-17T15:39:44.491018431Z,2025-07-17T15:39:44.490852860Z,160,2,1108,C,A,15,15.92,100,0,165571,248754608,13.26,100,1,14.07,2,1,13.04,2,1,14.26,100,1,13.03,100,1,14.40,100,1,12.73,100,1,14.56,900,3,12.71,100,1,14.60,700,1,12.50,700,1,14.61,200,2,12.46,200,2,14.68,1400,2,12.43,700,1,14.78,100,1,12.42,700,1,14.81,100,1,12.37,700,1,14.96,100,1,ARL,286681229
1001,2025-07-17T15:39:44.491018431Z,2025-07-17T15:39:44.490852860Z,160,2,1108,A,A,15,16.08,100,130,165571,248754608,13.26,100,1,14.07,2,1,13.04,2,1,14.26,100,1,13.03,100,1,14.40,100,1,12.73,100,1,14.56,900,3,12.71,100,1,14.60,700,1,12.50,700,1,14.61,200,2,12.46,200,2,14.68,1400,2,12.43,700,1,14.78,100,1,12.42,700,1,14.81,100,1,12.37,700,1,14.96,100,1,ARL,296480097
1002,2025-07-17T15:39:44.593773213Z,2025-07-17T15:39:44.593607433Z,160,2,1108,C,A,8,14.81,100,0,165780,248756227,13.26,100,1,14.07,2,1,13.04,2,1,14.26,100,1,13.03,100,1,14.40,100,1,12.73,100,1,14.56,900,3,12.71,100,1,14.60,700,1,12.50,700,1,14.61,200,2,12.46,200,2,14.68,1400,2,12.43,700,1,14.78,100,1,12.42,700,1,14.96,100,1,12.37,700,1,15.06,100,1,ARL,286684005
1003,2025-07-17T15:39:44.593773213Z,2025-07-17T15:39:44.593607433Z,160,2,1108,A,A,8,14.96,100,130,165780,248756227,13.26,100,1,14.07,2,1,13.04,2,1,14.26,100,1,13.03,100,1,14.40,100,1,12.73,100,1,14.56,900,3,12.71,100,1,14.60,700,1,12.50,700,1,14.61,200,2,12.46,200,2,14.68,1400,2,12.43,700,1,14.78,100,1,12.42,700,1,14.96,200,2,12.37,700,1,15.06,100,1,ARL,296482509
1004,2025-07-17T15:39:44.859886562Z,2025-07-17T15:39:44.859720946Z,160,2,1108,C,A,5,14.61,100,0,165616,248760319,13.26,100,1,14.07,2,1,13.04,2,1,14.26,100,1,13.03,100,1,14.40,100,1,12.73,100,1,14.56,900,3,12.71,100,1,14.60,700,1,12.50,700,1,14.61,100,1,12.46,200,2,14.68,1400,2,12.43,700,1,14.78,100,1,12.42,700,1,14.96,200,2,12.37,700,1,15.06,100,1,ARL,296455041
1005,2025-07-17T15:39:44.859886562Z,2025-07-17T15:39:44.859720946Z,160,2,1108,A,A,10,15.10,100,130,165616,248760319,13.26,100,1,14.07,2,1,13.04,2,1,14.26,100,1,13.03,100,1,14.40,100,1,12.73,100,1,14.56,900,3,12.71,100,1,14.60,700,1,12.50,700,1,14.61,100,1,12.46,200,2,14.68,1400,2,12.43,700,1,14.78,100,1,12.42,700,1,14.96,200,2,12.37,700,1,15.06,100,1,ARL,296485621
1006,2025-07-17T15:39:44.860160096Z,2025-07-17T15:39:44.859994671Z,160,2,1108,A,A,1,14.08,100,130,165425,248760324,13.26,100,1,14.07,2,1,13.04,2,1,14.08,100,1,13.03,100,1,14.26,100,1,12.73,100,1,14.40,100,1,12.71,100,1,14.56,900,3,12.50,700,1,14.60,700,1,12.46,200,2,14.61,100,1,12.43,700,1,14.68,1400,2,12.42,700,1,14.78,100,1,12.37,700,1,14.96,200,2,ARL,296485629
1007,2025-07-17T15:39:44.863678795Z,2025-07-17T15:39:44.863513587Z,160,2,1108,C,A,6,14.61,100,0,165208,248760417,13.26,100,1,14.07,2,1,13.04,2,1,14.08,100,1,13.03,100,1,14.26,100,1,12.73,100,1,14.40,100,1,12.71,100,1,14.56,900,3,12.50,700,1,14.60,700,1,12.46,200,2,14.68,1400,2,12.43,700,1,14.78,100,1,12.42,700,1,14.96,200,2,12.37,700,1,15.06,100,1,ARL,296455037
1008,2025-07-17T15:39:44.863678795Z,2025-07-17T15:39:44.863513587Z,160,2,1108,A,A,10,15.10,100,130,165208,248760417,13.26,100,1,14.07,2,1,13.04,2,1,14.08,100,1,13.03,100,1,14.26,100,1,12.73,100,1,14.40,100,1,12.71,100,1,14.56,900,3,12.50,700,1,14.60,700,1,12.46,200,2,14.68,1400,2,12.43,700,1,14.78,100,1,12.42,700,1,14.96,200,2,12.37,700,1,15.06,100,1,ARL,296485649
1009,2025-07-17T15:39:54.187008224Z,2025-07-17T15:39:54.186842327Z,160,2,1108,C,A,10,15.10,100,0,165897,248915116,13.26,100,1,14.07,2,1,13.04,2,1,14.08,100,1,13.03,100,1,14.26,100,1,12.73,100,1,14.40,100,1,12.71,100,1,14.56,900,3,12.50,700,1,14.60,700,1,12.46,200,2,14.68,1400,2,12.43,700,1,14.78,100,1,12.42,700,1,14.96,200,2,12.37,700,1,15.06,100,1,ARL,296485649
1010,2025-07-17T15:39:54.187008224Z,2025-07-17T15:39:54.186842327Z,160,2,1108,A,A,8,14.88,100,130,165897,248915116,13.26,100,1,14.07,2,1,13.04,2,1,14.08,100,1,13.03,100,1,14.26,100,1,12.73,100,1,14.40,100,1,12.71,100,1,14.56,900,3,12.50,700,1,14.60,700,1,12.46,200,2,14.68,1400,2,12.43,700,1,14.78,100,1,12.42,700,1,14.88,100,1,12.37,700,1,14.96,200,2,ARL,296679277
1011,2025-07-17T15:39:54.187557412Z,2025-07-17T15:39:54.187391707Z,160,2,1108,C,A,11,15.10,100,0,165705,248915126,13.26,100,1,14.07,2,1,13.04,2,1,14.08,100,1,13.03,100,1,14.26,100,1,12.73,100,1,14.40,100,1,12.71,100,1,14.56,900,3,12.50,700,1,14.60,700,1,12.46,200,2,14.68,1400,2,12.43,700,1,14.78,100,1,12.42,700,1,14.88,100,1,12.37,700,1,14.96,200,2,ARL,296485621
1012,2025-07-17T15:39:54.187557412Z,2025-07-17T15:39:54.187391707Z,160,2,1108,A,A,8,14.88,100,130,165705,248915126,13.26,100,1,14.07,2,1,13.04,2,1,14.08,100,1,13.03,100,1,14.26,100,1,12.73,100,1,14.40,100,1,12.71,100,1,14.56,900,3,12.50,700,1,14.60,700,1,12.46,200,2,14.68,1400,2,12.43,700,1,14.78,100,1,12.42,700,1,14.88,200,2,12.37,700,1,14.96,200,2,ARL,296679285
1013,2025-07-17T15:42:06.780503054Z,2025-07-17T15:42:06.780337543Z,160,2,1108,A,A,0,13.90,15,130,165511,251407709,13.26,100,1,13.90,15,1,13.04,2,1,14.07,2,1,13.03,100,1,14.08,100,1,12.73,100,1,14.26,100,1,12.71,100,1,14.40,100,1,12.50,700,1,14.56,900,3,12.46,200,2,14.60,700,1,12.43,700,1,14.68,1400,2,12.42,700,1,14.78,100,1,12.37,700,1,14.88,200,2,ARL,299689753
1014,2025-07-17T15:42:06.780767761Z,2025-07-17T15:42:06.780602350Z,160,2,1108,C,A,2,14.08,100,0,165411,251407713,13.26,100,1,13.90,15,1,13.04,2,1,14.07,2,1,13.03,100,1,14.26,100,1,12.73,100,1,14.40,100,1,12.71,100,1,14.56,900,3,12.50,700,1,14.60,700,1,12.46,200,2,14.68,1400,2,12.43,700,1,14.78,100,1,12.42,700,1,14.88,200,2,12.37,700,1,14.96,200,2,ARL,296485629
1015,2025-07-17T15:42:06.780767761Z,2025-07-17T15:42:06.780602350Z,160,2,1108,A,A,1,13.91,100,130,165411,251407713,13.26,100,1,13.90,15,1,13.04,2,1,13.91,100,1,13.03,100,1,14.07,2,1,12.73,100,1,14.26,100,1,12.71,100,1,14.40,100,1,12.50,700,1,14.56,900,3,12.46,200,2,14.60,700,1,12.43,700,1,14.68,1400,2,12.42,700,1,14.78,100,1,12.37,700,1,14.88,200,2,ARL,299689769
1016,2025-07-17T15:42:06.781502831Z,2025-07-17T15:42:06.781336642Z,160,2,1108,C,A,11,15.06,100,0,166189,251407747,13.26,100,1,13.90,15,1,13.04,2,1,13.91,100,1,13.03,100,1,14.07,2,1,12.73,100,1,14.26,100,1,12.71,100,1,14.40,100,1,12.50,700,1,14.56,900,3,12.46,200,2,14.60,700,1,12.43,700,1,14.68,1400,2,12.42,700,1,14.78,100,1,12.37,700,1,14.88,200,2,ARL,296478965
1017,2025-07-17T15:42:06.781502831Z,2025-07-17T15:42:06.781336642Z,160,2,1108,A,A,11,14.99,100,130,166189,251407747,13.26,100,1,13.90,15,1,13.04,2,1,13.91,100,1,13.03,100,1,14.07,2,1,12.73,100,1,14.26,100,1,12.71,100,1,14.40,100,1,12.50,700,1,14.56,900,3,12.46,200,2,14.60,700,1,12.43,700,1,14.68,1400,2,12.42,700,1,14.78,100,1,12.37,700,1,14.88,200,2,ARL,299689857
1018,2025-07-17T15:42:06.795521307Z,2025-07-17T15:42:06.795355762Z,160,2,1108,C,A,3,14.26,100,130,165545,251408268,13.26,100,1,13.90,15,1,13.04,2,1,13.91,100,1,13.03,100,1,14.07,2,1,12.73,100,1,14.40,100,1,12.71,100,1,14.56,900,3,12.50,700,1,14.60,700,1,12.46,200,2,14.68,1400,2,12.43,700,1,14.78,100,1,12.42,700,1,14.88,200,2,12.37,700,1,14.96,200,2,ARL,296479425
1019,2025-07-17T15:42:06.795573392Z,2025-07-17T15:42:06.795408057Z,160,2,1108,A,A,3,14.19,100,130,165335,251408269,13.26,100,1,13.90,15,1,13.04,2,1,13.91,100,1,13.03,100,1,14.07,2,1,12.73,100,1,14.19,100,1,12.71,100,1,14.40,100,1,12.50,700,1,14.56,900,3,12.46,200,2,14.60,700,1,12.43,700,1,14.68,1400,2,12.42,700,1,14.78,100,1,12.37,700,1,14.88,200,2,ARL,299690593
1020,2025-07-17T15:42:16.264132159Z,2025-07-17T15:42:16.263966448Z,160,2,1108,C,A,9,14.88,100,0,165711,251574391,13.26,100,1,13.90,15,1,13.04,2,1,13.91,100,1,13.03,100,1,14.07,2,1,12.73,100,1,14.19,100,1,12.71,100,1,14.40,100,1,12.50,700,1,14.56,900,3,12.46,200,2,14.60,700,1,12.43,700,1,14.68,1400,2,12.42,700,1,14.78,100,1,12.37,700,1,14.88,100,1,ARL,296679285
1021,2025-07-17T15:42:16.264132159Z,2025-07-17T15:42:16.263966448Z,160,2,1108,A,A,8,14.76,100,130,165711,251574391,13.26,100,1,13.90,15,1,13.04,2,1,13.91,100,1,13.03,100,1,14.07,2,1,12.73,100,1,14.19,100,1,12.71,100,1,14.40,100,1,12.50,700,1,14.56,900,3,12.46,200,2,14.60,700,1,12.43,700,1,14.68,1400,2,12.42,700,1,14.76,100,1,12.37,700,1,14.78,100,1,ARL,299903169
1022,2025-07-17T15:42:17.356766715Z,2025-07-17T15:42:17.356601231Z,160,2,1108,A,A,0,13.83,15,130,165484,251593608,13.26,100,1,13.83,15,1,13.04,2,1,13.90,15,1,13.03,100,1,13.91,100,1,12.73,100,1,14.07,2,1,12.71,100,1,14.19,100,1,12.50,700,1,14.40,100,1,12.46,200,2,14.56,900,3,12.43,700,1,14.60,700,1,12.42,700,1,14.68,1400,2,12.37,700,1,14.76,100,1,ARL,299923773
1023,2025-07-17T15:42:17.577474246Z,2025-07-17T15:42:17.577308779Z,160,2,1108,C,A,2,13.91,100,0,165467,251595553,13.26,100,1,13.83,15,1,13.04,2,1,13.90,15,1,13.03,100,1,14.07,2,1,12.73,100,1,14.19,100,1,12.71,100,1,14.40,100,1,12.50,700,1,14.56,900,3,12.46,200,2,14.60,700,1,12.43,700,1,14.68,1400,2,12.42,700,1,14.76,100,1,12.37,700,1,14.78,100,1,ARL,299689769
1024,2025-07-17T15:42:17.577474246Z,2025-07-17T15:42:17.577308779Z,160,2,1108,A,A,1,13.84,100,130,165467,251595553,13.26,100,1,13.83,15,1,13.04,2,1,13.84,100,1,13.03,100,1,13.90,15,1,12.73,100,1,14.07,2,1,12.71,100,1,14.19,100,1,12.50,700,1,14.40,100,1,12.46,200,2,14.56,900,3,12.43,700,1,14.60,700,1,12.42,700,1,14.68,1400,2,12.37,700,1,14.76,100,1,ARL,299926781
1025,2025-07-17T15:42:17.578219175Z,2025-07-17T15:42:17.578053644Z,160,2,1108,C,A,13,14.99,100,0,165531,251595563,13.26,100,1,13.83,15,1,13.04,2,1,13.84,100,1,13.03,100,1,13.90,15,1,12.73,100,1,14.07,2,1,12.71,100,1,14.19,100,1,12.50,700,1,14.40,100,1,12.46,200,2,14.56,900,3,12.43,700,1,14.60,700,1,12.42,700,1,14.68,1400,2,12.37,700,1,14.76,100,1,ARL,299689857
1026,2025-07-17T15:42:17.578219175Z,2025-07-17T15:42:17.578053644Z,160,2,1108,A,A,12,14.91,100,130,165531,251595563,13.26,100,1,13.83,15,1,13.04,2,1,13.84,100,1,13.03,100,1,13.90,15,1,12.73,100,1,14.07,2,1,12.71,100,1,14.19,100,1,12.50,700,1,14.40,100,1,12.46,200,2,14.56,900,3,12.43,700,1,14.60,700,1,12.42,700,1,14.68,1400,2,12.37,700,1,14.76,100,1,ARL,299926801
1027,2025-07-17T15:42:17.579343189Z,2025-07-17T15:42:17.579177582Z,160,2,1108,C,A,10,14.78,100,0,165607,251595571,13.26,100,1,13.83,15,1,13.04,2,1,13.84,100,1,13.03,100,1,13.90,15,1,12.73,100,1,14.07,2,1,12.71,100,1,14.19,100,1,12.50,700,1,14.40,100,1,12.46,200,2,14.56,900,3,12.43,700,1,14.60,700,1,12.42,700,1,14.68,1400,2,12.37,700,1,14.76,100,1,ARL,296479285
1028,2025-07-17T15:42:17.579343189Z,2025-07-17T15:42:17.579177582Z,160,2,1108,A,A,8,14.64,100,130,165607,251595571,13.26,100,1,13.83,15,1,13.04,2,1,13.84,100,1,13.03,100,1,13.90,15,1,12.73,100,1,14.07,2,1,12.71,100,1,14.19,100,1,12.50,700,1,14.40,100,1,12.46,200,2,14.56,900,3,12.43,700,1,14.60,700,1,12.42,700,1,14.64,100,1,12.37,700,1,14.68,1400,2,ARL,299926813
1029,2025-07-17T15:42:17.580008869Z,2025-07-17T15:42:17.579843331Z,160,2,1108,C,A,13,14.96,100,0,165538,251595576,13.26,100,1,13.83,15,1,13.04,2,1,13.84,100,1,13.03,100,1,13.90,15,1,12.73,100,1,14.07,2,1,12.71,100,1,14.19,100,1,12.50,700,1,14.40,100,1,12.46,200,2,14.56,900,3,12.43,700,1,14.60,700,1,12.42,700,1,14.64,100,1,12.37,700,1,14.68,1400,2,ARL,296479053
1030,2025-07-17T15:42:17.580008869Z,2025-07-17T15:42:17.579843331Z,160,2,1108,A,A,11,14.81,100,130,165538,251595576,13.26,100,1,13.83,15,1,13.04,2,1,13.84,100,1,13.03,100,1,13.90,15,1,12.73,100,1,14.07,2,1,12.71,100,1,14.19,100,1,12.50,700,1,14.40,100,1,12.46,200,2,14.56,900,3,12.43,700,1,14.60,700,1,12.42,700,1,14.64,100,1,12.37,700,1,14.68,1400,2,ARL,299926849
1031,2025-07-17T15:42:17.580035793Z,2025-07-17T15:42:17.579870309Z,160,2,1108,C,A,19,16.08,100,0,165484,251595577,13.26,100,1,13.83,15,1,13.04,2,1,13.84,100,1,13.03,100,1,13.90,15,1,12.73,100,1,14.07,2,1,12.71,100,1,14.19,100,1,12.50,700,1,14.40,100,1,12.46,200,2,14.56,900,3,12.43,700,1,14.60,700,1,12.42,700,1,14.64,100,1,12.37,700,1,14.68,1400,2,ARL,296480097
1032,2025-07-17T15:42:17.580035793Z,2025-07-17T15:42:17.579870309Z,160,2,1108,A,A,19,15.92,100,130,165484,251595577,13.26,100,1,13.83,15,1,13.04,2,1,13.84,100,1,13.03,100,1,13.90,15,1,12.73,100,1,14.07,2,1,12.71,100,1,14.19,100,1,12.50,700,1,14.40,100,1,12.46,200,2,14.56,900,3,12.43,700,1,14.60,700,1,12.42,700,1,14.64,100,1,12.37,700,1,14.68,1400,2,ARL,299926853
1033,2025-07-17T15:42:17.580061097Z,2025-07-17T15:42:17.579895610Z,160,2,1108,C,A,14,14.96,100,0,165487,251595578,13.26,100,1,13.83,15,1,13.04,2,1,13.84,100,1,13.03,100,1,13.90,15,1,12.73,100,1,14.07,2,1,12.71,100,1,14.19,100,1,12.50,700,1,14.40,100,1,12.46,200,2,14.56,900,3,12.43,700,1,14.60,700,1,12.42,700,1,14.64,100,1,12.37,700,1,14.68,1400,2,ARL,296482509
1034,2025-07-17T15:42:17.580061097Z,2025-07-17T15:42:17.579895610Z,160,2,1108,A,A,11,14.81,100,130,165487,251595578,13.26,100,1,13.83,15,1,13.04,2,1,13.84,100,1,13.03,100,1,13.90,15,1,12.73,100,1,14.07,2,1,12.71,100,1,14.19,100,1,12.50,700,1,14.40,100,1,12.46,200,2,14.56,900,3,12.43,700,1,14.60,700,1,12.42,700,1,14.64,100,1,12.37,700,1,14.68,1400,2,ARL,299926857
1035,2025-07-17T15:42:17.580093535Z,2025-07-17T15:42:17.579928136Z,160,2,1108,C,A,21,17.76,100,0,165399,251595580,13.26,100,1,13.83,15,1,13.04,2,1,13.84,100,1,13.03,100,1,13.90,15,1,12.73,100,1,14.07,2,1,12.71,100,1,14.19,100,1,12.50,700,1,14.40,100,1,12.46,200,2,14.56,900,3,12.43,700,1,14.60,700,1,12.42,700,1,14.64,100,1,12.37,700,1,14.68,1400,2,ARL,296479893
1036,2025-07-17T15:42:17.580093535Z,2025-07-17T15:42:17.579928136Z,160,2,1108,A,A,21,17.58,100,130,165399,251595580,13.26,100,1,13.83,15,1,13.04,2,1,13.84,100,1,13.03,100,1,13.90,15,1,12.73,100,1,14.07,2,1,12.71,100,1,14.19,100,1,12.50,700,1,14.40,100,1,12.46,200,2,14.56,900,3,12.43,700,1,14.60,700,1,12.42,700,1,14.64,100,1,12.37,700,1,14.68,1400,2,ARL,299926861
1037,2025-07-17T15:42:17.589263550Z,2025-07-17T15:42:17.589098227Z,160,2,1108,C,A,4,14.19,100,130,165323,251595691,13.26,100,1,13.83,15,1,13.04,2,1,13.84,100,1,13.03,100,1,13.90,15,1,12.73,100,1,14.07,2,1,12.71,100,1,14.40,100,1,12.50,700,1,14.56,900,3,12.46,200,2,14.60,700,1,12.43,700,1,14.64,100,1,12.42,700,1,14.68,1400,2,12.37,700,1,14.76,100,1,ARL,299690593
1038,2025-07-17T15:42:17.589316911Z,2025-07-17T15:42:17.589151325Z,160,2,1108,A,A,4,14.12,100,130,165586,251595692,13.26,100,1,13.83,15,1,13.04,2,1,13.84,100,1,13.03,100,1,13.90,15,1,12.73,100,1,14.07,2,1,12.71,100,1,14.12,100,1,12.50,700,1,14.40,100,1,12.46,200,2,14.56,900,3,12.43,700,1,14.60,700,1,12.42,700,1,14.64,100,1,12.37,700,1,14.68,1400,2,ARL,299926965
1039,2025-07-17T15:42:18.398220000Z,2025-07-17T15:42:18.398054465Z,160,2,1108,C,A,12,14.88,100,0,165535,251612478,13.26,100,1,13.83,15,1,13.04,2,1,13.84,100,1,13.03,100,1,13.90,15,1,12.73,100,1,14.07,2,1,12.71,100,1,14.12,100,1,12.50,700,1,14.40,100,1,12.46,200,2,14.56,900,3,12.43,700,1,14.60,700,1,12.42,700,1,14.64,100,1,12.37,700,1,14.68,1400,2,ARL,296679277
1040,2025-07-17T15:42:18.398220000Z,2025-07-17T15:42:18.398054465Z,160,2,1108,A,A,10,14.73,100,130,165535,251612478,13.26,100,1,13.83,15,1,13.04,2,1,13.84,100,1,13.03,100,1,13.90,15,1,12.73,100,1,14.07,2,1,12.71,100,1,14.12,100,1,12.50,700,1,14.40,100,1,12.46,200,2,14.56,900,3,12.43,700,1,14.60,700,1,12.42,700,1,14.64,100,1,12.37,700,1,14.68,1400,2,ARL,299945073
1041,2025-07-17T15:42:21.517871714Z,2025-07-17T15:42:21.517706139Z,160,2,1108,C,A,2,13.90,15,130,165575,251668179,13.26,100,1,13.83,15,1,13.04,2,1,13.84,100,1,13.03,100,1,14.07,2,1,12.73,100,1,14.12,100,1,12.71,100,1,14.40,100,1,12.50,700,1,14.56,900,3,12.46,200,2,14.60,700,1,12.43,700,1,14.64,100,1,12.42,700,1,14.68,1400,2,12.37,700,1,14.73,100,1,ARL,299689753
1042,2025-07-17T15:42:22.522744242Z,2025-07-17T15:42:22.522578675Z,160,2,1108,A,A,0,13.79,15,130,165567,251690950,13.26,100,1,13.79,15,1,13.04,2,1,13.83,15,1,13.03,100,1,13.84,100,1,12.73,100,1,14.07,2,1,12.71,100,1,14.12,100,1,12.50,700,1,14.40,100,1,12.46,200,2,14.56,900,3,12.43,700,1,14.60,700,1,12.42,700,1,14.64,100,1,12.37,700,1,14.68,1400,2,ARL,300042293
1043,2025-07-17T15:42:22.533681479Z,2025-07-17T15:42:22.533515955Z,160,2,1108,A,A,1,13.82,100,130,165524,251691033,13.26,100,1,13.79,15,1,13.04,2,1,13.82,100,1,13.03,100,1,13.83,15,1,12.73,100,1,13.84,100,1,12.71,100,1,14.07,2,1,12.50,700,1,14.12,100,1,12.46,200,2,14.40,100,1,12.43,700,1,14.56,900,3,12.42,700,1,14.60,700,1,12.37,700,1,14.64,100,1,ARL,300042385
1044,2025-07-17T15:42:23.490247121Z,2025-07-17T15:42:23.490079821Z,160,2,1108,C,A,3,13.84,100,0,167300,251710173,13.26,100,1,13.79,15,1,13.04,2,1,13.82,100,1,13.03,100,1,13.83,15,1,12.73,100,1,14.07,2,1,12.71,100,1,14.12,100,1,12.50,700,1,14.40,100,1,12.46,200,2,14.56,900,3,12.43,700,1,14.60,700,1,12.42,700,1,14.64,100,1,12.37,700,1,14.68,1400,2,ARL,299926781
1045,2025-07-17T15:42:23.490247121Z,2025-07-17T15:42:23.490079821Z,160,2,1108,A,A,1,13.80,100,128,167300,251710173,13.26,100,1,13.79,15,1,13.04,2,1,13.80,100,1,13.03,100,1,13.82,100,1,12.73,100,1,13.83,15,1,12.71,100,1,14.07,2,1,12.50,700,1,14.12,100,1,12.46,200,2,14.40,100,1,12.43,700,1,14.56,900,3,12.42,700,1,14.60,700,1,12.37,700,1,14.64,100,1,ARL,300061581
1046,2025-07-17T15:42:23.491451368Z,2025-07-17T15:42:23.491285065Z,160,2,1108,C,A,14,14.91,100,0,166303,251710647,13.26,100,1,13.79,15,1,13.04,2,1,13.80,100,1,13.03,100,1,13.82,100,1,12.73,100,1,13.83,15,1,12.71,100,1,14.07,2,1,12.50,700,1,14.12,100,1,12.46,200,2,14.40,100,1,12.43,700,1,14.56,900,3,12.42,700,1,14.60,700,1,12.37,700,1,14.64,100,1,ARL,299926801
1047,2025-07-17T15:42:23.491451368Z,2025-07-17T15:42:23.491285065Z,160,2,1108,A,A,14,14.87,100,128,166303,251710647,13.26,100,1,13.79,15,1,13.04,2,1,13.80,100,1,13.03,100,1,13.82,100,1,12.73,100,1,13.83,15,1,12.71,100,1,14.07,2,1,12.50,700,1,14.12,100,1,12.46,200,2,14.40,100,1,12.43,700,1,14.56,900,3,12.42,700,1,14.60,700,1,12.37,700,1,14.64,100,1,ARL,300061989
1048,2025-07-17T15:42:23.589065154Z,2025-07-17T15:42:23.588899941Z,160,2,1108,C,A,0,13.79,15,130,165213,251718746,13.26,100,1,13.80,100,1,13.04,2,1,13.82,100,1,13.03,100,1,13.83,15,1,12.73,100,1,14.07,2,1,12.71,100,1,14.12,100,1,12.50,700,1,14.40,100,1,12.46,200,2,14.56,900,3,12.43,700,1,14.60,700,1,12.42,700,1,14.64,100,1,12.37,700,1,14.68,1400,2,ARL,300042293
1049,2025-07-17T15:42:23.589220778Z,2025-07-17T15:42:23.589055082Z,160,2,1108,C,A,2,13.83,15,130,165696,251718767,13.26,100,1,13.80,100,1,13.04,2,1,13.82,100,1,13.03,100,1,14.07,2,1,12.73,100,1,14.12,100,1,12.71,100,1,14.40,100,1,12.50,700,1,14.56,900,3,12.46,200,2,14.60,700,1,12.43,700,1,14.64,100,1,12.42,700,1,14.68,1400,2,12.37,700,1,14.73,100,1,ARL,299923773
1050,2025-07-17T15:42:34.003710081Z,2025-07-17T15:42:34.003544527Z,160,2,1108,C,A,0,13.80,100,130,165554,251901273,13.26,100,1,13.82,100,1,13.04,2,1,14.07,2,1,13.03,100,1,14.12,100,1,12.73,100,1,14.40,100,1,12.71,100,1,14.56,900,3,12.50,700,1,14.60,700,1,12.46,200,2,14.64,100,1,12.43,700,1,14.68,1400,2,12.42,700,1,14.73,100,1,12.37,700,1,14.76,100,1,ARL,300061581
1051,2025-07-17T15:42:34.003949340Z,2025-07-17T15:42:34.003783950Z,160,2,1108,C,A,0,13.82,100,130,165390,251901275,13.26,100,1,14.07,2,1,13.04,2,1,14.12,100,1,13.03,100,1,14.40,100,1,12.73,100,1,14.56,900,3,12.71,100,1,14.60,700,1,12.50,700,1,14.64,100,1,12.46,200,2,14.68,1400,2,12.43,700,1,14.73,100,1,12.42,700,1,14.76,100,1,12.37,700,1,14.81,200,2,ARL,300042385
1052,2025-07-17T15:42:34.004225180Z,2025-07-17T15:42:34.004059450Z,160,2,1108,C,A,7,14.73,100,0,165730,251901280,13.26,100,1,14.07,2,1,13.04,2,1,14.12,100,1,13.03,100,1,14.40,100,1,12.73,100,1,14.56,900,3,12.71,100,1,14.60,700,1,12.50,700,1,14.64,100,1,12.46,200,2,14.68,1400,2,12.43,700,1,14.76,100,1,12.42,700,1,14.81,200,2,12.37,700,1,14.87,100,1,ARL,299945073
1053,2025-07-17T15:42:34.004225180Z,2025-07-17T15:42:34.004059450Z,160,2,1108,A,A,10,14.88,100,130,165730,251901280,13.26,100,1,14.07,2,1,13.04,2,1,14.12,100,1,13.03,100,1,14.40,100,1,12.73,100,1,14.56,900,3,12.71,100,1,14.60,700,1,12.50,700,1,14.64,100,1,12.46,200,2,14.68,1400,2,12.43,700,1,14.76,100,1,12.42,700,1,14.81,200,2,12.37,700,1,14.87,100,1,ARL,300280745
1054,2025-07-17T15:42:34.004671652Z,2025-07-17T15:42:34.004506043Z,160,2,1108,C,A,9,14.87,100,0,165609,251901285,13.26,100,1,14.07,2,1,13.04,2,1,14.12,100,1,13.03,100,1,14.40,100,1,12.73,100,1,14.56,900,3,12.71,100,1,14.60,700,1,12.50,700,1,14.64,100,1,12.46,200,2,14.68,1400,2,12.43,700,1,14.76,100,1,12.42,700,1,14.81,200,2,12.37,700,1,14.88,100,1,ARL,300061989
1055,2025-07-17T15:42:34.004671652Z,2025-07-17T15:42:34.004506043Z,160,2,1108,A,A,10,15.06,100,130,165609,251901285,13.26,100,1,14.07,2,1,13.04,2,1,14.12,100,1,13.03,100,1,14.40,100,1,12.73,100,1,14.56,900,3,12.71,100,1,14.60,700,1,12.50,700,1,14.64,100,1,12.46,200,2,14.68,1400,2,12.43,700,1,14.76,100,1,12.42,700,1,14.81,200,2,12.37,700,1,14.88,100,1,ARL,300280757
1056,2025-07-17T15:42:34.004677786Z,2025-07-17T15:42:34.004512153Z,160,2,1108,C,A,7,14.76,100,0,165633,251901286,13.26,100,1,14.07,2,1,13.04,2,1,14.12,100,1,13.03,100,1,14.40,100,1,12.73,100,1,14.56,900,3,12.71,100,1,14.60,700,1,12.50,700,1,14.64,100,1,12.46,200,2,14.68,1400,2,12.43,700,1,14.81,200,2,12.42,700,1,14.88,100,1,12.37,700,1,15.06,100,1,ARL,299903169
1057,2025-07-17T15:42:34.004677786Z,2025-07-17T15:42:34.004512153Z,160,2,1108,A,A,8,14.88,100,130,165633,251901286,13.26,100,1,14.07,2,1,13.04,2,1,14.12,100,1,13.03,100,1,14.40,100,1,12.73,100,1,14.56,900,3,12.71,100,1,14.60,700,1,12.50,700,1,14.64,100,1,12.46,200,2,14.68,1400,2,12.43,700,1,14.81,200,2,12.42,700,1,14.88,200,2,12.37,700,1,15.06,100,1,ARL,300280761
1058,2025-07-17T15:42:34.005574760Z,2025-07-17T15:42:34.005409139Z,160,2,1108,C,A,14,15.92,100,0,165621,251901302,13.26,100,1,14.07,2,1,13.04,2,1,14.12,100,1,13.03,100,1,14.40,100,1,12.73,100,1,14.56,900,3,12.71,100,1,14.60,700,1,12.50,700,1,14.64,100,1,12.46,200,2,14.68,1400,2,12.43,700,1,14.81,200,2,12.42,700,1,14.88,200,2,12.37,700,1,15.06,100,1,ARL,299926853
1059,2025-07-17T15:42:34.005574760Z,2025-07-17T15:42:34.005409139Z,160,2,1108,A,A,14,16.08,100,130,165621,251901302,13.26,100,1,14.07,2,1,13.04,2,1,14.12,100,1,13.03,100,1,14.40,100,1,12.73,100,1,14.56,900,3,12.71,100,1,14.60,700,1,12.50,700,1,14.64,100,1,12.46,200,2,14.68,1400,2,12.43,700,1,14.81,200,2,12.42,700,1,14.88,200,2,12.37,700,1,15.06,100,1,ARL,300280773
1060,2025-07-17T15:42:34.005832926Z,2025-07-17T15:42:34.005667449Z,160,2,1108,C,A,7,14.81,100,0,165477,251901305,13.26,100,1,14.07,2,1,13.04,2,1,14.12,100,1,13.03,100,1,14.40,100,1,12.73,100,1,14.56,900,3,12.71,100,1,14.60,700,1,12.50,700,1,14.64,100,1,12.46,200,2,14.68,1400,2,12.43,700,1,14.81,100,1,12.42,700,1,14.88,200,2,12.37,700,1,15.06,100,1,ARL,299926849
1061,2025-07-17T15:42:34.005832926Z,2025-07-17T15:42:34.005667449Z,160,2,1108,A,A,9,14.96,100,130,165477,251901305,13.26,100,1,14.07,2,1,13.04,2,1,14.12,100,1,13.03,100,1,14.40,100,1,12.73,100,1,14.56,900,3,12.71,100,1,14.60,700,1,12.50,700,1,14.64,100,1,12.46,200,2,14.68,1400,2,12.43,700,1,14.81,100,1,12.42,700,1,14.88,200,2,12.37,700,1,14.96,100,1,ARL,300280777
1062,2025-07-17T15:42:34.006831024Z,2025-07-17T15:42:34.006665512Z,160,2,1108,C,A,17,17.58,100,0,165512,251901319,13.26,100,1,14.07,2,1,13.04,2,1,14.12,100,1,13.03,100,1,14.40,100,1,12.73,100,1,14.56,900,3,12.71,100,1,14.60,700,1,12.50,700,1,14.64,100,1,12.46,200,2,14.68,1400,2,12.43,700,1,14.81,100,1,12.42,700,1,14.88,200,2,12.37,700,1,14.96,100,1,ARL,299926861
1063,2025-07-17T15:42:34.006831024Z,2025-07-17T15:42:34.006665512Z,160,2,1108,A,A,17,17.76,100,130,165512,251901319,13.26,100,1,14.07,2,1,13.04,2,1,14.12,100,1,13.03,100,1,14.40,100,1,12.73,100,1,14.56,900,3,12.71,100,1,14.60,700,1,12.50,700,1,14.64,100,1,12.46,200,2,14.68,1400,2,12.43,700,1,14.81,100,1,12.42,700,1,14.88,200,2,12.37,700,1,14.96,100,1,ARL,300280797
1064,2025-07-17T15:42:34.007908678Z,2025-07-17T15:42:34.007743383Z,160,2,1108,C,A,5,14.64,100,130,165295,251901330,13.26,100,1,14.07,2,1,13.04,2,1,14.12,100,1,13.03,100,1,14.40,100,1,12.73,100,1,14.56,900,3,12.71,100,1,14.60,700,1,12.50,700,1,14.68,1400,2,12.46,200,2,14.81,100,1,12.43,700,1,14.88,200,2,12.42,700,1,14.96,100,1,12.37,700,1,15.06,100,1,ARL,299926813
1065,2025-07-17T15:42:34.008072663Z,2025-07-17T15:42:34.007907269Z,160,2,1108,A,A,6,14.78,100,130,165394,251901331,13.26,100,1,14.07,2,1,13.04,2,1,14.12,100,1,13.03,100,1,14.40,100,1,12.73,100,1,14.56,900,3,12.71,100,1,14.60,700,1,12.50,700,1,14.68,1400,2,12.46,200,2,14.78,100,1,12.43,700,1,14.81,100,1,12.42,700,1,14.88,200,2,12.37,700,1,14.96,100,1,ARL,300280825
1066,2025-07-17T15:42:34.010196831Z,2025-07-17T15:42:34.010031518Z,160,2,1108,C,A,1,14.12,100,130,165313,251901352,13.26,100,1,14.07,2,1,13.04,2,1,14.40,100,1,13.03,100,1,14.56,900,3,12.73,100,1,14.60,700,1,12.71,100,1,14.68,1400,2,12.50,700,1,14.78,100,1,12.46,200,2,14.81,100,1,12.43,700,1,14.88,200,2,12.42,700,1,14.96,100,1,12.37,700,1,15.06,100,1,ARL,299926965
1067,2025-07-17T15:42:34.010248842Z,2025-07-17T15:42:34.010083409Z,160,2,1108,A,A,1,14.26,100,130,165433,251901353,13.26,100,1,14.07,2,1,13.04,2,1,14.26,100,1,13.03,100,1,14.40,100,1,12.73,100,1,14.56,900,3,12.71,100,1,14.60,700,1,12.50,700,1,14.68,1400,2,12.46,200,2,14.78,100,1,12.43,700,1,14.81,100,1,12.42,700,1,14.88,200,2,12.37,700,1,14.96,100,1,ARL,300280857
1068,2025-07-17T15:42:34.010572370Z,2025-07-17T15:42:34.010406771Z,160,2,1108,C,A,7,14.81,100,0,165599,251901355,13.26,100,1,14.07,2,1,13.04,2,1,14.26,100,1,13.03,100,1,14.40,100,1,12.73,100,1,14.56,900,3,12.71,100,1,14.60,700,1,12.50,700,1,14.68,1400,2,12.46,200,2,14.78,100,1,12.43,700,1,14.88,200,2,12.42,700,1,14.96,100,1,12.37,700,1,15.06,100,1,ARL,299926857
1069,2025-07-17T15:42:34.010572370Z,2025-07-17T15:42:34.010406771Z,160,2,1108,A,A,8,14.96,100,130,165599,251901355,13.26,100,1,14.07,2,1,13.04,2,1,14.26,100,1,13.03,100,1,14.40,100,1,12.73,100,1,14.56,900,3,12.71,100,1,14.60,700,1,12.50,700,1,14.68,1400,2,12.46,200,2,14.78,100,1,12.43,700,1,14.88,200,2,12.42,700,1,14.96,200,2,12.37,700,1,15.06,100,1,ARL,300280873
1070,2025-07-17T15:42:34.952098027Z,2025-07-17T15:42:34.951932909Z,160,2,1108,A,A,1,14.08,100,130,165118,251912292,13.26,100,1,14.07,2,1,13.04,2,1,14.08,100,1,13.03,100,1,14.26,100,1,12.73,100,1,14.40,100,1,12.71,100,1,14.56,900,3,12.50,700,1,14.60,700,1,12.46,200,2,14.68,1400,2,12.43,700,1,14.78,100,1,12.42,700,1,14.88,200,2,12.37,700,1,14.96,200,2,ARL,300294885
1071,2025-07-17T15:43:21.513838949Z,2025-07-17T15:43:21.513673603Z,160,2,1108,A,A,0,13.92,15,130,165346,252622568,13.26,100,1,13.92,15,1,13.04,2,1,14.07,2,1,13.03,100,1,14.08,100,1,12.73,100,1,14.26,100,1,12.71,100,1,14.40,100,1,12.50,700,1,14.56,900,3,12.46,200,2,14.60,700,1,12.43,700,1,14.68,1400,2,12.42,700,1,14.78,100,1,12.37,700,1,14.88,200,2,ARL,301218889
1072,2025-07-17T15:43:24.878236760Z,2025-07-17T15:43:24.878071152Z,160,2,1108,C,A,2,14.08,100,0,165608,252681819,13.26,100,1,13.92,15,1,13.04,2,1,14.07,2,1,13.03,100,1,14.26,100,1,12.73,100,1,14.40,100,1,12.71,100,1,14.56,900,3,12.50,700,1,14.60,700,1,12.46,200,2,14.68,1400,2,12.43,700,1,14.78,100,1,12.42,700,1,14.88,200,2,12.37,700,1,14.96,200,2,ARL,300294885
1073,2025-07-17T15:43:24.878236760Z,2025-07-17T15:43:24.878071152Z,160,2,1108,A,A,1,13.93,100,130,165608,252681819,13.26,100,1,13.92,15,1,13.04,2,1,13.93,100,1,13.03,100,1,14.07,2,1,12.73,100,1,14.26,100,1,12.71,100,1,14.40,100,1,12.50,700,1,14.56,900,3,12.46,200,2,14.60,700,1,12.43,700,1,14.68,1400,2,12.42,700,1,14.78,100,1,12.37,700,1,14.88,200,2,ARL,301295841
1074,2025-07-17T15:43:24.879003443Z,2025-07-17T15:43:24.878837670Z,160,2,1108,C,A,11,15.06,100,0,165773,252681832,13.26,100,1,13.92,15,1,13.04,2,1,13.93,100,1,13.03,100,1,14.07,2,1,12.73,100,1,14.26,100,1,12.71,100,1,14.40,100,1,12.50,700,1,14.56,900,3,12.46,200,2,14.60,700,1,12.43,700,1,14.68,1400,2,12.42,700,1,14.78,100,1,12.37,700,1,14.88,200,2,ARL,300280757
1075,2025-07-17T15:43:24.879003443Z,2025-07-17T15:43:24.878837670Z,160,2,1108,A,A,11,15.01,100,130,165773,252681832,13.26,100,1,13.92,15,1,13.04,2,1,13.93,100,1,13.03,100,1,14.07,2,1,12.73,100,1,14.26,100,1,12.71,100,1,14.40,100,1,12.50,700,1,14.56,900,3,12.46,200,2,14.60,700,1,12.43,700,1,14.68,1400,2,12.42,700,1,14.78,100,1,12.37,700,1,14.88,200,2,ARL,301295873
1076,2025-07-17T15:43:32.780372412Z,2025-07-17T15:43:32.780206927Z,160,2,1108,A,A,0,13.88,15,130,165485,252800884,13.26,100,1,13.88,15,1,13.04,2,1,13.92,15,1,13.03,100,1,13.93,100,1,12.73,100,1,14.07,2,1,12.71,100,1,14.26,100,1,12.50,700,1,14.40,100,1,12.46,200,2,14.56,900,3,12.43,700,1,14.60,700,1,12.42,700,1,14.68,1400,2,12.37,700,1,14.78,100,1,ARL,301451057
1077,2025-07-17T15:43:32.780639619Z,2025-07-17T15:43:32.780474141Z,160,2,1108,C,A,2,13.93,100,0,165478,252800887,13.26,100,1,13.88,15,1,13.04,2,1,13.92,15,1,13.03,100,1,14.07,2,1,12.73,100,1,14.26,100,1,12.71,100,1,14.40,100,1,12.50,700,1,14.56,900,3,12.46,200,2,14.60,700,1,12.43,700,1,14.68,1400,2,12.42,700,1,14.78,100,1,12.37,700,1,14.88,200,2,ARL,301295841
1078,2025-07-17T15:43:32.780639619Z,2025-07-17T15:43:32.780474141Z,160,2,1108,A,A,1,13.89,100,130,165478,252800887,13.26,100,1,13.88,15,1,13.04,2,1,13.89,100,1,13.03,100,1,13.92,15,1,12.73,100,1,14.07,2,1,12.71,100,1,14.26,100,1,12.50,700,1,14.40,100,1,12.46,200,2,14.56,900,3,12.43,700,1,14.60,700,1,12.42,700,1,14.68,1400,2,12.37,700,1,14.78,100,1,ARL,301451061
1079,2025-07-17T15:43:32.781382162Z,2025-07-17T15:43:32.781216589Z,160,2,1108,C,A,12,15.01,100,0,165573,252800892,13.26,100,1,13.88,15,1,13.04,2,1,13.89,100,1,13.03,100,1,13.92,15,1,12.73,100,1,14.07,2,1,12.71,100,1,14.26,100,1,12.50,700,1,14.40,100,1,12.46,200,2,14.56,900,3,12.43,700,1,14.60,700,1,12.42,700,1,14.68,1400,2,12.37,700,1,14.78,100,1,ARL,301295873
1080,2025-07-17T15:43:32.781382162Z,2025-07-17T15:43:32.781216589Z,160,2,1108,A,A,12,14.97,100,130,165573,252800892,13.26,100,1,13.88,15,1,13.04,2,1,13.89,100,1,13.03,100,1,13.92,15,1,12.73,100,1,14.07,2,1,12.71,100,1,14.26,100,1,12.50,700,1,14.40,100,1,12.46,200,2,14.56,900,3,12.43,700,1,14.60,700,1,12.42,700,1,14.68,1400,2,12.37,700,1,14.78,100,1,ARL,301451077
1081,2025-07-17T15:43:32.792119698Z,2025-07-17T15:43:32.791954053Z,160,2,1108,C,A,4,14.26,100,130,165645,252801681,13.26,100,1,13.88,15,1,13.04,2,1,13.89,100,1,13.03,100,1,13.92,15,1,12.73,100,1,14.07,2,1,12.71,100,1,14.40,100,1,12.50,700,1,14.56,900,3,12.46,200,2,14.60,700,1,12.43,700,1,14.68,1400,2,12.42,700,1,14.78,100,1,12.37,700,1,14.88,200,2,ARL,300280857
1082,2025-07-17T15:43:32.792174617Z,2025-07-17T15:43:32.792008881Z,160,2,1108,A,A,4,14.17,100,130,165736,252801689,13.26,100,1,13.88,15,1,13.04,2,1,13.89,100,1,13.03,100,1,13.92,15,1,12.73,100,1,14.07,2,1,12.71,100,1,14.17,100,1,12.50,700,1,14.40,100,1,12.46,200,2,14.56,900,3,12.43,700,1,14.60,700,1,12.42,700,1,14.68,1400,2,12.37,700,1,14.78,100,1,ARL,301452785
1083,2025-07-17T15:43:44.004832641Z,2025-07-17T15:43:44.004667259Z,160,2,1108,C,A,2,13.92,15,130,165382,252977583,13.26,100,1,13.88,15,1,13.04,2,1,13.89,100,1,13.03,100,1,14.07,2,1,12.73,100,1,14.17,100,1,12.71,100,1,14.40,100,1,12.50,700,1,14.56,900,3,12.46,200,2,14.60,700,1,12.43,700,1,14.68,1400,2,12.42,700,1,14.78,100,1,12.37,700,1,14.88,200,2,ARL,301218889
1084,2025-07-17T15:43:44.005191111Z,2025-07-17T15:43:44.005025587Z,160,2,1108,C,A,9,14.88,100,0,165524,252977592,13.26,100,1,13.88,15,1,13.04,2,1,13.89,100,1,13.03,100,1,14.07,2,1,12.73,100,1,14.17,100,1,12.71,100,1,14.40,100,1,12.50,700,1,14.56,900,3,12.46,200,2,14.60,700,1,12.43,700,1,14.68,1400,2,12.42,700,1,14.78,100,1,12.37,700,1,14.88,100,1,ARL,300280761
1085,2025-07-17T15:43:44.005191111Z,2025-07-17T15:43:44.005025587Z,160,2,1108,A,A,8,14.77,100,130,165524,252977592,13.26,100,1,13.88,15,1,13.04,2,1,13.89,100,1,13.03,100,1,14.07,2,1,12.73,100,1,14.17,100,1,12.71,100,1,14.40,100,1,12.50,700,1,14.56,900,3,12.46,200,2,14.60,700,1,12.43,700,1,14.68,1400,2,12.42,700,1,14.77,100,1,12.37,700,1,14.78,100,1,ARL,301671709
1086,2025-07-17T15:43:44.005313071Z,2025-07-17T15:43:44.005147707Z,160,2,1108,C,A,10,14.88,100,0,165364,252977595,13.26,100,1,13.88,15,1,13.04,2,1,13.89,100,1,13.03,100,1,14.07,2,1,12.73,100,1,14.17,100,1,12.71,100,1,14.40,100,1,12.50,700,1,14.56,900,3,12.46,200,2,14.60,700,1,12.43,700,1,14.68,1400,2,12.42,700,1,14.77,100,1,12.37,700,1,14.78,100,1,ARL,300280745
1087,2025-07-17T15:43:44.005313071Z,2025-07-17T15:43:44.005147707Z,160,2,1108,A,A,8,14.77,100,130,165364,252977595,13.26,100,1,13.88,15,1,13.04,2,1,13.89,100,1,13.03,100,1,14.07,2,1,12.73,100,1,14.17,100,1,12.71,100,1,14.40,100,1,12.50,700,1,14.56,900,3,12.46,200,2,14.60,700,1,12.43,700,1,14.68,1400,2,12.42,700,1,14.77,200,2,12.37,700,1,14.78,100,1,ARL,301671713
1088,2025-07-17T15:43:48.787497664Z,2025-07-17T15:43:48.787332399Z,160,2,1108,A,A,0,13.83,15,130,165265,253027890,13.26,100,1,13.83,15,1,13.04,2,1,13.88,15,1,13.03,100,1,13.89,100,1,12.73,100,1,14.07,2,1,12.71,100,1,14.17,100,1,12.50,700,1,14.40,100,1,12.46,200,2,14.56,900,3,12.43,700,1,14.60,700,1,12.42,700,1,14.68,1400,2,12.37,700,1,14.77,200,2,ARL,301746941
1089,2025-07-17T15:43:48.787766907Z,2025-07-17T15:43:48.787601640Z,160,2,1108,C,A,2,13.89,100,0,165267,253027924,13.26,100,1,13.83,15,1,13.04,2,1,13.88,15,1,13.03,100,1,14.07,2,1,12.73,100,1,14.17,100,1,12.71,100,1,14.40,100,1,12.50,700,1,14.56,900,3,12.46,200,2,14.60,700,1,12.43,700,1,14.68,1400,2,12.42,700,1,14.77,200,2,12.37,700,1,14.78,100,1,ARL,301451061
1090,2025-07-17T15:43:48.787766907Z,2025-07-17T15:43:48.787601640Z,160,2,1108,A,A,1,13.84,100,130,165267,253027924,13.26,100,1,13.83,15,1,13.04,2,1,13.84,100,1,13.03,100,1,13.88,15,1,12.73,100,1,14.07,2,1,12.71,100,1,14.17,100,1,12.50,700,1,14.40,100,1,12.46,200,2,14.56,900,3,12.43,700,1,14.60,700,1,12.42,700,1,14.68,1400,2,12.37,700,1,14.77,200,2,ARL,301746949
1091,2025-07-17T15:43:48.788512022Z,2025-07-17T15:43:48.788345787Z,160,2,1108,C,A,12,14.97,100,0,166235,253027959,13.26,100,1,13.83,15,1,13.04,2,1,13.84,100,1,13.03,100,1,13.88,15,1,12.73,100,1,14.07,2,1,12.71,100,1,14.17,100,1,12.50,700,1,14.40,100,1,12.46,200,2,14.56,900,3,12.43,700,1,14.60,700,1,12.42,700,1,14.68,1400,2,12.37,700,1,14.77,200,2,ARL,301451077
1092,2025-07-17T15:43:48.788512022Z,2025-07-17T15:43:48.788345787Z,160,2,1108,A,A,11,14.91,100,128,166235,253027959,13.26,100,1,13.83,15,1,13.04,2,1,13.84,100,1,13.03,100,1,13.88,15,1,12.73,100,1,14.07,2,1,12.71,100,1,14.17,100,1,12.50,700,1,14.40,100,1,12.46,200,2,14.56,900,3,12.43,700,1,14.60,700,1,12.42,700,1,14.68,1400,2,12.37,700,1,14.77,200,2,ARL,301746969
1093,2025-07-17T15:43:48.790573820Z,2025-07-17T15:43:48.790408191Z,160,2,1108,C,A,12,14.96,100,0,165629,253028026,13.26,100,1,13.83,15,1,13.04,2,1,13.84,100,1,13.03,100,1,13.88,15,1,12.73,100,1,14.07,2,1,12.71,100,1,14.17,100,1,12.50,700,1,14.40,100,1,12.46,200,2,14.56,900,3,12.43,700,1,14.60,700,1,12.42,700,1,14.68,1400,2,12.37,700,1,14.77,200,2,ARL,300280777
1094,2025-07-17T15:43:48.790573820Z,2025-07-17T15:43:48.790408191Z,160,2,1108,A,A,11,14.81,100,130,165629,253028026,13.26,100,1,13.83,15,1,13.04,2,1,13.84,100,1,13.03,100,1,13.88,15,1,12.73,100,1,14.07,2,1,12.71,100,1,14.17,100,1,12.50,700,1,14.40,100,1,12.46,200,2,14.56,900,3,12.43,700,1,14.60,700,1,12.42,700,1,14.68,1400,2,12.37,700,1,14.77,200,2,ARL,301747001
1095,2025-07-17T15:43:48.790600546Z,2025-07-17T15:43:48.790434947Z,160,2,1108,C,A,10,14.78,100,0,165599,253028027,13.26,100,1,13.83,15,1,13.04,2,1,13.84,100,1,13.03,100,1,13.88,15,1,12.73,100,1,14.07,2,1,12.71,100,1,14.17,100,1,12.50,700,1,14.40,100,1,12.46,200,2,14.56,900,3,12.43,700,1,14.60,700,1,12.42,700,1,14.68,1400,2,12.37,700,1,14.77,200,2,ARL,300280825
1096,2025-07-17T15:43:48.790600546Z,2025-07-17T15:43:48.790434947Z,160,2,1108,A,A,8,14.64,100,130,165599,253028027,13.26,100,1,13.83,15,1,13.04,2,1,13.84,100,1,13.03,100,1,13.88,15,1,12.73,100,1,14.07,2,1,12.71,100,1,14.17,100,1,12.50,700,1,14.40,100,1,12.46,200,2,14.56,900,3,12.43,700,1,14.60,700,1,12.42,700,1,14.64,100,1,12.37,700,1,14.68,1400,2,ARL,301747005
1097,2025-07-17T15:43:48.800959598Z,2025-07-17T15:43:48.800794196Z,160,2,1108,C,A,20,17.76,100,0,165402,253028707,13.26,100,1,13.83,15,1,13.04,2,1,13.84,100,1,13.03,100,1,13.88,15,1,12.73,100,1,14.07,2,1,12.71,100,1,14.17,100,1,12.50,700,1,14.40,100,1,12.46,200,2,14.56,900,3,12.43,700,1,14.60,700,1,12.42,700,1,14.64,100,1,12.37,700,1,14.68,1400,2,ARL,300280797
1098,2025-07-17T15:43:48.800959598Z,2025-07-17T15:43:48.800794196Z,160,2,1108,A,A,20,17.58,100,130,165402,253028707,13.26,100,1,13.83,15,1,13.04,2,1,13.84,100,1,13.03,100,1,13.88,15,1,12.73,100,1,14.07,2,1,12.71,100,1,14.17,100,1,12.50,700,1,14.40,100,1,12.46,200,2,14.56,900,3,12.43,700,1,14.60,700,1,12.42,700,1,14.64,100,1,12.37,700,1,14.68,1400,2,ARL,301747261
1099,2025-07-17T15:43:48.806845249Z,2025-07-17T15:43:48.806679708Z,160,2,1108,C,A,18,16.08,100,0,165541,253028803,13.26,100,1,13.83,15,1,13.04,2,1,13.84,100,1,13.03,100,1,13.88,15,1,12.73,100,1,14.07,2,1,12.71,100,1,14.17,100,1,12.50,700,1,14.40,100,1,12.46,200,2,14.56,900,3,12.43,700,1,14.60,700,1,12.42,700,1,14.64,100,1,12.37,700,1,14.68,1400,2,ARL,300280773
1100,2025-07-17T15:43:48.806845249Z,2025-07-17T15:43:48.806679708Z,160,2,1108,A,A,18,15.92,100,130,165541,253028803,13.26,100,1,13.83,15,1,13.04,2,1,13.84,100,1,13.03,100,1,13.88,15,1,12.73,100,1,14.07,2,1,12.71,100,1,14.17,100,1,12.50,700,1,14.40,100,1,12.46,200,2,14.56,900,3,12.43,700,1,14.60,700,1,12.42,700,1,14.64,100,1,12.37,700,1,14.68,1400,2,ARL,301747301
1101,2025-07-17T15:43:48.852570853Z,2025-07-17T15:43:48.852405047Z,160,2,1108,C,A,13,14.96,100,0,165806,253029437,13.26,100,1,13.83,15,1,13.04,2,1,13.84,100,1,13.03,100,1,13.88,15,1,12.73,100,1,14.07,2,1,12.71,100,1,14.17,100,1,12.50,700,1,14.40,100,1,12.46,200,2,14.56,900,3,12.43,700,1,14.60,700,1,12.42,700,1,14.64,100,1,12.37,700,1,14.68,1400,2,ARL,300280873
1102,2025-07-17T15:43:48.852570853Z,2025-07-17T15:43:48.852405047Z,160,2,1108,A,A,11,14.81,100,130,165806,253029437,13.26,100,1,13.83,15,1,13.04,2,1,13.84,100,1,13.03,100,1,13.88,15,1,12.73,100,1,14.07,2,1,12.71,100,1,14.17,100,1,12.50,700,1,14.40,100,1,12.46,200,2,14.56,900,3,12.43,700,1,14.60,700,1,12.42,700,1,14.64,100,1,12.37,700,1,14.68,1400,2,ARL,301747957
1103,2025-07-17T15:43:53.123817759Z,2025-07-17T15:43:53.123652480Z,160,2,1108,C,A,2,13.88,15,130,165279,253100941,13.26,100,1,13.83,15,1,13.04,2,1,13.84,100,1,13.03,100,1,14.07,2,1,12.73,100,1,14.17,100,1,12.71,100,1,14.40,100,1,12.50,700,1,14.56,900,3,12.46,200,2,14.60,700,1,12.43,700,1,14.64,100,1,12.42,700,1,14.68,1400,2,12.37,700,1,14.77,200,2,ARL,301451057
1104,2025-07-17T15:43:54.126276976Z,2025-07-17T15:43:54.126111293Z,160,2,1108,A,A,0,13.81,15,130,165683,253121467,13.26,100,1,13.81,15,1,13.04,2,1,13.83,15,1,13.03,100,1,13.84,100,1,12.73,100,1,14.07,2,1,12.71,100,1,14.17,100,1,12.50,700,1,14.40,100,1,12.46,200,2,14.56,900,3,12.43,700,1,14.60,700,1,12.42,700,1,14.64,100,1,12.37,700,1,14.68,1400,2,ARL,301867541
1105,2025-07-17T15:43:54.998238933Z,2025-07-17T15:43:54.998073317Z,160,2,1108,C,A,2,13.84,100,0,165616,253137948,13.26,100,1,13.81,15,1,13.04,2,1,13.83,15,1,13.03,100,1,14.07,2,1,12.73,100,1,14.17,100,1,12.71,100,1,14.40,100,1,12.50,700,1,14.56,900,3,12.46,200,2,14.60,700,1,12.43,700,1,14.64,100,1,12.42,700,1,14.68,1400,2,12.37,700,1,14.77,200,2,ARL,301746949
1106,2025-07-17T15:43:54.998238933Z,2025-07-17T15:43:54.998073317Z,160,2,1108,A,A,1,13.82,100,130,165616,253137948,13.26,100,1,13.81,15,1,13.04,2,1,13.82,100,1,13.03,100,1,13.83,15,1,12.73,100,1,14.07,2,1,12.71,100,1,14.17,100,1,12.50,700,1,14.40,100,1,12.46,200,2,14.56,900,3,12.43,700,1,14.60,700,1,12.42,700,1,14.64,100,1,12.37,700,1,14.68,1400,2,ARL,301885353
1107,2025-07-17T15:43:55.019172741Z,2025-07-17T15:43:55.019007300Z,160,2,1108,C,A,4,14.17,100,130,165441,253138492,13.26,100,1,13.81,15,1,13.04,2,1,13.82,100,1,13.03,100,1,13.83,15,1,12.73,100,1,14.07,2,1,12.71,100,1,14.40,100,1,12.50,700,1,14.56,900,3,12.46,200,2,14.60,700,1,12.43,700,1,14.64,100,1,12.42,700,1,14.68,1400,2,12.37,700,1,14.77,200,2,ARL,301452785
1108,2025-07-17T15:43:55.019225935Z,2025-07-17T15:43:55.019060515Z,160,2,1108,A,A,4,14.10,100,130,165420,253138493,13.26,100,1,13.81,15,1,13.04,2,1,13.82,100,1,13.03,100,1,13.83,15,1,12.73,100,1,14.07,2,1,12.71,100,1,14.10,100,1,12.50,700,1,14.40,100,1,12.46,200,2,14.56,900,3,12.43,700,1,14.60,700,1,12.42,700,1,14.64,100,1,12.37,700,1,14.68,1400,2,ARL,301886057
1109,2025-07-17T15:44:01.698791467Z,2025-07-17T15:44:01.698626200Z,160,2,1108,C,A,2,13.83,15,130,165267,253246317,13.26,100,1,13.81,15,1,13.04,2,1,13.82,100,1,13.03,100,1,14.07,2,1,12.73,100,1,14.10,100,1,12.71,100,1,14.40,100,1,12.50,700,1,14.56,900,3,12.46,200,2,14.60,700,1,12.43,700,1,14.64,100,1,12.42,700,1,14.68,1400,2,12.37,700,1,14.77,200,2,ARL,301746941
1110,2025-07-17T15:44:04.014878156Z,2025-07-17T15:44:04.014712730Z,160,2,1108,A,A,2,13.83,100,130,165426,253292355,13.26,100,1,13.81,15,1,13.04,2,1,13.82,100,1,13.03,100,1,13.83,100,1,12.73,100,1,14.07,2,1,12.71,100,1,14.10,100,1,12.50,700,1,14.40,100,1,12.46,200,2,14.56,900,3,12.43,700,1,14.60,700,1,12.42,700,1,14.64,100,1,12.37,700,1,14.68,1400,2,ARL,302078553
1111,2025-07-17T15:44:05.055626948Z,2025-07-17T15:44:05.055461574Z,160,2,1108,A,A,0,13.81,100,130,165374,253307083,13.26,100,1,13.81,115,2,13.04,2,1,13.82,100,1,13.03,100,1,13.83,100,1,12.73,100,1,14.07,2,1,12.71,100,1,14.10,100,1,12.50,700,1,14.40,100,1,12.46,200,2,14.56,900,3,12.43,700,1,14.60,700,1,12.42,700,1,14.64,100,1,12.37,700,1,14.68,1400,2,ARL,302100649
1112,2025-07-17T15:44:05.062431949Z,2025-07-17T15:44:05.062266845Z,160,2,1108,C,A,2,13.83,100,130,165104,253307147,13.26,100,1,13.81,115,2,13.04,2,1,13.82,100,1,13.03,100,1,14.07,2,1,12.73,100,1,14.10,100,1,12.71,100,1,14.40,100,1,12.50,700,1,14.56,900,3,12.46,200,2,14.60,700,1,12.43,700,1,14.64,100,1,12.42,700,1,14.68,1400,2,12.37,700,1,14.77,200,2,ARL,302078553
1113,2025-07-17T15:44:09.389713730Z,2025-07-17T15:44:09.389548394Z,160,2,1108,A,A,0,13.76,15,130,165336,253384422,13.26,100,1,13.76,15,1,13.04,2,1,13.81,115,2,13.03,100,1,13.82,100,1,12.73,100,1,14.07,2,1,12.71,100,1,14.10,100,1,12.50,700,1,14.40,100,1,12.46,200,2,14.56,900,3,12.43,700,1,14.60,700,1,12.42,700,1,14.64,100,1,12.37,700,1,14.68,1400,2,ARL,302205249
1114,2025-07-17T15:44:09.390496140Z,2025-07-17T15:44:09.390329935Z,160,2,1108,C,A,10,14.77,100,0,166205,253384438,13.26,100,1,13.76,15,1,13.04,2,1,13.81,115,2,13.03,100,1,13.82,100,1,12.73,100,1,14.07,2,1,12.71,100,1,14.10,100,1,12.50,700,1,14.40,100,1,12.46,200,2,14.56,900,3,12.43,700,1,14.60,700,1,12.42,700,1,14.64,100,1,12.37,700,1,14.68,1400,2,ARL,301671709
1115,2025-07-17T15:44:09.390496140Z,2025-07-17T15:44:09.390329935Z,160,2,1108,A,A,9,14.66,100,128,166205,253384438,13.26,100,1,13.76,15,1,13.04,2,1,13.81,115,2,13.03,100,1,13.82,100,1,12.73,100,1,14.07,2,1,12.71,100,1,14.10,100,1,12.50,700,1,14.40,100,1,12.46,200,2,14.56,900,3,12.43,700,1,14.60,700,1,12.42,700,1,14.64,100,1,12.37,700,1,14.66,100,1,ARL,302205289
1116,2025-07-17T15:44:09.391058486Z,2025-07-17T15:44:09.390893172Z,160,2,1108,C,A,11,14.77,100,0,165314,253384456,13.26,100,1,13.76,15,1,13.04,2,1,13.81,115,2,13.03,100,1,13.82,100,1,12.73,100,1,14.07,2,1,12.71,100,1,14.10,100,1,12.50,700,1,14.40,100,1,12.46,200,2,14.56,900,3,12.43,700,1,14.60,700,1,12.42,700,1,14.64,100,1,12.37,700,1,14.66,100,1,ARL,301671713
1117,2025-07-17T15:44:09.391058486Z,2025-07-17T15:44:09.390893172Z,160,2,1108,A,A,9,14.66,100,130,165314,253384456,13.26,100,1,13.76,15,1,13.04,2,1,13.81,115,2,13.03,100,1,13.82,100,1,12.73,100,1,14.07,2,1,12.71,100,1,14.10,100,1,12.50,700,1,14.40,100,1,12.46,200,2,14.56,900,3,12.43,700,1,14.60,700,1,12.42,700,1,14.64,100,1,12.37,700,1,14.66,200,2,ARL,302205309
1118,2025-07-17T15:44:09.395447612Z,2025-07-17T15:44:09.395281780Z,160,2,1108,C,A,2,13.82,100,0,165832,253384698,13.26,100,1,13.76,15,1,13.04,2,1,13.81,115,2,13.03,100,1,14.07,2,1,12.73,100,1,14.10,100,1,12.71,100,1,14.40,100,1,12.50,700,1,14.56,900,3,12.46,200,2,14.60,700,1,12.43,700,1,14.64,100,1,12.42,700,1,14.66,200,2,12.37,700,1,14.68,1400,2,ARL,301885353
1119,2025-07-17T15:44:09.395447612Z,2025-07-17T15:44:09.395281780Z,160,2,1108,A,A,1,13.77,100,130,165832,253384698,13.26,100,1,13.76,15,1,13.04,2,1,13.77,100,1,13.03,100,1,13.81,115,2,12.73,100,1,14.07,2,1,12.71,100,1,14.10,100,1,12.50,700,1,14.40,100,1,12.46,200,2,14.56,900,3,12.43,700,1,14.60,700,1,12.42,700,1,14.64,100,1,12.37,700,1,14.66,200,2,ARL,302205493
1120,2025-07-17T15:44:09.396195647Z,2025-07-17T15:44:09.396030225Z,160,2,1108,C,A,12,14.91,100,0,165422,253384731,13.26,100,1,13.76,15,1,13.04,2,1,13.77,100,1,13.03,100,1,13.81,115,2,12.73,100,1,14.07,2,1,12.71,100,1,14.10,100,1,12.50,700,1,14.40,100,1,12.46,200,2,14.56,900,3,12.43,700,1,14.60,700,1,12.42,700,1,14.64,100,1,12.37,700,1,14.66,200,2,ARL,301746969
1121,2025-07-17T15:44:09.396195647Z,2025-07-17T15:44:09.396030225Z,160,2,1108,A,A,12,14.84,100,130,165422,253384731,13.26,100,1,13.76,15,1,13.04,2,1,13.77,100,1,13.03,100,1,13.81,115,2,12.73,100,1,14.07,2,1,12.71,100,1,14.10,100,1,12.50,700,1,14.40,100,1,12.46,200,2,14.56,900,3,12.43,700,1,14.60,700,1,12.42,700,1,14.64,100,1,12.37,700,1,14.66,200,2,ARL,302205537
1122,2025-07-17T15:44:09.398011186Z,2025-07-17T15:44:09.397845986Z,160,2,1108,A,A,2,13.79,100,130,165200,253384788,13.26,100,1,13.76,15,1,13.04,2,1,13.77,100,1,13.03,100,1,13.79,100,1,12.73,100,1,13.81,115,2,12.71,100,1,14.07,2,1,12.50,700,1,14.10,100,1,12.46,200,2,14.40,100,1,12.43,700,1,14.56,900,3,12.42,700,1,14.60,700,1,12.37,700,1,14.64,100,1,ARL,302205561
1123,2025-07-17T15:44:09.404828956Z,2025-07-17T15:44:09.404663816Z,160,2,1108,C,A,3,13.81,100,130,165140,253385013,13.26,100,1,13.76,15,1,13.04,2,1,13.77,100,1,13.03,100,1,13.79,100,1,12.73,100,1,13.81,15,1,12.71,100,1,14.07,2,1,12.50,700,1,14.10,100,1,12.46,200,2,14.40,100,1,12.43,700,1,14.56,900,3,12.42,700,1,14.60,700,1,12.37,700,1,14.64,100,1,ARL,302100649
1124,2025-07-17T15:44:20.402535831Z,2025-07-17T15:44:20.402370565Z,160,2,1108,C,A,3,13.81,15,130,165266,253562230,13.26,100,1,13.76,15,1,13.04,2,1,13.77,100,1,13.03,100,1,13.79,100,1,12.73,100,1,14.07,2,1,12.71,100,1,14.10,100,1,12.50,700,1,14.40,100,1,12.46,200,2,14.56,900,3,12.43,700,1,14.60,700,1,12.42,700,1,14.64,100,1,12.37,700,1,14.66,200,2,ARL,301867541
1125,2025-07-17T15:44:21.405486122Z,2025-07-17T15:44:21.405320730Z,160,2,1108,A,A,0,13.74,15,130,165392,253582427,13.26,100,1,13.74,15,1,13.04,2,1,13.76,15,1,13.03,100,1,13.77,100,1,12.73,100,1,13.79,100,1,12.71,100,1,14.07,2,1,12.50,700,1,14.10,100,1,12.46,200,2,14.40,100,1,12.43,700,1,14.56,900,3,12.42,700,1,14.60,700,1,12.37,700,1,14.64,100,1,ARL,302458113
1126,2025-07-17T15:44:21.843235911Z,2025-07-17T15:44:21.843070079Z,160,2,1108,C,A,2,13.77,100,0,165832,253590641,13.26,100,1,13.74,15,1,13.04,2,1,13.76,15,1,13.03,100,1,13.79,100,1,12.73,100,1,14.07,2,1,12.71,100,1,14.10,100,1,12.50,700,1,14.40,100,1,12.46,200,2,14.56,900,3,12.43,700,1,14.60,700,1,12.42,700,1,14.64,100,1,12.37,700,1,14.66,200,2,ARL,302205493
1127,2025-07-17T15:44:21.843235911Z,2025-07-17T15:44:21.843070079Z,160,2,1108,A,A,1,13.75,100,130,165832,253590641,13.26,100,1,13.74,15,1,13.04,2,1,13.75,100,1,13.03,100,1,13.76,15,1,12.73,100,1,13.79,100,1,12.71,100,1,14.07,2,1,12.50,700,1,14.10,100,1,12.46,200,2,14.40,100,1,12.43,700,1,14.56,900,3,12.42,700,1,14.60,700,1,12.37,700,1,14.64,100,1,ARL,302466045
1128,2025-07-17T15:44:21.855416093Z,2025-07-17T15:44:21.855250804Z,160,2,1108,C,A,5,14.10,100,130,165289,253590837,13.26,100,1,13.74,15,1,13.04,2,1,13.75,100,1,13.03,100,1,13.76,15,1,12.73,100,1,13.79,100,1,12.71,100,1,14.07,2,1,12.50,700,1,14.40,100,1,12.46,200,2,14.56,900,3,12.43,700,1,14.60,700,1,12.42,700,1,14.64,100,1,12.37,700,1,14.66,200,2,ARL,301886057
